Workbook

Sheet 0_說明
B1: EX01｜W1 容量器具校正（秤重法）
B2: 食品分析實驗・入門數據分析（Excel 版）。不用寫程式；同一份數據在 Colab 筆記本做進階分析，答案應該一致。
B4: 學習目標
B5: • 把秤到的水重，經水溫密度與空氣浮力校正，換成真實體積。
B6: • 用 AVERAGE、STDEV.S、T.INV.2T 算平均、SD、RSD 與 95% 信賴區間。
B7: • 用 Class A 公差判斷準確度與精密度，畫 target diagram。
B8: • 依信賴區間決定平均值該報告到第幾位小數。
B10: 顏色代表什麼
C11: 黃色：輸入或貼上數據的地方
C12: 綠色：公式，會自動計算，不要改
C13: 橘色：重點結果，寫報告時用
B15: 操作步驟
B16: 1. 看「1_原始數據」：一列是一次秤重。右邊綠色欄已經把每一次換成體積 (mL)。
B17: 2. 看「2_密度換算」：理解密度與浮力校正，做第 36–41 列的自我檢查。
B18: 3. 看「3_逐生統計」：每位同學一列，算平均、SD、RSD、CI、bias，並自動分類。往下捲有兩張圖。
B19: 4. 看「4_組別與全班」：各組平均、兩種器具比較、單樣本 t 檢定。
B20: 5. 完成「練習題」。
B21: 6. 換成班級數據：把共用 Google Sheet 的數據貼到「1_原始數據」A2 起；學生名單不同就改「3_逐生統計」A–C 欄。
B23: 對答案：用內建範例數據時，你的結果應該等於
B24: 項目 | C24: 本檔計算值 | D24: Colab 筆記本的值 | E24: 一致？
B25: ρw(25 °C) (g/mL) | C25: ='2_密度換算'!C38 | D25: 0.99704702 | E25: =IF(ABS(C25-D25)<=9.970570216718241e-05,"✔ 一致","✘ 不一致（換成班級數據後本來就會不同）")
B26: G1_S1 移液管平均 (mL) | C26: ='3_逐生統計'!Q5 | D26: 10.002786 | E26: =IF(ABS(C26-D26)<=0.0010002796391635198,"✔ 一致","✘ 不一致（換成班級數據後本來就會不同）")
B27: G1_S1 移液管 SD (mL) | C27: ='3_逐生統計'!R5 | D27: 0.0034232885 | E27: =IF(ABS(C27-D27)<=3.4332884538860615e-07,"✔ 一致","✘ 不一致（換成班級數據後本來就會不同）")
B28: G1_S1 移液管 95% CI 半寬 | C28: ='3_逐生統計'!U5 | D28: 0.002448873 | E28: =IF(ABS(C28-D28)<=2.4588730366170335e-07,"✔ 一致","✘ 不一致（換成班級數據後本來就會不同）")
B29: G1_S1 滴定管 t 值（Colab 範例 t = 5.085） | C29: ='4_組別與全班'!B28 | D29: 5.0854578 | E29: =IF(ABS(C29-D29)<=0.0005085467829282833,"✔ 一致","✘ 不一致（換成班級數據後本來就會不同）")
B30: 移液管全班平均 RSD (%) | C30: ='4_組別與全班'!D18 | D30: 0.23150318 | E30: =IF(ABS(C30-D30)<=2.3151317634301493e-05,"✔ 一致","✘ 不一致（換成班級數據後本來就會不同）")
B31: 滴定管全班平均 RSD (%) | C31: ='4_組別與全班'!D19 | D31: 0.070806097 | E31: =IF(ABS(C31-D31)<=7.08160973286325e-06,"✔ 一致","✘ 不一致（換成班級數據後本來就會不同）")
B32: 「Colab 筆記本的值」是用內建模擬數據算出的答案；換成全班數據後，這一欄就不再適用。
B34: 相關連結
B35: 本週實驗投影片 | C35: https://tai-shengyeh.github.io/food-analysis-lab/labs/w01_volumetric/index.html
B36: Orange 流程檔 | C36: https://tai-shengyeh.github.io/food-analysis-lab/orange/OR01_intro_boxplot.ows
B37: 進階：Colab 筆記本（Python） | C37: https://colab.research.google.com/github/Tai-ShengYeh/food-analysis-lab/blob/main/notebooks/NB01_volumetric_calibration.ipynb
B38: 數據分析工具指南（Excel／Orange／Colab） | C38: https://tai-shengyeh.github.io/food-analysis-lab/tools.html
B40: 小提醒
B41: • Google 試算表也能開這個檔（檔案 → 匯入），公式都一樣能用。
B42: • Mac 版 Numbers 不支援部分函式，請用 Excel、Google 試算表或 LibreOffice。
B43: • 看到 #NAME? 表示 Excel 版本太舊（2007 以前），請改用 Google 試算表。

Sheet 1_原始數據
A1: group | B1: student | C1: item | D1: rep | E1: value | F1: unit | G1: temp_C | H1: note | I1: rho_w_g_mL | J1: buoyancy | K1: volume_mL | M1: 這張工作表怎麼用
A2: 1 | B2: G1_S1 | C2: pipette_10mL | D2: 1 | E2: 9.9608 | F2: g | G2: 24.2 | I2: =IF($A2="","",'2_密度換算'!$C$12*(1-((G2+'2_密度換算'!$C$8)^2*(G2+'2_密度換算'!$C$9))/('2_密度換算'!$C$10*(G2+'2_密度換算'!$C$11)))/1000) | J2: =IF($A2="","",1+'2_密度換算'!$C$6*(1/I2-1/'2_密度換算'!$C$7)) | K2: =IF($A2="","",E2*J2/I2) | M2: 本週欄位：item＝器具（pipette_10mL 移液管、burette_25mL 滴定管遞送 25.00 mL）；value＝秤到的水重 (g)；temp_C＝水溫。
A3: 1 | B3: G1_S1 | C3: burette_25mL | D3: 1 | E3: 24.9056 | F3: g | G3: 25.5 | I3: =IF($A3="","",'2_密度換算'!$C$12*(1-((G3+'2_密度換算'!$C$8)^2*(G3+'2_密度換算'!$C$9))/('2_密度換算'!$C$10*(G3+'2_密度換算'!$C$11)))/1000) | J3: =IF($A3="","",1+'2_密度換算'!$C$6*(1/I3-1/'2_密度換算'!$C$7)) | K3: =IF($A3="","",E3*J3/I3) | M3: 黃色欄位＝原始數據。換成全班數據時：從共用 Google Sheet 複製，貼到 A2（欄位順序必須一樣），舊資料多出來的列要整列刪除。
A4: 1 | B4: G1_S1 | C4: pipette_10mL | D4: 2 | E4: 9.9624 | F4: g | G4: 24.3 | I4: =IF($A4="","",'2_密度換算'!$C$12*(1-((G4+'2_密度換算'!$C$8)^2*(G4+'2_密度換算'!$C$9))/('2_密度換算'!$C$10*(G4+'2_密度換算'!$C$11)))/1000) | J4: =IF($A4="","",1+'2_密度換算'!$C$6*(1/I4-1/'2_密度換算'!$C$7)) | K4: =IF($A4="","",E4*J4/I4) | M4: 綠色欄位＝公式，會自動算到第 1000 列，不要手動修改。
A5: 1 | B5: G1_S1 | C5: burette_25mL | D5: 2 | E5: 24.9293 | F5: g | G5: 24.7 | I5: =IF($A5="","",'2_密度換算'!$C$12*(1-((G5+'2_密度換算'!$C$8)^2*(G5+'2_密度換算'!$C$9))/('2_密度換算'!$C$10*(G5+'2_密度換算'!$C$11)))/1000) | J5: =IF($A5="","",1+'2_密度換算'!$C$6*(1/I5-1/'2_密度換算'!$C$7)) | K5: =IF($A5="","",E5*J5/I5) | M5: 「rho_w_g_mL」：用 temp_C 算出的水密度（參數在「2_密度換算」）。
A6: 1 | B6: G1_S1 | C6: pipette_10mL | D6: 3 | E6: 9.9684 | F6: g | G6: 25.3 | I6: =IF($A6="","",'2_密度換算'!$C$12*(1-((G6+'2_密度換算'!$C$8)^2*(G6+'2_密度換算'!$C$9))/('2_密度換算'!$C$10*(G6+'2_密度換算'!$C$11)))/1000) | J6: =IF($A6="","",1+'2_密度換算'!$C$6*(1/I6-1/'2_密度換算'!$C$7)) | K6: =IF($A6="","",E6*J6/I6) | M6: 「buoyancy」：空氣浮力校正因子。
A7: 1 | B7: G1_S1 | C7: burette_25mL | D7: 3 | E7: 24.9003 | F7: g | G7: 24.9 | I7: =IF($A7="","",'2_密度換算'!$C$12*(1-((G7+'2_密度換算'!$C$8)^2*(G7+'2_密度換算'!$C$9))/('2_密度換算'!$C$10*(G7+'2_密度換算'!$C$11)))/1000) | J7: =IF($A7="","",1+'2_密度換算'!$C$6*(1/I7-1/'2_密度換算'!$C$7)) | K7: =IF($A7="","",E7*J7/I7) | M7: 「volume_mL」：真實體積 = value × 浮力因子 ÷ 密度。
A8: 1 | B8: G1_S1 | C8: pipette_10mL | D8: 4 | E8: 9.96 | F8: g | G8: 25.1 | I8: =IF($A8="","",'2_密度換算'!$C$12*(1-((G8+'2_密度換算'!$C$8)^2*(G8+'2_密度換算'!$C$9))/('2_密度換算'!$C$10*(G8+'2_密度換算'!$C$11)))/1000) | J8: =IF($A8="","",1+'2_密度換算'!$C$6*(1/I8-1/'2_密度換算'!$C$7)) | K8: =IF($A8="","",E8*J8/I8)
A9: 1 | B9: G1_S1 | C9: burette_25mL | D9: 4 | E9: 24.9088 | F9: g | G9: 25.7 | I9: =IF($A9="","",'2_密度換算'!$C$12*(1-((G9+'2_密度換算'!$C$8)^2*(G9+'2_密度換算'!$C$9))/('2_密度換算'!$C$10*(G9+'2_密度換算'!$C$11)))/1000) | J9: =IF($A9="","",1+'2_密度換算'!$C$6*(1/I9-1/'2_密度換算'!$C$7)) | K9: =IF($A9="","",E9*J9/I9)
A10: 1 | B10: G1_S1 | C10: pipette_10mL | D10: 5 | E10: 9.9601 | F10: g | G10: 25.5 | I10: =IF($A10="","",'2_密度換算'!$C$12*(1-((G10+'2_密度換算'!$C$8)^2*(G10+'2_密度換算'!$C$9))/('2_密度換算'!$C$10*(G10+'2_密度換算'!$C$11)))/1000) | J10: =IF($A10="","",1+'2_密度換算'!$C$6*(1/I10-1/'2_密度換算'!$C$7)) | K10: =IF($A10="","",E10*J10/I10)
A11: 1 | B11: G1_S1 | C11: burette_25mL | D11: 5 | E11: 24.9057 | F11: g | G11: 25.9 | I11: =IF($A11="","",'2_密度換算'!$C$12*(1-((G11+'2_密度換算'!$C$8)^2*(G11+'2_密度換算'!$C$9))/('2_密度換算'!$C$10*(G11+'2_密度換算'!$C$11)))/1000) | J11: =IF($A11="","",1+'2_密度換算'!$C$6*(1/I11-1/'2_密度換算'!$C$7)) | K11: =IF($A11="","",E11*J11/I11)
A12: 1 | B12: G1_S1 | C12: pipette_10mL | D12: 6 | E12: 9.9613 | F12: g | G12: 25.6 | I12: =IF($A12="","",'2_密度換算'!$C$12*(1-((G12+'2_密度換算'!$C$8)^2*(G12+'2_密度換算'!$C$9))/('2_密度換算'!$C$10*(G12+'2_密度換算'!$C$11)))/1000) | J12: =IF($A12="","",1+'2_密度換算'!$C$6*(1/I12-1/'2_密度換算'!$C$7)) | K12: =IF($A12="","",E12*J12/I12)
A13: 1 | B13: G1_S1 | C13: burette_25mL | D13: 6 | E13: 24.921 | F13: g | G13: 24.9 | I13: =IF($A13="","",'2_密度換算'!$C$12*(1-((G13+'2_密度換算'!$C$8)^2*(G13+'2_密度換算'!$C$9))/('2_密度換算'!$C$10*(G13+'2_密度換算'!$C$11)))/1000) | J13: =IF($A13="","",1+'2_密度換算'!$C$6*(1/I13-1/'2_密度換算'!$C$7)) | K13: =IF($A13="","",E13*J13/I13)
A14: 1 | B14: G1_S1 | C14: pipette_10mL | D14: 7 | E14: 9.968 | F14: g | G14: 24.3 | I14: =IF($A14="","",'2_密度換算'!$C$12*(1-((G14+'2_密度換算'!$C$8)^2*(G14+'2_密度換算'!$C$9))/('2_密度換算'!$C$10*(G14+'2_密度換算'!$C$11)))/1000) | J14: =IF($A14="","",1+'2_密度換算'!$C$6*(1/I14-1/'2_密度換算'!$C$7)) | K14: =IF($A14="","",E14*J14/I14)
A15: 1 | B15: G1_S1 | C15: burette_25mL | D15: 7 | E15: 24.9041 | F15: g | G15: 25.5 | I15: =IF($A15="","",'2_密度換算'!$C$12*(1-((G15+'2_密度換算'!$C$8)^2*(G15+'2_密度換算'!$C$9))/('2_密度換算'!$C$10*(G15+'2_密度換算'!$C$11)))/1000) | J15: =IF($A15="","",1+'2_密度換算'!$C$6*(1/I15-1/'2_密度換算'!$C$7)) | K15: =IF($A15="","",E15*J15/I15)
A16: 1 | B16: G1_S1 | C16: pipette_10mL | D16: 8 | E16: 9.9616 | F16: g | G16: 24.7 | I16: =IF($A16="","",'2_密度換算'!$C$12*(1-((G16+'2_密度換算'!$C$8)^2*(G16+'2_密度換算'!$C$9))/('2_密度換算'!$C$10*(G16+'2_密度換算'!$C$11)))/1000) | J16: =IF($A16="","",1+'2_密度換算'!$C$6*(1/I16-1/'2_密度換算'!$C$7)) | K16: =IF($A16="","",E16*J16/I16)
A17: 1 | B17: G1_S1 | C17: burette_25mL | D17: 8 | E17: 24.934 | F17: g | G17: 24.9 | I17: =IF($A17="","",'2_密度換算'!$C$12*(1-((G17+'2_密度換算'!$C$8)^2*(G17+'2_密度換算'!$C$9))/('2_密度換算'!$C$10*(G17+'2_密度換算'!$C$11)))/1000) | J17: =IF($A17="","",1+'2_密度換算'!$C$6*(1/I17-1/'2_密度換算'!$C$7)) | K17: =IF($A17="","",E17*J17/I17)
A18: 1 | B18: G1_S1 | C18: pipette_10mL | D18: 9 | E18: 9.9625 | F18: g | G18: 24.3 | I18: =IF($A18="","",'2_密度換算'!$C$12*(1-((G18+'2_密度換算'!$C$8)^2*(G18+'2_密度換算'!$C$9))/('2_密度換算'!$C$10*(G18+'2_密度換算'!$C$11)))/1000) | J18: =IF($A18="","",1+'2_密度換算'!$C$6*(1/I18-1/'2_密度換算'!$C$7)) | K18: =IF($A18="","",E18*J18/I18)
A19: 1 | B19: G1_S1 | C19: burette_25mL | D19: 9 | E19: 24.9284 | F19: g | G19: 24.5 | I19: =IF($A19="","",'2_密度換算'!$C$12*(1-((G19+'2_密度換算'!$C$8)^2*(G19+'2_密度換算'!$C$9))/('2_密度換算'!$C$10*(G19+'2_密度換算'!$C$11)))/1000) | J19: =IF($A19="","",1+'2_密度換算'!$C$6*(1/I19-1/'2_密度換算'!$C$7)) | K19: =IF($A19="","",E19*J19/I19)
... A49: 1 | B49: G1_S3 | C49: burette_25mL | D49: 4 | E49: 24.8982 | F49: g | G49: 24.2 | I49: =IF($A49="","",'2_密度換算'!$C$12*(1-((G49+'2_密度換算'!$C$8)^2*(G49+'2_密度換算'!$C$9))/('2_密度換算'!$C$10*(G49+'2_密度換算'!$C$11)))/1000) | J49: =IF($A49="","",1+'2_密度換算'!$C$6*(1/I49-1/'2_密度換算'!$C$7)) | K49: =IF($A49="","",E49*J49/I49)
A50: 1 | B50: G1_S3 | C50: pipette_10mL | D50: 5 | E50: 9.089 | F50: g | G50: 24.9 | H50: possible data-entry error (數據疑似誤植) | I50: =IF($A50="","",'2_密度換算'!$C$12*(1-((G50+'2_密度換算'!$C$8)^2*(G50+'2_密度換算'!$C$9))/('2_密度換算'!$C$10*(G50+'2_密度換算'!$C$11)))/1000) | J50: =IF($A50="","",1+'2_密度換算'!$C$6*(1/I50-1/'2_密度換算'!$C$7)) | K50: =IF($A50="","",E50*J50/I50)
A51: 1 | B51: G1_S3 | C51: burette_25mL | D51: 5 | E51: 24.9036 | F51: g | G51: 24.6 | I51: =IF($A51="","",'2_密度換算'!$C$12*(1-((G51+'2_密度換算'!$C$8)^2*(G51+'2_密度換算'!$C$9))/('2_密度換算'!$C$10*(G51+'2_密度換算'!$C$11)))/1000) | J51: =IF($A51="","",1+'2_密度換算'!$C$6*(1/I51-1/'2_密度換算'!$C$7)) | K51: =IF($A51="","",E51*J51/I51)
A52: 1 | B52: G1_S3 | C52: pipette_10mL | D52: 6 | E52: 9.9486 | F52: g | G52: 24.4 | I52: =IF($A52="","",'2_密度換算'!$C$12*(1-((G52+'2_密度換算'!$C$8)^2*(G52+'2_密度換算'!$C$9))/('2_密度換算'!$C$10*(G52+'2_密度換算'!$C$11)))/1000) | J52: =IF($A52="","",1+'2_密度換算'!$C$6*(1/I52-1/'2_密度換算'!$C$7)) | K52: =IF($A52="","",E52*J52/I52)
A53: 1 | B53: G1_S3 | C53: burette_25mL | D53: 6 | E53: 24.8873 | F53: g | G53: 25.5 | I53: =IF($A53="","",'2_密度換算'!$C$12*(1-((G53+'2_密度換算'!$C$8)^2*(G53+'2_密度換算'!$C$9))/('2_密度換算'!$C$10*(G53+'2_密度換算'!$C$11)))/1000) | J53: =IF($A53="","",1+'2_密度換算'!$C$6*(1/I53-1/'2_密度換算'!$C$7)) | K53: =IF($A53="","",E53*J53/I53)
A54: 1 | B54: G1_S3 | C54: pipette_10mL | D54: 7 | E54: 9.9548 | F54: g | G54: 24.9 | I54: =IF($A54="","",'2_密度換算'!$C$12*(1-((G54+'2_密度換算'!$C$8)^2*(G54+'2_密度換算'!$C$9))/('2_密度換算'!$C$10*(G54+'2_密度換算'!$C$11)))/1000) | J54: =IF($A54="","",1+'2_密度換算'!$C$6*(1/I54-1/'2_密度換算'!$C$7)) | K54: =IF($A54="","",E54*J54/I54)
A55: 1 | B55: G1_S3 | C55: burette_25mL | D55: 7 | E55: 24.8932 | F55: g | G55: 25.2 | I55: =IF($A55="","",'2_密度換算'!$C$12*(1-((G55+'2_密度換算'!$C$8)^2*(G55+'2_密度換算'!$C$9))/('2_密度換算'!$C$10*(G55+'2_密度換算'!$C$11)))/1000) | J55: =IF($A55="","",1+'2_密度換算'!$C$6*(1/I55-1/'2_密度換算'!$C$7)) | K55: =IF($A55="","",E55*J55/I55)
A56: 1 | B56: G1_S3 | C56: pipette_10mL | D56: 8 | E56: 9.9574 | F56: g | G56: 24.2 | I56: =IF($A56="","",'2_密度換算'!$C$12*(1-((G56+'2_密度換算'!$C$8)^2*(G56+'2_密度換算'!$C$9))/('2_密度換算'!$C$10*(G56+'2_密度換算'!$C$11)))/1000) | J56: =IF($A56="","",1+'2_密度換算'!$C$6*(1/I56-1/'2_密度換算'!$C$7)) | K56: =IF($A56="","",E56*J56/I56)
A57: 1 | B57: G1_S3 | C57: burette_25mL | D57: 8 | E57: 24.9222 | F57: g | G57: 24.1 | I57: =IF($A57="","",'2_密度換算'!$C$12*(1-((G57+'2_密度換算'!$C$8)^2*(G57+'2_密度換算'!$C$9))/('2_密度換算'!$C$10*(G57+'2_密度換算'!$C$11)))/1000) | J57: =IF($A57="","",1+'2_密度換算'!$C$6*(1/I57-1/'2_密度換算'!$C$7)) | K57: =IF($A57="","",E57*J57/I57)
A58: 1 | B58: G1_S3 | C58: pipette_10mL | D58: 9 | E58: 9.957 | F58: g | G58: 24.7 | I58: =IF($A58="","",'2_密度換算'!$C$12*(1-((G58+'2_密度換算'!$C$8)^2*(G58+'2_密度換算'!$C$9))/('2_密度換算'!$C$10*(G58+'2_密度換算'!$C$11)))/1000) | J58: =IF($A58="","",1+'2_密度換算'!$C$6*(1/I58-1/'2_密度換算'!$C$7)) | K58: =IF($A58="","",E58*J58/I58)
A59: 1 | B59: G1_S3 | C59: burette_25mL | D59: 9 | E59: 24.8865 | F59: g | G59: 24.2 | I59: =IF($A59="","",'2_密度換算'!$C$12*(1-((G59+'2_密度換算'!$C$8)^2*(G59+'2_密度換算'!$C$9))/('2_密度換算'!$C$10*(G59+'2_密度換算'!$C$11)))/1000) | J59: =IF($A59="","",1+'2_密度換算'!$C$6*(1/I59-1/'2_密度換算'!$C$7)) | K59: =IF($A59="","",E59*J59/I59)
A60: 1 | B60: G1_S3 | C60: pipette_10mL | D60: 10 | E60: 9.9515 | F60: g | G60: 24.3 | I60: =IF($A60="","",'2_密度換算'!$C$12*(1-((G60+'2_密度換算'!$C$8)^2*(G60+'2_密度換算'!$C$9))/('2_密度換算'!$C$10*(G60+'2_密度換算'!$C$11)))/1000) | J60: =IF($A60="","",1+'2_密度換算'!$C$6*(1/I60-1/'2_密度換算'!$C$7)) | K60: =IF($A60="","",E60*J60/I60)
A61: 1 | B61: G1_S3 | C61: burette_25mL | D61: 10 | E61: 24.8776 | F61: g | G61: 25.2 | I61: =IF($A61="","",'2_密度換算'!$C$12*(1-((G61+'2_密度換算'!$C$8)^2*(G61+'2_密度換算'!$C$9))/('2_密度換算'!$C$10*(G61+'2_密度換算'!$C$11)))/1000) | J61: =IF($A61="","",1+'2_密度換算'!$C$6*(1/I61-1/'2_密度換算'!$C$7)) | K61: =IF($A61="","",E61*J61/I61)
A62: 2 | B62: G2_S1 | C62: pipette_10mL | D62: 1 | E62: 9.9624 | F62: g | G62: 25.6 | I62: =IF($A62="","",'2_密度換算'!$C$12*(1-((G62+'2_密度換算'!$C$8)^2*(G62+'2_密度換算'!$C$9))/('2_密度換算'!$C$10*(G62+'2_密度換算'!$C$11)))/1000) | J62: =IF($A62="","",1+'2_密度換算'!$C$6*(1/I62-1/'2_密度換算'!$C$7)) | K62: =IF($A62="","",E62*J62/I62)
... A301: 5 | B301: G5_S3 | C301: burette_25mL | D301: 10 | E301: 24.9299 | F301: g | G301: 25.6 | I301: =IF($A301="","",'2_密度換算'!$C$12*(1-((G301+'2_密度換算'!$C$8)^2*(G301+'2_密度換算'!$C$9))/('2_密度換算'!$C$10*(G301+'2_密度換算'!$C$11)))/1000) | J301: =IF($A301="","",1+'2_密度換算'!$C$6*(1/I301-1/'2_密度換算'!$C$7)) | K301: =IF($A301="","",E301*J301/I301)
I302: =IF($A302="","",'2_密度換算'!$C$12*(1-((G302+'2_密度換算'!$C$8)^2*(G302+'2_密度換算'!$C$9))/('2_密度換算'!$C$10*(G302+'2_密度換算'!$C$11)))/1000) | J302: =IF($A302="","",1+'2_密度換算'!$C$6*(1/I302-1/'2_密度換算'!$C$7)) | K302: =IF($A302="","",E302*J302/I302)
I303: =IF($A303="","",'2_密度換算'!$C$12*(1-((G303+'2_密度換算'!$C$8)^2*(G303+'2_密度換算'!$C$9))/('2_密度換算'!$C$10*(G303+'2_密度換算'!$C$11)))/1000) | J303: =IF($A303="","",1+'2_密度換算'!$C$6*(1/I303-1/'2_密度換算'!$C$7)) | K303: =IF($A303="","",E303*J303/I303)
I304: =IF($A304="","",'2_密度換算'!$C$12*(1-((G304+'2_密度換算'!$C$8)^2*(G304+'2_密度換算'!$C$9))/('2_密度換算'!$C$10*(G304+'2_密度換算'!$C$11)))/1000) | J304: =IF($A304="","",1+'2_密度換算'!$C$6*(1/I304-1/'2_密度換算'!$C$7)) | K304: =IF($A304="","",E304*J304/I304)
I305: =IF($A305="","",'2_密度換算'!$C$12*(1-((G305+'2_密度換算'!$C$8)^2*(G305+'2_密度換算'!$C$9))/('2_密度換算'!$C$10*(G305+'2_密度換算'!$C$11)))/1000) | J305: =IF($A305="","",1+'2_密度換算'!$C$6*(1/I305-1/'2_密度換算'!$C$7)) | K305: =IF($A305="","",E305*J305/I305)
I306: =IF($A306="","",'2_密度換算'!$C$12*(1-((G306+'2_密度換算'!$C$8)^2*(G306+'2_密度換算'!$C$9))/('2_密度換算'!$C$10*(G306+'2_密度換算'!$C$11)))/1000) | J306: =IF($A306="","",1+'2_密度換算'!$C$6*(1/I306-1/'2_密度換算'!$C$7)) | K306: =IF($A306="","",E306*J306/I306)
I307: =IF($A307="","",'2_密度換算'!$C$12*(1-((G307+'2_密度換算'!$C$8)^2*(G307+'2_密度換算'!$C$9))/('2_密度換算'!$C$10*(G307+'2_密度換算'!$C$11)))/1000) | J307: =IF($A307="","",1+'2_密度換算'!$C$6*(1/I307-1/'2_密度換算'!$C$7)) | K307: =IF($A307="","",E307*J307/I307)
...

Sheet 2_密度換算
B1: 步驟 1 水的密度與空氣浮力校正
B2: 天平讀到的是「表觀質量」。先用水溫查水的密度，再做空氣浮力校正，才能換成真正的體積。
B4: 參數
B5: 參數 | C5: 數值 | D5: 單位
B6: 空氣密度 ρ_air | C6: 0.0012 | D6: g/mL | F6: ρ_air 與 ρ_weights 可以改（黃色），其他 Tanaka 係數請不要動。
B7: 砝碼密度 ρ_weights | C7: 8 | D7: g/mL
B8: Tanaka a1 | C8: -3.983035 | D8: °C
B9: Tanaka a2 | C9: 301.797 | D9: °C
B10: Tanaka a3 | C10: 522528.9 | D10: °C²
B11: Tanaka a4 | C11: 69.34881 | D11: °C
B12: Tanaka a5 | C12: 999.97495 | D12: kg/m³
B15: 公式
B16: 水的密度（Tanaka 2001） | C16: ρw = a5 × [1 − (t + a1)²(t + a2) / (a3 (t + a4))] ÷ 1000 （g/mL）
B17: 浮力校正因子 | C17: factor = 1 + ρ_air × (1/ρw − 1/ρ_weights) （約 1.00105）
B18: 真實體積 | C18: V = 表觀質量 × factor ÷ ρw
B20: 密度對照表（20–30 °C）
B21: 水溫 (°C) | C21: 密度 ρw (g/mL) | D21: 浮力因子 | E21: 1 °C 密度變化 (%)
B22: 20 | C22: ='2_密度換算'!$C$12*(1-((B22+'2_密度換算'!$C$8)^2*(B22+'2_密度換算'!$C$9))/('2_密度換算'!$C$10*(B22+'2_密度換算'!$C$11)))/1000 | D22: =1+'2_密度換算'!$C$6*(1/C22-1/'2_密度換算'!$C$7) | F22: 觀察：溫度每升高 1 °C，密度下降約 0.02–0.03%。水溫記錄錯誤會直接變成體積誤差。
B23: 21 | C23: ='2_密度換算'!$C$12*(1-((B23+'2_密度換算'!$C$8)^2*(B23+'2_密度換算'!$C$9))/('2_密度換算'!$C$10*(B23+'2_密度換算'!$C$11)))/1000 | D23: =1+'2_密度換算'!$C$6*(1/C23-1/'2_密度換算'!$C$7) | E23: =(C23-C22)/C22*100
B24: 22 | C24: ='2_密度換算'!$C$12*(1-((B24+'2_密度換算'!$C$8)^2*(B24+'2_密度換算'!$C$9))/('2_密度換算'!$C$10*(B24+'2_密度換算'!$C$11)))/1000 | D24: =1+'2_密度換算'!$C$6*(1/C24-1/'2_密度換算'!$C$7) | E24: =(C24-C23)/C23*100
B25: 23 | C25: ='2_密度換算'!$C$12*(1-((B25+'2_密度換算'!$C$8)^2*(B25+'2_密度換算'!$C$9))/('2_密度換算'!$C$10*(B25+'2_密度換算'!$C$11)))/1000 | D25: =1+'2_密度換算'!$C$6*(1/C25-1/'2_密度換算'!$C$7) | E25: =(C25-C24)/C24*100
B26: 24 | C26: ='2_密度換算'!$C$12*(1-((B26+'2_密度換算'!$C$8)^2*(B26+'2_密度換算'!$C$9))/('2_密度換算'!$C$10*(B26+'2_密度換算'!$C$11)))/1000 | D26: =1+'2_密度換算'!$C$6*(1/C26-1/'2_密度換算'!$C$7) | E26: =(C26-C25)/C25*100
B27: 25 | C27: ='2_密度換算'!$C$12*(1-((B27+'2_密度換算'!$C$8)^2*(B27+'2_密度換算'!$C$9))/('2_密度換算'!$C$10*(B27+'2_密度換算'!$C$11)))/1000 | D27: =1+'2_密度換算'!$C$6*(1/C27-1/'2_密度換算'!$C$7) | E27: =(C27-C26)/C26*100
B28: 26 | C28: ='2_密度換算'!$C$12*(1-((B28+'2_密度換算'!$C$8)^2*(B28+'2_密度換算'!$C$9))/('2_密度換算'!$C$10*(B28+'2_密度換算'!$C$11)))/1000 | D28: =1+'2_密度換算'!$C$6*(1/C28-1/'2_密度換算'!$C$7) | E28: =(C28-C27)/C27*100
B29: 27 | C29: ='2_密度換算'!$C$12*(1-((B29+'2_密度換算'!$C$8)^2*(B29+'2_密度換算'!$C$9))/('2_密度換算'!$C$10*(B29+'2_密度換算'!$C$11)))/1000 | D29: =1+'2_密度換算'!$C$6*(1/C29-1/'2_密度換算'!$C$7) | E29: =(C29-C28)/C28*100
B30: 28 | C30: ='2_密度換算'!$C$12*(1-((B30+'2_密度換算'!$C$8)^2*(B30+'2_密度換算'!$C$9))/('2_密度換算'!$C$10*(B30+'2_密度換算'!$C$11)))/1000 | D30: =1+'2_密度換算'!$C$6*(1/C30-1/'2_密度換算'!$C$7) | E30: =(C30-C29)/C29*100
B31: 29 | C31: ='2_密度換算'!$C$12*(1-((B31+'2_密度換算'!$C$8)^2*(B31+'2_密度換算'!$C$9))/('2_密度換算'!$C$10*(B31+'2_密度換算'!$C$11)))/1000 | D31: =1+'2_密度換算'!$C$6*(1/C31-1/'2_密度換算'!$C$7) | E31: =(C31-C30)/C30*100
B32: 30 | C32: ='2_密度換算'!$C$12*(1-((B32+'2_密度換算'!$C$8)^2*(B32+'2_密度換算'!$C$9))/('2_密度換算'!$C$10*(B32+'2_密度換算'!$C$11)))/1000 | D32: =1+'2_密度換算'!$C$6*(1/C32-1/'2_密度換算'!$C$7) | E32: =(C32-C31)/C31*100
B35: 自我檢查：9.9700 g、25 °C 的水是多少 mL？
B36: 表觀質量 (g) | C36: 9.97
B37: 水溫 (°C) | C37: 25
B38: ρw (g/mL) | C38: ='2_密度換算'!$C$12*(1-((C37+'2_密度換算'!$C$8)^2*(C37+'2_密度換算'!$C$9))/('2_密度換算'!$C$10*(C37+'2_密度換算'!$C$11)))/1000 | D38: 應約為 0.997047
B39: 浮力因子 | C39: =1+'2_密度換算'!$C$6*(1/C38-1/'2_密度換算'!$C$7) | D39: 應約為 1.00105
B40: 真實體積 (mL) | C40: =C36*C39/C38 | D40: 應接近 10.00 mL
B41: 與 10.00 mL 的差 (mL) | C41: =C40-10

Sheet 3_逐生統計
A1: 步驟 2 每位同學的平均、SD、RSD、95% 信賴區間與偏差
A2: 每一列是一位同學 × 一種器具。F–O 欄用 SUMIFS 從原始數據把 10 次重複的體積抓過來，後面的統計量都是一般 Excel 函式。換成班級數據時，只要改 A–C 欄（黃色）的組別、學生代號與器具。
AB3: 圖用輔助數據（公差線、精密度門檻線，自動計算）
A4: 組別 | B4: 學生 | C4: 器具 | D4: 標稱值 (mL) | E4: 公差 (mL) | F4: 第1次 | G4: 第2次 | H4: 第3次 | I4: 第4次 | J4: 第5次 | K4: 第6次 | L4: 第7次 | M4: 第8次 | N4: 第9次 | O4: 第10次 | P4: n | Q4: 平均 (mL) | R4: SD (mL) | S4: RSD (%) | T4: t 臨界值 | U4: 95% CI 半寬 | V4: 偏差 bias | W4: 準確？ | X4: 精密？ | Y4: 分類 | Z4: 報告寫法 | AB4: pip x | AC4: y | AE4: bur x | AF4: y
A5: 1 | B5: G1_S1 | C5: pipette_10mL | D5: =IF(C5="pipette_10mL",10,IF(C5="burette_25mL",25,"")) | E5: =IF(C5="pipette_10mL",0.02,IF(C5="burette_25mL",0.05,"")) | F5: =IF(COUNTIFS('1_原始數據'!$B$2:$B$1000,$B5,'1_原始數據'!$C$2:$C$1000,$C5,'1_原始數據'!$D$2:$D$1000,1)=0,"",SUMIFS('1_原始數據'!$K$2:$K$1000,'1_原始數據'!$B$2:$B$1000,$B5,'1_原始數據'!$C$2:$C$1000,$C5,'1_原始數據'!$D$2:$D$1000,1)) | G5: =IF(COUNTIFS('1_原始數據'!$B$2:$B$1000,$B5,'1_原始數據'!$C$2:$C$1000,$C5,'1_原始數據'!$D$2:$D$1000,2)=0,"",SUMIFS('1_原始數據'!$K$2:$K$1000,'1_原始數據'!$B$2:$B$1000,$B5,'1_原始數據'!$C$2:$C$1000,$C5,'1_原始數據'!$D$2:$D$1000,2)) | H5: =IF(COUNTIFS('1_原始數據'!$B$2:$B$1000,$B5,'1_原始數據'!$C$2:$C$1000,$C5,'1_原始數據'!$D$2:$D$1000,3)=0,"",SUMIFS('1_原始數據'!$K$2:$K$1000,'1_原始數據'!$B$2:$B$1000,$B5,'1_原始數據'!$C$2:$C$1000,$C5,'1_原始數據'!$D$2:$D$1000,3)) | I5: =IF(COUNTIFS('1_原始數據'!$B$2:$B$1000,$B5,'1_原始數據'!$C$2:$C$1000,$C5,'1_原始數據'!$D$2:$D$1000,4)=0,"",SUMIFS('1_原始數據'!$K$2:$K$1000,'1_原始數據'!$B$2:$B$1000,$B5,'1_原始數據'!$C$2:$C$1000,$C5,'1_原始數據'!$D$2:$D$1000,4)) | J5: =IF(COUNTIFS('1_原始數據'!$B$2:$B$1000,$B5,'1_原始數據'!$C$2:$C$1000,$C5,'1_原始數據'!$D$2:$D$1000,5)=0,"",SUMIFS('1_原始數據'!$K$2:$K$1000,'1_原始數據'!$B$2:$B$1000,$B5,'1_原始數據'!$C$2:$C$1000,$C5,'1_原始數據'!$D$2:$D$1000,5)) | K5: =IF(COUNTIFS('1_原始數據'!$B$2:$B$1000,$B5,'1_原始數據'!$C$2:$C$1000,$C5,'1_原始數據'!$D$2:$D$1000,6)=0,"",SUMIFS('1_原始數據'!$K$2:$K$1000,'1_原始數據'!$B$2:$B$1000,$B5,'1_原始數據'!$C$2:$C$1000,$C5,'1_原始數據'!$D$2:$D$1000,6)) | L5: =IF(COUNTIFS('1_原始數據'!$B$2:$B$1000,$B5,'1_原始數據'!$C$2:$C$1000,$C5,'1_原始數據'!$D$2:$D$1000,7)=0,"",SUMIFS('1_原始數據'!$K$2:$K$1000,'1_原始數據'!$B$2:$B$1000,$B5,'1_原始數據'!$C$2:$C$1000,$C5,'1_原始數據'!$D$2:$D$1000,7)) | M5: =IF(COUNTIFS('1_原始數據'!$B$2:$B$1000,$B5,'1_原始數據'!$C$2:$C$1000,$C5,'1_原始數據'!$D$2:$D$1000,8)=0,"",SUMIFS('1_原始數據'!$K$2:$K$1000,'1_原始數據'!$B$2:$B$1000,$B5,'1_原始數據'!$C$2:$C$1000,$C5,'1_原始數據'!$D$2:$D$1000,8)) | N5: =IF(COUNTIFS('1_原始數據'!$B$2:$B$1000,$B5,'1_原始數據'!$C$2:$C$1000,$C5,'1_原始數據'!$D$2:$D$1000,9)=0,"",SUMIFS('1_原始數據'!$K$2:$K$1000,'1_原始數據'!$B$2:$B$1000,$B5,'1_原始數據'!$C$2:$C$1000,$C5,'1_原始數據'!$D$2:$D$1000,9)) | O5: =IF(COUNTIFS('1_原始數據'!$B$2:$B$1000,$B5,'1_原始數據'!$C$2:$C$1000,$C5,'1_原始數據'!$D$2:$D$1000,10)=0,"",SUMIFS('1_原始數據'!$K$2:$K$1000,'1_原始數據'!$B$2:$B$1000,$B5,'1_原始數據'!$C$2:$C$1000,$C5,'1_原始數據'!$D$2:$D$1000,10)) | P5: =COUNT(F5:O5) | Q5: =AVERAGE(F5:O5) | R5: =_xlfn.STDEV.S(F5:O5) | S5: =R5/Q5*100 | T5: =_xlfn.T.INV.2T(0.05,P5-1) | U5: =T5*R5/SQRT(P5) | V5: =Q5-D5 | W5: =IF(ABS(V5)<=E5,"是","否") | X5: =IF(R5<=E5/2,"是","否") | Y5: =IF(W5="是",IF(X5="是","準確且精密","準確但不精密"),IF(X5="是","精密但不準確","不準確且不精密")) | Z5: =FIXED(Q5,MAX(0,1-INT(LOG10(ABS(U5)))))&" ± "&FIXED(U5,MAX(0,1-INT(LOG10(ABS(U5)))))&" mL" | AB5: =-E5 | AC5: =0 | AE5: =-E20 | AF5: =0
A6: 1 | B6: G1_S2 | C6: pipette_10mL | D6: =IF(C6="pipette_10mL",10,IF(C6="burette_25mL",25,"")) | E6: =IF(C6="pipette_10mL",0.02,IF(C6="burette_25mL",0.05,"")) | F6: =IF(COUNTIFS('1_原始數據'!$B$2:$B$1000,$B6,'1_原始數據'!$C$2:$C$1000,$C6,'1_原始數據'!$D$2:$D$1000,1)=0,"",SUMIFS('1_原始數據'!$K$2:$K$1000,'1_原始數據'!$B$2:$B$1000,$B6,'1_原始數據'!$C$2:$C$1000,$C6,'1_原始數據'!$D$2:$D$1000,1)) | G6: =IF(COUNTIFS('1_原始數據'!$B$2:$B$1000,$B6,'1_原始數據'!$C$2:$C$1000,$C6,'1_原始數據'!$D$2:$D$1000,2)=0,"",SUMIFS('1_原始數據'!$K$2:$K$1000,'1_原始數據'!$B$2:$B$1000,$B6,'1_原始數據'!$C$2:$C$1000,$C6,'1_原始數據'!$D$2:$D$1000,2)) | H6: =IF(COUNTIFS('1_原始數據'!$B$2:$B$1000,$B6,'1_原始數據'!$C$2:$C$1000,$C6,'1_原始數據'!$D$2:$D$1000,3)=0,"",SUMIFS('1_原始數據'!$K$2:$K$1000,'1_原始數據'!$B$2:$B$1000,$B6,'1_原始數據'!$C$2:$C$1000,$C6,'1_原始數據'!$D$2:$D$1000,3)) | I6: =IF(COUNTIFS('1_原始數據'!$B$2:$B$1000,$B6,'1_原始數據'!$C$2:$C$1000,$C6,'1_原始數據'!$D$2:$D$1000,4)=0,"",SUMIFS('1_原始數據'!$K$2:$K$1000,'1_原始數據'!$B$2:$B$1000,$B6,'1_原始數據'!$C$2:$C$1000,$C6,'1_原始數據'!$D$2:$D$1000,4)) | J6: =IF(COUNTIFS('1_原始數據'!$B$2:$B$1000,$B6,'1_原始數據'!$C$2:$C$1000,$C6,'1_原始數據'!$D$2:$D$1000,5)=0,"",SUMIFS('1_原始數據'!$K$2:$K$1000,'1_原始數據'!$B$2:$B$1000,$B6,'1_原始數據'!$C$2:$C$1000,$C6,'1_原始數據'!$D$2:$D$1000,5)) | K6: =IF(COUNTIFS('1_原始數據'!$B$2:$B$1000,$B6,'1_原始數據'!$C$2:$C$1000,$C6,'1_原始數據'!$D$2:$D$1000,6)=0,"",SUMIFS('1_原始數據'!$K$2:$K$1000,'1_原始數據'!$B$2:$B$1000,$B6,'1_原始數據'!$C$2:$C$1000,$C6,'1_原始數據'!$D$2:$D$1000,6)) | L6: =IF(COUNTIFS('1_原始數據'!$B$2:$B$1000,$B6,'1_原始數據'!$C$2:$C$1000,$C6,'1_原始數據'!$D$2:$D$1000,7)=0,"",SUMIFS('1_原始數據'!$K$2:$K$1000,'1_原始數據'!$B$2:$B$1000,$B6,'1_原始數據'!$C$2:$C$1000,$C6,'1_原始數據'!$D$2:$D$1000,7)) | M6: =IF(COUNTIFS('1_原始數據'!$B$2:$B$1000,$B6,'1_原始數據'!$C$2:$C$1000,$C6,'1_原始數據'!$D$2:$D$1000,8)=0,"",SUMIFS('1_原始數據'!$K$2:$K$1000,'1_原始數據'!$B$2:$B$1000,$B6,'1_原始數據'!$C$2:$C$1000,$C6,'1_原始數據'!$D$2:$D$1000,8)) | N6: =IF(COUNTIFS('1_原始數據'!$B$2:$B$1000,$B6,'1_原始數據'!$C$2:$C$1000,$C6,'1_原始數據'!$D$2:$D$1000,9)=0,"",SUMIFS('1_原始數據'!$K$2:$K$1000,'1_原始數據'!$B$2:$B$1000,$B6,'1_原始數據'!$C$2:$C$1000,$C6,'1_原始數據'!$D$2:$D$1000,9)) | O6: =IF(COUNTIFS('1_原始數據'!$B$2:$B$1000,$B6,'1_原始數據'!$C$2:$C$1000,$C6,'1_原始數據'!$D$2:$D$1000,10)=0,"",SUMIFS('1_原始數據'!$K$2:$K$1000,'1_原始數據'!$B$2:$B$1000,$B6,'1_原始數據'!$C$2:$C$1000,$C6,'1_原始數據'!$D$2:$D$1000,10)) | P6: =COUNT(F6:O6) | Q6: =AVERAGE(F6:O6) | R6: =_xlfn.STDEV.S(F6:O6) | S6: =R6/Q6*100 | T6: =_xlfn.T.INV.2T(0.05,P6-1) | U6: =T6*R6/SQRT(P6) | V6: =Q6-D6 | W6: =IF(ABS(V6)<=E6,"是","否") | X6: =IF(R6<=E6/2,"是","否") | Y6: =IF(W6="是",IF(X6="是","準確且精密","準確但不精密"),IF(X6="是","精密但不準確","不準確且不精密")) | Z6: =FIXED(Q6,MAX(0,1-INT(LOG10(ABS(U6)))))&" ± "&FIXED(U6,MAX(0,1-INT(LOG10(ABS(U6)))))&" mL" | AB6: =-E5 | AC6: =MAX(E5,MAX(R5:R19)*1.1) | AE6: =-E20 | AF6: =MAX(E20,MAX(R20:R34)*1.1)
A7: 1 | B7: G1_S3 | C7: pipette_10mL | D7: =IF(C7="pipette_10mL",10,IF(C7="burette_25mL",25,"")) | E7: =IF(C7="pipette_10mL",0.02,IF(C7="burette_25mL",0.05,"")) | F7: =IF(COUNTIFS('1_原始數據'!$B$2:$B$1000,$B7,'1_原始數據'!$C$2:$C$1000,$C7,'1_原始數據'!$D$2:$D$1000,1)=0,"",SUMIFS('1_原始數據'!$K$2:$K$1000,'1_原始數據'!$B$2:$B$1000,$B7,'1_原始數據'!$C$2:$C$1000,$C7,'1_原始數據'!$D$2:$D$1000,1)) | G7: =IF(COUNTIFS('1_原始數據'!$B$2:$B$1000,$B7,'1_原始數據'!$C$2:$C$1000,$C7,'1_原始數據'!$D$2:$D$1000,2)=0,"",SUMIFS('1_原始數據'!$K$2:$K$1000,'1_原始數據'!$B$2:$B$1000,$B7,'1_原始數據'!$C$2:$C$1000,$C7,'1_原始數據'!$D$2:$D$1000,2)) | H7: =IF(COUNTIFS('1_原始數據'!$B$2:$B$1000,$B7,'1_原始數據'!$C$2:$C$1000,$C7,'1_原始數據'!$D$2:$D$1000,3)=0,"",SUMIFS('1_原始數據'!$K$2:$K$1000,'1_原始數據'!$B$2:$B$1000,$B7,'1_原始數據'!$C$2:$C$1000,$C7,'1_原始數據'!$D$2:$D$1000,3)) | I7: =IF(COUNTIFS('1_原始數據'!$B$2:$B$1000,$B7,'1_原始數據'!$C$2:$C$1000,$C7,'1_原始數據'!$D$2:$D$1000,4)=0,"",SUMIFS('1_原始數據'!$K$2:$K$1000,'1_原始數據'!$B$2:$B$1000,$B7,'1_原始數據'!$C$2:$C$1000,$C7,'1_原始數據'!$D$2:$D$1000,4)) | J7: =IF(COUNTIFS('1_原始數據'!$B$2:$B$1000,$B7,'1_原始數據'!$C$2:$C$1000,$C7,'1_原始數據'!$D$2:$D$1000,5)=0,"",SUMIFS('1_原始數據'!$K$2:$K$1000,'1_原始數據'!$B$2:$B$1000,$B7,'1_原始數據'!$C$2:$C$1000,$C7,'1_原始數據'!$D$2:$D$1000,5)) | K7: =IF(COUNTIFS('1_原始數據'!$B$2:$B$1000,$B7,'1_原始數據'!$C$2:$C$1000,$C7,'1_原始數據'!$D$2:$D$1000,6)=0,"",SUMIFS('1_原始數據'!$K$2:$K$1000,'1_原始數據'!$B$2:$B$1000,$B7,'1_原始數據'!$C$2:$C$1000,$C7,'1_原始數據'!$D$2:$D$1000,6)) | L7: =IF(COUNTIFS('1_原始數據'!$B$2:$B$1000,$B7,'1_原始數據'!$C$2:$C$1000,$C7,'1_原始數據'!$D$2:$D$1000,7)=0,"",SUMIFS('1_原始數據'!$K$2:$K$1000,'1_原始數據'!$B$2:$B$1000,$B7,'1_原始數據'!$C$2:$C$1000,$C7,'1_原始數據'!$D$2:$D$1000,7)) | M7: =IF(COUNTIFS('1_原始數據'!$B$2:$B$1000,$B7,'1_原始數據'!$C$2:$C$1000,$C7,'1_原始數據'!$D$2:$D$1000,8)=0,"",SUMIFS('1_原始數據'!$K$2:$K$1000,'1_原始數據'!$B$2:$B$1000,$B7,'1_原始數據'!$C$2:$C$1000,$C7,'1_原始數據'!$D$2:$D$1000,8)) | N7: =IF(COUNTIFS('1_原始數據'!$B$2:$B$1000,$B7,'1_原始數據'!$C$2:$C$1000,$C7,'1_原始數據'!$D$2:$D$1000,9)=0,"",SUMIFS('1_原始數據'!$K$2:$K$1000,'1_原始數據'!$B$2:$B$1000,$B7,'1_原始數據'!$C$2:$C$1000,$C7,'1_原始數據'!$D$2:$D$1000,9)) | O7: =IF(COUNTIFS('1_原始數據'!$B$2:$B$1000,$B7,'1_原始數據'!$C$2:$C$1000,$C7,'1_原始數據'!$D$2:$D$1000,10)=0,"",SUMIFS('1_原始數據'!$K$2:$K$1000,'1_原始數據'!$B$2:$B$1000,$B7,'1_原始數據'!$C$2:$C$1000,$C7,'1_原始數據'!$D$2:$D$1000,10)) | P7: =COUNT(F7:O7) | Q7: =AVERAGE(F7:O7) | R7: =_xlfn.STDEV.S(F7:O7) | S7: =R7/Q7*100 | T7: =_xlfn.T.INV.2T(0.05,P7-1) | U7: =T7*R7/SQRT(P7) | V7: =Q7-D7 | W7: =IF(ABS(V7)<=E7,"是","否") | X7: =IF(R7<=E7/2,"是","否") | Y7: =IF(W7="是",IF(X7="是","準確且精密","準確但不精密"),IF(X7="是","精密但不準確","不準確且不精密")) | Z7: =FIXED(Q7,MAX(0,1-INT(LOG10(ABS(U7)))))&" ± "&FIXED(U7,MAX(0,1-INT(LOG10(ABS(U7)))))&" mL" | AB7: =E5 | AC7: =0 | AE7: =E20 | AF7: =0
A8: 2 | B8: G2_S1 | C8: pipette_10mL | D8: =IF(C8="pipette_10mL",10,IF(C8="burette_25mL",25,"")) | E8: =IF(C8="pipette_10mL",0.02,IF(C8="burette_25mL",0.05,"")) | F8: =IF(COUNTIFS('1_原始數據'!$B$2:$B$1000,$B8,'1_原始數據'!$C$2:$C$1000,$C8,'1_原始數據'!$D$2:$D$1000,1)=0,"",SUMIFS('1_原始數據'!$K$2:$K$1000,'1_原始數據'!$B$2:$B$1000,$B8,'1_原始數據'!$C$2:$C$1000,$C8,'1_原始數據'!$D$2:$D$1000,1)) | G8: =IF(COUNTIFS('1_原始數據'!$B$2:$B$1000,$B8,'1_原始數據'!$C$2:$C$1000,$C8,'1_原始數據'!$D$2:$D$1000,2)=0,"",SUMIFS('1_原始數據'!$K$2:$K$1000,'1_原始數據'!$B$2:$B$1000,$B8,'1_原始數據'!$C$2:$C$1000,$C8,'1_原始數據'!$D$2:$D$1000,2)) | H8: =IF(COUNTIFS('1_原始數據'!$B$2:$B$1000,$B8,'1_原始數據'!$C$2:$C$1000,$C8,'1_原始數據'!$D$2:$D$1000,3)=0,"",SUMIFS('1_原始數據'!$K$2:$K$1000,'1_原始數據'!$B$2:$B$1000,$B8,'1_原始數據'!$C$2:$C$1000,$C8,'1_原始數據'!$D$2:$D$1000,3)) | I8: =IF(COUNTIFS('1_原始數據'!$B$2:$B$1000,$B8,'1_原始數據'!$C$2:$C$1000,$C8,'1_原始數據'!$D$2:$D$1000,4)=0,"",SUMIFS('1_原始數據'!$K$2:$K$1000,'1_原始數據'!$B$2:$B$1000,$B8,'1_原始數據'!$C$2:$C$1000,$C8,'1_原始數據'!$D$2:$D$1000,4)) | J8: =IF(COUNTIFS('1_原始數據'!$B$2:$B$1000,$B8,'1_原始數據'!$C$2:$C$1000,$C8,'1_原始數據'!$D$2:$D$1000,5)=0,"",SUMIFS('1_原始數據'!$K$2:$K$1000,'1_原始數據'!$B$2:$B$1000,$B8,'1_原始數據'!$C$2:$C$1000,$C8,'1_原始數據'!$D$2:$D$1000,5)) | K8: =IF(COUNTIFS('1_原始數據'!$B$2:$B$1000,$B8,'1_原始數據'!$C$2:$C$1000,$C8,'1_原始數據'!$D$2:$D$1000,6)=0,"",SUMIFS('1_原始數據'!$K$2:$K$1000,'1_原始數據'!$B$2:$B$1000,$B8,'1_原始數據'!$C$2:$C$1000,$C8,'1_原始數據'!$D$2:$D$1000,6)) | L8: =IF(COUNTIFS('1_原始數據'!$B$2:$B$1000,$B8,'1_原始數據'!$C$2:$C$1000,$C8,'1_原始數據'!$D$2:$D$1000,7)=0,"",SUMIFS('1_原始數據'!$K$2:$K$1000,'1_原始數據'!$B$2:$B$1000,$B8,'1_原始數據'!$C$2:$C$1000,$C8,'1_原始數據'!$D$2:$D$1000,7)) | M8: =IF(COUNTIFS('1_原始數據'!$B$2:$B$1000,$B8,'1_原始數據'!$C$2:$C$1000,$C8,'1_原始數據'!$D$2:$D$1000,8)=0,"",SUMIFS('1_原始數據'!$K$2:$K$1000,'1_原始數據'!$B$2:$B$1000,$B8,'1_原始數據'!$C$2:$C$1000,$C8,'1_原始數據'!$D$2:$D$1000,8)) | N8: =IF(COUNTIFS('1_原始數據'!$B$2:$B$1000,$B8,'1_原始數據'!$C$2:$C$1000,$C8,'1_原始數據'!$D$2:$D$1000,9)=0,"",SUMIFS('1_原始數據'!$K$2:$K$1000,'1_原始數據'!$B$2:$B$1000,$B8,'1_原始數據'!$C$2:$C$1000,$C8,'1_原始數據'!$D$2:$D$1000,9)) | O8: =IF(COUNTIFS('1_原始數據'!$B$2:$B$1000,$B8,'1_原始數據'!$C$2:$C$1000,$C8,'1_原始數據'!$D$2:$D$1000,10)=0,"",SUMIFS('1_原始數據'!$K$2:$K$1000,'1_原始數據'!$B$2:$B$1000,$B8,'1_原始數據'!$C$2:$C$1000,$C8,'1_原始數據'!$D$2:$D$1000,10)) | P8: =COUNT(F8:O8) | Q8: =AVERAGE(F8:O8) | R8: =_xlfn.STDEV.S(F8:O8) | S8: =R8/Q8*100 | T8: =_xlfn.T.INV.2T(0.05,P8-1) | U8: =T8*R8/SQRT(P8) | V8: =Q8-D8 | W8: =IF(ABS(V8)<=E8,"是","否") | X8: =IF(R8<=E8/2,"是","否") | Y8: =IF(W8="是",IF(X8="是","準確且精密","準確但不精密"),IF(X8="是","精密但不準確","不準確且不精密")) | Z8: =FIXED(Q8,MAX(0,1-INT(LOG10(ABS(U8)))))&" ± "&FIXED(U8,MAX(0,1-INT(LOG10(ABS(U8)))))&" mL" | AB8: =E5 | AC8: =MAX(E5,MAX(R5:R19)*1.1) | AE8: =E20 | AF8: =MAX(E20,MAX(R20:R34)*1.1)
A9: 2 | B9: G2_S2 | C9: pipette_10mL | D9: =IF(C9="pipette_10mL",10,IF(C9="burette_25mL",25,"")) | E9: =IF(C9="pipette_10mL",0.02,IF(C9="burette_25mL",0.05,"")) | F9: =IF(COUNTIFS('1_原始數據'!$B$2:$B$1000,$B9,'1_原始數據'!$C$2:$C$1000,$C9,'1_原始數據'!$D$2:$D$1000,1)=0,"",SUMIFS('1_原始數據'!$K$2:$K$1000,'1_原始數據'!$B$2:$B$1000,$B9,'1_原始數據'!$C$2:$C$1000,$C9,'1_原始數據'!$D$2:$D$1000,1)) | G9: =IF(COUNTIFS('1_原始數據'!$B$2:$B$1000,$B9,'1_原始數據'!$C$2:$C$1000,$C9,'1_原始數據'!$D$2:$D$1000,2)=0,"",SUMIFS('1_原始數據'!$K$2:$K$1000,'1_原始數據'!$B$2:$B$1000,$B9,'1_原始數據'!$C$2:$C$1000,$C9,'1_原始數據'!$D$2:$D$1000,2)) | H9: =IF(COUNTIFS('1_原始數據'!$B$2:$B$1000,$B9,'1_原始數據'!$C$2:$C$1000,$C9,'1_原始數據'!$D$2:$D$1000,3)=0,"",SUMIFS('1_原始數據'!$K$2:$K$1000,'1_原始數據'!$B$2:$B$1000,$B9,'1_原始數據'!$C$2:$C$1000,$C9,'1_原始數據'!$D$2:$D$1000,3)) | I9: =IF(COUNTIFS('1_原始數據'!$B$2:$B$1000,$B9,'1_原始數據'!$C$2:$C$1000,$C9,'1_原始數據'!$D$2:$D$1000,4)=0,"",SUMIFS('1_原始數據'!$K$2:$K$1000,'1_原始數據'!$B$2:$B$1000,$B9,'1_原始數據'!$C$2:$C$1000,$C9,'1_原始數據'!$D$2:$D$1000,4)) | J9: =IF(COUNTIFS('1_原始數據'!$B$2:$B$1000,$B9,'1_原始數據'!$C$2:$C$1000,$C9,'1_原始數據'!$D$2:$D$1000,5)=0,"",SUMIFS('1_原始數據'!$K$2:$K$1000,'1_原始數據'!$B$2:$B$1000,$B9,'1_原始數據'!$C$2:$C$1000,$C9,'1_原始數據'!$D$2:$D$1000,5)) | K9: =IF(COUNTIFS('1_原始數據'!$B$2:$B$1000,$B9,'1_原始數據'!$C$2:$C$1000,$C9,'1_原始數據'!$D$2:$D$1000,6)=0,"",SUMIFS('1_原始數據'!$K$2:$K$1000,'1_原始數據'!$B$2:$B$1000,$B9,'1_原始數據'!$C$2:$C$1000,$C9,'1_原始數據'!$D$2:$D$1000,6)) | L9: =IF(COUNTIFS('1_原始數據'!$B$2:$B$1000,$B9,'1_原始數據'!$C$2:$C$1000,$C9,'1_原始數據'!$D$2:$D$1000,7)=0,"",SUMIFS('1_原始數據'!$K$2:$K$1000,'1_原始數據'!$B$2:$B$1000,$B9,'1_原始數據'!$C$2:$C$1000,$C9,'1_原始數據'!$D$2:$D$1000,7)) | M9: =IF(COUNTIFS('1_原始數據'!$B$2:$B$1000,$B9,'1_原始數據'!$C$2:$C$1000,$C9,'1_原始數據'!$D$2:$D$1000,8)=0,"",SUMIFS('1_原始數據'!$K$2:$K$1000,'1_原始數據'!$B$2:$B$1000,$B9,'1_原始數據'!$C$2:$C$1000,$C9,'1_原始數據'!$D$2:$D$1000,8)) | N9: =IF(COUNTIFS('1_原始數據'!$B$2:$B$1000,$B9,'1_原始數據'!$C$2:$C$1000,$C9,'1_原始數據'!$D$2:$D$1000,9)=0,"",SUMIFS('1_原始數據'!$K$2:$K$1000,'1_原始數據'!$B$2:$B$1000,$B9,'1_原始數據'!$C$2:$C$1000,$C9,'1_原始數據'!$D$2:$D$1000,9)) | O9: =IF(COUNTIFS('1_原始數據'!$B$2:$B$1000,$B9,'1_原始數據'!$C$2:$C$1000,$C9,'1_原始數據'!$D$2:$D$1000,10)=0,"",SUMIFS('1_原始數據'!$K$2:$K$1000,'1_原始數據'!$B$2:$B$1000,$B9,'1_原始數據'!$C$2:$C$1000,$C9,'1_原始數據'!$D$2:$D$1000,10)) | P9: =COUNT(F9:O9) | Q9: =AVERAGE(F9:O9) | R9: =_xlfn.STDEV.S(F9:O9) | S9: =R9/Q9*100 | T9: =_xlfn.T.INV.2T(0.05,P9-1) | U9: =T9*R9/SQRT(P9) | V9: =Q9-D9 | W9: =IF(ABS(V9)<=E9,"是","否") | X9: =IF(R9<=E9/2,"是","否") | Y9: =IF(W9="是",IF(X9="是","準確且精密","準確但不精密"),IF(X9="是","精密但不準確","不準確且不精密")) | Z9: =FIXED(Q9,MAX(0,1-INT(LOG10(ABS(U9)))))&" ± "&FIXED(U9,MAX(0,1-INT(LOG10(ABS(U9)))))&" mL" | AB9: =-MAX(E5*1.5,MAX(ABS(MAX(V5:V19)),ABS(MIN(V5:V19)))*1.1) | AC9: =E5/2 | AE9: =-MAX(E20*1.5,MAX(ABS(MAX(V20:V34)),ABS(MIN(V20:V34)))*1.1) | AF9: =E20/2
A10: 2 | B10: G2_S3 | C10: pipette_10mL | D10: =IF(C10="pipette_10mL",10,IF(C10="burette_25mL",25,"")) | E10: =IF(C10="pipette_10mL",0.02,IF(C10="burette_25mL",0.05,"")) | F10: =IF(COUNTIFS('1_原始數據'!$B$2:$B$1000,$B10,'1_原始數據'!$C$2:$C$1000,$C10,'1_原始數據'!$D$2:$D$1000,1)=0,"",SUMIFS('1_原始數據'!$K$2:$K$1000,'1_原始數據'!$B$2:$B$1000,$B10,'1_原始數據'!$C$2:$C$1000,$C10,'1_原始數據'!$D$2:$D$1000,1)) | G10: =IF(COUNTIFS('1_原始數據'!$B$2:$B$1000,$B10,'1_原始數據'!$C$2:$C$1000,$C10,'1_原始數據'!$D$2:$D$1000,2)=0,"",SUMIFS('1_原始數據'!$K$2:$K$1000,'1_原始數據'!$B$2:$B$1000,$B10,'1_原始數據'!$C$2:$C$1000,$C10,'1_原始數據'!$D$2:$D$1000,2)) | H10: =IF(COUNTIFS('1_原始數據'!$B$2:$B$1000,$B10,'1_原始數據'!$C$2:$C$1000,$C10,'1_原始數據'!$D$2:$D$1000,3)=0,"",SUMIFS('1_原始數據'!$K$2:$K$1000,'1_原始數據'!$B$2:$B$1000,$B10,'1_原始數據'!$C$2:$C$1000,$C10,'1_原始數據'!$D$2:$D$1000,3)) | I10: =IF(COUNTIFS('1_原始數據'!$B$2:$B$1000,$B10,'1_原始數據'!$C$2:$C$1000,$C10,'1_原始數據'!$D$2:$D$1000,4)=0,"",SUMIFS('1_原始數據'!$K$2:$K$1000,'1_原始數據'!$B$2:$B$1000,$B10,'1_原始數據'!$C$2:$C$1000,$C10,'1_原始數據'!$D$2:$D$1000,4)) | J10: =IF(COUNTIFS('1_原始數據'!$B$2:$B$1000,$B10,'1_原始數據'!$C$2:$C$1000,$C10,'1_原始數據'!$D$2:$D$1000,5)=0,"",SUMIFS('1_原始數據'!$K$2:$K$1000,'1_原始數據'!$B$2:$B$1000,$B10,'1_原始數據'!$C$2:$C$1000,$C10,'1_原始數據'!$D$2:$D$1000,5)) | K10: =IF(COUNTIFS('1_原始數據'!$B$2:$B$1000,$B10,'1_原始數據'!$C$2:$C$1000,$C10,'1_原始數據'!$D$2:$D$1000,6)=0,"",SUMIFS('1_原始數據'!$K$2:$K$1000,'1_原始數據'!$B$2:$B$1000,$B10,'1_原始數據'!$C$2:$C$1000,$C10,'1_原始數據'!$D$2:$D$1000,6)) | L10: =IF(COUNTIFS('1_原始數據'!$B$2:$B$1000,$B10,'1_原始數據'!$C$2:$C$1000,$C10,'1_原始數據'!$D$2:$D$1000,7)=0,"",SUMIFS('1_原始數據'!$K$2:$K$1000,'1_原始數據'!$B$2:$B$1000,$B10,'1_原始數據'!$C$2:$C$1000,$C10,'1_原始數據'!$D$2:$D$1000,7)) | M10: =IF(COUNTIFS('1_原始數據'!$B$2:$B$1000,$B10,'1_原始數據'!$C$2:$C$1000,$C10,'1_原始數據'!$D$2:$D$1000,8)=0,"",SUMIFS('1_原始數據'!$K$2:$K$1000,'1_原始數據'!$B$2:$B$1000,$B10,'1_原始數據'!$C$2:$C$1000,$C10,'1_原始數據'!$D$2:$D$1000,8)) | N10: =IF(COUNTIFS('1_原始數據'!$B$2:$B$1000,$B10,'1_原始數據'!$C$2:$C$1000,$C10,'1_原始數據'!$D$2:$D$1000,9)=0,"",SUMIFS('1_原始數據'!$K$2:$K$1000,'1_原始數據'!$B$2:$B$1000,$B10,'1_原始數據'!$C$2:$C$1000,$C10,'1_原始數據'!$D$2:$D$1000,9)) | O10: =IF(COUNTIFS('1_原始數據'!$B$2:$B$1000,$B10,'1_原始數據'!$C$2:$C$1000,$C10,'1_原始數據'!$D$2:$D$1000,10)=0,"",SUMIFS('1_原始數據'!$K$2:$K$1000,'1_原始數據'!$B$2:$B$1000,$B10,'1_原始數據'!$C$2:$C$1000,$C10,'1_原始數據'!$D$2:$D$1000,10)) | P10: =COUNT(F10:O10) | Q10: =AVERAGE(F10:O10) | R10: =_xlfn.STDEV.S(F10:O10) | S10: =R10/Q10*100 | T10: =_xlfn.T.INV.2T(0.05,P10-1) | U10: =T10*R10/SQRT(P10) | V10: =Q10-D10 | W10: =IF(ABS(V10)<=E10,"是","否") | X10: =IF(R10<=E10/2,"是","否") | Y10: =IF(W10="是",IF(X10="是","準確且精密","準確但不精密"),IF(X10="是","精密但不準確","不準確且不精密")) | Z10: =FIXED(Q10,MAX(0,1-INT(LOG10(ABS(U10)))))&" ± "&FIXED(U10,MAX(0,1-INT(LOG10(ABS(U10)))))&" mL" | AB10: =MAX(E5*1.5,MAX(ABS(MAX(V5:V19)),ABS(MIN(V5:V19)))*1.1) | AC10: =E5/2 | AE10: =MAX(E20*1.5,MAX(ABS(MAX(V20:V34)),ABS(MIN(V20:V34)))*1.1) | AF10: =E20/2
A11: 3 | B11: G3_S1 | C11: pipette_10mL | D11: =IF(C11="pipette_10mL",10,IF(C11="burette_25mL",25,"")) | E11: =IF(C11="pipette_10mL",0.02,IF(C11="burette_25mL",0.05,"")) | F11: =IF(COUNTIFS('1_原始數據'!$B$2:$B$1000,$B11,'1_原始數據'!$C$2:$C$1000,$C11,'1_原始數據'!$D$2:$D$1000,1)=0,"",SUMIFS('1_原始數據'!$K$2:$K$1000,'1_原始數據'!$B$2:$B$1000,$B11,'1_原始數據'!$C$2:$C$1000,$C11,'1_原始數據'!$D$2:$D$1000,1)) | G11: =IF(COUNTIFS('1_原始數據'!$B$2:$B$1000,$B11,'1_原始數據'!$C$2:$C$1000,$C11,'1_原始數據'!$D$2:$D$1000,2)=0,"",SUMIFS('1_原始數據'!$K$2:$K$1000,'1_原始數據'!$B$2:$B$1000,$B11,'1_原始數據'!$C$2:$C$1000,$C11,'1_原始數據'!$D$2:$D$1000,2)) | H11: =IF(COUNTIFS('1_原始數據'!$B$2:$B$1000,$B11,'1_原始數據'!$C$2:$C$1000,$C11,'1_原始數據'!$D$2:$D$1000,3)=0,"",SUMIFS('1_原始數據'!$K$2:$K$1000,'1_原始數據'!$B$2:$B$1000,$B11,'1_原始數據'!$C$2:$C$1000,$C11,'1_原始數據'!$D$2:$D$1000,3)) | I11: =IF(COUNTIFS('1_原始數據'!$B$2:$B$1000,$B11,'1_原始數據'!$C$2:$C$1000,$C11,'1_原始數據'!$D$2:$D$1000,4)=0,"",SUMIFS('1_原始數據'!$K$2:$K$1000,'1_原始數據'!$B$2:$B$1000,$B11,'1_原始數據'!$C$2:$C$1000,$C11,'1_原始數據'!$D$2:$D$1000,4)) | J11: =IF(COUNTIFS('1_原始數據'!$B$2:$B$1000,$B11,'1_原始數據'!$C$2:$C$1000,$C11,'1_原始數據'!$D$2:$D$1000,5)=0,"",SUMIFS('1_原始數據'!$K$2:$K$1000,'1_原始數據'!$B$2:$B$1000,$B11,'1_原始數據'!$C$2:$C$1000,$C11,'1_原始數據'!$D$2:$D$1000,5)) | K11: =IF(COUNTIFS('1_原始數據'!$B$2:$B$1000,$B11,'1_原始數據'!$C$2:$C$1000,$C11,'1_原始數據'!$D$2:$D$1000,6)=0,"",SUMIFS('1_原始數據'!$K$2:$K$1000,'1_原始數據'!$B$2:$B$1000,$B11,'1_原始數據'!$C$2:$C$1000,$C11,'1_原始數據'!$D$2:$D$1000,6)) | L11: =IF(COUNTIFS('1_原始數據'!$B$2:$B$1000,$B11,'1_原始數據'!$C$2:$C$1000,$C11,'1_原始數據'!$D$2:$D$1000,7)=0,"",SUMIFS('1_原始數據'!$K$2:$K$1000,'1_原始數據'!$B$2:$B$1000,$B11,'1_原始數據'!$C$2:$C$1000,$C11,'1_原始數據'!$D$2:$D$1000,7)) | M11: =IF(COUNTIFS('1_原始數據'!$B$2:$B$1000,$B11,'1_原始數據'!$C$2:$C$1000,$C11,'1_原始數據'!$D$2:$D$1000,8)=0,"",SUMIFS('1_原始數據'!$K$2:$K$1000,'1_原始數據'!$B$2:$B$1000,$B11,'1_原始數據'!$C$2:$C$1000,$C11,'1_原始數據'!$D$2:$D$1000,8)) | N11: =IF(COUNTIFS('1_原始數據'!$B$2:$B$1000,$B11,'1_原始數據'!$C$2:$C$1000,$C11,'1_原始數據'!$D$2:$D$1000,9)=0,"",SUMIFS('1_原始數據'!$K$2:$K$1000,'1_原始數據'!$B$2:$B$1000,$B11,'1_原始數據'!$C$2:$C$1000,$C11,'1_原始數據'!$D$2:$D$1000,9)) | O11: =IF(COUNTIFS('1_原始數據'!$B$2:$B$1000,$B11,'1_原始數據'!$C$2:$C$1000,$C11,'1_原始數據'!$D$2:$D$1000,10)=0,"",SUMIFS('1_原始數據'!$K$2:$K$1000,'1_原始數據'!$B$2:$B$1000,$B11,'1_原始數據'!$C$2:$C$1000,$C11,'1_原始數據'!$D$2:$D$1000,10)) | P11: =COUNT(F11:O11) | Q11: =AVERAGE(F11:O11) | R11: =_xlfn.STDEV.S(F11:O11) | S11: =R11/Q11*100 | T11: =_xlfn.T.INV.2T(0.05,P11-1) | U11: =T11*R11/SQRT(P11) | V11: =Q11-D11 | W11: =IF(ABS(V11)<=E11,"是","否") | X11: =IF(R11<=E11/2,"是","否") | Y11: =IF(W11="是",IF(X11="是","準確且精密","準確但不精密"),IF(X11="是","精密但不準確","不準確且不精密")) | Z11: =FIXED(Q11,MAX(0,1-INT(LOG10(ABS(U11)))))&" ± "&FIXED(U11,MAX(0,1-INT(LOG10(ABS(U11)))))&" mL"
A12: 3 | B12: G3_S2 | C12: pipette_10mL | D12: =IF(C12="pipette_10mL",10,IF(C12="burette_25mL",25,"")) | E12: =IF(C12="pipette_10mL",0.02,IF(C12="burette_25mL",0.05,"")) | F12: =IF(COUNTIFS('1_原始數據'!$B$2:$B$1000,$B12,'1_原始數據'!$C$2:$C$1000,$C12,'1_原始數據'!$D$2:$D$1000,1)=0,"",SUMIFS('1_原始數據'!$K$2:$K$1000,'1_原始數據'!$B$2:$B$1000,$B12,'1_原始數據'!$C$2:$C$1000,$C12,'1_原始數據'!$D$2:$D$1000,1)) | G12: =IF(COUNTIFS('1_原始數據'!$B$2:$B$1000,$B12,'1_原始數據'!$C$2:$C$1000,$C12,'1_原始數據'!$D$2:$D$1000,2)=0,"",SUMIFS('1_原始數據'!$K$2:$K$1000,'1_原始數據'!$B$2:$B$1000,$B12,'1_原始數據'!$C$2:$C$1000,$C12,'1_原始數據'!$D$2:$D$1000,2)) | H12: =IF(COUNTIFS('1_原始數據'!$B$2:$B$1000,$B12,'1_原始數據'!$C$2:$C$1000,$C12,'1_原始數據'!$D$2:$D$1000,3)=0,"",SUMIFS('1_原始數據'!$K$2:$K$1000,'1_原始數據'!$B$2:$B$1000,$B12,'1_原始數據'!$C$2:$C$1000,$C12,'1_原始數據'!$D$2:$D$1000,3)) | I12: =IF(COUNTIFS('1_原始數據'!$B$2:$B$1000,$B12,'1_原始數據'!$C$2:$C$1000,$C12,'1_原始數據'!$D$2:$D$1000,4)=0,"",SUMIFS('1_原始數據'!$K$2:$K$1000,'1_原始數據'!$B$2:$B$1000,$B12,'1_原始數據'!$C$2:$C$1000,$C12,'1_原始數據'!$D$2:$D$1000,4)) | J12: =IF(COUNTIFS('1_原始數據'!$B$2:$B$1000,$B12,'1_原始數據'!$C$2:$C$1000,$C12,'1_原始數據'!$D$2:$D$1000,5)=0,"",SUMIFS('1_原始數據'!$K$2:$K$1000,'1_原始數據'!$B$2:$B$1000,$B12,'1_原始數據'!$C$2:$C$1000,$C12,'1_原始數據'!$D$2:$D$1000,5)) | K12: =IF(COUNTIFS('1_原始數據'!$B$2:$B$1000,$B12,'1_原始數據'!$C$2:$C$1000,$C12,'1_原始數據'!$D$2:$D$1000,6)=0,"",SUMIFS('1_原始數據'!$K$2:$K$1000,'1_原始數據'!$B$2:$B$1000,$B12,'1_原始數據'!$C$2:$C$1000,$C12,'1_原始數據'!$D$2:$D$1000,6)) | L12: =IF(COUNTIFS('1_原始數據'!$B$2:$B$1000,$B12,'1_原始數據'!$C$2:$C$1000,$C12,'1_原始數據'!$D$2:$D$1000,7)=0,"",SUMIFS('1_原始數據'!$K$2:$K$1000,'1_原始數據'!$B$2:$B$1000,$B12,'1_原始數據'!$C$2:$C$1000,$C12,'1_原始數據'!$D$2:$D$1000,7)) | M12: =IF(COUNTIFS('1_原始數據'!$B$2:$B$1000,$B12,'1_原始數據'!$C$2:$C$1000,$C12,'1_原始數據'!$D$2:$D$1000,8)=0,"",SUMIFS('1_原始數據'!$K$2:$K$1000,'1_原始數據'!$B$2:$B$1000,$B12,'1_原始數據'!$C$2:$C$1000,$C12,'1_原始數據'!$D$2:$D$1000,8)) | N12: =IF(COUNTIFS('1_原始數據'!$B$2:$B$1000,$B12,'1_原始數據'!$C$2:$C$1000,$C12,'1_原始數據'!$D$2:$D$1000,9)=0,"",SUMIFS('1_原始數據'!$K$2:$K$1000,'1_原始數據'!$B$2:$B$1000,$B12,'1_原始數據'!$C$2:$C$1000,$C12,'1_原始數據'!$D$2:$D$1000,9)) | O12: =IF(COUNTIFS('1_原始數據'!$B$2:$B$1000,$B12,'1_原始數據'!$C$2:$C$1000,$C12,'1_原始數據'!$D$2:$D$1000,10)=0,"",SUMIFS('1_原始數據'!$K$2:$K$1000,'1_原始數據'!$B$2:$B$1000,$B12,'1_原始數據'!$C$2:$C$1000,$C12,'1_原始數據'!$D$2:$D$1000,10)) | P12: =COUNT(F12:O12) | Q12: =AVERAGE(F12:O12) | R12: =_xlfn.STDEV.S(F12:O12) | S12: =R12/Q12*100 | T12: =_xlfn.T.INV.2T(0.05,P12-1) | U12: =T12*R12/SQRT(P12) | V12: =Q12-D12 | W12: =IF(ABS(V12)<=E12,"是","否") | X12: =IF(R12<=E12/2,"是","否") | Y12: =IF(W12="是",IF(X12="是","準確且精密","準確但不精密"),IF(X12="是","精密但不準確","不準確且不精密")) | Z12: =FIXED(Q12,MAX(0,1-INT(LOG10(ABS(U12)))))&" ± "&FIXED(U12,MAX(0,1-INT(LOG10(ABS(U12)))))&" mL"
A13: 3 | B13: G3_S3 | C13: pipette_10mL | D13: =IF(C13="pipette_10mL",10,IF(C13="burette_25mL",25,"")) | E13: =IF(C13="pipette_10mL",0.02,IF(C13="burette_25mL",0.05,"")) | F13: =IF(COUNTIFS('1_原始數據'!$B$2:$B$1000,$B13,'1_原始數據'!$C$2:$C$1000,$C13,'1_原始數據'!$D$2:$D$1000,1)=0,"",SUMIFS('1_原始數據'!$K$2:$K$1000,'1_原始數據'!$B$2:$B$1000,$B13,'1_原始數據'!$C$2:$C$1000,$C13,'1_原始數據'!$D$2:$D$1000,1)) | G13: =IF(COUNTIFS('1_原始數據'!$B$2:$B$1000,$B13,'1_原始數據'!$C$2:$C$1000,$C13,'1_原始數據'!$D$2:$D$1000,2)=0,"",SUMIFS('1_原始數據'!$K$2:$K$1000,'1_原始數據'!$B$2:$B$1000,$B13,'1_原始數據'!$C$2:$C$1000,$C13,'1_原始數據'!$D$2:$D$1000,2)) | H13: =IF(COUNTIFS('1_原始數據'!$B$2:$B$1000,$B13,'1_原始數據'!$C$2:$C$1000,$C13,'1_原始數據'!$D$2:$D$1000,3)=0,"",SUMIFS('1_原始數據'!$K$2:$K$1000,'1_原始數據'!$B$2:$B$1000,$B13,'1_原始數據'!$C$2:$C$1000,$C13,'1_原始數據'!$D$2:$D$1000,3)) | I13: =IF(COUNTIFS('1_原始數據'!$B$2:$B$1000,$B13,'1_原始數據'!$C$2:$C$1000,$C13,'1_原始數據'!$D$2:$D$1000,4)=0,"",SUMIFS('1_原始數據'!$K$2:$K$1000,'1_原始數據'!$B$2:$B$1000,$B13,'1_原始數據'!$C$2:$C$1000,$C13,'1_原始數據'!$D$2:$D$1000,4)) | J13: =IF(COUNTIFS('1_原始數據'!$B$2:$B$1000,$B13,'1_原始數據'!$C$2:$C$1000,$C13,'1_原始數據'!$D$2:$D$1000,5)=0,"",SUMIFS('1_原始數據'!$K$2:$K$1000,'1_原始數據'!$B$2:$B$1000,$B13,'1_原始數據'!$C$2:$C$1000,$C13,'1_原始數據'!$D$2:$D$1000,5)) | K13: =IF(COUNTIFS('1_原始數據'!$B$2:$B$1000,$B13,'1_原始數據'!$C$2:$C$1000,$C13,'1_原始數據'!$D$2:$D$1000,6)=0,"",SUMIFS('1_原始數據'!$K$2:$K$1000,'1_原始數據'!$B$2:$B$1000,$B13,'1_原始數據'!$C$2:$C$1000,$C13,'1_原始數據'!$D$2:$D$1000,6)) | L13: =IF(COUNTIFS('1_原始數據'!$B$2:$B$1000,$B13,'1_原始數據'!$C$2:$C$1000,$C13,'1_原始數據'!$D$2:$D$1000,7)=0,"",SUMIFS('1_原始數據'!$K$2:$K$1000,'1_原始數據'!$B$2:$B$1000,$B13,'1_原始數據'!$C$2:$C$1000,$C13,'1_原始數據'!$D$2:$D$1000,7)) | M13: =IF(COUNTIFS('1_原始數據'!$B$2:$B$1000,$B13,'1_原始數據'!$C$2:$C$1000,$C13,'1_原始數據'!$D$2:$D$1000,8)=0,"",SUMIFS('1_原始數據'!$K$2:$K$1000,'1_原始數據'!$B$2:$B$1000,$B13,'1_原始數據'!$C$2:$C$1000,$C13,'1_原始數據'!$D$2:$D$1000,8)) | N13: =IF(COUNTIFS('1_原始數據'!$B$2:$B$1000,$B13,'1_原始數據'!$C$2:$C$1000,$C13,'1_原始數據'!$D$2:$D$1000,9)=0,"",SUMIFS('1_原始數據'!$K$2:$K$1000,'1_原始數據'!$B$2:$B$1000,$B13,'1_原始數據'!$C$2:$C$1000,$C13,'1_原始數據'!$D$2:$D$1000,9)) | O13: =IF(COUNTIFS('1_原始數據'!$B$2:$B$1000,$B13,'1_原始數據'!$C$2:$C$1000,$C13,'1_原始數據'!$D$2:$D$1000,10)=0,"",SUMIFS('1_原始數據'!$K$2:$K$1000,'1_原始數據'!$B$2:$B$1000,$B13,'1_原始數據'!$C$2:$C$1000,$C13,'1_原始數據'!$D$2:$D$1000,10)) | P13: =COUNT(F13:O13) | Q13: =AVERAGE(F13:O13) | R13: =_xlfn.STDEV.S(F13:O13) | S13: =R13/Q13*100 | T13: =_xlfn.T.INV.2T(0.05,P13-1) | U13: =T13*R13/SQRT(P13) | V13: =Q13-D13 | W13: =IF(ABS(V13)<=E13,"是","否") | X13: =IF(R13<=E13/2,"是","否") | Y13: =IF(W13="是",IF(X13="是","準確且精密","準確但不精密"),IF(X13="是","精密但不準確","不準確且不精密")) | Z13: =FIXED(Q13,MAX(0,1-INT(LOG10(ABS(U13)))))&" ± "&FIXED(U13,MAX(0,1-INT(LOG10(ABS(U13)))))&" mL"
A14: 4 | B14: G4_S1 | C14: pipette_10mL | D14: =IF(C14="pipette_10mL",10,IF(C14="burette_25mL",25,"")) | E14: =IF(C14="pipette_10mL",0.02,IF(C14="burette_25mL",0.05,"")) | F14: =IF(COUNTIFS('1_原始數據'!$B$2:$B$1000,$B14,'1_原始數據'!$C$2:$C$1000,$C14,'1_原始數據'!$D$2:$D$1000,1)=0,"",SUMIFS('1_原始數據'!$K$2:$K$1000,'1_原始數據'!$B$2:$B$1000,$B14,'1_原始數據'!$C$2:$C$1000,$C14,'1_原始數據'!$D$2:$D$1000,1)) | G14: =IF(COUNTIFS('1_原始數據'!$B$2:$B$1000,$B14,'1_原始數據'!$C$2:$C$1000,$C14,'1_原始數據'!$D$2:$D$1000,2)=0,"",SUMIFS('1_原始數據'!$K$2:$K$1000,'1_原始數據'!$B$2:$B$1000,$B14,'1_原始數據'!$C$2:$C$1000,$C14,'1_原始數據'!$D$2:$D$1000,2)) | H14: =IF(COUNTIFS('1_原始數據'!$B$2:$B$1000,$B14,'1_原始數據'!$C$2:$C$1000,$C14,'1_原始數據'!$D$2:$D$1000,3)=0,"",SUMIFS('1_原始數據'!$K$2:$K$1000,'1_原始數據'!$B$2:$B$1000,$B14,'1_原始數據'!$C$2:$C$1000,$C14,'1_原始數據'!$D$2:$D$1000,3)) | I14: =IF(COUNTIFS('1_原始數據'!$B$2:$B$1000,$B14,'1_原始數據'!$C$2:$C$1000,$C14,'1_原始數據'!$D$2:$D$1000,4)=0,"",SUMIFS('1_原始數據'!$K$2:$K$1000,'1_原始數據'!$B$2:$B$1000,$B14,'1_原始數據'!$C$2:$C$1000,$C14,'1_原始數據'!$D$2:$D$1000,4)) | J14: =IF(COUNTIFS('1_原始數據'!$B$2:$B$1000,$B14,'1_原始數據'!$C$2:$C$1000,$C14,'1_原始數據'!$D$2:$D$1000,5)=0,"",SUMIFS('1_原始數據'!$K$2:$K$1000,'1_原始數據'!$B$2:$B$1000,$B14,'1_原始數據'!$C$2:$C$1000,$C14,'1_原始數據'!$D$2:$D$1000,5)) | K14: =IF(COUNTIFS('1_原始數據'!$B$2:$B$1000,$B14,'1_原始數據'!$C$2:$C$1000,$C14,'1_原始數據'!$D$2:$D$1000,6)=0,"",SUMIFS('1_原始數據'!$K$2:$K$1000,'1_原始數據'!$B$2:$B$1000,$B14,'1_原始數據'!$C$2:$C$1000,$C14,'1_原始數據'!$D$2:$D$1000,6)) | L14: =IF(COUNTIFS('1_原始數據'!$B$2:$B$1000,$B14,'1_原始數據'!$C$2:$C$1000,$C14,'1_原始數據'!$D$2:$D$1000,7)=0,"",SUMIFS('1_原始數據'!$K$2:$K$1000,'1_原始數據'!$B$2:$B$1000,$B14,'1_原始數據'!$C$2:$C$1000,$C14,'1_原始數據'!$D$2:$D$1000,7)) | M14: =IF(COUNTIFS('1_原始數據'!$B$2:$B$1000,$B14,'1_原始數據'!$C$2:$C$1000,$C14,'1_原始數據'!$D$2:$D$1000,8)=0,"",SUMIFS('1_原始數據'!$K$2:$K$1000,'1_原始數據'!$B$2:$B$1000,$B14,'1_原始數據'!$C$2:$C$1000,$C14,'1_原始數據'!$D$2:$D$1000,8)) | N14: =IF(COUNTIFS('1_原始數據'!$B$2:$B$1000,$B14,'1_原始數據'!$C$2:$C$1000,$C14,'1_原始數據'!$D$2:$D$1000,9)=0,"",SUMIFS('1_原始數據'!$K$2:$K$1000,'1_原始數據'!$B$2:$B$1000,$B14,'1_原始數據'!$C$2:$C$1000,$C14,'1_原始數據'!$D$2:$D$1000,9)) | O14: =IF(COUNTIFS('1_原始數據'!$B$2:$B$1000,$B14,'1_原始數據'!$C$2:$C$1000,$C14,'1_原始數據'!$D$2:$D$1000,10)=0,"",SUMIFS('1_原始數據'!$K$2:$K$1000,'1_原始數據'!$B$2:$B$1000,$B14,'1_原始數據'!$C$2:$C$1000,$C14,'1_原始數據'!$D$2:$D$1000,10)) | P14: =COUNT(F14:O14) | Q14: =AVERAGE(F14:O14) | R14: =_xlfn.STDEV.S(F14:O14) | S14: =R14/Q14*100 | T14: =_xlfn.T.INV.2T(0.05,P14-1) | U14: =T14*R14/SQRT(P14) | V14: =Q14-D14 | W14: =IF(ABS(V14)<=E14,"是","否") | X14: =IF(R14<=E14/2,"是","否") | Y14: =IF(W14="是",IF(X14="是","準確且精密","準確但不精密"),IF(X14="是","精密但不準確","不準確且不精密")) | Z14: =FIXED(Q14,MAX(0,1-INT(LOG10(ABS(U14)))))&" ± "&FIXED(U14,MAX(0,1-INT(LOG10(ABS(U14)))))&" mL"
A15: 4 | B15: G4_S2 | C15: pipette_10mL | D15: =IF(C15="pipette_10mL",10,IF(C15="burette_25mL",25,"")) | E15: =IF(C15="pipette_10mL",0.02,IF(C15="burette_25mL",0.05,"")) | F15: =IF(COUNTIFS('1_原始數據'!$B$2:$B$1000,$B15,'1_原始數據'!$C$2:$C$1000,$C15,'1_原始數據'!$D$2:$D$1000,1)=0,"",SUMIFS('1_原始數據'!$K$2:$K$1000,'1_原始數據'!$B$2:$B$1000,$B15,'1_原始數據'!$C$2:$C$1000,$C15,'1_原始數據'!$D$2:$D$1000,1)) | G15: =IF(COUNTIFS('1_原始數據'!$B$2:$B$1000,$B15,'1_原始數據'!$C$2:$C$1000,$C15,'1_原始數據'!$D$2:$D$1000,2)=0,"",SUMIFS('1_原始數據'!$K$2:$K$1000,'1_原始數據'!$B$2:$B$1000,$B15,'1_原始數據'!$C$2:$C$1000,$C15,'1_原始數據'!$D$2:$D$1000,2)) | H15: =IF(COUNTIFS('1_原始數據'!$B$2:$B$1000,$B15,'1_原始數據'!$C$2:$C$1000,$C15,'1_原始數據'!$D$2:$D$1000,3)=0,"",SUMIFS('1_原始數據'!$K$2:$K$1000,'1_原始數據'!$B$2:$B$1000,$B15,'1_原始數據'!$C$2:$C$1000,$C15,'1_原始數據'!$D$2:$D$1000,3)) | I15: =IF(COUNTIFS('1_原始數據'!$B$2:$B$1000,$B15,'1_原始數據'!$C$2:$C$1000,$C15,'1_原始數據'!$D$2:$D$1000,4)=0,"",SUMIFS('1_原始數據'!$K$2:$K$1000,'1_原始數據'!$B$2:$B$1000,$B15,'1_原始數據'!$C$2:$C$1000,$C15,'1_原始數據'!$D$2:$D$1000,4)) | J15: =IF(COUNTIFS('1_原始數據'!$B$2:$B$1000,$B15,'1_原始數據'!$C$2:$C$1000,$C15,'1_原始數據'!$D$2:$D$1000,5)=0,"",SUMIFS('1_原始數據'!$K$2:$K$1000,'1_原始數據'!$B$2:$B$1000,$B15,'1_原始數據'!$C$2:$C$1000,$C15,'1_原始數據'!$D$2:$D$1000,5)) | K15: =IF(COUNTIFS('1_原始數據'!$B$2:$B$1000,$B15,'1_原始數據'!$C$2:$C$1000,$C15,'1_原始數據'!$D$2:$D$1000,6)=0,"",SUMIFS('1_原始數據'!$K$2:$K$1000,'1_原始數據'!$B$2:$B$1000,$B15,'1_原始數據'!$C$2:$C$1000,$C15,'1_原始數據'!$D$2:$D$1000,6)) | L15: =IF(COUNTIFS('1_原始數據'!$B$2:$B$1000,$B15,'1_原始數據'!$C$2:$C$1000,$C15,'1_原始數據'!$D$2:$D$1000,7)=0,"",SUMIFS('1_原始數據'!$K$2:$K$1000,'1_原始數據'!$B$2:$B$1000,$B15,'1_原始數據'!$C$2:$C$1000,$C15,'1_原始數據'!$D$2:$D$1000,7)) | M15: =IF(COUNTIFS('1_原始數據'!$B$2:$B$1000,$B15,'1_原始數據'!$C$2:$C$1000,$C15,'1_原始數據'!$D$2:$D$1000,8)=0,"",SUMIFS('1_原始數據'!$K$2:$K$1000,'1_原始數據'!$B$2:$B$1000,$B15,'1_原始數據'!$C$2:$C$1000,$C15,'1_原始數據'!$D$2:$D$1000,8)) | N15: =IF(COUNTIFS('1_原始數據'!$B$2:$B$1000,$B15,'1_原始數據'!$C$2:$C$1000,$C15,'1_原始數據'!$D$2:$D$1000,9)=0,"",SUMIFS('1_原始數據'!$K$2:$K$1000,'1_原始數據'!$B$2:$B$1000,$B15,'1_原始數據'!$C$2:$C$1000,$C15,'1_原始數據'!$D$2:$D$1000,9)) | O15: =IF(COUNTIFS('1_原始數據'!$B$2:$B$1000,$B15,'1_原始數據'!$C$2:$C$1000,$C15,'1_原始數據'!$D$2:$D$1000,10)=0,"",SUMIFS('1_原始數據'!$K$2:$K$1000,'1_原始數據'!$B$2:$B$1000,$B15,'1_原始數據'!$C$2:$C$1000,$C15,'1_原始數據'!$D$2:$D$1000,10)) | P15: =COUNT(F15:O15) | Q15: =AVERAGE(F15:O15) | R15: =_xlfn.STDEV.S(F15:O15) | S15: =R15/Q15*100 | T15: =_xlfn.T.INV.2T(0.05,P15-1) | U15: =T15*R15/SQRT(P15) | V15: =Q15-D15 | W15: =IF(ABS(V15)<=E15,"是","否") | X15: =IF(R15<=E15/2,"是","否") | Y15: =IF(W15="是",IF(X15="是","準確且精密","準確但不精密"),IF(X15="是","精密但不準確","不準確且不精密")) | Z15: =FIXED(Q15,MAX(0,1-INT(LOG10(ABS(U15)))))&" ± "&FIXED(U15,MAX(0,1-INT(LOG10(ABS(U15)))))&" mL"
A16: 4 | B16: G4_S3 | C16: pipette_10mL | D16: =IF(C16="pipette_10mL",10,IF(C16="burette_25mL",25,"")) | E16: =IF(C16="pipette_10mL",0.02,IF(C16="burette_25mL",0.05,"")) | F16: =IF(COUNTIFS('1_原始數據'!$B$2:$B$1000,$B16,'1_原始數據'!$C$2:$C$1000,$C16,'1_原始數據'!$D$2:$D$1000,1)=0,"",SUMIFS('1_原始數據'!$K$2:$K$1000,'1_原始數據'!$B$2:$B$1000,$B16,'1_原始數據'!$C$2:$C$1000,$C16,'1_原始數據'!$D$2:$D$1000,1)) | G16: =IF(COUNTIFS('1_原始數據'!$B$2:$B$1000,$B16,'1_原始數據'!$C$2:$C$1000,$C16,'1_原始數據'!$D$2:$D$1000,2)=0,"",SUMIFS('1_原始數據'!$K$2:$K$1000,'1_原始數據'!$B$2:$B$1000,$B16,'1_原始數據'!$C$2:$C$1000,$C16,'1_原始數據'!$D$2:$D$1000,2)) | H16: =IF(COUNTIFS('1_原始數據'!$B$2:$B$1000,$B16,'1_原始數據'!$C$2:$C$1000,$C16,'1_原始數據'!$D$2:$D$1000,3)=0,"",SUMIFS('1_原始數據'!$K$2:$K$1000,'1_原始數據'!$B$2:$B$1000,$B16,'1_原始數據'!$C$2:$C$1000,$C16,'1_原始數據'!$D$2:$D$1000,3)) | I16: =IF(COUNTIFS('1_原始數據'!$B$2:$B$1000,$B16,'1_原始數據'!$C$2:$C$1000,$C16,'1_原始數據'!$D$2:$D$1000,4)=0,"",SUMIFS('1_原始數據'!$K$2:$K$1000,'1_原始數據'!$B$2:$B$1000,$B16,'1_原始數據'!$C$2:$C$1000,$C16,'1_原始數據'!$D$2:$D$1000,4)) | J16: =IF(COUNTIFS('1_原始數據'!$B$2:$B$1000,$B16,'1_原始數據'!$C$2:$C$1000,$C16,'1_原始數據'!$D$2:$D$1000,5)=0,"",SUMIFS('1_原始數據'!$K$2:$K$1000,'1_原始數據'!$B$2:$B$1000,$B16,'1_原始數據'!$C$2:$C$1000,$C16,'1_原始數據'!$D$2:$D$1000,5)) | K16: =IF(COUNTIFS('1_原始數據'!$B$2:$B$1000,$B16,'1_原始數據'!$C$2:$C$1000,$C16,'1_原始數據'!$D$2:$D$1000,6)=0,"",SUMIFS('1_原始數據'!$K$2:$K$1000,'1_原始數據'!$B$2:$B$1000,$B16,'1_原始數據'!$C$2:$C$1000,$C16,'1_原始數據'!$D$2:$D$1000,6)) | L16: =IF(COUNTIFS('1_原始數據'!$B$2:$B$1000,$B16,'1_原始數據'!$C$2:$C$1000,$C16,'1_原始數據'!$D$2:$D$1000,7)=0,"",SUMIFS('1_原始數據'!$K$2:$K$1000,'1_原始數據'!$B$2:$B$1000,$B16,'1_原始數據'!$C$2:$C$1000,$C16,'1_原始數據'!$D$2:$D$1000,7)) | M16: =IF(COUNTIFS('1_原始數據'!$B$2:$B$1000,$B16,'1_原始數據'!$C$2:$C$1000,$C16,'1_原始數據'!$D$2:$D$1000,8)=0,"",SUMIFS('1_原始數據'!$K$2:$K$1000,'1_原始數據'!$B$2:$B$1000,$B16,'1_原始數據'!$C$2:$C$1000,$C16,'1_原始數據'!$D$2:$D$1000,8)) | N16: =IF(COUNTIFS('1_原始數據'!$B$2:$B$1000,$B16,'1_原始數據'!$C$2:$C$1000,$C16,'1_原始數據'!$D$2:$D$1000,9)=0,"",SUMIFS('1_原始數據'!$K$2:$K$1000,'1_原始數據'!$B$2:$B$1000,$B16,'1_原始數據'!$C$2:$C$1000,$C16,'1_原始數據'!$D$2:$D$1000,9)) | O16: =IF(COUNTIFS('1_原始數據'!$B$2:$B$1000,$B16,'1_原始數據'!$C$2:$C$1000,$C16,'1_原始數據'!$D$2:$D$1000,10)=0,"",SUMIFS('1_原始數據'!$K$2:$K$1000,'1_原始數據'!$B$2:$B$1000,$B16,'1_原始數據'!$C$2:$C$1000,$C16,'1_原始數據'!$D$2:$D$1000,10)) | P16: =COUNT(F16:O16) | Q16: =AVERAGE(F16:O16) | R16: =_xlfn.STDEV.S(F16:O16) | S16: =R16/Q16*100 | T16: =_xlfn.T.INV.2T(0.05,P16-1) | U16: =T16*R16/SQRT(P16) | V16: =Q16-D16 | W16: =IF(ABS(V16)<=E16,"是","否") | X16: =IF(R16<=E16/2,"是","否") | Y16: =IF(W16="是",IF(X16="是","準確且精密","準確但不精密"),IF(X16="是","精密但不準確","不準確且不精密")) | Z16: =FIXED(Q16,MAX(0,1-INT(LOG10(ABS(U16)))))&" ± "&FIXED(U16,MAX(0,1-INT(LOG10(ABS(U16)))))&" mL"
A17: 5 | B17: G5_S1 | C17: pipette_10mL | D17: =IF(C17="pipette_10mL",10,IF(C17="burette_25mL",25,"")) | E17: =IF(C17="pipette_10mL",0.02,IF(C17="burette_25mL",0.05,"")) | F17: =IF(COUNTIFS('1_原始數據'!$B$2:$B$1000,$B17,'1_原始數據'!$C$2:$C$1000,$C17,'1_原始數據'!$D$2:$D$1000,1)=0,"",SUMIFS('1_原始數據'!$K$2:$K$1000,'1_原始數據'!$B$2:$B$1000,$B17,'1_原始數據'!$C$2:$C$1000,$C17,'1_原始數據'!$D$2:$D$1000,1)) | G17: =IF(COUNTIFS('1_原始數據'!$B$2:$B$1000,$B17,'1_原始數據'!$C$2:$C$1000,$C17,'1_原始數據'!$D$2:$D$1000,2)=0,"",SUMIFS('1_原始數據'!$K$2:$K$1000,'1_原始數據'!$B$2:$B$1000,$B17,'1_原始數據'!$C$2:$C$1000,$C17,'1_原始數據'!$D$2:$D$1000,2)) | H17: =IF(COUNTIFS('1_原始數據'!$B$2:$B$1000,$B17,'1_原始數據'!$C$2:$C$1000,$C17,'1_原始數據'!$D$2:$D$1000,3)=0,"",SUMIFS('1_原始數據'!$K$2:$K$1000,'1_原始數據'!$B$2:$B$1000,$B17,'1_原始數據'!$C$2:$C$1000,$C17,'1_原始數據'!$D$2:$D$1000,3)) | I17: =IF(COUNTIFS('1_原始數據'!$B$2:$B$1000,$B17,'1_原始數據'!$C$2:$C$1000,$C17,'1_原始數據'!$D$2:$D$1000,4)=0,"",SUMIFS('1_原始數據'!$K$2:$K$1000,'1_原始數據'!$B$2:$B$1000,$B17,'1_原始數據'!$C$2:$C$1000,$C17,'1_原始數據'!$D$2:$D$1000,4)) | J17: =IF(COUNTIFS('1_原始數據'!$B$2:$B$1000,$B17,'1_原始數據'!$C$2:$C$1000,$C17,'1_原始數據'!$D$2:$D$1000,5)=0,"",SUMIFS('1_原始數據'!$K$2:$K$1000,'1_原始數據'!$B$2:$B$1000,$B17,'1_原始數據'!$C$2:$C$1000,$C17,'1_原始數據'!$D$2:$D$1000,5)) | K17: =IF(COUNTIFS('1_原始數據'!$B$2:$B$1000,$B17,'1_原始數據'!$C$2:$C$1000,$C17,'1_原始數據'!$D$2:$D$1000,6)=0,"",SUMIFS('1_原始數據'!$K$2:$K$1000,'1_原始數據'!$B$2:$B$1000,$B17,'1_原始數據'!$C$2:$C$1000,$C17,'1_原始數據'!$D$2:$D$1000,6)) | L17: =IF(COUNTIFS('1_原始數據'!$B$2:$B$1000,$B17,'1_原始數據'!$C$2:$C$1000,$C17,'1_原始數據'!$D$2:$D$1000,7)=0,"",SUMIFS('1_原始數據'!$K$2:$K$1000,'1_原始數據'!$B$2:$B$1000,$B17,'1_原始數據'!$C$2:$C$1000,$C17,'1_原始數據'!$D$2:$D$1000,7)) | M17: =IF(COUNTIFS('1_原始數據'!$B$2:$B$1000,$B17,'1_原始數據'!$C$2:$C$1000,$C17,'1_原始數據'!$D$2:$D$1000,8)=0,"",SUMIFS('1_原始數據'!$K$2:$K$1000,'1_原始數據'!$B$2:$B$1000,$B17,'1_原始數據'!$C$2:$C$1000,$C17,'1_原始數據'!$D$2:$D$1000,8)) | N17: =IF(COUNTIFS('1_原始數據'!$B$2:$B$1000,$B17,'1_原始數據'!$C$2:$C$1000,$C17,'1_原始數據'!$D$2:$D$1000,9)=0,"",SUMIFS('1_原始數據'!$K$2:$K$1000,'1_原始數據'!$B$2:$B$1000,$B17,'1_原始數據'!$C$2:$C$1000,$C17,'1_原始數據'!$D$2:$D$1000,9)) | O17: =IF(COUNTIFS('1_原始數據'!$B$2:$B$1000,$B17,'1_原始數據'!$C$2:$C$1000,$C17,'1_原始數據'!$D$2:$D$1000,10)=0,"",SUMIFS('1_原始數據'!$K$2:$K$1000,'1_原始數據'!$B$2:$B$1000,$B17,'1_原始數據'!$C$2:$C$1000,$C17,'1_原始數據'!$D$2:$D$1000,10)) | P17: =COUNT(F17:O17) | Q17: =AVERAGE(F17:O17) | R17: =_xlfn.STDEV.S(F17:O17) | S17: =R17/Q17*100 | T17: =_xlfn.T.INV.2T(0.05,P17-1) | U17: =T17*R17/SQRT(P17) | V17: =Q17-D17 | W17: =IF(ABS(V17)<=E17,"是","否") | X17: =IF(R17<=E17/2,"是","否") | Y17: =IF(W17="是",IF(X17="是","準確且精密","準確但不精密"),IF(X17="是","精密但不準確","不準確且不精密")) | Z17: =FIXED(Q17,MAX(0,1-INT(LOG10(ABS(U17)))))&" ± "&FIXED(U17,MAX(0,1-INT(LOG10(ABS(U17)))))&" mL"
A18: 5 | B18: G5_S2 | C18: pipette_10mL | D18: =IF(C18="pipette_10mL",10,IF(C18="burette_25mL",25,"")) | E18: =IF(C18="pipette_10mL",0.02,IF(C18="burette_25mL",0.05,"")) | F18: =IF(COUNTIFS('1_原始數據'!$B$2:$B$1000,$B18,'1_原始數據'!$C$2:$C$1000,$C18,'1_原始數據'!$D$2:$D$1000,1)=0,"",SUMIFS('1_原始數據'!$K$2:$K$1000,'1_原始數據'!$B$2:$B$1000,$B18,'1_原始數據'!$C$2:$C$1000,$C18,'1_原始數據'!$D$2:$D$1000,1)) | G18: =IF(COUNTIFS('1_原始數據'!$B$2:$B$1000,$B18,'1_原始數據'!$C$2:$C$1000,$C18,'1_原始數據'!$D$2:$D$1000,2)=0,"",SUMIFS('1_原始數據'!$K$2:$K$1000,'1_原始數據'!$B$2:$B$1000,$B18,'1_原始數據'!$C$2:$C$1000,$C18,'1_原始數據'!$D$2:$D$1000,2)) | H18: =IF(COUNTIFS('1_原始數據'!$B$2:$B$1000,$B18,'1_原始數據'!$C$2:$C$1000,$C18,'1_原始數據'!$D$2:$D$1000,3)=0,"",SUMIFS('1_原始數據'!$K$2:$K$1000,'1_原始數據'!$B$2:$B$1000,$B18,'1_原始數據'!$C$2:$C$1000,$C18,'1_原始數據'!$D$2:$D$1000,3)) | I18: =IF(COUNTIFS('1_原始數據'!$B$2:$B$1000,$B18,'1_原始數據'!$C$2:$C$1000,$C18,'1_原始數據'!$D$2:$D$1000,4)=0,"",SUMIFS('1_原始數據'!$K$2:$K$1000,'1_原始數據'!$B$2:$B$1000,$B18,'1_原始數據'!$C$2:$C$1000,$C18,'1_原始數據'!$D$2:$D$1000,4)) | J18: =IF(COUNTIFS('1_原始數據'!$B$2:$B$1000,$B18,'1_原始數據'!$C$2:$C$1000,$C18,'1_原始數據'!$D$2:$D$1000,5)=0,"",SUMIFS('1_原始數據'!$K$2:$K$1000,'1_原始數據'!$B$2:$B$1000,$B18,'1_原始數據'!$C$2:$C$1000,$C18,'1_原始數據'!$D$2:$D$1000,5)) | K18: =IF(COUNTIFS('1_原始數據'!$B$2:$B$1000,$B18,'1_原始數據'!$C$2:$C$1000,$C18,'1_原始數據'!$D$2:$D$1000,6)=0,"",SUMIFS('1_原始數據'!$K$2:$K$1000,'1_原始數據'!$B$2:$B$1000,$B18,'1_原始數據'!$C$2:$C$1000,$C18,'1_原始數據'!$D$2:$D$1000,6)) | L18: =IF(COUNTIFS('1_原始數據'!$B$2:$B$1000,$B18,'1_原始數據'!$C$2:$C$1000,$C18,'1_原始數據'!$D$2:$D$1000,7)=0,"",SUMIFS('1_原始數據'!$K$2:$K$1000,'1_原始數據'!$B$2:$B$1000,$B18,'1_原始數據'!$C$2:$C$1000,$C18,'1_原始數據'!$D$2:$D$1000,7)) | M18: =IF(COUNTIFS('1_原始數據'!$B$2:$B$1000,$B18,'1_原始數據'!$C$2:$C$1000,$C18,'1_原始數據'!$D$2:$D$1000,8)=0,"",SUMIFS('1_原始數據'!$K$2:$K$1000,'1_原始數據'!$B$2:$B$1000,$B18,'1_原始數據'!$C$2:$C$1000,$C18,'1_原始數據'!$D$2:$D$1000,8)) | N18: =IF(COUNTIFS('1_原始數據'!$B$2:$B$1000,$B18,'1_原始數據'!$C$2:$C$1000,$C18,'1_原始數據'!$D$2:$D$1000,9)=0,"",SUMIFS('1_原始數據'!$K$2:$K$1000,'1_原始數據'!$B$2:$B$1000,$B18,'1_原始數據'!$C$2:$C$1000,$C18,'1_原始數據'!$D$2:$D$1000,9)) | O18: =IF(COUNTIFS('1_原始數據'!$B$2:$B$1000,$B18,'1_原始數據'!$C$2:$C$1000,$C18,'1_原始數據'!$D$2:$D$1000,10)=0,"",SUMIFS('1_原始數據'!$K$2:$K$1000,'1_原始數據'!$B$2:$B$1000,$B18,'1_原始數據'!$C$2:$C$1000,$C18,'1_原始數據'!$D$2:$D$1000,10)) | P18: =COUNT(F18:O18) | Q18: =AVERAGE(F18:O18) | R18: =_xlfn.STDEV.S(F18:O18) | S18: =R18/Q18*100 | T18: =_xlfn.T.INV.2T(0.05,P18-1) | U18: =T18*R18/SQRT(P18) | V18: =Q18-D18 | W18: =IF(ABS(V18)<=E18,"是","否") | X18: =IF(R18<=E18/2,"是","否") | Y18: =IF(W18="是",IF(X18="是","準確且精密","準確但不精密"),IF(X18="是","精密但不準確","不準確且不精密")) | Z18: =FIXED(Q18,MAX(0,1-INT(LOG10(ABS(U18)))))&" ± "&FIXED(U18,MAX(0,1-INT(LOG10(ABS(U18)))))&" mL"
A19: 5 | B19: G5_S3 | C19: pipette_10mL | D19: =IF(C19="pipette_10mL",10,IF(C19="burette_25mL",25,"")) | E19: =IF(C19="pipette_10mL",0.02,IF(C19="burette_25mL",0.05,"")) | F19: =IF(COUNTIFS('1_原始數據'!$B$2:$B$1000,$B19,'1_原始數據'!$C$2:$C$1000,$C19,'1_原始數據'!$D$2:$D$1000,1)=0,"",SUMIFS('1_原始數據'!$K$2:$K$1000,'1_原始數據'!$B$2:$B$1000,$B19,'1_原始數據'!$C$2:$C$1000,$C19,'1_原始數據'!$D$2:$D$1000,1)) | G19: =IF(COUNTIFS('1_原始數據'!$B$2:$B$1000,$B19,'1_原始數據'!$C$2:$C$1000,$C19,'1_原始數據'!$D$2:$D$1000,2)=0,"",SUMIFS('1_原始數據'!$K$2:$K$1000,'1_原始數據'!$B$2:$B$1000,$B19,'1_原始數據'!$C$2:$C$1000,$C19,'1_原始數據'!$D$2:$D$1000,2)) | H19: =IF(COUNTIFS('1_原始數據'!$B$2:$B$1000,$B19,'1_原始數據'!$C$2:$C$1000,$C19,'1_原始數據'!$D$2:$D$1000,3)=0,"",SUMIFS('1_原始數據'!$K$2:$K$1000,'1_原始數據'!$B$2:$B$1000,$B19,'1_原始數據'!$C$2:$C$1000,$C19,'1_原始數據'!$D$2:$D$1000,3)) | I19: =IF(COUNTIFS('1_原始數據'!$B$2:$B$1000,$B19,'1_原始數據'!$C$2:$C$1000,$C19,'1_原始數據'!$D$2:$D$1000,4)=0,"",SUMIFS('1_原始數據'!$K$2:$K$1000,'1_原始數據'!$B$2:$B$1000,$B19,'1_原始數據'!$C$2:$C$1000,$C19,'1_原始數據'!$D$2:$D$1000,4)) | J19: =IF(COUNTIFS('1_原始數據'!$B$2:$B$1000,$B19,'1_原始數據'!$C$2:$C$1000,$C19,'1_原始數據'!$D$2:$D$1000,5)=0,"",SUMIFS('1_原始數據'!$K$2:$K$1000,'1_原始數據'!$B$2:$B$1000,$B19,'1_原始數據'!$C$2:$C$1000,$C19,'1_原始數據'!$D$2:$D$1000,5)) | K19: =IF(COUNTIFS('1_原始數據'!$B$2:$B$1000,$B19,'1_原始數據'!$C$2:$C$1000,$C19,'1_原始數據'!$D$2:$D$1000,6)=0,"",SUMIFS('1_原始數據'!$K$2:$K$1000,'1_原始數據'!$B$2:$B$1000,$B19,'1_原始數據'!$C$2:$C$1000,$C19,'1_原始數據'!$D$2:$D$1000,6)) | L19: =IF(COUNTIFS('1_原始數據'!$B$2:$B$1000,$B19,'1_原始數據'!$C$2:$C$1000,$C19,'1_原始數據'!$D$2:$D$1000,7)=0,"",SUMIFS('1_原始數據'!$K$2:$K$1000,'1_原始數據'!$B$2:$B$1000,$B19,'1_原始數據'!$C$2:$C$1000,$C19,'1_原始數據'!$D$2:$D$1000,7)) | M19: =IF(COUNTIFS('1_原始數據'!$B$2:$B$1000,$B19,'1_原始數據'!$C$2:$C$1000,$C19,'1_原始數據'!$D$2:$D$1000,8)=0,"",SUMIFS('1_原始數據'!$K$2:$K$1000,'1_原始數據'!$B$2:$B$1000,$B19,'1_原始數據'!$C$2:$C$1000,$C19,'1_原始數據'!$D$2:$D$1000,8)) | N19: =IF(COUNTIFS('1_原始數據'!$B$2:$B$1000,$B19,'1_原始數據'!$C$2:$C$1000,$C19,'1_原始數據'!$D$2:$D$1000,9)=0,"",SUMIFS('1_原始數據'!$K$2:$K$1000,'1_原始數據'!$B$2:$B$1000,$B19,'1_原始數據'!$C$2:$C$1000,$C19,'1_原始數據'!$D$2:$D$1000,9)) | O19: =IF(COUNTIFS('1_原始數據'!$B$2:$B$1000,$B19,'1_原始數據'!$C$2:$C$1000,$C19,'1_原始數據'!$D$2:$D$1000,10)=0,"",SUMIFS('1_原始數據'!$K$2:$K$1000,'1_原始數據'!$B$2:$B$1000,$B19,'1_原始數據'!$C$2:$C$1000,$C19,'1_原始數據'!$D$2:$D$1000,10)) | P19: =COUNT(F19:O19) | Q19: =AVERAGE(F19:O19) | R19: =_xlfn.STDEV.S(F19:O19) | S19: =R19/Q19*100 | T19: =_xlfn.T.INV.2T(0.05,P19-1) | U19: =T19*R19/SQRT(P19) | V19: =Q19-D19 | W19: =IF(ABS(V19)<=E19,"是","否") | X19: =IF(R19<=E19/2,"是","否") | Y19: =IF(W19="是",IF(X19="是","準確且精密","準確但不精密"),IF(X19="是","精密但不準確","不準確且不精密")) | Z19: =FIXED(Q19,MAX(0,1-INT(LOG10(ABS(U19)))))&" ± "&FIXED(U19,MAX(0,1-INT(LOG10(ABS(U19)))))&" mL"
