Workbook

Sheet 0_說明
B1: EX02｜W2 水分與水活性
B2: 食品分析實驗・入門數據分析（Excel 版）。不用寫程式；同一份數據在 Colab 筆記本做進階分析，答案應該一致。
B4: 學習目標
B5: • 由空盤、盤+樣品、乾燥後的秤重，算出濕基 (wet basis) 與乾基 (dry basis) 水分 %。
B6: • 用「連續兩次秤重差 ≤ 2 mg」判斷是否達恆重，決定要不要再烘一次、該用哪一次的重量。
B7: • 用 AVERAGEIFS、STDEV.S 算各組平均、SD、RSD%。
B8: • 用成對 t 檢定（T.DIST.2T）判斷紅外線水分計和烘箱法有沒有系統性偏差 (bias)。
B9: • 用散佈圖說明「水分％相同 ≠ 水活性 aw 相同」，並對照微生物生長下限。
B10: • 分析全學期共同盲樣（全脂奶粉）的班級數據 (n = 5 組)。
B11: • （延伸）用真實麵條數據畫等溫吸濕曲線，判斷 BET／GAB 算出的單分子層水 Xm 撐不撐得住（「8_吸濕曲線」）。
B12: 顏色代表什麼
C13: 黃色：輸入或貼上數據的地方
C14: 綠色：公式，會自動計算，不要改
C15: 橘色：重點結果，寫報告時用
B17: 操作步驟
B18: 1. 看「1_原始數據」：一列是一次秤重或一次讀值，item 欄告訴你是哪一種。
B19: 2. 看「2_濕基乾基」：用講義例題熟悉公式，再用恆重計算器練習判斷。
B20: 3. 看「3_烘箱法恆重」：每位同學一列，自動判定恆重並算出濕基、乾基水分。
B21: 4. 看「4_各組統計」：各組（各食品）的平均、SD、RSD%。
B22: 5. 看「5_烘箱vs紅外線」：成對 t 檢定與差異圖。
B23: 6. 看「6_水活性」與「7_共同盲樣」：aw vs 水分散佈圖、奶粉盲樣的班級平均。
B24: 7. 完成「練習題」。
B25: 8. 換成班級數據：把共用 Google Sheet 的數據貼到「1_原始數據」A2 起；名單不同就改「3_烘箱法恆重」A–C 欄、「4_各組統計」A–B 欄、「6_水活性」A–B 欄。
B27: 對答案：用內建範例數據時，你的結果應該等於
B28: 項目 | C28: 本檔計算值 | D28: Colab 筆記本的值 | E28: 一致？
B29: G1_S1 牛肉乾 濕基水分 (%) | C29: ='3_烘箱法恆重'!Q5 | D29: 20.420624 | E29: =IF(ABS(C29-D29)<=0.002042063415196735,"✔ 一致","✘ 不一致（換成班級數據後本來就會不同）")
B30: G1_S1 牛肉乾 乾基水分 (%) | C30: ='3_烘箱法恆重'!R5 | D30: 25.660699 | E30: =IF(ABS(C30-D30)<=0.002566070906223345,"✔ 一致","✘ 不一致（換成班級數據後本來就會不同）")
B31: G3_S2 白吐司 濕基水分（用第 3 次秤重）(%) | C31: ='3_烘箱法恆重'!Q12 | D31: 35.281321 | E31: =IF(ABS(C31-D31)<=0.0035281331071887754,"✔ 一致","✘ 不一致（換成班級數據後本來就會不同）")
B32: 白吐司（第 3 組）RSD (%) | C32: ='4_各組統計'!F7 | D32: 1.5218552 | E32: =IF(ABS(C32-D32)<=0.00015218652362701012,"✔ 一致","✘ 不一致（換成班級數據後本來就會不同）")
B33: 洋芋片（第 4 組）RSD (%) | C33: ='4_各組統計'!F8 | D33: 25.836074 | E33: =IF(ABS(C33-D33)<=0.0025836084398943608,"✔ 一致","✘ 不一致（換成班級數據後本來就會不同）")
B34: 平均偏差 IR − 烘箱 (%) | C34: ='5_烘箱vs紅外線'!J6 | D34: -0.49861903 | E34: =IF(ABS(C34-D34)<=4.986290314390424e-05,"✔ 一致","✘ 不一致（換成班級數據後本來就會不同）")
B35: 成對 t 值 | C35: ='5_烘箱vs紅外線'!J9 | D35: -8.6443869 | E35: =IF(ABS(C35-D35)<=0.0008644396893055584,"✔ 一致","✘ 不一致（換成班級數據後本來就會不同）")
B36: 全脂奶粉盲樣 RSD (%) | C36: ='7_共同盲樣'!B15 | D36: 16.953688 | E36: =IF(ABS(C36-D36)<=0.0016953697744064955,"✔ 一致","✘ 不一致（換成班級數據後本來就會不同）")
B37: 「Colab 筆記本的值」是用內建模擬數據算出的答案；換成全班數據後，這一欄就不再適用。
B39: 相關連結
B40: 本週實驗投影片 | C40: https://tai-shengyeh.github.io/food-analysis-lab/labs/w02_moisture/index.html
B41: 進階：Colab 筆記本（Python） | C41: https://colab.research.google.com/github/Tai-ShengYeh/food-analysis-lab/blob/main/notebooks/NB02_moisture_aw.ipynb
B42: 數據分析工具指南（Excel／Orange／Colab） | C42: https://tai-shengyeh.github.io/food-analysis-lab/tools.html
B43: 延伸：麵條等溫吸濕曲線（互動網頁） | C43: https://tai-shengyeh.github.io/food-analysis-lab/labs/w02_moisture/isotherm.html
B44: 小提醒
...

Sheet 1_原始數據
A1: group | B1: student | C1: item | D1: rep | E1: value | F1: unit | G1: temp_C | H1: note | I1: sample | K1: 這張工作表怎麼用
A2: 1 | B2: G1_S1 | C2: oven_dish_g | D2: 1 | E2: 18.8698 | F2: g | G2: 103.4 | I2: beef_jerky | K2: 本週欄位：item＝量測項目。oven_dish_g 空盤重、oven_wet_g 盤+樣品重、oven_dry1_g／dry2_g／dry3_g 第 1／2／3 次乾燥後（盤+乾樣品）重，單位 g；ir_moisture_pct 紅外線水分計讀值 (%)；moisture_pct_survey 與 aw_reading 是全班 6 種食品的快速水分 (%) 與水活性 aw。
A3: 1 | B3: G1_S1 | C3: oven_wet_g | D3: 1 | E3: 21.8178 | F3: g | G3: 103.4 | I3: beef_jerky | K3: sample＝食品樣品名稱（beef_jerky 牛肉乾、dried_longan 龍眼乾、white_bread 白吐司、potato_chips 洋芋片、milk_powder 全脂奶粉、honey 蜂蜜）。
A4: 1 | B4: G1_S1 | C4: oven_dry1_g | D4: 1 | E4: 21.2171 | F4: g | G4: 103.4 | I4: beef_jerky | K4: 本週沒有需要換算的欄位，所以沒有綠色欄；計算都在後面的工作表。
A5: 1 | B5: G1_S1 | C5: oven_dry2_g | D5: 1 | E5: 21.2158 | F5: g | G5: 103.4 | H5: 第2次與第1次秤重差 ≤ 2 mg，達恆重 | I5: beef_jerky | K5: 黃色欄位＝原始數據。換成全班數據時：從共用 Google Sheet 複製，貼到 A2（欄位順序必須一樣），舊資料多出來的列要整列刪除。
A6: 1 | B6: G1_S1 | C6: ir_moisture_pct | D6: 1 | E6: 19.63 | F6: % | G6: 25.5 | I6: beef_jerky | K6: 綠色欄位＝公式，會自動算到第 1000 列，不要手動修改。
A7: 1 | B7: G1_S2 | C7: oven_dish_g | D7: 1 | E7: 18.9303 | F7: g | G7: 105.6 | I7: beef_jerky
A8: 1 | B8: G1_S2 | C8: oven_wet_g | D8: 1 | E8: 21.9295 | F8: g | G8: 105.6 | I8: beef_jerky
A9: 1 | B9: G1_S2 | C9: oven_dry1_g | D9: 1 | E9: 21.3425 | F9: g | G9: 105.6 | I9: beef_jerky
A10: 1 | B10: G1_S2 | C10: oven_dry2_g | D10: 1 | E10: 21.3418 | F10: g | G10: 105.6 | H10: 第2次與第1次秤重差 ≤ 2 mg，達恆重 | I10: beef_jerky
A11: 1 | B11: G1_S2 | C11: ir_moisture_pct | D11: 1 | E11: 19.22 | F11: % | G11: 25.6 | I11: beef_jerky
A12: 1 | B12: G1_S3 | C12: oven_dish_g | D12: 1 | E12: 17.2171 | F12: g | G12: 105.7 | I12: beef_jerky
A13: 1 | B13: G1_S3 | C13: oven_wet_g | D13: 1 | E13: 20.1741 | F13: g | G13: 105.7 | I13: beef_jerky
A14: 1 | B14: G1_S3 | C14: oven_dry1_g | D14: 1 | E14: 19.5772 | F14: g | G14: 105.7 | I14: beef_jerky
A15: 1 | B15: G1_S3 | C15: oven_dry2_g | D15: 1 | E15: 19.577 | F15: g | G15: 105.7 | H15: 第2次與第1次秤重差 ≤ 2 mg，達恆重 | I15: beef_jerky
A16: 1 | B16: G1_S3 | C16: ir_moisture_pct | D16: 1 | E16: 19.78 | F16: % | G16: 25.5 | I16: beef_jerky
A17: 2 | B17: G2_S1 | C17: oven_dish_g | D17: 1 | E17: 16.7726 | F17: g | G17: 104.7 | I17: dried_longan
A18: 2 | B18: G2_S1 | C18: oven_wet_g | D18: 1 | E18: 19.8337 | F18: g | G18: 104.7 | I18: dried_longan
A19: 2 | B19: G2_S1 | C19: oven_dry1_g | D19: 1 | E19: 19.2238 | F19: g | G19: 104.7 | I19: dried_longan
A20: 2 | B20: G2_S1 | C20: oven_dry2_g | D20: 1 | E20: 19.2224 | F20: g | G20: 104.7 | H20: 第2次與第1次秤重差 ≤ 2 mg，達恆重 | I20: dried_longan
A21: 2 | B21: G2_S1 | C21: ir_moisture_pct | D21: 1 | E21: 19.73 | F21: % | G21: 24.1 | I21: dried_longan
A22: 2 | B22: G2_S2 | C22: oven_dish_g | D22: 1 | E22: 15.7714 | F22: g | G22: 104.6 | I22: dried_longan
A23: 2 | B23: G2_S2 | C23: oven_wet_g | D23: 1 | E23: 18.7929 | F23: g | G23: 104.6 | I23: dried_longan
A24: 2 | B24: G2_S2 | C24: oven_dry1_g | D24: 1 | E24: 18.1562 | F24: g | G24: 104.6 | I24: dried_longan
A25: 2 | B25: G2_S2 | C25: oven_dry2_g | D25: 1 | E25: 18.1545 | F25: g | G25: 104.6 | H25: 第2次與第1次秤重差 ≤ 2 mg，達恆重 | I25: dried_longan
A26: 2 | B26: G2_S2 | C26: ir_moisture_pct | D26: 1 | E26: 20.48 | F26: % | G26: 24.9 | I26: dried_longan
A27: 2 | B27: G2_S3 | C27: oven_dish_g | D27: 1 | E27: 15.9474 | F27: g | G27: 105.5 | I27: dried_longan
A28: 2 | B28: G2_S3 | C28: oven_wet_g | D28: 1 | E28: 18.9417 | F28: g | G28: 105.5 | I28: dried_longan
A29: 2 | B29: G2_S3 | C29: oven_dry1_g | D29: 1 | E29: 18.3554 | F29: g | G29: 105.5 | I29: dried_longan
A30: 2 | B30: G2_S3 | C30: oven_dry2_g | D30: 1 | E30: 18.3549 | F30: g | G30: 105.5 | H30: 第2次與第1次秤重差 ≤ 2 mg，達恆重 | I30: dried_longan
A31: 2 | B31: G2_S3 | C31: ir_moisture_pct | D31: 1 | E31: 19.42 | F31: % | G31: 25.7 | I31: dried_longan
A32: 3 | B32: G3_S1 | C32: oven_dish_g | D32: 1 | E32: 18.5013 | F32: g | G32: 105.1 | I32: white_bread
A33: 3 | B33: G3_S1 | C33: oven_wet_g | D33: 1 | E33: 21.5285 | F33: g | G33: 105.1 | I33: white_bread
A34: 3 | B34: G3_S1 | C34: oven_dry1_g | D34: 1 | E34: 20.4791 | F34: g | G34: 105.1 | I34: white_bread
A35: 3 | B35: G3_S1 | C35: oven_dry2_g | D35: 1 | E35: 20.4776 | F35: g | G35: 105.1 | H35: 第2次與第1次秤重差 ≤ 2 mg，達恆重 | I35: white_bread
A36: 3 | B36: G3_S1 | C36: ir_moisture_pct | D36: 1 | E36: 34.38 | F36: % | G36: 25.4 | I36: white_bread
A37: 3 | B37: G3_S2 | C37: oven_dish_g | D37: 1 | E37: 15.6988 | F37: g | G37: 103.8 | I37: white_bread
A38: 3 | B38: G3_S2 | C38: oven_wet_g | D38: 1 | E38: 18.7327 | F38: g | G38: 103.8 | I38: white_bread
A39: 3 | B39: G3_S2 | C39: oven_dry1_g | D39: 1 | E39: 17.6698 | F39: g | G39: 103.8 | I39: white_bread
A40: 3 | B40: G3_S2 | C40: oven_dry2_g | D40: 1 | E40: 17.6634 | F40: g | G40: 103.8 | H40: 第2次與第1次秤重差 > 2 mg，尚未恆重，需再烘1小時 | I40: white_bread
...

Sheet 2_濕基乾基
B1: 步驟 1 濕基與乾基水分、恆重判定
B2: 先用講義的例題熟悉公式，再用恆重計算器練習判斷「要不要再烘一次」。黃色格子可以改，綠色會自動算。
B4: 參數
B5: 恆重判準（連續兩次秤重差 ≤） | C5: 2 | D5: mg | E5: 本課程 SOP：連續兩次乾燥後秤重差 ≤ 2 mg（0.002 g）才算恆重。各實驗室規定可能不同，改這一格，後面所有判定都會跟著變。
B7: 例題（課程講義數字）
B8: 項目 | C8: 數值 | D8: 單位 | E8: 公式說明
B9: 空盤重 | C9: 25.1234 | D9: g | E9: 鋁盤（或坩堝）本身的重量
B10: 盤 + 樣品重 | C10: 28.1234 | D10: g | E10: 烘之前秤
B11: 乾燥後（盤 + 乾樣品）重 | C11: 27.9734 | D11: g | E11: 達恆重後那一次的重量
B12: 樣品濕重 W濕 | C12: =C10-C9 | D12: g | E12: = 盤+樣品 − 空盤
B13: 水分重 | C13: =C10-C11 | D13: g | E13: = 盤+樣品 − 乾燥後。烘掉的就是水
B14: 乾固形物重 W乾 | C14: =C11-C9 | D14: g | E14: = 乾燥後 − 空盤（也等於 樣品濕重 − 水分重）
B15: 濕基水分 (%) | C15: =C13/C12*100 | D15: % | E15: = 水分重 ÷ 樣品濕重 × 100。分母是「原本的濕樣品」。應為 5.00%
B16: 乾基水分 (%) | C16: =C13/C14*100 | D16: % | E16: = 水分重 ÷ 乾固形物重 × 100。分母是「烘乾後剩下的固形物」。應為 5.26%
B17: 由濕基換算乾基 (%) | C17: =C15/(100-C15)*100 | D17: % | E17: = 濕基 ÷ (100 − 濕基) × 100。跟上一格一樣，代表兩者可以互換
B19: 觀察：同一份樣品，乾基一定比濕基大，因為分母比較小。水分越高差越多（白吐司濕基 35% ≈ 乾基 54%）。報告時一定要寫清楚是哪一種基準。
B21: 恆重計算器（輸入連續三次乾燥後的秤重）
B22: 項目 | C22: 數值 | D22: 單位 | E22: 公式說明
B23: 第 1 次乾燥後重 | C23: 17.6698 | D23: g | E23: 預設是 G3_S2 白吐司的數據（本週唯一需要第三次秤重的人）
B24: 第 2 次乾燥後重 | C24: 17.6634 | D24: g
B25: 第 3 次乾燥後重（沒有就留空） | C25: 17.6623 | D25: g | E25: 第 2 次已恆重就不必再烘，這格留空
B26: 第 1→2 次差 | C26: =ROUND(ABS(C24-C23)*1000,1) | D26: mg | E26: =ROUND(ABS(第2次−第1次)×1000, 1) ABS 取絕對值，×1000 把 g 換成 mg，ROUND 四捨五入到 0.1 mg（天平的最小讀數）
B27: 第 2→3 次差 | C27: =IF(C25="","",ROUND(ABS(C25-C24)*1000,1)) | D27: mg | E27: 沒有第 3 次就顯示空白
B28: 判定 | C28: =IF(C26<='2_濕基乾基'!$C$5,"第 2 次達恆重，用第 2 次重量",IF(C25="","尚未恆重，需再烘 1 小時",IF(C27<='2_濕基乾基'!$C$5,"第 3 次達恆重，用第 3 次重量","第 3 次仍未恆重，需再烘"))) | E28: IF(條件, 成立時, 不成立時)：先看 1→2 次差是否 ≤ 判準；不是的話再看有沒有第 3 次、2→3 次差是否 ≤ 判準
B29: 計算水分要用的乾重 | C29: =IF(C26<='2_濕基乾基'!$C$5,C24,IF(C25="",C24,C25)) | D29: g | E29: 達恆重的那一次重量（最後一次秤重）

Sheet 3_烘箱法恆重
A1: 步驟 2 每位同學的烘箱法：恆重判定 → 濕基／乾基水分
A2: D–H 欄用 SUMIFS 從「1_原始數據」依「學生＋樣品＋項目」抓秤重值（第 3 列是項目代號）；沒有這筆數據就顯示空白。換成班級數據時，只改 A–C 欄（黃色）。人數不同：在表格「中間」插入或刪除整列，再把上一列的綠色公式往下複製。
D3: oven_dish_g | E3: oven_wet_g | F3: oven_dry1_g | G3: oven_dry2_g | H3: oven_dry3_g
A4: 組別 | B4: 學生 | C4: 樣品 | D4: 空盤重 (g) | E4: 盤+樣品 (g) | F4: 第1次乾燥 (g) | G4: 第2次乾燥 (g) | H4: 第3次乾燥 (g) | I4: 1→2 次差 (mg) | J4: 2→3 次差 (mg) | K4: 恆重判定 | L4: 採用第幾次 | M4: 最終乾重 (g) | N4: 樣品濕重 (g) | O4: 水分重 (g) | P4: 乾固形物重 (g) | Q4: 濕基水分 (%) | R4: 乾基水分 (%)
A5: 1 | B5: G1_S1 | C5: beef_jerky | D5: =IF(COUNTIFS('1_原始數據'!$B$2:$B$1000,$B5,'1_原始數據'!$I$2:$I$1000,$C5,'1_原始數據'!$C$2:$C$1000,D$3)=0,"",SUMIFS('1_原始數據'!$E$2:$E$1000,'1_原始數據'!$B$2:$B$1000,$B5,'1_原始數據'!$I$2:$I$1000,$C5,'1_原始數據'!$C$2:$C$1000,D$3)) | E5: =IF(COUNTIFS('1_原始數據'!$B$2:$B$1000,$B5,'1_原始數據'!$I$2:$I$1000,$C5,'1_原始數據'!$C$2:$C$1000,E$3)=0,"",SUMIFS('1_原始數據'!$E$2:$E$1000,'1_原始數據'!$B$2:$B$1000,$B5,'1_原始數據'!$I$2:$I$1000,$C5,'1_原始數據'!$C$2:$C$1000,E$3)) | F5: =IF(COUNTIFS('1_原始數據'!$B$2:$B$1000,$B5,'1_原始數據'!$I$2:$I$1000,$C5,'1_原始數據'!$C$2:$C$1000,F$3)=0,"",SUMIFS('1_原始數據'!$E$2:$E$1000,'1_原始數據'!$B$2:$B$1000,$B5,'1_原始數據'!$I$2:$I$1000,$C5,'1_原始數據'!$C$2:$C$1000,F$3)) | G5: =IF(COUNTIFS('1_原始數據'!$B$2:$B$1000,$B5,'1_原始數據'!$I$2:$I$1000,$C5,'1_原始數據'!$C$2:$C$1000,G$3)=0,"",SUMIFS('1_原始數據'!$E$2:$E$1000,'1_原始數據'!$B$2:$B$1000,$B5,'1_原始數據'!$I$2:$I$1000,$C5,'1_原始數據'!$C$2:$C$1000,G$3)) | H5: =IF(COUNTIFS('1_原始數據'!$B$2:$B$1000,$B5,'1_原始數據'!$I$2:$I$1000,$C5,'1_原始數據'!$C$2:$C$1000,H$3)=0,"",SUMIFS('1_原始數據'!$E$2:$E$1000,'1_原始數據'!$B$2:$B$1000,$B5,'1_原始數據'!$I$2:$I$1000,$C5,'1_原始數據'!$C$2:$C$1000,H$3)) | I5: =ROUND(ABS(G5-F5)*1000,1) | J5: =IF(H5="","",ROUND(ABS(H5-G5)*1000,1)) | K5: =IF(I5<='2_濕基乾基'!$C$5,"第2次達恆重",IF(H5="","尚未恆重，需再烘",IF(J5<='2_濕基乾基'!$C$5,"第3次達恆重","第3次仍未恆重，需再烘"))) | L5: =IF(I5<='2_濕基乾基'!$C$5,2,IF(H5="",2,3)) | M5: =IF(L5=3,H5,G5) | N5: =E5-D5 | O5: =E5-M5 | P5: =M5-D5 | Q5: =O5/N5*100 | R5: =O5/P5*100
A6: 1 | B6: G1_S2 | C6: beef_jerky | D6: =IF(COUNTIFS('1_原始數據'!$B$2:$B$1000,$B6,'1_原始數據'!$I$2:$I$1000,$C6,'1_原始數據'!$C$2:$C$1000,D$3)=0,"",SUMIFS('1_原始數據'!$E$2:$E$1000,'1_原始數據'!$B$2:$B$1000,$B6,'1_原始數據'!$I$2:$I$1000,$C6,'1_原始數據'!$C$2:$C$1000,D$3)) | E6: =IF(COUNTIFS('1_原始數據'!$B$2:$B$1000,$B6,'1_原始數據'!$I$2:$I$1000,$C6,'1_原始數據'!$C$2:$C$1000,E$3)=0,"",SUMIFS('1_原始數據'!$E$2:$E$1000,'1_原始數據'!$B$2:$B$1000,$B6,'1_原始數據'!$I$2:$I$1000,$C6,'1_原始數據'!$C$2:$C$1000,E$3)) | F6: =IF(COUNTIFS('1_原始數據'!$B$2:$B$1000,$B6,'1_原始數據'!$I$2:$I$1000,$C6,'1_原始數據'!$C$2:$C$1000,F$3)=0,"",SUMIFS('1_原始數據'!$E$2:$E$1000,'1_原始數據'!$B$2:$B$1000,$B6,'1_原始數據'!$I$2:$I$1000,$C6,'1_原始數據'!$C$2:$C$1000,F$3)) | G6: =IF(COUNTIFS('1_原始數據'!$B$2:$B$1000,$B6,'1_原始數據'!$I$2:$I$1000,$C6,'1_原始數據'!$C$2:$C$1000,G$3)=0,"",SUMIFS('1_原始數據'!$E$2:$E$1000,'1_原始數據'!$B$2:$B$1000,$B6,'1_原始數據'!$I$2:$I$1000,$C6,'1_原始數據'!$C$2:$C$1000,G$3)) | H6: =IF(COUNTIFS('1_原始數據'!$B$2:$B$1000,$B6,'1_原始數據'!$I$2:$I$1000,$C6,'1_原始數據'!$C$2:$C$1000,H$3)=0,"",SUMIFS('1_原始數據'!$E$2:$E$1000,'1_原始數據'!$B$2:$B$1000,$B6,'1_原始數據'!$I$2:$I$1000,$C6,'1_原始數據'!$C$2:$C$1000,H$3)) | I6: =ROUND(ABS(G6-F6)*1000,1) | J6: =IF(H6="","",ROUND(ABS(H6-G6)*1000,1)) | K6: =IF(I6<='2_濕基乾基'!$C$5,"第2次達恆重",IF(H6="","尚未恆重，需再烘",IF(J6<='2_濕基乾基'!$C$5,"第3次達恆重","第3次仍未恆重，需再烘"))) | L6: =IF(I6<='2_濕基乾基'!$C$5,2,IF(H6="",2,3)) | M6: =IF(L6=3,H6,G6) | N6: =E6-D6 | O6: =E6-M6 | P6: =M6-D6 | Q6: =O6/N6*100 | R6: =O6/P6*100
A7: 1 | B7: G1_S3 | C7: beef_jerky | D7: =IF(COUNTIFS('1_原始數據'!$B$2:$B$1000,$B7,'1_原始數據'!$I$2:$I$1000,$C7,'1_原始數據'!$C$2:$C$1000,D$3)=0,"",SUMIFS('1_原始數據'!$E$2:$E$1000,'1_原始數據'!$B$2:$B$1000,$B7,'1_原始數據'!$I$2:$I$1000,$C7,'1_原始數據'!$C$2:$C$1000,D$3)) | E7: =IF(COUNTIFS('1_原始數據'!$B$2:$B$1000,$B7,'1_原始數據'!$I$2:$I$1000,$C7,'1_原始數據'!$C$2:$C$1000,E$3)=0,"",SUMIFS('1_原始數據'!$E$2:$E$1000,'1_原始數據'!$B$2:$B$1000,$B7,'1_原始數據'!$I$2:$I$1000,$C7,'1_原始數據'!$C$2:$C$1000,E$3)) | F7: =IF(COUNTIFS('1_原始數據'!$B$2:$B$1000,$B7,'1_原始數據'!$I$2:$I$1000,$C7,'1_原始數據'!$C$2:$C$1000,F$3)=0,"",SUMIFS('1_原始數據'!$E$2:$E$1000,'1_原始數據'!$B$2:$B$1000,$B7,'1_原始數據'!$I$2:$I$1000,$C7,'1_原始數據'!$C$2:$C$1000,F$3)) | G7: =IF(COUNTIFS('1_原始數據'!$B$2:$B$1000,$B7,'1_原始數據'!$I$2:$I$1000,$C7,'1_原始數據'!$C$2:$C$1000,G$3)=0,"",SUMIFS('1_原始數據'!$E$2:$E$1000,'1_原始數據'!$B$2:$B$1000,$B7,'1_原始數據'!$I$2:$I$1000,$C7,'1_原始數據'!$C$2:$C$1000,G$3)) | H7: =IF(COUNTIFS('1_原始數據'!$B$2:$B$1000,$B7,'1_原始數據'!$I$2:$I$1000,$C7,'1_原始數據'!$C$2:$C$1000,H$3)=0,"",SUMIFS('1_原始數據'!$E$2:$E$1000,'1_原始數據'!$B$2:$B$1000,$B7,'1_原始數據'!$I$2:$I$1000,$C7,'1_原始數據'!$C$2:$C$1000,H$3)) | I7: =ROUND(ABS(G7-F7)*1000,1) | J7: =IF(H7="","",ROUND(ABS(H7-G7)*1000,1)) | K7: =IF(I7<='2_濕基乾基'!$C$5,"第2次達恆重",IF(H7="","尚未恆重，需再烘",IF(J7<='2_濕基乾基'!$C$5,"第3次達恆重","第3次仍未恆重，需再烘"))) | L7: =IF(I7<='2_濕基乾基'!$C$5,2,IF(H7="",2,3)) | M7: =IF(L7=3,H7,G7) | N7: =E7-D7 | O7: =E7-M7 | P7: =M7-D7 | Q7: =O7/N7*100 | R7: =O7/P7*100
A8: 2 | B8: G2_S1 | C8: dried_longan | D8: =IF(COUNTIFS('1_原始數據'!$B$2:$B$1000,$B8,'1_原始數據'!$I$2:$I$1000,$C8,'1_原始數據'!$C$2:$C$1000,D$3)=0,"",SUMIFS('1_原始數據'!$E$2:$E$1000,'1_原始數據'!$B$2:$B$1000,$B8,'1_原始數據'!$I$2:$I$1000,$C8,'1_原始數據'!$C$2:$C$1000,D$3)) | E8: =IF(COUNTIFS('1_原始數據'!$B$2:$B$1000,$B8,'1_原始數據'!$I$2:$I$1000,$C8,'1_原始數據'!$C$2:$C$1000,E$3)=0,"",SUMIFS('1_原始數據'!$E$2:$E$1000,'1_原始數據'!$B$2:$B$1000,$B8,'1_原始數據'!$I$2:$I$1000,$C8,'1_原始數據'!$C$2:$C$1000,E$3)) | F8: =IF(COUNTIFS('1_原始數據'!$B$2:$B$1000,$B8,'1_原始數據'!$I$2:$I$1000,$C8,'1_原始數據'!$C$2:$C$1000,F$3)=0,"",SUMIFS('1_原始數據'!$E$2:$E$1000,'1_原始數據'!$B$2:$B$1000,$B8,'1_原始數據'!$I$2:$I$1000,$C8,'1_原始數據'!$C$2:$C$1000,F$3)) | G8: =IF(COUNTIFS('1_原始數據'!$B$2:$B$1000,$B8,'1_原始數據'!$I$2:$I$1000,$C8,'1_原始數據'!$C$2:$C$1000,G$3)=0,"",SUMIFS('1_原始數據'!$E$2:$E$1000,'1_原始數據'!$B$2:$B$1000,$B8,'1_原始數據'!$I$2:$I$1000,$C8,'1_原始數據'!$C$2:$C$1000,G$3)) | H8: =IF(COUNTIFS('1_原始數據'!$B$2:$B$1000,$B8,'1_原始數據'!$I$2:$I$1000,$C8,'1_原始數據'!$C$2:$C$1000,H$3)=0,"",SUMIFS('1_原始數據'!$E$2:$E$1000,'1_原始數據'!$B$2:$B$1000,$B8,'1_原始數據'!$I$2:$I$1000,$C8,'1_原始數據'!$C$2:$C$1000,H$3)) | I8: =ROUND(ABS(G8-F8)*1000,1) | J8: =IF(H8="","",ROUND(ABS(H8-G8)*1000,1)) | K8: =IF(I8<='2_濕基乾基'!$C$5,"第2次達恆重",IF(H8="","尚未恆重，需再烘",IF(J8<='2_濕基乾基'!$C$5,"第3次達恆重","第3次仍未恆重，需再烘"))) | L8: =IF(I8<='2_濕基乾基'!$C$5,2,IF(H8="",2,3)) | M8: =IF(L8=3,H8,G8) | N8: =E8-D8 | O8: =E8-M8 | P8: =M8-D8 | Q8: =O8/N8*100 | R8: =O8/P8*100
A9: 2 | B9: G2_S2 | C9: dried_longan | D9: =IF(COUNTIFS('1_原始數據'!$B$2:$B$1000,$B9,'1_原始數據'!$I$2:$I$1000,$C9,'1_原始數據'!$C$2:$C$1000,D$3)=0,"",SUMIFS('1_原始數據'!$E$2:$E$1000,'1_原始數據'!$B$2:$B$1000,$B9,'1_原始數據'!$I$2:$I$1000,$C9,'1_原始數據'!$C$2:$C$1000,D$3)) | E9: =IF(COUNTIFS('1_原始數據'!$B$2:$B$1000,$B9,'1_原始數據'!$I$2:$I$1000,$C9,'1_原始數據'!$C$2:$C$1000,E$3)=0,"",SUMIFS('1_原始數據'!$E$2:$E$1000,'1_原始數據'!$B$2:$B$1000,$B9,'1_原始數據'!$I$2:$I$1000,$C9,'1_原始數據'!$C$2:$C$1000,E$3)) | F9: =IF(COUNTIFS('1_原始數據'!$B$2:$B$1000,$B9,'1_原始數據'!$I$2:$I$1000,$C9,'1_原始數據'!$C$2:$C$1000,F$3)=0,"",SUMIFS('1_原始數據'!$E$2:$E$1000,'1_原始數據'!$B$2:$B$1000,$B9,'1_原始數據'!$I$2:$I$1000,$C9,'1_原始數據'!$C$2:$C$1000,F$3)) | G9: =IF(COUNTIFS('1_原始數據'!$B$2:$B$1000,$B9,'1_原始數據'!$I$2:$I$1000,$C9,'1_原始數據'!$C$2:$C$1000,G$3)=0,"",SUMIFS('1_原始數據'!$E$2:$E$1000,'1_原始數據'!$B$2:$B$1000,$B9,'1_原始數據'!$I$2:$I$1000,$C9,'1_原始數據'!$C$2:$C$1000,G$3)) | H9: =IF(COUNTIFS('1_原始數據'!$B$2:$B$1000,$B9,'1_原始數據'!$I$2:$I$1000,$C9,'1_原始數據'!$C$2:$C$1000,H$3)=0,"",SUMIFS('1_原始數據'!$E$2:$E$1000,'1_原始數據'!$B$2:$B$1000,$B9,'1_原始數據'!$I$2:$I$1000,$C9,'1_原始數據'!$C$2:$C$1000,H$3)) | I9: =ROUND(ABS(G9-F9)*1000,1) | J9: =IF(H9="","",ROUND(ABS(H9-G9)*1000,1)) | K9: =IF(I9<='2_濕基乾基'!$C$5,"第2次達恆重",IF(H9="","尚未恆重，需再烘",IF(J9<='2_濕基乾基'!$C$5,"第3次達恆重","第3次仍未恆重，需再烘"))) | L9: =IF(I9<='2_濕基乾基'!$C$5,2,IF(H9="",2,3)) | M9: =IF(L9=3,H9,G9) | N9: =E9-D9 | O9: =E9-M9 | P9: =M9-D9 | Q9: =O9/N9*100 | R9: =O9/P9*100
A10: 2 | B10: G2_S3 | C10: dried_longan | D10: =IF(COUNTIFS('1_原始數據'!$B$2:$B$1000,$B10,'1_原始數據'!$I$2:$I$1000,$C10,'1_原始數據'!$C$2:$C$1000,D$3)=0,"",SUMIFS('1_原始數據'!$E$2:$E$1000,'1_原始數據'!$B$2:$B$1000,$B10,'1_原始數據'!$I$2:$I$1000,$C10,'1_原始數據'!$C$2:$C$1000,D$3)) | E10: =IF(COUNTIFS('1_原始數據'!$B$2:$B$1000,$B10,'1_原始數據'!$I$2:$I$1000,$C10,'1_原始數據'!$C$2:$C$1000,E$3)=0,"",SUMIFS('1_原始數據'!$E$2:$E$1000,'1_原始數據'!$B$2:$B$1000,$B10,'1_原始數據'!$I$2:$I$1000,$C10,'1_原始數據'!$C$2:$C$1000,E$3)) | F10: =IF(COUNTIFS('1_原始數據'!$B$2:$B$1000,$B10,'1_原始數據'!$I$2:$I$1000,$C10,'1_原始數據'!$C$2:$C$1000,F$3)=0,"",SUMIFS('1_原始數據'!$E$2:$E$1000,'1_原始數據'!$B$2:$B$1000,$B10,'1_原始數據'!$I$2:$I$1000,$C10,'1_原始數據'!$C$2:$C$1000,F$3)) | G10: =IF(COUNTIFS('1_原始數據'!$B$2:$B$1000,$B10,'1_原始數據'!$I$2:$I$1000,$C10,'1_原始數據'!$C$2:$C$1000,G$3)=0,"",SUMIFS('1_原始數據'!$E$2:$E$1000,'1_原始數據'!$B$2:$B$1000,$B10,'1_原始數據'!$I$2:$I$1000,$C10,'1_原始數據'!$C$2:$C$1000,G$3)) | H10: =IF(COUNTIFS('1_原始數據'!$B$2:$B$1000,$B10,'1_原始數據'!$I$2:$I$1000,$C10,'1_原始數據'!$C$2:$C$1000,H$3)=0,"",SUMIFS('1_原始數據'!$E$2:$E$1000,'1_原始數據'!$B$2:$B$1000,$B10,'1_原始數據'!$I$2:$I$1000,$C10,'1_原始數據'!$C$2:$C$1000,H$3)) | I10: =ROUND(ABS(G10-F10)*1000,1) | J10: =IF(H10="","",ROUND(ABS(H10-G10)*1000,1)) | K10: =IF(I10<='2_濕基乾基'!$C$5,"第2次達恆重",IF(H10="","尚未恆重，需再烘",IF(J10<='2_濕基乾基'!$C$5,"第3次達恆重","第3次仍未恆重，需再烘"))) | L10: =IF(I10<='2_濕基乾基'!$C$5,2,IF(H10="",2,3)) | M10: =IF(L10=3,H10,G10) | N10: =E10-D10 | O10: =E10-M10 | P10: =M10-D10 | Q10: =O10/N10*100 | R10: =O10/P10*100
A11: 3 | B11: G3_S1 | C11: white_bread | D11: =IF(COUNTIFS('1_原始數據'!$B$2:$B$1000,$B11,'1_原始數據'!$I$2:$I$1000,$C11,'1_原始數據'!$C$2:$C$1000,D$3)=0,"",SUMIFS('1_原始數據'!$E$2:$E$1000,'1_原始數據'!$B$2:$B$1000,$B11,'1_原始數據'!$I$2:$I$1000,$C11,'1_原始數據'!$C$2:$C$1000,D$3)) | E11: =IF(COUNTIFS('1_原始數據'!$B$2:$B$1000,$B11,'1_原始數據'!$I$2:$I$1000,$C11,'1_原始數據'!$C$2:$C$1000,E$3)=0,"",SUMIFS('1_原始數據'!$E$2:$E$1000,'1_原始數據'!$B$2:$B$1000,$B11,'1_原始數據'!$I$2:$I$1000,$C11,'1_原始數據'!$C$2:$C$1000,E$3)) | F11: =IF(COUNTIFS('1_原始數據'!$B$2:$B$1000,$B11,'1_原始數據'!$I$2:$I$1000,$C11,'1_原始數據'!$C$2:$C$1000,F$3)=0,"",SUMIFS('1_原始數據'!$E$2:$E$1000,'1_原始數據'!$B$2:$B$1000,$B11,'1_原始數據'!$I$2:$I$1000,$C11,'1_原始數據'!$C$2:$C$1000,F$3)) | G11: =IF(COUNTIFS('1_原始數據'!$B$2:$B$1000,$B11,'1_原始數據'!$I$2:$I$1000,$C11,'1_原始數據'!$C$2:$C$1000,G$3)=0,"",SUMIFS('1_原始數據'!$E$2:$E$1000,'1_原始數據'!$B$2:$B$1000,$B11,'1_原始數據'!$I$2:$I$1000,$C11,'1_原始數據'!$C$2:$C$1000,G$3)) | H11: =IF(COUNTIFS('1_原始數據'!$B$2:$B$1000,$B11,'1_原始數據'!$I$2:$I$1000,$C11,'1_原始數據'!$C$2:$C$1000,H$3)=0,"",SUMIFS('1_原始數據'!$E$2:$E$1000,'1_原始數據'!$B$2:$B$1000,$B11,'1_原始數據'!$I$2:$I$1000,$C11,'1_原始數據'!$C$2:$C$1000,H$3)) | I11: =ROUND(ABS(G11-F11)*1000,1) | J11: =IF(H11="","",ROUND(ABS(H11-G11)*1000,1)) | K11: =IF(I11<='2_濕基乾基'!$C$5,"第2次達恆重",IF(H11="","尚未恆重，需再烘",IF(J11<='2_濕基乾基'!$C$5,"第3次達恆重","第3次仍未恆重，需再烘"))) | L11: =IF(I11<='2_濕基乾基'!$C$5,2,IF(H11="",2,3)) | M11: =IF(L11=3,H11,G11) | N11: =E11-D11 | O11: =E11-M11 | P11: =M11-D11 | Q11: =O11/N11*100 | R11: =O11/P11*100
A12: 3 | B12: G3_S2 | C12: white_bread | D12: =IF(COUNTIFS('1_原始數據'!$B$2:$B$1000,$B12,'1_原始數據'!$I$2:$I$1000,$C12,'1_原始數據'!$C$2:$C$1000,D$3)=0,"",SUMIFS('1_原始數據'!$E$2:$E$1000,'1_原始數據'!$B$2:$B$1000,$B12,'1_原始數據'!$I$2:$I$1000,$C12,'1_原始數據'!$C$2:$C$1000,D$3)) | E12: =IF(COUNTIFS('1_原始數據'!$B$2:$B$1000,$B12,'1_原始數據'!$I$2:$I$1000,$C12,'1_原始數據'!$C$2:$C$1000,E$3)=0,"",SUMIFS('1_原始數據'!$E$2:$E$1000,'1_原始數據'!$B$2:$B$1000,$B12,'1_原始數據'!$I$2:$I$1000,$C12,'1_原始數據'!$C$2:$C$1000,E$3)) | F12: =IF(COUNTIFS('1_原始數據'!$B$2:$B$1000,$B12,'1_原始數據'!$I$2:$I$1000,$C12,'1_原始數據'!$C$2:$C$1000,F$3)=0,"",SUMIFS('1_原始數據'!$E$2:$E$1000,'1_原始數據'!$B$2:$B$1000,$B12,'1_原始數據'!$I$2:$I$1000,$C12,'1_原始數據'!$C$2:$C$1000,F$3)) | G12: =IF(COUNTIFS('1_原始數據'!$B$2:$B$1000,$B12,'1_原始數據'!$I$2:$I$1000,$C12,'1_原始數據'!$C$2:$C$1000,G$3)=0,"",SUMIFS('1_原始數據'!$E$2:$E$1000,'1_原始數據'!$B$2:$B$1000,$B12,'1_原始數據'!$I$2:$I$1000,$C12,'1_原始數據'!$C$2:$C$1000,G$3)) | H12: =IF(COUNTIFS('1_原始數據'!$B$2:$B$1000,$B12,'1_原始數據'!$I$2:$I$1000,$C12,'1_原始數據'!$C$2:$C$1000,H$3)=0,"",SUMIFS('1_原始數據'!$E$2:$E$1000,'1_原始數據'!$B$2:$B$1000,$B12,'1_原始數據'!$I$2:$I$1000,$C12,'1_原始數據'!$C$2:$C$1000,H$3)) | I12: =ROUND(ABS(G12-F12)*1000,1) | J12: =IF(H12="","",ROUND(ABS(H12-G12)*1000,1)) | K12: =IF(I12<='2_濕基乾基'!$C$5,"第2次達恆重",IF(H12="","尚未恆重，需再烘",IF(J12<='2_濕基乾基'!$C$5,"第3次達恆重","第3次仍未恆重，需再烘"))) | L12: =IF(I12<='2_濕基乾基'!$C$5,2,IF(H12="",2,3)) | M12: =IF(L12=3,H12,G12) | N12: =E12-D12 | O12: =E12-M12 | P12: =M12-D12 | Q12: =O12/N12*100 | R12: =O12/P12*100
A13: 3 | B13: G3_S3 | C13: white_bread | D13: =IF(COUNTIFS('1_原始數據'!$B$2:$B$1000,$B13,'1_原始數據'!$I$2:$I$1000,$C13,'1_原始數據'!$C$2:$C$1000,D$3)=0,"",SUMIFS('1_原始數據'!$E$2:$E$1000,'1_原始數據'!$B$2:$B$1000,$B13,'1_原始數據'!$I$2:$I$1000,$C13,'1_原始數據'!$C$2:$C$1000,D$3)) | E13: =IF(COUNTIFS('1_原始數據'!$B$2:$B$1000,$B13,'1_原始數據'!$I$2:$I$1000,$C13,'1_原始數據'!$C$2:$C$1000,E$3)=0,"",SUMIFS('1_原始數據'!$E$2:$E$1000,'1_原始數據'!$B$2:$B$1000,$B13,'1_原始數據'!$I$2:$I$1000,$C13,'1_原始數據'!$C$2:$C$1000,E$3)) | F13: =IF(COUNTIFS('1_原始數據'!$B$2:$B$1000,$B13,'1_原始數據'!$I$2:$I$1000,$C13,'1_原始數據'!$C$2:$C$1000,F$3)=0,"",SUMIFS('1_原始數據'!$E$2:$E$1000,'1_原始數據'!$B$2:$B$1000,$B13,'1_原始數據'!$I$2:$I$1000,$C13,'1_原始數據'!$C$2:$C$1000,F$3)) | G13: =IF(COUNTIFS('1_原始數據'!$B$2:$B$1000,$B13,'1_原始數據'!$I$2:$I$1000,$C13,'1_原始數據'!$C$2:$C$1000,G$3)=0,"",SUMIFS('1_原始數據'!$E$2:$E$1000,'1_原始數據'!$B$2:$B$1000,$B13,'1_原始數據'!$I$2:$I$1000,$C13,'1_原始數據'!$C$2:$C$1000,G$3)) | H13: =IF(COUNTIFS('1_原始數據'!$B$2:$B$1000,$B13,'1_原始數據'!$I$2:$I$1000,$C13,'1_原始數據'!$C$2:$C$1000,H$3)=0,"",SUMIFS('1_原始數據'!$E$2:$E$1000,'1_原始數據'!$B$2:$B$1000,$B13,'1_原始數據'!$I$2:$I$1000,$C13,'1_原始數據'!$C$2:$C$1000,H$3)) | I13: =ROUND(ABS(G13-F13)*1000,1) | J13: =IF(H13="","",ROUND(ABS(H13-G13)*1000,1)) | K13: =IF(I13<='2_濕基乾基'!$C$5,"第2次達恆重",IF(H13="","尚未恆重，需再烘",IF(J13<='2_濕基乾基'!$C$5,"第3次達恆重","第3次仍未恆重，需再烘"))) | L13: =IF(I13<='2_濕基乾基'!$C$5,2,IF(H13="",2,3)) | M13: =IF(L13=3,H13,G13) | N13: =E13-D13 | O13: =E13-M13 | P13: =M13-D13 | Q13: =O13/N13*100 | R13: =O13/P13*100
A14: 4 | B14: G4_S1 | C14: potato_chips | D14: =IF(COUNTIFS('1_原始數據'!$B$2:$B$1000,$B14,'1_原始數據'!$I$2:$I$1000,$C14,'1_原始數據'!$C$2:$C$1000,D$3)=0,"",SUMIFS('1_原始數據'!$E$2:$E$1000,'1_原始數據'!$B$2:$B$1000,$B14,'1_原始數據'!$I$2:$I$1000,$C14,'1_原始數據'!$C$2:$C$1000,D$3)) | E14: =IF(COUNTIFS('1_原始數據'!$B$2:$B$1000,$B14,'1_原始數據'!$I$2:$I$1000,$C14,'1_原始數據'!$C$2:$C$1000,E$3)=0,"",SUMIFS('1_原始數據'!$E$2:$E$1000,'1_原始數據'!$B$2:$B$1000,$B14,'1_原始數據'!$I$2:$I$1000,$C14,'1_原始數據'!$C$2:$C$1000,E$3)) | F14: =IF(COUNTIFS('1_原始數據'!$B$2:$B$1000,$B14,'1_原始數據'!$I$2:$I$1000,$C14,'1_原始數據'!$C$2:$C$1000,F$3)=0,"",SUMIFS('1_原始數據'!$E$2:$E$1000,'1_原始數據'!$B$2:$B$1000,$B14,'1_原始數據'!$I$2:$I$1000,$C14,'1_原始數據'!$C$2:$C$1000,F$3)) | G14: =IF(COUNTIFS('1_原始數據'!$B$2:$B$1000,$B14,'1_原始數據'!$I$2:$I$1000,$C14,'1_原始數據'!$C$2:$C$1000,G$3)=0,"",SUMIFS('1_原始數據'!$E$2:$E$1000,'1_原始數據'!$B$2:$B$1000,$B14,'1_原始數據'!$I$2:$I$1000,$C14,'1_原始數據'!$C$2:$C$1000,G$3)) | H14: =IF(COUNTIFS('1_原始數據'!$B$2:$B$1000,$B14,'1_原始數據'!$I$2:$I$1000,$C14,'1_原始數據'!$C$2:$C$1000,H$3)=0,"",SUMIFS('1_原始數據'!$E$2:$E$1000,'1_原始數據'!$B$2:$B$1000,$B14,'1_原始數據'!$I$2:$I$1000,$C14,'1_原始數據'!$C$2:$C$1000,H$3)) | I14: =ROUND(ABS(G14-F14)*1000,1) | J14: =IF(H14="","",ROUND(ABS(H14-G14)*1000,1)) | K14: =IF(I14<='2_濕基乾基'!$C$5,"第2次達恆重",IF(H14="","尚未恆重，需再烘",IF(J14<='2_濕基乾基'!$C$5,"第3次達恆重","第3次仍未恆重，需再烘"))) | L14: =IF(I14<='2_濕基乾基'!$C$5,2,IF(H14="",2,3)) | M14: =IF(L14=3,H14,G14) | N14: =E14-D14 | O14: =E14-M14 | P14: =M14-D14 | Q14: =O14/N14*100 | R14: =O14/P14*100
A15: 4 | B15: G4_S2 | C15: potato_chips | D15: =IF(COUNTIFS('1_原始數據'!$B$2:$B$1000,$B15,'1_原始數據'!$I$2:$I$1000,$C15,'1_原始數據'!$C$2:$C$1000,D$3)=0,"",SUMIFS('1_原始數據'!$E$2:$E$1000,'1_原始數據'!$B$2:$B$1000,$B15,'1_原始數據'!$I$2:$I$1000,$C15,'1_原始數據'!$C$2:$C$1000,D$3)) | E15: =IF(COUNTIFS('1_原始數據'!$B$2:$B$1000,$B15,'1_原始數據'!$I$2:$I$1000,$C15,'1_原始數據'!$C$2:$C$1000,E$3)=0,"",SUMIFS('1_原始數據'!$E$2:$E$1000,'1_原始數據'!$B$2:$B$1000,$B15,'1_原始數據'!$I$2:$I$1000,$C15,'1_原始數據'!$C$2:$C$1000,E$3)) | F15: =IF(COUNTIFS('1_原始數據'!$B$2:$B$1000,$B15,'1_原始數據'!$I$2:$I$1000,$C15,'1_原始數據'!$C$2:$C$1000,F$3)=0,"",SUMIFS('1_原始數據'!$E$2:$E$1000,'1_原始數據'!$B$2:$B$1000,$B15,'1_原始數據'!$I$2:$I$1000,$C15,'1_原始數據'!$C$2:$C$1000,F$3)) | G15: =IF(COUNTIFS('1_原始數據'!$B$2:$B$1000,$B15,'1_原始數據'!$I$2:$I$1000,$C15,'1_原始數據'!$C$2:$C$1000,G$3)=0,"",SUMIFS('1_原始數據'!$E$2:$E$1000,'1_原始數據'!$B$2:$B$1000,$B15,'1_原始數據'!$I$2:$I$1000,$C15,'1_原始數據'!$C$2:$C$1000,G$3)) | H15: =IF(COUNTIFS('1_原始數據'!$B$2:$B$1000,$B15,'1_原始數據'!$I$2:$I$1000,$C15,'1_原始數據'!$C$2:$C$1000,H$3)=0,"",SUMIFS('1_原始數據'!$E$2:$E$1000,'1_原始數據'!$B$2:$B$1000,$B15,'1_原始數據'!$I$2:$I$1000,$C15,'1_原始數據'!$C$2:$C$1000,H$3)) | I15: =ROUND(ABS(G15-F15)*1000,1) | J15: =IF(H15="","",ROUND(ABS(H15-G15)*1000,1)) | K15: =IF(I15<='2_濕基乾基'!$C$5,"第2次達恆重",IF(H15="","尚未恆重，需再烘",IF(J15<='2_濕基乾基'!$C$5,"第3次達恆重","第3次仍未恆重，需再烘"))) | L15: =IF(I15<='2_濕基乾基'!$C$5,2,IF(H15="",2,3)) | M15: =IF(L15=3,H15,G15) | N15: =E15-D15 | O15: =E15-M15 | P15: =M15-D15 | Q15: =O15/N15*100 | R15: =O15/P15*100
A16: 4 | B16: G4_S3 | C16: potato_chips | D16: =IF(COUNTIFS('1_原始數據'!$B$2:$B$1000,$B16,'1_原始數據'!$I$2:$I$1000,$C16,'1_原始數據'!$C$2:$C$1000,D$3)=0,"",SUMIFS('1_原始數據'!$E$2:$E$1000,'1_原始數據'!$B$2:$B$1000,$B16,'1_原始數據'!$I$2:$I$1000,$C16,'1_原始數據'!$C$2:$C$1000,D$3)) | E16: =IF(COUNTIFS('1_原始數據'!$B$2:$B$1000,$B16,'1_原始數據'!$I$2:$I$1000,$C16,'1_原始數據'!$C$2:$C$1000,E$3)=0,"",SUMIFS('1_原始數據'!$E$2:$E$1000,'1_原始數據'!$B$2:$B$1000,$B16,'1_原始數據'!$I$2:$I$1000,$C16,'1_原始數據'!$C$2:$C$1000,E$3)) | F16: =IF(COUNTIFS('1_原始數據'!$B$2:$B$1000,$B16,'1_原始數據'!$I$2:$I$1000,$C16,'1_原始數據'!$C$2:$C$1000,F$3)=0,"",SUMIFS('1_原始數據'!$E$2:$E$1000,'1_原始數據'!$B$2:$B$1000,$B16,'1_原始數據'!$I$2:$I$1000,$C16,'1_原始數據'!$C$2:$C$1000,F$3)) | G16: =IF(COUNTIFS('1_原始數據'!$B$2:$B$1000,$B16,'1_原始數據'!$I$2:$I$1000,$C16,'1_原始數據'!$C$2:$C$1000,G$3)=0,"",SUMIFS('1_原始數據'!$E$2:$E$1000,'1_原始數據'!$B$2:$B$1000,$B16,'1_原始數據'!$I$2:$I$1000,$C16,'1_原始數據'!$C$2:$C$1000,G$3)) | H16: =IF(COUNTIFS('1_原始數據'!$B$2:$B$1000,$B16,'1_原始數據'!$I$2:$I$1000,$C16,'1_原始數據'!$C$2:$C$1000,H$3)=0,"",SUMIFS('1_原始數據'!$E$2:$E$1000,'1_原始數據'!$B$2:$B$1000,$B16,'1_原始數據'!$I$2:$I$1000,$C16,'1_原始數據'!$C$2:$C$1000,H$3)) | I16: =ROUND(ABS(G16-F16)*1000,1) | J16: =IF(H16="","",ROUND(ABS(H16-G16)*1000,1)) | K16: =IF(I16<='2_濕基乾基'!$C$5,"第2次達恆重",IF(H16="","尚未恆重，需再烘",IF(J16<='2_濕基乾基'!$C$5,"第3次達恆重","第3次仍未恆重，需再烘"))) | L16: =IF(I16<='2_濕基乾基'!$C$5,2,IF(H16="",2,3)) | M16: =IF(L16=3,H16,G16) | N16: =E16-D16 | O16: =E16-M16 | P16: =M16-D16 | Q16: =O16/N16*100 | R16: =O16/P16*100
... A19: 5 | B19: G5_S3 | C19: milk_powder | D19: =IF(COUNTIFS('1_原始數據'!$B$2:$B$1000,$B19,'1_原始數據'!$I$2:$I$1000,$C19,'1_原始數據'!$C$2:$C$1000,D$3)=0,"",SUMIFS('1_原始數據'!$E$2:$E$1000,'1_原始數據'!$B$2:$B$1000,$B19,'1_原始數據'!$I$2:$I$1000,$C19,'1_原始數據'!$C$2:$C$1000,D$3)) | E19: =IF(COUNTIFS('1_原始數據'!$B$2:$B$1000,$B19,'1_原始數據'!$I$2:$I$1000,$C19,'1_原始數據'!$C$2:$C$1000,E$3)=0,"",SUMIFS('1_原始數據'!$E$2:$E$1000,'1_原始數據'!$B$2:$B$1000,$B19,'1_原始數據'!$I$2:$I$1000,$C19,'1_原始數據'!$C$2:$C$1000,E$3)) | F19: =IF(COUNTIFS('1_原始數據'!$B$2:$B$1000,$B19,'1_原始數據'!$I$2:$I$1000,$C19,'1_原始數據'!$C$2:$C$1000,F$3)=0,"",SUMIFS('1_原始數據'!$E$2:$E$1000,'1_原始數據'!$B$2:$B$1000,$B19,'1_原始數據'!$I$2:$I$1000,$C19,'1_原始數據'!$C$2:$C$1000,F$3)) | G19: =IF(COUNTIFS('1_原始數據'!$B$2:$B$1000,$B19,'1_原始數據'!$I$2:$I$1000,$C19,'1_原始數據'!$C$2:$C$1000,G$3)=0,"",SUMIFS('1_原始數據'!$E$2:$E$1000,'1_原始數據'!$B$2:$B$1000,$B19,'1_原始數據'!$I$2:$I$1000,$C19,'1_原始數據'!$C$2:$C$1000,G$3)) | H19: =IF(COUNTIFS('1_原始數據'!$B$2:$B$1000,$B19,'1_原始數據'!$I$2:$I$1000,$C19,'1_原始數據'!$C$2:$C$1000,H$3)=0,"",SUMIFS('1_原始數據'!$E$2:$E$1000,'1_原始數據'!$B$2:$B$1000,$B19,'1_原始數據'!$I$2:$I$1000,$C19,'1_原始數據'!$C$2:$C$1000,H$3)) | I19: =ROUND(ABS(G19-F19)*1000,1) | J19: =IF(H19="","",ROUND(ABS(H19-G19)*1000,1)) | K19: =IF(I19<='2_濕基乾基'!$C$5,"第2次達恆重",IF(H19="","尚未恆重，需再烘",IF(J19<='2_濕基乾基'!$C$5,"第3次達恆重","第3次仍未恆重，需再烘"))) | L19: =IF(I19<='2_濕基乾基'!$C$5,2,IF(H19="",2,3)) | M19: =IF(L19=3,H19,G19) | N19: =E19-D19 | O19: =E19-M19 | P19: =M19-D19 | Q19: =O19/N19*100 | R19: =O19/P19*100
A21: 公式說明
A22: 抓數據 | D22: =SUMIFS(原始數據value, student,B5, sample,C5, item,"oven_dish_g") 把「學生、樣品、項目」三個條件都符合的數字加起來；每個條件只有一筆，所以就是把那一筆抓過來。COUNTIFS 先數有沒有這筆，沒有就顯示空白（例如大多數人沒有第 3 次秤重）。
A23: 秤重差 | D23: =ROUND(ABS(G5−F5)×1000, 1) 兩次秤重差的絕對值，換成 mg，四捨五入到 0.1 mg。
A24: 恆重判定 | D24: 1→2 次差 ≤ 判準（「2_濕基乾基」C5，預設 2 mg）＝第 2 次達恆重；否則看第 3 次。黃底＝用了第 3 次；紅底＝還沒恆重，要回烘箱。
A25: 最終乾重 | D25: 達恆重的那一次（盤+乾樣品）重量。只有 G3_S2 用到第 3 次。
A26: 濕基 % | D26: = 水分重 ÷ 樣品濕重 × 100 = (盤+樣品 − 最終乾重) ÷ (盤+樣品 − 空盤) × 100
A27: 乾基 % | D27: = 水分重 ÷ 乾固形物重 × 100 = (盤+樣品 − 最終乾重) ÷ (最終乾重 − 空盤) × 100

Sheet 4_各組統計
A1: 步驟 3 各組（各食品）濕基水分的平均、SD、RSD%
A2: 每組 3 位同學測同一種食品＝組內三重複。資料來自「3_烘箱法恆重」的濕基水分（Q 欄）。
A4: 組別 | B4: 樣品 | C4: n | D4: 平均濕基 (%) | E4: SD (%) | F4: RSD (%)
A5: 1 | B5: beef_jerky | C5: =COUNTIFS('3_烘箱法恆重'!$A$5:$A$19,A5,'3_烘箱法恆重'!$C$5:$C$19,B5) | D5: =AVERAGEIFS('3_烘箱法恆重'!$Q$5:$Q$19,'3_烘箱法恆重'!$A$5:$A$19,A5,'3_烘箱法恆重'!$C$5:$C$19,B5) | E5: {=_xlfn.STDEV.S(IF(('3_烘箱法恆重'!$A$5:$A$19=A5)*('3_烘箱法恆重'!$C$5:$C$19=B5),'3_烘箱法恆重'!$Q$5:$Q$19))} | F5: =E5/D5*100 | H5: COUNTIFS 數有幾位同學；AVERAGEIFS 依「組別＋樣品」兩個條件取平均。
A6: 2 | B6: dried_longan | C6: =COUNTIFS('3_烘箱法恆重'!$A$5:$A$19,A6,'3_烘箱法恆重'!$C$5:$C$19,B6) | D6: =AVERAGEIFS('3_烘箱法恆重'!$Q$5:$Q$19,'3_烘箱法恆重'!$A$5:$A$19,A6,'3_烘箱法恆重'!$C$5:$C$19,B6) | E6: {=_xlfn.STDEV.S(IF(('3_烘箱法恆重'!$A$5:$A$19=A6)*('3_烘箱法恆重'!$C$5:$C$19=B6),'3_烘箱法恆重'!$Q$5:$Q$19))} | F6: =E6/D6*100 | H6: Excel 沒有 STDEV.IFS，SD 用陣列公式 {=STDEV.S(IF(條件, 數值))}：只把符合條件的數字交給 STDEV.S（樣本標準差，除以 n−1）。自己輸入時，舊版 Excel 按 Ctrl+Shift+Enter；Excel 365 直接 Enter。
A7: 3 | B7: white_bread | C7: =COUNTIFS('3_烘箱法恆重'!$A$5:$A$19,A7,'3_烘箱法恆重'!$C$5:$C$19,B7) | D7: =AVERAGEIFS('3_烘箱法恆重'!$Q$5:$Q$19,'3_烘箱法恆重'!$A$5:$A$19,A7,'3_烘箱法恆重'!$C$5:$C$19,B7) | E7: {=_xlfn.STDEV.S(IF(('3_烘箱法恆重'!$A$5:$A$19=A7)*('3_烘箱法恆重'!$C$5:$C$19=B7),'3_烘箱法恆重'!$Q$5:$Q$19))} | F7: =E7/D7*100 | H7: RSD = SD ÷ 平均 × 100。平均很小時（洋芋片、奶粉只有 2–3% 水分），同樣 0.3–0.5% 的 SD 會讓 RSD 變很大——低水分樣品的 RSD 大，不一定代表操作比較差。
A8: 4 | B8: potato_chips | C8: =COUNTIFS('3_烘箱法恆重'!$A$5:$A$19,A8,'3_烘箱法恆重'!$C$5:$C$19,B8) | D8: =AVERAGEIFS('3_烘箱法恆重'!$Q$5:$Q$19,'3_烘箱法恆重'!$A$5:$A$19,A8,'3_烘箱法恆重'!$C$5:$C$19,B8) | E8: {=_xlfn.STDEV.S(IF(('3_烘箱法恆重'!$A$5:$A$19=A8)*('3_烘箱法恆重'!$C$5:$C$19=B8),'3_烘箱法恆重'!$Q$5:$Q$19))} | F8: =E8/D8*100
A9: 5 | B9: milk_powder | C9: =COUNTIFS('3_烘箱法恆重'!$A$5:$A$19,A9,'3_烘箱法恆重'!$C$5:$C$19,B9) | D9: =AVERAGEIFS('3_烘箱法恆重'!$Q$5:$Q$19,'3_烘箱法恆重'!$A$5:$A$19,A9,'3_烘箱法恆重'!$C$5:$C$19,B9) | E9: {=_xlfn.STDEV.S(IF(('3_烘箱法恆重'!$A$5:$A$19=A9)*('3_烘箱法恆重'!$C$5:$C$19=B9),'3_烘箱法恆重'!$Q$5:$Q$19))} | F9: =E9/D9*100
A11: RSD 最大（精密度最差） | D11: =INDEX(B5:B9,MATCH(MAX(F5:F9),F5:F9,0)) | E11: =MAX(F5:F9) | H11: INDEX(樣品欄, MATCH(MAX(RSD欄), RSD欄, 0))：先找出最大 RSD 在第幾列，再回傳那一列的樣品名稱。
A12: RSD 最小（精密度最好） | D12: =INDEX(B5:B9,MATCH(MIN(F5:F9),F5:F9,0)) | E12: =MIN(F5:F9)

Sheet 5_烘箱vs紅外線
A1: 步驟 4 烘箱法 vs 紅外線水分計：成對比較（paired t-test）
A2: 同一位同學、同一份樣品，用兩種方法各測一次，所以數據是「一對一對」的。把每一對相減得到「差」，再檢定這些差的平均是不是 0。烘箱法是參考法，差的平均＝紅外線水分計的偏差 (bias)。
M3: 圖用輔助數據（自動計算）
A4: 組別 | B4: 學生 | C4: 樣品 | D4: 烘箱濕基 (%) | E4: 紅外線 IR (%) | F4: 差 IR − 烘箱 | G4: 兩法平均 (%) | I4: 項目 | J4: 數值 | K4: 公式說明 | M4: x | N4: bias 線 | O4: 0 線
A5: ='3_烘箱法恆重'!A5 | B5: ='3_烘箱法恆重'!B5 | C5: ='3_烘箱法恆重'!C5 | D5: ='3_烘箱法恆重'!Q5 | E5: =IF(COUNTIFS('1_原始數據'!$B$2:$B$1000,B5,'1_原始數據'!$I$2:$I$1000,C5,'1_原始數據'!$C$2:$C$1000,"ir_moisture_pct")=0,"",SUMIFS('1_原始數據'!$E$2:$E$1000,'1_原始數據'!$B$2:$B$1000,B5,'1_原始數據'!$I$2:$I$1000,C5,'1_原始數據'!$C$2:$C$1000,"ir_moisture_pct")) | F5: =E5-D5 | G5: =(D5+E5)/2 | I5: 成對數 n | J5: =COUNT(F5:F19) | K5: COUNT 數有幾個數字（幾對） | M5: =0 | N5: =$J$6 | O5: =0
A6: ='3_烘箱法恆重'!A6 | B6: ='3_烘箱法恆重'!B6 | C6: ='3_烘箱法恆重'!C6 | D6: ='3_烘箱法恆重'!Q6 | E6: =IF(COUNTIFS('1_原始數據'!$B$2:$B$1000,B6,'1_原始數據'!$I$2:$I$1000,C6,'1_原始數據'!$C$2:$C$1000,"ir_moisture_pct")=0,"",SUMIFS('1_原始數據'!$E$2:$E$1000,'1_原始數據'!$B$2:$B$1000,B6,'1_原始數據'!$I$2:$I$1000,C6,'1_原始數據'!$C$2:$C$1000,"ir_moisture_pct")) | F6: =E6-D6 | G6: =(D6+E6)/2 | I6: 平均差 d̄ = bias (%) | J6: =AVERAGE(F5:F19) | K6: 負值＝紅外線比烘箱法低。這就是紅外線水分計的偏差 | M6: =MAX(G5:G19)*1.05 | N6: =$J$6 | O6: =0
A7: ='3_烘箱法恆重'!A7 | B7: ='3_烘箱法恆重'!B7 | C7: ='3_烘箱法恆重'!C7 | D7: ='3_烘箱法恆重'!Q7 | E7: =IF(COUNTIFS('1_原始數據'!$B$2:$B$1000,B7,'1_原始數據'!$I$2:$I$1000,C7,'1_原始數據'!$C$2:$C$1000,"ir_moisture_pct")=0,"",SUMIFS('1_原始數據'!$E$2:$E$1000,'1_原始數據'!$B$2:$B$1000,B7,'1_原始數據'!$I$2:$I$1000,C7,'1_原始數據'!$C$2:$C$1000,"ir_moisture_pct")) | F7: =E7-D7 | G7: =(D7+E7)/2 | I7: 差的 SD s_d (%) | J7: =_xlfn.STDEV.S(F5:F19) | K7: STDEV.S：樣本標準差。成對比較只看「差」的變異，同一份樣品本身水分高低的差異被抵消掉了
A8: ='3_烘箱法恆重'!A8 | B8: ='3_烘箱法恆重'!B8 | C8: ='3_烘箱法恆重'!C8 | D8: ='3_烘箱法恆重'!Q8 | E8: =IF(COUNTIFS('1_原始數據'!$B$2:$B$1000,B8,'1_原始數據'!$I$2:$I$1000,C8,'1_原始數據'!$C$2:$C$1000,"ir_moisture_pct")=0,"",SUMIFS('1_原始數據'!$E$2:$E$1000,'1_原始數據'!$B$2:$B$1000,B8,'1_原始數據'!$I$2:$I$1000,C8,'1_原始數據'!$C$2:$C$1000,"ir_moisture_pct")) | F8: =E8-D8 | G8: =(D8+E8)/2 | I8: 平均差的標準誤 SE (%) | J8: =J7/SQRT(J5) | K8: = s_d ÷ √n
A9: ='3_烘箱法恆重'!A9 | B9: ='3_烘箱法恆重'!B9 | C9: ='3_烘箱法恆重'!C9 | D9: ='3_烘箱法恆重'!Q9 | E9: =IF(COUNTIFS('1_原始數據'!$B$2:$B$1000,B9,'1_原始數據'!$I$2:$I$1000,C9,'1_原始數據'!$C$2:$C$1000,"ir_moisture_pct")=0,"",SUMIFS('1_原始數據'!$E$2:$E$1000,'1_原始數據'!$B$2:$B$1000,B9,'1_原始數據'!$I$2:$I$1000,C9,'1_原始數據'!$C$2:$C$1000,"ir_moisture_pct")) | F9: =E9-D9 | G9: =(D9+E9)/2 | I9: t 值 | J9: =J6/J8 | K9: = d̄ ÷ SE。|t| 越大，越不像「只是隨機誤差」
A10: ='3_烘箱法恆重'!A10 | B10: ='3_烘箱法恆重'!B10 | C10: ='3_烘箱法恆重'!C10 | D10: ='3_烘箱法恆重'!Q10 | E10: =IF(COUNTIFS('1_原始數據'!$B$2:$B$1000,B10,'1_原始數據'!$I$2:$I$1000,C10,'1_原始數據'!$C$2:$C$1000,"ir_moisture_pct")=0,"",SUMIFS('1_原始數據'!$E$2:$E$1000,'1_原始數據'!$B$2:$B$1000,B10,'1_原始數據'!$I$2:$I$1000,C10,'1_原始數據'!$C$2:$C$1000,"ir_moisture_pct")) | F10: =E10-D10 | G10: =(D10+E10)/2 | I10: 自由度 df | J10: =J5-1 | K10: = n − 1
A11: ='3_烘箱法恆重'!A11 | B11: ='3_烘箱法恆重'!B11 | C11: ='3_烘箱法恆重'!C11 | D11: ='3_烘箱法恆重'!Q11 | E11: =IF(COUNTIFS('1_原始數據'!$B$2:$B$1000,B11,'1_原始數據'!$I$2:$I$1000,C11,'1_原始數據'!$C$2:$C$1000,"ir_moisture_pct")=0,"",SUMIFS('1_原始數據'!$E$2:$E$1000,'1_原始數據'!$B$2:$B$1000,B11,'1_原始數據'!$I$2:$I$1000,C11,'1_原始數據'!$C$2:$C$1000,"ir_moisture_pct")) | F11: =E11-D11 | G11: =(D11+E11)/2 | I11: p 值（雙尾） | J11: =_xlfn.T.DIST.2T(ABS(J9),J10) | K11: T.DIST.2T(|t|, df)：若兩法其實沒差，碰巧得到這麼大 |t| 的機率。舊版 Excel 可用 TDIST(|t|, df, 2)
A12: ='3_烘箱法恆重'!A12 | B12: ='3_烘箱法恆重'!B12 | C12: ='3_烘箱法恆重'!C12 | D12: ='3_烘箱法恆重'!Q12 | E12: =IF(COUNTIFS('1_原始數據'!$B$2:$B$1000,B12,'1_原始數據'!$I$2:$I$1000,C12,'1_原始數據'!$C$2:$C$1000,"ir_moisture_pct")=0,"",SUMIFS('1_原始數據'!$E$2:$E$1000,'1_原始數據'!$B$2:$B$1000,B12,'1_原始數據'!$I$2:$I$1000,C12,'1_原始數據'!$C$2:$C$1000,"ir_moisture_pct")) | F12: =E12-D12 | G12: =(D12+E12)/2 | I12: 驗算：T.TEST 成對 p 值 | J12: =_xlfn.T.TEST(E5:E19,D5:D19,2,1) | K12: T.TEST(陣列1, 陣列2, 2=雙尾, 1=成對)：一步算出 p 值，應與上一格相同
A13: ='3_烘箱法恆重'!A13 | B13: ='3_烘箱法恆重'!B13 | C13: ='3_烘箱法恆重'!C13 | D13: ='3_烘箱法恆重'!Q13 | E13: =IF(COUNTIFS('1_原始數據'!$B$2:$B$1000,B13,'1_原始數據'!$I$2:$I$1000,C13,'1_原始數據'!$C$2:$C$1000,"ir_moisture_pct")=0,"",SUMIFS('1_原始數據'!$E$2:$E$1000,'1_原始數據'!$B$2:$B$1000,B13,'1_原始數據'!$I$2:$I$1000,C13,'1_原始數據'!$C$2:$C$1000,"ir_moisture_pct")) | F13: =E13-D13 | G13: =(D13+E13)/2 | I13: t 臨界值（95%） | J13: =_xlfn.T.INV.2T(0.05,J10) | K13: T.INV.2T(0.05, df)
A14: ='3_烘箱法恆重'!A14 | B14: ='3_烘箱法恆重'!B14 | C14: ='3_烘箱法恆重'!C14 | D14: ='3_烘箱法恆重'!Q14 | E14: =IF(COUNTIFS('1_原始數據'!$B$2:$B$1000,B14,'1_原始數據'!$I$2:$I$1000,C14,'1_原始數據'!$C$2:$C$1000,"ir_moisture_pct")=0,"",SUMIFS('1_原始數據'!$E$2:$E$1000,'1_原始數據'!$B$2:$B$1000,B14,'1_原始數據'!$I$2:$I$1000,C14,'1_原始數據'!$C$2:$C$1000,"ir_moisture_pct")) | F14: =E14-D14 | G14: =(D14+E14)/2 | I14: bias 的 95% CI 下限 (%) | J14: =J6-J13*J8 | K14: = d̄ − t臨界 × SE
A15: ='3_烘箱法恆重'!A15 | B15: ='3_烘箱法恆重'!B15 | C15: ='3_烘箱法恆重'!C15 | D15: ='3_烘箱法恆重'!Q15 | E15: =IF(COUNTIFS('1_原始數據'!$B$2:$B$1000,B15,'1_原始數據'!$I$2:$I$1000,C15,'1_原始數據'!$C$2:$C$1000,"ir_moisture_pct")=0,"",SUMIFS('1_原始數據'!$E$2:$E$1000,'1_原始數據'!$B$2:$B$1000,B15,'1_原始數據'!$I$2:$I$1000,C15,'1_原始數據'!$C$2:$C$1000,"ir_moisture_pct")) | F15: =E15-D15 | G15: =(D15+E15)/2 | I15: bias 的 95% CI 上限 (%) | J15: =J6+J13*J8 | K15: = d̄ + t臨界 × SE。CI 不含 0 ＝ 顯著
A16: ='3_烘箱法恆重'!A16 | B16: ='3_烘箱法恆重'!B16 | C16: ='3_烘箱法恆重'!C16 | D16: ='3_烘箱法恆重'!Q16 | E16: =IF(COUNTIFS('1_原始數據'!$B$2:$B$1000,B16,'1_原始數據'!$I$2:$I$1000,C16,'1_原始數據'!$C$2:$C$1000,"ir_moisture_pct")=0,"",SUMIFS('1_原始數據'!$E$2:$E$1000,'1_原始數據'!$B$2:$B$1000,B16,'1_原始數據'!$I$2:$I$1000,C16,'1_原始數據'!$C$2:$C$1000,"ir_moisture_pct")) | F16: =E16-D16 | G16: =(D16+E16)/2 | I16: 結論（α = 0.05） | J16: =IF(J11<0.05,"p < 0.05：兩法有顯著的系統性差異 (bias)","p ≥ 0.05：沒有足夠證據說兩法有系統性差異")
A17: ='3_烘箱法恆重'!A17 | B17: ='3_烘箱法恆重'!B17 | C17: ='3_烘箱法恆重'!C17 | D17: ='3_烘箱法恆重'!Q17 | E17: =IF(COUNTIFS('1_原始數據'!$B$2:$B$1000,B17,'1_原始數據'!$I$2:$I$1000,C17,'1_原始數據'!$C$2:$C$1000,"ir_moisture_pct")=0,"",SUMIFS('1_原始數據'!$E$2:$E$1000,'1_原始數據'!$B$2:$B$1000,B17,'1_原始數據'!$I$2:$I$1000,C17,'1_原始數據'!$C$2:$C$1000,"ir_moisture_pct")) | F17: =E17-D17 | G17: =(D17+E17)/2
A18: ='3_烘箱法恆重'!A18 | B18: ='3_烘箱法恆重'!B18 | C18: ='3_烘箱法恆重'!C18 | D18: ='3_烘箱法恆重'!Q18 | E18: =IF(COUNTIFS('1_原始數據'!$B$2:$B$1000,B18,'1_原始數據'!$I$2:$I$1000,C18,'1_原始數據'!$C$2:$C$1000,"ir_moisture_pct")=0,"",SUMIFS('1_原始數據'!$E$2:$E$1000,'1_原始數據'!$B$2:$B$1000,B18,'1_原始數據'!$I$2:$I$1000,C18,'1_原始數據'!$C$2:$C$1000,"ir_moisture_pct")) | F18: =E18-D18 | G18: =(D18+E18)/2
A19: ='3_烘箱法恆重'!A19 | B19: ='3_烘箱法恆重'!B19 | C19: ='3_烘箱法恆重'!C19 | D19: ='3_烘箱法恆重'!Q19 | E19: =IF(COUNTIFS('1_原始數據'!$B$2:$B$1000,B19,'1_原始數據'!$I$2:$I$1000,C19,'1_原始數據'!$C$2:$C$1000,"ir_moisture_pct")=0,"",SUMIFS('1_原始數據'!$E$2:$E$1000,'1_原始數據'!$B$2:$B$1000,B19,'1_原始數據'!$I$2:$I$1000,C19,'1_原始數據'!$C$2:$C$1000,"ir_moisture_pct")) | F19: =E19-D19 | G19: =(D19+E19)/2
A20: A–D 欄直接連到「3_烘箱法恆重」同一列；E 欄用 SUMIFS 抓同一位同學、同一樣品的 ir_moisture_pct。
I21: 另一種做法：資料 → 資料分析 → 「t 檢定：成對母體平均數差異檢定」，變數 1 選 E5:E19、變數 2 選 D5:D19，結果的 t 統計與「P(T<=t) 雙尾」應與上表一致。（要先在 檔案 → 選項 → 增益集 啟用「分析工具箱」。）
I23: 注意：這只是初步線索。完整的方法比較（Bland–Altman 一致性界限、F 檢定）在 W4／NB04 才會做。本週樣品水分從 1% 到 35%，如果偏差會隨水分變大（比例偏差），只用一個平均 bias 描述就不夠。
A41: 看圖：每個點是一位同學。點都在灰色虛線 0 的下方＝紅外線幾乎每次都比烘箱法低；紅線＝平均偏差。如果點的上下散布隨 x 變大而變寬，就是比例偏差的線索。

Sheet 6_水活性
A1: 步驟 5 水活性 aw vs 水分含量：同水分％不代表同 aw
A2: 全班 5 組 × 6 種食品，各量一次快速水分 (%) 與水活性 aw。C、D 欄用 SUMIFS 依「組別＋樣品＋項目」抓值。牛肉乾與龍眼乾水分都約 20%，但 aw 差很多——水的「量」相同，不代表水的「有效性」相同。
F3: 微生物生長的最低 aw（教材值，可改） | L3: 圖用輔助數據（下限線，自動計算）
A4: 組別 | B4: 樣品 | C4: 水分 (%) | D4: aw | F4: 微生物 | G4: 最低 aw | L4: x | M4: y
A5: 1 | B5: beef_jerky | C5: =IF(COUNTIFS('1_原始數據'!$A$2:$A$1000,$A5,'1_原始數據'!$I$2:$I$1000,$B5,'1_原始數據'!$C$2:$C$1000,"moisture_pct_survey")=0,"",SUMIFS('1_原始數據'!$E$2:$E$1000,'1_原始數據'!$A$2:$A$1000,$A5,'1_原始數據'!$I$2:$I$1000,$B5,'1_原始數據'!$C$2:$C$1000,"moisture_pct_survey")) | D5: =IF(COUNTIFS('1_原始數據'!$A$2:$A$1000,$A5,'1_原始數據'!$I$2:$I$1000,$B5,'1_原始數據'!$C$2:$C$1000,"aw_reading")=0,"",SUMIFS('1_原始數據'!$E$2:$E$1000,'1_原始數據'!$A$2:$A$1000,$A5,'1_原始數據'!$I$2:$I$1000,$B5,'1_原始數據'!$C$2:$C$1000,"aw_reading")) | F5: 細菌 bacteria | G5: 0.91 | L5: =0 | M5: =$G$5
A6: 2 | B6: beef_jerky | C6: =IF(COUNTIFS('1_原始數據'!$A$2:$A$1000,$A6,'1_原始數據'!$I$2:$I$1000,$B6,'1_原始數據'!$C$2:$C$1000,"moisture_pct_survey")=0,"",SUMIFS('1_原始數據'!$E$2:$E$1000,'1_原始數據'!$A$2:$A$1000,$A6,'1_原始數據'!$I$2:$I$1000,$B6,'1_原始數據'!$C$2:$C$1000,"moisture_pct_survey")) | D6: =IF(COUNTIFS('1_原始數據'!$A$2:$A$1000,$A6,'1_原始數據'!$I$2:$I$1000,$B6,'1_原始數據'!$C$2:$C$1000,"aw_reading")=0,"",SUMIFS('1_原始數據'!$E$2:$E$1000,'1_原始數據'!$A$2:$A$1000,$A6,'1_原始數據'!$I$2:$I$1000,$B6,'1_原始數據'!$C$2:$C$1000,"aw_reading")) | F6: 酵母菌 yeast | G6: 0.88 | L6: =MAX($C$5:$C$34)*1.1 | M6: =$G$5
A7: 3 | B7: beef_jerky | C7: =IF(COUNTIFS('1_原始數據'!$A$2:$A$1000,$A7,'1_原始數據'!$I$2:$I$1000,$B7,'1_原始數據'!$C$2:$C$1000,"moisture_pct_survey")=0,"",SUMIFS('1_原始數據'!$E$2:$E$1000,'1_原始數據'!$A$2:$A$1000,$A7,'1_原始數據'!$I$2:$I$1000,$B7,'1_原始數據'!$C$2:$C$1000,"moisture_pct_survey")) | D7: =IF(COUNTIFS('1_原始數據'!$A$2:$A$1000,$A7,'1_原始數據'!$I$2:$I$1000,$B7,'1_原始數據'!$C$2:$C$1000,"aw_reading")=0,"",SUMIFS('1_原始數據'!$E$2:$E$1000,'1_原始數據'!$A$2:$A$1000,$A7,'1_原始數據'!$I$2:$I$1000,$B7,'1_原始數據'!$C$2:$C$1000,"aw_reading")) | F7: 黴菌 mold | G7: 0.8 | L7: =0 | M7: =$G$6
A8: 4 | B8: beef_jerky | C8: =IF(COUNTIFS('1_原始數據'!$A$2:$A$1000,$A8,'1_原始數據'!$I$2:$I$1000,$B8,'1_原始數據'!$C$2:$C$1000,"moisture_pct_survey")=0,"",SUMIFS('1_原始數據'!$E$2:$E$1000,'1_原始數據'!$A$2:$A$1000,$A8,'1_原始數據'!$I$2:$I$1000,$B8,'1_原始數據'!$C$2:$C$1000,"moisture_pct_survey")) | D8: =IF(COUNTIFS('1_原始數據'!$A$2:$A$1000,$A8,'1_原始數據'!$I$2:$I$1000,$B8,'1_原始數據'!$C$2:$C$1000,"aw_reading")=0,"",SUMIFS('1_原始數據'!$E$2:$E$1000,'1_原始數據'!$A$2:$A$1000,$A8,'1_原始數據'!$I$2:$I$1000,$B8,'1_原始數據'!$C$2:$C$1000,"aw_reading")) | F8: 嗜旱性黴菌 xerophilic mold | G8: 0.61 | L8: =MAX($C$5:$C$34)*1.1 | M8: =$G$6
A9: 5 | B9: beef_jerky | C9: =IF(COUNTIFS('1_原始數據'!$A$2:$A$1000,$A9,'1_原始數據'!$I$2:$I$1000,$B9,'1_原始數據'!$C$2:$C$1000,"moisture_pct_survey")=0,"",SUMIFS('1_原始數據'!$E$2:$E$1000,'1_原始數據'!$A$2:$A$1000,$A9,'1_原始數據'!$I$2:$I$1000,$B9,'1_原始數據'!$C$2:$C$1000,"moisture_pct_survey")) | D9: =IF(COUNTIFS('1_原始數據'!$A$2:$A$1000,$A9,'1_原始數據'!$I$2:$I$1000,$B9,'1_原始數據'!$C$2:$C$1000,"aw_reading")=0,"",SUMIFS('1_原始數據'!$E$2:$E$1000,'1_原始數據'!$A$2:$A$1000,$A9,'1_原始數據'!$I$2:$I$1000,$B9,'1_原始數據'!$C$2:$C$1000,"aw_reading")) | L9: =0 | M9: =$G$7
A10: 1 | B10: dried_longan | C10: =IF(COUNTIFS('1_原始數據'!$A$2:$A$1000,$A10,'1_原始數據'!$I$2:$I$1000,$B10,'1_原始數據'!$C$2:$C$1000,"moisture_pct_survey")=0,"",SUMIFS('1_原始數據'!$E$2:$E$1000,'1_原始數據'!$A$2:$A$1000,$A10,'1_原始數據'!$I$2:$I$1000,$B10,'1_原始數據'!$C$2:$C$1000,"moisture_pct_survey")) | D10: =IF(COUNTIFS('1_原始數據'!$A$2:$A$1000,$A10,'1_原始數據'!$I$2:$I$1000,$B10,'1_原始數據'!$C$2:$C$1000,"aw_reading")=0,"",SUMIFS('1_原始數據'!$E$2:$E$1000,'1_原始數據'!$A$2:$A$1000,$A10,'1_原始數據'!$I$2:$I$1000,$B10,'1_原始數據'!$C$2:$C$1000,"aw_reading")) | L10: =MAX($C$5:$C$34)*1.1 | M10: =$G$7
A11: 2 | B11: dried_longan | C11: =IF(COUNTIFS('1_原始數據'!$A$2:$A$1000,$A11,'1_原始數據'!$I$2:$I$1000,$B11,'1_原始數據'!$C$2:$C$1000,"moisture_pct_survey")=0,"",SUMIFS('1_原始數據'!$E$2:$E$1000,'1_原始數據'!$A$2:$A$1000,$A11,'1_原始數據'!$I$2:$I$1000,$B11,'1_原始數據'!$C$2:$C$1000,"moisture_pct_survey")) | D11: =IF(COUNTIFS('1_原始數據'!$A$2:$A$1000,$A11,'1_原始數據'!$I$2:$I$1000,$B11,'1_原始數據'!$C$2:$C$1000,"aw_reading")=0,"",SUMIFS('1_原始數據'!$E$2:$E$1000,'1_原始數據'!$A$2:$A$1000,$A11,'1_原始數據'!$I$2:$I$1000,$B11,'1_原始數據'!$C$2:$C$1000,"aw_reading")) | F11: 各食品平均與「可能生長的微生物」 | L11: =0 | M11: =$G$8
A12: 3 | B12: dried_longan | C12: =IF(COUNTIFS('1_原始數據'!$A$2:$A$1000,$A12,'1_原始數據'!$I$2:$I$1000,$B12,'1_原始數據'!$C$2:$C$1000,"moisture_pct_survey")=0,"",SUMIFS('1_原始數據'!$E$2:$E$1000,'1_原始數據'!$A$2:$A$1000,$A12,'1_原始數據'!$I$2:$I$1000,$B12,'1_原始數據'!$C$2:$C$1000,"moisture_pct_survey")) | D12: =IF(COUNTIFS('1_原始數據'!$A$2:$A$1000,$A12,'1_原始數據'!$I$2:$I$1000,$B12,'1_原始數據'!$C$2:$C$1000,"aw_reading")=0,"",SUMIFS('1_原始數據'!$E$2:$E$1000,'1_原始數據'!$A$2:$A$1000,$A12,'1_原始數據'!$I$2:$I$1000,$B12,'1_原始數據'!$C$2:$C$1000,"aw_reading")) | F12: 樣品 | G12: 平均水分 (%) | H12: 平均 aw | I12: aw 的 SD | J12: aw 高於哪些下限？ | L12: =MAX($C$5:$C$34)*1.1 | M12: =$G$8
A13: 4 | B13: dried_longan | C13: =IF(COUNTIFS('1_原始數據'!$A$2:$A$1000,$A13,'1_原始數據'!$I$2:$I$1000,$B13,'1_原始數據'!$C$2:$C$1000,"moisture_pct_survey")=0,"",SUMIFS('1_原始數據'!$E$2:$E$1000,'1_原始數據'!$A$2:$A$1000,$A13,'1_原始數據'!$I$2:$I$1000,$B13,'1_原始數據'!$C$2:$C$1000,"moisture_pct_survey")) | D13: =IF(COUNTIFS('1_原始數據'!$A$2:$A$1000,$A13,'1_原始數據'!$I$2:$I$1000,$B13,'1_原始數據'!$C$2:$C$1000,"aw_reading")=0,"",SUMIFS('1_原始數據'!$E$2:$E$1000,'1_原始數據'!$A$2:$A$1000,$A13,'1_原始數據'!$I$2:$I$1000,$B13,'1_原始數據'!$C$2:$C$1000,"aw_reading")) | F13: beef_jerky | G13: =AVERAGEIF($B$5:$B$34,F13,$C$5:$C$34) | H13: =AVERAGEIF($B$5:$B$34,F13,$D$5:$D$34) | I13: {=_xlfn.STDEV.S(IF($B$5:$B$34=F13,$D$5:$D$34))} | J13: =IF(H13>=$G$5,"細菌、酵母、黴菌都可能生長",IF(H13>=$G$6,"酵母、黴菌可能生長",IF(H13>=$G$7,"黴菌可能生長",IF(H13>=$G$8,"只有嗜旱性黴菌可能生長","一般微生物無法生長"))))
A14: 5 | B14: dried_longan | C14: =IF(COUNTIFS('1_原始數據'!$A$2:$A$1000,$A14,'1_原始數據'!$I$2:$I$1000,$B14,'1_原始數據'!$C$2:$C$1000,"moisture_pct_survey")=0,"",SUMIFS('1_原始數據'!$E$2:$E$1000,'1_原始數據'!$A$2:$A$1000,$A14,'1_原始數據'!$I$2:$I$1000,$B14,'1_原始數據'!$C$2:$C$1000,"moisture_pct_survey")) | D14: =IF(COUNTIFS('1_原始數據'!$A$2:$A$1000,$A14,'1_原始數據'!$I$2:$I$1000,$B14,'1_原始數據'!$C$2:$C$1000,"aw_reading")=0,"",SUMIFS('1_原始數據'!$E$2:$E$1000,'1_原始數據'!$A$2:$A$1000,$A14,'1_原始數據'!$I$2:$I$1000,$B14,'1_原始數據'!$C$2:$C$1000,"aw_reading")) | F14: dried_longan | G14: =AVERAGEIF($B$5:$B$34,F14,$C$5:$C$34) | H14: =AVERAGEIF($B$5:$B$34,F14,$D$5:$D$34) | I14: {=_xlfn.STDEV.S(IF($B$5:$B$34=F14,$D$5:$D$34))} | J14: =IF(H14>=$G$5,"細菌、酵母、黴菌都可能生長",IF(H14>=$G$6,"酵母、黴菌可能生長",IF(H14>=$G$7,"黴菌可能生長",IF(H14>=$G$8,"只有嗜旱性黴菌可能生長","一般微生物無法生長"))))
A15: 1 | B15: white_bread | C15: =IF(COUNTIFS('1_原始數據'!$A$2:$A$1000,$A15,'1_原始數據'!$I$2:$I$1000,$B15,'1_原始數據'!$C$2:$C$1000,"moisture_pct_survey")=0,"",SUMIFS('1_原始數據'!$E$2:$E$1000,'1_原始數據'!$A$2:$A$1000,$A15,'1_原始數據'!$I$2:$I$1000,$B15,'1_原始數據'!$C$2:$C$1000,"moisture_pct_survey")) | D15: =IF(COUNTIFS('1_原始數據'!$A$2:$A$1000,$A15,'1_原始數據'!$I$2:$I$1000,$B15,'1_原始數據'!$C$2:$C$1000,"aw_reading")=0,"",SUMIFS('1_原始數據'!$E$2:$E$1000,'1_原始數據'!$A$2:$A$1000,$A15,'1_原始數據'!$I$2:$I$1000,$B15,'1_原始數據'!$C$2:$C$1000,"aw_reading")) | F15: white_bread | G15: =AVERAGEIF($B$5:$B$34,F15,$C$5:$C$34) | H15: =AVERAGEIF($B$5:$B$34,F15,$D$5:$D$34) | I15: {=_xlfn.STDEV.S(IF($B$5:$B$34=F15,$D$5:$D$34))} | J15: =IF(H15>=$G$5,"細菌、酵母、黴菌都可能生長",IF(H15>=$G$6,"酵母、黴菌可能生長",IF(H15>=$G$7,"黴菌可能生長",IF(H15>=$G$8,"只有嗜旱性黴菌可能生長","一般微生物無法生長"))))
A16: 2 | B16: white_bread | C16: =IF(COUNTIFS('1_原始數據'!$A$2:$A$1000,$A16,'1_原始數據'!$I$2:$I$1000,$B16,'1_原始數據'!$C$2:$C$1000,"moisture_pct_survey")=0,"",SUMIFS('1_原始數據'!$E$2:$E$1000,'1_原始數據'!$A$2:$A$1000,$A16,'1_原始數據'!$I$2:$I$1000,$B16,'1_原始數據'!$C$2:$C$1000,"moisture_pct_survey")) | D16: =IF(COUNTIFS('1_原始數據'!$A$2:$A$1000,$A16,'1_原始數據'!$I$2:$I$1000,$B16,'1_原始數據'!$C$2:$C$1000,"aw_reading")=0,"",SUMIFS('1_原始數據'!$E$2:$E$1000,'1_原始數據'!$A$2:$A$1000,$A16,'1_原始數據'!$I$2:$I$1000,$B16,'1_原始數據'!$C$2:$C$1000,"aw_reading")) | F16: potato_chips | G16: =AVERAGEIF($B$5:$B$34,F16,$C$5:$C$34) | H16: =AVERAGEIF($B$5:$B$34,F16,$D$5:$D$34) | I16: {=_xlfn.STDEV.S(IF($B$5:$B$34=F16,$D$5:$D$34))} | J16: =IF(H16>=$G$5,"細菌、酵母、黴菌都可能生長",IF(H16>=$G$6,"酵母、黴菌可能生長",IF(H16>=$G$7,"黴菌可能生長",IF(H16>=$G$8,"只有嗜旱性黴菌可能生長","一般微生物無法生長"))))
A17: 3 | B17: white_bread | C17: =IF(COUNTIFS('1_原始數據'!$A$2:$A$1000,$A17,'1_原始數據'!$I$2:$I$1000,$B17,'1_原始數據'!$C$2:$C$1000,"moisture_pct_survey")=0,"",SUMIFS('1_原始數據'!$E$2:$E$1000,'1_原始數據'!$A$2:$A$1000,$A17,'1_原始數據'!$I$2:$I$1000,$B17,'1_原始數據'!$C$2:$C$1000,"moisture_pct_survey")) | D17: =IF(COUNTIFS('1_原始數據'!$A$2:$A$1000,$A17,'1_原始數據'!$I$2:$I$1000,$B17,'1_原始數據'!$C$2:$C$1000,"aw_reading")=0,"",SUMIFS('1_原始數據'!$E$2:$E$1000,'1_原始數據'!$A$2:$A$1000,$A17,'1_原始數據'!$I$2:$I$1000,$B17,'1_原始數據'!$C$2:$C$1000,"aw_reading")) | F17: milk_powder | G17: =AVERAGEIF($B$5:$B$34,F17,$C$5:$C$34) | H17: =AVERAGEIF($B$5:$B$34,F17,$D$5:$D$34) | I17: {=_xlfn.STDEV.S(IF($B$5:$B$34=F17,$D$5:$D$34))} | J17: =IF(H17>=$G$5,"細菌、酵母、黴菌都可能生長",IF(H17>=$G$6,"酵母、黴菌可能生長",IF(H17>=$G$7,"黴菌可能生長",IF(H17>=$G$8,"只有嗜旱性黴菌可能生長","一般微生物無法生長"))))
A18: 4 | B18: white_bread | C18: =IF(COUNTIFS('1_原始數據'!$A$2:$A$1000,$A18,'1_原始數據'!$I$2:$I$1000,$B18,'1_原始數據'!$C$2:$C$1000,"moisture_pct_survey")=0,"",SUMIFS('1_原始數據'!$E$2:$E$1000,'1_原始數據'!$A$2:$A$1000,$A18,'1_原始數據'!$I$2:$I$1000,$B18,'1_原始數據'!$C$2:$C$1000,"moisture_pct_survey")) | D18: =IF(COUNTIFS('1_原始數據'!$A$2:$A$1000,$A18,'1_原始數據'!$I$2:$I$1000,$B18,'1_原始數據'!$C$2:$C$1000,"aw_reading")=0,"",SUMIFS('1_原始數據'!$E$2:$E$1000,'1_原始數據'!$A$2:$A$1000,$A18,'1_原始數據'!$I$2:$I$1000,$B18,'1_原始數據'!$C$2:$C$1000,"aw_reading")) | F18: honey | G18: =AVERAGEIF($B$5:$B$34,F18,$C$5:$C$34) | H18: =AVERAGEIF($B$5:$B$34,F18,$D$5:$D$34) | I18: {=_xlfn.STDEV.S(IF($B$5:$B$34=F18,$D$5:$D$34))} | J18: =IF(H18>=$G$5,"細菌、酵母、黴菌都可能生長",IF(H18>=$G$6,"酵母、黴菌可能生長",IF(H18>=$G$7,"黴菌可能生長",IF(H18>=$G$8,"只有嗜旱性黴菌可能生長","一般微生物無法生長"))))
A19: 5 | B19: white_bread | C19: =IF(COUNTIFS('1_原始數據'!$A$2:$A$1000,$A19,'1_原始數據'!$I$2:$I$1000,$B19,'1_原始數據'!$C$2:$C$1000,"moisture_pct_survey")=0,"",SUMIFS('1_原始數據'!$E$2:$E$1000,'1_原始數據'!$A$2:$A$1000,$A19,'1_原始數據'!$I$2:$I$1000,$B19,'1_原始數據'!$C$2:$C$1000,"moisture_pct_survey")) | D19: =IF(COUNTIFS('1_原始數據'!$A$2:$A$1000,$A19,'1_原始數據'!$I$2:$I$1000,$B19,'1_原始數據'!$C$2:$C$1000,"aw_reading")=0,"",SUMIFS('1_原始數據'!$E$2:$E$1000,'1_原始數據'!$A$2:$A$1000,$A19,'1_原始數據'!$I$2:$I$1000,$B19,'1_原始數據'!$C$2:$C$1000,"aw_reading")) | F19: AVERAGEIF(樣品欄, 這個樣品, 數值欄)：只對符合的列取平均。巢狀 IF 由高往低比：先看 aw 是否 ≥ 0.91，不是再看 ≥ 0.88 …，第一個成立的就是答案。微生物是否真的會長，還要看 pH、溫度、防腐劑等，這裡只看 aw。
A20: 1 | B20: potato_chips | C20: =IF(COUNTIFS('1_原始數據'!$A$2:$A$1000,$A20,'1_原始數據'!$I$2:$I$1000,$B20,'1_原始數據'!$C$2:$C$1000,"moisture_pct_survey")=0,"",SUMIFS('1_原始數據'!$E$2:$E$1000,'1_原始數據'!$A$2:$A$1000,$A20,'1_原始數據'!$I$2:$I$1000,$B20,'1_原始數據'!$C$2:$C$1000,"moisture_pct_survey")) | D20: =IF(COUNTIFS('1_原始數據'!$A$2:$A$1000,$A20,'1_原始數據'!$I$2:$I$1000,$B20,'1_原始數據'!$C$2:$C$1000,"aw_reading")=0,"",SUMIFS('1_原始數據'!$E$2:$E$1000,'1_原始數據'!$A$2:$A$1000,$A20,'1_原始數據'!$I$2:$I$1000,$B20,'1_原始數據'!$C$2:$C$1000,"aw_reading"))
A21: 2 | B21: potato_chips | C21: =IF(COUNTIFS('1_原始數據'!$A$2:$A$1000,$A21,'1_原始數據'!$I$2:$I$1000,$B21,'1_原始數據'!$C$2:$C$1000,"moisture_pct_survey")=0,"",SUMIFS('1_原始數據'!$E$2:$E$1000,'1_原始數據'!$A$2:$A$1000,$A21,'1_原始數據'!$I$2:$I$1000,$B21,'1_原始數據'!$C$2:$C$1000,"moisture_pct_survey")) | D21: =IF(COUNTIFS('1_原始數據'!$A$2:$A$1000,$A21,'1_原始數據'!$I$2:$I$1000,$B21,'1_原始數據'!$C$2:$C$1000,"aw_reading")=0,"",SUMIFS('1_原始數據'!$E$2:$E$1000,'1_原始數據'!$A$2:$A$1000,$A21,'1_原始數據'!$I$2:$I$1000,$B21,'1_原始數據'!$C$2:$C$1000,"aw_reading"))
A22: 3 | B22: potato_chips | C22: =IF(COUNTIFS('1_原始數據'!$A$2:$A$1000,$A22,'1_原始數據'!$I$2:$I$1000,$B22,'1_原始數據'!$C$2:$C$1000,"moisture_pct_survey")=0,"",SUMIFS('1_原始數據'!$E$2:$E$1000,'1_原始數據'!$A$2:$A$1000,$A22,'1_原始數據'!$I$2:$I$1000,$B22,'1_原始數據'!$C$2:$C$1000,"moisture_pct_survey")) | D22: =IF(COUNTIFS('1_原始數據'!$A$2:$A$1000,$A22,'1_原始數據'!$I$2:$I$1000,$B22,'1_原始數據'!$C$2:$C$1000,"aw_reading")=0,"",SUMIFS('1_原始數據'!$E$2:$E$1000,'1_原始數據'!$A$2:$A$1000,$A22,'1_原始數據'!$I$2:$I$1000,$B22,'1_原始數據'!$C$2:$C$1000,"aw_reading"))
A23: 4 | B23: potato_chips | C23: =IF(COUNTIFS('1_原始數據'!$A$2:$A$1000,$A23,'1_原始數據'!$I$2:$I$1000,$B23,'1_原始數據'!$C$2:$C$1000,"moisture_pct_survey")=0,"",SUMIFS('1_原始數據'!$E$2:$E$1000,'1_原始數據'!$A$2:$A$1000,$A23,'1_原始數據'!$I$2:$I$1000,$B23,'1_原始數據'!$C$2:$C$1000,"moisture_pct_survey")) | D23: =IF(COUNTIFS('1_原始數據'!$A$2:$A$1000,$A23,'1_原始數據'!$I$2:$I$1000,$B23,'1_原始數據'!$C$2:$C$1000,"aw_reading")=0,"",SUMIFS('1_原始數據'!$E$2:$E$1000,'1_原始數據'!$A$2:$A$1000,$A23,'1_原始數據'!$I$2:$I$1000,$B23,'1_原始數據'!$C$2:$C$1000,"aw_reading"))
A24: 5 | B24: potato_chips | C24: =IF(COUNTIFS('1_原始數據'!$A$2:$A$1000,$A24,'1_原始數據'!$I$2:$I$1000,$B24,'1_原始數據'!$C$2:$C$1000,"moisture_pct_survey")=0,"",SUMIFS('1_原始數據'!$E$2:$E$1000,'1_原始數據'!$A$2:$A$1000,$A24,'1_原始數據'!$I$2:$I$1000,$B24,'1_原始數據'!$C$2:$C$1000,"moisture_pct_survey")) | D24: =IF(COUNTIFS('1_原始數據'!$A$2:$A$1000,$A24,'1_原始數據'!$I$2:$I$1000,$B24,'1_原始數據'!$C$2:$C$1000,"aw_reading")=0,"",SUMIFS('1_原始數據'!$E$2:$E$1000,'1_原始數據'!$A$2:$A$1000,$A24,'1_原始數據'!$I$2:$I$1000,$B24,'1_原始數據'!$C$2:$C$1000,"aw_reading"))
A25: 1 | B25: milk_powder | C25: =IF(COUNTIFS('1_原始數據'!$A$2:$A$1000,$A25,'1_原始數據'!$I$2:$I$1000,$B25,'1_原始數據'!$C$2:$C$1000,"moisture_pct_survey")=0,"",SUMIFS('1_原始數據'!$E$2:$E$1000,'1_原始數據'!$A$2:$A$1000,$A25,'1_原始數據'!$I$2:$I$1000,$B25,'1_原始數據'!$C$2:$C$1000,"moisture_pct_survey")) | D25: =IF(COUNTIFS('1_原始數據'!$A$2:$A$1000,$A25,'1_原始數據'!$I$2:$I$1000,$B25,'1_原始數據'!$C$2:$C$1000,"aw_reading")=0,"",SUMIFS('1_原始數據'!$E$2:$E$1000,'1_原始數據'!$A$2:$A$1000,$A25,'1_原始數據'!$I$2:$I$1000,$B25,'1_原始數據'!$C$2:$C$1000,"aw_reading"))
A26: 2 | B26: milk_powder | C26: =IF(COUNTIFS('1_原始數據'!$A$2:$A$1000,$A26,'1_原始數據'!$I$2:$I$1000,$B26,'1_原始數據'!$C$2:$C$1000,"moisture_pct_survey")=0,"",SUMIFS('1_原始數據'!$E$2:$E$1000,'1_原始數據'!$A$2:$A$1000,$A26,'1_原始數據'!$I$2:$I$1000,$B26,'1_原始數據'!$C$2:$C$1000,"moisture_pct_survey")) | D26: =IF(COUNTIFS('1_原始數據'!$A$2:$A$1000,$A26,'1_原始數據'!$I$2:$I$1000,$B26,'1_原始數據'!$C$2:$C$1000,"aw_reading")=0,"",SUMIFS('1_原始數據'!$E$2:$E$1000,'1_原始數據'!$A$2:$A$1000,$A26,'1_原始數據'!$I$2:$I$1000,$B26,'1_原始數據'!$C$2:$C$1000,"aw_reading"))
A27: 3 | B27: milk_powder | C27: =IF(COUNTIFS('1_原始數據'!$A$2:$A$1000,$A27,'1_原始數據'!$I$2:$I$1000,$B27,'1_原始數據'!$C$2:$C$1000,"moisture_pct_survey")=0,"",SUMIFS('1_原始數據'!$E$2:$E$1000,'1_原始數據'!$A$2:$A$1000,$A27,'1_原始數據'!$I$2:$I$1000,$B27,'1_原始數據'!$C$2:$C$1000,"moisture_pct_survey")) | D27: =IF(COUNTIFS('1_原始數據'!$A$2:$A$1000,$A27,'1_原始數據'!$I$2:$I$1000,$B27,'1_原始數據'!$C$2:$C$1000,"aw_reading")=0,"",SUMIFS('1_原始數據'!$E$2:$E$1000,'1_原始數據'!$A$2:$A$1000,$A27,'1_原始數據'!$I$2:$I$1000,$B27,'1_原始數據'!$C$2:$C$1000,"aw_reading"))
A28: 4 | B28: milk_powder | C28: =IF(COUNTIFS('1_原始數據'!$A$2:$A$1000,$A28,'1_原始數據'!$I$2:$I$1000,$B28,'1_原始數據'!$C$2:$C$1000,"moisture_pct_survey")=0,"",SUMIFS('1_原始數據'!$E$2:$E$1000,'1_原始數據'!$A$2:$A$1000,$A28,'1_原始數據'!$I$2:$I$1000,$B28,'1_原始數據'!$C$2:$C$1000,"moisture_pct_survey")) | D28: =IF(COUNTIFS('1_原始數據'!$A$2:$A$1000,$A28,'1_原始數據'!$I$2:$I$1000,$B28,'1_原始數據'!$C$2:$C$1000,"aw_reading")=0,"",SUMIFS('1_原始數據'!$E$2:$E$1000,'1_原始數據'!$A$2:$A$1000,$A28,'1_原始數據'!$I$2:$I$1000,$B28,'1_原始數據'!$C$2:$C$1000,"aw_reading"))
A29: 5 | B29: milk_powder | C29: =IF(COUNTIFS('1_原始數據'!$A$2:$A$1000,$A29,'1_原始數據'!$I$2:$I$1000,$B29,'1_原始數據'!$C$2:$C$1000,"moisture_pct_survey")=0,"",SUMIFS('1_原始數據'!$E$2:$E$1000,'1_原始數據'!$A$2:$A$1000,$A29,'1_原始數據'!$I$2:$I$1000,$B29,'1_原始數據'!$C$2:$C$1000,"moisture_pct_survey")) | D29: =IF(COUNTIFS('1_原始數據'!$A$2:$A$1000,$A29,'1_原始數據'!$I$2:$I$1000,$B29,'1_原始數據'!$C$2:$C$1000,"aw_reading")=0,"",SUMIFS('1_原始數據'!$E$2:$E$1000,'1_原始數據'!$A$2:$A$1000,$A29,'1_原始數據'!$I$2:$I$1000,$B29,'1_原始數據'!$C$2:$C$1000,"aw_reading"))
A30: 1 | B30: honey | C30: =IF(COUNTIFS('1_原始數據'!$A$2:$A$1000,$A30,'1_原始數據'!$I$2:$I$1000,$B30,'1_原始數據'!$C$2:$C$1000,"moisture_pct_survey")=0,"",SUMIFS('1_原始數據'!$E$2:$E$1000,'1_原始數據'!$A$2:$A$1000,$A30,'1_原始數據'!$I$2:$I$1000,$B30,'1_原始數據'!$C$2:$C$1000,"moisture_pct_survey")) | D30: =IF(COUNTIFS('1_原始數據'!$A$2:$A$1000,$A30,'1_原始數據'!$I$2:$I$1000,$B30,'1_原始數據'!$C$2:$C$1000,"aw_reading")=0,"",SUMIFS('1_原始數據'!$E$2:$E$1000,'1_原始數據'!$A$2:$A$1000,$A30,'1_原始數據'!$I$2:$I$1000,$B30,'1_原始數據'!$C$2:$C$1000,"aw_reading"))
A31: 2 | B31: honey | C31: =IF(COUNTIFS('1_原始數據'!$A$2:$A$1000,$A31,'1_原始數據'!$I$2:$I$1000,$B31,'1_原始數據'!$C$2:$C$1000,"moisture_pct_survey")=0,"",SUMIFS('1_原始數據'!$E$2:$E$1000,'1_原始數據'!$A$2:$A$1000,$A31,'1_原始數據'!$I$2:$I$1000,$B31,'1_原始數據'!$C$2:$C$1000,"moisture_pct_survey")) | D31: =IF(COUNTIFS('1_原始數據'!$A$2:$A$1000,$A31,'1_原始數據'!$I$2:$I$1000,$B31,'1_原始數據'!$C$2:$C$1000,"aw_reading")=0,"",SUMIFS('1_原始數據'!$E$2:$E$1000,'1_原始數據'!$A$2:$A$1000,$A31,'1_原始數據'!$I$2:$I$1000,$B31,'1_原始數據'!$C$2:$C$1000,"aw_reading"))
... A34: 5 | B34: honey | C34: =IF(COUNTIFS('1_原始數據'!$A$2:$A$1000,$A34,'1_原始數據'!$I$2:$I$1000,$B34,'1_原始數據'!$C$2:$C$1000,"moisture_pct_survey")=0,"",SUMIFS('1_原始數據'!$E$2:$E$1000,'1_原始數據'!$A$2:$A$1000,$A34,'1_原始數據'!$I$2:$I$1000,$B34,'1_原始數據'!$C$2:$C$1000,"moisture_pct_survey")) | D34: =IF(COUNTIFS('1_原始數據'!$A$2:$A$1000,$A34,'1_原始數據'!$I$2:$I$1000,$B34,'1_原始數據'!$C$2:$C$1000,"aw_reading")=0,"",SUMIFS('1_原始數據'!$E$2:$E$1000,'1_原始數據'!$A$2:$A$1000,$A34,'1_原始數據'!$I$2:$I$1000,$B34,'1_原始數據'!$C$2:$C$1000,"aw_reading"))
A35: 樣品要連續排在一起（同一種食品 5 列），圖才會把它們畫成同一種顏色。
F47: 看圖：灰色線由上到下是細菌、酵母、黴菌、嗜旱性黴菌的最低 aw。牛肉乾與龍眼乾水分差不多（x 相近），但牛肉乾的 aw 落在黴菌線與嗜旱性黴菌線之間，龍眼乾卻在嗜旱性黴菌線以下。蜂蜜水分近 17%，aw 卻只有約 0.6：糖把水「綁住」了。

Sheet 7_共同盲樣
A1: 步驟 6 全學期共同盲樣：全脂奶粉水分 (n = 5 組)
A2: 全脂奶粉是全學期共同盲樣，W3／W5／W6／W8 會用同一批樣品做灰分、蛋白質、脂肪等。這裡看 5 組的快速水分量測是否一致。
A3: 盲樣名稱（sample 欄） | B3: milk_powder
A5: 組別 | B5: 水分 (%)
A6: 1 | B6: =IF(COUNTIFS('1_原始數據'!$A$2:$A$1000,A6,'1_原始數據'!$I$2:$I$1000,$B$3,'1_原始數據'!$C$2:$C$1000,"moisture_pct_survey")=0,"",SUMIFS('1_原始數據'!$E$2:$E$1000,'1_原始數據'!$A$2:$A$1000,A6,'1_原始數據'!$I$2:$I$1000,$B$3,'1_原始數據'!$C$2:$C$1000,"moisture_pct_survey")) | D6: 每組只貢獻一個值，所以 n = 5 是「組間」的重複。組間 RSD 通常比組內 RSD 大，因為還包含不同人、不同秤、不同時間的差異。
A7: 2 | B7: =IF(COUNTIFS('1_原始數據'!$A$2:$A$1000,A7,'1_原始數據'!$I$2:$I$1000,$B$3,'1_原始數據'!$C$2:$C$1000,"moisture_pct_survey")=0,"",SUMIFS('1_原始數據'!$E$2:$E$1000,'1_原始數據'!$A$2:$A$1000,A7,'1_原始數據'!$I$2:$I$1000,$B$3,'1_原始數據'!$C$2:$C$1000,"moisture_pct_survey"))
A8: 3 | B8: =IF(COUNTIFS('1_原始數據'!$A$2:$A$1000,A8,'1_原始數據'!$I$2:$I$1000,$B$3,'1_原始數據'!$C$2:$C$1000,"moisture_pct_survey")=0,"",SUMIFS('1_原始數據'!$E$2:$E$1000,'1_原始數據'!$A$2:$A$1000,A8,'1_原始數據'!$I$2:$I$1000,$B$3,'1_原始數據'!$C$2:$C$1000,"moisture_pct_survey"))
A9: 4 | B9: =IF(COUNTIFS('1_原始數據'!$A$2:$A$1000,A9,'1_原始數據'!$I$2:$I$1000,$B$3,'1_原始數據'!$C$2:$C$1000,"moisture_pct_survey")=0,"",SUMIFS('1_原始數據'!$E$2:$E$1000,'1_原始數據'!$A$2:$A$1000,A9,'1_原始數據'!$I$2:$I$1000,$B$3,'1_原始數據'!$C$2:$C$1000,"moisture_pct_survey"))
A10: 5 | B10: =IF(COUNTIFS('1_原始數據'!$A$2:$A$1000,A10,'1_原始數據'!$I$2:$I$1000,$B$3,'1_原始數據'!$C$2:$C$1000,"moisture_pct_survey")=0,"",SUMIFS('1_原始數據'!$E$2:$E$1000,'1_原始數據'!$A$2:$A$1000,A10,'1_原始數據'!$I$2:$I$1000,$B$3,'1_原始數據'!$C$2:$C$1000,"moisture_pct_survey"))
A12: n（組數） | B12: =COUNT(B6:B10)
A13: 平均 (%) | B13: =AVERAGE(B6:B10)
A14: SD (%) | B14: =_xlfn.STDEV.S(B6:B10)
A15: RSD (%) | B15: =B14/B13*100 | D15: 奶粉水分只有 2–3%，SD 0.4% 就讓 RSD 接近 17%。低含量樣品的 RSD 天生比較大。
A16: 對照：G5 烘箱法三重複平均 (%) | B16: =AVERAGEIF('3_烘箱法恆重'!$C$5:$C$19,B3,'3_烘箱法恆重'!$Q$5:$Q$19) | D16: 最後一列用「3_烘箱法恆重」G5 三位同學的烘箱法濕基水分做對照。兩個數字不同，想想可能原因（方法不同、樣品吸濕…）。

Sheet 8_吸濕曲線
A1: 步驟 8（延伸） 等溫吸濕曲線：麵條真實數據算得出單分子層水嗎？
A2: 真實數據：麵條在 28 °C 乾燥過程中的 8 個取樣點，同一份樣品以 105 °C 烘箱法與 FD-660 紅外線水分計測水分（濕基 %），並以 aw 計測水活性（data/w02_noodle_msi.csv）。等溫吸濕曲線 (MSI) 的 y 軸用乾基 X = 濕基% ÷ (100 − 濕基%)。教科書說用 BET 或 GAB 擬合就能算出單分子層水 Xm；這張表要練習判斷：算出來的 Xm，數據撐得住嗎？互動版：https://tai-shengyeh.github.io/food-analysis-lab/labs/w02_moisture/isotherm.html
A3: ① 原始數據與換算（黃色可換成你自己的 8 個點） | M3: ② BET 線性化 | S3: 圖用輔助數據（自動計算）
A4: 取樣時間 | B4: aw | C4: 烘箱 水分 (%wb) | D4: FD-660 水分 (%wb) | E4: 烘箱 X (g/g) | F4: FD-660 X (g/g) | G4: 分析用 X (g/g) | H4: BET：aw/[(1−aw)X] | I4: GAB：aw/X | J4: aw² | K4: aw | M4: 分析用的水分數據 | N4: 烘箱法 | S4: aw | T4: X_GAB（⑤）
A5: 1425 | B5: 0.867 | C5: 18.1 | D5: 16.81 | E5: =C5/(100-C5) | F5: =D5/(100-D5) | G5: =IF($N$4="FD-660",F5,E5) | H5: =B5/((1-B5)*G5) | I5: =B5/G5 | J5: =B5^2 | K5: =B5 | M5: BET 適用範圍上限 aw | N5: 0.45 | S5: =0.05 | T5: =N$41*N$42*N$43*S5/((1-N$43*S5)*(1-N$43*S5+N$42*N$43*S5))
A6: 1455 | B6: 0.856 | C6: 17.55 | D6: 16.57 | E6: =C6/(100-C6) | F6: =D6/(100-D6) | G6: =IF($N$4="FD-660",F6,E6) | H6: =B6/((1-B6)*G6) | I6: =B6/G6 | J6: =B6^2 | K6: =B6 | M6: 範圍內（0.05 ≤ aw ≤ 上限）的點數 | N6: =COUNTIFS(B5:B12,">=0.05",B5:B12,"<="&N5) | S6: =0.10 | T6: =N$41*N$42*N$43*S6/((1-N$43*S6)*(1-N$43*S6+N$42*N$43*S6))
A7: 1525 | B7: 0.866 | C7: 17.6 | D7: 16.31 | E7: =C7/(100-C7) | F7: =D7/(100-D7) | G7: =IF($N$4="FD-660",F7,E7) | H7: =B7/((1-B7)*G7) | I7: =B7/G7 | J7: =B7^2 | K7: =B7 | M7: 斜率 s（硬套全部 8 點） | N7: =SLOPE(H5:H12,B5:B12) | S7: =0.15 | T7: =N$41*N$42*N$43*S7/((1-N$43*S7)*(1-N$43*S7+N$42*N$43*S7))
A8: 1555 | B8: 0.72 | C8: 12.6 | D8: 11.85 | E8: =C8/(100-C8) | F8: =D8/(100-D8) | G8: =IF($N$4="FD-660",F8,E8) | H8: =B8/((1-B8)*G8) | I8: =B8/G8 | J8: =B8^2 | K8: =B8 | M8: 截距 i | N8: =INTERCEPT(H5:H12,B5:B12) | S8: =0.20 | T8: =N$41*N$42*N$43*S8/((1-N$43*S8)*(1-N$43*S8+N$42*N$43*S8))
A9: 1625 | B9: 0.643 | C9: 11.3 | D9: 11.43 | E9: =C9/(100-C9) | F9: =D9/(100-D9) | G9: =IF($N$4="FD-660",F9,E9) | H9: =B9/((1-B9)*G9) | I9: =B9/G9 | J9: =B9^2 | K9: =B9 | M9: R² | N9: =RSQ(H5:H12,B5:B12) | S9: =0.25 | T9: =N$41*N$42*N$43*S9/((1-N$43*S9)*(1-N$43*S9+N$42*N$43*S9))
A10: 1655 | B10: 0.628 | C10: 10.9 | D10: 10.07 | E10: =C10/(100-C10) | F10: =D10/(100-D10) | G10: =IF($N$4="FD-660",F10,E10) | H10: =B10/((1-B10)*G10) | I10: =B10/G10 | J10: =B10^2 | K10: =B10 | M10: C = 1 + s/i | N10: =1+N7/N8 | S10: =0.30 | T10: =N$41*N$42*N$43*S10/((1-N$43*S10)*(1-N$43*S10+N$42*N$43*S10))
