Workbook

Sheet 0_說明
B1: EX03｜W3 灰分與鈉離子
B2: 食品分析實驗・入門數據分析（Excel 版）。不用寫程式；同一份數據在 Colab 筆記本做進階分析，答案應該一致。
B4: 學習目標
B5: • 由坩堝空重、坩堝＋樣品、灰化後坩堝＋灰分（恆重）計算灰分 %，比較黑糖 vs 白糖、糙米 vs 白米。
B6: • 由 Na⁺ ISE 讀數與稀釋倍數回推樣品的鈉濃度，換算成 NaCl 當量（× 2.542 = 58.44/22.99）。
B7: • 計算標準添加回收率 %，用 90–110% 判斷方法準確性；檢查飄移（每 10 個樣品重測標準液，偏差 > ±5% 要重新校正）。
B8: • 把量測鈉換成每 100 g，跟營養標示比較，並討論非 NaCl 的含鈉來源。
B9: • 用官方食物成分資料庫（USDA、衛福部 TFND）檢查數據是否合理，並用旗標抓出單位／稀釋倍數／乾濕基的換算錯誤。
B11: 顏色代表什麼
C12: 黃色：輸入或貼上數據的地方
C13: 綠色：公式，會自動計算，不要改
C14: 橘色：重點結果，寫報告時用
B16: 操作步驟
B17: 1. 看「1_原始數據」：一列是一次量測，item 欄說明量的是什麼。
B18: 2. 「2_灰分」：先做講義範例（應為 1.47%），再看各組與各樣品的灰分 % 和長條圖。
B19: 3. 「3_鈉與NaCl」：講義範例（醬油 1:50，NaCl 應為 13.98 g/100 mL），再看五種產品的鈉與 NaCl 當量。
B20: 4. 「4_回收率與飄移」：回收率是否在 90–110%；飄移圖有沒有點超出 ±5%；（選用）Nernst 斜率。
B21: 5. 「5_標示比較」：標示換成每 100 g 後跟量測值比。
B22: 6. 「6_資料庫比對」：全班平均是否在資料庫合理範圍內、有沒有 ⚑ 旗標；看故意算錯的 G6–G8。資料庫原始數字在「7_參考資料」。
B23: 7. 完成「練習題」。
B24: 8. 換成班級數據：把共用 Google Sheet 的數據貼到「1_原始數據」A2 起。組別、樣品不同時，改各表黃色的組別／樣品欄。
B26: 對答案：用內建範例數據時，你的結果應該等於
B27: 項目 | C27: 本檔計算值 | D27: Colab 筆記本的值 | E27: 一致？
B28: 黑糖 全班平均灰分 (%) | C28: ='2_灰分'!D45 | D28: 1.4918757 | E28: =IF(ABS(C28-D28)<=0.000149188570459651,"✔ 一致","✘ 不一致（換成班級數據後本來就會不同）")
B29: 全脂奶粉 灰分 SD (%) | C29: ='2_灰分'!E46 | D29: 0.30662921 | E29: =IF(ABS(C29-D29)<=3.0663921328691596e-05,"✔ 一致","✘ 不一致（換成班級數據後本來就會不同）")
B30: 醬油 Na (mg/100 mL) | C30: ='3_鈉與NaCl'!M19 | D30: 6013.6 | E30: =IF(ABS(C30-D30)<=0.6013600010000001,"✔ 一致","✘ 不一致（換成班級數據後本來就會不同）")
B31: 第 4 組 標準添加回收率 (%) | C31: ='4_回收率與飄移'!D12 | D31: 75.85 | E31: =IF(ABS(C31-D31)<=0.007585001,"✔ 一致","✘ 不一致（換成班級數據後本來就會不同）")
B32: 第 40 個樣品時 標準液偏差 (%) | C32: ='4_回收率與飄移'!C31 | D32: 6.1 | E32: =IF(ABS(C32-D32)<=0.000610001,"✔ 一致","✘ 不一致（換成班級數據後本來就會不同）")
B33: 洋芋片 量測 vs 標示差異 (%) | C33: ='5_標示比較'!G6 | D33: -8.8933333 | E33: =IF(ABS(C33-D33)<=0.0008893343333333335,"✔ 一致","✘ 不一致（換成班級數據後本來就會不同）")
B34: 醬油 量測 vs 標示差異 (%) | C34: ='5_標示比較'!G5 | D34: -10.065803 | E34: =IF(ABS(C34-D34)<=0.0010065812592223314,"✔ 一致","✘ 不一致（換成班級數據後本來就會不同）")
B35: 醬油 換算成 mg/100 g（÷ 密度 1.18） | C35: ='6_資料庫比對'!F21 | D35: 5096.2712 | E35: =IF(ABS(C35-D35)<=0.5096271196440678,"✔ 一致","✘ 不一致（換成班級數據後本來就會不同）")
B36: 糙米灰分 資料庫合理範圍上限 (%) | C36: ='6_資料庫比對'!J18 | D36: 1.47545 | E36: =IF(ABS(C36-D36)<=0.000147546,"✔ 一致","✘ 不一致（換成班級數據後本來就會不同）")
B37: 「Colab 筆記本的值」是用內建模擬數據算出的答案；換成全班數據後，這一欄就不再適用。
B39: 相關連結
B40: 本週實驗投影片 | C40: https://tai-shengyeh.github.io/food-analysis-lab/labs/w03_ash_sodium/index.html
B41: 進階：Colab 筆記本（Python） | C41: https://colab.research.google.com/github/Tai-ShengYeh/food-analysis-lab/blob/main/notebooks/NB03_ash_sodium.ipynb
B42: 數據分析工具指南（Excel／Orange／Colab） | C42: https://tai-shengyeh.github.io/food-analysis-lab/tools.html
B44: 小提醒
B45: • 本檔的數據是模擬教學資料，不是真實量測值。
B46: • 進階：資料庫比對的完整版（每一組鈉的逐一比對、每個品項的小圖、ISE／方法的說明文字、R 語言版本）與結果匯出 CSV，請看 Colab 筆記本。本檔的旗標是同一套規則的簡化版（單位 10 倍、NaCl 2.542 倍、稀釋倍數、乾濕基）。
...

Sheet 1_原始數據
A1: group | B1: student | C1: item | D1: rep | E1: value | F1: unit | G1: temp_C | H1: note | I1: sample | K1: 這張工作表怎麼用
A2: 1 | B2: G1_S1 | C2: crucible_empty_g | D2: 1 | E2: 28.6437 | F2: g | G2: 555 | I2: black_sugar | K2: 本週欄位：item＝量測項目。crucible_empty_g 坩堝空重、crucible_sample_g 坩堝＋樣品、crucible_ash_g 灰化後坩堝＋灰分（恆重）；na_ise_ppm Na⁺ ISE 讀數；std_addition_before_ppm／std_addition_after_ppm 標準添加前／後讀數；drift_check_ppm 飄移監控（group=0 代表 QC 標準液，rep＝第幾個樣品時重測）；nernst_mV 兩點 Nernst 電位。
A3: 1 | B3: G1_S1 | C3: crucible_sample_g | D3: 1 | E3: 31.0917 | F3: g | G3: 555 | I3: black_sugar | K3: sample＝樣品名稱。灰分列的 temp_C 是高溫爐溫度（約 550 °C），不是室溫。
A4: 1 | B4: G1_S1 | C4: crucible_ash_g | D4: 1 | E4: 28.6815 | F4: g | G4: 555 | I4: black_sugar | K4: 本表不需要額外計算欄；後面每一張工作表都用 AVERAGEIFS／COUNTIFS 依 group、item、sample 把數字抓過去。
A5: 1 | B5: G1_S1 | C5: crucible_empty_g | D5: 1 | E5: 24.5651 | F5: g | G5: 548 | I5: white_sugar | K5: 黃色欄位＝原始數據。換成全班數據時：從共用 Google Sheet 複製，貼到 A2（欄位順序必須一樣），舊資料多出來的列要整列刪除。
A6: 1 | B6: G1_S1 | C6: crucible_sample_g | D6: 1 | E6: 27 | F6: g | G6: 548 | I6: white_sugar | K6: 綠色欄位＝公式，會自動算到第 1000 列，不要手動修改。
A7: 1 | B7: G1_S1 | C7: crucible_ash_g | D7: 1 | E7: 24.5659 | F7: g | G7: 548 | I7: white_sugar
A8: 1 | B8: G1_S1 | C8: crucible_empty_g | D8: 1 | E8: 24.7687 | F8: g | G8: 554 | I8: brown_rice
A9: 1 | B9: G1_S1 | C9: crucible_sample_g | D9: 1 | E9: 27.226 | F9: g | G9: 554 | I9: brown_rice
A10: 1 | B10: G1_S1 | C10: crucible_ash_g | D10: 1 | E10: 24.8 | F10: g | G10: 554 | I10: brown_rice
A11: 1 | B11: G1_S1 | C11: crucible_empty_g | D11: 1 | E11: 27.8632 | F11: g | G11: 546 | I11: polished_rice
A12: 1 | B12: G1_S1 | C12: crucible_sample_g | D12: 1 | E12: 30.4196 | F12: g | G12: 546 | I12: polished_rice
A13: 1 | B13: G1_S1 | C13: crucible_ash_g | D13: 1 | E13: 27.8765 | F13: g | G13: 546 | I13: polished_rice
A14: 1 | B14: G1_S1 | C14: crucible_empty_g | D14: 1 | E14: 27.3275 | F14: g | G14: 550 | I14: milk_powder
A15: 1 | B15: G1_S1 | C15: crucible_sample_g | D15: 1 | E15: 29.7796 | F15: g | G15: 550 | I15: milk_powder
A16: 1 | B16: G1_S1 | C16: crucible_ash_g | D16: 1 | E16: 27.4826 | F16: g | G16: 550 | I16: milk_powder
A17: 2 | B17: G2_S1 | C17: crucible_empty_g | D17: 1 | E17: 28.5485 | F17: g | G17: 549 | I17: black_sugar
A18: 2 | B18: G2_S1 | C18: crucible_sample_g | D18: 1 | E18: 31.0145 | F18: g | G18: 549 | I18: black_sugar
... A108: 4 | B108: G4_S2 | C108: std_addition_before_ppm | D108: 1 | E108: 302 | F108: ppm | G108: 25 | I108: soy_sauce
A109: 4 | B109: G4_S2 | C109: std_addition_after_ppm | D109: 1 | E109: 453.7 | F109: ppm | G109: 25 | H109: 回收率 < 90%，疑似基質效應或加標體積誤差，建議重做 | I109: soy_sauce
A110: 5 | B110: G5_S2 | C110: std_addition_before_ppm | D110: 1 | E110: 292.5 | F110: ppm | G110: 25 | I110: soy_sauce
A111: 5 | B111: G5_S2 | C111: std_addition_after_ppm | D111: 1 | E111: 485.6 | F111: ppm | G111: 25 | I111: soy_sauce
A112: 0 | B112: QC_standard | C112: drift_check_ppm | D112: 0 | E112: 988.4 | F112: ppm | G112: 25 | I112: Na_1000ppm_std
A113: 0 | B113: QC_standard | C113: drift_check_ppm | D113: 10 | E113: 991.3 | F113: ppm | G113: 25 | I113: Na_1000ppm_std
A114: 0 | B114: QC_standard | C114: drift_check_ppm | D114: 20 | E114: 1025.5 | F114: ppm | G114: 25 | I114: Na_1000ppm_std
A115: 0 | B115: QC_standard | C115: drift_check_ppm | D115: 30 | E115: 990.1 | F115: ppm | G115: 25 | I115: Na_1000ppm_std
A116: 0 | B116: QC_standard | C116: drift_check_ppm | D116: 40 | E116: 1061 | F116: ppm | G116: 25 | I116: Na_1000ppm_std
A117: 0 | B117: QC_standard | C117: drift_check_ppm | D117: 50 | E117: 989.2 | F117: ppm | G117: 25 | I117: Na_1000ppm_std
A118: 1 | B118: G1_S3 | C118: nernst_mV | D118: 1 | E118: 101.1 | F118: mV | G118: 25 | I118: std_100ppm
A119: 1 | B119: G1_S3 | C119: nernst_mV | D119: 1 | E119: 159.7 | F119: mV | G119: 25 | I119: std_1000ppm
A120: 2 | B120: G2_S3 | C120: nernst_mV | D120: 1 | E120: 99.8 | F120: mV | G120: 25 | I120: std_100ppm
A121: 2 | B121: G2_S3 | C121: nernst_mV | D121: 1 | E121: 159.2 | F121: mV | G121: 25 | I121: std_1000ppm
... A127: 5 | B127: G5_S3 | C127: nernst_mV | D127: 1 | E127: 159.4 | F127: mV | G127: 25 | I127: std_1000ppm

Sheet 2_灰分
A1: 步驟 1 灰分 %（乾式灰化，550 °C）
A2: 灰分％ = 灰分重 ÷ 樣品重 × 100。三個秤重都是「坩堝的重量」，先相減得到樣品重與灰分重，再相除。灰化後要反覆加熱、冷卻、秤重，直到兩次相差 ≤ 0.5 mg（恆重）才記錄。
A4: 1-1 講義範例（黑糖）：先用這一題確認你懂公式
A5: 坩堝空重 W₀ (g) | D5: 26.184
A6: 坩堝＋樣品 W₁ (g) | D6: 28.696
A7: 灰化後坩堝＋灰分（恆重）W₂ (g) | D7: 26.221
A8: 樣品重 = W₁ − W₀ (g) | D8: =D6-D5 | J8: 應為 2.512 g
A9: 灰分重 = W₂ − W₀ (g) | D9: =D7-D5 | J9: 應為 0.037 g
A10: 灰分 % = 灰分重 ÷ 樣品重 × 100 | D10: =D9/D8*100 | J10: 應約為 1.47 %。注意：灰分重只有幾十 mg，天平讀錯 1 mg 灰分％就差約 3%（相對）。
A12: 1-2 各組灰分（從原始數據自動抓）
A13: 組別 | B13: 樣品 | C13: 坩堝空重 W₀ (g) | D13: 坩堝＋樣品 W₁ (g) | E13: 灰化後坩堝＋灰分 W₂ (g) | F13: 樣品重 (g) | G13: 灰分重 (g) | H13: 灰分 %（濕基）
A14: 1 | B14: black_sugar | C14: =IF(COUNTIFS('1_原始數據'!$C$2:$C$1000,"crucible_empty_g",'1_原始數據'!$I$2:$I$1000,$B14,'1_原始數據'!$A$2:$A$1000,$A14)=0,"",AVERAGEIFS('1_原始數據'!$E$2:$E$1000,'1_原始數據'!$C$2:$C$1000,"crucible_empty_g",'1_原始數據'!$I$2:$I$1000,$B14,'1_原始數據'!$A$2:$A$1000,$A14)) | D14: =IF(COUNTIFS('1_原始數據'!$C$2:$C$1000,"crucible_sample_g",'1_原始數據'!$I$2:$I$1000,$B14,'1_原始數據'!$A$2:$A$1000,$A14)=0,"",AVERAGEIFS('1_原始數據'!$E$2:$E$1000,'1_原始數據'!$C$2:$C$1000,"crucible_sample_g",'1_原始數據'!$I$2:$I$1000,$B14,'1_原始數據'!$A$2:$A$1000,$A14)) | E14: =IF(COUNTIFS('1_原始數據'!$C$2:$C$1000,"crucible_ash_g",'1_原始數據'!$I$2:$I$1000,$B14,'1_原始數據'!$A$2:$A$1000,$A14)=0,"",AVERAGEIFS('1_原始數據'!$E$2:$E$1000,'1_原始數據'!$C$2:$C$1000,"crucible_ash_g",'1_原始數據'!$I$2:$I$1000,$B14,'1_原始數據'!$A$2:$A$1000,$A14)) | F14: =IF(OR(C14="",D14=""),"",D14-C14) | G14: =IF(OR(C14="",E14=""),"",E14-C14) | H14: =IF(OR(F14="",G14=""),"",G14/F14*100) | J14: C–E 欄的公式：=AVERAGEIFS(value 欄, item 欄,"crucible_empty_g", sample 欄, B14, group 欄, A14)。意思是「在原始數據裡，找 item、樣品、組別都符合的那一列，把 value 拿過來」。找不到時顯示空白。
A15: 1 | B15: white_sugar | C15: =IF(COUNTIFS('1_原始數據'!$C$2:$C$1000,"crucible_empty_g",'1_原始數據'!$I$2:$I$1000,$B15,'1_原始數據'!$A$2:$A$1000,$A15)=0,"",AVERAGEIFS('1_原始數據'!$E$2:$E$1000,'1_原始數據'!$C$2:$C$1000,"crucible_empty_g",'1_原始數據'!$I$2:$I$1000,$B15,'1_原始數據'!$A$2:$A$1000,$A15)) | D15: =IF(COUNTIFS('1_原始數據'!$C$2:$C$1000,"crucible_sample_g",'1_原始數據'!$I$2:$I$1000,$B15,'1_原始數據'!$A$2:$A$1000,$A15)=0,"",AVERAGEIFS('1_原始數據'!$E$2:$E$1000,'1_原始數據'!$C$2:$C$1000,"crucible_sample_g",'1_原始數據'!$I$2:$I$1000,$B15,'1_原始數據'!$A$2:$A$1000,$A15)) | E15: =IF(COUNTIFS('1_原始數據'!$C$2:$C$1000,"crucible_ash_g",'1_原始數據'!$I$2:$I$1000,$B15,'1_原始數據'!$A$2:$A$1000,$A15)=0,"",AVERAGEIFS('1_原始數據'!$E$2:$E$1000,'1_原始數據'!$C$2:$C$1000,"crucible_ash_g",'1_原始數據'!$I$2:$I$1000,$B15,'1_原始數據'!$A$2:$A$1000,$A15)) | F15: =IF(OR(C15="",D15=""),"",D15-C15) | G15: =IF(OR(C15="",E15=""),"",E15-C15) | H15: =IF(OR(F15="",G15=""),"",G15/F15*100)
A16: 1 | B16: brown_rice | C16: =IF(COUNTIFS('1_原始數據'!$C$2:$C$1000,"crucible_empty_g",'1_原始數據'!$I$2:$I$1000,$B16,'1_原始數據'!$A$2:$A$1000,$A16)=0,"",AVERAGEIFS('1_原始數據'!$E$2:$E$1000,'1_原始數據'!$C$2:$C$1000,"crucible_empty_g",'1_原始數據'!$I$2:$I$1000,$B16,'1_原始數據'!$A$2:$A$1000,$A16)) | D16: =IF(COUNTIFS('1_原始數據'!$C$2:$C$1000,"crucible_sample_g",'1_原始數據'!$I$2:$I$1000,$B16,'1_原始數據'!$A$2:$A$1000,$A16)=0,"",AVERAGEIFS('1_原始數據'!$E$2:$E$1000,'1_原始數據'!$C$2:$C$1000,"crucible_sample_g",'1_原始數據'!$I$2:$I$1000,$B16,'1_原始數據'!$A$2:$A$1000,$A16)) | E16: =IF(COUNTIFS('1_原始數據'!$C$2:$C$1000,"crucible_ash_g",'1_原始數據'!$I$2:$I$1000,$B16,'1_原始數據'!$A$2:$A$1000,$A16)=0,"",AVERAGEIFS('1_原始數據'!$E$2:$E$1000,'1_原始數據'!$C$2:$C$1000,"crucible_ash_g",'1_原始數據'!$I$2:$I$1000,$B16,'1_原始數據'!$A$2:$A$1000,$A16)) | F16: =IF(OR(C16="",D16=""),"",D16-C16) | G16: =IF(OR(C16="",E16=""),"",E16-C16) | H16: =IF(OR(F16="",G16=""),"",G16/F16*100) | J16: F＝D−C（樣品重），G＝E−C（灰分重），H＝G÷F×100。分母是「樣品濕重」，所以是濕基灰分％。
A17: 1 | B17: polished_rice | C17: =IF(COUNTIFS('1_原始數據'!$C$2:$C$1000,"crucible_empty_g",'1_原始數據'!$I$2:$I$1000,$B17,'1_原始數據'!$A$2:$A$1000,$A17)=0,"",AVERAGEIFS('1_原始數據'!$E$2:$E$1000,'1_原始數據'!$C$2:$C$1000,"crucible_empty_g",'1_原始數據'!$I$2:$I$1000,$B17,'1_原始數據'!$A$2:$A$1000,$A17)) | D17: =IF(COUNTIFS('1_原始數據'!$C$2:$C$1000,"crucible_sample_g",'1_原始數據'!$I$2:$I$1000,$B17,'1_原始數據'!$A$2:$A$1000,$A17)=0,"",AVERAGEIFS('1_原始數據'!$E$2:$E$1000,'1_原始數據'!$C$2:$C$1000,"crucible_sample_g",'1_原始數據'!$I$2:$I$1000,$B17,'1_原始數據'!$A$2:$A$1000,$A17)) | E17: =IF(COUNTIFS('1_原始數據'!$C$2:$C$1000,"crucible_ash_g",'1_原始數據'!$I$2:$I$1000,$B17,'1_原始數據'!$A$2:$A$1000,$A17)=0,"",AVERAGEIFS('1_原始數據'!$E$2:$E$1000,'1_原始數據'!$C$2:$C$1000,"crucible_ash_g",'1_原始數據'!$I$2:$I$1000,$B17,'1_原始數據'!$A$2:$A$1000,$A17)) | F17: =IF(OR(C17="",D17=""),"",D17-C17) | G17: =IF(OR(C17="",E17=""),"",E17-C17) | H17: =IF(OR(F17="",G17=""),"",G17/F17*100)
A18: 1 | B18: milk_powder | C18: =IF(COUNTIFS('1_原始數據'!$C$2:$C$1000,"crucible_empty_g",'1_原始數據'!$I$2:$I$1000,$B18,'1_原始數據'!$A$2:$A$1000,$A18)=0,"",AVERAGEIFS('1_原始數據'!$E$2:$E$1000,'1_原始數據'!$C$2:$C$1000,"crucible_empty_g",'1_原始數據'!$I$2:$I$1000,$B18,'1_原始數據'!$A$2:$A$1000,$A18)) | D18: =IF(COUNTIFS('1_原始數據'!$C$2:$C$1000,"crucible_sample_g",'1_原始數據'!$I$2:$I$1000,$B18,'1_原始數據'!$A$2:$A$1000,$A18)=0,"",AVERAGEIFS('1_原始數據'!$E$2:$E$1000,'1_原始數據'!$C$2:$C$1000,"crucible_sample_g",'1_原始數據'!$I$2:$I$1000,$B18,'1_原始數據'!$A$2:$A$1000,$A18)) | E18: =IF(COUNTIFS('1_原始數據'!$C$2:$C$1000,"crucible_ash_g",'1_原始數據'!$I$2:$I$1000,$B18,'1_原始數據'!$A$2:$A$1000,$A18)=0,"",AVERAGEIFS('1_原始數據'!$E$2:$E$1000,'1_原始數據'!$C$2:$C$1000,"crucible_ash_g",'1_原始數據'!$I$2:$I$1000,$B18,'1_原始數據'!$A$2:$A$1000,$A18)) | F18: =IF(OR(C18="",D18=""),"",D18-C18) | G18: =IF(OR(C18="",E18=""),"",E18-C18) | H18: =IF(OR(F18="",G18=""),"",G18/F18*100) | J18: 組數不同：在表格中間插入列，把上一列整列複製下來，再改 A、B 欄（黃色）。下面的統計範圍會自動跟著擴大。
A19: 2 | B19: black_sugar | C19: =IF(COUNTIFS('1_原始數據'!$C$2:$C$1000,"crucible_empty_g",'1_原始數據'!$I$2:$I$1000,$B19,'1_原始數據'!$A$2:$A$1000,$A19)=0,"",AVERAGEIFS('1_原始數據'!$E$2:$E$1000,'1_原始數據'!$C$2:$C$1000,"crucible_empty_g",'1_原始數據'!$I$2:$I$1000,$B19,'1_原始數據'!$A$2:$A$1000,$A19)) | D19: =IF(COUNTIFS('1_原始數據'!$C$2:$C$1000,"crucible_sample_g",'1_原始數據'!$I$2:$I$1000,$B19,'1_原始數據'!$A$2:$A$1000,$A19)=0,"",AVERAGEIFS('1_原始數據'!$E$2:$E$1000,'1_原始數據'!$C$2:$C$1000,"crucible_sample_g",'1_原始數據'!$I$2:$I$1000,$B19,'1_原始數據'!$A$2:$A$1000,$A19)) | E19: =IF(COUNTIFS('1_原始數據'!$C$2:$C$1000,"crucible_ash_g",'1_原始數據'!$I$2:$I$1000,$B19,'1_原始數據'!$A$2:$A$1000,$A19)=0,"",AVERAGEIFS('1_原始數據'!$E$2:$E$1000,'1_原始數據'!$C$2:$C$1000,"crucible_ash_g",'1_原始數據'!$I$2:$I$1000,$B19,'1_原始數據'!$A$2:$A$1000,$A19)) | F19: =IF(OR(C19="",D19=""),"",D19-C19) | G19: =IF(OR(C19="",E19=""),"",E19-C19) | H19: =IF(OR(F19="",G19=""),"",G19/F19*100)
A20: 2 | B20: white_sugar | C20: =IF(COUNTIFS('1_原始數據'!$C$2:$C$1000,"crucible_empty_g",'1_原始數據'!$I$2:$I$1000,$B20,'1_原始數據'!$A$2:$A$1000,$A20)=0,"",AVERAGEIFS('1_原始數據'!$E$2:$E$1000,'1_原始數據'!$C$2:$C$1000,"crucible_empty_g",'1_原始數據'!$I$2:$I$1000,$B20,'1_原始數據'!$A$2:$A$1000,$A20)) | D20: =IF(COUNTIFS('1_原始數據'!$C$2:$C$1000,"crucible_sample_g",'1_原始數據'!$I$2:$I$1000,$B20,'1_原始數據'!$A$2:$A$1000,$A20)=0,"",AVERAGEIFS('1_原始數據'!$E$2:$E$1000,'1_原始數據'!$C$2:$C$1000,"crucible_sample_g",'1_原始數據'!$I$2:$I$1000,$B20,'1_原始數據'!$A$2:$A$1000,$A20)) | E20: =IF(COUNTIFS('1_原始數據'!$C$2:$C$1000,"crucible_ash_g",'1_原始數據'!$I$2:$I$1000,$B20,'1_原始數據'!$A$2:$A$1000,$A20)=0,"",AVERAGEIFS('1_原始數據'!$E$2:$E$1000,'1_原始數據'!$C$2:$C$1000,"crucible_ash_g",'1_原始數據'!$I$2:$I$1000,$B20,'1_原始數據'!$A$2:$A$1000,$A20)) | F20: =IF(OR(C20="",D20=""),"",D20-C20) | G20: =IF(OR(C20="",E20=""),"",E20-C20) | H20: =IF(OR(F20="",G20=""),"",G20/F20*100)
A21: 2 | B21: brown_rice | C21: =IF(COUNTIFS('1_原始數據'!$C$2:$C$1000,"crucible_empty_g",'1_原始數據'!$I$2:$I$1000,$B21,'1_原始數據'!$A$2:$A$1000,$A21)=0,"",AVERAGEIFS('1_原始數據'!$E$2:$E$1000,'1_原始數據'!$C$2:$C$1000,"crucible_empty_g",'1_原始數據'!$I$2:$I$1000,$B21,'1_原始數據'!$A$2:$A$1000,$A21)) | D21: =IF(COUNTIFS('1_原始數據'!$C$2:$C$1000,"crucible_sample_g",'1_原始數據'!$I$2:$I$1000,$B21,'1_原始數據'!$A$2:$A$1000,$A21)=0,"",AVERAGEIFS('1_原始數據'!$E$2:$E$1000,'1_原始數據'!$C$2:$C$1000,"crucible_sample_g",'1_原始數據'!$I$2:$I$1000,$B21,'1_原始數據'!$A$2:$A$1000,$A21)) | E21: =IF(COUNTIFS('1_原始數據'!$C$2:$C$1000,"crucible_ash_g",'1_原始數據'!$I$2:$I$1000,$B21,'1_原始數據'!$A$2:$A$1000,$A21)=0,"",AVERAGEIFS('1_原始數據'!$E$2:$E$1000,'1_原始數據'!$C$2:$C$1000,"crucible_ash_g",'1_原始數據'!$I$2:$I$1000,$B21,'1_原始數據'!$A$2:$A$1000,$A21)) | F21: =IF(OR(C21="",D21=""),"",D21-C21) | G21: =IF(OR(C21="",E21=""),"",E21-C21) | H21: =IF(OR(F21="",G21=""),"",G21/F21*100)
A22: 2 | B22: polished_rice | C22: =IF(COUNTIFS('1_原始數據'!$C$2:$C$1000,"crucible_empty_g",'1_原始數據'!$I$2:$I$1000,$B22,'1_原始數據'!$A$2:$A$1000,$A22)=0,"",AVERAGEIFS('1_原始數據'!$E$2:$E$1000,'1_原始數據'!$C$2:$C$1000,"crucible_empty_g",'1_原始數據'!$I$2:$I$1000,$B22,'1_原始數據'!$A$2:$A$1000,$A22)) | D22: =IF(COUNTIFS('1_原始數據'!$C$2:$C$1000,"crucible_sample_g",'1_原始數據'!$I$2:$I$1000,$B22,'1_原始數據'!$A$2:$A$1000,$A22)=0,"",AVERAGEIFS('1_原始數據'!$E$2:$E$1000,'1_原始數據'!$C$2:$C$1000,"crucible_sample_g",'1_原始數據'!$I$2:$I$1000,$B22,'1_原始數據'!$A$2:$A$1000,$A22)) | E22: =IF(COUNTIFS('1_原始數據'!$C$2:$C$1000,"crucible_ash_g",'1_原始數據'!$I$2:$I$1000,$B22,'1_原始數據'!$A$2:$A$1000,$A22)=0,"",AVERAGEIFS('1_原始數據'!$E$2:$E$1000,'1_原始數據'!$C$2:$C$1000,"crucible_ash_g",'1_原始數據'!$I$2:$I$1000,$B22,'1_原始數據'!$A$2:$A$1000,$A22)) | F22: =IF(OR(C22="",D22=""),"",D22-C22) | G22: =IF(OR(C22="",E22=""),"",E22-C22) | H22: =IF(OR(F22="",G22=""),"",G22/F22*100)
A23: 2 | B23: milk_powder | C23: =IF(COUNTIFS('1_原始數據'!$C$2:$C$1000,"crucible_empty_g",'1_原始數據'!$I$2:$I$1000,$B23,'1_原始數據'!$A$2:$A$1000,$A23)=0,"",AVERAGEIFS('1_原始數據'!$E$2:$E$1000,'1_原始數據'!$C$2:$C$1000,"crucible_empty_g",'1_原始數據'!$I$2:$I$1000,$B23,'1_原始數據'!$A$2:$A$1000,$A23)) | D23: =IF(COUNTIFS('1_原始數據'!$C$2:$C$1000,"crucible_sample_g",'1_原始數據'!$I$2:$I$1000,$B23,'1_原始數據'!$A$2:$A$1000,$A23)=0,"",AVERAGEIFS('1_原始數據'!$E$2:$E$1000,'1_原始數據'!$C$2:$C$1000,"crucible_sample_g",'1_原始數據'!$I$2:$I$1000,$B23,'1_原始數據'!$A$2:$A$1000,$A23)) | E23: =IF(COUNTIFS('1_原始數據'!$C$2:$C$1000,"crucible_ash_g",'1_原始數據'!$I$2:$I$1000,$B23,'1_原始數據'!$A$2:$A$1000,$A23)=0,"",AVERAGEIFS('1_原始數據'!$E$2:$E$1000,'1_原始數據'!$C$2:$C$1000,"crucible_ash_g",'1_原始數據'!$I$2:$I$1000,$B23,'1_原始數據'!$A$2:$A$1000,$A23)) | F23: =IF(OR(C23="",D23=""),"",D23-C23) | G23: =IF(OR(C23="",E23=""),"",E23-C23) | H23: =IF(OR(F23="",G23=""),"",G23/F23*100)
A24: 3 | B24: black_sugar | C24: =IF(COUNTIFS('1_原始數據'!$C$2:$C$1000,"crucible_empty_g",'1_原始數據'!$I$2:$I$1000,$B24,'1_原始數據'!$A$2:$A$1000,$A24)=0,"",AVERAGEIFS('1_原始數據'!$E$2:$E$1000,'1_原始數據'!$C$2:$C$1000,"crucible_empty_g",'1_原始數據'!$I$2:$I$1000,$B24,'1_原始數據'!$A$2:$A$1000,$A24)) | D24: =IF(COUNTIFS('1_原始數據'!$C$2:$C$1000,"crucible_sample_g",'1_原始數據'!$I$2:$I$1000,$B24,'1_原始數據'!$A$2:$A$1000,$A24)=0,"",AVERAGEIFS('1_原始數據'!$E$2:$E$1000,'1_原始數據'!$C$2:$C$1000,"crucible_sample_g",'1_原始數據'!$I$2:$I$1000,$B24,'1_原始數據'!$A$2:$A$1000,$A24)) | E24: =IF(COUNTIFS('1_原始數據'!$C$2:$C$1000,"crucible_ash_g",'1_原始數據'!$I$2:$I$1000,$B24,'1_原始數據'!$A$2:$A$1000,$A24)=0,"",AVERAGEIFS('1_原始數據'!$E$2:$E$1000,'1_原始數據'!$C$2:$C$1000,"crucible_ash_g",'1_原始數據'!$I$2:$I$1000,$B24,'1_原始數據'!$A$2:$A$1000,$A24)) | F24: =IF(OR(C24="",D24=""),"",D24-C24) | G24: =IF(OR(C24="",E24=""),"",E24-C24) | H24: =IF(OR(F24="",G24=""),"",G24/F24*100)
A25: 3 | B25: white_sugar | C25: =IF(COUNTIFS('1_原始數據'!$C$2:$C$1000,"crucible_empty_g",'1_原始數據'!$I$2:$I$1000,$B25,'1_原始數據'!$A$2:$A$1000,$A25)=0,"",AVERAGEIFS('1_原始數據'!$E$2:$E$1000,'1_原始數據'!$C$2:$C$1000,"crucible_empty_g",'1_原始數據'!$I$2:$I$1000,$B25,'1_原始數據'!$A$2:$A$1000,$A25)) | D25: =IF(COUNTIFS('1_原始數據'!$C$2:$C$1000,"crucible_sample_g",'1_原始數據'!$I$2:$I$1000,$B25,'1_原始數據'!$A$2:$A$1000,$A25)=0,"",AVERAGEIFS('1_原始數據'!$E$2:$E$1000,'1_原始數據'!$C$2:$C$1000,"crucible_sample_g",'1_原始數據'!$I$2:$I$1000,$B25,'1_原始數據'!$A$2:$A$1000,$A25)) | E25: =IF(COUNTIFS('1_原始數據'!$C$2:$C$1000,"crucible_ash_g",'1_原始數據'!$I$2:$I$1000,$B25,'1_原始數據'!$A$2:$A$1000,$A25)=0,"",AVERAGEIFS('1_原始數據'!$E$2:$E$1000,'1_原始數據'!$C$2:$C$1000,"crucible_ash_g",'1_原始數據'!$I$2:$I$1000,$B25,'1_原始數據'!$A$2:$A$1000,$A25)) | F25: =IF(OR(C25="",D25=""),"",D25-C25) | G25: =IF(OR(C25="",E25=""),"",E25-C25) | H25: =IF(OR(F25="",G25=""),"",G25/F25*100)
A26: 3 | B26: brown_rice | C26: =IF(COUNTIFS('1_原始數據'!$C$2:$C$1000,"crucible_empty_g",'1_原始數據'!$I$2:$I$1000,$B26,'1_原始數據'!$A$2:$A$1000,$A26)=0,"",AVERAGEIFS('1_原始數據'!$E$2:$E$1000,'1_原始數據'!$C$2:$C$1000,"crucible_empty_g",'1_原始數據'!$I$2:$I$1000,$B26,'1_原始數據'!$A$2:$A$1000,$A26)) | D26: =IF(COUNTIFS('1_原始數據'!$C$2:$C$1000,"crucible_sample_g",'1_原始數據'!$I$2:$I$1000,$B26,'1_原始數據'!$A$2:$A$1000,$A26)=0,"",AVERAGEIFS('1_原始數據'!$E$2:$E$1000,'1_原始數據'!$C$2:$C$1000,"crucible_sample_g",'1_原始數據'!$I$2:$I$1000,$B26,'1_原始數據'!$A$2:$A$1000,$A26)) | E26: =IF(COUNTIFS('1_原始數據'!$C$2:$C$1000,"crucible_ash_g",'1_原始數據'!$I$2:$I$1000,$B26,'1_原始數據'!$A$2:$A$1000,$A26)=0,"",AVERAGEIFS('1_原始數據'!$E$2:$E$1000,'1_原始數據'!$C$2:$C$1000,"crucible_ash_g",'1_原始數據'!$I$2:$I$1000,$B26,'1_原始數據'!$A$2:$A$1000,$A26)) | F26: =IF(OR(C26="",D26=""),"",D26-C26) | G26: =IF(OR(C26="",E26=""),"",E26-C26) | H26: =IF(OR(F26="",G26=""),"",G26/F26*100)
A27: 3 | B27: polished_rice | C27: =IF(COUNTIFS('1_原始數據'!$C$2:$C$1000,"crucible_empty_g",'1_原始數據'!$I$2:$I$1000,$B27,'1_原始數據'!$A$2:$A$1000,$A27)=0,"",AVERAGEIFS('1_原始數據'!$E$2:$E$1000,'1_原始數據'!$C$2:$C$1000,"crucible_empty_g",'1_原始數據'!$I$2:$I$1000,$B27,'1_原始數據'!$A$2:$A$1000,$A27)) | D27: =IF(COUNTIFS('1_原始數據'!$C$2:$C$1000,"crucible_sample_g",'1_原始數據'!$I$2:$I$1000,$B27,'1_原始數據'!$A$2:$A$1000,$A27)=0,"",AVERAGEIFS('1_原始數據'!$E$2:$E$1000,'1_原始數據'!$C$2:$C$1000,"crucible_sample_g",'1_原始數據'!$I$2:$I$1000,$B27,'1_原始數據'!$A$2:$A$1000,$A27)) | E27: =IF(COUNTIFS('1_原始數據'!$C$2:$C$1000,"crucible_ash_g",'1_原始數據'!$I$2:$I$1000,$B27,'1_原始數據'!$A$2:$A$1000,$A27)=0,"",AVERAGEIFS('1_原始數據'!$E$2:$E$1000,'1_原始數據'!$C$2:$C$1000,"crucible_ash_g",'1_原始數據'!$I$2:$I$1000,$B27,'1_原始數據'!$A$2:$A$1000,$A27)) | F27: =IF(OR(C27="",D27=""),"",D27-C27) | G27: =IF(OR(C27="",E27=""),"",E27-C27) | H27: =IF(OR(F27="",G27=""),"",G27/F27*100)
A28: 3 | B28: milk_powder | C28: =IF(COUNTIFS('1_原始數據'!$C$2:$C$1000,"crucible_empty_g",'1_原始數據'!$I$2:$I$1000,$B28,'1_原始數據'!$A$2:$A$1000,$A28)=0,"",AVERAGEIFS('1_原始數據'!$E$2:$E$1000,'1_原始數據'!$C$2:$C$1000,"crucible_empty_g",'1_原始數據'!$I$2:$I$1000,$B28,'1_原始數據'!$A$2:$A$1000,$A28)) | D28: =IF(COUNTIFS('1_原始數據'!$C$2:$C$1000,"crucible_sample_g",'1_原始數據'!$I$2:$I$1000,$B28,'1_原始數據'!$A$2:$A$1000,$A28)=0,"",AVERAGEIFS('1_原始數據'!$E$2:$E$1000,'1_原始數據'!$C$2:$C$1000,"crucible_sample_g",'1_原始數據'!$I$2:$I$1000,$B28,'1_原始數據'!$A$2:$A$1000,$A28)) | E28: =IF(COUNTIFS('1_原始數據'!$C$2:$C$1000,"crucible_ash_g",'1_原始數據'!$I$2:$I$1000,$B28,'1_原始數據'!$A$2:$A$1000,$A28)=0,"",AVERAGEIFS('1_原始數據'!$E$2:$E$1000,'1_原始數據'!$C$2:$C$1000,"crucible_ash_g",'1_原始數據'!$I$2:$I$1000,$B28,'1_原始數據'!$A$2:$A$1000,$A28)) | F28: =IF(OR(C28="",D28=""),"",D28-C28) | G28: =IF(OR(C28="",E28=""),"",E28-C28) | H28: =IF(OR(F28="",G28=""),"",G28/F28*100)
A29: 4 | B29: black_sugar | C29: =IF(COUNTIFS('1_原始數據'!$C$2:$C$1000,"crucible_empty_g",'1_原始數據'!$I$2:$I$1000,$B29,'1_原始數據'!$A$2:$A$1000,$A29)=0,"",AVERAGEIFS('1_原始數據'!$E$2:$E$1000,'1_原始數據'!$C$2:$C$1000,"crucible_empty_g",'1_原始數據'!$I$2:$I$1000,$B29,'1_原始數據'!$A$2:$A$1000,$A29)) | D29: =IF(COUNTIFS('1_原始數據'!$C$2:$C$1000,"crucible_sample_g",'1_原始數據'!$I$2:$I$1000,$B29,'1_原始數據'!$A$2:$A$1000,$A29)=0,"",AVERAGEIFS('1_原始數據'!$E$2:$E$1000,'1_原始數據'!$C$2:$C$1000,"crucible_sample_g",'1_原始數據'!$I$2:$I$1000,$B29,'1_原始數據'!$A$2:$A$1000,$A29)) | E29: =IF(COUNTIFS('1_原始數據'!$C$2:$C$1000,"crucible_ash_g",'1_原始數據'!$I$2:$I$1000,$B29,'1_原始數據'!$A$2:$A$1000,$A29)=0,"",AVERAGEIFS('1_原始數據'!$E$2:$E$1000,'1_原始數據'!$C$2:$C$1000,"crucible_ash_g",'1_原始數據'!$I$2:$I$1000,$B29,'1_原始數據'!$A$2:$A$1000,$A29)) | F29: =IF(OR(C29="",D29=""),"",D29-C29) | G29: =IF(OR(C29="",E29=""),"",E29-C29) | H29: =IF(OR(F29="",G29=""),"",G29/F29*100)
A30: 4 | B30: white_sugar | C30: =IF(COUNTIFS('1_原始數據'!$C$2:$C$1000,"crucible_empty_g",'1_原始數據'!$I$2:$I$1000,$B30,'1_原始數據'!$A$2:$A$1000,$A30)=0,"",AVERAGEIFS('1_原始數據'!$E$2:$E$1000,'1_原始數據'!$C$2:$C$1000,"crucible_empty_g",'1_原始數據'!$I$2:$I$1000,$B30,'1_原始數據'!$A$2:$A$1000,$A30)) | D30: =IF(COUNTIFS('1_原始數據'!$C$2:$C$1000,"crucible_sample_g",'1_原始數據'!$I$2:$I$1000,$B30,'1_原始數據'!$A$2:$A$1000,$A30)=0,"",AVERAGEIFS('1_原始數據'!$E$2:$E$1000,'1_原始數據'!$C$2:$C$1000,"crucible_sample_g",'1_原始數據'!$I$2:$I$1000,$B30,'1_原始數據'!$A$2:$A$1000,$A30)) | E30: =IF(COUNTIFS('1_原始數據'!$C$2:$C$1000,"crucible_ash_g",'1_原始數據'!$I$2:$I$1000,$B30,'1_原始數據'!$A$2:$A$1000,$A30)=0,"",AVERAGEIFS('1_原始數據'!$E$2:$E$1000,'1_原始數據'!$C$2:$C$1000,"crucible_ash_g",'1_原始數據'!$I$2:$I$1000,$B30,'1_原始數據'!$A$2:$A$1000,$A30)) | F30: =IF(OR(C30="",D30=""),"",D30-C30) | G30: =IF(OR(C30="",E30=""),"",E30-C30) | H30: =IF(OR(F30="",G30=""),"",G30/F30*100)
... A38: 5 | B38: milk_powder | C38: =IF(COUNTIFS('1_原始數據'!$C$2:$C$1000,"crucible_empty_g",'1_原始數據'!$I$2:$I$1000,$B38,'1_原始數據'!$A$2:$A$1000,$A38)=0,"",AVERAGEIFS('1_原始數據'!$E$2:$E$1000,'1_原始數據'!$C$2:$C$1000,"crucible_empty_g",'1_原始數據'!$I$2:$I$1000,$B38,'1_原始數據'!$A$2:$A$1000,$A38)) | D38: =IF(COUNTIFS('1_原始數據'!$C$2:$C$1000,"crucible_sample_g",'1_原始數據'!$I$2:$I$1000,$B38,'1_原始數據'!$A$2:$A$1000,$A38)=0,"",AVERAGEIFS('1_原始數據'!$E$2:$E$1000,'1_原始數據'!$C$2:$C$1000,"crucible_sample_g",'1_原始數據'!$I$2:$I$1000,$B38,'1_原始數據'!$A$2:$A$1000,$A38)) | E38: =IF(COUNTIFS('1_原始數據'!$C$2:$C$1000,"crucible_ash_g",'1_原始數據'!$I$2:$I$1000,$B38,'1_原始數據'!$A$2:$A$1000,$A38)=0,"",AVERAGEIFS('1_原始數據'!$E$2:$E$1000,'1_原始數據'!$C$2:$C$1000,"crucible_ash_g",'1_原始數據'!$I$2:$I$1000,$B38,'1_原始數據'!$A$2:$A$1000,$A38)) | F38: =IF(OR(C38="",D38=""),"",D38-C38) | G38: =IF(OR(C38="",E38=""),"",E38-C38) | H38: =IF(OR(F38="",G38=""),"",G38/F38*100)
A40: 1-3 各樣品的全班平均、SD、RSD
A41: 樣品 | B41: 中文 | C41: n | D41: 平均灰分 % | E41: SD (%) | F41: RSD (%)
A42: white_sugar | B42: 白糖 | C42: =SUMPRODUCT(('2_灰分'!$B$14:$B$38=A42)*ISNUMBER('2_灰分'!$H$14:$H$38)) | D42: =AVERAGEIF('2_灰分'!$B$14:$B$38,A42,'2_灰分'!$H$14:$H$38) | E42: {=_xlfn.STDEV.S(IF('2_灰分'!$B$14:$B$38=A42,'2_灰分'!$H$14:$H$38))} | F42: =E42/D42*100 | J42: n：SUMPRODUCT((樣品欄=A)*ISNUMBER(灰分%欄)) 數「這個樣品有幾個數字」。平均：AVERAGEIF(樣品欄, A, 灰分%欄) 只平均符合條件的格子。
A43: polished_rice | B43: 白米 | C43: =SUMPRODUCT(('2_灰分'!$B$14:$B$38=A43)*ISNUMBER('2_灰分'!$H$14:$H$38)) | D43: =AVERAGEIF('2_灰分'!$B$14:$B$38,A43,'2_灰分'!$H$14:$H$38) | E43: {=_xlfn.STDEV.S(IF('2_灰分'!$B$14:$B$38=A43,'2_灰分'!$H$14:$H$38))} | F43: =E43/D43*100 | J43: SD：Excel 沒有 STDEV.IFS，所以用陣列公式 {=STDEV.S(IF(樣品欄=A, 灰分%欄))}：IF 先把不符合的格子變成 FALSE，STDEV.S 只算剩下的數字（樣本標準差，除以 n−1）。舊版 Excel 自己輸入時要按 Ctrl+Shift+Enter；Excel 365 直接 Enter。
A44: brown_rice | B44: 糙米 | C44: =SUMPRODUCT(('2_灰分'!$B$14:$B$38=A44)*ISNUMBER('2_灰分'!$H$14:$H$38)) | D44: =AVERAGEIF('2_灰分'!$B$14:$B$38,A44,'2_灰分'!$H$14:$H$38) | E44: {=_xlfn.STDEV.S(IF('2_灰分'!$B$14:$B$38=A44,'2_灰分'!$H$14:$H$38))} | F44: =E44/D44*100 | J44: RSD＝SD÷平均×100。白糖灰分極低（只有零點幾 mg），天平的 0.1 mg 誤差就佔很大比例，所以 RSD 特別大。
A45: black_sugar | B45: 黑糖 | C45: =SUMPRODUCT(('2_灰分'!$B$14:$B$38=A45)*ISNUMBER('2_灰分'!$H$14:$H$38)) | D45: =AVERAGEIF('2_灰分'!$B$14:$B$38,A45,'2_灰分'!$H$14:$H$38) | E45: {=_xlfn.STDEV.S(IF('2_灰分'!$B$14:$B$38=A45,'2_灰分'!$H$14:$H$38))} | F45: =E45/D45*100 | J45: 解讀：黑糖／糙米灰分明顯高於白糖／白米，這是「精製程度」的指標。但灰分只代表「總無機殘留物」，不能告訴你是哪一種礦物質、有多少鈉或鹽；鈉要用下一張的 Na⁺ ISE 才能回答。
A46: milk_powder | B46: 全脂奶粉（盲樣） | C46: =SUMPRODUCT(('2_灰分'!$B$14:$B$38=A46)*ISNUMBER('2_灰分'!$H$14:$H$38)) | D46: =AVERAGEIF('2_灰分'!$B$14:$B$38,A46,'2_灰分'!$H$14:$H$38) | E46: {=_xlfn.STDEV.S(IF('2_灰分'!$B$14:$B$38=A46,'2_灰分'!$H$14:$H$38))} | F46: =E46/D46*100

Sheet 3_鈉與NaCl
A1: 步驟 2 Na⁺ ISE 讀數 × 稀釋倍數 → 樣品的鈉濃度 → NaCl 當量
A2: ISE 讀到的是「上機溶液」的濃度（ppm＝mg/L）。乘上稀釋倍數 D 才回到原樣品；再換成每 100 mL 或每 100 g。NaCl 當量＝Na × 58.44／22.99（≈ 2.542）。
A4: 2-1 換算係數
A5: Na 原子量 | C5: 22.99
A6: NaCl 式量 | C6: 58.44
A7: NaCl ÷ Na 係數 | C7: =C6/C5 | D7: =58.44/22.99 ≈ 2.542：1 g 鈉相當於 2.542 g 食鹽。
A9: 2-2 講義範例：醬油稀釋 1:50，ISE 讀數 1100 ppm
A10: ISE 讀數 (ppm = mg/L) | C10: 1100
A11: 稀釋倍數 D | C11: 50
A12: 原醬油 Na (g/L) = 讀數 × D ÷ 1000 | C12: =C10*C11/1000
A13: 原醬油 Na (g/100 mL) = g/L ÷ 10 | C13: =C12/10 | D13: 應為 5.50 g/100 mL
A14: NaCl 當量 (g/100 mL) = Na × 2.542 | C14: =C13*'3_鈉與NaCl'!$C$7 | D14: 應約為 13.98 g/100 mL。練習題 2 用這一塊：把 C10、C11 改成題目的數字。
A16: 2-3 各產品：全班讀數 → 每 100 g（或 100 mL）的鈉
D17: 組別 → | E17: 1 | F17: 2 | G17: 3 | H17: 4 | I17: 5
A18: 產品 | B18: 中文 | C18: 稀釋倍數 D | D18: 結果基準 | E18: 讀數 (ppm) | F18: 讀數 (ppm) | G18: 讀數 (ppm) | H18: 讀數 (ppm) | I18: 讀數 (ppm) | J18: n | K18: 平均讀數 (ppm) | L18: SD 讀數 | M18: Na (mg/100 g 或 mL) | N18: SD Na | O18: NaCl 當量 (g/100 g 或 mL) | Q18: 醬油、運動飲料是液體，結果是「每 100 mL」。要跟每 100 g 的資料庫比時，要再除以密度（見「6_資料庫比對」）。
A19: soy_sauce | B19: 醬油 | C19: 50 | D19: mg/100 mL | E19: =IF(COUNTIFS('1_原始數據'!$C$2:$C$1000,"na_ise_ppm",'1_原始數據'!$I$2:$I$1000,$A19,'1_原始數據'!$A$2:$A$1000,E$17)=0,"",AVERAGEIFS('1_原始數據'!$E$2:$E$1000,'1_原始數據'!$C$2:$C$1000,"na_ise_ppm",'1_原始數據'!$I$2:$I$1000,$A19,'1_原始數據'!$A$2:$A$1000,E$17)) | F19: =IF(COUNTIFS('1_原始數據'!$C$2:$C$1000,"na_ise_ppm",'1_原始數據'!$I$2:$I$1000,$A19,'1_原始數據'!$A$2:$A$1000,F$17)=0,"",AVERAGEIFS('1_原始數據'!$E$2:$E$1000,'1_原始數據'!$C$2:$C$1000,"na_ise_ppm",'1_原始數據'!$I$2:$I$1000,$A19,'1_原始數據'!$A$2:$A$1000,F$17)) | G19: =IF(COUNTIFS('1_原始數據'!$C$2:$C$1000,"na_ise_ppm",'1_原始數據'!$I$2:$I$1000,$A19,'1_原始數據'!$A$2:$A$1000,G$17)=0,"",AVERAGEIFS('1_原始數據'!$E$2:$E$1000,'1_原始數據'!$C$2:$C$1000,"na_ise_ppm",'1_原始數據'!$I$2:$I$1000,$A19,'1_原始數據'!$A$2:$A$1000,G$17)) | H19: =IF(COUNTIFS('1_原始數據'!$C$2:$C$1000,"na_ise_ppm",'1_原始數據'!$I$2:$I$1000,$A19,'1_原始數據'!$A$2:$A$1000,H$17)=0,"",AVERAGEIFS('1_原始數據'!$E$2:$E$1000,'1_原始數據'!$C$2:$C$1000,"na_ise_ppm",'1_原始數據'!$I$2:$I$1000,$A19,'1_原始數據'!$A$2:$A$1000,H$17)) | I19: =IF(COUNTIFS('1_原始數據'!$C$2:$C$1000,"na_ise_ppm",'1_原始數據'!$I$2:$I$1000,$A19,'1_原始數據'!$A$2:$A$1000,I$17)=0,"",AVERAGEIFS('1_原始數據'!$E$2:$E$1000,'1_原始數據'!$C$2:$C$1000,"na_ise_ppm",'1_原始數據'!$I$2:$I$1000,$A19,'1_原始數據'!$A$2:$A$1000,I$17)) | J19: =COUNT(E19:I19) | K19: =AVERAGE(E19:I19) | L19: =_xlfn.STDEV.S(E19:I19) | M19: =K19*C19/10 | N19: =L19*C19/10 | O19: =M19*'3_鈉與NaCl'!$C$7/1000
A20: potato_chips | B20: 洋芋片 | C20: =100/5 | D20: mg/100 g | E20: =IF(COUNTIFS('1_原始數據'!$C$2:$C$1000,"na_ise_ppm",'1_原始數據'!$I$2:$I$1000,$A20,'1_原始數據'!$A$2:$A$1000,E$17)=0,"",AVERAGEIFS('1_原始數據'!$E$2:$E$1000,'1_原始數據'!$C$2:$C$1000,"na_ise_ppm",'1_原始數據'!$I$2:$I$1000,$A20,'1_原始數據'!$A$2:$A$1000,E$17)) | F20: =IF(COUNTIFS('1_原始數據'!$C$2:$C$1000,"na_ise_ppm",'1_原始數據'!$I$2:$I$1000,$A20,'1_原始數據'!$A$2:$A$1000,F$17)=0,"",AVERAGEIFS('1_原始數據'!$E$2:$E$1000,'1_原始數據'!$C$2:$C$1000,"na_ise_ppm",'1_原始數據'!$I$2:$I$1000,$A20,'1_原始數據'!$A$2:$A$1000,F$17)) | G20: =IF(COUNTIFS('1_原始數據'!$C$2:$C$1000,"na_ise_ppm",'1_原始數據'!$I$2:$I$1000,$A20,'1_原始數據'!$A$2:$A$1000,G$17)=0,"",AVERAGEIFS('1_原始數據'!$E$2:$E$1000,'1_原始數據'!$C$2:$C$1000,"na_ise_ppm",'1_原始數據'!$I$2:$I$1000,$A20,'1_原始數據'!$A$2:$A$1000,G$17)) | H20: =IF(COUNTIFS('1_原始數據'!$C$2:$C$1000,"na_ise_ppm",'1_原始數據'!$I$2:$I$1000,$A20,'1_原始數據'!$A$2:$A$1000,H$17)=0,"",AVERAGEIFS('1_原始數據'!$E$2:$E$1000,'1_原始數據'!$C$2:$C$1000,"na_ise_ppm",'1_原始數據'!$I$2:$I$1000,$A20,'1_原始數據'!$A$2:$A$1000,H$17)) | I20: =IF(COUNTIFS('1_原始數據'!$C$2:$C$1000,"na_ise_ppm",'1_原始數據'!$I$2:$I$1000,$A20,'1_原始數據'!$A$2:$A$1000,I$17)=0,"",AVERAGEIFS('1_原始數據'!$E$2:$E$1000,'1_原始數據'!$C$2:$C$1000,"na_ise_ppm",'1_原始數據'!$I$2:$I$1000,$A20,'1_原始數據'!$A$2:$A$1000,I$17)) | J20: =COUNT(E20:I20) | K20: =AVERAGE(E20:I20) | L20: =_xlfn.STDEV.S(E20:I20) | M20: =K20*C20/10 | N20: =L20*C20/10 | O20: =M20*'3_鈉與NaCl'!$C$7/1000
A21: instant_soup | B21: 即食湯（沖泡後） | C21: 20 | D21: mg/100 g | E21: =IF(COUNTIFS('1_原始數據'!$C$2:$C$1000,"na_ise_ppm",'1_原始數據'!$I$2:$I$1000,$A21,'1_原始數據'!$A$2:$A$1000,E$17)=0,"",AVERAGEIFS('1_原始數據'!$E$2:$E$1000,'1_原始數據'!$C$2:$C$1000,"na_ise_ppm",'1_原始數據'!$I$2:$I$1000,$A21,'1_原始數據'!$A$2:$A$1000,E$17)) | F21: =IF(COUNTIFS('1_原始數據'!$C$2:$C$1000,"na_ise_ppm",'1_原始數據'!$I$2:$I$1000,$A21,'1_原始數據'!$A$2:$A$1000,F$17)=0,"",AVERAGEIFS('1_原始數據'!$E$2:$E$1000,'1_原始數據'!$C$2:$C$1000,"na_ise_ppm",'1_原始數據'!$I$2:$I$1000,$A21,'1_原始數據'!$A$2:$A$1000,F$17)) | G21: =IF(COUNTIFS('1_原始數據'!$C$2:$C$1000,"na_ise_ppm",'1_原始數據'!$I$2:$I$1000,$A21,'1_原始數據'!$A$2:$A$1000,G$17)=0,"",AVERAGEIFS('1_原始數據'!$E$2:$E$1000,'1_原始數據'!$C$2:$C$1000,"na_ise_ppm",'1_原始數據'!$I$2:$I$1000,$A21,'1_原始數據'!$A$2:$A$1000,G$17)) | H21: =IF(COUNTIFS('1_原始數據'!$C$2:$C$1000,"na_ise_ppm",'1_原始數據'!$I$2:$I$1000,$A21,'1_原始數據'!$A$2:$A$1000,H$17)=0,"",AVERAGEIFS('1_原始數據'!$E$2:$E$1000,'1_原始數據'!$C$2:$C$1000,"na_ise_ppm",'1_原始數據'!$I$2:$I$1000,$A21,'1_原始數據'!$A$2:$A$1000,H$17)) | I21: =IF(COUNTIFS('1_原始數據'!$C$2:$C$1000,"na_ise_ppm",'1_原始數據'!$I$2:$I$1000,$A21,'1_原始數據'!$A$2:$A$1000,I$17)=0,"",AVERAGEIFS('1_原始數據'!$E$2:$E$1000,'1_原始數據'!$C$2:$C$1000,"na_ise_ppm",'1_原始數據'!$I$2:$I$1000,$A21,'1_原始數據'!$A$2:$A$1000,I$17)) | J21: =COUNT(E21:I21) | K21: =AVERAGE(E21:I21) | L21: =_xlfn.STDEV.S(E21:I21) | M21: =K21*C21/10 | N21: =L21*C21/10 | O21: =M21*'3_鈉與NaCl'!$C$7/1000
A22: sports_drink | B22: 運動飲料 | C22: 1 | D22: mg/100 mL（≈100 g） | E22: =IF(COUNTIFS('1_原始數據'!$C$2:$C$1000,"na_ise_ppm",'1_原始數據'!$I$2:$I$1000,$A22,'1_原始數據'!$A$2:$A$1000,E$17)=0,"",AVERAGEIFS('1_原始數據'!$E$2:$E$1000,'1_原始數據'!$C$2:$C$1000,"na_ise_ppm",'1_原始數據'!$I$2:$I$1000,$A22,'1_原始數據'!$A$2:$A$1000,E$17)) | F22: =IF(COUNTIFS('1_原始數據'!$C$2:$C$1000,"na_ise_ppm",'1_原始數據'!$I$2:$I$1000,$A22,'1_原始數據'!$A$2:$A$1000,F$17)=0,"",AVERAGEIFS('1_原始數據'!$E$2:$E$1000,'1_原始數據'!$C$2:$C$1000,"na_ise_ppm",'1_原始數據'!$I$2:$I$1000,$A22,'1_原始數據'!$A$2:$A$1000,F$17)) | G22: =IF(COUNTIFS('1_原始數據'!$C$2:$C$1000,"na_ise_ppm",'1_原始數據'!$I$2:$I$1000,$A22,'1_原始數據'!$A$2:$A$1000,G$17)=0,"",AVERAGEIFS('1_原始數據'!$E$2:$E$1000,'1_原始數據'!$C$2:$C$1000,"na_ise_ppm",'1_原始數據'!$I$2:$I$1000,$A22,'1_原始數據'!$A$2:$A$1000,G$17)) | H22: =IF(COUNTIFS('1_原始數據'!$C$2:$C$1000,"na_ise_ppm",'1_原始數據'!$I$2:$I$1000,$A22,'1_原始數據'!$A$2:$A$1000,H$17)=0,"",AVERAGEIFS('1_原始數據'!$E$2:$E$1000,'1_原始數據'!$C$2:$C$1000,"na_ise_ppm",'1_原始數據'!$I$2:$I$1000,$A22,'1_原始數據'!$A$2:$A$1000,H$17)) | I22: =IF(COUNTIFS('1_原始數據'!$C$2:$C$1000,"na_ise_ppm",'1_原始數據'!$I$2:$I$1000,$A22,'1_原始數據'!$A$2:$A$1000,I$17)=0,"",AVERAGEIFS('1_原始數據'!$E$2:$E$1000,'1_原始數據'!$C$2:$C$1000,"na_ise_ppm",'1_原始數據'!$I$2:$I$1000,$A22,'1_原始數據'!$A$2:$A$1000,I$17)) | J22: =COUNT(E22:I22) | K22: =AVERAGE(E22:I22) | L22: =_xlfn.STDEV.S(E22:I22) | M22: =K22*C22/10 | N22: =L22*C22/10 | O22: =M22*'3_鈉與NaCl'!$C$7/1000
A23: milk_powder | B23: 全脂奶粉（盲樣） | C23: 20 | D23: mg/100 g | E23: =IF(COUNTIFS('1_原始數據'!$C$2:$C$1000,"na_ise_ppm",'1_原始數據'!$I$2:$I$1000,$A23,'1_原始數據'!$A$2:$A$1000,E$17)=0,"",AVERAGEIFS('1_原始數據'!$E$2:$E$1000,'1_原始數據'!$C$2:$C$1000,"na_ise_ppm",'1_原始數據'!$I$2:$I$1000,$A23,'1_原始數據'!$A$2:$A$1000,E$17)) | F23: =IF(COUNTIFS('1_原始數據'!$C$2:$C$1000,"na_ise_ppm",'1_原始數據'!$I$2:$I$1000,$A23,'1_原始數據'!$A$2:$A$1000,F$17)=0,"",AVERAGEIFS('1_原始數據'!$E$2:$E$1000,'1_原始數據'!$C$2:$C$1000,"na_ise_ppm",'1_原始數據'!$I$2:$I$1000,$A23,'1_原始數據'!$A$2:$A$1000,F$17)) | G23: =IF(COUNTIFS('1_原始數據'!$C$2:$C$1000,"na_ise_ppm",'1_原始數據'!$I$2:$I$1000,$A23,'1_原始數據'!$A$2:$A$1000,G$17)=0,"",AVERAGEIFS('1_原始數據'!$E$2:$E$1000,'1_原始數據'!$C$2:$C$1000,"na_ise_ppm",'1_原始數據'!$I$2:$I$1000,$A23,'1_原始數據'!$A$2:$A$1000,G$17)) | H23: =IF(COUNTIFS('1_原始數據'!$C$2:$C$1000,"na_ise_ppm",'1_原始數據'!$I$2:$I$1000,$A23,'1_原始數據'!$A$2:$A$1000,H$17)=0,"",AVERAGEIFS('1_原始數據'!$E$2:$E$1000,'1_原始數據'!$C$2:$C$1000,"na_ise_ppm",'1_原始數據'!$I$2:$I$1000,$A23,'1_原始數據'!$A$2:$A$1000,H$17)) | I23: =IF(COUNTIFS('1_原始數據'!$C$2:$C$1000,"na_ise_ppm",'1_原始數據'!$I$2:$I$1000,$A23,'1_原始數據'!$A$2:$A$1000,I$17)=0,"",AVERAGEIFS('1_原始數據'!$E$2:$E$1000,'1_原始數據'!$C$2:$C$1000,"na_ise_ppm",'1_原始數據'!$I$2:$I$1000,$A23,'1_原始數據'!$A$2:$A$1000,I$17)) | J23: =COUNT(E23:I23) | K23: =AVERAGE(E23:I23) | L23: =_xlfn.STDEV.S(E23:I23) | M23: =K23*C23/10 | N23: =L23*C23/10 | O23: =M23*'3_鈉與NaCl'!$C$7/1000
A25: 公式說明
A26: 讀數 | C26: =AVERAGEIFS(value, item,"na_ise_ppm", sample, A19, group, E17) 依產品和組別把讀數抓過來。組數不同就改第 17 列的組別號碼（插入欄可加組）。
A27: 稀釋倍數 D | C27: 液體：「1:50」就是 D = 50。固體：D = 定容體積 (mL) ÷ 樣品重 (g)。洋芋片是 5.00 g 萃取成 100 mL，所以 D = 100 ÷ 5 = 20。
A28: Na (mg/100) | C28: = 平均讀數 × D ÷ 10。讀數 (mg/L) × D 是原樣品每公升（或每 1000 g）的 mg；÷ 10 換成每 100 mL（或 100 g）。
A29: SD Na | C29: = SD 讀數 × D ÷ 10。乘上常數，SD 也跟著乘。
A30: NaCl 當量 | C30: = Na (mg/100) × 2.542 ÷ 1000，單位 g/100 g。前提是「所有的鈉都來自食鹽」，其實味精、小蘇打、苯甲酸鈉也含鈉。
A31: n、平均、SD | C31: COUNT 數有幾個數字、AVERAGE 平均、STDEV.S 樣本標準差（除以 n−1）。空白格會自動略過。

Sheet 4_回收率與飄移
A1: 步驟 3 品管：標準添加回收率、飄移檢查、（選用）Nernst 斜率
A3: 3-1 標準添加回收率（醬油）
A4: 加標量 (ppm) | B4: 200 | C4: 回收率 % ＝（加標後讀數 − 加標前讀數）÷ 加標量 × 100。教學判準：90–110% 可接受。
A5: 可接受下限 (%) | B5: 90
A6: 可接受上限 (%) | B6: 110
A8: 組別 | B8: 加標前 (ppm) | C8: 加標後 (ppm) | D8: 回收率 (%) | E8: 判定 | F8: 原始數據 note
A9: 1 | B9: =IF(COUNTIFS('1_原始數據'!$C$2:$C$1000,"std_addition_before_ppm",'1_原始數據'!$A$2:$A$1000,$A9)=0,"",AVERAGEIFS('1_原始數據'!$E$2:$E$1000,'1_原始數據'!$C$2:$C$1000,"std_addition_before_ppm",'1_原始數據'!$A$2:$A$1000,$A9)) | C9: =IF(COUNTIFS('1_原始數據'!$C$2:$C$1000,"std_addition_after_ppm",'1_原始數據'!$A$2:$A$1000,$A9)=0,"",AVERAGEIFS('1_原始數據'!$E$2:$E$1000,'1_原始數據'!$C$2:$C$1000,"std_addition_after_ppm",'1_原始數據'!$A$2:$A$1000,$A9)) | D9: =IF(OR(B9="",C9=""),"",(C9-B9)/$B$4*100) | E9: =IF(D9="","",IF(AND(D9>=$B$5,D9<=$B$6),"合格","⚠ 不合格")) | F9: {=IFERROR(INDEX('1_原始數據'!$H$2:$H$1000,MATCH(1,('1_原始數據'!$A$2:$A$1000=A9)*('1_原始數據'!$C$2:$C$1000="std_addition_after_ppm"),0))&"","")} | L9: B、C 欄：AVERAGEIFS 依組別抓 std_addition_before_ppm／after_ppm。E 欄：IF(AND(回收率 ≥ 下限, 回收率 ≤ 上限), "合格", "不合格")。
A10: 2 | B10: =IF(COUNTIFS('1_原始數據'!$C$2:$C$1000,"std_addition_before_ppm",'1_原始數據'!$A$2:$A$1000,$A10)=0,"",AVERAGEIFS('1_原始數據'!$E$2:$E$1000,'1_原始數據'!$C$2:$C$1000,"std_addition_before_ppm",'1_原始數據'!$A$2:$A$1000,$A10)) | C10: =IF(COUNTIFS('1_原始數據'!$C$2:$C$1000,"std_addition_after_ppm",'1_原始數據'!$A$2:$A$1000,$A10)=0,"",AVERAGEIFS('1_原始數據'!$E$2:$E$1000,'1_原始數據'!$C$2:$C$1000,"std_addition_after_ppm",'1_原始數據'!$A$2:$A$1000,$A10)) | D10: =IF(OR(B10="",C10=""),"",(C10-B10)/$B$4*100) | E10: =IF(D10="","",IF(AND(D10>=$B$5,D10<=$B$6),"合格","⚠ 不合格")) | F10: {=IFERROR(INDEX('1_原始數據'!$H$2:$H$1000,MATCH(1,('1_原始數據'!$A$2:$A$1000=A10)*('1_原始數據'!$C$2:$C$1000="std_addition_after_ppm"),0))&"","")} | L10: F 欄把原始數據的 note 抓過來（陣列公式 INDEX＋MATCH）。回收率 < 90% 常見原因：基質效應、加標體積量錯、電極反應慢沒等讀數穩定。
A11: 3 | B11: =IF(COUNTIFS('1_原始數據'!$C$2:$C$1000,"std_addition_before_ppm",'1_原始數據'!$A$2:$A$1000,$A11)=0,"",AVERAGEIFS('1_原始數據'!$E$2:$E$1000,'1_原始數據'!$C$2:$C$1000,"std_addition_before_ppm",'1_原始數據'!$A$2:$A$1000,$A11)) | C11: =IF(COUNTIFS('1_原始數據'!$C$2:$C$1000,"std_addition_after_ppm",'1_原始數據'!$A$2:$A$1000,$A11)=0,"",AVERAGEIFS('1_原始數據'!$E$2:$E$1000,'1_原始數據'!$C$2:$C$1000,"std_addition_after_ppm",'1_原始數據'!$A$2:$A$1000,$A11)) | D11: =IF(OR(B11="",C11=""),"",(C11-B11)/$B$4*100) | E11: =IF(D11="","",IF(AND(D11>=$B$5,D11<=$B$6),"合格","⚠ 不合格")) | F11: {=IFERROR(INDEX('1_原始數據'!$H$2:$H$1000,MATCH(1,('1_原始數據'!$A$2:$A$1000=A11)*('1_原始數據'!$C$2:$C$1000="std_addition_after_ppm"),0))&"","")}
A12: 4 | B12: =IF(COUNTIFS('1_原始數據'!$C$2:$C$1000,"std_addition_before_ppm",'1_原始數據'!$A$2:$A$1000,$A12)=0,"",AVERAGEIFS('1_原始數據'!$E$2:$E$1000,'1_原始數據'!$C$2:$C$1000,"std_addition_before_ppm",'1_原始數據'!$A$2:$A$1000,$A12)) | C12: =IF(COUNTIFS('1_原始數據'!$C$2:$C$1000,"std_addition_after_ppm",'1_原始數據'!$A$2:$A$1000,$A12)=0,"",AVERAGEIFS('1_原始數據'!$E$2:$E$1000,'1_原始數據'!$C$2:$C$1000,"std_addition_after_ppm",'1_原始數據'!$A$2:$A$1000,$A12)) | D12: =IF(OR(B12="",C12=""),"",(C12-B12)/$B$4*100) | E12: =IF(D12="","",IF(AND(D12>=$B$5,D12<=$B$6),"合格","⚠ 不合格")) | F12: {=IFERROR(INDEX('1_原始數據'!$H$2:$H$1000,MATCH(1,('1_原始數據'!$A$2:$A$1000=A12)*('1_原始數據'!$C$2:$C$1000="std_addition_after_ppm"),0))&"","")}
A13: 5 | B13: =IF(COUNTIFS('1_原始數據'!$C$2:$C$1000,"std_addition_before_ppm",'1_原始數據'!$A$2:$A$1000,$A13)=0,"",AVERAGEIFS('1_原始數據'!$E$2:$E$1000,'1_原始數據'!$C$2:$C$1000,"std_addition_before_ppm",'1_原始數據'!$A$2:$A$1000,$A13)) | C13: =IF(COUNTIFS('1_原始數據'!$C$2:$C$1000,"std_addition_after_ppm",'1_原始數據'!$A$2:$A$1000,$A13)=0,"",AVERAGEIFS('1_原始數據'!$E$2:$E$1000,'1_原始數據'!$C$2:$C$1000,"std_addition_after_ppm",'1_原始數據'!$A$2:$A$1000,$A13)) | D13: =IF(OR(B13="",C13=""),"",(C13-B13)/$B$4*100) | E13: =IF(D13="","",IF(AND(D13>=$B$5,D13<=$B$6),"合格","⚠ 不合格")) | F13: {=IFERROR(INDEX('1_原始數據'!$H$2:$H$1000,MATCH(1,('1_原始數據'!$A$2:$A$1000=A13)*('1_原始數據'!$C$2:$C$1000="std_addition_after_ppm"),0))&"","")}
A15: 練習計算區（練習題 1 用）
A16: 加標前 (ppm) | B16: 297.6 | C16: 預設是第 1 組的數字（回收率 100.10%）。把黃色格子改成題目的數字即可。
A17: 加標後 (ppm) | B17: 497.8
A18: 加標量 (ppm) | B18: 200
A19: 回收率 (%) | B19: =(B17-B16)/B18*100
A20: 判定 | B20: =IF(AND(B19>=$B$5,B19<=$B$6),"合格","⚠ 不合格")
A22: 3-2 飄移檢查（drift check）：每測約 10 個樣品重測一次 1000 ppm 標準液
A23: 標準液標稱值 (ppm) | B23: 1000 | C23: 偏差 % ＝（讀數 − 標稱值）÷ 標稱值 × 100。超過 ±5% 就要重新校正電極，並回頭重測上一次合格之後的樣品。
A24: 容許偏差 ± (%) | B24: 5
H25: 圖用輔助數據（容許線，自動計算）
A26: 第幾個樣品時 | B26: 讀數 (ppm) | C26: 偏差 (%) | D26: 判定 | H26: 圖：x | I26: +限 | J26: −限 | K26: 0
A27: 0 | B27: =IF(COUNTIFS('1_原始數據'!$C$2:$C$1000,"drift_check_ppm",'1_原始數據'!$D$2:$D$1000,$A27)=0,"",AVERAGEIFS('1_原始數據'!$E$2:$E$1000,'1_原始數據'!$C$2:$C$1000,"drift_check_ppm",'1_原始數據'!$D$2:$D$1000,$A27)) | C27: =IF(B27="","",(B27-$B$23)/$B$23*100) | D27: =IF(C27="","",IF(ABS(C27)>$B$24,"⚠ 超過，要重新校正","OK")) | H27: =MIN(A27:A32) | I27: =$B$24 | J27: =-$B$24 | K27: =0 | L27: B 欄：AVERAGEIFS(value, item,"drift_check_ppm", rep, A 欄)。原始數據裡 rep 就是「第幾個樣品時重測」。重測次數不同：在表格中間插入列再改 A 欄（圖會跟著更新）。
A28: 10 | B28: =IF(COUNTIFS('1_原始數據'!$C$2:$C$1000,"drift_check_ppm",'1_原始數據'!$D$2:$D$1000,$A28)=0,"",AVERAGEIFS('1_原始數據'!$E$2:$E$1000,'1_原始數據'!$C$2:$C$1000,"drift_check_ppm",'1_原始數據'!$D$2:$D$1000,$A28)) | C28: =IF(B28="","",(B28-$B$23)/$B$23*100) | D28: =IF(C28="","",IF(ABS(C28)>$B$24,"⚠ 超過，要重新校正","OK")) | H28: =MAX(A27:A32) | I28: =$B$24 | J28: =-$B$24 | K28: =0 | L28: 看圖：藍線是每次重測的偏差；兩條虛線是 ±5%。超出虛線的那一點（本範例第 40 個樣品，+6.1%）代表電極飄移了：第 30～40 個樣品的結果不可信，要重新校正後重測。
A29: 20 | B29: =IF(COUNTIFS('1_原始數據'!$C$2:$C$1000,"drift_check_ppm",'1_原始數據'!$D$2:$D$1000,$A29)=0,"",AVERAGEIFS('1_原始數據'!$E$2:$E$1000,'1_原始數據'!$C$2:$C$1000,"drift_check_ppm",'1_原始數據'!$D$2:$D$1000,$A29)) | C29: =IF(B29="","",(B29-$B$23)/$B$23*100) | D29: =IF(C29="","",IF(ABS(C29)>$B$24,"⚠ 超過，要重新校正","OK"))
A30: 30 | B30: =IF(COUNTIFS('1_原始數據'!$C$2:$C$1000,"drift_check_ppm",'1_原始數據'!$D$2:$D$1000,$A30)=0,"",AVERAGEIFS('1_原始數據'!$E$2:$E$1000,'1_原始數據'!$C$2:$C$1000,"drift_check_ppm",'1_原始數據'!$D$2:$D$1000,$A30)) | C30: =IF(B30="","",(B30-$B$23)/$B$23*100) | D30: =IF(C30="","",IF(ABS(C30)>$B$24,"⚠ 超過，要重新校正","OK"))
A31: 40 | B31: =IF(COUNTIFS('1_原始數據'!$C$2:$C$1000,"drift_check_ppm",'1_原始數據'!$D$2:$D$1000,$A31)=0,"",AVERAGEIFS('1_原始數據'!$E$2:$E$1000,'1_原始數據'!$C$2:$C$1000,"drift_check_ppm",'1_原始數據'!$D$2:$D$1000,$A31)) | C31: =IF(B31="","",(B31-$B$23)/$B$23*100) | D31: =IF(C31="","",IF(ABS(C31)>$B$24,"⚠ 超過，要重新校正","OK"))
A32: 50 | B32: =IF(COUNTIFS('1_原始數據'!$C$2:$C$1000,"drift_check_ppm",'1_原始數據'!$D$2:$D$1000,$A32)=0,"",AVERAGEIFS('1_原始數據'!$E$2:$E$1000,'1_原始數據'!$C$2:$C$1000,"drift_check_ppm",'1_原始數據'!$D$2:$D$1000,$A32)) | C32: =IF(B32="","",(B32-$B$23)/$B$23*100) | D32: =IF(C32="","",IF(ABS(C32)>$B$24,"⚠ 超過，要重新校正","OK"))
A55: 3-3（選用）兩點 Nernst 斜率：電極健康檢查
A56: 低濃度標準液 (ppm) | B56: 100 | C56: std_100ppm | D56: C 欄是原始數據 sample 欄的名稱。斜率 ＝（mV₂ − mV₁）÷（log₁₀C₂ − log₁₀C₁）。濃度差 10 倍時，分母剛好是 1。
A57: 高濃度標準液 (ppm) | B57: 1000 | C57: std_1000ppm
A58: 理論斜率 (mV/decade, 25 °C) | B58: 59.2
A60: 組別 | B60: mV（低） | C60: mV（高） | D60: 斜率 (mV/decade) | E60: 與理論差 (%)
A61: 1 | B61: =IF(COUNTIFS('1_原始數據'!$C$2:$C$1000,"nernst_mV",'1_原始數據'!$I$2:$I$1000,$C$56,'1_原始數據'!$A$2:$A$1000,$A61)=0,"",AVERAGEIFS('1_原始數據'!$E$2:$E$1000,'1_原始數據'!$C$2:$C$1000,"nernst_mV",'1_原始數據'!$I$2:$I$1000,$C$56,'1_原始數據'!$A$2:$A$1000,$A61)) | C61: =IF(COUNTIFS('1_原始數據'!$C$2:$C$1000,"nernst_mV",'1_原始數據'!$I$2:$I$1000,$C$57,'1_原始數據'!$A$2:$A$1000,$A61)=0,"",AVERAGEIFS('1_原始數據'!$E$2:$E$1000,'1_原始數據'!$C$2:$C$1000,"nernst_mV",'1_原始數據'!$I$2:$I$1000,$C$57,'1_原始數據'!$A$2:$A$1000,$A61)) | D61: =IF(OR(B61="",C61=""),"",(C61-B61)/(LOG10($B$57)-LOG10($B$56))) | E61: =IF(D61="","",(D61-$B$58)/$B$58*100) | L61: LOG10 是以 10 為底的對數。健康的 Na⁺ 電極在 25 °C 斜率約 59 mV/decade；明顯偏低（例如 < 55）代表電極老化或膜被污染，要保養或更換。
A62: 2 | B62: =IF(COUNTIFS('1_原始數據'!$C$2:$C$1000,"nernst_mV",'1_原始數據'!$I$2:$I$1000,$C$56,'1_原始數據'!$A$2:$A$1000,$A62)=0,"",AVERAGEIFS('1_原始數據'!$E$2:$E$1000,'1_原始數據'!$C$2:$C$1000,"nernst_mV",'1_原始數據'!$I$2:$I$1000,$C$56,'1_原始數據'!$A$2:$A$1000,$A62)) | C62: =IF(COUNTIFS('1_原始數據'!$C$2:$C$1000,"nernst_mV",'1_原始數據'!$I$2:$I$1000,$C$57,'1_原始數據'!$A$2:$A$1000,$A62)=0,"",AVERAGEIFS('1_原始數據'!$E$2:$E$1000,'1_原始數據'!$C$2:$C$1000,"nernst_mV",'1_原始數據'!$I$2:$I$1000,$C$57,'1_原始數據'!$A$2:$A$1000,$A62)) | D62: =IF(OR(B62="",C62=""),"",(C62-B62)/(LOG10($B$57)-LOG10($B$56))) | E62: =IF(D62="","",(D62-$B$58)/$B$58*100)
A63: 3 | B63: =IF(COUNTIFS('1_原始數據'!$C$2:$C$1000,"nernst_mV",'1_原始數據'!$I$2:$I$1000,$C$56,'1_原始數據'!$A$2:$A$1000,$A63)=0,"",AVERAGEIFS('1_原始數據'!$E$2:$E$1000,'1_原始數據'!$C$2:$C$1000,"nernst_mV",'1_原始數據'!$I$2:$I$1000,$C$56,'1_原始數據'!$A$2:$A$1000,$A63)) | C63: =IF(COUNTIFS('1_原始數據'!$C$2:$C$1000,"nernst_mV",'1_原始數據'!$I$2:$I$1000,$C$57,'1_原始數據'!$A$2:$A$1000,$A63)=0,"",AVERAGEIFS('1_原始數據'!$E$2:$E$1000,'1_原始數據'!$C$2:$C$1000,"nernst_mV",'1_原始數據'!$I$2:$I$1000,$C$57,'1_原始數據'!$A$2:$A$1000,$A63)) | D63: =IF(OR(B63="",C63=""),"",(C63-B63)/(LOG10($B$57)-LOG10($B$56))) | E63: =IF(D63="","",(D63-$B$58)/$B$58*100)
A64: 4 | B64: =IF(COUNTIFS('1_原始數據'!$C$2:$C$1000,"nernst_mV",'1_原始數據'!$I$2:$I$1000,$C$56,'1_原始數據'!$A$2:$A$1000,$A64)=0,"",AVERAGEIFS('1_原始數據'!$E$2:$E$1000,'1_原始數據'!$C$2:$C$1000,"nernst_mV",'1_原始數據'!$I$2:$I$1000,$C$56,'1_原始數據'!$A$2:$A$1000,$A64)) | C64: =IF(COUNTIFS('1_原始數據'!$C$2:$C$1000,"nernst_mV",'1_原始數據'!$I$2:$I$1000,$C$57,'1_原始數據'!$A$2:$A$1000,$A64)=0,"",AVERAGEIFS('1_原始數據'!$E$2:$E$1000,'1_原始數據'!$C$2:$C$1000,"nernst_mV",'1_原始數據'!$I$2:$I$1000,$C$57,'1_原始數據'!$A$2:$A$1000,$A64)) | D64: =IF(OR(B64="",C64=""),"",(C64-B64)/(LOG10($B$57)-LOG10($B$56))) | E64: =IF(D64="","",(D64-$B$58)/$B$58*100)
A65: 5 | B65: =IF(COUNTIFS('1_原始數據'!$C$2:$C$1000,"nernst_mV",'1_原始數據'!$I$2:$I$1000,$C$56,'1_原始數據'!$A$2:$A$1000,$A65)=0,"",AVERAGEIFS('1_原始數據'!$E$2:$E$1000,'1_原始數據'!$C$2:$C$1000,"nernst_mV",'1_原始數據'!$I$2:$I$1000,$C$56,'1_原始數據'!$A$2:$A$1000,$A65)) | C65: =IF(COUNTIFS('1_原始數據'!$C$2:$C$1000,"nernst_mV",'1_原始數據'!$I$2:$I$1000,$C$57,'1_原始數據'!$A$2:$A$1000,$A65)=0,"",AVERAGEIFS('1_原始數據'!$E$2:$E$1000,'1_原始數據'!$C$2:$C$1000,"nernst_mV",'1_原始數據'!$I$2:$I$1000,$C$57,'1_原始數據'!$A$2:$A$1000,$A65)) | D65: =IF(OR(B65="",C65=""),"",(C65-B65)/(LOG10($B$57)-LOG10($B$56))) | E65: =IF(D65="","",(D65-$B$58)/$B$58*100)
A66: 班級平均 | D66: =AVERAGE(D61:D65)

Sheet 5_標示比較
A1: 步驟 4 量測鈉 vs 營養標示鈉（換成每 100 g 再比）
A2: 包裝標示是「每份」。先把標示換成每 100 g：標示 mg／份 ÷ 每份克數 × 100，才能跟量測值比。
A4: 產品 | B4: 中文 | C4: 標示鈉 (mg/份) | D4: 每份 (g) | E4: 標示 (mg/100 g) | F4: 量測 (mg/100 g) | G4: 差異 (%) | H4: 量測低於標示？
A5: ='3_鈉與NaCl'!A19 | B5: ='3_鈉與NaCl'!B19 | C5: 850 | D5: 15 | E5: =C5/D5*100 | F5: ='3_鈉與NaCl'!M19/'6_資料庫比對'!$H$10 | G5: =(F5-E5)/E5*100 | H5: =IF(F5<E5,"是（低於標示）","否") | J5: E＝C÷D×100；F 從「3_鈉與NaCl」M 欄抓（醬油再除以密度）；差異 %＝（量測 − 標示）÷ 標示 × 100。
A6: ='3_鈉與NaCl'!A20 | B6: ='3_鈉與NaCl'!B20 | C6: 180 | D6: 30 | E6: =C6/D6*100 | F6: ='3_鈉與NaCl'!M20 | G6: =(F6-E6)/E6*100 | H6: =IF(F6<E6,"是（低於標示）","否") | J6: 差異的可能來源：秤重或稀釋誤差、批次不同、標示四捨五入，以及非 NaCl 的含鈉成分（味精 MSG、小蘇打 NaHCO₃、苯甲酸鈉…）——它們都貢獻鈉，但不是鹽。量測低於標示不一定代表標示造假。
A7: ='3_鈉與NaCl'!A21 | B7: ='3_鈉與NaCl'!B21 | C7: 750 | D7: 250 | E7: =C7/D7*100 | F7: ='3_鈉與NaCl'!M21 | G7: =(F7-E7)/E7*100 | H7: =IF(F7<E7,"是（低於標示）","否") | J7: 醬油是液體，量測值是 mg/100 mL，標示是 mg/100 g，所以 F 欄先除以密度（1.18 g/mL，教學假設，在「6_資料庫比對」H10 可改）。沒除密度會算出比標示高約 6%，除了之後反而低約 10%——基準沒對齊，結論會相反。
A8: ='3_鈉與NaCl'!A22 | B8: ='3_鈉與NaCl'!B22 | C8: 110 | D8: 500 | E8: =C8/D8*100 | F8: ='3_鈉與NaCl'!M22 | G8: =(F8-E8)/E8*100 | H8: =IF(F8<E8,"是（低於標示）","否")
A9: ='3_鈉與NaCl'!A23 | B9: ='3_鈉與NaCl'!B23 | C9: 120 | D9: 25 | E9: =C9/D9*100 | F9: ='3_鈉與NaCl'!M23 | G9: =(F9-E9)/E9*100 | H9: =IF(F9<E9,"是（低於標示）","否")
A31: 縱軸是對數刻度（每一格差 10 倍），醬油和運動飲料差了 300 倍，才能畫在同一張圖上。兩根柱子高度越接近，量測越接近標示。

Sheet 6_資料庫比對
A1: 步驟 5 用官方食物成分資料庫檢查：我的數據合理嗎？
A2: 資料庫 ≠ 標示 ≠ 實驗值。三者不一致時，先排除「自己算錯」（單位、稀釋倍數、乾／濕基、換算係數），再考慮「方法偏差」，最後才是「樣品本來就不一樣」。資料庫數字在「7_參考資料」（USDA FoodData Central 與 衛福部食藥署 食品營養成分資料庫）。
A4: 5-1 教學預設容許差（教學假設，不是資料庫數值）
A5: 營養素 | B5: 相對容許差 | C5: 絕對下限 | D5: 單位 | F5: 合理範圍怎麼來：每一筆資料庫值先算自己的區間——有 min–max 就用 min–max；有 SD 且 n ≥ 2 就用 平均 ± 2 SD；而且至少保留「數值 ± max(相對容許差 × 數值, 絕對下限)」。再把同一食品的各筆區間聯集起來＝合理範圍。每一筆的區間在「7_參考資料」T、U 欄。
A6: water | B6: 0.1 | C6: 0.3 | D6: g/100 g
A7: protein | B7: 0.1 | C7: 0.3 | D7: g/100 g
A8: fat | B8: 0.15 | C8: 0.3 | D8: g/100 g
A9: ash | B9: 0.15 | C9: 0.05 | D9: g/100 g
A10: carbohydrate | B10: 0.1 | C10: 1 | D10: g/100 g | F10: 醬油密度 (g/mL) | H10: 1.18 | I10: 教學假設（醬油約 1.15–1.20 g/mL），請實際秤 10.00 mL 醬油確認。運動飲料與沖泡湯密度接近 1。
A11: sugars_total | B11: 0.15 | C11: 0.5 | D11: g/100 g
A12: sodium | B12: 0.15 | C12: 5 | D12: mg/100 g
A14: 5-2 全班平均 vs 資料庫合理範圍
A15: 標籤 | B15: food_key（資料庫品項） | C15: 營養素 | D15: 報告值 | E15: 密度 (g/mL) | F15: 實測（每 100 g，濕基） | G15: SD | H15: 稀釋倍數 D | I15: 參考下限 | J15: 參考上限 | K15: 參考中心 | L15: 實測 ÷ 中心 | M15: 判定 | N15: 涵蓋筆數 | O15: 資料庫水分 (g/100 g) | P15: ⚑ 旗標（可能算錯的提示）
A16: black_sugar | B16: brown_sugar | C16: ash | D16: =IFERROR(INDEX('2_灰分'!$D$42:$D$46,MATCH(A16,'2_灰分'!$A$42:$A$46,0)),"") | F16: =IF(D16="","",IF(ISNUMBER(E16),D16/E16,D16)) | G16: =IFERROR(INDEX('2_灰分'!$E$42:$E$46,MATCH(A16,'2_灰分'!$A$42:$A$46,0)),"") | I16: {=IF(COUNTIFS('7_參考資料'!$A$2:$A$335,B16,'7_參考資料'!$I$2:$I$335,C16)=0,"",MIN(IF(('7_參考資料'!$A$2:$A$335=B16)*('7_參考資料'!$I$2:$I$335=C16)*ISNUMBER('7_參考資料'!$T$2:$T$335),'7_參考資料'!$T$2:$T$335)))} | J16: {=IF(COUNTIFS('7_參考資料'!$A$2:$A$335,B16,'7_參考資料'!$I$2:$I$335,C16)=0,"",MAX(IF(('7_參考資料'!$A$2:$A$335=B16)*('7_參考資料'!$I$2:$I$335=C16)*ISNUMBER('7_參考資料'!$T$2:$T$335),'7_參考資料'!$U$2:$U$335)))} | K16: =IF(COUNTIFS('7_參考資料'!$A$2:$A$335,B16,'7_參考資料'!$I$2:$I$335,C16)=0,"",AVERAGEIFS('7_參考資料'!$J$2:$J$335,'7_參考資料'!$A$2:$A$335,B16,'7_參考資料'!$I$2:$I$335,C16)) | L16: =IF(OR(F16="",K16=""),"",IF(K16=0,"",F16/K16)) | M16: =IF(OR(F16="",I16=""),"",IF(F16<I16,"偏低",IF(F16>J16,"偏高","範圍內"))) | N16: =IF(OR(F16="",I16=""),"",COUNTIFS('7_參考資料'!$A$2:$A$335,B16,'7_參考資料'!$I$2:$I$335,C16,'7_參考資料'!$T$2:$T$335,"<="&F16,'7_參考資料'!$U$2:$U$335,">="&F16)&" / "&COUNTIFS('7_參考資料'!$A$2:$A$335,B16,'7_參考資料'!$I$2:$I$335,C16)) | O16: =IFERROR(AVERAGEIFS('7_參考資料'!$J$2:$J$335,'7_參考資料'!$A$2:$A$335,B16,'7_參考資料'!$I$2:$I$335,"water"),"") | P16: =IF(F16="","",IF(AND(M16<>"範圍內",ISNUMBER(L16),N(L16)>0),IF(AND(ABS(ROUND(LOG10(L16),0))>=1,ABS(ROUND(LOG10(L16),0))<=3,ABS(LOG10(L16)-ROUND(LOG10(L16),0))<LOG10(1.25)),"單位換算錯誤？實測約"&IF(L16>1,"高","低")&" "&10^ABS(ROUND(LOG10(L16),0))&" 倍；",""),"")&IF(AND(AND(M16<>"範圍內",ISNUMBER(L16),N(L16)>0),C16="sodium"),IF(ABS(ABS(LOG10(L16))-LOG10('3_鈉與NaCl'!$C$7))<LOG10(1.25),"Na 與 NaCl 混用？約 2.542 倍；",""),"")&IF(AND(AND(M16<>"範圍內",ISNUMBER(L16),N(L16)>0),ISNUMBER(H16),N(H16)>1),IF(ABS(ABS(LOG10(L16))-LOG10(H16))<LOG10(1.25),"稀釋倍數 "&H16&" 忘了乘或多乘？；",IF(AND(H16/10<>1,H16/10<>10,H16/10<>100,ABS(ABS(LOG10(L16))-LOG10(H16/10))<LOG10(1.25)),"約 D/10 = "&H16/10&" 倍：忘了 ×D 並 ÷10 換成每 100 g？；","")),"")&IF(AND(ISNUMBER(O16),N(O16)>=3,ISNUMBER(K16),N(K16)>0),IF(AND(ABS(F16/(K16/(1-O16/100))-1)<0.05,ABS(F16/K16-1)>0.08),"基準不一致？接近乾基參考值 "&TEXT((K16/(1-O16/100)),"0.00")&"（資料庫是濕基）；",""),"")) | R16: A 欄是本檔的樣品名稱（黃色 B 欄是對應的資料庫品項，可改）。D＝報告值：灰分來自「2_灰分」的全班平均，鈉來自「3_鈉與NaCl」M 欄。
A17: white_sugar | B17: white_sugar | C17: ash | D17: =IFERROR(INDEX('2_灰分'!$D$42:$D$46,MATCH(A17,'2_灰分'!$A$42:$A$46,0)),"") | F17: =IF(D17="","",IF(ISNUMBER(E17),D17/E17,D17)) | G17: =IFERROR(INDEX('2_灰分'!$E$42:$E$46,MATCH(A17,'2_灰分'!$A$42:$A$46,0)),"") | I17: {=IF(COUNTIFS('7_參考資料'!$A$2:$A$335,B17,'7_參考資料'!$I$2:$I$335,C17)=0,"",MIN(IF(('7_參考資料'!$A$2:$A$335=B17)*('7_參考資料'!$I$2:$I$335=C17)*ISNUMBER('7_參考資料'!$T$2:$T$335),'7_參考資料'!$T$2:$T$335)))} | J17: {=IF(COUNTIFS('7_參考資料'!$A$2:$A$335,B17,'7_參考資料'!$I$2:$I$335,C17)=0,"",MAX(IF(('7_參考資料'!$A$2:$A$335=B17)*('7_參考資料'!$I$2:$I$335=C17)*ISNUMBER('7_參考資料'!$T$2:$T$335),'7_參考資料'!$U$2:$U$335)))} | K17: =IF(COUNTIFS('7_參考資料'!$A$2:$A$335,B17,'7_參考資料'!$I$2:$I$335,C17)=0,"",AVERAGEIFS('7_參考資料'!$J$2:$J$335,'7_參考資料'!$A$2:$A$335,B17,'7_參考資料'!$I$2:$I$335,C17)) | L17: =IF(OR(F17="",K17=""),"",IF(K17=0,"",F17/K17)) | M17: =IF(OR(F17="",I17=""),"",IF(F17<I17,"偏低",IF(F17>J17,"偏高","範圍內"))) | N17: =IF(OR(F17="",I17=""),"",COUNTIFS('7_參考資料'!$A$2:$A$335,B17,'7_參考資料'!$I$2:$I$335,C17,'7_參考資料'!$T$2:$T$335,"<="&F17,'7_參考資料'!$U$2:$U$335,">="&F17)&" / "&COUNTIFS('7_參考資料'!$A$2:$A$335,B17,'7_參考資料'!$I$2:$I$335,C17)) | O17: =IFERROR(AVERAGEIFS('7_參考資料'!$J$2:$J$335,'7_參考資料'!$A$2:$A$335,B17,'7_參考資料'!$I$2:$I$335,"water"),"") | P17: =IF(F17="","",IF(AND(M17<>"範圍內",ISNUMBER(L17),N(L17)>0),IF(AND(ABS(ROUND(LOG10(L17),0))>=1,ABS(ROUND(LOG10(L17),0))<=3,ABS(LOG10(L17)-ROUND(LOG10(L17),0))<LOG10(1.25)),"單位換算錯誤？實測約"&IF(L17>1,"高","低")&" "&10^ABS(ROUND(LOG10(L17),0))&" 倍；",""),"")&IF(AND(AND(M17<>"範圍內",ISNUMBER(L17),N(L17)>0),C17="sodium"),IF(ABS(ABS(LOG10(L17))-LOG10('3_鈉與NaCl'!$C$7))<LOG10(1.25),"Na 與 NaCl 混用？約 2.542 倍；",""),"")&IF(AND(AND(M17<>"範圍內",ISNUMBER(L17),N(L17)>0),ISNUMBER(H17),N(H17)>1),IF(ABS(ABS(LOG10(L17))-LOG10(H17))<LOG10(1.25),"稀釋倍數 "&H17&" 忘了乘或多乘？；",IF(AND(H17/10<>1,H17/10<>10,H17/10<>100,ABS(ABS(LOG10(L17))-LOG10(H17/10))<LOG10(1.25)),"約 D/10 = "&H17/10&" 倍：忘了 ×D 並 ÷10 換成每 100 g？；","")),"")&IF(AND(ISNUMBER(O17),N(O17)>=3,ISNUMBER(K17),N(K17)>0),IF(AND(ABS(F17/(K17/(1-O17/100))-1)<0.05,ABS(F17/K17-1)>0.08),"基準不一致？接近乾基參考值 "&TEXT((K17/(1-O17/100)),"0.00")&"（資料庫是濕基）；",""),"")) | R17: E＝密度：醬油的結果是 mg/100 mL，資料庫是 mg/100 g，所以 F ＝ D ÷ 密度。SD 也一樣除以密度。
A18: brown_rice | B18: brown_rice | C18: ash | D18: =IFERROR(INDEX('2_灰分'!$D$42:$D$46,MATCH(A18,'2_灰分'!$A$42:$A$46,0)),"") | F18: =IF(D18="","",IF(ISNUMBER(E18),D18/E18,D18)) | G18: =IFERROR(INDEX('2_灰分'!$E$42:$E$46,MATCH(A18,'2_灰分'!$A$42:$A$46,0)),"") | I18: {=IF(COUNTIFS('7_參考資料'!$A$2:$A$335,B18,'7_參考資料'!$I$2:$I$335,C18)=0,"",MIN(IF(('7_參考資料'!$A$2:$A$335=B18)*('7_參考資料'!$I$2:$I$335=C18)*ISNUMBER('7_參考資料'!$T$2:$T$335),'7_參考資料'!$T$2:$T$335)))} | J18: {=IF(COUNTIFS('7_參考資料'!$A$2:$A$335,B18,'7_參考資料'!$I$2:$I$335,C18)=0,"",MAX(IF(('7_參考資料'!$A$2:$A$335=B18)*('7_參考資料'!$I$2:$I$335=C18)*ISNUMBER('7_參考資料'!$T$2:$T$335),'7_參考資料'!$U$2:$U$335)))} | K18: =IF(COUNTIFS('7_參考資料'!$A$2:$A$335,B18,'7_參考資料'!$I$2:$I$335,C18)=0,"",AVERAGEIFS('7_參考資料'!$J$2:$J$335,'7_參考資料'!$A$2:$A$335,B18,'7_參考資料'!$I$2:$I$335,C18)) | L18: =IF(OR(F18="",K18=""),"",IF(K18=0,"",F18/K18)) | M18: =IF(OR(F18="",I18=""),"",IF(F18<I18,"偏低",IF(F18>J18,"偏高","範圍內"))) | N18: =IF(OR(F18="",I18=""),"",COUNTIFS('7_參考資料'!$A$2:$A$335,B18,'7_參考資料'!$I$2:$I$335,C18,'7_參考資料'!$T$2:$T$335,"<="&F18,'7_參考資料'!$U$2:$U$335,">="&F18)&" / "&COUNTIFS('7_參考資料'!$A$2:$A$335,B18,'7_參考資料'!$I$2:$I$335,C18)) | O18: =IFERROR(AVERAGEIFS('7_參考資料'!$J$2:$J$335,'7_參考資料'!$A$2:$A$335,B18,'7_參考資料'!$I$2:$I$335,"water"),"") | P18: =IF(F18="","",IF(AND(M18<>"範圍內",ISNUMBER(L18),N(L18)>0),IF(AND(ABS(ROUND(LOG10(L18),0))>=1,ABS(ROUND(LOG10(L18),0))<=3,ABS(LOG10(L18)-ROUND(LOG10(L18),0))<LOG10(1.25)),"單位換算錯誤？實測約"&IF(L18>1,"高","低")&" "&10^ABS(ROUND(LOG10(L18),0))&" 倍；",""),"")&IF(AND(AND(M18<>"範圍內",ISNUMBER(L18),N(L18)>0),C18="sodium"),IF(ABS(ABS(LOG10(L18))-LOG10('3_鈉與NaCl'!$C$7))<LOG10(1.25),"Na 與 NaCl 混用？約 2.542 倍；",""),"")&IF(AND(AND(M18<>"範圍內",ISNUMBER(L18),N(L18)>0),ISNUMBER(H18),N(H18)>1),IF(ABS(ABS(LOG10(L18))-LOG10(H18))<LOG10(1.25),"稀釋倍數 "&H18&" 忘了乘或多乘？；",IF(AND(H18/10<>1,H18/10<>10,H18/10<>100,ABS(ABS(LOG10(L18))-LOG10(H18/10))<LOG10(1.25)),"約 D/10 = "&H18/10&" 倍：忘了 ×D 並 ÷10 換成每 100 g？；","")),"")&IF(AND(ISNUMBER(O18),N(O18)>=3,ISNUMBER(K18),N(K18)>0),IF(AND(ABS(F18/(K18/(1-O18/100))-1)<0.05,ABS(F18/K18-1)>0.08),"基準不一致？接近乾基參考值 "&TEXT((K18/(1-O18/100)),"0.00")&"（資料庫是濕基）；",""),"")) | R18: I、J＝合理範圍：陣列公式 {=MIN(IF((品項=B)*(營養素=C), 每筆下限))}，就是在「7_參考資料」裡，只挑這個食品、這個營養素的列，取最小的下限／最大的上限。
A19: polished_rice | B19: white_rice | C19: ash | D19: =IFERROR(INDEX('2_灰分'!$D$42:$D$46,MATCH(A19,'2_灰分'!$A$42:$A$46,0)),"") | F19: =IF(D19="","",IF(ISNUMBER(E19),D19/E19,D19)) | G19: =IFERROR(INDEX('2_灰分'!$E$42:$E$46,MATCH(A19,'2_灰分'!$A$42:$A$46,0)),"") | I19: {=IF(COUNTIFS('7_參考資料'!$A$2:$A$335,B19,'7_參考資料'!$I$2:$I$335,C19)=0,"",MIN(IF(('7_參考資料'!$A$2:$A$335=B19)*('7_參考資料'!$I$2:$I$335=C19)*ISNUMBER('7_參考資料'!$T$2:$T$335),'7_參考資料'!$T$2:$T$335)))} | J19: {=IF(COUNTIFS('7_參考資料'!$A$2:$A$335,B19,'7_參考資料'!$I$2:$I$335,C19)=0,"",MAX(IF(('7_參考資料'!$A$2:$A$335=B19)*('7_參考資料'!$I$2:$I$335=C19)*ISNUMBER('7_參考資料'!$T$2:$T$335),'7_參考資料'!$U$2:$U$335)))} | K19: =IF(COUNTIFS('7_參考資料'!$A$2:$A$335,B19,'7_參考資料'!$I$2:$I$335,C19)=0,"",AVERAGEIFS('7_參考資料'!$J$2:$J$335,'7_參考資料'!$A$2:$A$335,B19,'7_參考資料'!$I$2:$I$335,C19)) | L19: =IF(OR(F19="",K19=""),"",IF(K19=0,"",F19/K19)) | M19: =IF(OR(F19="",I19=""),"",IF(F19<I19,"偏低",IF(F19>J19,"偏高","範圍內"))) | N19: =IF(OR(F19="",I19=""),"",COUNTIFS('7_參考資料'!$A$2:$A$335,B19,'7_參考資料'!$I$2:$I$335,C19,'7_參考資料'!$T$2:$T$335,"<="&F19,'7_參考資料'!$U$2:$U$335,">="&F19)&" / "&COUNTIFS('7_參考資料'!$A$2:$A$335,B19,'7_參考資料'!$I$2:$I$335,C19)) | O19: =IFERROR(AVERAGEIFS('7_參考資料'!$J$2:$J$335,'7_參考資料'!$A$2:$A$335,B19,'7_參考資料'!$I$2:$I$335,"water"),"") | P19: =IF(F19="","",IF(AND(M19<>"範圍內",ISNUMBER(L19),N(L19)>0),IF(AND(ABS(ROUND(LOG10(L19),0))>=1,ABS(ROUND(LOG10(L19),0))<=3,ABS(LOG10(L19)-ROUND(LOG10(L19),0))<LOG10(1.25)),"單位換算錯誤？實測約"&IF(L19>1,"高","低")&" "&10^ABS(ROUND(LOG10(L19),0))&" 倍；",""),"")&IF(AND(AND(M19<>"範圍內",ISNUMBER(L19),N(L19)>0),C19="sodium"),IF(ABS(ABS(LOG10(L19))-LOG10('3_鈉與NaCl'!$C$7))<LOG10(1.25),"Na 與 NaCl 混用？約 2.542 倍；",""),"")&IF(AND(AND(M19<>"範圍內",ISNUMBER(L19),N(L19)>0),ISNUMBER(H19),N(H19)>1),IF(ABS(ABS(LOG10(L19))-LOG10(H19))<LOG10(1.25),"稀釋倍數 "&H19&" 忘了乘或多乘？；",IF(AND(H19/10<>1,H19/10<>10,H19/10<>100,ABS(ABS(LOG10(L19))-LOG10(H19/10))<LOG10(1.25)),"約 D/10 = "&H19/10&" 倍：忘了 ×D 並 ÷10 換成每 100 g？；","")),"")&IF(AND(ISNUMBER(O19),N(O19)>=3,ISNUMBER(K19),N(K19)>0),IF(AND(ABS(F19/(K19/(1-O19/100))-1)<0.05,ABS(F19/K19-1)>0.08),"基準不一致？接近乾基參考值 "&TEXT((K19/(1-O19/100)),"0.00")&"（資料庫是濕基）；",""),"")) | R19: K＝參考中心：各筆資料庫值的平均（AVERAGEIFS）。L＝實測 ÷ 中心，≈ 1 表示跟資料庫差不多。
A20: milk_powder | B20: whole_milk_powder | C20: ash | D20: =IFERROR(INDEX('2_灰分'!$D$42:$D$46,MATCH(A20,'2_灰分'!$A$42:$A$46,0)),"") | F20: =IF(D20="","",IF(ISNUMBER(E20),D20/E20,D20)) | G20: =IFERROR(INDEX('2_灰分'!$E$42:$E$46,MATCH(A20,'2_灰分'!$A$42:$A$46,0)),"") | I20: {=IF(COUNTIFS('7_參考資料'!$A$2:$A$335,B20,'7_參考資料'!$I$2:$I$335,C20)=0,"",MIN(IF(('7_參考資料'!$A$2:$A$335=B20)*('7_參考資料'!$I$2:$I$335=C20)*ISNUMBER('7_參考資料'!$T$2:$T$335),'7_參考資料'!$T$2:$T$335)))} | J20: {=IF(COUNTIFS('7_參考資料'!$A$2:$A$335,B20,'7_參考資料'!$I$2:$I$335,C20)=0,"",MAX(IF(('7_參考資料'!$A$2:$A$335=B20)*('7_參考資料'!$I$2:$I$335=C20)*ISNUMBER('7_參考資料'!$T$2:$T$335),'7_參考資料'!$U$2:$U$335)))} | K20: =IF(COUNTIFS('7_參考資料'!$A$2:$A$335,B20,'7_參考資料'!$I$2:$I$335,C20)=0,"",AVERAGEIFS('7_參考資料'!$J$2:$J$335,'7_參考資料'!$A$2:$A$335,B20,'7_參考資料'!$I$2:$I$335,C20)) | L20: =IF(OR(F20="",K20=""),"",IF(K20=0,"",F20/K20)) | M20: =IF(OR(F20="",I20=""),"",IF(F20<I20,"偏低",IF(F20>J20,"偏高","範圍內"))) | N20: =IF(OR(F20="",I20=""),"",COUNTIFS('7_參考資料'!$A$2:$A$335,B20,'7_參考資料'!$I$2:$I$335,C20,'7_參考資料'!$T$2:$T$335,"<="&F20,'7_參考資料'!$U$2:$U$335,">="&F20)&" / "&COUNTIFS('7_參考資料'!$A$2:$A$335,B20,'7_參考資料'!$I$2:$I$335,C20)) | O20: =IFERROR(AVERAGEIFS('7_參考資料'!$J$2:$J$335,'7_參考資料'!$A$2:$A$335,B20,'7_參考資料'!$I$2:$I$335,"water"),"") | P20: =IF(F20="","",IF(AND(M20<>"範圍內",ISNUMBER(L20),N(L20)>0),IF(AND(ABS(ROUND(LOG10(L20),0))>=1,ABS(ROUND(LOG10(L20),0))<=3,ABS(LOG10(L20)-ROUND(LOG10(L20),0))<LOG10(1.25)),"單位換算錯誤？實測約"&IF(L20>1,"高","低")&" "&10^ABS(ROUND(LOG10(L20),0))&" 倍；",""),"")&IF(AND(AND(M20<>"範圍內",ISNUMBER(L20),N(L20)>0),C20="sodium"),IF(ABS(ABS(LOG10(L20))-LOG10('3_鈉與NaCl'!$C$7))<LOG10(1.25),"Na 與 NaCl 混用？約 2.542 倍；",""),"")&IF(AND(AND(M20<>"範圍內",ISNUMBER(L20),N(L20)>0),ISNUMBER(H20),N(H20)>1),IF(ABS(ABS(LOG10(L20))-LOG10(H20))<LOG10(1.25),"稀釋倍數 "&H20&" 忘了乘或多乘？；",IF(AND(H20/10<>1,H20/10<>10,H20/10<>100,ABS(ABS(LOG10(L20))-LOG10(H20/10))<LOG10(1.25)),"約 D/10 = "&H20/10&" 倍：忘了 ×D 並 ÷10 換成每 100 g？；","")),"")&IF(AND(ISNUMBER(O20),N(O20)>=3,ISNUMBER(K20),N(K20)>0),IF(AND(ABS(F20/(K20/(1-O20/100))-1)<0.05,ABS(F20/K20-1)>0.08),"基準不一致？接近乾基參考值 "&TEXT((K20/(1-O20/100)),"0.00")&"（資料庫是濕基）；",""),"")) | R20: M＝判定：比下限小是「偏低」、比上限大是「偏高」。N＝有幾筆資料庫值的區間涵蓋你的數字；若只有 1 筆撐住「範圍內」，解讀要保守。
