Workbook

Sheet 0_說明
B1: EX04｜W4 手動滴定 vs 自動滴定（可滴定酸度）
B2: 食品分析實驗・入門數據分析（Excel 版）。不用寫程式；同一份數據在 Colab 筆記本做進階分析，答案應該一致。
B4: 學習目標
B5: • 用 KHP 標定 NaOH：N = KHP 質量 ÷ (204.22 × V_L)，並看各組標定的一致性（平均、SD、RSD）。
B6: • 用 % 酸 = N × V × 當量重 ÷ (W × 1000) × 100 算白醋、柳橙汁、優格、紅酒的可滴定酸度。
B7: • 讀 PASCO 匯出的滴定曲線，用一階導數最大值（MAX／MATCH／INDEX）與二階導數零交叉找當量點，用半當量點估 pKa。
B8: • 理解體積間距不均勻時，一定要用每一段實際的 ΔV 算導數。
B9: • 用 Bland–Altman（bias、±1.96 SD 一致性界限）、配對 t 檢定、F 檢定比較手動與 PASCO；理解 r 高不代表兩法一致。
B11: 顏色代表什麼
C12: 黃色：輸入或貼上數據的地方
C13: 綠色：公式，會自動計算，不要改
C14: 橘色：重點結果，寫報告時用
B16: 操作步驟
B17: 1. 看「1_原始數據」：一列是一次量測。右邊綠色欄逐列算好 N、當量重、% 酸、配對的 PASCO 值與差值。
B18: 2. 看「2_NaOH標定」：用講義範例練習計算機，再看各組的 N 與全班 RSD。
B19: 3. 看「3_可滴定酸度」：確認樣品參數表（當量重、取樣量），看各樣品的平均 % 酸與 RSD。
B20: 4. 看「4_滴定曲線」：A、B 欄是 PASCO 曲線，右邊找當量點與半當量點，往下捲有三張圖。
B21: 5. 看「5_手動vs自動」：配對表、Bland–Altman 統計、配對 t、F 檢定與兩張圖。
B22: 6. 完成「練習題」。
B23: 7. 換成班級數據：Google Sheet 的長格式數據貼到「1_原始數據」A2；PASCO 曲線（體積, pH）貼到「4_滴定曲線」A4。
B25: 對答案：用內建範例數據時，你的結果應該等於
B26: 項目 | C26: 本檔計算值 | D26: Colab 筆記本的值 | E26: 一致？
B27: 第 1 組 N_NaOH (M) | C27: ='2_NaOH標定'!F15 | D27: 0.10082319 | E27: =IF(ABS(C27-D27)<=1.0083318892734904e-05,"✔ 一致","✘ 不一致（換成班級數據後本來就會不同）")
B28: 白醋手動平均 % 酸 | C28: ='3_可滴定酸度'!D24 | D28: 4.5154413 | E28: =IF(ABS(C28-D28)<=0.0004515451314535296,"✔ 一致","✘ 不一致（換成班級數據後本來就會不同）")
B29: 紅酒手動 RSD (%) | C29: ='3_可滴定酸度'!F27 | D29: 21.344948 | E29: =IF(ABS(C29-D29)<=0.002134495777532426,"✔ 一致","✘ 不一致（換成班級數據後本來就會不同）")
B30: 當量點 Veq，一階導數法 (mL) | C30: ='4_滴定曲線'!L10 | D30: 18.7465 | E30: =IF(ABS(C30-D30)<=0.0018746510000000002,"✔ 一致","✘ 不一致（換成班級數據後本來就會不同）")
B31: 一階導數峰值 (pH/mL) | C31: ='4_滴定曲線'!L8 | D31: 25.115044 | E31: =IF(ABS(C31-D31)<=0.002511505424778772,"✔ 一致","✘ 不一致（換成班級數據後本來就會不同）")
B32: bias：PASCO − 手動 (%) | C32: ='5_手動vs自動'!L6 | D32: 0.017984613 | E32: =IF(ABS(C32-D32)<=1.7994612643236835e-06,"✔ 一致","✘ 不一致（換成班級數據後本來就會不同）")
B33: 一致性界限上限 (%) | C33: ='5_手動vs自動'!L9 | D33: 0.12144152 | E33: =IF(ABS(C33-D33)<=1.2145151627049954e-05,"✔ 一致","✘ 不一致（換成班級數據後本來就會不同）")
B34: F（合併變異數比） | C34: ='5_手動vs自動'!L29 | D34: 1.7942664 | E34: =IF(ABS(C34-D34)<=0.00017942764137279715,"✔ 一致","✘ 不一致（換成班級數據後本來就會不同）")
B35: 「Colab 筆記本的值」是用內建模擬數據算出的答案；換成全班數據後，這一欄就不再適用。
B37: 相關連結
B38: 本週實驗投影片 | C38: https://tai-shengyeh.github.io/food-analysis-lab/labs/w04_titration/index.html
B39: 進階：Colab 筆記本（Python） | C39: https://colab.research.google.com/github/Tai-ShengYeh/food-analysis-lab/blob/main/notebooks/NB04_titration.ipynb
B40: 數據分析工具指南（Excel／Orange／Colab） | C40: https://tai-shengyeh.github.io/food-analysis-lab/tools.html
B42: 小提醒
B43: • 進階：把曲線內插到 0.05 mL 的均勻網格、再用移動平均平滑化後取導數（看平滑化對峰值的影響），以及用完整電荷平衡式模擬理論曲線，這兩部分請看 Colab 筆記本。
B44: • 本檔的二階導數零交叉是在一階導數峰值前後直接內插，範例曲線得約 18.75 mL；Colab 筆記本在平滑後的網格上取「±3 mL 內第一個變號點」，會抓到雜訊而得 16.19 mL，兩者不同是正常的。
B45: • 滴定曲線圖的範圍涵蓋到第 603 列，PASCO 數據點數不同也不用改圖。
B46: • Google 試算表也能開這個檔（檔案 → 匯入），公式都一樣能用。
...

Sheet 1_原始數據
A1: group | B1: student | C1: item | D1: rep | E1: value | F1: unit | G1: temp_C | H1: note | I1: sample | J1: N_KHP_M | K1: N_NaOH_M | L1: eqwt | M1: W_sample | N1: manual_pct_acid | O1: pasco_pct_acid | P1: diff_pct | Q1: mean_pct | R1: pair_no | T1: 這張工作表怎麼用
A2: 1 | B2: G1_S1 | C2: khp_mass_g | D2: 1 | E2: 0.5164 | F2: g | G2: 25 | I2: KHP | J2: =IF($A2="","",IF($C2<>"khp_titration_mL","",IF(COUNTIFS('1_原始數據'!$A$2:$A$1000,$A2,'1_原始數據'!$B$2:$B$1000,$B2,'1_原始數據'!$D$2:$D$1000,$D2,'1_原始數據'!$C$2:$C$1000,"khp_mass_g")=0,"",SUMIFS('1_原始數據'!$E$2:$E$1000,'1_原始數據'!$A$2:$A$1000,$A2,'1_原始數據'!$B$2:$B$1000,$B2,'1_原始數據'!$D$2:$D$1000,$D2,'1_原始數據'!$C$2:$C$1000,"khp_mass_g")/('2_NaOH標定'!$C$5*$E2/1000)))) | K2: =IF($A2="","",IF($C2<>"manual_titration_mL","",IF(COUNTIFS('1_原始數據'!$A$2:$A$1000,$A2,'1_原始數據'!$C$2:$C$1000,"khp_titration_mL")=0,"",AVERAGEIFS('1_原始數據'!$J$2:$J$1000,'1_原始數據'!$A$2:$A$1000,$A2,'1_原始數據'!$C$2:$C$1000,"khp_titration_mL")))) | L2: =IF($A2="","",IF($C2<>"manual_titration_mL","",IFERROR(INDEX('3_可滴定酸度'!$E$6:$E$13,MATCH($I2,'3_可滴定酸度'!$B$6:$B$13,0)),""))) | M2: =IF($A2="","",IF($C2<>"manual_titration_mL","",IFERROR(INDEX('3_可滴定酸度'!$F$6:$F$13,MATCH($I2,'3_可滴定酸度'!$B$6:$B$13,0)),""))) | N2: =IF($A2="","",IF(OR(K2="",L2="",M2=""),"",K2*E2*L2/(M2*1000)*100)) | O2: =IF($A2="","",IF(N2="","",IF(COUNTIFS('1_原始數據'!$A$2:$A$1000,$A2,'1_原始數據'!$B$2:$B$1000,$B2,'1_原始數據'!$D$2:$D$1000,$D2,'1_原始數據'!$I$2:$I$1000,$I2,'1_原始數據'!$C$2:$C$1000,"pasco_pct_acid")=0,"",SUMIFS('1_原始數據'!$E$2:$E$1000,'1_原始數據'!$A$2:$A$1000,$A2,'1_原始數據'!$B$2:$B$1000,$B2,'1_原始數據'!$D$2:$D$1000,$D2,'1_原始數據'!$I$2:$I$1000,$I2,'1_原始數據'!$C$2:$C$1000,"pasco_pct_acid")))) | P2: =IF($A2="","",IF(OR(N2="",O2=""),"",O2-N2)) | Q2: =IF($A2="","",IF(P2="","",(O2+N2)/2)) | R2: =IF($A2="","",IF(P2="","",COUNT($P$2:P2))) | T2: 本週 item：khp_mass_g＝KHP 質量 (g)；khp_titration_mL＝標定用去的 NaOH (mL)；manual_titration_mL＝手動滴定樣品用去的 NaOH (mL)；pasco_pct_acid＝PASCO 軟體直接算出的 % 酸。sample＝樣品（vinegar 白醋、orange_juice 柳橙汁、yogurt 優格、red_wine 紅酒）。
A3: 1 | B3: G1_S1 | C3: khp_titration_mL | D3: 1 | E3: 25.08 | F3: mL | G3: 25 | I3: NaOH | J3: =IF($A3="","",IF($C3<>"khp_titration_mL","",IF(COUNTIFS('1_原始數據'!$A$2:$A$1000,$A3,'1_原始數據'!$B$2:$B$1000,$B3,'1_原始數據'!$D$2:$D$1000,$D3,'1_原始數據'!$C$2:$C$1000,"khp_mass_g")=0,"",SUMIFS('1_原始數據'!$E$2:$E$1000,'1_原始數據'!$A$2:$A$1000,$A3,'1_原始數據'!$B$2:$B$1000,$B3,'1_原始數據'!$D$2:$D$1000,$D3,'1_原始數據'!$C$2:$C$1000,"khp_mass_g")/('2_NaOH標定'!$C$5*$E3/1000)))) | K3: =IF($A3="","",IF($C3<>"manual_titration_mL","",IF(COUNTIFS('1_原始數據'!$A$2:$A$1000,$A3,'1_原始數據'!$C$2:$C$1000,"khp_titration_mL")=0,"",AVERAGEIFS('1_原始數據'!$J$2:$J$1000,'1_原始數據'!$A$2:$A$1000,$A3,'1_原始數據'!$C$2:$C$1000,"khp_titration_mL")))) | L3: =IF($A3="","",IF($C3<>"manual_titration_mL","",IFERROR(INDEX('3_可滴定酸度'!$E$6:$E$13,MATCH($I3,'3_可滴定酸度'!$B$6:$B$13,0)),""))) | M3: =IF($A3="","",IF($C3<>"manual_titration_mL","",IFERROR(INDEX('3_可滴定酸度'!$F$6:$F$13,MATCH($I3,'3_可滴定酸度'!$B$6:$B$13,0)),""))) | N3: =IF($A3="","",IF(OR(K3="",L3="",M3=""),"",K3*E3*L3/(M3*1000)*100)) | O3: =IF($A3="","",IF(N3="","",IF(COUNTIFS('1_原始數據'!$A$2:$A$1000,$A3,'1_原始數據'!$B$2:$B$1000,$B3,'1_原始數據'!$D$2:$D$1000,$D3,'1_原始數據'!$I$2:$I$1000,$I3,'1_原始數據'!$C$2:$C$1000,"pasco_pct_acid")=0,"",SUMIFS('1_原始數據'!$E$2:$E$1000,'1_原始數據'!$A$2:$A$1000,$A3,'1_原始數據'!$B$2:$B$1000,$B3,'1_原始數據'!$D$2:$D$1000,$D3,'1_原始數據'!$I$2:$I$1000,$I3,'1_原始數據'!$C$2:$C$1000,"pasco_pct_acid")))) | P3: =IF($A3="","",IF(OR(N3="",O3=""),"",O3-N3)) | Q3: =IF($A3="","",IF(P3="","",(O3+N3)/2)) | R3: =IF($A3="","",IF(P3="","",COUNT($P$2:P3))) | T3: 滴定曲線（體積-pH）是另一種格式，請貼在「4_滴定曲線」。
A4: 2 | B4: G2_S1 | C4: khp_mass_g | D4: 1 | E4: 0.5215 | F4: g | G4: 25 | I4: KHP | J4: =IF($A4="","",IF($C4<>"khp_titration_mL","",IF(COUNTIFS('1_原始數據'!$A$2:$A$1000,$A4,'1_原始數據'!$B$2:$B$1000,$B4,'1_原始數據'!$D$2:$D$1000,$D4,'1_原始數據'!$C$2:$C$1000,"khp_mass_g")=0,"",SUMIFS('1_原始數據'!$E$2:$E$1000,'1_原始數據'!$A$2:$A$1000,$A4,'1_原始數據'!$B$2:$B$1000,$B4,'1_原始數據'!$D$2:$D$1000,$D4,'1_原始數據'!$C$2:$C$1000,"khp_mass_g")/('2_NaOH標定'!$C$5*$E4/1000)))) | K4: =IF($A4="","",IF($C4<>"manual_titration_mL","",IF(COUNTIFS('1_原始數據'!$A$2:$A$1000,$A4,'1_原始數據'!$C$2:$C$1000,"khp_titration_mL")=0,"",AVERAGEIFS('1_原始數據'!$J$2:$J$1000,'1_原始數據'!$A$2:$A$1000,$A4,'1_原始數據'!$C$2:$C$1000,"khp_titration_mL")))) | L4: =IF($A4="","",IF($C4<>"manual_titration_mL","",IFERROR(INDEX('3_可滴定酸度'!$E$6:$E$13,MATCH($I4,'3_可滴定酸度'!$B$6:$B$13,0)),""))) | M4: =IF($A4="","",IF($C4<>"manual_titration_mL","",IFERROR(INDEX('3_可滴定酸度'!$F$6:$F$13,MATCH($I4,'3_可滴定酸度'!$B$6:$B$13,0)),""))) | N4: =IF($A4="","",IF(OR(K4="",L4="",M4=""),"",K4*E4*L4/(M4*1000)*100)) | O4: =IF($A4="","",IF(N4="","",IF(COUNTIFS('1_原始數據'!$A$2:$A$1000,$A4,'1_原始數據'!$B$2:$B$1000,$B4,'1_原始數據'!$D$2:$D$1000,$D4,'1_原始數據'!$I$2:$I$1000,$I4,'1_原始數據'!$C$2:$C$1000,"pasco_pct_acid")=0,"",SUMIFS('1_原始數據'!$E$2:$E$1000,'1_原始數據'!$A$2:$A$1000,$A4,'1_原始數據'!$B$2:$B$1000,$B4,'1_原始數據'!$D$2:$D$1000,$D4,'1_原始數據'!$I$2:$I$1000,$I4,'1_原始數據'!$C$2:$C$1000,"pasco_pct_acid")))) | P4: =IF($A4="","",IF(OR(N4="",O4=""),"",O4-N4)) | Q4: =IF($A4="","",IF(P4="","",(O4+N4)/2)) | R4: =IF($A4="","",IF(P4="","",COUNT($P$2:P4))) | T4: 黃色欄位＝原始數據。換成全班數據時：從共用 Google Sheet 複製，貼到 A2（欄位順序必須一樣），舊資料多出來的列要整列刪除。
A5: 2 | B5: G2_S1 | C5: khp_titration_mL | D5: 1 | E5: 25.43 | F5: mL | G5: 25 | I5: NaOH | J5: =IF($A5="","",IF($C5<>"khp_titration_mL","",IF(COUNTIFS('1_原始數據'!$A$2:$A$1000,$A5,'1_原始數據'!$B$2:$B$1000,$B5,'1_原始數據'!$D$2:$D$1000,$D5,'1_原始數據'!$C$2:$C$1000,"khp_mass_g")=0,"",SUMIFS('1_原始數據'!$E$2:$E$1000,'1_原始數據'!$A$2:$A$1000,$A5,'1_原始數據'!$B$2:$B$1000,$B5,'1_原始數據'!$D$2:$D$1000,$D5,'1_原始數據'!$C$2:$C$1000,"khp_mass_g")/('2_NaOH標定'!$C$5*$E5/1000)))) | K5: =IF($A5="","",IF($C5<>"manual_titration_mL","",IF(COUNTIFS('1_原始數據'!$A$2:$A$1000,$A5,'1_原始數據'!$C$2:$C$1000,"khp_titration_mL")=0,"",AVERAGEIFS('1_原始數據'!$J$2:$J$1000,'1_原始數據'!$A$2:$A$1000,$A5,'1_原始數據'!$C$2:$C$1000,"khp_titration_mL")))) | L5: =IF($A5="","",IF($C5<>"manual_titration_mL","",IFERROR(INDEX('3_可滴定酸度'!$E$6:$E$13,MATCH($I5,'3_可滴定酸度'!$B$6:$B$13,0)),""))) | M5: =IF($A5="","",IF($C5<>"manual_titration_mL","",IFERROR(INDEX('3_可滴定酸度'!$F$6:$F$13,MATCH($I5,'3_可滴定酸度'!$B$6:$B$13,0)),""))) | N5: =IF($A5="","",IF(OR(K5="",L5="",M5=""),"",K5*E5*L5/(M5*1000)*100)) | O5: =IF($A5="","",IF(N5="","",IF(COUNTIFS('1_原始數據'!$A$2:$A$1000,$A5,'1_原始數據'!$B$2:$B$1000,$B5,'1_原始數據'!$D$2:$D$1000,$D5,'1_原始數據'!$I$2:$I$1000,$I5,'1_原始數據'!$C$2:$C$1000,"pasco_pct_acid")=0,"",SUMIFS('1_原始數據'!$E$2:$E$1000,'1_原始數據'!$A$2:$A$1000,$A5,'1_原始數據'!$B$2:$B$1000,$B5,'1_原始數據'!$D$2:$D$1000,$D5,'1_原始數據'!$I$2:$I$1000,$I5,'1_原始數據'!$C$2:$C$1000,"pasco_pct_acid")))) | P5: =IF($A5="","",IF(OR(N5="",O5=""),"",O5-N5)) | Q5: =IF($A5="","",IF(P5="","",(O5+N5)/2)) | R5: =IF($A5="","",IF(P5="","",COUNT($P$2:P5))) | T5: 綠色欄位＝公式，會自動算到第 1000 列，不要手動修改。
A6: 3 | B6: G3_S1 | C6: khp_mass_g | D6: 1 | E6: 0.4757 | F6: g | G6: 25 | I6: KHP | J6: =IF($A6="","",IF($C6<>"khp_titration_mL","",IF(COUNTIFS('1_原始數據'!$A$2:$A$1000,$A6,'1_原始數據'!$B$2:$B$1000,$B6,'1_原始數據'!$D$2:$D$1000,$D6,'1_原始數據'!$C$2:$C$1000,"khp_mass_g")=0,"",SUMIFS('1_原始數據'!$E$2:$E$1000,'1_原始數據'!$A$2:$A$1000,$A6,'1_原始數據'!$B$2:$B$1000,$B6,'1_原始數據'!$D$2:$D$1000,$D6,'1_原始數據'!$C$2:$C$1000,"khp_mass_g")/('2_NaOH標定'!$C$5*$E6/1000)))) | K6: =IF($A6="","",IF($C6<>"manual_titration_mL","",IF(COUNTIFS('1_原始數據'!$A$2:$A$1000,$A6,'1_原始數據'!$C$2:$C$1000,"khp_titration_mL")=0,"",AVERAGEIFS('1_原始數據'!$J$2:$J$1000,'1_原始數據'!$A$2:$A$1000,$A6,'1_原始數據'!$C$2:$C$1000,"khp_titration_mL")))) | L6: =IF($A6="","",IF($C6<>"manual_titration_mL","",IFERROR(INDEX('3_可滴定酸度'!$E$6:$E$13,MATCH($I6,'3_可滴定酸度'!$B$6:$B$13,0)),""))) | M6: =IF($A6="","",IF($C6<>"manual_titration_mL","",IFERROR(INDEX('3_可滴定酸度'!$F$6:$F$13,MATCH($I6,'3_可滴定酸度'!$B$6:$B$13,0)),""))) | N6: =IF($A6="","",IF(OR(K6="",L6="",M6=""),"",K6*E6*L6/(M6*1000)*100)) | O6: =IF($A6="","",IF(N6="","",IF(COUNTIFS('1_原始數據'!$A$2:$A$1000,$A6,'1_原始數據'!$B$2:$B$1000,$B6,'1_原始數據'!$D$2:$D$1000,$D6,'1_原始數據'!$I$2:$I$1000,$I6,'1_原始數據'!$C$2:$C$1000,"pasco_pct_acid")=0,"",SUMIFS('1_原始數據'!$E$2:$E$1000,'1_原始數據'!$A$2:$A$1000,$A6,'1_原始數據'!$B$2:$B$1000,$B6,'1_原始數據'!$D$2:$D$1000,$D6,'1_原始數據'!$I$2:$I$1000,$I6,'1_原始數據'!$C$2:$C$1000,"pasco_pct_acid")))) | P6: =IF($A6="","",IF(OR(N6="",O6=""),"",O6-N6)) | Q6: =IF($A6="","",IF(P6="","",(O6+N6)/2)) | R6: =IF($A6="","",IF(P6="","",COUNT($P$2:P6))) | T6: 「N_KHP_M」：只在 khp_titration_mL 那一列算：同組、同學生、同 rep 的 KHP 質量 ÷ (204.22 × NaOH 體積 L)，得到這一次標定的 NaOH 濃度 (M)。
A7: 3 | B7: G3_S1 | C7: khp_titration_mL | D7: 1 | E7: 23.09 | F7: mL | G7: 25 | I7: NaOH | J7: =IF($A7="","",IF($C7<>"khp_titration_mL","",IF(COUNTIFS('1_原始數據'!$A$2:$A$1000,$A7,'1_原始數據'!$B$2:$B$1000,$B7,'1_原始數據'!$D$2:$D$1000,$D7,'1_原始數據'!$C$2:$C$1000,"khp_mass_g")=0,"",SUMIFS('1_原始數據'!$E$2:$E$1000,'1_原始數據'!$A$2:$A$1000,$A7,'1_原始數據'!$B$2:$B$1000,$B7,'1_原始數據'!$D$2:$D$1000,$D7,'1_原始數據'!$C$2:$C$1000,"khp_mass_g")/('2_NaOH標定'!$C$5*$E7/1000)))) | K7: =IF($A7="","",IF($C7<>"manual_titration_mL","",IF(COUNTIFS('1_原始數據'!$A$2:$A$1000,$A7,'1_原始數據'!$C$2:$C$1000,"khp_titration_mL")=0,"",AVERAGEIFS('1_原始數據'!$J$2:$J$1000,'1_原始數據'!$A$2:$A$1000,$A7,'1_原始數據'!$C$2:$C$1000,"khp_titration_mL")))) | L7: =IF($A7="","",IF($C7<>"manual_titration_mL","",IFERROR(INDEX('3_可滴定酸度'!$E$6:$E$13,MATCH($I7,'3_可滴定酸度'!$B$6:$B$13,0)),""))) | M7: =IF($A7="","",IF($C7<>"manual_titration_mL","",IFERROR(INDEX('3_可滴定酸度'!$F$6:$F$13,MATCH($I7,'3_可滴定酸度'!$B$6:$B$13,0)),""))) | N7: =IF($A7="","",IF(OR(K7="",L7="",M7=""),"",K7*E7*L7/(M7*1000)*100)) | O7: =IF($A7="","",IF(N7="","",IF(COUNTIFS('1_原始數據'!$A$2:$A$1000,$A7,'1_原始數據'!$B$2:$B$1000,$B7,'1_原始數據'!$D$2:$D$1000,$D7,'1_原始數據'!$I$2:$I$1000,$I7,'1_原始數據'!$C$2:$C$1000,"pasco_pct_acid")=0,"",SUMIFS('1_原始數據'!$E$2:$E$1000,'1_原始數據'!$A$2:$A$1000,$A7,'1_原始數據'!$B$2:$B$1000,$B7,'1_原始數據'!$D$2:$D$1000,$D7,'1_原始數據'!$I$2:$I$1000,$I7,'1_原始數據'!$C$2:$C$1000,"pasco_pct_acid")))) | P7: =IF($A7="","",IF(OR(N7="",O7=""),"",O7-N7)) | Q7: =IF($A7="","",IF(P7="","",(O7+N7)/2)) | R7: =IF($A7="","",IF(P7="","",COUNT($P$2:P7))) | T7: 「N_NaOH_M」：手動滴定那一列：抓「自己這一組」標定出來的 NaOH 濃度（同組有多次標定就取平均）。
A8: 4 | B8: G4_S1 | C8: khp_mass_g | D8: 1 | E8: 0.5157 | F8: g | G8: 25 | I8: KHP | J8: =IF($A8="","",IF($C8<>"khp_titration_mL","",IF(COUNTIFS('1_原始數據'!$A$2:$A$1000,$A8,'1_原始數據'!$B$2:$B$1000,$B8,'1_原始數據'!$D$2:$D$1000,$D8,'1_原始數據'!$C$2:$C$1000,"khp_mass_g")=0,"",SUMIFS('1_原始數據'!$E$2:$E$1000,'1_原始數據'!$A$2:$A$1000,$A8,'1_原始數據'!$B$2:$B$1000,$B8,'1_原始數據'!$D$2:$D$1000,$D8,'1_原始數據'!$C$2:$C$1000,"khp_mass_g")/('2_NaOH標定'!$C$5*$E8/1000)))) | K8: =IF($A8="","",IF($C8<>"manual_titration_mL","",IF(COUNTIFS('1_原始數據'!$A$2:$A$1000,$A8,'1_原始數據'!$C$2:$C$1000,"khp_titration_mL")=0,"",AVERAGEIFS('1_原始數據'!$J$2:$J$1000,'1_原始數據'!$A$2:$A$1000,$A8,'1_原始數據'!$C$2:$C$1000,"khp_titration_mL")))) | L8: =IF($A8="","",IF($C8<>"manual_titration_mL","",IFERROR(INDEX('3_可滴定酸度'!$E$6:$E$13,MATCH($I8,'3_可滴定酸度'!$B$6:$B$13,0)),""))) | M8: =IF($A8="","",IF($C8<>"manual_titration_mL","",IFERROR(INDEX('3_可滴定酸度'!$F$6:$F$13,MATCH($I8,'3_可滴定酸度'!$B$6:$B$13,0)),""))) | N8: =IF($A8="","",IF(OR(K8="",L8="",M8=""),"",K8*E8*L8/(M8*1000)*100)) | O8: =IF($A8="","",IF(N8="","",IF(COUNTIFS('1_原始數據'!$A$2:$A$1000,$A8,'1_原始數據'!$B$2:$B$1000,$B8,'1_原始數據'!$D$2:$D$1000,$D8,'1_原始數據'!$I$2:$I$1000,$I8,'1_原始數據'!$C$2:$C$1000,"pasco_pct_acid")=0,"",SUMIFS('1_原始數據'!$E$2:$E$1000,'1_原始數據'!$A$2:$A$1000,$A8,'1_原始數據'!$B$2:$B$1000,$B8,'1_原始數據'!$D$2:$D$1000,$D8,'1_原始數據'!$I$2:$I$1000,$I8,'1_原始數據'!$C$2:$C$1000,"pasco_pct_acid")))) | P8: =IF($A8="","",IF(OR(N8="",O8=""),"",O8-N8)) | Q8: =IF($A8="","",IF(P8="","",(O8+N8)/2)) | R8: =IF($A8="","",IF(P8="","",COUNT($P$2:P8))) | T8: 「eqwt」：主要酸的當量重 (g/eq)，從「3_可滴定酸度」的參數表查。
A9: 4 | B9: G4_S1 | C9: khp_titration_mL | D9: 1 | E9: 25.09 | F9: mL | G9: 25 | I9: NaOH | J9: =IF($A9="","",IF($C9<>"khp_titration_mL","",IF(COUNTIFS('1_原始數據'!$A$2:$A$1000,$A9,'1_原始數據'!$B$2:$B$1000,$B9,'1_原始數據'!$D$2:$D$1000,$D9,'1_原始數據'!$C$2:$C$1000,"khp_mass_g")=0,"",SUMIFS('1_原始數據'!$E$2:$E$1000,'1_原始數據'!$A$2:$A$1000,$A9,'1_原始數據'!$B$2:$B$1000,$B9,'1_原始數據'!$D$2:$D$1000,$D9,'1_原始數據'!$C$2:$C$1000,"khp_mass_g")/('2_NaOH標定'!$C$5*$E9/1000)))) | K9: =IF($A9="","",IF($C9<>"manual_titration_mL","",IF(COUNTIFS('1_原始數據'!$A$2:$A$1000,$A9,'1_原始數據'!$C$2:$C$1000,"khp_titration_mL")=0,"",AVERAGEIFS('1_原始數據'!$J$2:$J$1000,'1_原始數據'!$A$2:$A$1000,$A9,'1_原始數據'!$C$2:$C$1000,"khp_titration_mL")))) | L9: =IF($A9="","",IF($C9<>"manual_titration_mL","",IFERROR(INDEX('3_可滴定酸度'!$E$6:$E$13,MATCH($I9,'3_可滴定酸度'!$B$6:$B$13,0)),""))) | M9: =IF($A9="","",IF($C9<>"manual_titration_mL","",IFERROR(INDEX('3_可滴定酸度'!$F$6:$F$13,MATCH($I9,'3_可滴定酸度'!$B$6:$B$13,0)),""))) | N9: =IF($A9="","",IF(OR(K9="",L9="",M9=""),"",K9*E9*L9/(M9*1000)*100)) | O9: =IF($A9="","",IF(N9="","",IF(COUNTIFS('1_原始數據'!$A$2:$A$1000,$A9,'1_原始數據'!$B$2:$B$1000,$B9,'1_原始數據'!$D$2:$D$1000,$D9,'1_原始數據'!$I$2:$I$1000,$I9,'1_原始數據'!$C$2:$C$1000,"pasco_pct_acid")=0,"",SUMIFS('1_原始數據'!$E$2:$E$1000,'1_原始數據'!$A$2:$A$1000,$A9,'1_原始數據'!$B$2:$B$1000,$B9,'1_原始數據'!$D$2:$D$1000,$D9,'1_原始數據'!$I$2:$I$1000,$I9,'1_原始數據'!$C$2:$C$1000,"pasco_pct_acid")))) | P9: =IF($A9="","",IF(OR(N9="",O9=""),"",O9-N9)) | Q9: =IF($A9="","",IF(P9="","",(O9+N9)/2)) | R9: =IF($A9="","",IF(P9="","",COUNT($P$2:P9))) | T9: 「W_sample」：取樣量 W（mL 或 g），同樣從參數表查。
A10: 5 | B10: G5_S1 | C10: khp_mass_g | D10: 1 | E10: 0.4777 | F10: g | G10: 25 | I10: KHP | J10: =IF($A10="","",IF($C10<>"khp_titration_mL","",IF(COUNTIFS('1_原始數據'!$A$2:$A$1000,$A10,'1_原始數據'!$B$2:$B$1000,$B10,'1_原始數據'!$D$2:$D$1000,$D10,'1_原始數據'!$C$2:$C$1000,"khp_mass_g")=0,"",SUMIFS('1_原始數據'!$E$2:$E$1000,'1_原始數據'!$A$2:$A$1000,$A10,'1_原始數據'!$B$2:$B$1000,$B10,'1_原始數據'!$D$2:$D$1000,$D10,'1_原始數據'!$C$2:$C$1000,"khp_mass_g")/('2_NaOH標定'!$C$5*$E10/1000)))) | K10: =IF($A10="","",IF($C10<>"manual_titration_mL","",IF(COUNTIFS('1_原始數據'!$A$2:$A$1000,$A10,'1_原始數據'!$C$2:$C$1000,"khp_titration_mL")=0,"",AVERAGEIFS('1_原始數據'!$J$2:$J$1000,'1_原始數據'!$A$2:$A$1000,$A10,'1_原始數據'!$C$2:$C$1000,"khp_titration_mL")))) | L10: =IF($A10="","",IF($C10<>"manual_titration_mL","",IFERROR(INDEX('3_可滴定酸度'!$E$6:$E$13,MATCH($I10,'3_可滴定酸度'!$B$6:$B$13,0)),""))) | M10: =IF($A10="","",IF($C10<>"manual_titration_mL","",IFERROR(INDEX('3_可滴定酸度'!$F$6:$F$13,MATCH($I10,'3_可滴定酸度'!$B$6:$B$13,0)),""))) | N10: =IF($A10="","",IF(OR(K10="",L10="",M10=""),"",K10*E10*L10/(M10*1000)*100)) | O10: =IF($A10="","",IF(N10="","",IF(COUNTIFS('1_原始數據'!$A$2:$A$1000,$A10,'1_原始數據'!$B$2:$B$1000,$B10,'1_原始數據'!$D$2:$D$1000,$D10,'1_原始數據'!$I$2:$I$1000,$I10,'1_原始數據'!$C$2:$C$1000,"pasco_pct_acid")=0,"",SUMIFS('1_原始數據'!$E$2:$E$1000,'1_原始數據'!$A$2:$A$1000,$A10,'1_原始數據'!$B$2:$B$1000,$B10,'1_原始數據'!$D$2:$D$1000,$D10,'1_原始數據'!$I$2:$I$1000,$I10,'1_原始數據'!$C$2:$C$1000,"pasco_pct_acid")))) | P10: =IF($A10="","",IF(OR(N10="",O10=""),"",O10-N10)) | Q10: =IF($A10="","",IF(P10="","",(O10+N10)/2)) | R10: =IF($A10="","",IF(P10="","",COUNT($P$2:P10))) | T10: 「manual_pct_acid」：手動滴定的 % 酸 = N × V × 當量重 ÷ (W × 1000) × 100。
A11: 5 | B11: G5_S1 | C11: khp_titration_mL | D11: 1 | E11: 23.21 | F11: mL | G11: 25 | I11: NaOH | J11: =IF($A11="","",IF($C11<>"khp_titration_mL","",IF(COUNTIFS('1_原始數據'!$A$2:$A$1000,$A11,'1_原始數據'!$B$2:$B$1000,$B11,'1_原始數據'!$D$2:$D$1000,$D11,'1_原始數據'!$C$2:$C$1000,"khp_mass_g")=0,"",SUMIFS('1_原始數據'!$E$2:$E$1000,'1_原始數據'!$A$2:$A$1000,$A11,'1_原始數據'!$B$2:$B$1000,$B11,'1_原始數據'!$D$2:$D$1000,$D11,'1_原始數據'!$C$2:$C$1000,"khp_mass_g")/('2_NaOH標定'!$C$5*$E11/1000)))) | K11: =IF($A11="","",IF($C11<>"manual_titration_mL","",IF(COUNTIFS('1_原始數據'!$A$2:$A$1000,$A11,'1_原始數據'!$C$2:$C$1000,"khp_titration_mL")=0,"",AVERAGEIFS('1_原始數據'!$J$2:$J$1000,'1_原始數據'!$A$2:$A$1000,$A11,'1_原始數據'!$C$2:$C$1000,"khp_titration_mL")))) | L11: =IF($A11="","",IF($C11<>"manual_titration_mL","",IFERROR(INDEX('3_可滴定酸度'!$E$6:$E$13,MATCH($I11,'3_可滴定酸度'!$B$6:$B$13,0)),""))) | M11: =IF($A11="","",IF($C11<>"manual_titration_mL","",IFERROR(INDEX('3_可滴定酸度'!$F$6:$F$13,MATCH($I11,'3_可滴定酸度'!$B$6:$B$13,0)),""))) | N11: =IF($A11="","",IF(OR(K11="",L11="",M11=""),"",K11*E11*L11/(M11*1000)*100)) | O11: =IF($A11="","",IF(N11="","",IF(COUNTIFS('1_原始數據'!$A$2:$A$1000,$A11,'1_原始數據'!$B$2:$B$1000,$B11,'1_原始數據'!$D$2:$D$1000,$D11,'1_原始數據'!$I$2:$I$1000,$I11,'1_原始數據'!$C$2:$C$1000,"pasco_pct_acid")=0,"",SUMIFS('1_原始數據'!$E$2:$E$1000,'1_原始數據'!$A$2:$A$1000,$A11,'1_原始數據'!$B$2:$B$1000,$B11,'1_原始數據'!$D$2:$D$1000,$D11,'1_原始數據'!$I$2:$I$1000,$I11,'1_原始數據'!$C$2:$C$1000,"pasco_pct_acid")))) | P11: =IF($A11="","",IF(OR(N11="",O11=""),"",O11-N11)) | Q11: =IF($A11="","",IF(P11="","",(O11+N11)/2)) | R11: =IF($A11="","",IF(P11="","",COUNT($P$2:P11))) | T11: 「pasco_pct_acid」：同一位同學、同一 rep、同一樣品的 PASCO % 酸（配對用）。找不到就留空。
A12: 1 | B12: G1_S1 | C12: manual_titration_mL | D12: 1 | E12: 14.95 | F12: mL | G12: 25 | I12: vinegar | J12: =IF($A12="","",IF($C12<>"khp_titration_mL","",IF(COUNTIFS('1_原始數據'!$A$2:$A$1000,$A12,'1_原始數據'!$B$2:$B$1000,$B12,'1_原始數據'!$D$2:$D$1000,$D12,'1_原始數據'!$C$2:$C$1000,"khp_mass_g")=0,"",SUMIFS('1_原始數據'!$E$2:$E$1000,'1_原始數據'!$A$2:$A$1000,$A12,'1_原始數據'!$B$2:$B$1000,$B12,'1_原始數據'!$D$2:$D$1000,$D12,'1_原始數據'!$C$2:$C$1000,"khp_mass_g")/('2_NaOH標定'!$C$5*$E12/1000)))) | K12: =IF($A12="","",IF($C12<>"manual_titration_mL","",IF(COUNTIFS('1_原始數據'!$A$2:$A$1000,$A12,'1_原始數據'!$C$2:$C$1000,"khp_titration_mL")=0,"",AVERAGEIFS('1_原始數據'!$J$2:$J$1000,'1_原始數據'!$A$2:$A$1000,$A12,'1_原始數據'!$C$2:$C$1000,"khp_titration_mL")))) | L12: =IF($A12="","",IF($C12<>"manual_titration_mL","",IFERROR(INDEX('3_可滴定酸度'!$E$6:$E$13,MATCH($I12,'3_可滴定酸度'!$B$6:$B$13,0)),""))) | M12: =IF($A12="","",IF($C12<>"manual_titration_mL","",IFERROR(INDEX('3_可滴定酸度'!$F$6:$F$13,MATCH($I12,'3_可滴定酸度'!$B$6:$B$13,0)),""))) | N12: =IF($A12="","",IF(OR(K12="",L12="",M12=""),"",K12*E12*L12/(M12*1000)*100)) | O12: =IF($A12="","",IF(N12="","",IF(COUNTIFS('1_原始數據'!$A$2:$A$1000,$A12,'1_原始數據'!$B$2:$B$1000,$B12,'1_原始數據'!$D$2:$D$1000,$D12,'1_原始數據'!$I$2:$I$1000,$I12,'1_原始數據'!$C$2:$C$1000,"pasco_pct_acid")=0,"",SUMIFS('1_原始數據'!$E$2:$E$1000,'1_原始數據'!$A$2:$A$1000,$A12,'1_原始數據'!$B$2:$B$1000,$B12,'1_原始數據'!$D$2:$D$1000,$D12,'1_原始數據'!$I$2:$I$1000,$I12,'1_原始數據'!$C$2:$C$1000,"pasco_pct_acid")))) | P12: =IF($A12="","",IF(OR(N12="",O12=""),"",O12-N12)) | Q12: =IF($A12="","",IF(P12="","",(O12+N12)/2)) | R12: =IF($A12="","",IF(P12="","",COUNT($P$2:P12))) | T12: 「diff_pct」：差值 = PASCO − 手動（Bland–Altman 的 y 軸）。
A13: 1 | B13: G1_S1 | C13: pasco_pct_acid | D13: 1 | E13: 4.6 | F13: % | G13: 25 | I13: vinegar | J13: =IF($A13="","",IF($C13<>"khp_titration_mL","",IF(COUNTIFS('1_原始數據'!$A$2:$A$1000,$A13,'1_原始數據'!$B$2:$B$1000,$B13,'1_原始數據'!$D$2:$D$1000,$D13,'1_原始數據'!$C$2:$C$1000,"khp_mass_g")=0,"",SUMIFS('1_原始數據'!$E$2:$E$1000,'1_原始數據'!$A$2:$A$1000,$A13,'1_原始數據'!$B$2:$B$1000,$B13,'1_原始數據'!$D$2:$D$1000,$D13,'1_原始數據'!$C$2:$C$1000,"khp_mass_g")/('2_NaOH標定'!$C$5*$E13/1000)))) | K13: =IF($A13="","",IF($C13<>"manual_titration_mL","",IF(COUNTIFS('1_原始數據'!$A$2:$A$1000,$A13,'1_原始數據'!$C$2:$C$1000,"khp_titration_mL")=0,"",AVERAGEIFS('1_原始數據'!$J$2:$J$1000,'1_原始數據'!$A$2:$A$1000,$A13,'1_原始數據'!$C$2:$C$1000,"khp_titration_mL")))) | L13: =IF($A13="","",IF($C13<>"manual_titration_mL","",IFERROR(INDEX('3_可滴定酸度'!$E$6:$E$13,MATCH($I13,'3_可滴定酸度'!$B$6:$B$13,0)),""))) | M13: =IF($A13="","",IF($C13<>"manual_titration_mL","",IFERROR(INDEX('3_可滴定酸度'!$F$6:$F$13,MATCH($I13,'3_可滴定酸度'!$B$6:$B$13,0)),""))) | N13: =IF($A13="","",IF(OR(K13="",L13="",M13=""),"",K13*E13*L13/(M13*1000)*100)) | O13: =IF($A13="","",IF(N13="","",IF(COUNTIFS('1_原始數據'!$A$2:$A$1000,$A13,'1_原始數據'!$B$2:$B$1000,$B13,'1_原始數據'!$D$2:$D$1000,$D13,'1_原始數據'!$I$2:$I$1000,$I13,'1_原始數據'!$C$2:$C$1000,"pasco_pct_acid")=0,"",SUMIFS('1_原始數據'!$E$2:$E$1000,'1_原始數據'!$A$2:$A$1000,$A13,'1_原始數據'!$B$2:$B$1000,$B13,'1_原始數據'!$D$2:$D$1000,$D13,'1_原始數據'!$I$2:$I$1000,$I13,'1_原始數據'!$C$2:$C$1000,"pasco_pct_acid")))) | P13: =IF($A13="","",IF(OR(N13="",O13=""),"",O13-N13)) | Q13: =IF($A13="","",IF(P13="","",(O13+N13)/2)) | R13: =IF($A13="","",IF(P13="","",COUNT($P$2:P13))) | T13: 「mean_pct」：兩法平均（Bland–Altman 的 x 軸）。
A14: 2 | B14: G2_S2 | C14: manual_titration_mL | D14: 2 | E14: 14.95 | F14: mL | G14: 25 | I14: vinegar | J14: =IF($A14="","",IF($C14<>"khp_titration_mL","",IF(COUNTIFS('1_原始數據'!$A$2:$A$1000,$A14,'1_原始數據'!$B$2:$B$1000,$B14,'1_原始數據'!$D$2:$D$1000,$D14,'1_原始數據'!$C$2:$C$1000,"khp_mass_g")=0,"",SUMIFS('1_原始數據'!$E$2:$E$1000,'1_原始數據'!$A$2:$A$1000,$A14,'1_原始數據'!$B$2:$B$1000,$B14,'1_原始數據'!$D$2:$D$1000,$D14,'1_原始數據'!$C$2:$C$1000,"khp_mass_g")/('2_NaOH標定'!$C$5*$E14/1000)))) | K14: =IF($A14="","",IF($C14<>"manual_titration_mL","",IF(COUNTIFS('1_原始數據'!$A$2:$A$1000,$A14,'1_原始數據'!$C$2:$C$1000,"khp_titration_mL")=0,"",AVERAGEIFS('1_原始數據'!$J$2:$J$1000,'1_原始數據'!$A$2:$A$1000,$A14,'1_原始數據'!$C$2:$C$1000,"khp_titration_mL")))) | L14: =IF($A14="","",IF($C14<>"manual_titration_mL","",IFERROR(INDEX('3_可滴定酸度'!$E$6:$E$13,MATCH($I14,'3_可滴定酸度'!$B$6:$B$13,0)),""))) | M14: =IF($A14="","",IF($C14<>"manual_titration_mL","",IFERROR(INDEX('3_可滴定酸度'!$F$6:$F$13,MATCH($I14,'3_可滴定酸度'!$B$6:$B$13,0)),""))) | N14: =IF($A14="","",IF(OR(K14="",L14="",M14=""),"",K14*E14*L14/(M14*1000)*100)) | O14: =IF($A14="","",IF(N14="","",IF(COUNTIFS('1_原始數據'!$A$2:$A$1000,$A14,'1_原始數據'!$B$2:$B$1000,$B14,'1_原始數據'!$D$2:$D$1000,$D14,'1_原始數據'!$I$2:$I$1000,$I14,'1_原始數據'!$C$2:$C$1000,"pasco_pct_acid")=0,"",SUMIFS('1_原始數據'!$E$2:$E$1000,'1_原始數據'!$A$2:$A$1000,$A14,'1_原始數據'!$B$2:$B$1000,$B14,'1_原始數據'!$D$2:$D$1000,$D14,'1_原始數據'!$I$2:$I$1000,$I14,'1_原始數據'!$C$2:$C$1000,"pasco_pct_acid")))) | P14: =IF($A14="","",IF(OR(N14="",O14=""),"",O14-N14)) | Q14: =IF($A14="","",IF(P14="","",(O14+N14)/2)) | R14: =IF($A14="","",IF(P14="","",COUNT($P$2:P14))) | T14: 「pair_no」：第幾組配對（1, 2, 3…），讓「5_手動vs自動」可以依序抓出來。
A15: 2 | B15: G2_S2 | C15: pasco_pct_acid | D15: 2 | E15: 4.589 | F15: % | G15: 25 | I15: vinegar | J15: =IF($A15="","",IF($C15<>"khp_titration_mL","",IF(COUNTIFS('1_原始數據'!$A$2:$A$1000,$A15,'1_原始數據'!$B$2:$B$1000,$B15,'1_原始數據'!$D$2:$D$1000,$D15,'1_原始數據'!$C$2:$C$1000,"khp_mass_g")=0,"",SUMIFS('1_原始數據'!$E$2:$E$1000,'1_原始數據'!$A$2:$A$1000,$A15,'1_原始數據'!$B$2:$B$1000,$B15,'1_原始數據'!$D$2:$D$1000,$D15,'1_原始數據'!$C$2:$C$1000,"khp_mass_g")/('2_NaOH標定'!$C$5*$E15/1000)))) | K15: =IF($A15="","",IF($C15<>"manual_titration_mL","",IF(COUNTIFS('1_原始數據'!$A$2:$A$1000,$A15,'1_原始數據'!$C$2:$C$1000,"khp_titration_mL")=0,"",AVERAGEIFS('1_原始數據'!$J$2:$J$1000,'1_原始數據'!$A$2:$A$1000,$A15,'1_原始數據'!$C$2:$C$1000,"khp_titration_mL")))) | L15: =IF($A15="","",IF($C15<>"manual_titration_mL","",IFERROR(INDEX('3_可滴定酸度'!$E$6:$E$13,MATCH($I15,'3_可滴定酸度'!$B$6:$B$13,0)),""))) | M15: =IF($A15="","",IF($C15<>"manual_titration_mL","",IFERROR(INDEX('3_可滴定酸度'!$F$6:$F$13,MATCH($I15,'3_可滴定酸度'!$B$6:$B$13,0)),""))) | N15: =IF($A15="","",IF(OR(K15="",L15="",M15=""),"",K15*E15*L15/(M15*1000)*100)) | O15: =IF($A15="","",IF(N15="","",IF(COUNTIFS('1_原始數據'!$A$2:$A$1000,$A15,'1_原始數據'!$B$2:$B$1000,$B15,'1_原始數據'!$D$2:$D$1000,$D15,'1_原始數據'!$I$2:$I$1000,$I15,'1_原始數據'!$C$2:$C$1000,"pasco_pct_acid")=0,"",SUMIFS('1_原始數據'!$E$2:$E$1000,'1_原始數據'!$A$2:$A$1000,$A15,'1_原始數據'!$B$2:$B$1000,$B15,'1_原始數據'!$D$2:$D$1000,$D15,'1_原始數據'!$I$2:$I$1000,$I15,'1_原始數據'!$C$2:$C$1000,"pasco_pct_acid")))) | P15: =IF($A15="","",IF(OR(N15="",O15=""),"",O15-N15)) | Q15: =IF($A15="","",IF(P15="","",(O15+N15)/2)) | R15: =IF($A15="","",IF(P15="","",COUNT($P$2:P15)))
A16: 3 | B16: G3_S3 | C16: manual_titration_mL | D16: 3 | E16: 14.9 | F16: mL | G16: 25 | I16: vinegar | J16: =IF($A16="","",IF($C16<>"khp_titration_mL","",IF(COUNTIFS('1_原始數據'!$A$2:$A$1000,$A16,'1_原始數據'!$B$2:$B$1000,$B16,'1_原始數據'!$D$2:$D$1000,$D16,'1_原始數據'!$C$2:$C$1000,"khp_mass_g")=0,"",SUMIFS('1_原始數據'!$E$2:$E$1000,'1_原始數據'!$A$2:$A$1000,$A16,'1_原始數據'!$B$2:$B$1000,$B16,'1_原始數據'!$D$2:$D$1000,$D16,'1_原始數據'!$C$2:$C$1000,"khp_mass_g")/('2_NaOH標定'!$C$5*$E16/1000)))) | K16: =IF($A16="","",IF($C16<>"manual_titration_mL","",IF(COUNTIFS('1_原始數據'!$A$2:$A$1000,$A16,'1_原始數據'!$C$2:$C$1000,"khp_titration_mL")=0,"",AVERAGEIFS('1_原始數據'!$J$2:$J$1000,'1_原始數據'!$A$2:$A$1000,$A16,'1_原始數據'!$C$2:$C$1000,"khp_titration_mL")))) | L16: =IF($A16="","",IF($C16<>"manual_titration_mL","",IFERROR(INDEX('3_可滴定酸度'!$E$6:$E$13,MATCH($I16,'3_可滴定酸度'!$B$6:$B$13,0)),""))) | M16: =IF($A16="","",IF($C16<>"manual_titration_mL","",IFERROR(INDEX('3_可滴定酸度'!$F$6:$F$13,MATCH($I16,'3_可滴定酸度'!$B$6:$B$13,0)),""))) | N16: =IF($A16="","",IF(OR(K16="",L16="",M16=""),"",K16*E16*L16/(M16*1000)*100)) | O16: =IF($A16="","",IF(N16="","",IF(COUNTIFS('1_原始數據'!$A$2:$A$1000,$A16,'1_原始數據'!$B$2:$B$1000,$B16,'1_原始數據'!$D$2:$D$1000,$D16,'1_原始數據'!$I$2:$I$1000,$I16,'1_原始數據'!$C$2:$C$1000,"pasco_pct_acid")=0,"",SUMIFS('1_原始數據'!$E$2:$E$1000,'1_原始數據'!$A$2:$A$1000,$A16,'1_原始數據'!$B$2:$B$1000,$B16,'1_原始數據'!$D$2:$D$1000,$D16,'1_原始數據'!$I$2:$I$1000,$I16,'1_原始數據'!$C$2:$C$1000,"pasco_pct_acid")))) | P16: =IF($A16="","",IF(OR(N16="",O16=""),"",O16-N16)) | Q16: =IF($A16="","",IF(P16="","",(O16+N16)/2)) | R16: =IF($A16="","",IF(P16="","",COUNT($P$2:P16)))
A17: 3 | B17: G3_S3 | C17: pasco_pct_acid | D17: 3 | E17: 4.503 | F17: % | G17: 25 | I17: vinegar | J17: =IF($A17="","",IF($C17<>"khp_titration_mL","",IF(COUNTIFS('1_原始數據'!$A$2:$A$1000,$A17,'1_原始數據'!$B$2:$B$1000,$B17,'1_原始數據'!$D$2:$D$1000,$D17,'1_原始數據'!$C$2:$C$1000,"khp_mass_g")=0,"",SUMIFS('1_原始數據'!$E$2:$E$1000,'1_原始數據'!$A$2:$A$1000,$A17,'1_原始數據'!$B$2:$B$1000,$B17,'1_原始數據'!$D$2:$D$1000,$D17,'1_原始數據'!$C$2:$C$1000,"khp_mass_g")/('2_NaOH標定'!$C$5*$E17/1000)))) | K17: =IF($A17="","",IF($C17<>"manual_titration_mL","",IF(COUNTIFS('1_原始數據'!$A$2:$A$1000,$A17,'1_原始數據'!$C$2:$C$1000,"khp_titration_mL")=0,"",AVERAGEIFS('1_原始數據'!$J$2:$J$1000,'1_原始數據'!$A$2:$A$1000,$A17,'1_原始數據'!$C$2:$C$1000,"khp_titration_mL")))) | L17: =IF($A17="","",IF($C17<>"manual_titration_mL","",IFERROR(INDEX('3_可滴定酸度'!$E$6:$E$13,MATCH($I17,'3_可滴定酸度'!$B$6:$B$13,0)),""))) | M17: =IF($A17="","",IF($C17<>"manual_titration_mL","",IFERROR(INDEX('3_可滴定酸度'!$F$6:$F$13,MATCH($I17,'3_可滴定酸度'!$B$6:$B$13,0)),""))) | N17: =IF($A17="","",IF(OR(K17="",L17="",M17=""),"",K17*E17*L17/(M17*1000)*100)) | O17: =IF($A17="","",IF(N17="","",IF(COUNTIFS('1_原始數據'!$A$2:$A$1000,$A17,'1_原始數據'!$B$2:$B$1000,$B17,'1_原始數據'!$D$2:$D$1000,$D17,'1_原始數據'!$I$2:$I$1000,$I17,'1_原始數據'!$C$2:$C$1000,"pasco_pct_acid")=0,"",SUMIFS('1_原始數據'!$E$2:$E$1000,'1_原始數據'!$A$2:$A$1000,$A17,'1_原始數據'!$B$2:$B$1000,$B17,'1_原始數據'!$D$2:$D$1000,$D17,'1_原始數據'!$I$2:$I$1000,$I17,'1_原始數據'!$C$2:$C$1000,"pasco_pct_acid")))) | P17: =IF($A17="","",IF(OR(N17="",O17=""),"",O17-N17)) | Q17: =IF($A17="","",IF(P17="","",(O17+N17)/2)) | R17: =IF($A17="","",IF(P17="","",COUNT($P$2:P17)))
A18: 4 | B18: G4_S1 | C18: manual_titration_mL | D18: 1 | E18: 7.85 | F18: mL | G18: 25 | I18: orange_juice | J18: =IF($A18="","",IF($C18<>"khp_titration_mL","",IF(COUNTIFS('1_原始數據'!$A$2:$A$1000,$A18,'1_原始數據'!$B$2:$B$1000,$B18,'1_原始數據'!$D$2:$D$1000,$D18,'1_原始數據'!$C$2:$C$1000,"khp_mass_g")=0,"",SUMIFS('1_原始數據'!$E$2:$E$1000,'1_原始數據'!$A$2:$A$1000,$A18,'1_原始數據'!$B$2:$B$1000,$B18,'1_原始數據'!$D$2:$D$1000,$D18,'1_原始數據'!$C$2:$C$1000,"khp_mass_g")/('2_NaOH標定'!$C$5*$E18/1000)))) | K18: =IF($A18="","",IF($C18<>"manual_titration_mL","",IF(COUNTIFS('1_原始數據'!$A$2:$A$1000,$A18,'1_原始數據'!$C$2:$C$1000,"khp_titration_mL")=0,"",AVERAGEIFS('1_原始數據'!$J$2:$J$1000,'1_原始數據'!$A$2:$A$1000,$A18,'1_原始數據'!$C$2:$C$1000,"khp_titration_mL")))) | L18: =IF($A18="","",IF($C18<>"manual_titration_mL","",IFERROR(INDEX('3_可滴定酸度'!$E$6:$E$13,MATCH($I18,'3_可滴定酸度'!$B$6:$B$13,0)),""))) | M18: =IF($A18="","",IF($C18<>"manual_titration_mL","",IFERROR(INDEX('3_可滴定酸度'!$F$6:$F$13,MATCH($I18,'3_可滴定酸度'!$B$6:$B$13,0)),""))) | N18: =IF($A18="","",IF(OR(K18="",L18="",M18=""),"",K18*E18*L18/(M18*1000)*100)) | O18: =IF($A18="","",IF(N18="","",IF(COUNTIFS('1_原始數據'!$A$2:$A$1000,$A18,'1_原始數據'!$B$2:$B$1000,$B18,'1_原始數據'!$D$2:$D$1000,$D18,'1_原始數據'!$I$2:$I$1000,$I18,'1_原始數據'!$C$2:$C$1000,"pasco_pct_acid")=0,"",SUMIFS('1_原始數據'!$E$2:$E$1000,'1_原始數據'!$A$2:$A$1000,$A18,'1_原始數據'!$B$2:$B$1000,$B18,'1_原始數據'!$D$2:$D$1000,$D18,'1_原始數據'!$I$2:$I$1000,$I18,'1_原始數據'!$C$2:$C$1000,"pasco_pct_acid")))) | P18: =IF($A18="","",IF(OR(N18="",O18=""),"",O18-N18)) | Q18: =IF($A18="","",IF(P18="","",(O18+N18)/2)) | R18: =IF($A18="","",IF(P18="","",COUNT($P$2:P18)))
A19: 4 | B19: G4_S1 | C19: pasco_pct_acid | D19: 1 | E19: 0.995 | F19: % | G19: 25 | I19: orange_juice | J19: =IF($A19="","",IF($C19<>"khp_titration_mL","",IF(COUNTIFS('1_原始數據'!$A$2:$A$1000,$A19,'1_原始數據'!$B$2:$B$1000,$B19,'1_原始數據'!$D$2:$D$1000,$D19,'1_原始數據'!$C$2:$C$1000,"khp_mass_g")=0,"",SUMIFS('1_原始數據'!$E$2:$E$1000,'1_原始數據'!$A$2:$A$1000,$A19,'1_原始數據'!$B$2:$B$1000,$B19,'1_原始數據'!$D$2:$D$1000,$D19,'1_原始數據'!$C$2:$C$1000,"khp_mass_g")/('2_NaOH標定'!$C$5*$E19/1000)))) | K19: =IF($A19="","",IF($C19<>"manual_titration_mL","",IF(COUNTIFS('1_原始數據'!$A$2:$A$1000,$A19,'1_原始數據'!$C$2:$C$1000,"khp_titration_mL")=0,"",AVERAGEIFS('1_原始數據'!$J$2:$J$1000,'1_原始數據'!$A$2:$A$1000,$A19,'1_原始數據'!$C$2:$C$1000,"khp_titration_mL")))) | L19: =IF($A19="","",IF($C19<>"manual_titration_mL","",IFERROR(INDEX('3_可滴定酸度'!$E$6:$E$13,MATCH($I19,'3_可滴定酸度'!$B$6:$B$13,0)),""))) | M19: =IF($A19="","",IF($C19<>"manual_titration_mL","",IFERROR(INDEX('3_可滴定酸度'!$F$6:$F$13,MATCH($I19,'3_可滴定酸度'!$B$6:$B$13,0)),""))) | N19: =IF($A19="","",IF(OR(K19="",L19="",M19=""),"",K19*E19*L19/(M19*1000)*100)) | O19: =IF($A19="","",IF(N19="","",IF(COUNTIFS('1_原始數據'!$A$2:$A$1000,$A19,'1_原始數據'!$B$2:$B$1000,$B19,'1_原始數據'!$D$2:$D$1000,$D19,'1_原始數據'!$I$2:$I$1000,$I19,'1_原始數據'!$C$2:$C$1000,"pasco_pct_acid")=0,"",SUMIFS('1_原始數據'!$E$2:$E$1000,'1_原始數據'!$A$2:$A$1000,$A19,'1_原始數據'!$B$2:$B$1000,$B19,'1_原始數據'!$D$2:$D$1000,$D19,'1_原始數據'!$I$2:$I$1000,$I19,'1_原始數據'!$C$2:$C$1000,"pasco_pct_acid")))) | P19: =IF($A19="","",IF(OR(N19="",O19=""),"",O19-N19)) | Q19: =IF($A19="","",IF(P19="","",(O19+N19)/2)) | R19: =IF($A19="","",IF(P19="","",COUNT($P$2:P19)))
A20: 5 | B20: G5_S2 | C20: manual_titration_mL | D20: 2 | E20: 8 | F20: mL | G20: 25 | I20: orange_juice | J20: =IF($A20="","",IF($C20<>"khp_titration_mL","",IF(COUNTIFS('1_原始數據'!$A$2:$A$1000,$A20,'1_原始數據'!$B$2:$B$1000,$B20,'1_原始數據'!$D$2:$D$1000,$D20,'1_原始數據'!$C$2:$C$1000,"khp_mass_g")=0,"",SUMIFS('1_原始數據'!$E$2:$E$1000,'1_原始數據'!$A$2:$A$1000,$A20,'1_原始數據'!$B$2:$B$1000,$B20,'1_原始數據'!$D$2:$D$1000,$D20,'1_原始數據'!$C$2:$C$1000,"khp_mass_g")/('2_NaOH標定'!$C$5*$E20/1000)))) | K20: =IF($A20="","",IF($C20<>"manual_titration_mL","",IF(COUNTIFS('1_原始數據'!$A$2:$A$1000,$A20,'1_原始數據'!$C$2:$C$1000,"khp_titration_mL")=0,"",AVERAGEIFS('1_原始數據'!$J$2:$J$1000,'1_原始數據'!$A$2:$A$1000,$A20,'1_原始數據'!$C$2:$C$1000,"khp_titration_mL")))) | L20: =IF($A20="","",IF($C20<>"manual_titration_mL","",IFERROR(INDEX('3_可滴定酸度'!$E$6:$E$13,MATCH($I20,'3_可滴定酸度'!$B$6:$B$13,0)),""))) | M20: =IF($A20="","",IF($C20<>"manual_titration_mL","",IFERROR(INDEX('3_可滴定酸度'!$F$6:$F$13,MATCH($I20,'3_可滴定酸度'!$B$6:$B$13,0)),""))) | N20: =IF($A20="","",IF(OR(K20="",L20="",M20=""),"",K20*E20*L20/(M20*1000)*100)) | O20: =IF($A20="","",IF(N20="","",IF(COUNTIFS('1_原始數據'!$A$2:$A$1000,$A20,'1_原始數據'!$B$2:$B$1000,$B20,'1_原始數據'!$D$2:$D$1000,$D20,'1_原始數據'!$I$2:$I$1000,$I20,'1_原始數據'!$C$2:$C$1000,"pasco_pct_acid")=0,"",SUMIFS('1_原始數據'!$E$2:$E$1000,'1_原始數據'!$A$2:$A$1000,$A20,'1_原始數據'!$B$2:$B$1000,$B20,'1_原始數據'!$D$2:$D$1000,$D20,'1_原始數據'!$I$2:$I$1000,$I20,'1_原始數據'!$C$2:$C$1000,"pasco_pct_acid")))) | P20: =IF($A20="","",IF(OR(N20="",O20=""),"",O20-N20)) | Q20: =IF($A20="","",IF(P20="","",(O20+N20)/2)) | R20: =IF($A20="","",IF(P20="","",COUNT($P$2:P20)))
A21: 5 | B21: G5_S2 | C21: pasco_pct_acid | D21: 2 | E21: 1.058 | F21: % | G21: 25 | I21: orange_juice | J21: =IF($A21="","",IF($C21<>"khp_titration_mL","",IF(COUNTIFS('1_原始數據'!$A$2:$A$1000,$A21,'1_原始數據'!$B$2:$B$1000,$B21,'1_原始數據'!$D$2:$D$1000,$D21,'1_原始數據'!$C$2:$C$1000,"khp_mass_g")=0,"",SUMIFS('1_原始數據'!$E$2:$E$1000,'1_原始數據'!$A$2:$A$1000,$A21,'1_原始數據'!$B$2:$B$1000,$B21,'1_原始數據'!$D$2:$D$1000,$D21,'1_原始數據'!$C$2:$C$1000,"khp_mass_g")/('2_NaOH標定'!$C$5*$E21/1000)))) | K21: =IF($A21="","",IF($C21<>"manual_titration_mL","",IF(COUNTIFS('1_原始數據'!$A$2:$A$1000,$A21,'1_原始數據'!$C$2:$C$1000,"khp_titration_mL")=0,"",AVERAGEIFS('1_原始數據'!$J$2:$J$1000,'1_原始數據'!$A$2:$A$1000,$A21,'1_原始數據'!$C$2:$C$1000,"khp_titration_mL")))) | L21: =IF($A21="","",IF($C21<>"manual_titration_mL","",IFERROR(INDEX('3_可滴定酸度'!$E$6:$E$13,MATCH($I21,'3_可滴定酸度'!$B$6:$B$13,0)),""))) | M21: =IF($A21="","",IF($C21<>"manual_titration_mL","",IFERROR(INDEX('3_可滴定酸度'!$F$6:$F$13,MATCH($I21,'3_可滴定酸度'!$B$6:$B$13,0)),""))) | N21: =IF($A21="","",IF(OR(K21="",L21="",M21=""),"",K21*E21*L21/(M21*1000)*100)) | O21: =IF($A21="","",IF(N21="","",IF(COUNTIFS('1_原始數據'!$A$2:$A$1000,$A21,'1_原始數據'!$B$2:$B$1000,$B21,'1_原始數據'!$D$2:$D$1000,$D21,'1_原始數據'!$I$2:$I$1000,$I21,'1_原始數據'!$C$2:$C$1000,"pasco_pct_acid")=0,"",SUMIFS('1_原始數據'!$E$2:$E$1000,'1_原始數據'!$A$2:$A$1000,$A21,'1_原始數據'!$B$2:$B$1000,$B21,'1_原始數據'!$D$2:$D$1000,$D21,'1_原始數據'!$I$2:$I$1000,$I21,'1_原始數據'!$C$2:$C$1000,"pasco_pct_acid")))) | P21: =IF($A21="","",IF(OR(N21="",O21=""),"",O21-N21)) | Q21: =IF($A21="","",IF(P21="","",(O21+N21)/2)) | R21: =IF($A21="","",IF(P21="","",COUNT($P$2:P21)))
A22: 1 | B22: G1_S3 | C22: manual_titration_mL | D22: 3 | E22: 7.7 | F22: mL | G22: 25 | I22: orange_juice | J22: =IF($A22="","",IF($C22<>"khp_titration_mL","",IF(COUNTIFS('1_原始數據'!$A$2:$A$1000,$A22,'1_原始數據'!$B$2:$B$1000,$B22,'1_原始數據'!$D$2:$D$1000,$D22,'1_原始數據'!$C$2:$C$1000,"khp_mass_g")=0,"",SUMIFS('1_原始數據'!$E$2:$E$1000,'1_原始數據'!$A$2:$A$1000,$A22,'1_原始數據'!$B$2:$B$1000,$B22,'1_原始數據'!$D$2:$D$1000,$D22,'1_原始數據'!$C$2:$C$1000,"khp_mass_g")/('2_NaOH標定'!$C$5*$E22/1000)))) | K22: =IF($A22="","",IF($C22<>"manual_titration_mL","",IF(COUNTIFS('1_原始數據'!$A$2:$A$1000,$A22,'1_原始數據'!$C$2:$C$1000,"khp_titration_mL")=0,"",AVERAGEIFS('1_原始數據'!$J$2:$J$1000,'1_原始數據'!$A$2:$A$1000,$A22,'1_原始數據'!$C$2:$C$1000,"khp_titration_mL")))) | L22: =IF($A22="","",IF($C22<>"manual_titration_mL","",IFERROR(INDEX('3_可滴定酸度'!$E$6:$E$13,MATCH($I22,'3_可滴定酸度'!$B$6:$B$13,0)),""))) | M22: =IF($A22="","",IF($C22<>"manual_titration_mL","",IFERROR(INDEX('3_可滴定酸度'!$F$6:$F$13,MATCH($I22,'3_可滴定酸度'!$B$6:$B$13,0)),""))) | N22: =IF($A22="","",IF(OR(K22="",L22="",M22=""),"",K22*E22*L22/(M22*1000)*100)) | O22: =IF($A22="","",IF(N22="","",IF(COUNTIFS('1_原始數據'!$A$2:$A$1000,$A22,'1_原始數據'!$B$2:$B$1000,$B22,'1_原始數據'!$D$2:$D$1000,$D22,'1_原始數據'!$I$2:$I$1000,$I22,'1_原始數據'!$C$2:$C$1000,"pasco_pct_acid")=0,"",SUMIFS('1_原始數據'!$E$2:$E$1000,'1_原始數據'!$A$2:$A$1000,$A22,'1_原始數據'!$B$2:$B$1000,$B22,'1_原始數據'!$D$2:$D$1000,$D22,'1_原始數據'!$I$2:$I$1000,$I22,'1_原始數據'!$C$2:$C$1000,"pasco_pct_acid")))) | P22: =IF($A22="","",IF(OR(N22="",O22=""),"",O22-N22)) | Q22: =IF($A22="","",IF(P22="","",(O22+N22)/2)) | R22: =IF($A22="","",IF(P22="","",COUNT($P$2:P22)))
A23: 1 | B23: G1_S3 | C23: pasco_pct_acid | D23: 3 | E23: 0.989 | F23: % | G23: 25 | I23: orange_juice | J23: =IF($A23="","",IF($C23<>"khp_titration_mL","",IF(COUNTIFS('1_原始數據'!$A$2:$A$1000,$A23,'1_原始數據'!$B$2:$B$1000,$B23,'1_原始數據'!$D$2:$D$1000,$D23,'1_原始數據'!$C$2:$C$1000,"khp_mass_g")=0,"",SUMIFS('1_原始數據'!$E$2:$E$1000,'1_原始數據'!$A$2:$A$1000,$A23,'1_原始數據'!$B$2:$B$1000,$B23,'1_原始數據'!$D$2:$D$1000,$D23,'1_原始數據'!$C$2:$C$1000,"khp_mass_g")/('2_NaOH標定'!$C$5*$E23/1000)))) | K23: =IF($A23="","",IF($C23<>"manual_titration_mL","",IF(COUNTIFS('1_原始數據'!$A$2:$A$1000,$A23,'1_原始數據'!$C$2:$C$1000,"khp_titration_mL")=0,"",AVERAGEIFS('1_原始數據'!$J$2:$J$1000,'1_原始數據'!$A$2:$A$1000,$A23,'1_原始數據'!$C$2:$C$1000,"khp_titration_mL")))) | L23: =IF($A23="","",IF($C23<>"manual_titration_mL","",IFERROR(INDEX('3_可滴定酸度'!$E$6:$E$13,MATCH($I23,'3_可滴定酸度'!$B$6:$B$13,0)),""))) | M23: =IF($A23="","",IF($C23<>"manual_titration_mL","",IFERROR(INDEX('3_可滴定酸度'!$F$6:$F$13,MATCH($I23,'3_可滴定酸度'!$B$6:$B$13,0)),""))) | N23: =IF($A23="","",IF(OR(K23="",L23="",M23=""),"",K23*E23*L23/(M23*1000)*100)) | O23: =IF($A23="","",IF(N23="","",IF(COUNTIFS('1_原始數據'!$A$2:$A$1000,$A23,'1_原始數據'!$B$2:$B$1000,$B23,'1_原始數據'!$D$2:$D$1000,$D23,'1_原始數據'!$I$2:$I$1000,$I23,'1_原始數據'!$C$2:$C$1000,"pasco_pct_acid")=0,"",SUMIFS('1_原始數據'!$E$2:$E$1000,'1_原始數據'!$A$2:$A$1000,$A23,'1_原始數據'!$B$2:$B$1000,$B23,'1_原始數據'!$D$2:$D$1000,$D23,'1_原始數據'!$I$2:$I$1000,$I23,'1_原始數據'!$C$2:$C$1000,"pasco_pct_acid")))) | P23: =IF($A23="","",IF(OR(N23="",O23=""),"",O23-N23)) | Q23: =IF($A23="","",IF(P23="","",(O23+N23)/2)) | R23: =IF($A23="","",IF(P23="","",COUNT($P$2:P23)))
A24: 2 | B24: G2_S1 | C24: manual_titration_mL | D24: 1 | E24: 5.2 | F24: mL | G24: 25 | I24: yogurt | J24: =IF($A24="","",IF($C24<>"khp_titration_mL","",IF(COUNTIFS('1_原始數據'!$A$2:$A$1000,$A24,'1_原始數據'!$B$2:$B$1000,$B24,'1_原始數據'!$D$2:$D$1000,$D24,'1_原始數據'!$C$2:$C$1000,"khp_mass_g")=0,"",SUMIFS('1_原始數據'!$E$2:$E$1000,'1_原始數據'!$A$2:$A$1000,$A24,'1_原始數據'!$B$2:$B$1000,$B24,'1_原始數據'!$D$2:$D$1000,$D24,'1_原始數據'!$C$2:$C$1000,"khp_mass_g")/('2_NaOH標定'!$C$5*$E24/1000)))) | K24: =IF($A24="","",IF($C24<>"manual_titration_mL","",IF(COUNTIFS('1_原始數據'!$A$2:$A$1000,$A24,'1_原始數據'!$C$2:$C$1000,"khp_titration_mL")=0,"",AVERAGEIFS('1_原始數據'!$J$2:$J$1000,'1_原始數據'!$A$2:$A$1000,$A24,'1_原始數據'!$C$2:$C$1000,"khp_titration_mL")))) | L24: =IF($A24="","",IF($C24<>"manual_titration_mL","",IFERROR(INDEX('3_可滴定酸度'!$E$6:$E$13,MATCH($I24,'3_可滴定酸度'!$B$6:$B$13,0)),""))) | M24: =IF($A24="","",IF($C24<>"manual_titration_mL","",IFERROR(INDEX('3_可滴定酸度'!$F$6:$F$13,MATCH($I24,'3_可滴定酸度'!$B$6:$B$13,0)),""))) | N24: =IF($A24="","",IF(OR(K24="",L24="",M24=""),"",K24*E24*L24/(M24*1000)*100)) | O24: =IF($A24="","",IF(N24="","",IF(COUNTIFS('1_原始數據'!$A$2:$A$1000,$A24,'1_原始數據'!$B$2:$B$1000,$B24,'1_原始數據'!$D$2:$D$1000,$D24,'1_原始數據'!$I$2:$I$1000,$I24,'1_原始數據'!$C$2:$C$1000,"pasco_pct_acid")=0,"",SUMIFS('1_原始數據'!$E$2:$E$1000,'1_原始數據'!$A$2:$A$1000,$A24,'1_原始數據'!$B$2:$B$1000,$B24,'1_原始數據'!$D$2:$D$1000,$D24,'1_原始數據'!$I$2:$I$1000,$I24,'1_原始數據'!$C$2:$C$1000,"pasco_pct_acid")))) | P24: =IF($A24="","",IF(OR(N24="",O24=""),"",O24-N24)) | Q24: =IF($A24="","",IF(P24="","",(O24+N24)/2)) | R24: =IF($A24="","",IF(P24="","",COUNT($P$2:P24)))
A25: 2 | B25: G2_S1 | C25: pasco_pct_acid | D25: 1 | E25: 0.965 | F25: % | G25: 25 | I25: yogurt | J25: =IF($A25="","",IF($C25<>"khp_titration_mL","",IF(COUNTIFS('1_原始數據'!$A$2:$A$1000,$A25,'1_原始數據'!$B$2:$B$1000,$B25,'1_原始數據'!$D$2:$D$1000,$D25,'1_原始數據'!$C$2:$C$1000,"khp_mass_g")=0,"",SUMIFS('1_原始數據'!$E$2:$E$1000,'1_原始數據'!$A$2:$A$1000,$A25,'1_原始數據'!$B$2:$B$1000,$B25,'1_原始數據'!$D$2:$D$1000,$D25,'1_原始數據'!$C$2:$C$1000,"khp_mass_g")/('2_NaOH標定'!$C$5*$E25/1000)))) | K25: =IF($A25="","",IF($C25<>"manual_titration_mL","",IF(COUNTIFS('1_原始數據'!$A$2:$A$1000,$A25,'1_原始數據'!$C$2:$C$1000,"khp_titration_mL")=0,"",AVERAGEIFS('1_原始數據'!$J$2:$J$1000,'1_原始數據'!$A$2:$A$1000,$A25,'1_原始數據'!$C$2:$C$1000,"khp_titration_mL")))) | L25: =IF($A25="","",IF($C25<>"manual_titration_mL","",IFERROR(INDEX('3_可滴定酸度'!$E$6:$E$13,MATCH($I25,'3_可滴定酸度'!$B$6:$B$13,0)),""))) | M25: =IF($A25="","",IF($C25<>"manual_titration_mL","",IFERROR(INDEX('3_可滴定酸度'!$F$6:$F$13,MATCH($I25,'3_可滴定酸度'!$B$6:$B$13,0)),""))) | N25: =IF($A25="","",IF(OR(K25="",L25="",M25=""),"",K25*E25*L25/(M25*1000)*100)) | O25: =IF($A25="","",IF(N25="","",IF(COUNTIFS('1_原始數據'!$A$2:$A$1000,$A25,'1_原始數據'!$B$2:$B$1000,$B25,'1_原始數據'!$D$2:$D$1000,$D25,'1_原始數據'!$I$2:$I$1000,$I25,'1_原始數據'!$C$2:$C$1000,"pasco_pct_acid")=0,"",SUMIFS('1_原始數據'!$E$2:$E$1000,'1_原始數據'!$A$2:$A$1000,$A25,'1_原始數據'!$B$2:$B$1000,$B25,'1_原始數據'!$D$2:$D$1000,$D25,'1_原始數據'!$I$2:$I$1000,$I25,'1_原始數據'!$C$2:$C$1000,"pasco_pct_acid")))) | P25: =IF($A25="","",IF(OR(N25="",O25=""),"",O25-N25)) | Q25: =IF($A25="","",IF(P25="","",(O25+N25)/2)) | R25: =IF($A25="","",IF(P25="","",COUNT($P$2:P25)))
A26: 3 | B26: G3_S2 | C26: manual_titration_mL | D26: 2 | E26: 4.85 | F26: mL | G26: 25 | I26: yogurt | J26: =IF($A26="","",IF($C26<>"khp_titration_mL","",IF(COUNTIFS('1_原始數據'!$A$2:$A$1000,$A26,'1_原始數據'!$B$2:$B$1000,$B26,'1_原始數據'!$D$2:$D$1000,$D26,'1_原始數據'!$C$2:$C$1000,"khp_mass_g")=0,"",SUMIFS('1_原始數據'!$E$2:$E$1000,'1_原始數據'!$A$2:$A$1000,$A26,'1_原始數據'!$B$2:$B$1000,$B26,'1_原始數據'!$D$2:$D$1000,$D26,'1_原始數據'!$C$2:$C$1000,"khp_mass_g")/('2_NaOH標定'!$C$5*$E26/1000)))) | K26: =IF($A26="","",IF($C26<>"manual_titration_mL","",IF(COUNTIFS('1_原始數據'!$A$2:$A$1000,$A26,'1_原始數據'!$C$2:$C$1000,"khp_titration_mL")=0,"",AVERAGEIFS('1_原始數據'!$J$2:$J$1000,'1_原始數據'!$A$2:$A$1000,$A26,'1_原始數據'!$C$2:$C$1000,"khp_titration_mL")))) | L26: =IF($A26="","",IF($C26<>"manual_titration_mL","",IFERROR(INDEX('3_可滴定酸度'!$E$6:$E$13,MATCH($I26,'3_可滴定酸度'!$B$6:$B$13,0)),""))) | M26: =IF($A26="","",IF($C26<>"manual_titration_mL","",IFERROR(INDEX('3_可滴定酸度'!$F$6:$F$13,MATCH($I26,'3_可滴定酸度'!$B$6:$B$13,0)),""))) | N26: =IF($A26="","",IF(OR(K26="",L26="",M26=""),"",K26*E26*L26/(M26*1000)*100)) | O26: =IF($A26="","",IF(N26="","",IF(COUNTIFS('1_原始數據'!$A$2:$A$1000,$A26,'1_原始數據'!$B$2:$B$1000,$B26,'1_原始數據'!$D$2:$D$1000,$D26,'1_原始數據'!$I$2:$I$1000,$I26,'1_原始數據'!$C$2:$C$1000,"pasco_pct_acid")=0,"",SUMIFS('1_原始數據'!$E$2:$E$1000,'1_原始數據'!$A$2:$A$1000,$A26,'1_原始數據'!$B$2:$B$1000,$B26,'1_原始數據'!$D$2:$D$1000,$D26,'1_原始數據'!$I$2:$I$1000,$I26,'1_原始數據'!$C$2:$C$1000,"pasco_pct_acid")))) | P26: =IF($A26="","",IF(OR(N26="",O26=""),"",O26-N26)) | Q26: =IF($A26="","",IF(P26="","",(O26+N26)/2)) | R26: =IF($A26="","",IF(P26="","",COUNT($P$2:P26)))
... A35: 2 | B35: G2_S3 | C35: pasco_pct_acid | D35: 3 | E35: 0.454 | F35: % | G35: 25 | I35: red_wine | J35: =IF($A35="","",IF($C35<>"khp_titration_mL","",IF(COUNTIFS('1_原始數據'!$A$2:$A$1000,$A35,'1_原始數據'!$B$2:$B$1000,$B35,'1_原始數據'!$D$2:$D$1000,$D35,'1_原始數據'!$C$2:$C$1000,"khp_mass_g")=0,"",SUMIFS('1_原始數據'!$E$2:$E$1000,'1_原始數據'!$A$2:$A$1000,$A35,'1_原始數據'!$B$2:$B$1000,$B35,'1_原始數據'!$D$2:$D$1000,$D35,'1_原始數據'!$C$2:$C$1000,"khp_mass_g")/('2_NaOH標定'!$C$5*$E35/1000)))) | K35: =IF($A35="","",IF($C35<>"manual_titration_mL","",IF(COUNTIFS('1_原始數據'!$A$2:$A$1000,$A35,'1_原始數據'!$C$2:$C$1000,"khp_titration_mL")=0,"",AVERAGEIFS('1_原始數據'!$J$2:$J$1000,'1_原始數據'!$A$2:$A$1000,$A35,'1_原始數據'!$C$2:$C$1000,"khp_titration_mL")))) | L35: =IF($A35="","",IF($C35<>"manual_titration_mL","",IFERROR(INDEX('3_可滴定酸度'!$E$6:$E$13,MATCH($I35,'3_可滴定酸度'!$B$6:$B$13,0)),""))) | M35: =IF($A35="","",IF($C35<>"manual_titration_mL","",IFERROR(INDEX('3_可滴定酸度'!$F$6:$F$13,MATCH($I35,'3_可滴定酸度'!$B$6:$B$13,0)),""))) | N35: =IF($A35="","",IF(OR(K35="",L35="",M35=""),"",K35*E35*L35/(M35*1000)*100)) | O35: =IF($A35="","",IF(N35="","",IF(COUNTIFS('1_原始數據'!$A$2:$A$1000,$A35,'1_原始數據'!$B$2:$B$1000,$B35,'1_原始數據'!$D$2:$D$1000,$D35,'1_原始數據'!$I$2:$I$1000,$I35,'1_原始數據'!$C$2:$C$1000,"pasco_pct_acid")=0,"",SUMIFS('1_原始數據'!$E$2:$E$1000,'1_原始數據'!$A$2:$A$1000,$A35,'1_原始數據'!$B$2:$B$1000,$B35,'1_原始數據'!$D$2:$D$1000,$D35,'1_原始數據'!$I$2:$I$1000,$I35,'1_原始數據'!$C$2:$C$1000,"pasco_pct_acid")))) | P35: =IF($A35="","",IF(OR(N35="",O35=""),"",O35-N35)) | Q35: =IF($A35="","",IF(P35="","",(O35+N35)/2)) | R35: =IF($A35="","",IF(P35="","",COUNT($P$2:P35)))
J36: =IF($A36="","",IF($C36<>"khp_titration_mL","",IF(COUNTIFS('1_原始數據'!$A$2:$A$1000,$A36,'1_原始數據'!$B$2:$B$1000,$B36,'1_原始數據'!$D$2:$D$1000,$D36,'1_原始數據'!$C$2:$C$1000,"khp_mass_g")=0,"",SUMIFS('1_原始數據'!$E$2:$E$1000,'1_原始數據'!$A$2:$A$1000,$A36,'1_原始數據'!$B$2:$B$1000,$B36,'1_原始數據'!$D$2:$D$1000,$D36,'1_原始數據'!$C$2:$C$1000,"khp_mass_g")/('2_NaOH標定'!$C$5*$E36/1000)))) | K36: =IF($A36="","",IF($C36<>"manual_titration_mL","",IF(COUNTIFS('1_原始數據'!$A$2:$A$1000,$A36,'1_原始數據'!$C$2:$C$1000,"khp_titration_mL")=0,"",AVERAGEIFS('1_原始數據'!$J$2:$J$1000,'1_原始數據'!$A$2:$A$1000,$A36,'1_原始數據'!$C$2:$C$1000,"khp_titration_mL")))) | L36: =IF($A36="","",IF($C36<>"manual_titration_mL","",IFERROR(INDEX('3_可滴定酸度'!$E$6:$E$13,MATCH($I36,'3_可滴定酸度'!$B$6:$B$13,0)),""))) | M36: =IF($A36="","",IF($C36<>"manual_titration_mL","",IFERROR(INDEX('3_可滴定酸度'!$F$6:$F$13,MATCH($I36,'3_可滴定酸度'!$B$6:$B$13,0)),""))) | N36: =IF($A36="","",IF(OR(K36="",L36="",M36=""),"",K36*E36*L36/(M36*1000)*100)) | O36: =IF($A36="","",IF(N36="","",IF(COUNTIFS('1_原始數據'!$A$2:$A$1000,$A36,'1_原始數據'!$B$2:$B$1000,$B36,'1_原始數據'!$D$2:$D$1000,$D36,'1_原始數據'!$I$2:$I$1000,$I36,'1_原始數據'!$C$2:$C$1000,"pasco_pct_acid")=0,"",SUMIFS('1_原始數據'!$E$2:$E$1000,'1_原始數據'!$A$2:$A$1000,$A36,'1_原始數據'!$B$2:$B$1000,$B36,'1_原始數據'!$D$2:$D$1000,$D36,'1_原始數據'!$I$2:$I$1000,$I36,'1_原始數據'!$C$2:$C$1000,"pasco_pct_acid")))) | P36: =IF($A36="","",IF(OR(N36="",O36=""),"",O36-N36)) | Q36: =IF($A36="","",IF(P36="","",(O36+N36)/2)) | R36: =IF($A36="","",IF(P36="","",COUNT($P$2:P36)))
J37: =IF($A37="","",IF($C37<>"khp_titration_mL","",IF(COUNTIFS('1_原始數據'!$A$2:$A$1000,$A37,'1_原始數據'!$B$2:$B$1000,$B37,'1_原始數據'!$D$2:$D$1000,$D37,'1_原始數據'!$C$2:$C$1000,"khp_mass_g")=0,"",SUMIFS('1_原始數據'!$E$2:$E$1000,'1_原始數據'!$A$2:$A$1000,$A37,'1_原始數據'!$B$2:$B$1000,$B37,'1_原始數據'!$D$2:$D$1000,$D37,'1_原始數據'!$C$2:$C$1000,"khp_mass_g")/('2_NaOH標定'!$C$5*$E37/1000)))) | K37: =IF($A37="","",IF($C37<>"manual_titration_mL","",IF(COUNTIFS('1_原始數據'!$A$2:$A$1000,$A37,'1_原始數據'!$C$2:$C$1000,"khp_titration_mL")=0,"",AVERAGEIFS('1_原始數據'!$J$2:$J$1000,'1_原始數據'!$A$2:$A$1000,$A37,'1_原始數據'!$C$2:$C$1000,"khp_titration_mL")))) | L37: =IF($A37="","",IF($C37<>"manual_titration_mL","",IFERROR(INDEX('3_可滴定酸度'!$E$6:$E$13,MATCH($I37,'3_可滴定酸度'!$B$6:$B$13,0)),""))) | M37: =IF($A37="","",IF($C37<>"manual_titration_mL","",IFERROR(INDEX('3_可滴定酸度'!$F$6:$F$13,MATCH($I37,'3_可滴定酸度'!$B$6:$B$13,0)),""))) | N37: =IF($A37="","",IF(OR(K37="",L37="",M37=""),"",K37*E37*L37/(M37*1000)*100)) | O37: =IF($A37="","",IF(N37="","",IF(COUNTIFS('1_原始數據'!$A$2:$A$1000,$A37,'1_原始數據'!$B$2:$B$1000,$B37,'1_原始數據'!$D$2:$D$1000,$D37,'1_原始數據'!$I$2:$I$1000,$I37,'1_原始數據'!$C$2:$C$1000,"pasco_pct_acid")=0,"",SUMIFS('1_原始數據'!$E$2:$E$1000,'1_原始數據'!$A$2:$A$1000,$A37,'1_原始數據'!$B$2:$B$1000,$B37,'1_原始數據'!$D$2:$D$1000,$D37,'1_原始數據'!$I$2:$I$1000,$I37,'1_原始數據'!$C$2:$C$1000,"pasco_pct_acid")))) | P37: =IF($A37="","",IF(OR(N37="",O37=""),"",O37-N37)) | Q37: =IF($A37="","",IF(P37="","",(O37+N37)/2)) | R37: =IF($A37="","",IF(P37="","",COUNT($P$2:P37)))
J38: =IF($A38="","",IF($C38<>"khp_titration_mL","",IF(COUNTIFS('1_原始數據'!$A$2:$A$1000,$A38,'1_原始數據'!$B$2:$B$1000,$B38,'1_原始數據'!$D$2:$D$1000,$D38,'1_原始數據'!$C$2:$C$1000,"khp_mass_g")=0,"",SUMIFS('1_原始數據'!$E$2:$E$1000,'1_原始數據'!$A$2:$A$1000,$A38,'1_原始數據'!$B$2:$B$1000,$B38,'1_原始數據'!$D$2:$D$1000,$D38,'1_原始數據'!$C$2:$C$1000,"khp_mass_g")/('2_NaOH標定'!$C$5*$E38/1000)))) | K38: =IF($A38="","",IF($C38<>"manual_titration_mL","",IF(COUNTIFS('1_原始數據'!$A$2:$A$1000,$A38,'1_原始數據'!$C$2:$C$1000,"khp_titration_mL")=0,"",AVERAGEIFS('1_原始數據'!$J$2:$J$1000,'1_原始數據'!$A$2:$A$1000,$A38,'1_原始數據'!$C$2:$C$1000,"khp_titration_mL")))) | L38: =IF($A38="","",IF($C38<>"manual_titration_mL","",IFERROR(INDEX('3_可滴定酸度'!$E$6:$E$13,MATCH($I38,'3_可滴定酸度'!$B$6:$B$13,0)),""))) | M38: =IF($A38="","",IF($C38<>"manual_titration_mL","",IFERROR(INDEX('3_可滴定酸度'!$F$6:$F$13,MATCH($I38,'3_可滴定酸度'!$B$6:$B$13,0)),""))) | N38: =IF($A38="","",IF(OR(K38="",L38="",M38=""),"",K38*E38*L38/(M38*1000)*100)) | O38: =IF($A38="","",IF(N38="","",IF(COUNTIFS('1_原始數據'!$A$2:$A$1000,$A38,'1_原始數據'!$B$2:$B$1000,$B38,'1_原始數據'!$D$2:$D$1000,$D38,'1_原始數據'!$I$2:$I$1000,$I38,'1_原始數據'!$C$2:$C$1000,"pasco_pct_acid")=0,"",SUMIFS('1_原始數據'!$E$2:$E$1000,'1_原始數據'!$A$2:$A$1000,$A38,'1_原始數據'!$B$2:$B$1000,$B38,'1_原始數據'!$D$2:$D$1000,$D38,'1_原始數據'!$I$2:$I$1000,$I38,'1_原始數據'!$C$2:$C$1000,"pasco_pct_acid")))) | P38: =IF($A38="","",IF(OR(N38="",O38=""),"",O38-N38)) | Q38: =IF($A38="","",IF(P38="","",(O38+N38)/2)) | R38: =IF($A38="","",IF(P38="","",COUNT($P$2:P38)))
J39: =IF($A39="","",IF($C39<>"khp_titration_mL","",IF(COUNTIFS('1_原始數據'!$A$2:$A$1000,$A39,'1_原始數據'!$B$2:$B$1000,$B39,'1_原始數據'!$D$2:$D$1000,$D39,'1_原始數據'!$C$2:$C$1000,"khp_mass_g")=0,"",SUMIFS('1_原始數據'!$E$2:$E$1000,'1_原始數據'!$A$2:$A$1000,$A39,'1_原始數據'!$B$2:$B$1000,$B39,'1_原始數據'!$D$2:$D$1000,$D39,'1_原始數據'!$C$2:$C$1000,"khp_mass_g")/('2_NaOH標定'!$C$5*$E39/1000)))) | K39: =IF($A39="","",IF($C39<>"manual_titration_mL","",IF(COUNTIFS('1_原始數據'!$A$2:$A$1000,$A39,'1_原始數據'!$C$2:$C$1000,"khp_titration_mL")=0,"",AVERAGEIFS('1_原始數據'!$J$2:$J$1000,'1_原始數據'!$A$2:$A$1000,$A39,'1_原始數據'!$C$2:$C$1000,"khp_titration_mL")))) | L39: =IF($A39="","",IF($C39<>"manual_titration_mL","",IFERROR(INDEX('3_可滴定酸度'!$E$6:$E$13,MATCH($I39,'3_可滴定酸度'!$B$6:$B$13,0)),""))) | M39: =IF($A39="","",IF($C39<>"manual_titration_mL","",IFERROR(INDEX('3_可滴定酸度'!$F$6:$F$13,MATCH($I39,'3_可滴定酸度'!$B$6:$B$13,0)),""))) | N39: =IF($A39="","",IF(OR(K39="",L39="",M39=""),"",K39*E39*L39/(M39*1000)*100)) | O39: =IF($A39="","",IF(N39="","",IF(COUNTIFS('1_原始數據'!$A$2:$A$1000,$A39,'1_原始數據'!$B$2:$B$1000,$B39,'1_原始數據'!$D$2:$D$1000,$D39,'1_原始數據'!$I$2:$I$1000,$I39,'1_原始數據'!$C$2:$C$1000,"pasco_pct_acid")=0,"",SUMIFS('1_原始數據'!$E$2:$E$1000,'1_原始數據'!$A$2:$A$1000,$A39,'1_原始數據'!$B$2:$B$1000,$B39,'1_原始數據'!$D$2:$D$1000,$D39,'1_原始數據'!$I$2:$I$1000,$I39,'1_原始數據'!$C$2:$C$1000,"pasco_pct_acid")))) | P39: =IF($A39="","",IF(OR(N39="",O39=""),"",O39-N39)) | Q39: =IF($A39="","",IF(P39="","",(O39+N39)/2)) | R39: =IF($A39="","",IF(P39="","",COUNT($P$2:P39)))
J40: =IF($A40="","",IF($C40<>"khp_titration_mL","",IF(COUNTIFS('1_原始數據'!$A$2:$A$1000,$A40,'1_原始數據'!$B$2:$B$1000,$B40,'1_原始數據'!$D$2:$D$1000,$D40,'1_原始數據'!$C$2:$C$1000,"khp_mass_g")=0,"",SUMIFS('1_原始數據'!$E$2:$E$1000,'1_原始數據'!$A$2:$A$1000,$A40,'1_原始數據'!$B$2:$B$1000,$B40,'1_原始數據'!$D$2:$D$1000,$D40,'1_原始數據'!$C$2:$C$1000,"khp_mass_g")/('2_NaOH標定'!$C$5*$E40/1000)))) | K40: =IF($A40="","",IF($C40<>"manual_titration_mL","",IF(COUNTIFS('1_原始數據'!$A$2:$A$1000,$A40,'1_原始數據'!$C$2:$C$1000,"khp_titration_mL")=0,"",AVERAGEIFS('1_原始數據'!$J$2:$J$1000,'1_原始數據'!$A$2:$A$1000,$A40,'1_原始數據'!$C$2:$C$1000,"khp_titration_mL")))) | L40: =IF($A40="","",IF($C40<>"manual_titration_mL","",IFERROR(INDEX('3_可滴定酸度'!$E$6:$E$13,MATCH($I40,'3_可滴定酸度'!$B$6:$B$13,0)),""))) | M40: =IF($A40="","",IF($C40<>"manual_titration_mL","",IFERROR(INDEX('3_可滴定酸度'!$F$6:$F$13,MATCH($I40,'3_可滴定酸度'!$B$6:$B$13,0)),""))) | N40: =IF($A40="","",IF(OR(K40="",L40="",M40=""),"",K40*E40*L40/(M40*1000)*100)) | O40: =IF($A40="","",IF(N40="","",IF(COUNTIFS('1_原始數據'!$A$2:$A$1000,$A40,'1_原始數據'!$B$2:$B$1000,$B40,'1_原始數據'!$D$2:$D$1000,$D40,'1_原始數據'!$I$2:$I$1000,$I40,'1_原始數據'!$C$2:$C$1000,"pasco_pct_acid")=0,"",SUMIFS('1_原始數據'!$E$2:$E$1000,'1_原始數據'!$A$2:$A$1000,$A40,'1_原始數據'!$B$2:$B$1000,$B40,'1_原始數據'!$D$2:$D$1000,$D40,'1_原始數據'!$I$2:$I$1000,$I40,'1_原始數據'!$C$2:$C$1000,"pasco_pct_acid")))) | P40: =IF($A40="","",IF(OR(N40="",O40=""),"",O40-N40)) | Q40: =IF($A40="","",IF(P40="","",(O40+N40)/2)) | R40: =IF($A40="","",IF(P40="","",COUNT($P$2:P40)))
J41: =IF($A41="","",IF($C41<>"khp_titration_mL","",IF(COUNTIFS('1_原始數據'!$A$2:$A$1000,$A41,'1_原始數據'!$B$2:$B$1000,$B41,'1_原始數據'!$D$2:$D$1000,$D41,'1_原始數據'!$C$2:$C$1000,"khp_mass_g")=0,"",SUMIFS('1_原始數據'!$E$2:$E$1000,'1_原始數據'!$A$2:$A$1000,$A41,'1_原始數據'!$B$2:$B$1000,$B41,'1_原始數據'!$D$2:$D$1000,$D41,'1_原始數據'!$C$2:$C$1000,"khp_mass_g")/('2_NaOH標定'!$C$5*$E41/1000)))) | K41: =IF($A41="","",IF($C41<>"manual_titration_mL","",IF(COUNTIFS('1_原始數據'!$A$2:$A$1000,$A41,'1_原始數據'!$C$2:$C$1000,"khp_titration_mL")=0,"",AVERAGEIFS('1_原始數據'!$J$2:$J$1000,'1_原始數據'!$A$2:$A$1000,$A41,'1_原始數據'!$C$2:$C$1000,"khp_titration_mL")))) | L41: =IF($A41="","",IF($C41<>"manual_titration_mL","",IFERROR(INDEX('3_可滴定酸度'!$E$6:$E$13,MATCH($I41,'3_可滴定酸度'!$B$6:$B$13,0)),""))) | M41: =IF($A41="","",IF($C41<>"manual_titration_mL","",IFERROR(INDEX('3_可滴定酸度'!$F$6:$F$13,MATCH($I41,'3_可滴定酸度'!$B$6:$B$13,0)),""))) | N41: =IF($A41="","",IF(OR(K41="",L41="",M41=""),"",K41*E41*L41/(M41*1000)*100)) | O41: =IF($A41="","",IF(N41="","",IF(COUNTIFS('1_原始數據'!$A$2:$A$1000,$A41,'1_原始數據'!$B$2:$B$1000,$B41,'1_原始數據'!$D$2:$D$1000,$D41,'1_原始數據'!$I$2:$I$1000,$I41,'1_原始數據'!$C$2:$C$1000,"pasco_pct_acid")=0,"",SUMIFS('1_原始數據'!$E$2:$E$1000,'1_原始數據'!$A$2:$A$1000,$A41,'1_原始數據'!$B$2:$B$1000,$B41,'1_原始數據'!$D$2:$D$1000,$D41,'1_原始數據'!$I$2:$I$1000,$I41,'1_原始數據'!$C$2:$C$1000,"pasco_pct_acid")))) | P41: =IF($A41="","",IF(OR(N41="",O41=""),"",O41-N41)) | Q41: =IF($A41="","",IF(P41="","",(O41+N41)/2)) | R41: =IF($A41="","",IF(P41="","",COUNT($P$2:P41)))
J42: =IF($A42="","",IF($C42<>"khp_titration_mL","",IF(COUNTIFS('1_原始數據'!$A$2:$A$1000,$A42,'1_原始數據'!$B$2:$B$1000,$B42,'1_原始數據'!$D$2:$D$1000,$D42,'1_原始數據'!$C$2:$C$1000,"khp_mass_g")=0,"",SUMIFS('1_原始數據'!$E$2:$E$1000,'1_原始數據'!$A$2:$A$1000,$A42,'1_原始數據'!$B$2:$B$1000,$B42,'1_原始數據'!$D$2:$D$1000,$D42,'1_原始數據'!$C$2:$C$1000,"khp_mass_g")/('2_NaOH標定'!$C$5*$E42/1000)))) | K42: =IF($A42="","",IF($C42<>"manual_titration_mL","",IF(COUNTIFS('1_原始數據'!$A$2:$A$1000,$A42,'1_原始數據'!$C$2:$C$1000,"khp_titration_mL")=0,"",AVERAGEIFS('1_原始數據'!$J$2:$J$1000,'1_原始數據'!$A$2:$A$1000,$A42,'1_原始數據'!$C$2:$C$1000,"khp_titration_mL")))) | L42: =IF($A42="","",IF($C42<>"manual_titration_mL","",IFERROR(INDEX('3_可滴定酸度'!$E$6:$E$13,MATCH($I42,'3_可滴定酸度'!$B$6:$B$13,0)),""))) | M42: =IF($A42="","",IF($C42<>"manual_titration_mL","",IFERROR(INDEX('3_可滴定酸度'!$F$6:$F$13,MATCH($I42,'3_可滴定酸度'!$B$6:$B$13,0)),""))) | N42: =IF($A42="","",IF(OR(K42="",L42="",M42=""),"",K42*E42*L42/(M42*1000)*100)) | O42: =IF($A42="","",IF(N42="","",IF(COUNTIFS('1_原始數據'!$A$2:$A$1000,$A42,'1_原始數據'!$B$2:$B$1000,$B42,'1_原始數據'!$D$2:$D$1000,$D42,'1_原始數據'!$I$2:$I$1000,$I42,'1_原始數據'!$C$2:$C$1000,"pasco_pct_acid")=0,"",SUMIFS('1_原始數據'!$E$2:$E$1000,'1_原始數據'!$A$2:$A$1000,$A42,'1_原始數據'!$B$2:$B$1000,$B42,'1_原始數據'!$D$2:$D$1000,$D42,'1_原始數據'!$I$2:$I$1000,$I42,'1_原始數據'!$C$2:$C$1000,"pasco_pct_acid")))) | P42: =IF($A42="","",IF(OR(N42="",O42=""),"",O42-N42)) | Q42: =IF($A42="","",IF(P42="","",(O42+N42)/2)) | R42: =IF($A42="","",IF(P42="","",COUNT($P$2:P42)))
J43: =IF($A43="","",IF($C43<>"khp_titration_mL","",IF(COUNTIFS('1_原始數據'!$A$2:$A$1000,$A43,'1_原始數據'!$B$2:$B$1000,$B43,'1_原始數據'!$D$2:$D$1000,$D43,'1_原始數據'!$C$2:$C$1000,"khp_mass_g")=0,"",SUMIFS('1_原始數據'!$E$2:$E$1000,'1_原始數據'!$A$2:$A$1000,$A43,'1_原始數據'!$B$2:$B$1000,$B43,'1_原始數據'!$D$2:$D$1000,$D43,'1_原始數據'!$C$2:$C$1000,"khp_mass_g")/('2_NaOH標定'!$C$5*$E43/1000)))) | K43: =IF($A43="","",IF($C43<>"manual_titration_mL","",IF(COUNTIFS('1_原始數據'!$A$2:$A$1000,$A43,'1_原始數據'!$C$2:$C$1000,"khp_titration_mL")=0,"",AVERAGEIFS('1_原始數據'!$J$2:$J$1000,'1_原始數據'!$A$2:$A$1000,$A43,'1_原始數據'!$C$2:$C$1000,"khp_titration_mL")))) | L43: =IF($A43="","",IF($C43<>"manual_titration_mL","",IFERROR(INDEX('3_可滴定酸度'!$E$6:$E$13,MATCH($I43,'3_可滴定酸度'!$B$6:$B$13,0)),""))) | M43: =IF($A43="","",IF($C43<>"manual_titration_mL","",IFERROR(INDEX('3_可滴定酸度'!$F$6:$F$13,MATCH($I43,'3_可滴定酸度'!$B$6:$B$13,0)),""))) | N43: =IF($A43="","",IF(OR(K43="",L43="",M43=""),"",K43*E43*L43/(M43*1000)*100)) | O43: =IF($A43="","",IF(N43="","",IF(COUNTIFS('1_原始數據'!$A$2:$A$1000,$A43,'1_原始數據'!$B$2:$B$1000,$B43,'1_原始數據'!$D$2:$D$1000,$D43,'1_原始數據'!$I$2:$I$1000,$I43,'1_原始數據'!$C$2:$C$1000,"pasco_pct_acid")=0,"",SUMIFS('1_原始數據'!$E$2:$E$1000,'1_原始數據'!$A$2:$A$1000,$A43,'1_原始數據'!$B$2:$B$1000,$B43,'1_原始數據'!$D$2:$D$1000,$D43,'1_原始數據'!$I$2:$I$1000,$I43,'1_原始數據'!$C$2:$C$1000,"pasco_pct_acid")))) | P43: =IF($A43="","",IF(OR(N43="",O43=""),"",O43-N43)) | Q43: =IF($A43="","",IF(P43="","",(O43+N43)/2)) | R43: =IF($A43="","",IF(P43="","",COUNT($P$2:P43)))
J44: =IF($A44="","",IF($C44<>"khp_titration_mL","",IF(COUNTIFS('1_原始數據'!$A$2:$A$1000,$A44,'1_原始數據'!$B$2:$B$1000,$B44,'1_原始數據'!$D$2:$D$1000,$D44,'1_原始數據'!$C$2:$C$1000,"khp_mass_g")=0,"",SUMIFS('1_原始數據'!$E$2:$E$1000,'1_原始數據'!$A$2:$A$1000,$A44,'1_原始數據'!$B$2:$B$1000,$B44,'1_原始數據'!$D$2:$D$1000,$D44,'1_原始數據'!$C$2:$C$1000,"khp_mass_g")/('2_NaOH標定'!$C$5*$E44/1000)))) | K44: =IF($A44="","",IF($C44<>"manual_titration_mL","",IF(COUNTIFS('1_原始數據'!$A$2:$A$1000,$A44,'1_原始數據'!$C$2:$C$1000,"khp_titration_mL")=0,"",AVERAGEIFS('1_原始數據'!$J$2:$J$1000,'1_原始數據'!$A$2:$A$1000,$A44,'1_原始數據'!$C$2:$C$1000,"khp_titration_mL")))) | L44: =IF($A44="","",IF($C44<>"manual_titration_mL","",IFERROR(INDEX('3_可滴定酸度'!$E$6:$E$13,MATCH($I44,'3_可滴定酸度'!$B$6:$B$13,0)),""))) | M44: =IF($A44="","",IF($C44<>"manual_titration_mL","",IFERROR(INDEX('3_可滴定酸度'!$F$6:$F$13,MATCH($I44,'3_可滴定酸度'!$B$6:$B$13,0)),""))) | N44: =IF($A44="","",IF(OR(K44="",L44="",M44=""),"",K44*E44*L44/(M44*1000)*100)) | O44: =IF($A44="","",IF(N44="","",IF(COUNTIFS('1_原始數據'!$A$2:$A$1000,$A44,'1_原始數據'!$B$2:$B$1000,$B44,'1_原始數據'!$D$2:$D$1000,$D44,'1_原始數據'!$I$2:$I$1000,$I44,'1_原始數據'!$C$2:$C$1000,"pasco_pct_acid")=0,"",SUMIFS('1_原始數據'!$E$2:$E$1000,'1_原始數據'!$A$2:$A$1000,$A44,'1_原始數據'!$B$2:$B$1000,$B44,'1_原始數據'!$D$2:$D$1000,$D44,'1_原始數據'!$I$2:$I$1000,$I44,'1_原始數據'!$C$2:$C$1000,"pasco_pct_acid")))) | P44: =IF($A44="","",IF(OR(N44="",O44=""),"",O44-N44)) | Q44: =IF($A44="","",IF(P44="","",(O44+N44)/2)) | R44: =IF($A44="","",IF(P44="","",COUNT($P$2:P44)))
J45: =IF($A45="","",IF($C45<>"khp_titration_mL","",IF(COUNTIFS('1_原始數據'!$A$2:$A$1000,$A45,'1_原始數據'!$B$2:$B$1000,$B45,'1_原始數據'!$D$2:$D$1000,$D45,'1_原始數據'!$C$2:$C$1000,"khp_mass_g")=0,"",SUMIFS('1_原始數據'!$E$2:$E$1000,'1_原始數據'!$A$2:$A$1000,$A45,'1_原始數據'!$B$2:$B$1000,$B45,'1_原始數據'!$D$2:$D$1000,$D45,'1_原始數據'!$C$2:$C$1000,"khp_mass_g")/('2_NaOH標定'!$C$5*$E45/1000)))) | K45: =IF($A45="","",IF($C45<>"manual_titration_mL","",IF(COUNTIFS('1_原始數據'!$A$2:$A$1000,$A45,'1_原始數據'!$C$2:$C$1000,"khp_titration_mL")=0,"",AVERAGEIFS('1_原始數據'!$J$2:$J$1000,'1_原始數據'!$A$2:$A$1000,$A45,'1_原始數據'!$C$2:$C$1000,"khp_titration_mL")))) | L45: =IF($A45="","",IF($C45<>"manual_titration_mL","",IFERROR(INDEX('3_可滴定酸度'!$E$6:$E$13,MATCH($I45,'3_可滴定酸度'!$B$6:$B$13,0)),""))) | M45: =IF($A45="","",IF($C45<>"manual_titration_mL","",IFERROR(INDEX('3_可滴定酸度'!$F$6:$F$13,MATCH($I45,'3_可滴定酸度'!$B$6:$B$13,0)),""))) | N45: =IF($A45="","",IF(OR(K45="",L45="",M45=""),"",K45*E45*L45/(M45*1000)*100)) | O45: =IF($A45="","",IF(N45="","",IF(COUNTIFS('1_原始數據'!$A$2:$A$1000,$A45,'1_原始數據'!$B$2:$B$1000,$B45,'1_原始數據'!$D$2:$D$1000,$D45,'1_原始數據'!$I$2:$I$1000,$I45,'1_原始數據'!$C$2:$C$1000,"pasco_pct_acid")=0,"",SUMIFS('1_原始數據'!$E$2:$E$1000,'1_原始數據'!$A$2:$A$1000,$A45,'1_原始數據'!$B$2:$B$1000,$B45,'1_原始數據'!$D$2:$D$1000,$D45,'1_原始數據'!$I$2:$I$1000,$I45,'1_原始數據'!$C$2:$C$1000,"pasco_pct_acid")))) | P45: =IF($A45="","",IF(OR(N45="",O45=""),"",O45-N45)) | Q45: =IF($A45="","",IF(P45="","",(O45+N45)/2)) | R45: =IF($A45="","",IF(P45="","",COUNT($P$2:P45)))
