Workbook

Sheet 0_說明
B1: EX05｜W5 蛋白質（凱氏定氮法）
B2: 食品分析實驗・入門數據分析（Excel 版）。不用寫程式；同一份數據在 Colab 筆記本做進階分析，答案應該一致。
B4: 學習目標
B5: • 用 %N = (V_s − V_b) × N_HCl × 14.007 ÷ W_mg × 100 從滴定體積算出 %N，再用換算係數 5.7／6.25／6.38 換成蛋白質 %。
B6: • 說出換算係數選錯（小麥 5.7 誤用 6.25）造成的系統誤差有多大。
B7: • 計算硫酸銨蒸餾回收標準品的回收率 (recovery)，判斷蒸餾／捕氨是否完整（≥ 97%）。
B8: • 彙整全班盲樣（全脂奶粉，n = 5）的平均 ± 95% CI、SD、RSD。
B9: • 重新計算三聚氰胺事件：摻多少會虛增多少表觀蛋白質。
B10: • 用靈敏度分析說明滴定讀取誤差如何隨樣品重量放大。
B12: 顏色代表什麼
C13: 黃色：輸入或貼上數據的地方
C14: 綠色：公式，會自動計算，不要改
C15: 橘色：重點結果，寫報告時用
B17: 操作步驟
B18: 1. 看「1_原始數據」：一列是一管。右邊綠色欄已算好 weight_mg、扣空白後的體積與 %N。
B19: 2. 看「2_公式與參數」：HCl 濃度、試劑空白、換算係數都在這裡；做第 31–39 列的自我檢查。
B20: 3. 看「3_全班盲樣」：5 組奶粉的 %N、蛋白質 %、平均 ± 95% CI 與長條圖。
B21: 4. 看「4_麵粉與係數」：高筋 vs 低筋，與選錯係數的代價。
B22: 5. 看「5_回收率」、「6_三聚氰胺」、「7_靈敏度」。
B23: 6. 完成「練習題」。
B24: 7. 換成班級數據：把共用 Google Sheet 的數據貼到「1_原始數據」A2 起；組別或學生代號不同就改「3_全班盲樣」A–B 欄；HCl 濃度改「2_公式與參數」C6。
B26: 對答案：用內建範例數據時，你的結果應該等於
B27: 項目 | C27: 本檔計算值 | D27: Colab 筆記本的值 | E27: 一致？
B28: 全脂奶粉盲樣平均蛋白質 (%) | C28: ='3_全班盲樣'!K8 | D28: 25.851798 | E28: =IF(ABS(C28-D28)<=0.0025851807862261,"✔ 一致","✘ 不一致（換成班級數據後本來就會不同）")
B29: 盲樣 95% CI 半寬 (%) | C29: ='3_全班盲樣'!K12 | D29: 0.29815462 | E29: =IF(ABS(C29-D29)<=2.981646184197823e-05,"✔ 一致","✘ 不一致（換成班級數據後本來就會不同）")
B30: 盲樣 RSD (%) | C30: ='3_全班盲樣'!K13 | D30: 0.92885238 | E30: =IF(ABS(C30-D30)<=9.288623847872741e-05,"✔ 一致","✘ 不一致（換成班級數據後本來就會不同）")
B31: 高筋麵粉 %N | C31: ='4_麵粉與係數'!B10 | D31: 2.2789389 | E31: =IF(ABS(C31-D31)<=0.00022789489,"✔ 一致","✘ 不一致（換成班級數據後本來就會不同）")
B32: 高筋麵粉誤用 6.25 的相對高估 (%) | C32: ='4_麵粉與係數'!B15 | D32: 9.6491228 | E32: =IF(ABS(C32-D32)<=0.0009649132807017549,"✔ 一致","✘ 不一致（換成班級數據後本來就會不同）")
B33: 硫酸銨回收率 (%) | C33: ='5_回收率'!B11 | D33: 99.499914 | E33: =IF(ABS(C33-D33)<=0.009949992400000001,"✔ 一致","✘ 不一致（換成班級數據後本來就會不同）")
B34: 每摻 1% 三聚氰胺虛增表觀蛋白質（百分點） | C34: ='6_三聚氰胺'!B7 | D34: 4.2513099 | E34: =IF(ABS(C34-D34)<=0.0004251319911752812,"✔ 一致","✘ 不一致（換成班級數據後本來就會不同）")
B35: ΔV = 0.05 mL 對奶粉蛋白質 % 的影響 | C35: ='7_靈敏度'!F7 | D35: 0.089275385 | E35: =IF(ABS(C35-D35)<=8.928538461538466e-06,"✔ 一致","✘ 不一致（換成班級數據後本來就會不同）")
B36: 「Colab 筆記本的值」是用內建模擬數據算出的答案；換成全班數據後，這一欄就不再適用。
B38: 相關連結
B39: 本週實驗投影片 | C39: https://tai-shengyeh.github.io/food-analysis-lab/labs/w05_kjeldahl/index.html
B40: 進階：Colab 筆記本（Python） | C40: https://colab.research.google.com/github/Tai-ShengYeh/food-analysis-lab/blob/main/notebooks/NB05_kjeldahl_protein.ipynb
B41: 數據分析工具指南（Excel／Orange／Colab） | C41: https://tai-shengyeh.github.io/food-analysis-lab/tools.html
B43: 小提醒
B44: • 試劑空白、高筋／低筋麵粉、硫酸銨都各只有 1 管。若班上做了 2 管空白，「2_公式與參數」C12 會自動取平均（Colab 只取第一管）。
B45: • 所有 %N 都用「2_公式與參數」C14 的 V_b；改 C13 開關可以看不扣空白的結果。
B46: • 進階：匯出 CSV 請看 Colab 筆記本。本週所有計算都已包含在這個 Excel 檔中。
...

Sheet 1_原始數據
A1: group | B1: student | C1: item | D1: rep | E1: value | F1: unit | G1: temp_C | H1: weight_g | I1: note | J1: weight_mg | K1: V_net_mL | L1: pctN | N1: 這張工作表怎麼用
A2: 1 | B2: G1 | C2: milk_powder_blind | D2: 1 | E2: 14.67 | F2: mL | H2: 0.5005 | I2: 5 組各消化 1 管盲樣（設備僅容納 8 管） | J2: =IF($A2="","",IF(H2="","",H2*1000)) | K2: =IF($A2="","",E2-'2_公式與參數'!$C$14) | L2: =IF($A2="","",IF(H2="","",K2*'2_公式與參數'!$C$6*'2_公式與參數'!$C$7/J2*100)) | N2: 本週欄位：item＝管別（milk_powder_blind 全脂奶粉盲樣、reagent_blank 試劑空白、ammonium_sulfate_std 硫酸銨回收標準品、high_gluten_flour 高筋麵粉、low_gluten_flour 低筋麵粉）；value＝滴定用去的 HCl 體積 (mL)；weight_g＝樣品重 (g)；temp_C 本週不用，留空。
A3: 2 | B3: G2 | C3: milk_powder_blind | D3: 1 | E3: 15.03 | F3: mL | H3: 0.5011 | I3: 5 組各消化 1 管盲樣（設備僅容納 8 管） | J3: =IF($A3="","",IF(H3="","",H3*1000)) | K3: =IF($A3="","",E3-'2_公式與參數'!$C$14) | L3: =IF($A3="","",IF(H3="","",K3*'2_公式與參數'!$C$6*'2_公式與參數'!$C$7/J3*100)) | N3: 消化爐一次只能放 8 管：5 管盲樣（每組 1 管）＋ 1 管空白 ＋ 1 管回收標準品 ＋ 1 管高筋麵粉。低筋麵粉是助教提供的前次數據。
A4: 3 | B4: G3 | C4: milk_powder_blind | D4: 1 | E4: 14.63 | F4: mL | H4: 0.4971 | I4: 5 組各消化 1 管盲樣（設備僅容納 8 管） | J4: =IF($A4="","",IF(H4="","",H4*1000)) | K4: =IF($A4="","",E4-'2_公式與參數'!$C$14) | L4: =IF($A4="","",IF(H4="","",K4*'2_公式與參數'!$C$6*'2_公式與參數'!$C$7/J4*100)) | N4: 黃色欄位＝原始數據。換成全班數據時：從共用 Google Sheet 複製，貼到 A2（欄位順序必須一樣），舊資料多出來的列要整列刪除。
A5: 4 | B5: G4 | C5: milk_powder_blind | D5: 1 | E5: 14.8 | F5: mL | H5: 0.5002 | I5: 5 組各消化 1 管盲樣（設備僅容納 8 管） | J5: =IF($A5="","",IF(H5="","",H5*1000)) | K5: =IF($A5="","",E5-'2_公式與參數'!$C$14) | L5: =IF($A5="","",IF(H5="","",K5*'2_公式與參數'!$C$6*'2_公式與參數'!$C$7/J5*100)) | N5: 綠色欄位＝公式，會自動算到第 1000 列，不要手動修改。
A6: 5 | B6: G5 | C6: milk_powder_blind | D6: 1 | E6: 14.71 | F6: mL | H6: 0.5 | I6: 5 組各消化 1 管盲樣（設備僅容納 8 管） | J6: =IF($A6="","",IF(H6="","",H6*1000)) | K6: =IF($A6="","",E6-'2_公式與參數'!$C$14) | L6: =IF($A6="","",IF(H6="","",K6*'2_公式與參數'!$C$6*'2_公式與參數'!$C$7/J6*100)) | N6: 「weight_mg」：樣品重換成毫克（公式需要 mg）。試劑空白沒有樣品，留空。
A7: 0 | B7: shared | C7: reagent_blank | D7: 1 | E7: 0.31 | F7: mL | I7: 試劑空白，全班共用 1 管，不加樣品 | J7: =IF($A7="","",IF(H7="","",H7*1000)) | K7: =IF($A7="","",E7-'2_公式與參數'!$C$14) | L7: =IF($A7="","",IF(H7="","",K7*'2_公式與參數'!$C$6*'2_公式與參數'!$C$7/J7*100)) | N7: 「V_net_mL」：淨滴定體積 = value − 試劑空白 V_b（V_b 在「2_公式與參數」C14）。
A8: 0 | B8: shared | C8: ammonium_sulfate_std | D8: 1 | E8: 7.84 | F8: mL | H8: 0.05 | I8: 蒸餾回收標準品，理論 N%=21.20% (硫酸銨) | J8: =IF($A8="","",IF(H8="","",H8*1000)) | K8: =IF($A8="","",E8-'2_公式與參數'!$C$14) | L8: =IF($A8="","",IF(H8="","",K8*'2_公式與參數'!$C$6*'2_公式與參數'!$C$7/J8*100)) | N8: 「pctN」：%N = V_net × N_HCl × 14.007 ÷ weight_mg × 100。
A9: 1 | B9: G1 | C9: high_gluten_flour | D9: 1 | E9: 16.58 | F9: mL | H9: 1 | I9: 高筋麵粉，由 G1 代表操作，結果全班共用 | J9: =IF($A9="","",IF(H9="","",H9*1000)) | K9: =IF($A9="","",E9-'2_公式與參數'!$C$14) | L9: =IF($A9="","",IF(H9="","",K9*'2_公式與參數'!$C$6*'2_公式與參數'!$C$7/J9*100))
A10: 0 | B10: TA | C10: low_gluten_flour | D10: 1 | E10: 10.32 | F10: mL | H10: 1 | I10: TA 提供（前次操作數據），本次消化爐排程已滿 8 管，未現場加測 | J10: =IF($A10="","",IF(H10="","",H10*1000)) | K10: =IF($A10="","",E10-'2_公式與參數'!$C$14) | L10: =IF($A10="","",IF(H10="","",K10*'2_公式與參數'!$C$6*'2_公式與參數'!$C$7/J10*100))
J11: =IF($A11="","",IF(H11="","",H11*1000)) | K11: =IF($A11="","",E11-'2_公式與參數'!$C$14) | L11: =IF($A11="","",IF(H11="","",K11*'2_公式與參數'!$C$6*'2_公式與參數'!$C$7/J11*100))
J12: =IF($A12="","",IF(H12="","",H12*1000)) | K12: =IF($A12="","",E12-'2_公式與參數'!$C$14) | L12: =IF($A12="","",IF(H12="","",K12*'2_公式與參數'!$C$6*'2_公式與參數'!$C$7/J12*100))
J13: =IF($A13="","",IF(H13="","",H13*1000)) | K13: =IF($A13="","",E13-'2_公式與參數'!$C$14) | L13: =IF($A13="","",IF(H13="","",K13*'2_公式與參數'!$C$6*'2_公式與參數'!$C$7/J13*100))
J14: =IF($A14="","",IF(H14="","",H14*1000)) | K14: =IF($A14="","",E14-'2_公式與參數'!$C$14) | L14: =IF($A14="","",IF(H14="","",K14*'2_公式與參數'!$C$6*'2_公式與參數'!$C$7/J14*100))
J15: =IF($A15="","",IF(H15="","",H15*1000)) | K15: =IF($A15="","",E15-'2_公式與參數'!$C$14) | L15: =IF($A15="","",IF(H15="","",K15*'2_公式與參數'!$C$6*'2_公式與參數'!$C$7/J15*100))
J16: =IF($A16="","",IF(H16="","",H16*1000)) | K16: =IF($A16="","",E16-'2_公式與參數'!$C$14) | L16: =IF($A16="","",IF(H16="","",K16*'2_公式與參數'!$C$6*'2_公式與參數'!$C$7/J16*100))
J17: =IF($A17="","",IF(H17="","",H17*1000)) | K17: =IF($A17="","",E17-'2_公式與參數'!$C$14) | L17: =IF($A17="","",IF(H17="","",K17*'2_公式與參數'!$C$6*'2_公式與參數'!$C$7/J17*100))
J18: =IF($A18="","",IF(H18="","",H18*1000)) | K18: =IF($A18="","",E18-'2_公式與參數'!$C$14) | L18: =IF($A18="","",IF(H18="","",K18*'2_公式與參數'!$C$6*'2_公式與參數'!$C$7/J18*100))
J19: =IF($A19="","",IF(H19="","",H19*1000)) | K19: =IF($A19="","",E19-'2_公式與參數'!$C$14) | L19: =IF($A19="","",IF(H19="","",K19*'2_公式與參數'!$C$6*'2_公式與參數'!$C$7/J19*100))
J20: =IF($A20="","",IF(H20="","",H20*1000)) | K20: =IF($A20="","",E20-'2_公式與參數'!$C$14) | L20: =IF($A20="","",IF(H20="","",K20*'2_公式與參數'!$C$6*'2_公式與參數'!$C$7/J20*100))
J21: =IF($A21="","",IF(H21="","",H21*1000)) | K21: =IF($A21="","",E21-'2_公式與參數'!$C$14) | L21: =IF($A21="","",IF(H21="","",K21*'2_公式與參數'!$C$6*'2_公式與參數'!$C$7/J21*100))
J22: =IF($A22="","",IF(H22="","",H22*1000)) | K22: =IF($A22="","",E22-'2_公式與參數'!$C$14) | L22: =IF($A22="","",IF(H22="","",K22*'2_公式與參數'!$C$6*'2_公式與參數'!$C$7/J22*100))
... J1000: =IF($A1000="","",IF(H1000="","",H1000*1000)) | K1000: =IF($A1000="","",E1000-'2_公式與參數'!$C$14) | L1000: =IF($A1000="","",IF(H1000="","",K1000*'2_公式與參數'!$C$6*'2_公式與參數'!$C$7/J1000*100))

Sheet 2_公式與參數
B1: 步驟 1 凱氏法公式、參數與換算係數
B2: 凱氏法量到的是「總氮」。先算 %N，再乘上換算係數才是蛋白質 %。這張表的參數會被後面所有工作表引用。
B4: 參數
B5: 參數 | C5: 數值 | D5: 單位 | E5: 說明
B6: HCl 標準化濃度 N_HCl | C6: 0.1 | D6: eq/L | E6: 本週全班共用、已用 Na₂CO₃ 或 THAM 標定過的 HCl。換成你們實際標定的濃度。
B7: 氮原子量 N | C7: 14.007 | D7: g/mol | E7: 1 meq HCl 對應 14.007 mg 氮。以下原子量請不要改。
B8: 氫原子量 H | C8: 1.008 | D8: g/mol
B9: 碳原子量 C | C9: 12.011 | D9: g/mol
B10: 氧原子量 O | C10: 16 | D10: g/mol
B11: 硫原子量 S | C11: 32.06 | D11: g/mol
B12: 試劑空白實測 V_b | C12: =AVERAGEIFS('1_原始數據'!$E$2:$E$1000,'1_原始數據'!$C$2:$C$1000,"reagent_blank") | D12: mL | E12: =AVERAGEIFS(value, item, "reagent_blank") 從「1_原始數據」抓試劑空白管的滴定體積。有兩管以上空白時自動取平均。
B13: 是否扣除空白（1＝扣，0＝不扣） | C13: 1 | E13: 正常一定是 1。練習題 1 會請你暫時改成 0，看看忘記扣空白會高估多少。
B14: 計算用 V_b | C14: =C12*C13 | D14: mL | E14: = 實測 V_b × 開關。後面每一個 %N 都用這一格。
B16: 換算係數（蛋白質 % = %N × 係數）
B17: 食品類別 | C17: 係數 | E17: 理由（簡述）
B18: 一般 | C18: 6.25 | E18: 一般食品（通用值）：假設蛋白質平均含氮 16%（1 ÷ 0.16 = 6.25）
B19: 小麥 | C19: 5.7 | E19: 小麥／穀類：穀類蛋白（麩質）含氮比例較高，需用較小係數
B20: 乳品 | C20: 6.38 | E20: 乳品：酪蛋白等乳蛋白含氮比例較低，需用較大係數
B22: 公式
B23: %N | C23: %N = (V_s − V_b) × N_HCl × 14.007 ÷ W_mg × 100
B24: 符號 | C24: V_s 樣品滴定 HCl 體積 (mL)；V_b 試劑空白體積 (mL)；W_mg 樣品重（毫克＝公克 × 1000）
B25: 為什麼 | C25: (V_s − V_b) × N_HCl ＝ 樣品放出的 NH₃ 毫當量 (meq)；× 14.007 ＝ 氮的毫克數；÷ 樣品毫克數 × 100 ＝ %N
B26: 蛋白質 % | C26: 蛋白質 % = %N × 換算係數（一般 6.25／小麥 5.7／乳品 6.38）
B27: 硼酸 | C27: 蒸出的 NH₃ 被 4% 硼酸捕捉，再用標準 HCl 滴定。硼酸只負責捕氨，本身不需要標定，也不進公式。
B29: 自我檢查：一管樣品從滴定體積算到蛋白質 %
B30: 項目 | C30: 數值 | D30: 單位 | E30: 公式說明
B31: 樣品滴定體積 V_s | C31: 14.67 | D31: mL | E31: 預設是 G1 的全脂奶粉盲樣
B32: 樣品重 W | C32: 0.5005 | D32: g
B33: 食品類別（一般／小麥／乳品） | C33: 乳品 | E33: 從下拉選單選；決定用哪一個換算係數
B34: 淨滴定體積 V_s − V_b | C34: =C31-C14 | D34: mL | E34: 扣掉試劑本身消耗的 HCl
B35: 氮的毫克數 | C35: =C34*'2_公式與參數'!$C$6*'2_公式與參數'!$C$7 | D35: mg | E35: = 淨體積 × N_HCl × 14.007
B36: 樣品毫克數 W_mg | C36: =C32*1000 | D36: mg | E36: 公克 × 1000。忘記換算會差 1000 倍！
B37: %N | C37: =C35/C36*100 | D37: % | E37: = 氮 mg ÷ 樣品 mg × 100。G1 應為 4.0188%
B38: 換算係數 | C38: =VLOOKUP(C33,$B$18:$C$20,2,FALSE) | E38: VLOOKUP(要找的值, 表格範圍, 第幾欄, FALSE＝完全相符)：到上面係數表找「乳品」那一列的第 2 欄
B39: 蛋白質 (%) | C39: =C37*C38 | D39: % | E39: = %N × 係數。G1 應為 25.64%

Sheet 3_全班盲樣
A1: 步驟 2 全班盲樣：全脂奶粉 (n = 5，每組 1 管)
A2: 每組消化 1 管，全班湊成 n = 5。C、D 欄用 SUMIFS 依「學生＋管別」抓滴定體積與樣品重，其餘是公式。乳品用係數 6.38。
A3: 管別代號 | C3: milk_powder_blind
N4: 圖用輔助數據（自動計算）
A5: 組別 | B5: 學生 | C5: V_s (mL) | D5: W (g) | E5: V_s − V_b (mL) | F5: W (mg) | G5: %N | H5: 蛋白質 (%) | J5: 項目 | K5: 數值 | L5: 公式說明 | N5: class mean | O5: mean - 95% CI | P5: mean + 95% CI
A6: 1 | B6: G1 | C6: =IF(COUNTIFS('1_原始數據'!$B$2:$B$1000,B6,'1_原始數據'!$C$2:$C$1000,$C$3)=0,"",SUMIFS('1_原始數據'!$E$2:$E$1000,'1_原始數據'!$B$2:$B$1000,B6,'1_原始數據'!$C$2:$C$1000,$C$3)) | D6: =IF(COUNTIFS('1_原始數據'!$B$2:$B$1000,B6,'1_原始數據'!$C$2:$C$1000,$C$3)=0,"",SUMIFS('1_原始數據'!$H$2:$H$1000,'1_原始數據'!$B$2:$B$1000,B6,'1_原始數據'!$C$2:$C$1000,$C$3)) | E6: =C6-'2_公式與參數'!$C$14 | F6: =D6*1000 | G6: =E6*'2_公式與參數'!$C$6*'2_公式與參數'!$C$7/F6*100 | H6: =G6*'2_公式與參數'!$C$20 | J6: n（管數） | K6: =COUNT(H6:H10) | L6: COUNT 數有幾個數字 | N6: =$K$8 | O6: =$K$8-$K$12 | P6: =$K$8+$K$12
A7: 2 | B7: G2 | C7: =IF(COUNTIFS('1_原始數據'!$B$2:$B$1000,B7,'1_原始數據'!$C$2:$C$1000,$C$3)=0,"",SUMIFS('1_原始數據'!$E$2:$E$1000,'1_原始數據'!$B$2:$B$1000,B7,'1_原始數據'!$C$2:$C$1000,$C$3)) | D7: =IF(COUNTIFS('1_原始數據'!$B$2:$B$1000,B7,'1_原始數據'!$C$2:$C$1000,$C$3)=0,"",SUMIFS('1_原始數據'!$H$2:$H$1000,'1_原始數據'!$B$2:$B$1000,B7,'1_原始數據'!$C$2:$C$1000,$C$3)) | E7: =C7-'2_公式與參數'!$C$14 | F7: =D7*1000 | G7: =E7*'2_公式與參數'!$C$6*'2_公式與參數'!$C$7/F7*100 | H7: =G7*'2_公式與參數'!$C$20 | J7: 平均 %N | K7: =AVERAGE(G6:G10) | N7: =$K$8 | O7: =$K$8-$K$12 | P7: =$K$8+$K$12
A8: 3 | B8: G3 | C8: =IF(COUNTIFS('1_原始數據'!$B$2:$B$1000,B8,'1_原始數據'!$C$2:$C$1000,$C$3)=0,"",SUMIFS('1_原始數據'!$E$2:$E$1000,'1_原始數據'!$B$2:$B$1000,B8,'1_原始數據'!$C$2:$C$1000,$C$3)) | D8: =IF(COUNTIFS('1_原始數據'!$B$2:$B$1000,B8,'1_原始數據'!$C$2:$C$1000,$C$3)=0,"",SUMIFS('1_原始數據'!$H$2:$H$1000,'1_原始數據'!$B$2:$B$1000,B8,'1_原始數據'!$C$2:$C$1000,$C$3)) | E8: =C8-'2_公式與參數'!$C$14 | F8: =D8*1000 | G8: =E8*'2_公式與參數'!$C$6*'2_公式與參數'!$C$7/F8*100 | H8: =G8*'2_公式與參數'!$C$20 | J8: 平均蛋白質 (%) | K8: =AVERAGE(H6:H10) | L8: 班級平均 | N8: =$K$8 | O8: =$K$8-$K$12 | P8: =$K$8+$K$12
A9: 4 | B9: G4 | C9: =IF(COUNTIFS('1_原始數據'!$B$2:$B$1000,B9,'1_原始數據'!$C$2:$C$1000,$C$3)=0,"",SUMIFS('1_原始數據'!$E$2:$E$1000,'1_原始數據'!$B$2:$B$1000,B9,'1_原始數據'!$C$2:$C$1000,$C$3)) | D9: =IF(COUNTIFS('1_原始數據'!$B$2:$B$1000,B9,'1_原始數據'!$C$2:$C$1000,$C$3)=0,"",SUMIFS('1_原始數據'!$H$2:$H$1000,'1_原始數據'!$B$2:$B$1000,B9,'1_原始數據'!$C$2:$C$1000,$C$3)) | E9: =C9-'2_公式與參數'!$C$14 | F9: =D9*1000 | G9: =E9*'2_公式與參數'!$C$6*'2_公式與參數'!$C$7/F9*100 | H9: =G9*'2_公式與參數'!$C$20 | J9: SD (%) | K9: =_xlfn.STDEV.S(H6:H10) | L9: STDEV.S：樣本標準差（除以 n − 1） | N9: =$K$8 | O9: =$K$8-$K$12 | P9: =$K$8+$K$12
A10: 5 | B10: G5 | C10: =IF(COUNTIFS('1_原始數據'!$B$2:$B$1000,B10,'1_原始數據'!$C$2:$C$1000,$C$3)=0,"",SUMIFS('1_原始數據'!$E$2:$E$1000,'1_原始數據'!$B$2:$B$1000,B10,'1_原始數據'!$C$2:$C$1000,$C$3)) | D10: =IF(COUNTIFS('1_原始數據'!$B$2:$B$1000,B10,'1_原始數據'!$C$2:$C$1000,$C$3)=0,"",SUMIFS('1_原始數據'!$H$2:$H$1000,'1_原始數據'!$B$2:$B$1000,B10,'1_原始數據'!$C$2:$C$1000,$C$3)) | E10: =C10-'2_公式與參數'!$C$14 | F10: =D10*1000 | G10: =E10*'2_公式與參數'!$C$6*'2_公式與參數'!$C$7/F10*100 | H10: =G10*'2_公式與參數'!$C$20 | J10: 標準誤 SEM (%) | K10: =K9/SQRT(K6) | L10: = SD ÷ √n，代表「平均值」的不確定度 | N10: =$K$8 | O10: =$K$8-$K$12 | P10: =$K$8+$K$12
A11: E＝扣空白；F＝公克換毫克；G＝%N（公式見「2_公式與參數」）；H＝%N × 乳品係數 6.38。 | J11: t 臨界值（95%） | K11: =_xlfn.T.INV.2T(0.05,K6-1) | L11: T.INV.2T(0.05, n − 1)；n = 5 時約 2.776
J12: 95% CI 半寬 (%) | K12: =K11*K10 | L12: = t × SEM
J13: RSD (%) | K13: =K9/K8*100 | L13: = SD ÷ 平均 × 100
J14: 報告寫法 | K14: =FIXED(K8,2)&" ± "&FIXED(K12,2)&" %（95% CI, n = "&K6&"）"
J16: 為什麼要用全班數據？單組只有 1 管，算不出 SD；5 組湊起來才能估計精密度與 95% CI，也比較不會被某一管的操作失誤帶偏。
A37: 看圖：藍色圓點是每組的蛋白質 %（Colab 畫成長條圖，這裡用點圖，縱軸不必從 0 開始，差異看得比較清楚），黑色虛線是班級平均，兩條橘色點線之間是平均值的 95% CI。5 組差不多高＝組間一致；某一組明顯偏離 CI 很多，就回頭檢查那一管的秤重與滴定終點。

Sheet 4_麵粉與係數
A1: 步驟 3 高筋 vs 低筋麵粉：換算係數選錯的代價
A2: 兩種麵粉都該用小麥係數 5.7。高筋麵粉由 G1 代表操作、全班共用；低筋麵粉本次沒有現場加測，數值由助教提供。
A4: 項目 | B4: 高筋麵粉 | C4: 低筋麵粉 | E4: 公式說明
A5: 管別代號 | B5: high_gluten_flour | C5: low_gluten_flour | E5: 黃色，可改
A6: 來源（note 欄） | B6: =INDEX('1_原始數據'!$I$2:$I$1000,MATCH(B5,'1_原始數據'!$C$2:$C$1000,0)) | C6: =INDEX('1_原始數據'!$I$2:$I$1000,MATCH(C5,'1_原始數據'!$C$2:$C$1000,0)) | E6: INDEX(範圍, MATCH(要找的值, 範圍, 0))：找出第一筆 item 相符的列，回傳那一列的值（和 Colab 的 .iloc[0] 一樣）
A7: V_s (mL) | B7: =INDEX('1_原始數據'!$E$2:$E$1000,MATCH(B5,'1_原始數據'!$C$2:$C$1000,0)) | C7: =INDEX('1_原始數據'!$E$2:$E$1000,MATCH(C5,'1_原始數據'!$C$2:$C$1000,0))
A8: W (g) | B8: =INDEX('1_原始數據'!$H$2:$H$1000,MATCH(B5,'1_原始數據'!$C$2:$C$1000,0)) | C8: =INDEX('1_原始數據'!$H$2:$H$1000,MATCH(C5,'1_原始數據'!$C$2:$C$1000,0))
A9: V_s − V_b (mL) | B9: =B7-'2_公式與參數'!$C$14 | C9: =C7-'2_公式與參數'!$C$14 | E9: 扣試劑空白
A10: %N | B10: =B9*'2_公式與參數'!$C$6*'2_公式與參數'!$C$7/(B8*1000)*100 | C10: =C9*'2_公式與參數'!$C$6*'2_公式與參數'!$C$7/(C8*1000)*100 | E10: 同「2_公式與參數」的 %N 公式
A11: 蛋白質 %，小麥係數 5.7（正確） | B11: =B10*'2_公式與參數'!$C$19 | C11: =C10*'2_公式與參數'!$C$19 | E11: 報告用這一列
A12: 蛋白質 %，一般係數 6.25（錯誤） | B12: =B10*'2_公式與參數'!$C$18 | C12: =C10*'2_公式與參數'!$C$18 | E12: 誤用通用係數
A13: 蛋白質 %，乳品係數 6.38（錯誤） | B13: =B10*'2_公式與參數'!$C$20 | C13: =C10*'2_公式與參數'!$C$20 | E13: 對照看看：係數越大，算出的蛋白質越多
A14: 誤用 6.25 高估（百分點） | B14: =B12-B11 | C14: =C12-C11 | E14: = 錯誤 − 正確
A15: 誤用 6.25 相對高估 (%) | B15: =(B12-B11)/B11*100 | C15: =(C12-C11)/C11*100 | E15: = (錯誤 − 正確) ÷ 正確 × 100。兩種麵粉都一樣，因為它其實就是 (6.25 ÷ 5.7 − 1) × 100，跟測得多準無關——這是系統誤差
A17: 高筋 − 低筋 蛋白質差（百分點，係數 5.7） | B17: =B11-C11 | E17: 高筋麵粉蛋白質（麩質）多，適合做麵包；低筋麵粉蛋白質少，適合做蛋糕。

Sheet 5_回收率
A1: 步驟 4 品管：蒸餾回收標準品（硫酸銨）的回收率
A2: 硫酸銨 (NH₄)₂SO₄ 的含氮量可以由分子量算出來。讓它走一次蒸餾＋滴定，測得的 %N 和理論值一比，就知道 NH₃ 有沒有被完全蒸出、捕捉。
A4: 項目 | B4: 數值 | D4: 公式說明
A5: 管別代號 | B5: ammonium_sulfate_std | D5: 黃色，可改
A6: (NH₄)₂SO₄ 分子量 (g/mol) | B6: =2*('2_公式與參數'!$C$7+4*'2_公式與參數'!$C$8)+'2_公式與參數'!$C$11+4*'2_公式與參數'!$C$10 | D6: = 2 × (N + 4H) + S + 4O，原子量在「2_公式與參數」
A7: 理論 %N | B7: =2*'2_公式與參數'!$C$7/B6*100 | D7: = 2 × 14.007 ÷ 分子量 × 100 ≈ 21.20%
A8: V_s (mL) | B8: =INDEX('1_原始數據'!$E$2:$E$1000,MATCH(B5,'1_原始數據'!$C$2:$C$1000,0)) | D8: INDEX/MATCH 找第一筆 item 相符的列
A9: W (g) | B9: =INDEX('1_原始數據'!$H$2:$H$1000,MATCH(B5,'1_原始數據'!$C$2:$C$1000,0)) | D9: 標準品只秤 0.05 g
A10: 實測 %N | B10: =(B8-'2_公式與參數'!$C$14)*'2_公式與參數'!$C$6*'2_公式與參數'!$C$7/(B9*1000)*100 | D10: 同一個 %N 公式（有扣空白）
A11: 回收率 (%) | B11: =B10/B7*100 | D11: = 實測 %N ÷ 理論 %N × 100
A12: 可接受下限 (%) | B12: 97 | D12: 依方法規定，通常 ≥ 97%。黃色，可改
A13: 判定 | B13: =IF(B11>=B12,"回收率合格：蒸餾／捕氨步驟正常","回收率不足：檢查蒸餾／捕氨步驟")
A15: 回收率不足時可能的原因
A16: • NaOH 加得不夠，溶液沒有變鹼性，NH₄⁺ 沒有變成 NH₃ 蒸出來。
A17: • 蒸氣量不足或蒸餾時間太短，NH₃ 還沒蒸完。
A18: • 冷凝端漏氣，或接收瓶的出口沒有浸在硼酸液面下，NH₃ 逸散掉。
A19: • 回收標準品只走蒸餾＋滴定，不經過消化；所以回收率只能檢查「蒸餾／捕氨／滴定」，不能檢查消化是否完全。

Sheet 6_三聚氰胺
A1: 步驟 5 三聚氰胺 (melamine) 事件重新計算
A2: 凱氏法只量「總氮」，分不出氮來自蛋白質還是三聚氰胺 C₃H₆N₆。三聚氰胺含氮高達約 66.6%，摻一點點就能讓表觀蛋白質大增。
A4: 項目 | B4: 數值 | E4: 公式說明
A5: 三聚氰胺分子量 (g/mol) | B5: =3*'2_公式與參數'!$C$9+6*'2_公式與參數'!$C$8+6*'2_公式與參數'!$C$7 | E5: = 3C + 6H + 6N
A6: 三聚氰胺 %N | B6: =6*'2_公式與參數'!$C$7/B5*100 | E6: = 6 × 14.007 ÷ 分子量 × 100
A7: 每摻 1% (w/w) 虛增的表觀蛋白質（百分點） | B7: =B6/100*'2_公式與參數'!$C$20 | E7: 1 g 三聚氰胺／100 g 樣品帶進 0.666 g 氮；× 乳品係數 6.38 ≈ 4.25 g「表觀蛋白質」
A8: 奶粉基準蛋白質 (%) | B8: ='3_全班盲樣'!K8 | E8: 連到「3_全班盲樣」的班級平均
A10: 摻入比例與表觀蛋白質
A11: 摻入三聚氰胺 (% w/w) | B11: 表觀蛋白質 (%) | C11: 虛增（百分點）
A12: 0 | B12: =$B$8+A12*$B$7 | C12: =A12*$B$7 | E12: 表觀蛋白質 = 基準蛋白質 + 摻入比例 × 每 1% 虛增量。A 欄可以改成別的比例。
A13: 0.2 | B13: =$B$8+A13*$B$7 | C13: =A13*$B$7
A14: 0.4 | B14: =$B$8+A14*$B$7 | C14: =A14*$B$7
A15: 0.6 | B15: =$B$8+A15*$B$7 | C15: =A15*$B$7
A16: 0.8 | B16: =$B$8+A16*$B$7 | C16: =A16*$B$7
A17: 1 | B17: =$B$8+A17*$B$7 | C17: =A17*$B$7
A19: 自訂摻入比例 (% w/w) | B19: 0.5 | E19: 練習題 4：把 B19 改成 0.1，看虛增多少，再和「3_全班盲樣」的 95% CI 半寬（K12）比較。
A20: 虛增的表觀蛋白質（百分點） | B20: =B19*B7
A21: 檢出的表觀蛋白質 (%) | B21: =B8+B20
A41: 看圖：每多摻 0.2% 三聚氰胺，表觀蛋白質就多約 0.85 個百分點。凱氏法和 Dumas 燃燒法都無法分辨，所以後來改用專一的 LC-MS/MS 檢測。

Sheet 7_靈敏度
A1: 步驟 6 靈敏度分析：滴定讀取誤差怎麼傳到蛋白質 %
A2: 如果滴定終點判讀差了 ΔV，對不同樣品的 %N 或蛋白質 % 影響有多大？Δ(蛋白質%) = ΔV × N_HCl × 14.007 ÷ W_mg × 100 × 係數。樣品越輕，同樣的 ΔV 影響越大。
A4: 滴定讀取誤差 ΔV (mL) | B4: 0.05 | C4: 人眼判讀滴定終點的常見誤差量級。練習題 5 改成 0.10。
A6: 管別 | B6: 報告項目 | C6: W (g) | D6: 係數 | E6: Δ%N | F6: 影響（百分點） | G6: 該管測得值 | H6: 相對影響 (%)
A7: milk_powder_blind | B7: 蛋白質% | C7: =INDEX('1_原始數據'!$H$2:$H$1000,MATCH(A7,'1_原始數據'!$C$2:$C$1000,0)) | D7: ='2_公式與參數'!$C$20 | E7: =$B$4*'2_公式與參數'!$C$6*'2_公式與參數'!$C$7/(C7*1000)*100 | F7: =E7*D7 | G7: =INDEX('1_原始數據'!$L$2:$L$1000,MATCH(A7,'1_原始數據'!$C$2:$C$1000,0))*D7 | H7: =F7/G7*100
A8: high_gluten_flour | B8: 蛋白質% | C8: =INDEX('1_原始數據'!$H$2:$H$1000,MATCH(A8,'1_原始數據'!$C$2:$C$1000,0)) | D8: ='2_公式與參數'!$C$19 | E8: =$B$4*'2_公式與參數'!$C$6*'2_公式與參數'!$C$7/(C8*1000)*100 | F8: =E8*D8 | G8: =INDEX('1_原始數據'!$L$2:$L$1000,MATCH(A8,'1_原始數據'!$C$2:$C$1000,0))*D8 | H8: =F8/G8*100
A9: ammonium_sulfate_std | B9: %N | C9: =INDEX('1_原始數據'!$H$2:$H$1000,MATCH(A9,'1_原始數據'!$C$2:$C$1000,0)) | D9: =1 | E9: =$B$4*'2_公式與參數'!$C$6*'2_公式與參數'!$C$7/(C9*1000)*100 | F9: =E9*D9 | G9: =INDEX('1_原始數據'!$L$2:$L$1000,MATCH(A9,'1_原始數據'!$C$2:$C$1000,0))*D9 | H9: =F9/G9*100
A11: W：INDEX/MATCH 取第一筆（盲樣取 G1 那一管，和 Colab 一樣）。
A12: 係數：盲樣用乳品 6.38、高筋用小麥 5.7；硫酸銨直接報 %N，所以係數當作 1。
A13: 影響 = Δ%N × 係數，單位是「百分點」。相對影響 = 影響 ÷ 該管測得值 × 100（Colab 沒有算這一欄，給你多一個角度）。
A14: 結論：樣品重 0.05 g 的硫酸銨，同樣 0.05 mL 誤差的影響是 0.5 g 奶粉的 10 倍（以 %N 計）。所以 QC 標準品的秤重與終點判讀要格外小心。

Sheet 練習題
B1: 練習題（寫在黃色格子裡，交報告時一起附上）
B3: 問題 1：如果忘記扣除試劑空白（直接用 V_s 算 %N），全脂奶粉盲樣班級平均的蛋白質 % 會被高估多少（百分點與相對 %）？
B4: 提示：先記下「3_全班盲樣」K8 的值；到「2_公式與參數」把 C13 改成 0，再讀一次 K8，兩者相減。做完記得把 C13 改回 1。
B7: 問題 2：如果某組把高筋麵粉的 %N 誤用一般係數 6.25（而非小麥係數 5.7），算出的蛋白質 % 與相對誤差是多少？跟約 9.6% 是否一致？
B8: 提示：看「4_麵粉與係數」B12 與 B15。想一想：為什麼低筋麵粉的相對誤差（C15）一模一樣？
B11: 問題 3：蒸餾回收標準品的回收率如果只有 90%，該懷疑哪個步驟出了問題（消化、蒸餾、還是滴定）？為什麼？
B12: 提示：看「5_回收率」第 16–19 列。注意：硫酸銨已經是 NH₄⁺，不需要消化。
B15: 問題 4：如果某奶粉只摻入 0.1% 三聚氰胺，用乳品係數 6.38 換算，表觀蛋白質會虛增多少百分點？這樣的虛增量容不容易被發現？
B16: 提示：把「6_三聚氰胺」B19 改成 0.1，讀 B20；再和「3_全班盲樣」的 95% CI 半寬（K12）與 SD（K9）比較。
B19: 問題 5：如果你們這組的滴定讀取誤差其實是 0.10 mL（而不是 0.05 mL），對全脂奶粉與高筋麵粉的蛋白質 % 分別影響多少？誰受影響比較大？為什麼？
B20: 提示：把「7_靈敏度」B4 改成 0.10，比較 F7 與 F8；再看 C 欄的樣品重與 D 欄的係數。
