Workbook

Sheet 0_說明
B1: EX06｜W6 粗脂肪（Soxhlet 與酸水解）
B2: 食品分析實驗・入門數據分析（Excel 版）。不用寫程式；同一份數據在 Colab 筆記本做進階分析，答案應該一致。
B4: 學習目標
B5: • 用秤重公式算粗脂肪 %，分清楚「以乾樣品計（乾基）」與「以濕樣品計（濕基）」，並做乾基 → 濕基換算。
B6: • 用 STDEV.S 算三重複的 RSD%，判斷精密度。
B7: • 用已知脂肪對照品算回收率，用 95–105% 判斷操作是否合格；理解溶劑空白的意義。
B8: • 用全班盲樣（全脂奶粉）看到直接 Soxhlet 相對 Röse–Gottlieb 偏低的系統誤差（bias），並說明為什麼要先酸水解。
B9: • 用 Pearson 方塊算牛奶標準化所需的鮮奶油與脫脂乳重量，並驗算質量平衡。
B11: 顏色代表什麼
C12: 黃色：輸入或貼上數據的地方
C13: 綠色：公式，會自動計算，不要改
C14: 橘色：重點結果，寫報告時用
B16: 操作步驟
B17: 1. 看「1_原始數據」：一列是一次秤重或一個結果（item 說明它是什麼）。
B18: 2. 看「2_粗脂肪」：各組的空瓶、樣品、瓶+脂肪 → 脂肪重 → 粗脂肪 %（乾基）。
B19: 3. 看「3_濕基換算」：用 W2 的水分換成濕基，看長條圖。
B20: 4. 看「4_精密度與回收率」：三重複 RSD、已知對照品回收率與合格判定、溶劑空白。
B21: 5. 看「5_盲樣偏差」：各組三重複 → 組平均 → 班級平均，和 Röse–Gottlieb、標示值比較。
B22: 6. 看「6_Pearson方塊」：講義範例，並在 D 欄做自己的題目。
B23: 7. 完成「練習題」。
B24: 8. 換成班級數據：把共用 Google Sheet 的數據貼到「1_原始數據」A2 起；組別不同就改「2_粗脂肪」與「5_盲樣偏差」B 欄。
B26: 對答案：用內建範例數據時，你的結果應該等於
B27: 項目 | C27: 本檔計算值 | D27: Colab 筆記本的值 | E27: 一致？
B28: 第 1 組粗脂肪 %（乾基） | C28: ='2_粗脂肪'!H7 | D28: 35.751819 | E28: =IF(ABS(C28-D28)<=0.003575182891673472,"✔ 一致","✘ 不一致（換成班級數據後本來就會不同）")
B29: 第 1 組粗脂肪 %（濕基） | C29: ='3_濕基換算'!E8 | D29: 35.036783 | E29: =IF(ABS(C29-D29)<=0.003503679253840003,"✔ 一致","✘ 不一致（換成班級數據後本來就會不同）")
B30: 三重複 RSD (%) | C30: ='4_精密度與回收率'!C10 | D30: 0.72247219 | E30: =IF(ABS(C30-D30)<=7.22482194762752e-05,"✔ 一致","✘ 不一致（換成班級數據後本來就會不同）")
B31: 已知對照品回收率 (%) | C31: ='4_精密度與回收率'!C16 | D31: 97.35 | E31: =IF(ABS(C31-D31)<=0.009735001,"✔ 一致","✘ 不一致（換成班級數據後本來就會不同）")
B32: 盲樣班級平均 (%) | C32: ='5_盲樣偏差'!K6 | D32: 21.28 | E32: =IF(ABS(C32-D32)<=0.002128001,"✔ 一致","✘ 不一致（換成班級數據後本來就會不同）")
B33: 盲樣組間 SD (%) | C33: ='5_盲樣偏差'!K7 | D33: 0.42614552 | E33: =IF(ABS(C33-D33)<=4.261555150532492e-05,"✔ 一致","✘ 不一致（換成班級數據後本來就會不同）")
B34: bias vs RG（百分點） | C34: ='5_盲樣偏差'!K10 | D34: -4.42 | E34: =IF(ABS(C34-D34)<=0.00044200099999999986,"✔ 一致","✘ 不一致（換成班級數據後本來就會不同）")
B35: Pearson 方塊：鮮奶油 (kg) | C35: ='6_Pearson方塊'!C12 | D35: 8.7743733 | E35: =IF(ABS(C35-D35)<=0.0008774383259052926,"✔ 一致","✘ 不一致（換成班級數據後本來就會不同）")
B36: 「Colab 筆記本的值」是用內建模擬數據算出的答案；換成全班數據後，這一欄就不再適用。
B38: 相關連結
B39: 本週實驗投影片 | C39: https://tai-shengyeh.github.io/food-analysis-lab/labs/w06_fat/index.html
B40: 進階：Colab 筆記本（Python） | C40: https://colab.research.google.com/github/Tai-ShengYeh/food-analysis-lab/blob/main/notebooks/NB06_fat_soxhlet.ipynb
B41: 數據分析工具指南（Excel／Orange／Colab） | C41: https://tai-shengyeh.github.io/food-analysis-lab/tools.html
B43: 小提醒
B44: • 本週的酸水解（美乃滋）由助教示範，沒有數據要算；Colab 筆記本也一樣。盲樣偏低就是「沒有先水解」的後果。
B45: • 「5_盲樣偏差」的單樣本 t 檢定是本檔額外加的，Colab 筆記本沒有做；它只是幫你確認偏差不是隨機誤差。
B46: • Google 試算表也能開這個檔（檔案 → 匯入），公式都一樣能用。
...

Sheet 1_原始數據
A1: group | B1: student | C1: item | D1: rep | E1: value | F1: unit | G1: temp_C | H1: note | J1: 這張工作表怎麼用
A2: 1 | B2: G1 | C2: chips_flask_empty_g | D2: 1 | E2: 132.4056 | F2: g | H2: 萃取瓶(含止爆石)已烘至恆重 | J2: 本週 item：chips_flask_empty_g＝空萃取瓶（已恆重）；chips_sample_dry_g＝乾燥洋芋片樣品重；chips_flask_fat_g＝萃取、烘乾至恆重後的瓶＋脂肪；fat_replicate_demo＝TA 示範三重複 (%)；known_fat_reference_measured＝已知脂肪對照品測值 (%)；solvent_blank_residue_g＝溶劑空白殘留 (g)；milk_blind_fat_pct＝全脂奶粉盲樣直接 Soxhlet (%)；milk_blind_RG_reference＝Röse–Gottlieb 參考值；milk_blind_label＝標示值；chips_moisture_pct_wet＝W2 測的洋芋片水分（濕基 %）。
A3: 1 | B3: G1 | C3: chips_sample_dry_g | D3: 1 | E3: 2.9688 | F3: g | H3: 已乾燥、磨細的洋芋片樣品(沿用 W2 乾燥樣品) | J3: group = 0 代表 TA 或全班共用的數據。本週沒有額外的計算欄，計算都在後面的工作表。
A4: 1 | B4: G1 | C4: chips_flask_fat_g | D4: 1 | E4: 133.467 | F4: g | H4: 萃取＋烘乾至恆重後，瓶+脂肪 | J4: 黃色欄位＝原始數據。換成全班數據時：從共用 Google Sheet 複製，貼到 A2（欄位順序必須一樣），舊資料多出來的列要整列刪除。
A5: 2 | B5: G2 | C5: chips_flask_empty_g | D5: 1 | E5: 132.4069 | F5: g | H5: 萃取瓶(含止爆石)已烘至恆重 | J5: 綠色欄位＝公式，會自動算到第 1000 列，不要手動修改。
A6: 2 | B6: G2 | C6: chips_sample_dry_g | D6: 1 | E6: 2.9415 | F6: g | H6: 已乾燥、磨細的洋芋片樣品(沿用 W2 乾燥樣品)
A7: 2 | B7: G2 | C7: chips_flask_fat_g | D7: 1 | E7: 133.3981 | F7: g | H7: 萃取＋烘乾至恆重後，瓶+脂肪
A8: 3 | B8: G3 | C8: chips_flask_empty_g | D8: 1 | E8: 132.4053 | F8: g | H8: 萃取瓶(含止爆石)已烘至恆重
A9: 3 | B9: G3 | C9: chips_sample_dry_g | D9: 1 | E9: 2.9905 | F9: g | H9: 已乾燥、磨細的洋芋片樣品(沿用 W2 乾燥樣品)
A10: 3 | B10: G3 | C10: chips_flask_fat_g | D10: 1 | E10: 133.4515 | F10: g | H10: 萃取＋烘乾至恆重後，瓶+脂肪
A11: 4 | B11: G4 | C11: chips_flask_empty_g | D11: 1 | E11: 132.4033 | F11: g | H11: 萃取瓶(含止爆石)已烘至恆重
A12: 4 | B12: G4 | C12: chips_sample_dry_g | D12: 1 | E12: 3.0264 | F12: g | H12: 已乾燥、磨細的洋芋片樣品(沿用 W2 乾燥樣品)
A13: 4 | B13: G4 | C13: chips_flask_fat_g | D13: 1 | E13: 133.4861 | F13: g | H13: 萃取＋烘乾至恆重後，瓶+脂肪
A14: 5 | B14: G5 | C14: chips_flask_empty_g | D14: 1 | E14: 132.4051 | F14: g | H14: 萃取瓶(含止爆石)已烘至恆重
A15: 5 | B15: G5 | C15: chips_sample_dry_g | D15: 1 | E15: 3.0338 | F15: g | H15: 已乾燥、磨細的洋芋片樣品(沿用 W2 乾燥樣品)
A16: 5 | B16: G5 | C16: chips_flask_fat_g | D16: 1 | E16: 133.4811 | F16: g | H16: 萃取＋烘乾至恆重後，瓶+脂肪
A17: 0 | B17: TA_demo | C17: fat_replicate_demo | D17: 1 | E17: 34.8 | F17: % | H17: 示範同一樣品三重複，用於教你算 RSD，非全班分組數據
... A39: 0 | B39: shared | C39: chips_moisture_pct_wet | D39: 1 | E39: 2 | F39: % | H39: 取自 W2 該批洋芋片的濕基水分測定

Sheet 2_粗脂肪
B1: 步驟 1 洋芋片粗脂肪 %（以乾樣品計）
B2: 粗脂肪 % = [W(瓶+脂肪) − W(空瓶)] ÷ W(樣品) × 100。樣品秤入套管前已經乾燥過，所以分母是「乾樣品」，得到的是乾基的 %。兩個瓶重都必須是恆重（連續兩次秤重穩定）。
B4: 溶劑空白殘留 (g) | E4: =IF(COUNTIFS('1_原始數據'!$C$2:$C$1000,"solvent_blank_residue_g")=0,"",AVERAGEIFS('1_原始數據'!$E$2:$E$1000,'1_原始數據'!$C$2:$C$1000,"solvent_blank_residue_g")) | K4: 只蒸乾溶劑、不放樣品的殘留重，理論上應趨近於 0。I 欄示範把它從脂肪重扣掉（練習題 1 用）。
B6: 組別 | C6: 學生 | D6: 空瓶 (g) | E6: 樣品乾重 (g) | F6: 瓶+脂肪 (g) | G6: 脂肪重 (g) | H6: 粗脂肪 % (乾基) | I6: 扣除溶劑空白後 粗脂肪 % (乾基)
B7: 1 | C7: =IF(B7="","",IFERROR(INDEX('1_原始數據'!$B$2:$B$1000,MATCH(B7,'1_原始數據'!$A$2:$A$1000,0)),"")) | D7: =IF(B7="","",IF(COUNTIFS('1_原始數據'!$A$2:$A$1000,B7,'1_原始數據'!$C$2:$C$1000,"chips_flask_empty_g")=0,"",AVERAGEIFS('1_原始數據'!$E$2:$E$1000,'1_原始數據'!$A$2:$A$1000,B7,'1_原始數據'!$C$2:$C$1000,"chips_flask_empty_g"))) | E7: =IF(B7="","",IF(COUNTIFS('1_原始數據'!$A$2:$A$1000,B7,'1_原始數據'!$C$2:$C$1000,"chips_sample_dry_g")=0,"",AVERAGEIFS('1_原始數據'!$E$2:$E$1000,'1_原始數據'!$A$2:$A$1000,B7,'1_原始數據'!$C$2:$C$1000,"chips_sample_dry_g"))) | F7: =IF(B7="","",IF(COUNTIFS('1_原始數據'!$A$2:$A$1000,B7,'1_原始數據'!$C$2:$C$1000,"chips_flask_fat_g")=0,"",AVERAGEIFS('1_原始數據'!$E$2:$E$1000,'1_原始數據'!$A$2:$A$1000,B7,'1_原始數據'!$C$2:$C$1000,"chips_flask_fat_g"))) | G7: =IF(OR(D7="",F7=""),"",F7-D7) | H7: =IF(OR(G7="",E7=""),"",G7/E7*100) | I7: =IF(H7="","",(G7-$E$4)/E7*100) | K7: D–F 欄用 AVERAGEIFS（依條件平均）從原始數據抓「這一組、這個 item」的秤重。每組只秤一次，所以平均就是那個值。C 欄用 INDEX/MATCH 找這一組的學生代號。
B8: 2 | C8: =IF(B8="","",IFERROR(INDEX('1_原始數據'!$B$2:$B$1000,MATCH(B8,'1_原始數據'!$A$2:$A$1000,0)),"")) | D8: =IF(B8="","",IF(COUNTIFS('1_原始數據'!$A$2:$A$1000,B8,'1_原始數據'!$C$2:$C$1000,"chips_flask_empty_g")=0,"",AVERAGEIFS('1_原始數據'!$E$2:$E$1000,'1_原始數據'!$A$2:$A$1000,B8,'1_原始數據'!$C$2:$C$1000,"chips_flask_empty_g"))) | E8: =IF(B8="","",IF(COUNTIFS('1_原始數據'!$A$2:$A$1000,B8,'1_原始數據'!$C$2:$C$1000,"chips_sample_dry_g")=0,"",AVERAGEIFS('1_原始數據'!$E$2:$E$1000,'1_原始數據'!$A$2:$A$1000,B8,'1_原始數據'!$C$2:$C$1000,"chips_sample_dry_g"))) | F8: =IF(B8="","",IF(COUNTIFS('1_原始數據'!$A$2:$A$1000,B8,'1_原始數據'!$C$2:$C$1000,"chips_flask_fat_g")=0,"",AVERAGEIFS('1_原始數據'!$E$2:$E$1000,'1_原始數據'!$A$2:$A$1000,B8,'1_原始數據'!$C$2:$C$1000,"chips_flask_fat_g"))) | G8: =IF(OR(D8="",F8=""),"",F8-D8) | H8: =IF(OR(G8="",E8=""),"",G8/E8*100) | I8: =IF(H8="","",(G8-$E$4)/E8*100)
B9: 3 | C9: =IF(B9="","",IFERROR(INDEX('1_原始數據'!$B$2:$B$1000,MATCH(B9,'1_原始數據'!$A$2:$A$1000,0)),"")) | D9: =IF(B9="","",IF(COUNTIFS('1_原始數據'!$A$2:$A$1000,B9,'1_原始數據'!$C$2:$C$1000,"chips_flask_empty_g")=0,"",AVERAGEIFS('1_原始數據'!$E$2:$E$1000,'1_原始數據'!$A$2:$A$1000,B9,'1_原始數據'!$C$2:$C$1000,"chips_flask_empty_g"))) | E9: =IF(B9="","",IF(COUNTIFS('1_原始數據'!$A$2:$A$1000,B9,'1_原始數據'!$C$2:$C$1000,"chips_sample_dry_g")=0,"",AVERAGEIFS('1_原始數據'!$E$2:$E$1000,'1_原始數據'!$A$2:$A$1000,B9,'1_原始數據'!$C$2:$C$1000,"chips_sample_dry_g"))) | F9: =IF(B9="","",IF(COUNTIFS('1_原始數據'!$A$2:$A$1000,B9,'1_原始數據'!$C$2:$C$1000,"chips_flask_fat_g")=0,"",AVERAGEIFS('1_原始數據'!$E$2:$E$1000,'1_原始數據'!$A$2:$A$1000,B9,'1_原始數據'!$C$2:$C$1000,"chips_flask_fat_g"))) | G9: =IF(OR(D9="",F9=""),"",F9-D9) | H9: =IF(OR(G9="",E9=""),"",G9/E9*100) | I9: =IF(H9="","",(G9-$E$4)/E9*100)
B10: 4 | C10: =IF(B10="","",IFERROR(INDEX('1_原始數據'!$B$2:$B$1000,MATCH(B10,'1_原始數據'!$A$2:$A$1000,0)),"")) | D10: =IF(B10="","",IF(COUNTIFS('1_原始數據'!$A$2:$A$1000,B10,'1_原始數據'!$C$2:$C$1000,"chips_flask_empty_g")=0,"",AVERAGEIFS('1_原始數據'!$E$2:$E$1000,'1_原始數據'!$A$2:$A$1000,B10,'1_原始數據'!$C$2:$C$1000,"chips_flask_empty_g"))) | E10: =IF(B10="","",IF(COUNTIFS('1_原始數據'!$A$2:$A$1000,B10,'1_原始數據'!$C$2:$C$1000,"chips_sample_dry_g")=0,"",AVERAGEIFS('1_原始數據'!$E$2:$E$1000,'1_原始數據'!$A$2:$A$1000,B10,'1_原始數據'!$C$2:$C$1000,"chips_sample_dry_g"))) | F10: =IF(B10="","",IF(COUNTIFS('1_原始數據'!$A$2:$A$1000,B10,'1_原始數據'!$C$2:$C$1000,"chips_flask_fat_g")=0,"",AVERAGEIFS('1_原始數據'!$E$2:$E$1000,'1_原始數據'!$A$2:$A$1000,B10,'1_原始數據'!$C$2:$C$1000,"chips_flask_fat_g"))) | G10: =IF(OR(D10="",F10=""),"",F10-D10) | H10: =IF(OR(G10="",E10=""),"",G10/E10*100) | I10: =IF(H10="","",(G10-$E$4)/E10*100) | K10: G＝脂肪重＝瓶+脂肪 − 空瓶；H＝G ÷ 樣品乾重 × 100。組數比較多時在 B 欄空白黃色格補上組別。
B11: 5 | C11: =IF(B11="","",IFERROR(INDEX('1_原始數據'!$B$2:$B$1000,MATCH(B11,'1_原始數據'!$A$2:$A$1000,0)),"")) | D11: =IF(B11="","",IF(COUNTIFS('1_原始數據'!$A$2:$A$1000,B11,'1_原始數據'!$C$2:$C$1000,"chips_flask_empty_g")=0,"",AVERAGEIFS('1_原始數據'!$E$2:$E$1000,'1_原始數據'!$A$2:$A$1000,B11,'1_原始數據'!$C$2:$C$1000,"chips_flask_empty_g"))) | E11: =IF(B11="","",IF(COUNTIFS('1_原始數據'!$A$2:$A$1000,B11,'1_原始數據'!$C$2:$C$1000,"chips_sample_dry_g")=0,"",AVERAGEIFS('1_原始數據'!$E$2:$E$1000,'1_原始數據'!$A$2:$A$1000,B11,'1_原始數據'!$C$2:$C$1000,"chips_sample_dry_g"))) | F11: =IF(B11="","",IF(COUNTIFS('1_原始數據'!$A$2:$A$1000,B11,'1_原始數據'!$C$2:$C$1000,"chips_flask_fat_g")=0,"",AVERAGEIFS('1_原始數據'!$E$2:$E$1000,'1_原始數據'!$A$2:$A$1000,B11,'1_原始數據'!$C$2:$C$1000,"chips_flask_fat_g"))) | G11: =IF(OR(D11="",F11=""),"",F11-D11) | H11: =IF(OR(G11="",E11=""),"",G11/E11*100) | I11: =IF(H11="","",(G11-$E$4)/E11*100)
C12: =IF(B12="","",IFERROR(INDEX('1_原始數據'!$B$2:$B$1000,MATCH(B12,'1_原始數據'!$A$2:$A$1000,0)),"")) | D12: =IF(B12="","",IF(COUNTIFS('1_原始數據'!$A$2:$A$1000,B12,'1_原始數據'!$C$2:$C$1000,"chips_flask_empty_g")=0,"",AVERAGEIFS('1_原始數據'!$E$2:$E$1000,'1_原始數據'!$A$2:$A$1000,B12,'1_原始數據'!$C$2:$C$1000,"chips_flask_empty_g"))) | E12: =IF(B12="","",IF(COUNTIFS('1_原始數據'!$A$2:$A$1000,B12,'1_原始數據'!$C$2:$C$1000,"chips_sample_dry_g")=0,"",AVERAGEIFS('1_原始數據'!$E$2:$E$1000,'1_原始數據'!$A$2:$A$1000,B12,'1_原始數據'!$C$2:$C$1000,"chips_sample_dry_g"))) | F12: =IF(B12="","",IF(COUNTIFS('1_原始數據'!$A$2:$A$1000,B12,'1_原始數據'!$C$2:$C$1000,"chips_flask_fat_g")=0,"",AVERAGEIFS('1_原始數據'!$E$2:$E$1000,'1_原始數據'!$A$2:$A$1000,B12,'1_原始數據'!$C$2:$C$1000,"chips_flask_fat_g"))) | G12: =IF(OR(D12="",F12=""),"",F12-D12) | H12: =IF(OR(G12="",E12=""),"",G12/E12*100) | I12: =IF(H12="","",(G12-$E$4)/E12*100)
C13: =IF(B13="","",IFERROR(INDEX('1_原始數據'!$B$2:$B$1000,MATCH(B13,'1_原始數據'!$A$2:$A$1000,0)),"")) | D13: =IF(B13="","",IF(COUNTIFS('1_原始數據'!$A$2:$A$1000,B13,'1_原始數據'!$C$2:$C$1000,"chips_flask_empty_g")=0,"",AVERAGEIFS('1_原始數據'!$E$2:$E$1000,'1_原始數據'!$A$2:$A$1000,B13,'1_原始數據'!$C$2:$C$1000,"chips_flask_empty_g"))) | E13: =IF(B13="","",IF(COUNTIFS('1_原始數據'!$A$2:$A$1000,B13,'1_原始數據'!$C$2:$C$1000,"chips_sample_dry_g")=0,"",AVERAGEIFS('1_原始數據'!$E$2:$E$1000,'1_原始數據'!$A$2:$A$1000,B13,'1_原始數據'!$C$2:$C$1000,"chips_sample_dry_g"))) | F13: =IF(B13="","",IF(COUNTIFS('1_原始數據'!$A$2:$A$1000,B13,'1_原始數據'!$C$2:$C$1000,"chips_flask_fat_g")=0,"",AVERAGEIFS('1_原始數據'!$E$2:$E$1000,'1_原始數據'!$A$2:$A$1000,B13,'1_原始數據'!$C$2:$C$1000,"chips_flask_fat_g"))) | G13: =IF(OR(D13="",F13=""),"",F13-D13) | H13: =IF(OR(G13="",E13=""),"",G13/E13*100) | I13: =IF(H13="","",(G13-$E$4)/E13*100)
C14: =IF(B14="","",IFERROR(INDEX('1_原始數據'!$B$2:$B$1000,MATCH(B14,'1_原始數據'!$A$2:$A$1000,0)),"")) | D14: =IF(B14="","",IF(COUNTIFS('1_原始數據'!$A$2:$A$1000,B14,'1_原始數據'!$C$2:$C$1000,"chips_flask_empty_g")=0,"",AVERAGEIFS('1_原始數據'!$E$2:$E$1000,'1_原始數據'!$A$2:$A$1000,B14,'1_原始數據'!$C$2:$C$1000,"chips_flask_empty_g"))) | E14: =IF(B14="","",IF(COUNTIFS('1_原始數據'!$A$2:$A$1000,B14,'1_原始數據'!$C$2:$C$1000,"chips_sample_dry_g")=0,"",AVERAGEIFS('1_原始數據'!$E$2:$E$1000,'1_原始數據'!$A$2:$A$1000,B14,'1_原始數據'!$C$2:$C$1000,"chips_sample_dry_g"))) | F14: =IF(B14="","",IF(COUNTIFS('1_原始數據'!$A$2:$A$1000,B14,'1_原始數據'!$C$2:$C$1000,"chips_flask_fat_g")=0,"",AVERAGEIFS('1_原始數據'!$E$2:$E$1000,'1_原始數據'!$A$2:$A$1000,B14,'1_原始數據'!$C$2:$C$1000,"chips_flask_fat_g"))) | G14: =IF(OR(D14="",F14=""),"",F14-D14) | H14: =IF(OR(G14="",E14=""),"",G14/E14*100) | I14: =IF(H14="","",(G14-$E$4)/E14*100)
B16: 全班（各組一個值）
B17: 組數 | E17: =COUNT(H7:H14) | K17: COUNT：數有幾個數字。
B18: 平均 (%) | E18: =AVERAGE(H7:H14) | K18: 各組粗脂肪 %（乾基）的平均。
B19: SD (%) | E19: =_xlfn.STDEV.S(H7:H14) | K19: STDEV.S：樣本標準差（除以 n−1），代表組與組之間差多少。
B20: RSD (%) | E20: =E19/E18*100 | K20: RSD = SD ÷ 平均 × 100。

Sheet 3_濕基換算
B1: 步驟 2 乾基換算回濕基
B2: 樣品是先乾燥才萃取的，所以步驟 1 的 % 是「每 100 g 乾樣品」的脂肪。要換回「每 100 g 原本（濕）樣品」，要乘上乾物質的比例（1 − 水分%）。水分用 W2 對同一批洋芋片的濕基測定值。
B4: 水分 %（濕基，取自 W2） | E4: =IF(COUNTIFS('1_原始數據'!$C$2:$C$1000,"chips_moisture_pct_wet")=0,"",AVERAGEIFS('1_原始數據'!$E$2:$E$1000,'1_原始數據'!$C$2:$C$1000,"chips_moisture_pct_wet")) | H4: 從原始數據 item = chips_moisture_pct_wet 那一列抓。
B5: 乾物質比例 = 1 − 水分% ÷ 100 | E5: =1-E4/100 | H5: 公式：粗脂肪 %(濕基) = 粗脂肪 %(乾基) × (1 − 水分 %)。水分越高，濕基的脂肪 % 越低。
B7: 組別 | C7: 學生 | D7: 粗脂肪 % (乾基) | E7: 粗脂肪 % (濕基) | F7: 差 (百分點)
B8: =IF('2_粗脂肪'!B7="","",'2_粗脂肪'!B7) | C8: ='2_粗脂肪'!C7 | D8: ='2_粗脂肪'!H7 | E8: =IF(D8="","",D8*$E$5) | F8: =IF(D8="","",D8-E8) | H8: B–D 欄直接連到「2_粗脂肪」。E 欄 = D × 乾物質比例（$E$5 的 $ 代表往下複製時固定參照 E5）。
B9: =IF('2_粗脂肪'!B8="","",'2_粗脂肪'!B8) | C9: ='2_粗脂肪'!C8 | D9: ='2_粗脂肪'!H8 | E9: =IF(D9="","",D9*$E$5) | F9: =IF(D9="","",D9-E9)
B10: =IF('2_粗脂肪'!B9="","",'2_粗脂肪'!B9) | C10: ='2_粗脂肪'!C9 | D10: ='2_粗脂肪'!H9 | E10: =IF(D10="","",D10*$E$5) | F10: =IF(D10="","",D10-E10)
B11: =IF('2_粗脂肪'!B10="","",'2_粗脂肪'!B10) | C11: ='2_粗脂肪'!C10 | D11: ='2_粗脂肪'!H10 | E11: =IF(D11="","",D11*$E$5) | F11: =IF(D11="","",D11-E11)
B12: =IF('2_粗脂肪'!B11="","",'2_粗脂肪'!B11) | C12: ='2_粗脂肪'!C11 | D12: ='2_粗脂肪'!H11 | E12: =IF(D12="","",D12*$E$5) | F12: =IF(D12="","",D12-E12)
B13: =IF('2_粗脂肪'!B12="","",'2_粗脂肪'!B12) | C13: ='2_粗脂肪'!C12 | D13: ='2_粗脂肪'!H12 | E13: =IF(D13="","",D13*$E$5) | F13: =IF(D13="","",D13-E13)
B14: =IF('2_粗脂肪'!B13="","",'2_粗脂肪'!B13) | C14: ='2_粗脂肪'!C13 | D14: ='2_粗脂肪'!H13 | E14: =IF(D14="","",D14*$E$5) | F14: =IF(D14="","",D14-E14)
B15: =IF('2_粗脂肪'!B14="","",'2_粗脂肪'!B14) | C15: ='2_粗脂肪'!C14 | D15: ='2_粗脂肪'!H14 | E15: =IF(D15="","",D15*$E$5) | F15: =IF(D15="","",D15-E15)
B17: 全班平均 | D17: =AVERAGE(D8:D15) | E17: =AVERAGE(E8:E15) | F17: =D17-E17 | H17: 報告要寫清楚是哪一種基準：「粗脂肪 35.1%（濕基）」。洋芋片水分只有 2%，兩者差不到 1 個百分點；水分高的食品差很多。
B37: 注意 y 軸不一定從 0 開始，差距看起來會被放大，要看數字。組數不同時，在圖上按右鍵 →「選取資料」調整範圍。

Sheet 4_精密度與回收率
B1: 步驟 3 精密度（RSD）與準確度（回收率）
B3: 3-1 精密度：同一樣品三重複（TA 示範）
B4: 重複 | C4: 粗脂肪 (%)
B5: 第 1 次 | C5: =IF(COUNTIFS('1_原始數據'!$C$2:$C$1000,"fat_replicate_demo",'1_原始數據'!$D$2:$D$1000,1)=0,"",AVERAGEIFS('1_原始數據'!$E$2:$E$1000,'1_原始數據'!$C$2:$C$1000,"fat_replicate_demo",'1_原始數據'!$D$2:$D$1000,1)) | E5: 完整 Soxhlet 萃取要好幾個小時，本週每組只做 1 次，所以用 TA 示範的三重複學 RSD。
B6: 第 2 次 | C6: =IF(COUNTIFS('1_原始數據'!$C$2:$C$1000,"fat_replicate_demo",'1_原始數據'!$D$2:$D$1000,2)=0,"",AVERAGEIFS('1_原始數據'!$E$2:$E$1000,'1_原始數據'!$C$2:$C$1000,"fat_replicate_demo",'1_原始數據'!$D$2:$D$1000,2))
B7: 第 3 次 | C7: =IF(COUNTIFS('1_原始數據'!$C$2:$C$1000,"fat_replicate_demo",'1_原始數據'!$D$2:$D$1000,3)=0,"",AVERAGEIFS('1_原始數據'!$E$2:$E$1000,'1_原始數據'!$C$2:$C$1000,"fat_replicate_demo",'1_原始數據'!$D$2:$D$1000,3))
B8: 平均 (%) | C8: =AVERAGE(C5:C7) | E8: AVERAGE：平均值。
B9: SD (%) | C9: =_xlfn.STDEV.S(C5:C7) | E9: STDEV.S：樣本標準差，除以 n−1（n = 3）。
B10: RSD (%) | C10: =C9/C8*100 | E10: RSD = SD ÷ 平均 × 100。RSD 越小，重複性（精密度）越好。
B11: 精密度好不代表準確——請對照「5_盲樣偏差」：三重複很穩定，平均卻可能整個偏低。
B13: 3-2 準確度：已知脂肪對照品的回收率
B14: 證書標示值 (%) | C14: 20 | E14: 證書值寫在原始數據 note 欄（20.0%），請確認和這格一樣。
B15: Soxhlet 測得 (%) | C15: =IF(COUNTIFS('1_原始數據'!$C$2:$C$1000,"known_fat_reference_measured")=0,"",AVERAGEIFS('1_原始數據'!$E$2:$E$1000,'1_原始數據'!$C$2:$C$1000,"known_fat_reference_measured"))
B16: 回收率 (%) = 測得 ÷ 證書值 × 100 | C16: =C15/C14*100 | E16: 回收率回答「這個方法、今天的操作，能不能把已知量的脂肪完整測回來」。
B17: 合格範圍下限 (%) | C17: 95
B18: 合格範圍上限 (%) | C18: 105
B19: 判定 | C19: =IF(AND(C16>=C17,C16<=C18),"合格：操作正常","不合格：檢討操作條件") | E19: IF(AND(條件1, 條件2), 是, 否)：兩個條件都成立才算合格。實驗室 SOP 常用 95–105%。
B21: 3-3 溶劑空白
B22: 溶劑空白殘留 (g) | C22: ='2_粗脂肪'!E4 | E22: 空白偏高代表溶劑或玻璃器皿有污染，會讓所有樣品的脂肪 % 虛高，要先扣除。
B23: 相當於第 1 組脂肪 % 的多少百分點 | C23: ='2_粗脂肪'!H7-'2_粗脂肪'!I7 | E23: = 殘留 ÷ 樣品乾重 × 100（就是「2_粗脂肪」H 欄減 I 欄）。練習題 1 用。

Sheet 5_盲樣偏差
B1: 步驟 4 盲樣：全脂奶粉直接 Soxhlet 為什麼偏低？
B2: 5 組各對同一份全脂奶粉盲樣做直接 Soxhlet（未水解），每組三重複。先算各組三重複平均（組是量測的單位），再用 5 組平均算班級平均與組間 SD（n = 5），和 Röse–Gottlieb 參考法、標示值比較。
O3: 圖用輔助數據
B4: 組別 | C4: 學生 | D4: 第 1 次 (%) | E4: 第 2 次 (%) | F4: 第 3 次 (%) | G4: 組平均 (%) | H4: 組內 SD (%) | J4: 4-1 班級結果與偏差 | O4: 方法 | P4: 脂肪 % | Q4: 誤差線 (SD)
B5: 1 | C5: =IF(B5="","",IFERROR(INDEX('1_原始數據'!$B$2:$B$1000,MATCH(B5,'1_原始數據'!$A$2:$A$1000,0)),"")) | D5: =IF(B5="","",IF(COUNTIFS('1_原始數據'!$A$2:$A$1000,B5,'1_原始數據'!$C$2:$C$1000,"milk_blind_fat_pct",'1_原始數據'!$D$2:$D$1000,1)=0,"",SUMIFS('1_原始數據'!$E$2:$E$1000,'1_原始數據'!$A$2:$A$1000,B5,'1_原始數據'!$C$2:$C$1000,"milk_blind_fat_pct",'1_原始數據'!$D$2:$D$1000,1))) | E5: =IF(B5="","",IF(COUNTIFS('1_原始數據'!$A$2:$A$1000,B5,'1_原始數據'!$C$2:$C$1000,"milk_blind_fat_pct",'1_原始數據'!$D$2:$D$1000,2)=0,"",SUMIFS('1_原始數據'!$E$2:$E$1000,'1_原始數據'!$A$2:$A$1000,B5,'1_原始數據'!$C$2:$C$1000,"milk_blind_fat_pct",'1_原始數據'!$D$2:$D$1000,2))) | F5: =IF(B5="","",IF(COUNTIFS('1_原始數據'!$A$2:$A$1000,B5,'1_原始數據'!$C$2:$C$1000,"milk_blind_fat_pct",'1_原始數據'!$D$2:$D$1000,3)=0,"",SUMIFS('1_原始數據'!$E$2:$E$1000,'1_原始數據'!$A$2:$A$1000,B5,'1_原始數據'!$C$2:$C$1000,"milk_blind_fat_pct",'1_原始數據'!$D$2:$D$1000,3))) | G5: =IF(COUNT(D5:F5)=0,"",AVERAGE(D5:F5)) | H5: =IF(COUNT(D5:F5)<2,"",_xlfn.STDEV.S(D5:F5)) | J5: 組數 n | K5: =COUNT(G5:G12) | M5: 每組一個平均值，所以 n = 組數，不是 15 次。 | O5: Label | P5: =K9 | Q5: =0
B6: 2 | C6: =IF(B6="","",IFERROR(INDEX('1_原始數據'!$B$2:$B$1000,MATCH(B6,'1_原始數據'!$A$2:$A$1000,0)),"")) | D6: =IF(B6="","",IF(COUNTIFS('1_原始數據'!$A$2:$A$1000,B6,'1_原始數據'!$C$2:$C$1000,"milk_blind_fat_pct",'1_原始數據'!$D$2:$D$1000,1)=0,"",SUMIFS('1_原始數據'!$E$2:$E$1000,'1_原始數據'!$A$2:$A$1000,B6,'1_原始數據'!$C$2:$C$1000,"milk_blind_fat_pct",'1_原始數據'!$D$2:$D$1000,1))) | E6: =IF(B6="","",IF(COUNTIFS('1_原始數據'!$A$2:$A$1000,B6,'1_原始數據'!$C$2:$C$1000,"milk_blind_fat_pct",'1_原始數據'!$D$2:$D$1000,2)=0,"",SUMIFS('1_原始數據'!$E$2:$E$1000,'1_原始數據'!$A$2:$A$1000,B6,'1_原始數據'!$C$2:$C$1000,"milk_blind_fat_pct",'1_原始數據'!$D$2:$D$1000,2))) | F6: =IF(B6="","",IF(COUNTIFS('1_原始數據'!$A$2:$A$1000,B6,'1_原始數據'!$C$2:$C$1000,"milk_blind_fat_pct",'1_原始數據'!$D$2:$D$1000,3)=0,"",SUMIFS('1_原始數據'!$E$2:$E$1000,'1_原始數據'!$A$2:$A$1000,B6,'1_原始數據'!$C$2:$C$1000,"milk_blind_fat_pct",'1_原始數據'!$D$2:$D$1000,3))) | G6: =IF(COUNT(D6:F6)=0,"",AVERAGE(D6:F6)) | H6: =IF(COUNT(D6:F6)<2,"",_xlfn.STDEV.S(D6:F6)) | J6: 班級平均（直接 Soxhlet, %） | K6: =AVERAGE(G5:G12) | M6: 5 組平均的平均。 | O6: Rose-Gottlieb (reference) | P6: =K8 | Q6: =0
B7: 3 | C7: =IF(B7="","",IFERROR(INDEX('1_原始數據'!$B$2:$B$1000,MATCH(B7,'1_原始數據'!$A$2:$A$1000,0)),"")) | D7: =IF(B7="","",IF(COUNTIFS('1_原始數據'!$A$2:$A$1000,B7,'1_原始數據'!$C$2:$C$1000,"milk_blind_fat_pct",'1_原始數據'!$D$2:$D$1000,1)=0,"",SUMIFS('1_原始數據'!$E$2:$E$1000,'1_原始數據'!$A$2:$A$1000,B7,'1_原始數據'!$C$2:$C$1000,"milk_blind_fat_pct",'1_原始數據'!$D$2:$D$1000,1))) | E7: =IF(B7="","",IF(COUNTIFS('1_原始數據'!$A$2:$A$1000,B7,'1_原始數據'!$C$2:$C$1000,"milk_blind_fat_pct",'1_原始數據'!$D$2:$D$1000,2)=0,"",SUMIFS('1_原始數據'!$E$2:$E$1000,'1_原始數據'!$A$2:$A$1000,B7,'1_原始數據'!$C$2:$C$1000,"milk_blind_fat_pct",'1_原始數據'!$D$2:$D$1000,2))) | F7: =IF(B7="","",IF(COUNTIFS('1_原始數據'!$A$2:$A$1000,B7,'1_原始數據'!$C$2:$C$1000,"milk_blind_fat_pct",'1_原始數據'!$D$2:$D$1000,3)=0,"",SUMIFS('1_原始數據'!$E$2:$E$1000,'1_原始數據'!$A$2:$A$1000,B7,'1_原始數據'!$C$2:$C$1000,"milk_blind_fat_pct",'1_原始數據'!$D$2:$D$1000,3))) | G7: =IF(COUNT(D7:F7)=0,"",AVERAGE(D7:F7)) | H7: =IF(COUNT(D7:F7)<2,"",_xlfn.STDEV.S(D7:F7)) | J7: 組間 SD (%) | K7: =_xlfn.STDEV.S(G5:G12) | M7: 5 個組平均的樣本標準差。 | O7: Soxhlet (class mean) | P7: =K6 | Q7: =K7
B8: 4 | C8: =IF(B8="","",IFERROR(INDEX('1_原始數據'!$B$2:$B$1000,MATCH(B8,'1_原始數據'!$A$2:$A$1000,0)),"")) | D8: =IF(B8="","",IF(COUNTIFS('1_原始數據'!$A$2:$A$1000,B8,'1_原始數據'!$C$2:$C$1000,"milk_blind_fat_pct",'1_原始數據'!$D$2:$D$1000,1)=0,"",SUMIFS('1_原始數據'!$E$2:$E$1000,'1_原始數據'!$A$2:$A$1000,B8,'1_原始數據'!$C$2:$C$1000,"milk_blind_fat_pct",'1_原始數據'!$D$2:$D$1000,1))) | E8: =IF(B8="","",IF(COUNTIFS('1_原始數據'!$A$2:$A$1000,B8,'1_原始數據'!$C$2:$C$1000,"milk_blind_fat_pct",'1_原始數據'!$D$2:$D$1000,2)=0,"",SUMIFS('1_原始數據'!$E$2:$E$1000,'1_原始數據'!$A$2:$A$1000,B8,'1_原始數據'!$C$2:$C$1000,"milk_blind_fat_pct",'1_原始數據'!$D$2:$D$1000,2))) | F8: =IF(B8="","",IF(COUNTIFS('1_原始數據'!$A$2:$A$1000,B8,'1_原始數據'!$C$2:$C$1000,"milk_blind_fat_pct",'1_原始數據'!$D$2:$D$1000,3)=0,"",SUMIFS('1_原始數據'!$E$2:$E$1000,'1_原始數據'!$A$2:$A$1000,B8,'1_原始數據'!$C$2:$C$1000,"milk_blind_fat_pct",'1_原始數據'!$D$2:$D$1000,3))) | G8: =IF(COUNT(D8:F8)=0,"",AVERAGE(D8:F8)) | H8: =IF(COUNT(D8:F8)<2,"",_xlfn.STDEV.S(D8:F8)) | J8: Röse–Gottlieb 參考值 (%) | K8: =IF(COUNTIFS('1_原始數據'!$C$2:$C$1000,"milk_blind_RG_reference")=0,"",AVERAGEIFS('1_原始數據'!$E$2:$E$1000,'1_原始數據'!$C$2:$C$1000,"milk_blind_RG_reference")) | M8: TA／參考實驗室提供，乳品脂肪公認的參考方法。
B9: 5 | C9: =IF(B9="","",IFERROR(INDEX('1_原始數據'!$B$2:$B$1000,MATCH(B9,'1_原始數據'!$A$2:$A$1000,0)),"")) | D9: =IF(B9="","",IF(COUNTIFS('1_原始數據'!$A$2:$A$1000,B9,'1_原始數據'!$C$2:$C$1000,"milk_blind_fat_pct",'1_原始數據'!$D$2:$D$1000,1)=0,"",SUMIFS('1_原始數據'!$E$2:$E$1000,'1_原始數據'!$A$2:$A$1000,B9,'1_原始數據'!$C$2:$C$1000,"milk_blind_fat_pct",'1_原始數據'!$D$2:$D$1000,1))) | E9: =IF(B9="","",IF(COUNTIFS('1_原始數據'!$A$2:$A$1000,B9,'1_原始數據'!$C$2:$C$1000,"milk_blind_fat_pct",'1_原始數據'!$D$2:$D$1000,2)=0,"",SUMIFS('1_原始數據'!$E$2:$E$1000,'1_原始數據'!$A$2:$A$1000,B9,'1_原始數據'!$C$2:$C$1000,"milk_blind_fat_pct",'1_原始數據'!$D$2:$D$1000,2))) | F9: =IF(B9="","",IF(COUNTIFS('1_原始數據'!$A$2:$A$1000,B9,'1_原始數據'!$C$2:$C$1000,"milk_blind_fat_pct",'1_原始數據'!$D$2:$D$1000,3)=0,"",SUMIFS('1_原始數據'!$E$2:$E$1000,'1_原始數據'!$A$2:$A$1000,B9,'1_原始數據'!$C$2:$C$1000,"milk_blind_fat_pct",'1_原始數據'!$D$2:$D$1000,3))) | G9: =IF(COUNT(D9:F9)=0,"",AVERAGE(D9:F9)) | H9: =IF(COUNT(D9:F9)<2,"",_xlfn.STDEV.S(D9:F9)) | J9: 標示值 (%) | K9: =IF(COUNTIFS('1_原始數據'!$C$2:$C$1000,"milk_blind_label")=0,"",AVERAGEIFS('1_原始數據'!$E$2:$E$1000,'1_原始數據'!$C$2:$C$1000,"milk_blind_label")) | M9: 產品包裝上的數字。
C10: =IF(B10="","",IFERROR(INDEX('1_原始數據'!$B$2:$B$1000,MATCH(B10,'1_原始數據'!$A$2:$A$1000,0)),"")) | D10: =IF(B10="","",IF(COUNTIFS('1_原始數據'!$A$2:$A$1000,B10,'1_原始數據'!$C$2:$C$1000,"milk_blind_fat_pct",'1_原始數據'!$D$2:$D$1000,1)=0,"",SUMIFS('1_原始數據'!$E$2:$E$1000,'1_原始數據'!$A$2:$A$1000,B10,'1_原始數據'!$C$2:$C$1000,"milk_blind_fat_pct",'1_原始數據'!$D$2:$D$1000,1))) | E10: =IF(B10="","",IF(COUNTIFS('1_原始數據'!$A$2:$A$1000,B10,'1_原始數據'!$C$2:$C$1000,"milk_blind_fat_pct",'1_原始數據'!$D$2:$D$1000,2)=0,"",SUMIFS('1_原始數據'!$E$2:$E$1000,'1_原始數據'!$A$2:$A$1000,B10,'1_原始數據'!$C$2:$C$1000,"milk_blind_fat_pct",'1_原始數據'!$D$2:$D$1000,2))) | F10: =IF(B10="","",IF(COUNTIFS('1_原始數據'!$A$2:$A$1000,B10,'1_原始數據'!$C$2:$C$1000,"milk_blind_fat_pct",'1_原始數據'!$D$2:$D$1000,3)=0,"",SUMIFS('1_原始數據'!$E$2:$E$1000,'1_原始數據'!$A$2:$A$1000,B10,'1_原始數據'!$C$2:$C$1000,"milk_blind_fat_pct",'1_原始數據'!$D$2:$D$1000,3))) | G10: =IF(COUNT(D10:F10)=0,"",AVERAGE(D10:F10)) | H10: =IF(COUNT(D10:F10)<2,"",_xlfn.STDEV.S(D10:F10)) | J10: bias vs RG（百分點）= 平均 − RG | K10: =K6-K8 | M10: 負的＝偏低。單位是「百分點」（% 相減），不是 %。
C11: =IF(B11="","",IFERROR(INDEX('1_原始數據'!$B$2:$B$1000,MATCH(B11,'1_原始數據'!$A$2:$A$1000,0)),"")) | D11: =IF(B11="","",IF(COUNTIFS('1_原始數據'!$A$2:$A$1000,B11,'1_原始數據'!$C$2:$C$1000,"milk_blind_fat_pct",'1_原始數據'!$D$2:$D$1000,1)=0,"",SUMIFS('1_原始數據'!$E$2:$E$1000,'1_原始數據'!$A$2:$A$1000,B11,'1_原始數據'!$C$2:$C$1000,"milk_blind_fat_pct",'1_原始數據'!$D$2:$D$1000,1))) | E11: =IF(B11="","",IF(COUNTIFS('1_原始數據'!$A$2:$A$1000,B11,'1_原始數據'!$C$2:$C$1000,"milk_blind_fat_pct",'1_原始數據'!$D$2:$D$1000,2)=0,"",SUMIFS('1_原始數據'!$E$2:$E$1000,'1_原始數據'!$A$2:$A$1000,B11,'1_原始數據'!$C$2:$C$1000,"milk_blind_fat_pct",'1_原始數據'!$D$2:$D$1000,2))) | F11: =IF(B11="","",IF(COUNTIFS('1_原始數據'!$A$2:$A$1000,B11,'1_原始數據'!$C$2:$C$1000,"milk_blind_fat_pct",'1_原始數據'!$D$2:$D$1000,3)=0,"",SUMIFS('1_原始數據'!$E$2:$E$1000,'1_原始數據'!$A$2:$A$1000,B11,'1_原始數據'!$C$2:$C$1000,"milk_blind_fat_pct",'1_原始數據'!$D$2:$D$1000,3))) | G11: =IF(COUNT(D11:F11)=0,"",AVERAGE(D11:F11)) | H11: =IF(COUNT(D11:F11)<2,"",_xlfn.STDEV.S(D11:F11)) | J11: 回收率 vs RG (%) = 平均 ÷ RG × 100 | K11: =K6/K8*100 | M11: 只測回了約八成的脂肪。
C12: =IF(B12="","",IFERROR(INDEX('1_原始數據'!$B$2:$B$1000,MATCH(B12,'1_原始數據'!$A$2:$A$1000,0)),"")) | D12: =IF(B12="","",IF(COUNTIFS('1_原始數據'!$A$2:$A$1000,B12,'1_原始數據'!$C$2:$C$1000,"milk_blind_fat_pct",'1_原始數據'!$D$2:$D$1000,1)=0,"",SUMIFS('1_原始數據'!$E$2:$E$1000,'1_原始數據'!$A$2:$A$1000,B12,'1_原始數據'!$C$2:$C$1000,"milk_blind_fat_pct",'1_原始數據'!$D$2:$D$1000,1))) | E12: =IF(B12="","",IF(COUNTIFS('1_原始數據'!$A$2:$A$1000,B12,'1_原始數據'!$C$2:$C$1000,"milk_blind_fat_pct",'1_原始數據'!$D$2:$D$1000,2)=0,"",SUMIFS('1_原始數據'!$E$2:$E$1000,'1_原始數據'!$A$2:$A$1000,B12,'1_原始數據'!$C$2:$C$1000,"milk_blind_fat_pct",'1_原始數據'!$D$2:$D$1000,2))) | F12: =IF(B12="","",IF(COUNTIFS('1_原始數據'!$A$2:$A$1000,B12,'1_原始數據'!$C$2:$C$1000,"milk_blind_fat_pct",'1_原始數據'!$D$2:$D$1000,3)=0,"",SUMIFS('1_原始數據'!$E$2:$E$1000,'1_原始數據'!$A$2:$A$1000,B12,'1_原始數據'!$C$2:$C$1000,"milk_blind_fat_pct",'1_原始數據'!$D$2:$D$1000,3))) | G12: =IF(COUNT(D12:F12)=0,"",AVERAGE(D12:F12)) | H12: =IF(COUNT(D12:F12)<2,"",_xlfn.STDEV.S(D12:F12)) | J12: bias vs 標示值（百分點） | K12: =K6-K9 | M12: 練習題 2 用。
B13: D–F 欄用 SUMIFS 依「組別、item、rep」抓每一次的值；G = AVERAGE 三重複。組數較多時在 B 欄空白黃色格補上組別。 | J13: 回收率 vs 標示值 (%) | K13: =K6/K9*100
J15: 4-2 偏差是不是真的？（單樣本 t 檢定，對 RG）
J16: t = (平均 − RG) ÷ (SD/√n) | K16: =(K6-K8)/(K7/SQRT(K5)) | M16: 和 EX01 的單樣本 t 檢定一樣。|t| 越大，偏差越不可能是隨機誤差。
J17: p 值（雙尾） | K17: =_xlfn.T.DIST.2T(ABS(K16),K5-1) | M17: T.DIST.2T(|t|, 自由度 n−1)。
J18: 結論（α = 0.05） | K18: =IF(K17<0.05,"顯著偏低：系統誤差","沒有足夠證據說有偏差")
J20: 為什麼偏低：奶粉的脂肪被蛋白質與乳糖包覆（encapsulated fat），乙醚接觸不到。三重複很穩定（精密），但平均整個偏低（不準確）——這是方法的系統誤差，不是操作失誤。解法：先酸水解（或用 Röse–Gottlieb／Mojonnier 鹼性醇解）把包覆打開再萃取。這 5 組數據會帶到 W8 能力試驗，影響差減法算出的碳水化合物。
B44: 看圖：藍色柱（班級直接 Soxhlet，誤差線 = 組間 SD）比 Röse–Gottlieb 與標示值低約 4 個百分點；誤差線很短，表示這不是隨機誤差。

Sheet 6_Pearson方塊
B1: 步驟 5 Pearson 方塊：牛奶脂肪標準化
B2: 工廠把牛奶先脫脂，再依比例加回鮮奶油，調成指定脂肪 % 的產品。用的是質量平衡：W高脂 = (目標% − 低脂%) ÷ (高脂% − 低脂%) × W總；W低脂 = W總 − W高脂。
C4: 講義範例 | D4: 自己的題目 | F4: Pearson 方塊（講義範例）
B5: 高脂成分（鮮奶油）脂肪 % | C5: 36 | F5: =C5 | H5: =C10 | J5: C 欄是講義範例（36% 鮮奶油 + 0.1% 脫脂乳 → 100 kg 的 3.25% 全脂乳）。D 欄空白黃色格填自己的題目（練習題 3）。
B6: 低脂成分（脫脂乳）脂肪 % | C6: 0.1 | F6: 高脂 % | G6: ↘ ↗ | H6: 份（高脂）
B7: 目標脂肪 % | C7: 3.25 | G7: =C7
B8: 總重 W總 (kg) | C8: 100 | G8: ↗ ↘
B9: 目標在兩者之間嗎？ | C9: =IF(COUNT(C5:C8)<4,"",IF(AND(C6<C7,C7<C5),"可以","不行：目標必須介於低脂與高脂之間")) | D9: =IF(COUNT(D5:D8)<4,"",IF(AND(D6<D7,D7<D5),"可以","不行：目標必須介於低脂與高脂之間")) | F9: =C6 | H9: =C11 | J9: AND(低 < 目標, 目標 < 高)：目標如果不在中間，怎麼混都調不出來。
B10: 高脂成分份數 = 目標 − 低脂 | C10: =IF(C9<>"可以","",C7-C6) | D10: =IF(D9<>"可以","",D7-D6) | F10: 低脂 % | H10: 份（低脂） | J10: Pearson 方塊的「份數」：沿對角線相減取絕對值。高脂的份數 ÷ 總份數，就是高脂成分佔的比例；和上面的公式完全相同。
B11: 低脂成分份數 = 高脂 − 目標 | C11: =IF(C9<>"可以","",C5-C7) | D11: =IF(D9<>"可以","",D5-D7)
B12: 高脂成分（鮮奶油）(kg) | C12: =IF(C9<>"可以","",C10/(C10+C11)*C8) | D12: =IF(D9<>"可以","",D10/(D10+D11)*D8)
B13: 低脂成分（脫脂乳）(kg) | C13: =IF(C9<>"可以","",C8-C12) | D13: =IF(D9<>"可以","",D8-D12)
B14: 驗算：混合後脂肪 (kg) | C14: =IF(C9<>"可以","",C12*C5/100+C13*C6/100) | D14: =IF(D9<>"可以","",D12*D5/100+D13*D6/100) | J14: 驗算：每個成分的重量 × 它的脂肪 %，加起來要等於目標的脂肪總重。
B15: 應該等於：目標% × W總 (kg) | C15: =IF(C9<>"可以","",C7/100*C8) | D15: =IF(D9<>"可以","",D7/100*D8)
B16: 質量平衡通過？ | C16: =IF(C9<>"可以","",IF(ABS(C14-C15)<0.0005,"✔ 通過","✘ 檢查")) | D16: =IF(D9<>"可以","",IF(ABS(D14-D15)<0.0005,"✔ 通過","✘ 檢查"))

Sheet 練習題
B1: 練習題（寫在黃色格子裡，交報告時一起附上）
B3: 問題 1：如果忘記做溶劑空白校正，你們這組洋芋片的粗脂肪 % 會被高估多少？請寫出百分點與相對 %。
B4: 提示：「2_粗脂肪」H 欄（未扣空白）與 I 欄（扣除空白）相減就是百分點；再 ÷ I 欄 × 100 就是相對 %。第 1 組也可看「4_精密度與回收率」C23。
B7: 問題 2：用班級直接 Soxhlet 平均，分別算相對 Röse–Gottlieb 與標示值的 bias 與回收率，並用一到兩句話解釋為什麼方向是「偏低」而不是「偏高」。
B8: 提示：看「5_盲樣偏差」K10–K13。
B11: 問題 3：用 40% 鮮奶油 + 0.5% 脫脂乳，調配 200 kg 的 2% 低脂乳，各需要多少 kg？並驗算質量平衡。
B12: 提示：在「6_Pearson方塊」D5–D8 填入 40、0.5、2、200。
B15: 問題 4：如果某組把洋芋片磨得不夠細、顆粒偏大，對粗脂肪 %（相對真實值）會有什麼影響（偏高／偏低）？為什麼？
B18: 問題 5：已知對照品的回收率如果落在 95–105% 之外，SOP 會判定這批操作不合格。你們的回收率合格嗎？若不合格，列出兩個可能的原因。
B19: 提示：看「4_精密度與回收率」C16、C19。
