Workbook

Sheet 0_說明
B1: EX07｜W7 糖：Brix 與酚硫酸法
B2: 食品分析實驗・入門數據分析（Excel 版）。不用寫程式；同一份數據在 Colab 筆記本做進階分析，答案應該一致。
B4: 學習目標
B5: • 用 SLOPE、INTERCEPT、RSQ、STEYX、LINEST 做酚硫酸法標準曲線的線性迴歸，並畫殘差圖。
B6: • 理解「R² 高不代表直線對」，用重複測量做缺適性（lack-of-fit）F 檢定。
B7: • 用兩種 σ（迴歸殘差 SD、試劑空白 SD）算 LOD = 3.3σ/斜率 與 LOQ = 10σ/斜率。
B8: • 把未知樣品的吸光值換算成 g/100 mL 葡萄糖當量（含稀釋倍數、樣品空白），並估計預測不確定度。
B9: • 比較柳橙汁 Brix 與酚硫酸法總醣，並用質量守恆驗算楓糖漿的 40：1。
B11: 顏色代表什麼
C12: 黃色：輸入或貼上數據的地方
C13: 綠色：公式，會自動計算，不要改
C14: 橘色：重點結果，寫報告時用
B16: 操作步驟
B17: 1. 看「1_原始數據」：一列是一次讀值。右邊兩個綠色欄是用標準曲線反算的濃度與（未扣空白的）總醣。
B18: 2. 「2_標準曲線」：斜率、截距、R²、STEYX、LINEST 標準誤，往下捲看標準曲線圖與殘差圖。
B19: 3. 「3_缺適性檢定」：兩個重複合併，F 檢定判斷直線夠不夠好。
B20: 4. 「4_LOD_LOQ」：兩種 σ 的 LOD／LOQ 比較。
B21: 5. 「5_樣品換算」：未知樣品的總醣 ± SD，冬瓜茶扣樣品空白，稀釋倍數反推。
B22: 6. 「6_Brix比較」、「7_楓糖漿質量守恆」、「8_銅還原法概念」：Brix 與總醣、質量守恆、乙級方法計算。
B23: 7. 完成「練習題」。
B24: 8. 換成班級數據：把共用 Google Sheet 的數據貼到「1_原始數據」A2 起（欄位順序一樣，std_curve 的 conc_ug_mL 與 unknown_* 的 dilution_factor 一定要填）。樣品名稱不同就改「5_樣品換算」A、B 欄。
B26: 對答案：用內建範例數據時，你的結果應該等於
B27: 項目 | C27: 本檔計算值 | D27: Colab 筆記本的值 | E27: 一致？
B28: 標準曲線斜率 m | C28: ='2_標準曲線'!I8 | D28: 0.010107143 | E28: =IF(ABS(C28-D28)<=1.0117142857142856e-06,"✔ 一致","✘ 不一致（換成班級數據後本來就會不同）")
B29: R² | C29: ='2_標準曲線'!I10 | D29: 0.99935646 | E29: =IF(ABS(C29-D29)<=9.993664641331075e-05,"✔ 一致","✘ 不一致（換成班級數據後本來就會不同）")
B30: 缺適性 F | C30: ='3_缺適性檢定'!M28 | D30: 4.8803108 | E30: =IF(ABS(C30-D30)<=0.00048803208217969133,"✔ 一致","✘ 不一致（換成班級數據後本來就會不同）")
B31: 缺適性 p 值 | C31: ='3_缺適性檢定'!N28 | D31: 0.042811932 | E31: =IF(ABS(C31-D31)<=4.282193237527568e-06,"✔ 一致","✘ 不一致（換成班級數據後本來就會不同）")
B32: LOD，殘差 SD 法 (µg/mL) | C32: ='4_LOD_LOQ'!C11 | D32: 3.5031532 | E32: =IF(ABS(C32-D32)<=0.0003503163195113213,"✔ 一致","✘ 不一致（換成班級數據後本來就會不同）")
B33: LOD，空白 SD 法 (µg/mL) | C33: ='4_LOD_LOQ'!D11 | D33: 0.86743801 | E33: =IF(ABS(C33-D33)<=8.674480112247559e-05,"✔ 一致","✘ 不一致（換成班級數據後本來就會不同）")
B34: 冬瓜茶扣空白後總醣 (g/100 mL) | C34: ='5_樣品換算'!K9 | D34: 8.9993875 | E34: =IF(ABS(C34-D34)<=0.0008999397514723206,"✔ 一致","✘ 不一致（換成班級數據後本來就會不同）")
B35: 柳橙汁 Brix − 總醣 | C35: ='6_Brix比較'!C9 | D35: 1.9999764 | E35: =IF(ABS(C35-D35)<=0.00019999864428739671,"✔ 一致","✘ 不一致（換成班級數據後本來就會不同）")
B36: 「Colab 筆記本的值」是用內建模擬數據算出的答案；換成全班數據後，這一欄就不再適用。
B38: 相關連結
B39: 本週實驗投影片 | C39: https://tai-shengyeh.github.io/food-analysis-lab/labs/w07_sugar/index.html
B40: 進階：Colab 筆記本（Python） | C40: https://colab.research.google.com/github/Tai-ShengYeh/food-analysis-lab/blob/main/notebooks/NB07_sugar_phenolsulfuric.ipynb
B41: 數據分析工具指南（Excel／Orange／Colab） | C41: https://tai-shengyeh.github.io/food-analysis-lab/tools.html
B43: 小提醒
B44: • 大括號 {=…} 的格子是陣列公式。自己輸入時，舊版 Excel 要按 Ctrl+Shift+Enter；Excel 365 與 Google 試算表直接 Enter。
B45: • 迴歸也可以用「資料 → 資料分析 → 迴歸」（分析工具箱），會得到同樣的係數、標準誤與殘差；但它不會做缺適性檢定，也不會隨數據自動更新。
B46: • Colab 筆記本最後把結果匯出成 CSV；這裡直接把橘色格子抄進報告即可。
...

Sheet 1_原始數據
A1: group | B1: student | C1: item | D1: rep | E1: value | F1: unit | G1: temp_C | H1: conc_ug_mL | I1: dilution_factor | J1: note | K1: 反算濃度_ug_mL | L1: 總醣_g_100mL_未扣空白 | N1: 這張工作表怎麼用
A2: 0 | B2: class_curve | C2: std_curve | D2: 1 | E2: 0.021 | F2: AU | H2: 0 | J2: 標準曲線第 1 重複，本班的正式檢量線 | K2: =IF($A2="","",IF(F2="AU",(E2-'2_標準曲線'!$I$9)/'2_標準曲線'!$I$8,"")) | L2: =IF($A2="","",IF(ISNUMBER(I2),K2*I2*1E-4,"")) | N2: 本週欄位：item＝量測項目（std_curve 標準曲線、reagent_blank_490nm 試劑空白、unknown_* 未知樣品、orange_juice_brix 折射計讀值…）；value＝吸光值 (AU) 或 Brix 讀值 (°Brix)；conc_ug_mL＝標準品已知濃度（只有 std_curve 有）；dilution_factor＝未知樣品稀釋倍數。
A3: 0 | B3: class_curve | C3: std_curve | D3: 1 | E3: 0.233 | F3: AU | H3: 20 | J3: 標準曲線第 1 重複，本班的正式檢量線 | K3: =IF($A3="","",IF(F3="AU",(E3-'2_標準曲線'!$I$9)/'2_標準曲線'!$I$8,"")) | L3: =IF($A3="","",IF(ISNUMBER(I3),K3*I3*1E-4,"")) | N3: rep＝重複次數。標準曲線第 1 重複是本班正式檢量線；第 2 重複是為了做缺適性（lack-of-fit）檢定。
A4: 0 | B4: class_curve | C4: std_curve | D4: 1 | E4: 0.447 | F4: AU | H4: 40 | J4: 標準曲線第 1 重複，本班的正式檢量線 | K4: =IF($A4="","",IF(F4="AU",(E4-'2_標準曲線'!$I$9)/'2_標準曲線'!$I$8,"")) | L4: =IF($A4="","",IF(ISNUMBER(I4),K4*I4*1E-4,"")) | N4: ⚠ 內建數據是模擬教學資料，不是真實量測值。
A5: 0 | B5: class_curve | C5: std_curve | D5: 1 | E5: 0.64 | F5: AU | H5: 60 | J5: 標準曲線第 1 重複，本班的正式檢量線 | K5: =IF($A5="","",IF(F5="AU",(E5-'2_標準曲線'!$I$9)/'2_標準曲線'!$I$8,"")) | L5: =IF($A5="","",IF(ISNUMBER(I5),K5*I5*1E-4,"")) | N5: 黃色欄位＝原始數據。換成全班數據時：從共用 Google Sheet 複製，貼到 A2（欄位順序必須一樣），舊資料多出來的列要整列刪除。
A6: 0 | B6: class_curve | C6: std_curve | D6: 1 | E6: 0.847 | F6: AU | H6: 80 | J6: 標準曲線第 1 重複，本班的正式檢量線 | K6: =IF($A6="","",IF(F6="AU",(E6-'2_標準曲線'!$I$9)/'2_標準曲線'!$I$8,"")) | L6: =IF($A6="","",IF(ISNUMBER(I6),K6*I6*1E-4,"")) | N6: 綠色欄位＝公式，會自動算到第 1000 列，不要手動修改。
A7: 0 | B7: class_curve | C7: std_curve | D7: 1 | E7: 1.029 | F7: AU | H7: 100 | J7: 標準曲線第 1 重複，本班的正式檢量線 | K7: =IF($A7="","",IF(F7="AU",(E7-'2_標準曲線'!$I$9)/'2_標準曲線'!$I$8,"")) | L7: =IF($A7="","",IF(ISNUMBER(I7),K7*I7*1E-4,"")) | N7: 「反算濃度_ug_mL」：吸光值 (AU) 用「2_標準曲線」的直線反算成反應液濃度 (µg/mL)＝(A − b) ÷ m。標準品那幾列可以拿來和已知濃度 conc_ug_mL 比，看標準曲線回推得準不準。
A8: 0 | B8: class_curve | C8: std_curve | D8: 2 | E8: 0.0227 | F8: AU | H8: 0 | J8: 標準曲線第 2 重複，用於示範 lack-of-fit 檢定（需要重複才能估計純誤差） | K8: =IF($A8="","",IF(F8="AU",(E8-'2_標準曲線'!$I$9)/'2_標準曲線'!$I$8,"")) | L8: =IF($A8="","",IF(ISNUMBER(I8),K8*I8*1E-4,"")) | N8: 「總醣_g_100mL_未扣空白」：有稀釋倍數的列：反算濃度 × 稀釋倍數 × 10⁻⁴。注意這裡還沒扣樣品空白（冬瓜茶會高估），正式結果請看「5_樣品換算」。
A9: 0 | B9: class_curve | C9: std_curve | D9: 2 | E9: 0.2268 | F9: AU | H9: 20 | J9: 標準曲線第 2 重複，用於示範 lack-of-fit 檢定（需要重複才能估計純誤差） | K9: =IF($A9="","",IF(F9="AU",(E9-'2_標準曲線'!$I$9)/'2_標準曲線'!$I$8,"")) | L9: =IF($A9="","",IF(ISNUMBER(I9),K9*I9*1E-4,""))
A10: 0 | B10: class_curve | C10: std_curve | D10: 2 | E10: 0.4496 | F10: AU | H10: 40 | J10: 標準曲線第 2 重複，用於示範 lack-of-fit 檢定（需要重複才能估計純誤差） | K10: =IF($A10="","",IF(F10="AU",(E10-'2_標準曲線'!$I$9)/'2_標準曲線'!$I$8,"")) | L10: =IF($A10="","",IF(ISNUMBER(I10),K10*I10*1E-4,""))
A11: 0 | B11: class_curve | C11: std_curve | D11: 2 | E11: 0.6532 | F11: AU | H11: 60 | J11: 標準曲線第 2 重複，用於示範 lack-of-fit 檢定（需要重複才能估計純誤差） | K11: =IF($A11="","",IF(F11="AU",(E11-'2_標準曲線'!$I$9)/'2_標準曲線'!$I$8,"")) | L11: =IF($A11="","",IF(ISNUMBER(I11),K11*I11*1E-4,""))
A12: 0 | B12: class_curve | C12: std_curve | D12: 2 | E12: 0.8259 | F12: AU | H12: 80 | J12: 標準曲線第 2 重複，用於示範 lack-of-fit 檢定（需要重複才能估計純誤差） | K12: =IF($A12="","",IF(F12="AU",(E12-'2_標準曲線'!$I$9)/'2_標準曲線'!$I$8,"")) | L12: =IF($A12="","",IF(ISNUMBER(I12),K12*I12*1E-4,""))
A13: 0 | B13: class_curve | C13: std_curve | D13: 2 | E13: 1.0205 | F13: AU | H13: 100 | J13: 標準曲線第 2 重複，用於示範 lack-of-fit 檢定（需要重複才能估計純誤差） | K13: =IF($A13="","",IF(F13="AU",(E13-'2_標準曲線'!$I$9)/'2_標準曲線'!$I$8,"")) | L13: =IF($A13="","",IF(ISNUMBER(I13),K13*I13*1E-4,""))
A14: 0 | B14: class_blank | C14: reagent_blank_490nm | D14: 1 | E14: 0.0205 | F14: AU | J14: 試劑空白重複讀值，用於估計 blank SD（LOD 的另一種算法） | K14: =IF($A14="","",IF(F14="AU",(E14-'2_標準曲線'!$I$9)/'2_標準曲線'!$I$8,"")) | L14: =IF($A14="","",IF(ISNUMBER(I14),K14*I14*1E-4,""))
A15: 0 | B15: class_blank | C15: reagent_blank_490nm | D15: 2 | E15: 0.0187 | F15: AU | J15: 試劑空白重複讀值，用於估計 blank SD（LOD 的另一種算法） | K15: =IF($A15="","",IF(F15="AU",(E15-'2_標準曲線'!$I$9)/'2_標準曲線'!$I$8,"")) | L15: =IF($A15="","",IF(ISNUMBER(I15),K15*I15*1E-4,""))
A16: 0 | B16: class_blank | C16: reagent_blank_490nm | D16: 3 | E16: 0.0199 | F16: AU | J16: 試劑空白重複讀值，用於估計 blank SD（LOD 的另一種算法） | K16: =IF($A16="","",IF(F16="AU",(E16-'2_標準曲線'!$I$9)/'2_標準曲線'!$I$8,"")) | L16: =IF($A16="","",IF(ISNUMBER(I16),K16*I16*1E-4,""))
A17: 0 | B17: class_blank | C17: reagent_blank_490nm | D17: 4 | E17: 0.0166 | F17: AU | J17: 試劑空白重複讀值，用於估計 blank SD（LOD 的另一種算法） | K17: =IF($A17="","",IF(F17="AU",(E17-'2_標準曲線'!$I$9)/'2_標準曲線'!$I$8,"")) | L17: =IF($A17="","",IF(ISNUMBER(I17),K17*I17*1E-4,""))
A18: 0 | B18: class_blank | C18: reagent_blank_490nm | D18: 5 | E18: 0.0235 | F18: AU | J18: 試劑空白重複讀值，用於估計 blank SD（LOD 的另一種算法） | K18: =IF($A18="","",IF(F18="AU",(E18-'2_標準曲線'!$I$9)/'2_標準曲線'!$I$8,"")) | L18: =IF($A18="","",IF(ISNUMBER(I18),K18*I18*1E-4,""))
A19: 0 | B19: class_blank | C19: reagent_blank_490nm | D19: 6 | E19: 0.0231 | F19: AU | J19: 試劑空白重複讀值，用於估計 blank SD（LOD 的另一種算法） | K19: =IF($A19="","",IF(F19="AU",(E19-'2_標準曲線'!$I$9)/'2_標準曲線'!$I$8,"")) | L19: =IF($A19="","",IF(ISNUMBER(I19),K19*I19*1E-4,""))
A20: 0 | B20: class_blank | C20: reagent_blank_490nm | D20: 7 | E20: 0.0203 | F20: AU | J20: 試劑空白重複讀值，用於估計 blank SD（LOD 的另一種算法） | K20: =IF($A20="","",IF(F20="AU",(E20-'2_標準曲線'!$I$9)/'2_標準曲線'!$I$8,"")) | L20: =IF($A20="","",IF(ISNUMBER(I20),K20*I20*1E-4,""))
A21: 0 | B21: class_blank | C21: reagent_blank_490nm | D21: 8 | E21: 0.0245 | F21: AU | J21: 試劑空白重複讀值，用於估計 blank SD（LOD 的另一種算法） | K21: =IF($A21="","",IF(F21="AU",(E21-'2_標準曲線'!$I$9)/'2_標準曲線'!$I$8,"")) | L21: =IF($A21="","",IF(ISNUMBER(I21),K21*I21*1E-4,""))
A22: 1 | B22: G1 | C22: unknown_sports_drink | D22: 1 | E22: 0.637 | F22: AU | I22: 1000 | J22: 運動飲料，已知標準曲線範例（W7 課堂計算闖關） | K22: =IF($A22="","",IF(F22="AU",(E22-'2_標準曲線'!$I$9)/'2_標準曲線'!$I$8,"")) | L22: =IF($A22="","",IF(ISNUMBER(I22),K22*I22*1E-4,""))
A23: 2 | B23: G2 | C23: unknown_orange_juice_phenol | D23: 1 | E23: 0.5109 | F23: AU | I23: 2000 | J23: 柳橙汁，酚硫酸法總醣 | K23: =IF($A23="","",IF(F23="AU",(E23-'2_標準曲線'!$I$9)/'2_標準曲線'!$I$8,"")) | L23: =IF($A23="","",IF(ISNUMBER(I23),K23*I23*1E-4,""))
A24: 2 | B24: G2 | C24: orange_juice_brix | D24: 1 | E24: 11.5 | F24: degBrix | J24: 柳橙汁，折射計 Brix 讀值（20°C 對照，未做溫度校正） | K24: =IF($A24="","",IF(F24="AU",(E24-'2_標準曲線'!$I$9)/'2_標準曲線'!$I$8,"")) | L24: =IF($A24="","",IF(ISNUMBER(I24),K24*I24*1E-4,""))
A25: 3 | B25: G3 | C25: unknown_maple_syrup | D25: 1 | E25: 0.5378 | F25: AU | I25: 17500 | J25: 楓糖漿，酚硫酸法總醣，稀釋倍數很大(原液濃度高) | K25: =IF($A25="","",IF(F25="AU",(E25-'2_標準曲線'!$I$9)/'2_標準曲線'!$I$8,"")) | L25: =IF($A25="","",IF(ISNUMBER(I25),K25*I25*1E-4,""))
A26: 4 | B26: G4 | C26: unknown_winter_melon_tea | D26: 1 | E26: 0.5306 | F26: AU | I26: 2000 | J26: 冬瓜茶，樣品本身顏色深，讀值含顏色干擾(尚未扣除樣品空白) | K26: =IF($A26="","",IF(F26="AU",(E26-'2_標準曲線'!$I$9)/'2_標準曲線'!$I$8,"")) | L26: =IF($A26="","",IF(ISNUMBER(I26),K26*I26*1E-4,""))
A27: 4 | B27: G4 | C27: winter_melon_tea_sample_blank | D27: 1 | E27: 0.045 | F27: AU | I27: 2000 | J27: 冬瓜茶樣品本身的顏色空白(同稀釋倍數，不加酚/硫酸或以水代替糖反應)，用於扣除色素干擾 | K27: =IF($A27="","",IF(F27="AU",(E27-'2_標準曲線'!$I$9)/'2_標準曲線'!$I$8,"")) | L27: =IF($A27="","",IF(ISNUMBER(I27),K27*I27*1E-4,""))
K28: =IF($A28="","",IF(F28="AU",(E28-'2_標準曲線'!$I$9)/'2_標準曲線'!$I$8,"")) | L28: =IF($A28="","",IF(ISNUMBER(I28),K28*I28*1E-4,""))
K29: =IF($A29="","",IF(F29="AU",(E29-'2_標準曲線'!$I$9)/'2_標準曲線'!$I$8,"")) | L29: =IF($A29="","",IF(ISNUMBER(I29),K29*I29*1E-4,""))
K30: =IF($A30="","",IF(F30="AU",(E30-'2_標準曲線'!$I$9)/'2_標準曲線'!$I$8,"")) | L30: =IF($A30="","",IF(ISNUMBER(I30),K30*I30*1E-4,""))
K31: =IF($A31="","",IF(F31="AU",(E31-'2_標準曲線'!$I$9)/'2_標準曲線'!$I$8,"")) | L31: =IF($A31="","",IF(ISNUMBER(I31),K31*I31*1E-4,""))
K32: =IF($A32="","",IF(F32="AU",(E32-'2_標準曲線'!$I$9)/'2_標準曲線'!$I$8,"")) | L32: =IF($A32="","",IF(ISNUMBER(I32),K32*I32*1E-4,""))
K33: =IF($A33="","",IF(F33="AU",(E33-'2_標準曲線'!$I$9)/'2_標準曲線'!$I$8,"")) | L33: =IF($A33="","",IF(ISNUMBER(I33),K33*I33*1E-4,""))
K34: =IF($A34="","",IF(F34="AU",(E34-'2_標準曲線'!$I$9)/'2_標準曲線'!$I$8,"")) | L34: =IF($A34="","",IF(ISNUMBER(I34),K34*I34*1E-4,""))
K35: =IF($A35="","",IF(F35="AU",(E35-'2_標準曲線'!$I$9)/'2_標準曲線'!$I$8,"")) | L35: =IF($A35="","",IF(ISNUMBER(I35),K35*I35*1E-4,""))
K36: =IF($A36="","",IF(F36="AU",(E36-'2_標準曲線'!$I$9)/'2_標準曲線'!$I$8,"")) | L36: =IF($A36="","",IF(ISNUMBER(I36),K36*I36*1E-4,""))
K37: =IF($A37="","",IF(F37="AU",(E37-'2_標準曲線'!$I$9)/'2_標準曲線'!$I$8,"")) | L37: =IF($A37="","",IF(ISNUMBER(I37),K37*I37*1E-4,""))
K38: =IF($A38="","",IF(F38="AU",(E38-'2_標準曲線'!$I$9)/'2_標準曲線'!$I$8,"")) | L38: =IF($A38="","",IF(ISNUMBER(I38),K38*I38*1E-4,""))
K39: =IF($A39="","",IF(F39="AU",(E39-'2_標準曲線'!$I$9)/'2_標準曲線'!$I$8,"")) | L39: =IF($A39="","",IF(ISNUMBER(I39),K39*I39*1E-4,""))
... K1000: =IF($A1000="","",IF(F1000="AU",(E1000-'2_標準曲線'!$I$9)/'2_標準曲線'!$I$8,"")) | L1000: =IF($A1000="","",IF(ISNUMBER(I1000),K1000*I1000*1E-4,""))

Sheet 2_標準曲線
A1: 步驟 1 酚硫酸法標準曲線：線性迴歸 A = m × C + b
A2: 濃度 C（µg/mL 葡萄糖）是 x，490 nm 吸光值 A 是 y。濃度水準與吸光值都是從「1_原始數據」自動抓出來的，不用手打。看完數字，一定要往下看殘差圖。
B4: 正式檢量線用第幾重複 (rep) | E4: 1 | H4: 本班用第 1 重複當正式檢量線（和 Colab 相同）。改成 2 就會用第 2 重複重算整本活頁簿。 | N4: 圖用輔助數據（自動計算，不要改）
A6: k | B6: 濃度 C (µg/mL) | C6: 吸光值 A (AU) | D6: 預測 A | E6: 殘差 | F6: 正負 | H6: 結果 | I6: 數值 | L6: SLOPE、INTERCEPT 等的範圍寫成 OFFSET($B$7,0,0,$I$7)：從 B7 往下取 n 格。這樣換成班級數據、濃度水準數不同時，範圍會自動跟著變。 | N6: 點 x | O6: 點 y | P6: 殘差 | Q6: 直線 x | R6: 直線 y | S6: 零線 y
A7: 1 | B7: {=IF(COUNTIFS('1_原始數據'!$C$2:$C$1000,"std_curve",'1_原始數據'!$D$2:$D$1000,$E$4)=0,"",MIN(IF(('1_原始數據'!$C$2:$C$1000="std_curve")*('1_原始數據'!$D$2:$D$1000=$E$4),'1_原始數據'!$H$2:$H$1000)))} | C7: =IF(B7="","",AVERAGEIFS('1_原始數據'!$E$2:$E$1000,'1_原始數據'!$C$2:$C$1000,"std_curve",'1_原始數據'!$D$2:$D$1000,$E$4,'1_原始數據'!$H$2:$H$1000,B7)) | D7: =IF(B7="","",$I$8*B7+$I$9) | E7: =IF(B7="","",C7-D7) | F7: =IF(B7="","",IF(E7>0,"+","−")) | H7: 標準點數 n | I7: =COUNT(B7:B16) | L7: =COUNT(B7:B16) 數 B 欄有幾個數字。 | N7: =IF(B7="",0,B7) | O7: =IF(C7="",0,C7) | P7: =IF(E7="",0,E7) | Q7: =I17 | R7: =$I$8*Q7+$I$9 | S7: =0
A8: 2 | B8: {=IF(B7="","",IF(COUNTIFS('1_原始數據'!$C$2:$C$1000,"std_curve",'1_原始數據'!$D$2:$D$1000,$E$4,'1_原始數據'!$H$2:$H$1000,">"&B7)=0,"",MIN(IF(('1_原始數據'!$C$2:$C$1000="std_curve")*('1_原始數據'!$D$2:$D$1000=$E$4)*('1_原始數據'!$H$2:$H$1000>B7),'1_原始數據'!$H$2:$H$1000))))} | C8: =IF(B8="","",AVERAGEIFS('1_原始數據'!$E$2:$E$1000,'1_原始數據'!$C$2:$C$1000,"std_curve",'1_原始數據'!$D$2:$D$1000,$E$4,'1_原始數據'!$H$2:$H$1000,B8)) | D8: =IF(B8="","",$I$8*B8+$I$9) | E8: =IF(B8="","",C8-D8) | F8: =IF(B8="","",IF(E8>0,"+","−")) | H8: 斜率 m (AU per µg/mL) | I8: =SLOPE(OFFSET($C$7,0,0,$I$7),OFFSET($B$7,0,0,$I$7)) | L8: =SLOPE(y 範圍, x 範圍) 最小平方法的斜率。注意 y 在前、x 在後。 | N8: =IF(B8="",N7,B8) | O8: =IF(C8="",O7,C8) | P8: =IF(E8="",P7,E8) | Q8: =I18 | R8: =$I$8*Q8+$I$9 | S8: =0
A9: 3 | B9: {=IF(B8="","",IF(COUNTIFS('1_原始數據'!$C$2:$C$1000,"std_curve",'1_原始數據'!$D$2:$D$1000,$E$4,'1_原始數據'!$H$2:$H$1000,">"&B8)=0,"",MIN(IF(('1_原始數據'!$C$2:$C$1000="std_curve")*('1_原始數據'!$D$2:$D$1000=$E$4)*('1_原始數據'!$H$2:$H$1000>B8),'1_原始數據'!$H$2:$H$1000))))} | C9: =IF(B9="","",AVERAGEIFS('1_原始數據'!$E$2:$E$1000,'1_原始數據'!$C$2:$C$1000,"std_curve",'1_原始數據'!$D$2:$D$1000,$E$4,'1_原始數據'!$H$2:$H$1000,B9)) | D9: =IF(B9="","",$I$8*B9+$I$9) | E9: =IF(B9="","",C9-D9) | F9: =IF(B9="","",IF(E9>0,"+","−")) | H9: 截距 b (AU) | I9: =INTERCEPT(OFFSET($C$7,0,0,$I$7),OFFSET($B$7,0,0,$I$7)) | L9: =INTERCEPT(y, x) C = 0 時的預測吸光值。 | N9: =IF(B9="",N8,B9) | O9: =IF(C9="",O8,C9) | P9: =IF(E9="",P8,E9)
A10: 4 | B10: {=IF(B9="","",IF(COUNTIFS('1_原始數據'!$C$2:$C$1000,"std_curve",'1_原始數據'!$D$2:$D$1000,$E$4,'1_原始數據'!$H$2:$H$1000,">"&B9)=0,"",MIN(IF(('1_原始數據'!$C$2:$C$1000="std_curve")*('1_原始數據'!$D$2:$D$1000=$E$4)*('1_原始數據'!$H$2:$H$1000>B9),'1_原始數據'!$H$2:$H$1000))))} | C10: =IF(B10="","",AVERAGEIFS('1_原始數據'!$E$2:$E$1000,'1_原始數據'!$C$2:$C$1000,"std_curve",'1_原始數據'!$D$2:$D$1000,$E$4,'1_原始數據'!$H$2:$H$1000,B10)) | D10: =IF(B10="","",$I$8*B10+$I$9) | E10: =IF(B10="","",C10-D10) | F10: =IF(B10="","",IF(E10>0,"+","−")) | H10: R² | I10: =RSQ(OFFSET($C$7,0,0,$I$7),OFFSET($B$7,0,0,$I$7)) | L10: =RSQ(y, x) 判定係數。R² 高只代表點靠近直線，不代表直線是對的模型（看步驟 2）。 | N10: =IF(B10="",N9,B10) | O10: =IF(C10="",O9,C10) | P10: =IF(E10="",P9,E10)
A11: 5 | B11: {=IF(B10="","",IF(COUNTIFS('1_原始數據'!$C$2:$C$1000,"std_curve",'1_原始數據'!$D$2:$D$1000,$E$4,'1_原始數據'!$H$2:$H$1000,">"&B10)=0,"",MIN(IF(('1_原始數據'!$C$2:$C$1000="std_curve")*('1_原始數據'!$D$2:$D$1000=$E$4)*('1_原始數據'!$H$2:$H$1000>B10),'1_原始數據'!$H$2:$H$1000))))} | C11: =IF(B11="","",AVERAGEIFS('1_原始數據'!$E$2:$E$1000,'1_原始數據'!$C$2:$C$1000,"std_curve",'1_原始數據'!$D$2:$D$1000,$E$4,'1_原始數據'!$H$2:$H$1000,B11)) | D11: =IF(B11="","",$I$8*B11+$I$9) | E11: =IF(B11="","",C11-D11) | F11: =IF(B11="","",IF(E11>0,"+","−")) | H11: 殘差標準差 s_y (AU) | I11: =STEYX(OFFSET($C$7,0,0,$I$7),OFFSET($B$7,0,0,$I$7)) | L11: =STEYX(y, x) 殘差的標準差，除以 n − 2（因為估計了 m、b 兩個參數）。LOD 的第一種 σ 就是它。 | N11: =IF(B11="",N10,B11) | O11: =IF(C11="",O10,C11) | P11: =IF(E11="",P10,E11)
A12: 6 | B12: {=IF(B11="","",IF(COUNTIFS('1_原始數據'!$C$2:$C$1000,"std_curve",'1_原始數據'!$D$2:$D$1000,$E$4,'1_原始數據'!$H$2:$H$1000,">"&B11)=0,"",MIN(IF(('1_原始數據'!$C$2:$C$1000="std_curve")*('1_原始數據'!$D$2:$D$1000=$E$4)*('1_原始數據'!$H$2:$H$1000>B11),'1_原始數據'!$H$2:$H$1000))))} | C12: =IF(B12="","",AVERAGEIFS('1_原始數據'!$E$2:$E$1000,'1_原始數據'!$C$2:$C$1000,"std_curve",'1_原始數據'!$D$2:$D$1000,$E$4,'1_原始數據'!$H$2:$H$1000,B12)) | D12: =IF(B12="","",$I$8*B12+$I$9) | E12: =IF(B12="","",C12-D12) | F12: =IF(B12="","",IF(E12>0,"+","−")) | H12: 殘差平方和 SS_res | I12: =SUMSQ(E7:E16) | L12: =SUMSQ(殘差) 每個殘差平方後加總。 | N12: =IF(B12="",N11,B12) | O12: =IF(C12="",O11,C12) | P12: =IF(E12="",P11,E12)
A13: 7 | B13: {=IF(B12="","",IF(COUNTIFS('1_原始數據'!$C$2:$C$1000,"std_curve",'1_原始數據'!$D$2:$D$1000,$E$4,'1_原始數據'!$H$2:$H$1000,">"&B12)=0,"",MIN(IF(('1_原始數據'!$C$2:$C$1000="std_curve")*('1_原始數據'!$D$2:$D$1000=$E$4)*('1_原始數據'!$H$2:$H$1000>B12),'1_原始數據'!$H$2:$H$1000))))} | C13: =IF(B13="","",AVERAGEIFS('1_原始數據'!$E$2:$E$1000,'1_原始數據'!$C$2:$C$1000,"std_curve",'1_原始數據'!$D$2:$D$1000,$E$4,'1_原始數據'!$H$2:$H$1000,B13)) | D13: =IF(B13="","",$I$8*B13+$I$9) | E13: =IF(B13="","",C13-D13) | F13: =IF(B13="","",IF(E13>0,"+","−")) | H13: 總平方和 SS_tot | I13: =DEVSQ(OFFSET($C$7,0,0,$I$7)) | L13: =DEVSQ(y) 吸光值離平均值的平方和。 | N13: =IF(B13="",N12,B13) | O13: =IF(C13="",O12,C13) | P13: =IF(E13="",P12,E13)
A14: 8 | B14: {=IF(B13="","",IF(COUNTIFS('1_原始數據'!$C$2:$C$1000,"std_curve",'1_原始數據'!$D$2:$D$1000,$E$4,'1_原始數據'!$H$2:$H$1000,">"&B13)=0,"",MIN(IF(('1_原始數據'!$C$2:$C$1000="std_curve")*('1_原始數據'!$D$2:$D$1000=$E$4)*('1_原始數據'!$H$2:$H$1000>B13),'1_原始數據'!$H$2:$H$1000))))} | C14: =IF(B14="","",AVERAGEIFS('1_原始數據'!$E$2:$E$1000,'1_原始數據'!$C$2:$C$1000,"std_curve",'1_原始數據'!$D$2:$D$1000,$E$4,'1_原始數據'!$H$2:$H$1000,B14)) | D14: =IF(B14="","",$I$8*B14+$I$9) | E14: =IF(B14="","",C14-D14) | F14: =IF(B14="","",IF(E14>0,"+","−")) | H14: 驗算 R² = 1 − SS_res/SS_tot | I14: =1-I12/I13 | L14: 應該和 I10 一樣。R² 就是「直線解釋了多少比例的變異」。 | N14: =IF(B14="",N13,B14) | O14: =IF(C14="",O13,C14) | P14: =IF(E14="",P13,E14)
A15: 9 | B15: {=IF(B14="","",IF(COUNTIFS('1_原始數據'!$C$2:$C$1000,"std_curve",'1_原始數據'!$D$2:$D$1000,$E$4,'1_原始數據'!$H$2:$H$1000,">"&B14)=0,"",MIN(IF(('1_原始數據'!$C$2:$C$1000="std_curve")*('1_原始數據'!$D$2:$D$1000=$E$4)*('1_原始數據'!$H$2:$H$1000>B14),'1_原始數據'!$H$2:$H$1000))))} | C15: =IF(B15="","",AVERAGEIFS('1_原始數據'!$E$2:$E$1000,'1_原始數據'!$C$2:$C$1000,"std_curve",'1_原始數據'!$D$2:$D$1000,$E$4,'1_原始數據'!$H$2:$H$1000,B15)) | D15: =IF(B15="","",$I$8*B15+$I$9) | E15: =IF(B15="","",C15-D15) | F15: =IF(B15="","",IF(E15>0,"+","−")) | H15: 標準品吸光值平均 Ā | I15: =AVERAGE(OFFSET($C$7,0,0,$I$7)) | L15: 步驟 4 算預測不確定度會用到。 | N15: =IF(B15="",N14,B15) | O15: =IF(C15="",O14,C15) | P15: =IF(E15="",P14,E15)
A16: 10 | B16: {=IF(B15="","",IF(COUNTIFS('1_原始數據'!$C$2:$C$1000,"std_curve",'1_原始數據'!$D$2:$D$1000,$E$4,'1_原始數據'!$H$2:$H$1000,">"&B15)=0,"",MIN(IF(('1_原始數據'!$C$2:$C$1000="std_curve")*('1_原始數據'!$D$2:$D$1000=$E$4)*('1_原始數據'!$H$2:$H$1000>B15),'1_原始數據'!$H$2:$H$1000))))} | C16: =IF(B16="","",AVERAGEIFS('1_原始數據'!$E$2:$E$1000,'1_原始數據'!$C$2:$C$1000,"std_curve",'1_原始數據'!$D$2:$D$1000,$E$4,'1_原始數據'!$H$2:$H$1000,B16)) | D16: =IF(B16="","",$I$8*B16+$I$9) | E16: =IF(B16="","",C16-D16) | F16: =IF(B16="","",IF(E16>0,"+","−")) | H16: Sxx = Σ(C − C̄)² | I16: =DEVSQ(OFFSET($B$7,0,0,$I$7)) | L16: =DEVSQ(x) 濃度的平方和，步驟 4 會用到。 | N16: =IF(B16="",N15,B16) | O16: =IF(C16="",O15,C16) | P16: =IF(E16="",P15,E16)
H17: 最低標準濃度 (µg/mL) | I17: =MIN(OFFSET($B$7,0,0,$I$7)) | L17: 樣品反算濃度必須落在最低與最高標準點之間。
A18: B 欄：濃度水準。B7 用 {=MIN(IF(條件, 濃度))} 找最小的濃度，B8 以下找「比上一格大的最小濃度」，所以會自動由小到大排好，最多 10 個水準。這是陣列公式（大括號），不要手動改。 | H18: 最高標準濃度 (µg/mL) | I18: =MAX(OFFSET($B$7,0,0,$I$7)) | N18: 沒用到的列會重複最後一個點（疊在同一位置，看不出來），所以濃度水準數改變時圖也會自動更新。
A19: C 欄：=AVERAGEIFS(value, item,"std_curve", rep, 1, conc, 這個濃度) 把該濃度的吸光值抓過來。 | H19: 方程式 | I19: ="A = "&FIXED(I8,6)&" × C + "&FIXED(I9,6) | L19: FIXED(數字, 小數位) 把數字變成文字，方便寫報告。
A20: D 欄：預測 A = m × C + b（m、b 在右邊 I8、I9）。 E 欄：殘差 = 實測 − 預測。
A21: F 欄：殘差的正負號。如果符號是一段一段連在一起（例如 −、+、+、+、−），而不是隨機交錯，代表曲線有系統性彎曲。 | H21: LINEST：一次給出斜率、截距和它們的標準誤
H22: LINEST 輸出（5 列 × 2 欄） | I22: 左欄 | J22: 右欄 | L22: =LINEST(y, x, TRUE, TRUE) 是「多格陣列公式」：先選 I23:J27 十格，輸入公式後按 Ctrl+Shift+Enter（Excel 365 直接 Enter）。第 1 列和 SLOPE／INTERCEPT 一樣；第 2 列是它們的標準誤（SE），代表斜率、截距本身有多不確定；第 3 列 R² 和 STEYX 也和上面一樣。
H23: 第 1 列：斜率 m｜截距 b | I23: {=LINEST(OFFSET($C$7,0,0,$I$7),OFFSET($B$7,0,0,$I$7),TRUE,TRUE)} | L23: 報告寫法：m = 斜率 ± SE(m)。SE 越小，檢量線越可靠。
H24: 第 2 列：SE(m)｜SE(b) | L24: SE(b) 可以用來判斷截距和 0 有沒有差：|b| < 2×SE(b) 大致表示截距和 0 沒有明顯差別。
H25: 第 3 列：R²｜s_y
H26: 第 4 列：F 值｜自由度 df = n − 2
H27: 第 5 列：SS_reg｜SS_resid | L27: SS_reg + SS_resid = SS_tot。
H29: 斜率的相對標準誤 SE(m)/m (%) | I29: =I24/I23*100 | L29: 另一種做法：資料 → 資料分析 → 迴歸（需先啟用「分析工具箱」增益集），勾選「殘差」和「殘差圖」，會得到同樣的係數、標準誤與殘差。這本活頁簿用公式，換數據時會自動更新。
H30: 截距 ÷ SE(b) | I30: =J23/J24
A32: 圖 1 標準曲線（點＝實測，線＝迴歸直線） | H32: 圖 2 殘差圖（R² 迷思：看殘差有沒有規律）
A51: R² 迷思：本例 R² ≈ 0.999，看起來很完美；但殘差圖是一個拱形（兩端為負、中間為正），表示資料有一點點彎曲（高濃度略為飽和）。R² 沒辦法分辨「彎曲」和「隨機雜訊」，要用步驟 2 的缺適性檢定才能正式判斷。好的殘差圖應該是在 0 上下隨機散佈、沒有形狀。
A52: 在 Excel 裡也可以對圖 1 的點按右鍵 → 加上趨勢線 → 勾「在圖表上顯示方程式」「顯示 R 平方值」；結果會和 I8、I9、I10 一樣。但趨勢線不會告訴你殘差，所以殘差圖要自己畫。

Sheet 3_缺適性檢定
A1: 步驟 2 缺適性（lack-of-fit）F 檢定：用重複測量判斷「直線」對不對
A2: 把兩個重複的標準曲線（共 12 點）合併做一條直線。殘差分成兩部分：同一濃度重複之間的差＝純誤差（pure error，隨機雜訊）；各濃度平均值偏離直線＝缺適性（lack-of-fit，彎曲）。如果缺適性明顯大於純誤差，直線就不是好模型。
A4: 2-1 所有標準點（自動從原始數據抓） | I4: 2-2 合併迴歸（所有重複一起）
A5: k | B5: 原始列號 | C5: rep | D5: 濃度 C | E5: 吸光值 A | F5: 合併直線預測 | G5: 殘差
A6: 1 | B6: {=IF(1>COUNTIF('1_原始數據'!$C$2:$C$1000,"std_curve"),"",SMALL(IF('1_原始數據'!$C$2:$C$1000="std_curve",ROW('1_原始數據'!$C$2:$C$1000)),1))} | C6: =IF($B6="","",INDEX('1_原始數據'!$D$1:$D$1000,$B6)) | D6: =IF($B6="","",INDEX('1_原始數據'!$H$1:$H$1000,$B6)) | E6: =IF($B6="","",INDEX('1_原始數據'!$E$1:$E$1000,$B6)) | F6: =IF($B6="","",$J$7*D6+$J$8) | G6: =IF($B6="","",E6-F6) | I6: 總點數 N | J6: =COUNT(D6:D35)
A7: 2 | B7: {=IF(2>COUNTIF('1_原始數據'!$C$2:$C$1000,"std_curve"),"",SMALL(IF('1_原始數據'!$C$2:$C$1000="std_curve",ROW('1_原始數據'!$C$2:$C$1000)),2))} | C7: =IF($B7="","",INDEX('1_原始數據'!$D$1:$D$1000,$B7)) | D7: =IF($B7="","",INDEX('1_原始數據'!$H$1:$H$1000,$B7)) | E7: =IF($B7="","",INDEX('1_原始數據'!$E$1:$E$1000,$B7)) | F7: =IF($B7="","",$J$7*D7+$J$8) | G7: =IF($B7="","",E7-F7) | I7: 合併斜率 | J7: =SLOPE(OFFSET($E$6,0,0,$J$6),OFFSET($D$6,0,0,$J$6)) | P7: 注意：這是兩個重複合併的直線，只用在這個檢定。正式換算仍用步驟 1 的直線。
A8: 3 | B8: {=IF(3>COUNTIF('1_原始數據'!$C$2:$C$1000,"std_curve"),"",SMALL(IF('1_原始數據'!$C$2:$C$1000="std_curve",ROW('1_原始數據'!$C$2:$C$1000)),3))} | C8: =IF($B8="","",INDEX('1_原始數據'!$D$1:$D$1000,$B8)) | D8: =IF($B8="","",INDEX('1_原始數據'!$H$1:$H$1000,$B8)) | E8: =IF($B8="","",INDEX('1_原始數據'!$E$1:$E$1000,$B8)) | F8: =IF($B8="","",$J$7*D8+$J$8) | G8: =IF($B8="","",E8-F8) | I8: 合併截距 | J8: =INTERCEPT(OFFSET($E$6,0,0,$J$6),OFFSET($D$6,0,0,$J$6))
A9: 4 | B9: {=IF(4>COUNTIF('1_原始數據'!$C$2:$C$1000,"std_curve"),"",SMALL(IF('1_原始數據'!$C$2:$C$1000="std_curve",ROW('1_原始數據'!$C$2:$C$1000)),4))} | C9: =IF($B9="","",INDEX('1_原始數據'!$D$1:$D$1000,$B9)) | D9: =IF($B9="","",INDEX('1_原始數據'!$H$1:$H$1000,$B9)) | E9: =IF($B9="","",INDEX('1_原始數據'!$E$1:$E$1000,$B9)) | F9: =IF($B9="","",$J$7*D9+$J$8) | G9: =IF($B9="","",E9-F9) | I9: 合併 R² | J9: =RSQ(OFFSET($E$6,0,0,$J$6),OFFSET($D$6,0,0,$J$6)) | P9: R² 仍然很高，但下面的檢定會說直線不夠好。
A10: 5 | B10: {=IF(5>COUNTIF('1_原始數據'!$C$2:$C$1000,"std_curve"),"",SMALL(IF('1_原始數據'!$C$2:$C$1000="std_curve",ROW('1_原始數據'!$C$2:$C$1000)),5))} | C10: =IF($B10="","",INDEX('1_原始數據'!$D$1:$D$1000,$B10)) | D10: =IF($B10="","",INDEX('1_原始數據'!$H$1:$H$1000,$B10)) | E10: =IF($B10="","",INDEX('1_原始數據'!$E$1:$E$1000,$B10)) | F10: =IF($B10="","",$J$7*D10+$J$8) | G10: =IF($B10="","",E10-F10) | I10: 殘差平方和 SSE | J10: =SUMSQ(G6:G35) | P10: SSE = SS_lack-of-fit + SS_pure-error
A11: 6 | B11: {=IF(6>COUNTIF('1_原始數據'!$C$2:$C$1000,"std_curve"),"",SMALL(IF('1_原始數據'!$C$2:$C$1000="std_curve",ROW('1_原始數據'!$C$2:$C$1000)),6))} | C11: =IF($B11="","",INDEX('1_原始數據'!$D$1:$D$1000,$B11)) | D11: =IF($B11="","",INDEX('1_原始數據'!$H$1:$H$1000,$B11)) | E11: =IF($B11="","",INDEX('1_原始數據'!$E$1:$E$1000,$B11)) | F11: =IF($B11="","",$J$7*D11+$J$8) | G11: =IF($B11="","",E11-F11)
A12: 7 | B12: {=IF(7>COUNTIF('1_原始數據'!$C$2:$C$1000,"std_curve"),"",SMALL(IF('1_原始數據'!$C$2:$C$1000="std_curve",ROW('1_原始數據'!$C$2:$C$1000)),7))} | C12: =IF($B12="","",INDEX('1_原始數據'!$D$1:$D$1000,$B12)) | D12: =IF($B12="","",INDEX('1_原始數據'!$H$1:$H$1000,$B12)) | E12: =IF($B12="","",INDEX('1_原始數據'!$E$1:$E$1000,$B12)) | F12: =IF($B12="","",$J$7*D12+$J$8) | G12: =IF($B12="","",E12-F12) | I12: 2-3 各濃度水準
A13: 8 | B13: {=IF(8>COUNTIF('1_原始數據'!$C$2:$C$1000,"std_curve"),"",SMALL(IF('1_原始數據'!$C$2:$C$1000="std_curve",ROW('1_原始數據'!$C$2:$C$1000)),8))} | C13: =IF($B13="","",INDEX('1_原始數據'!$D$1:$D$1000,$B13)) | D13: =IF($B13="","",INDEX('1_原始數據'!$H$1:$H$1000,$B13)) | E13: =IF($B13="","",INDEX('1_原始數據'!$E$1:$E$1000,$B13)) | F13: =IF($B13="","",$J$7*D13+$J$8) | G13: =IF($B13="","",E13-F13) | I13: 濃度 C_i | J13: 重複數 n_i | K13: 平均 ȳ_i | L13: 直線預測 ŷ_i | M13: n_i(ȳ_i − ŷ_i)² | N13: Σ(y − ȳ_i)² | P13: M 欄＝缺適性的來源：平均值離直線多遠（乘上重複數）。N 欄＝純誤差的來源：同一濃度的重複彼此差多少，用 {=DEVSQ(IF(條件, 吸光值))} 算。
A14: 9 | B14: {=IF(9>COUNTIF('1_原始數據'!$C$2:$C$1000,"std_curve"),"",SMALL(IF('1_原始數據'!$C$2:$C$1000="std_curve",ROW('1_原始數據'!$C$2:$C$1000)),9))} | C14: =IF($B14="","",INDEX('1_原始數據'!$D$1:$D$1000,$B14)) | D14: =IF($B14="","",INDEX('1_原始數據'!$H$1:$H$1000,$B14)) | E14: =IF($B14="","",INDEX('1_原始數據'!$E$1:$E$1000,$B14)) | F14: =IF($B14="","",$J$7*D14+$J$8) | G14: =IF($B14="","",E14-F14) | I14: {=IF(COUNTIF('1_原始數據'!$C$2:$C$1000,"std_curve")=0,"",MIN(IF('1_原始數據'!$C$2:$C$1000="std_curve",'1_原始數據'!$H$2:$H$1000)))} | J14: =IF(I14="","",COUNTIFS('1_原始數據'!$C$2:$C$1000,"std_curve",'1_原始數據'!$H$2:$H$1000,I14)) | K14: =IF(I14="","",AVERAGEIFS('1_原始數據'!$E$2:$E$1000,'1_原始數據'!$C$2:$C$1000,"std_curve",'1_原始數據'!$H$2:$H$1000,I14)) | L14: =IF(I14="","",$J$7*I14+$J$8) | M14: =IF(I14="","",J14*(K14-L14)^2) | N14: {=IF(I14="","",DEVSQ(IF(('1_原始數據'!$C$2:$C$1000="std_curve")*('1_原始數據'!$H$2:$H$1000=I14),'1_原始數據'!$E$2:$E$1000)))}
A15: 10 | B15: {=IF(10>COUNTIF('1_原始數據'!$C$2:$C$1000,"std_curve"),"",SMALL(IF('1_原始數據'!$C$2:$C$1000="std_curve",ROW('1_原始數據'!$C$2:$C$1000)),10))} | C15: =IF($B15="","",INDEX('1_原始數據'!$D$1:$D$1000,$B15)) | D15: =IF($B15="","",INDEX('1_原始數據'!$H$1:$H$1000,$B15)) | E15: =IF($B15="","",INDEX('1_原始數據'!$E$1:$E$1000,$B15)) | F15: =IF($B15="","",$J$7*D15+$J$8) | G15: =IF($B15="","",E15-F15) | I15: {=IF(I14="","",IF(COUNTIFS('1_原始數據'!$C$2:$C$1000,"std_curve",'1_原始數據'!$H$2:$H$1000,">"&I14)=0,"",MIN(IF(('1_原始數據'!$C$2:$C$1000="std_curve")*('1_原始數據'!$H$2:$H$1000>I14),'1_原始數據'!$H$2:$H$1000))))} | J15: =IF(I15="","",COUNTIFS('1_原始數據'!$C$2:$C$1000,"std_curve",'1_原始數據'!$H$2:$H$1000,I15)) | K15: =IF(I15="","",AVERAGEIFS('1_原始數據'!$E$2:$E$1000,'1_原始數據'!$C$2:$C$1000,"std_curve",'1_原始數據'!$H$2:$H$1000,I15)) | L15: =IF(I15="","",$J$7*I15+$J$8) | M15: =IF(I15="","",J15*(K15-L15)^2) | N15: {=IF(I15="","",DEVSQ(IF(('1_原始數據'!$C$2:$C$1000="std_curve")*('1_原始數據'!$H$2:$H$1000=I15),'1_原始數據'!$E$2:$E$1000)))}
A16: 11 | B16: {=IF(11>COUNTIF('1_原始數據'!$C$2:$C$1000,"std_curve"),"",SMALL(IF('1_原始數據'!$C$2:$C$1000="std_curve",ROW('1_原始數據'!$C$2:$C$1000)),11))} | C16: =IF($B16="","",INDEX('1_原始數據'!$D$1:$D$1000,$B16)) | D16: =IF($B16="","",INDEX('1_原始數據'!$H$1:$H$1000,$B16)) | E16: =IF($B16="","",INDEX('1_原始數據'!$E$1:$E$1000,$B16)) | F16: =IF($B16="","",$J$7*D16+$J$8) | G16: =IF($B16="","",E16-F16) | I16: {=IF(I15="","",IF(COUNTIFS('1_原始數據'!$C$2:$C$1000,"std_curve",'1_原始數據'!$H$2:$H$1000,">"&I15)=0,"",MIN(IF(('1_原始數據'!$C$2:$C$1000="std_curve")*('1_原始數據'!$H$2:$H$1000>I15),'1_原始數據'!$H$2:$H$1000))))} | J16: =IF(I16="","",COUNTIFS('1_原始數據'!$C$2:$C$1000,"std_curve",'1_原始數據'!$H$2:$H$1000,I16)) | K16: =IF(I16="","",AVERAGEIFS('1_原始數據'!$E$2:$E$1000,'1_原始數據'!$C$2:$C$1000,"std_curve",'1_原始數據'!$H$2:$H$1000,I16)) | L16: =IF(I16="","",$J$7*I16+$J$8) | M16: =IF(I16="","",J16*(K16-L16)^2) | N16: {=IF(I16="","",DEVSQ(IF(('1_原始數據'!$C$2:$C$1000="std_curve")*('1_原始數據'!$H$2:$H$1000=I16),'1_原始數據'!$E$2:$E$1000)))}
A17: 12 | B17: {=IF(12>COUNTIF('1_原始數據'!$C$2:$C$1000,"std_curve"),"",SMALL(IF('1_原始數據'!$C$2:$C$1000="std_curve",ROW('1_原始數據'!$C$2:$C$1000)),12))} | C17: =IF($B17="","",INDEX('1_原始數據'!$D$1:$D$1000,$B17)) | D17: =IF($B17="","",INDEX('1_原始數據'!$H$1:$H$1000,$B17)) | E17: =IF($B17="","",INDEX('1_原始數據'!$E$1:$E$1000,$B17)) | F17: =IF($B17="","",$J$7*D17+$J$8) | G17: =IF($B17="","",E17-F17) | I17: {=IF(I16="","",IF(COUNTIFS('1_原始數據'!$C$2:$C$1000,"std_curve",'1_原始數據'!$H$2:$H$1000,">"&I16)=0,"",MIN(IF(('1_原始數據'!$C$2:$C$1000="std_curve")*('1_原始數據'!$H$2:$H$1000>I16),'1_原始數據'!$H$2:$H$1000))))} | J17: =IF(I17="","",COUNTIFS('1_原始數據'!$C$2:$C$1000,"std_curve",'1_原始數據'!$H$2:$H$1000,I17)) | K17: =IF(I17="","",AVERAGEIFS('1_原始數據'!$E$2:$E$1000,'1_原始數據'!$C$2:$C$1000,"std_curve",'1_原始數據'!$H$2:$H$1000,I17)) | L17: =IF(I17="","",$J$7*I17+$J$8) | M17: =IF(I17="","",J17*(K17-L17)^2) | N17: {=IF(I17="","",DEVSQ(IF(('1_原始數據'!$C$2:$C$1000="std_curve")*('1_原始數據'!$H$2:$H$1000=I17),'1_原始數據'!$E$2:$E$1000)))}
A18: 13 | B18: {=IF(13>COUNTIF('1_原始數據'!$C$2:$C$1000,"std_curve"),"",SMALL(IF('1_原始數據'!$C$2:$C$1000="std_curve",ROW('1_原始數據'!$C$2:$C$1000)),13))} | C18: =IF($B18="","",INDEX('1_原始數據'!$D$1:$D$1000,$B18)) | D18: =IF($B18="","",INDEX('1_原始數據'!$H$1:$H$1000,$B18)) | E18: =IF($B18="","",INDEX('1_原始數據'!$E$1:$E$1000,$B18)) | F18: =IF($B18="","",$J$7*D18+$J$8) | G18: =IF($B18="","",E18-F18) | I18: {=IF(I17="","",IF(COUNTIFS('1_原始數據'!$C$2:$C$1000,"std_curve",'1_原始數據'!$H$2:$H$1000,">"&I17)=0,"",MIN(IF(('1_原始數據'!$C$2:$C$1000="std_curve")*('1_原始數據'!$H$2:$H$1000>I17),'1_原始數據'!$H$2:$H$1000))))} | J18: =IF(I18="","",COUNTIFS('1_原始數據'!$C$2:$C$1000,"std_curve",'1_原始數據'!$H$2:$H$1000,I18)) | K18: =IF(I18="","",AVERAGEIFS('1_原始數據'!$E$2:$E$1000,'1_原始數據'!$C$2:$C$1000,"std_curve",'1_原始數據'!$H$2:$H$1000,I18)) | L18: =IF(I18="","",$J$7*I18+$J$8) | M18: =IF(I18="","",J18*(K18-L18)^2) | N18: {=IF(I18="","",DEVSQ(IF(('1_原始數據'!$C$2:$C$1000="std_curve")*('1_原始數據'!$H$2:$H$1000=I18),'1_原始數據'!$E$2:$E$1000)))}
A19: 14 | B19: {=IF(14>COUNTIF('1_原始數據'!$C$2:$C$1000,"std_curve"),"",SMALL(IF('1_原始數據'!$C$2:$C$1000="std_curve",ROW('1_原始數據'!$C$2:$C$1000)),14))} | C19: =IF($B19="","",INDEX('1_原始數據'!$D$1:$D$1000,$B19)) | D19: =IF($B19="","",INDEX('1_原始數據'!$H$1:$H$1000,$B19)) | E19: =IF($B19="","",INDEX('1_原始數據'!$E$1:$E$1000,$B19)) | F19: =IF($B19="","",$J$7*D19+$J$8) | G19: =IF($B19="","",E19-F19) | I19: {=IF(I18="","",IF(COUNTIFS('1_原始數據'!$C$2:$C$1000,"std_curve",'1_原始數據'!$H$2:$H$1000,">"&I18)=0,"",MIN(IF(('1_原始數據'!$C$2:$C$1000="std_curve")*('1_原始數據'!$H$2:$H$1000>I18),'1_原始數據'!$H$2:$H$1000))))} | J19: =IF(I19="","",COUNTIFS('1_原始數據'!$C$2:$C$1000,"std_curve",'1_原始數據'!$H$2:$H$1000,I19)) | K19: =IF(I19="","",AVERAGEIFS('1_原始數據'!$E$2:$E$1000,'1_原始數據'!$C$2:$C$1000,"std_curve",'1_原始數據'!$H$2:$H$1000,I19)) | L19: =IF(I19="","",$J$7*I19+$J$8) | M19: =IF(I19="","",J19*(K19-L19)^2) | N19: {=IF(I19="","",DEVSQ(IF(('1_原始數據'!$C$2:$C$1000="std_curve")*('1_原始數據'!$H$2:$H$1000=I19),'1_原始數據'!$E$2:$E$1000)))}
A20: 15 | B20: {=IF(15>COUNTIF('1_原始數據'!$C$2:$C$1000,"std_curve"),"",SMALL(IF('1_原始數據'!$C$2:$C$1000="std_curve",ROW('1_原始數據'!$C$2:$C$1000)),15))} | C20: =IF($B20="","",INDEX('1_原始數據'!$D$1:$D$1000,$B20)) | D20: =IF($B20="","",INDEX('1_原始數據'!$H$1:$H$1000,$B20)) | E20: =IF($B20="","",INDEX('1_原始數據'!$E$1:$E$1000,$B20)) | F20: =IF($B20="","",$J$7*D20+$J$8) | G20: =IF($B20="","",E20-F20) | I20: {=IF(I19="","",IF(COUNTIFS('1_原始數據'!$C$2:$C$1000,"std_curve",'1_原始數據'!$H$2:$H$1000,">"&I19)=0,"",MIN(IF(('1_原始數據'!$C$2:$C$1000="std_curve")*('1_原始數據'!$H$2:$H$1000>I19),'1_原始數據'!$H$2:$H$1000))))} | J20: =IF(I20="","",COUNTIFS('1_原始數據'!$C$2:$C$1000,"std_curve",'1_原始數據'!$H$2:$H$1000,I20)) | K20: =IF(I20="","",AVERAGEIFS('1_原始數據'!$E$2:$E$1000,'1_原始數據'!$C$2:$C$1000,"std_curve",'1_原始數據'!$H$2:$H$1000,I20)) | L20: =IF(I20="","",$J$7*I20+$J$8) | M20: =IF(I20="","",J20*(K20-L20)^2) | N20: {=IF(I20="","",DEVSQ(IF(('1_原始數據'!$C$2:$C$1000="std_curve")*('1_原始數據'!$H$2:$H$1000=I20),'1_原始數據'!$E$2:$E$1000)))}
A21: 16 | B21: {=IF(16>COUNTIF('1_原始數據'!$C$2:$C$1000,"std_curve"),"",SMALL(IF('1_原始數據'!$C$2:$C$1000="std_curve",ROW('1_原始數據'!$C$2:$C$1000)),16))} | C21: =IF($B21="","",INDEX('1_原始數據'!$D$1:$D$1000,$B21)) | D21: =IF($B21="","",INDEX('1_原始數據'!$H$1:$H$1000,$B21)) | E21: =IF($B21="","",INDEX('1_原始數據'!$E$1:$E$1000,$B21)) | F21: =IF($B21="","",$J$7*D21+$J$8) | G21: =IF($B21="","",E21-F21) | I21: {=IF(I20="","",IF(COUNTIFS('1_原始數據'!$C$2:$C$1000,"std_curve",'1_原始數據'!$H$2:$H$1000,">"&I20)=0,"",MIN(IF(('1_原始數據'!$C$2:$C$1000="std_curve")*('1_原始數據'!$H$2:$H$1000>I20),'1_原始數據'!$H$2:$H$1000))))} | J21: =IF(I21="","",COUNTIFS('1_原始數據'!$C$2:$C$1000,"std_curve",'1_原始數據'!$H$2:$H$1000,I21)) | K21: =IF(I21="","",AVERAGEIFS('1_原始數據'!$E$2:$E$1000,'1_原始數據'!$C$2:$C$1000,"std_curve",'1_原始數據'!$H$2:$H$1000,I21)) | L21: =IF(I21="","",$J$7*I21+$J$8) | M21: =IF(I21="","",J21*(K21-L21)^2) | N21: {=IF(I21="","",DEVSQ(IF(('1_原始數據'!$C$2:$C$1000="std_curve")*('1_原始數據'!$H$2:$H$1000=I21),'1_原始數據'!$E$2:$E$1000)))}
A22: 17 | B22: {=IF(17>COUNTIF('1_原始數據'!$C$2:$C$1000,"std_curve"),"",SMALL(IF('1_原始數據'!$C$2:$C$1000="std_curve",ROW('1_原始數據'!$C$2:$C$1000)),17))} | C22: =IF($B22="","",INDEX('1_原始數據'!$D$1:$D$1000,$B22)) | D22: =IF($B22="","",INDEX('1_原始數據'!$H$1:$H$1000,$B22)) | E22: =IF($B22="","",INDEX('1_原始數據'!$E$1:$E$1000,$B22)) | F22: =IF($B22="","",$J$7*D22+$J$8) | G22: =IF($B22="","",E22-F22) | I22: {=IF(I21="","",IF(COUNTIFS('1_原始數據'!$C$2:$C$1000,"std_curve",'1_原始數據'!$H$2:$H$1000,">"&I21)=0,"",MIN(IF(('1_原始數據'!$C$2:$C$1000="std_curve")*('1_原始數據'!$H$2:$H$1000>I21),'1_原始數據'!$H$2:$H$1000))))} | J22: =IF(I22="","",COUNTIFS('1_原始數據'!$C$2:$C$1000,"std_curve",'1_原始數據'!$H$2:$H$1000,I22)) | K22: =IF(I22="","",AVERAGEIFS('1_原始數據'!$E$2:$E$1000,'1_原始數據'!$C$2:$C$1000,"std_curve",'1_原始數據'!$H$2:$H$1000,I22)) | L22: =IF(I22="","",$J$7*I22+$J$8) | M22: =IF(I22="","",J22*(K22-L22)^2) | N22: {=IF(I22="","",DEVSQ(IF(('1_原始數據'!$C$2:$C$1000="std_curve")*('1_原始數據'!$H$2:$H$1000=I22),'1_原始數據'!$E$2:$E$1000)))}
A23: 18 | B23: {=IF(18>COUNTIF('1_原始數據'!$C$2:$C$1000,"std_curve"),"",SMALL(IF('1_原始數據'!$C$2:$C$1000="std_curve",ROW('1_原始數據'!$C$2:$C$1000)),18))} | C23: =IF($B23="","",INDEX('1_原始數據'!$D$1:$D$1000,$B23)) | D23: =IF($B23="","",INDEX('1_原始數據'!$H$1:$H$1000,$B23)) | E23: =IF($B23="","",INDEX('1_原始數據'!$E$1:$E$1000,$B23)) | F23: =IF($B23="","",$J$7*D23+$J$8) | G23: =IF($B23="","",E23-F23) | I23: {=IF(I22="","",IF(COUNTIFS('1_原始數據'!$C$2:$C$1000,"std_curve",'1_原始數據'!$H$2:$H$1000,">"&I22)=0,"",MIN(IF(('1_原始數據'!$C$2:$C$1000="std_curve")*('1_原始數據'!$H$2:$H$1000>I22),'1_原始數據'!$H$2:$H$1000))))} | J23: =IF(I23="","",COUNTIFS('1_原始數據'!$C$2:$C$1000,"std_curve",'1_原始數據'!$H$2:$H$1000,I23)) | K23: =IF(I23="","",AVERAGEIFS('1_原始數據'!$E$2:$E$1000,'1_原始數據'!$C$2:$C$1000,"std_curve",'1_原始數據'!$H$2:$H$1000,I23)) | L23: =IF(I23="","",$J$7*I23+$J$8) | M23: =IF(I23="","",J23*(K23-L23)^2) | N23: {=IF(I23="","",DEVSQ(IF(('1_原始數據'!$C$2:$C$1000="std_curve")*('1_原始數據'!$H$2:$H$1000=I23),'1_原始數據'!$E$2:$E$1000)))}
A24: 19 | B24: {=IF(19>COUNTIF('1_原始數據'!$C$2:$C$1000,"std_curve"),"",SMALL(IF('1_原始數據'!$C$2:$C$1000="std_curve",ROW('1_原始數據'!$C$2:$C$1000)),19))} | C24: =IF($B24="","",INDEX('1_原始數據'!$D$1:$D$1000,$B24)) | D24: =IF($B24="","",INDEX('1_原始數據'!$H$1:$H$1000,$B24)) | E24: =IF($B24="","",INDEX('1_原始數據'!$E$1:$E$1000,$B24)) | F24: =IF($B24="","",$J$7*D24+$J$8) | G24: =IF($B24="","",E24-F24)
A25: 20 | B25: {=IF(20>COUNTIF('1_原始數據'!$C$2:$C$1000,"std_curve"),"",SMALL(IF('1_原始數據'!$C$2:$C$1000="std_curve",ROW('1_原始數據'!$C$2:$C$1000)),20))} | C25: =IF($B25="","",INDEX('1_原始數據'!$D$1:$D$1000,$B25)) | D25: =IF($B25="","",INDEX('1_原始數據'!$H$1:$H$1000,$B25)) | E25: =IF($B25="","",INDEX('1_原始數據'!$E$1:$E$1000,$B25)) | F25: =IF($B25="","",$J$7*D25+$J$8) | G25: =IF($B25="","",E25-F25)
A26: 21 | B26: {=IF(21>COUNTIF('1_原始數據'!$C$2:$C$1000,"std_curve"),"",SMALL(IF('1_原始數據'!$C$2:$C$1000="std_curve",ROW('1_原始數據'!$C$2:$C$1000)),21))} | C26: =IF($B26="","",INDEX('1_原始數據'!$D$1:$D$1000,$B26)) | D26: =IF($B26="","",INDEX('1_原始數據'!$H$1:$H$1000,$B26)) | E26: =IF($B26="","",INDEX('1_原始數據'!$E$1:$E$1000,$B26)) | F26: =IF($B26="","",$J$7*D26+$J$8) | G26: =IF($B26="","",E26-F26) | I26: 2-4 缺適性 F 檢定表
A27: 22 | B27: {=IF(22>COUNTIF('1_原始數據'!$C$2:$C$1000,"std_curve"),"",SMALL(IF('1_原始數據'!$C$2:$C$1000="std_curve",ROW('1_原始數據'!$C$2:$C$1000)),22))} | C27: =IF($B27="","",INDEX('1_原始數據'!$D$1:$D$1000,$B27)) | D27: =IF($B27="","",INDEX('1_原始數據'!$H$1:$H$1000,$B27)) | E27: =IF($B27="","",INDEX('1_原始數據'!$E$1:$E$1000,$B27)) | F27: =IF($B27="","",$J$7*D27+$J$8) | G27: =IF($B27="","",E27-F27) | I27: 來源 | J27: 平方和 SS | K27: 自由度 df | L27: 均方 MS = SS/df | M27: F | N27: p 值
A28: 23 | B28: {=IF(23>COUNTIF('1_原始數據'!$C$2:$C$1000,"std_curve"),"",SMALL(IF('1_原始數據'!$C$2:$C$1000="std_curve",ROW('1_原始數據'!$C$2:$C$1000)),23))} | C28: =IF($B28="","",INDEX('1_原始數據'!$D$1:$D$1000,$B28)) | D28: =IF($B28="","",INDEX('1_原始數據'!$H$1:$H$1000,$B28)) | E28: =IF($B28="","",INDEX('1_原始數據'!$E$1:$E$1000,$B28)) | F28: =IF($B28="","",$J$7*D28+$J$8) | G28: =IF($B28="","",E28-F28) | I28: 缺適性 lack-of-fit | J28: =SUM(M14:M23) | K28: =J33-2 | L28: =J28/K28 | M28: =IF(K29>0,L28/L29,"沒有重複") | N28: =IF(K29>0,_xlfn.F.DIST.RT(M28,K28,K29),"") | P28: =SUM(M 欄)，df = L − 2（L 個濃度水準，減掉斜率和截距 2 個參數）
A29: 24 | B29: {=IF(24>COUNTIF('1_原始數據'!$C$2:$C$1000,"std_curve"),"",SMALL(IF('1_原始數據'!$C$2:$C$1000="std_curve",ROW('1_原始數據'!$C$2:$C$1000)),24))} | C29: =IF($B29="","",INDEX('1_原始數據'!$D$1:$D$1000,$B29)) | D29: =IF($B29="","",INDEX('1_原始數據'!$H$1:$H$1000,$B29)) | E29: =IF($B29="","",INDEX('1_原始數據'!$E$1:$E$1000,$B29)) | F29: =IF($B29="","",$J$7*D29+$J$8) | G29: =IF($B29="","",E29-F29) | I29: 純誤差 pure error | J29: =J10-J28 | K29: =J6-J33 | L29: =IF(K29>0,J29/K29,"") | P29: = SSE − SS_lof（和 Colab 相同算法），df = N − L
A30: 25 | B30: {=IF(25>COUNTIF('1_原始數據'!$C$2:$C$1000,"std_curve"),"",SMALL(IF('1_原始數據'!$C$2:$C$1000="std_curve",ROW('1_原始數據'!$C$2:$C$1000)),25))} | C30: =IF($B30="","",INDEX('1_原始數據'!$D$1:$D$1000,$B30)) | D30: =IF($B30="","",INDEX('1_原始數據'!$H$1:$H$1000,$B30)) | E30: =IF($B30="","",INDEX('1_原始數據'!$E$1:$E$1000,$B30)) | F30: =IF($B30="","",$J$7*D30+$J$8) | G30: =IF($B30="","",E30-F30) | I30: 殘差合計 SSE | J30: =J10 | K30: =J6-2 | P30: df = N − 2
A31: 26 | B31: {=IF(26>COUNTIF('1_原始數據'!$C$2:$C$1000,"std_curve"),"",SMALL(IF('1_原始數據'!$C$2:$C$1000="std_curve",ROW('1_原始數據'!$C$2:$C$1000)),26))} | C31: =IF($B31="","",INDEX('1_原始數據'!$D$1:$D$1000,$B31)) | D31: =IF($B31="","",INDEX('1_原始數據'!$H$1:$H$1000,$B31)) | E31: =IF($B31="","",INDEX('1_原始數據'!$E$1:$E$1000,$B31)) | F31: =IF($B31="","",$J$7*D31+$J$8) | G31: =IF($B31="","",E31-F31)
A32: 27 | B32: {=IF(27>COUNTIF('1_原始數據'!$C$2:$C$1000,"std_curve"),"",SMALL(IF('1_原始數據'!$C$2:$C$1000="std_curve",ROW('1_原始數據'!$C$2:$C$1000)),27))} | C32: =IF($B32="","",INDEX('1_原始數據'!$D$1:$D$1000,$B32)) | D32: =IF($B32="","",INDEX('1_原始數據'!$H$1:$H$1000,$B32)) | E32: =IF($B32="","",INDEX('1_原始數據'!$E$1:$E$1000,$B32)) | F32: =IF($B32="","",$J$7*D32+$J$8) | G32: =IF($B32="","",E32-F32)
A33: 28 | B33: {=IF(28>COUNTIF('1_原始數據'!$C$2:$C$1000,"std_curve"),"",SMALL(IF('1_原始數據'!$C$2:$C$1000="std_curve",ROW('1_原始數據'!$C$2:$C$1000)),28))} | C33: =IF($B33="","",INDEX('1_原始數據'!$D$1:$D$1000,$B33)) | D33: =IF($B33="","",INDEX('1_原始數據'!$H$1:$H$1000,$B33)) | E33: =IF($B33="","",INDEX('1_原始數據'!$E$1:$E$1000,$B33)) | F33: =IF($B33="","",$J$7*D33+$J$8) | G33: =IF($B33="","",E33-F33) | I33: 濃度水準數 L | J33: =COUNT(I14:I23) | P33: F = MS_lof ÷ MS_pe。F 越大，代表「彎曲」比「雜訊」大越多。
A34: 29 | B34: {=IF(29>COUNTIF('1_原始數據'!$C$2:$C$1000,"std_curve"),"",SMALL(IF('1_原始數據'!$C$2:$C$1000="std_curve",ROW('1_原始數據'!$C$2:$C$1000)),29))} | C34: =IF($B34="","",INDEX('1_原始數據'!$D$1:$D$1000,$B34)) | D34: =IF($B34="","",INDEX('1_原始數據'!$H$1:$H$1000,$B34)) | E34: =IF($B34="","",INDEX('1_原始數據'!$E$1:$E$1000,$B34)) | F34: =IF($B34="","",$J$7*D34+$J$8) | G34: =IF($B34="","",E34-F34) | I34: F 臨界值（α = 0.05） | J34: =IF(K29>0,_xlfn.F.INV.RT(0.05,K28,K29),"") | P34: =F.INV.RT(0.05, df_lof, df_pe) F 超過這個值就顯著。
A35: 30 | B35: {=IF(30>COUNTIF('1_原始數據'!$C$2:$C$1000,"std_curve"),"",SMALL(IF('1_原始數據'!$C$2:$C$1000="std_curve",ROW('1_原始數據'!$C$2:$C$1000)),30))} | C35: =IF($B35="","",INDEX('1_原始數據'!$D$1:$D$1000,$B35)) | D35: =IF($B35="","",INDEX('1_原始數據'!$H$1:$H$1000,$B35)) | E35: =IF($B35="","",INDEX('1_原始數據'!$E$1:$E$1000,$B35)) | F35: =IF($B35="","",$J$7*D35+$J$8) | G35: =IF($B35="","",E35-F35) | I35: 結論 | J35: =IF(K29<=0,"沒有重複，無法檢定",IF(N28<0.05,"p < 0.05：有顯著缺適性，直線不夠好","p ≥ 0.05：沒有證據顯示偏離直線")) | P35: p 值 =F.DIST.RT(F, df_lof, df_pe)：右尾機率。本例 p ≈ 0.04 < 0.05，R² 雖然 0.999，直線仍有顯著缺適性。
I36: 驗算：純誤差直接加總 ΣN 欄 | J36: =SUM(N14:N23) | P36: 應該和 J29 一樣：兩種算法得到同一個純誤差。
A37: B 欄 {=SMALL(IF(item="std_curve", 列號), k)}：找出第 k 個標準品在原始數據的第幾列，C–E 欄再用 INDEX(欄, 列號) 把 rep、濃度、吸光值抓過來。最多 30 點。
I38: 實務建議：有顯著缺適性時，可以 (1) 縮小工作範圍（例如只用 0–80 µg/mL），(2) 改用二次曲線，或 (3) 把樣品稀釋到曲線中段再測。只看 R² 永遠不會發現這個問題。Excel「資料分析 → 迴歸」不會做缺適性檢定，所以這裡用公式做。

Sheet 4_LOD_LOQ
B1: 步驟 3 偵測極限 LOD 與定量極限 LOQ：兩種 σ
B2: LOD = 3.3σ ÷ 斜率，LOQ = 10σ ÷ 斜率（單位 µg/mL）。σ 有兩種取法，報告時一定要註明用哪一種。
B4: 項目 | C4: 殘差 SD 法 | D4: 空白 SD 法
B5: σ 的來源 | C5: ="標準曲線第 "&'2_標準曲線'!$E$4&" 重複的 STEYX" | D5: ="試劑空白重複讀值 STDEV.S" | F5: 兩種 σ 都「對」，但意義不同。
B6: 空白的 item 名稱 | C6: — | D6: reagent_blank_490nm
B7: n | C7: ='2_標準曲線'!$I$7 | D7: =COUNTIFS('1_原始數據'!$C$2:$C$1000,D6) | F7: 殘差 SD 法用標準點數；空白 SD 法用空白讀了幾次（=COUNTIFS 數 item 名稱出現幾次）。
B8: 空白平均 (AU) | C8: — | D8: =AVERAGEIFS('1_原始數據'!$E$2:$E$1000,'1_原始數據'!$C$2:$C$1000,D6)
B9: σ (AU) | C9: ='2_標準曲線'!$I$11 | D9: {=_xlfn.STDEV.S(IF('1_原始數據'!$C$2:$C$1000=D6,'1_原始數據'!$E$2:$E$1000))} | F9: 殘差 SD：=STEYX（在「2_標準曲線」I11），反映整條曲線的擬合品質，也包含曲線彎曲（缺適性）。空白 SD：{=STDEV.S(IF(item=空白名稱, value))}，只看零濃度附近的儀器雜訊。
B10: 斜率 m（步驟 1） | C10: ='2_標準曲線'!$I$8 | D10: ='2_標準曲線'!$I$8
B11: LOD = 3.3σ/m (µg/mL) | C11: =3.3*C9/C10 | D11: =3.3*D9/D10 | F11: 3.3 和 10 是 ICH Q2 的慣用係數。σ 的單位是 AU，除以斜率（AU per µg/mL）後變成濃度單位。
B12: LOQ = 10σ/m (µg/mL) | C12: =10*C9/C10 | D12: =10*D9/D10 | F12: 空白 SD 法通常比較小、比較樂觀；殘差 SD 法把整條曲線的彎曲也算進去，比較保守，比較能代表「整個工作範圍都適用」的偵測極限。
B13: 最低的非零標準濃度 (µg/mL) | C13: {=MIN(IF(ISNUMBER('2_標準曲線'!$B$7:$B$16),IF('2_標準曲線'!$B$7:$B$16>0,'2_標準曲線'!$B$7:$B$16)))} | F13: {=MIN(IF(ISNUMBER(濃度),IF(濃度>0,濃度)))} 從「2_標準曲線」B 欄找大於 0 的最小濃度。
B14: LOQ 低於最低非零標準點嗎？ | C14: =IF(C12<$C$13,"是","否：最低標準點在 LOQ 以下") | D14: =IF(D12<$C$13,"是","否：最低標準點在 LOQ 以下") | F14: LOQ 最好低於最低非零標準點，否則最低那一點本身就不能可靠定量。
B16: 報告寫法範例：「LOD 為 3.5 µg/mL、LOQ 為 10.6 µg/mL（σ 採標準曲線殘差標準差，n = 6）」。樣品在反應液中的濃度低於 LOQ 時，只能寫「< LOQ」，不能報數字。

Sheet 5_樣品換算
A1: 步驟 4 未知樣品：吸光值 → 反應液濃度 → g/100 mL 葡萄糖當量
A2: C₀ = (A − b) ÷ m（µg/mL）；總醣 (g/100 mL) = C₀ × 稀釋倍數 × 10⁻⁴。（1 µg/mL = 10⁻⁶ g/mL，×100 mL → 10⁻⁴ g/100 mL）。顏色深的樣品要先扣「樣品空白」。
A5: 樣品 item | B5: 樣品空白 item（沒有就留空） | C5: 讀值次數 k | D5: A 平均 | E5: A 樣品空白 | F5: A 校正後 | G5: 稀釋倍數 DF | H5: C₀ (µg/mL) | I5: s(C₀) (µg/mL) | J5: 判讀 | K5: 總醣 (g/100 mL) | L5: ± SD (g/100 mL) | M5: 報告寫法
A6: unknown_sports_drink | C6: =IF($A6="","",COUNTIFS('1_原始數據'!$C$2:$C$1000,$A6)) | D6: =IF($A6="","",AVERAGEIFS('1_原始數據'!$E$2:$E$1000,'1_原始數據'!$C$2:$C$1000,$A6)) | E6: =IF($A6="","",IF($B6="",0,AVERAGEIFS('1_原始數據'!$E$2:$E$1000,'1_原始數據'!$C$2:$C$1000,$B6))) | F6: =IF($A6="","",D6-E6) | G6: =IF($A6="","",AVERAGEIFS('1_原始數據'!$I$2:$I$1000,'1_原始數據'!$C$2:$C$1000,$A6)) | H6: =IF($A6="","",(F6-'2_標準曲線'!$I$9)/'2_標準曲線'!$I$8) | I6: =IF($A6="","",('2_標準曲線'!$I$11/'2_標準曲線'!$I$8)*SQRT(1/C6+1/'2_標準曲線'!$I$7+(F6-'2_標準曲線'!$I$15)^2/('2_標準曲線'!$I$8^2*'2_標準曲線'!$I$16))) | J6: =IF($A6="","",IF(H6>'2_標準曲線'!$I$18,"超出曲線上限：加大稀釋",IF(H6<'4_LOD_LOQ'!$C$12,"低於 LOQ：減少稀釋","在曲線範圍內"))) | K6: =IF($A6="","",H6*G6*1E-4) | L6: =IF($A6="","",I6*G6*1E-4) | M6: =IF($A6="","",FIXED(K6,2)&" ± "&FIXED(L6,2)&" g/100 mL")
A7: unknown_orange_juice_phenol | C7: =IF($A7="","",COUNTIFS('1_原始數據'!$C$2:$C$1000,$A7)) | D7: =IF($A7="","",AVERAGEIFS('1_原始數據'!$E$2:$E$1000,'1_原始數據'!$C$2:$C$1000,$A7)) | E7: =IF($A7="","",IF($B7="",0,AVERAGEIFS('1_原始數據'!$E$2:$E$1000,'1_原始數據'!$C$2:$C$1000,$B7))) | F7: =IF($A7="","",D7-E7) | G7: =IF($A7="","",AVERAGEIFS('1_原始數據'!$I$2:$I$1000,'1_原始數據'!$C$2:$C$1000,$A7)) | H7: =IF($A7="","",(F7-'2_標準曲線'!$I$9)/'2_標準曲線'!$I$8) | I7: =IF($A7="","",('2_標準曲線'!$I$11/'2_標準曲線'!$I$8)*SQRT(1/C7+1/'2_標準曲線'!$I$7+(F7-'2_標準曲線'!$I$15)^2/('2_標準曲線'!$I$8^2*'2_標準曲線'!$I$16))) | J7: =IF($A7="","",IF(H7>'2_標準曲線'!$I$18,"超出曲線上限：加大稀釋",IF(H7<'4_LOD_LOQ'!$C$12,"低於 LOQ：減少稀釋","在曲線範圍內"))) | K7: =IF($A7="","",H7*G7*1E-4) | L7: =IF($A7="","",I7*G7*1E-4) | M7: =IF($A7="","",FIXED(K7,2)&" ± "&FIXED(L7,2)&" g/100 mL")
A8: unknown_maple_syrup | C8: =IF($A8="","",COUNTIFS('1_原始數據'!$C$2:$C$1000,$A8)) | D8: =IF($A8="","",AVERAGEIFS('1_原始數據'!$E$2:$E$1000,'1_原始數據'!$C$2:$C$1000,$A8)) | E8: =IF($A8="","",IF($B8="",0,AVERAGEIFS('1_原始數據'!$E$2:$E$1000,'1_原始數據'!$C$2:$C$1000,$B8))) | F8: =IF($A8="","",D8-E8) | G8: =IF($A8="","",AVERAGEIFS('1_原始數據'!$I$2:$I$1000,'1_原始數據'!$C$2:$C$1000,$A8)) | H8: =IF($A8="","",(F8-'2_標準曲線'!$I$9)/'2_標準曲線'!$I$8) | I8: =IF($A8="","",('2_標準曲線'!$I$11/'2_標準曲線'!$I$8)*SQRT(1/C8+1/'2_標準曲線'!$I$7+(F8-'2_標準曲線'!$I$15)^2/('2_標準曲線'!$I$8^2*'2_標準曲線'!$I$16))) | J8: =IF($A8="","",IF(H8>'2_標準曲線'!$I$18,"超出曲線上限：加大稀釋",IF(H8<'4_LOD_LOQ'!$C$12,"低於 LOQ：減少稀釋","在曲線範圍內"))) | K8: =IF($A8="","",H8*G8*1E-4) | L8: =IF($A8="","",I8*G8*1E-4) | M8: =IF($A8="","",FIXED(K8,2)&" ± "&FIXED(L8,2)&" g/100 mL")
A9: unknown_winter_melon_tea | B9: winter_melon_tea_sample_blank | C9: =IF($A9="","",COUNTIFS('1_原始數據'!$C$2:$C$1000,$A9)) | D9: =IF($A9="","",AVERAGEIFS('1_原始數據'!$E$2:$E$1000,'1_原始數據'!$C$2:$C$1000,$A9)) | E9: =IF($A9="","",IF($B9="",0,AVERAGEIFS('1_原始數據'!$E$2:$E$1000,'1_原始數據'!$C$2:$C$1000,$B9))) | F9: =IF($A9="","",D9-E9) | G9: =IF($A9="","",AVERAGEIFS('1_原始數據'!$I$2:$I$1000,'1_原始數據'!$C$2:$C$1000,$A9)) | H9: =IF($A9="","",(F9-'2_標準曲線'!$I$9)/'2_標準曲線'!$I$8) | I9: =IF($A9="","",('2_標準曲線'!$I$11/'2_標準曲線'!$I$8)*SQRT(1/C9+1/'2_標準曲線'!$I$7+(F9-'2_標準曲線'!$I$15)^2/('2_標準曲線'!$I$8^2*'2_標準曲線'!$I$16))) | J9: =IF($A9="","",IF(H9>'2_標準曲線'!$I$18,"超出曲線上限：加大稀釋",IF(H9<'4_LOD_LOQ'!$C$12,"低於 LOQ：減少稀釋","在曲線範圍內"))) | K9: =IF($A9="","",H9*G9*1E-4) | L9: =IF($A9="","",I9*G9*1E-4) | M9: =IF($A9="","",FIXED(K9,2)&" ± "&FIXED(L9,2)&" g/100 mL")
C10: =IF($A10="","",COUNTIFS('1_原始數據'!$C$2:$C$1000,$A10)) | D10: =IF($A10="","",AVERAGEIFS('1_原始數據'!$E$2:$E$1000,'1_原始數據'!$C$2:$C$1000,$A10)) | E10: =IF($A10="","",IF($B10="",0,AVERAGEIFS('1_原始數據'!$E$2:$E$1000,'1_原始數據'!$C$2:$C$1000,$B10))) | F10: =IF($A10="","",D10-E10) | G10: =IF($A10="","",AVERAGEIFS('1_原始數據'!$I$2:$I$1000,'1_原始數據'!$C$2:$C$1000,$A10)) | H10: =IF($A10="","",(F10-'2_標準曲線'!$I$9)/'2_標準曲線'!$I$8) | I10: =IF($A10="","",('2_標準曲線'!$I$11/'2_標準曲線'!$I$8)*SQRT(1/C10+1/'2_標準曲線'!$I$7+(F10-'2_標準曲線'!$I$15)^2/('2_標準曲線'!$I$8^2*'2_標準曲線'!$I$16))) | J10: =IF($A10="","",IF(H10>'2_標準曲線'!$I$18,"超出曲線上限：加大稀釋",IF(H10<'4_LOD_LOQ'!$C$12,"低於 LOQ：減少稀釋","在曲線範圍內"))) | K10: =IF($A10="","",H10*G10*1E-4) | L10: =IF($A10="","",I10*G10*1E-4) | M10: =IF($A10="","",FIXED(K10,2)&" ± "&FIXED(L10,2)&" g/100 mL")
C11: =IF($A11="","",COUNTIFS('1_原始數據'!$C$2:$C$1000,$A11)) | D11: =IF($A11="","",AVERAGEIFS('1_原始數據'!$E$2:$E$1000,'1_原始數據'!$C$2:$C$1000,$A11)) | E11: =IF($A11="","",IF($B11="",0,AVERAGEIFS('1_原始數據'!$E$2:$E$1000,'1_原始數據'!$C$2:$C$1000,$B11))) | F11: =IF($A11="","",D11-E11) | G11: =IF($A11="","",AVERAGEIFS('1_原始數據'!$I$2:$I$1000,'1_原始數據'!$C$2:$C$1000,$A11)) | H11: =IF($A11="","",(F11-'2_標準曲線'!$I$9)/'2_標準曲線'!$I$8) | I11: =IF($A11="","",('2_標準曲線'!$I$11/'2_標準曲線'!$I$8)*SQRT(1/C11+1/'2_標準曲線'!$I$7+(F11-'2_標準曲線'!$I$15)^2/('2_標準曲線'!$I$8^2*'2_標準曲線'!$I$16))) | J11: =IF($A11="","",IF(H11>'2_標準曲線'!$I$18,"超出曲線上限：加大稀釋",IF(H11<'4_LOD_LOQ'!$C$12,"低於 LOQ：減少稀釋","在曲線範圍內"))) | K11: =IF($A11="","",H11*G11*1E-4) | L11: =IF($A11="","",I11*G11*1E-4) | M11: =IF($A11="","",FIXED(K11,2)&" ± "&FIXED(L11,2)&" g/100 mL")
A13: A 欄：樣品在原始數據的 item 名稱（黃色，可以改或往下加）。B 欄：同稀釋倍數的樣品空白（顏色空白）item 名稱；沒有就留空＝扣 0。
A14: D、E、G 欄：=AVERAGEIFS(value 或 dilution_factor, item, 名稱) 同一個樣品讀了好幾次就自動取平均，k 就是次數。
A15: H 欄：C₀ = (A校正後 − b) ÷ m，m、b 來自「2_標準曲線」I8、I9。
A16: I 欄：預測不確定度 s(C₀) = (s_y/m) × √[1/k + 1/n + (A − Ā)² / (m² × Sxx)]。k＝樣品讀值次數，n＝標準點數。A 越靠近標準品平均 Ā，不確定度越小，所以樣品最好落在曲線中段。
A17: J 欄：C₀ 高於最高標準點就是外插，不可信，要加大稀釋重做；低於 LOQ（「4_LOD_LOQ」殘差 SD 法）要減少稀釋。
A18: K、L 欄：乘上稀釋倍數 × 10⁻⁴ 換成 g/100 mL 葡萄糖當量。SD 也要乘同樣的倍數：稀釋倍數越大，誤差也被放大越多（看楓糖漿）。
A20: 4-1 冬瓜茶：扣不扣樣品空白差多少？（用上表第 9 列）
A21: 原始讀值 A_raw | B21: =D9 | C21: 冬瓜茶顏色很深，樣品本身就會吸收 490 nm 的光。樣品空白＝同稀釋倍數、不加酚／硫酸（或以水代替）的讀值，要先從樣品讀值扣掉。練習題 1 請用這兩格算高估了多少。
A22: 樣品顏色空白 A_blank | B22: =E9
A23: 若忘記扣空白：總醣 (g/100 mL) | B23: =(D9-'2_標準曲線'!$I$9)/'2_標準曲線'!$I$8*G9*1E-4
A24: 扣除空白後：總醣 (g/100 mL) | B24: =K9
A26: 4-2 反推：換一個稀釋倍數，吸光值會變成多少？
A27: 樣品總醣 (g/100 mL)（預設＝柳橙汁 K7） | B27: =K7 | C27: 把 B28 改成不同的稀釋倍數試試看。稀釋倍數選得好，C 會落在曲線中段（不確定度最小）；選得不好，會超出曲線或低於 LOQ，就要重做。
A28: 新的稀釋倍數 DF | B28: 1000
A29: 反應液濃度 C = 總醣 ÷ (DF × 10⁻⁴) (µg/mL) | B29: =B27/(B28*1E-4)
A30: 預期吸光值 A = m × C + b | B30: ='2_標準曲線'!$I$8*B29+'2_標準曲線'!$I$9
A31: 在曲線範圍內嗎？ | B31: =IF(B29>'2_標準曲線'!$I$18,"否：超出最高標準點",IF(B29<'4_LOD_LOQ'!$C$12,"否：低於 LOQ","是"))

Sheet 6_Brix比較
B1: 步驟 5 柳橙汁：Brix vs 酚硫酸法總醣
B2: Brix 用折射率換算「可溶性固形物」；酚硫酸法只有醣類會顯色。柳橙汁裡還有酸等可溶物，所以 °Brix 通常比總醣大。
B4: Brix 讀值的 item 名稱 | C4: orange_juice_brix | E4: 黃色，可以改。 | G4: 圖用輔助數據
B5: 柳橙汁 Brix (°Brix) | C5: =AVERAGEIFS('1_原始數據'!$E$2:$E$1000,'1_原始數據'!$C$2:$C$1000,C4) | E5: =AVERAGEIFS(value, item, 名稱) 讀好幾次就取平均。 | G5: method | H5: value
B6: 酚硫酸法樣品的 item 名稱 | C6: unknown_orange_juice_phenol | E6: 要和「5_樣品換算」A 欄的名稱一樣。 | G6: Brix (degBrix) | H6: =C5
B7: 酚硫酸法總醣 (g/100 mL) | C7: =INDEX('5_樣品換算'!$K$6:$K$11,MATCH(C6,'5_樣品換算'!$A$6:$A$11,0)) | E7: =INDEX(總醣欄, MATCH(名稱, 樣品欄, 0)) 到「5_樣品換算」找這個樣品那一列的總醣。 | G7: Phenol-sulfuric (g/100 mL) | H7: =C7
B8: ± SD (g/100 mL) | C8: =INDEX('5_樣品換算'!$L$6:$L$11,MATCH(C6,'5_樣品換算'!$A$6:$A$11,0))
B9: 差距 = Brix − 總醣 | C9: =C5-C7 | E9: 差距主要來自酸（檸檬酸）和其他可溶性固形物。
B10: 非糖部分佔 Brix 的比例 (%) | C10: =C9/C5*100 | E10: =差距 ÷ Brix × 100
B12: 補充：單位換成一致再比
B13: 柳橙汁密度 (g/mL) | C13: 1.045 | E13: 黃色，可以改（柳橙汁約 1.04–1.05 g/mL）。
B14: Brix 換成 g/100 mL = °Brix × 密度 | C14: =C5*C13 | E14: Brix 的定義是 g/100 g（w/w），酚硫酸法是 g/100 mL（w/v）；乘上密度才同單位。
B15: 單位一致後的差距 (g/100 mL) | C15: =C14-C7 | E15: 方向不變：Brix 仍然比較大。重點是理解差距的方向，不是要兩者數值相等。
B17: 溫度提醒：折射計以 20 °C 為對照溫度。有自動溫度補償（ATC）的儀器不用自己校正；沒有 ATC 時，請在建議溫度範圍內操作，不要亂套校正公式。

Sheet 7_楓糖漿質量守恆
B1: 步驟 6 楓糖漿質量守恆：「40 加侖樹液 = 1 加侖糖漿」是真的嗎？
B2: 糖的質量在熬煮前後不變：樹液質量 × 樹液糖度 = 糖漿質量 × 糖漿糖度。
B4: 樹液糖度 (% w/w) | C4: 2 | E4: 黃色都可以改。練習題 5 把樹液糖度改成 2.2。
B5: 糖漿糖度 (% w/w) | C5: 66
B6: 樹液密度 (g/mL) | C6: 1.008
B7: 糖漿密度 (g/mL) | C7: 1.33
B9: 質量比（樹液 : 糖漿） | C9: =C5/C4 | E9: = 糖漿糖度 ÷ 樹液糖度
B10: 體積比（密度校正後） | C10: =C9*C7/C6 | E10: = 質量比 × ρ糖漿 ÷ ρ樹液。工廠說的 40：1 是體積比。
B11: Rule of 86：86 ÷ 樹液 °Brix | C11: =86/C4 | E11: 經驗法則（以樹液糖度 % 近似 °Brix），應和體積比接近。
B12: 體積比剛好 40：1 時，樹液糖度要多少 (%) | C12: =C5*C7/C6/40 | E12: = 糖漿糖度 × ρ糖漿 ÷ ρ樹液 ÷ 40
B14: 對照：本班測到的楓糖漿總醣 (g/100 mL) | C14: =INDEX('5_樣品換算'!$K$6:$K$11,MATCH("unknown_maple_syrup",'5_樣品換算'!$A$6:$A$11,0)) | E14: 從「5_樣品換算」抓 unknown_maple_syrup 的結果。
B15: 換成 % w/w = g/100 mL ÷ 糖漿密度 | C15: =C14/C7 | E15: 和 C5 的 66% 比較。酚硫酸法以葡萄糖當量計，楓糖漿主要是蔗糖，只是量級驗算。

Sheet 8_銅還原法概念
B1: 補充 乙級方法概念：銅還原滴定法（Bertrand）
B2: 本堂課不操作，只示範計算邏輯。數字是通用示意值，不是本班實測。還原糖把 Cu²⁺ 還原成 Cu₂O → Cu₂O 把 Fe³⁺ 還原成 Fe²⁺（1:1 當量）→ 用 KMnO₄ 滴定 Fe²⁺。
B4: KMnO₄ 滴定體積 V (mL) | C4: 15.2
B5: KMnO₄ 當量濃度 N (eq/L) | C5: 0.1
B7: meq Cu = meq Fe²⁺ = V × N | C7: =C4*C5 | E7: mL × eq/L = meq。Cu⁺ → Cu²⁺ 放出 1 個電子，所以 1 meq = 1 mmol Cu。
B8: mg Cu = meq × 63.55 | C8: =C7*63.55 | E8: 63.55 = 銅的莫耳質量 (g/mol) = mg/mmol。下一步查 Bertrand 表，把 mg Cu 換成還原糖 mg（表格是方法規定值，這裡不重現）。

Sheet 練習題
B1: 練習題（寫在黃色格子裡，交報告時一起附上）
B3: 問題 1：冬瓜茶如果忘記扣除自身顏色的樣品空白，總醣會被高估還是低估？請算出高估的量（g/100 mL）與相對 %。
B4: 提示：「5_樣品換算」B23（忘記扣）和 B24（扣除後）相減；相對 % = 差 ÷ B24 × 100。
B7: 問題 2：缺適性 F 檢定的 p 值是多少？這對「能不能信任這條標準曲線」有什麼實務建議（要不要改用二次曲線、要不要縮小工作範圍）？
B8: 提示：看「3_缺適性檢定」N28 與 J35，再對照「2_標準曲線」的殘差圖是什麼形狀。
B11: 問題 3：如果柳橙汁改用 DF = 1000（而不是 2000）稀釋，吸光值大約會是多少？還在標準曲線 0–100 µg/mL 的範圍內嗎？為什麼選對稀釋倍數很重要？
B12: 提示：「5_樣品換算」4-2 反推區：B28 填 1000，看 B29、B30、B31；再想想 I 欄的不確定度公式裡 (A − Ā)² 那一項。
B15: 問題 4：「4_LOD_LOQ」算出殘差 SD 法和空白 SD 法兩種 LOD。正式報告你會選哪一種？為什麼？
B16: 提示：比較 C11 和 D11，並想想哪一種 σ 包含了曲線彎曲（步驟 2 的結果）。
B19: 問題 5：如果某批楓樹液糖度實測是 2.2%（不是 2%），Rule of 86 與密度校正後的體積比各變成多少？兩者還吻合嗎？
B20: 提示：「7_楓糖漿質量守恆」C4 改成 2.2，看 C10 與 C11。做完改回 2。
