Workbook

Sheet 0_說明
B1: EX08｜W8 全班能力試驗與數據品管
B2: 食品分析實驗・入門數據分析（Excel 版）。不用寫程式；同一份數據在 Colab 筆記本做進階分析，答案應該一致。
B4: 學習目標
B5: • 把 5 組的水分、灰分、蛋白質、脂肪彙整成 proximate 表，用差減法算碳水化合物。
B6: • 用 T.INV 算 Grubbs 臨界值，比較組內 n=3 與班級層級 n=5 的離群值檢定力。
B7: • 用公式做一元 ANOVA（SS、MS、F、F.DIST.RT 的 p 值），分出重複性 s_r 與再現性 s_R。
B8: • 算 z-score（指定值＝中位數、σ_pt 固定 0.40%），依 |z|≤2／2<|z|<3／|z|≥3 分成滿意／問題／不滿意。
B9: • 畫 Shewhart 管制圖（±2s／±3s），用 Westgard 規則找出違規的 run。
B10: • 建立蛋白質不確定度預算：平方和開根號得到 u_c，U = k·u_c（k=2）；再用 guard band 做放行判定。
B11: • 跟 USDA／TFND 資料庫比，分辨「我這組有問題」和「全班／方法有問題」。
B13: 顏色代表什麼
C14: 黃色：輸入或貼上數據的地方
C15: 綠色：公式，會自動計算，不要改
C16: 橘色：重點結果，寫報告時用
B18: 操作步驟
B19: 1. 看「1_原始數據」：一列是一個量測值。G1–G5 是 5 組盲樣，QC 是管制圖樣品，TA 是助教的蛋白質重複。
B20: 2. 「2_組成表」：各組 proximate 表與差減法碳水化合物。
B21: 3. 「3_Grubbs離群」：先看臨界值表（n=3 為什麼測不出來），再做組內與班級層級的檢定。
B22: 4. 「4_ANOVA」：灰分的一元 ANOVA、s_r／s_L／s_R；可用資料分析工具箱對答案。
B23: 5. 「5_z分數」：每組蛋白質的 z-score 與分級，看長條圖。
B24: 6. 「6_管制圖」：QC 樣品 12 次 run 的管制圖與 5 條 Westgard 規則。
B25: 7. 「7_不確定度」：蛋白質不確定度預算與碳水化合物的 U。
B26: 8. 「8_放行判定」：6 個案例的放行／不放行／無法判斷；可加入自己的案例。
B27: 9. 「9_資料庫比對」：全班結果 vs USDA／TFND，找出脂肪的方法偏差。
B28: 10. 完成「練習題」。換成班級數據：把共用 Google Sheet 的數據貼到「1_原始數據」A2 起（組別須為 G1–G5，或改「2_組成表」A 欄）。
B30: 對答案：用內建範例數據時，你的結果應該等於
B31: 項目 | C31: 本檔計算值 | D31: Colab 筆記本的值 | E31: 一致？
B32: G1 碳水化合物（差減法, %） | C32: ='2_組成表'!F6 | D32: 44.49 | E32: =IF(ABS(C32-D32)<=0.004449001000000001,"✔ 一致","✘ 不一致（換成班級數據後本來就會不同）")
B33: G_crit (n=3, α=0.05) | C33: ='3_Grubbs離群'!D8 | D33: 1.1543049 | E33: =IF(ABS(C33-D33)<=0.00011543148513440387,"✔ 一致","✘ 不一致（換成班級數據後本來就會不同）")
B34: G4 蛋白質 Grubbs G（班級層級） | C34: ='3_Grubbs離群'!C51 | D34: 1.7750597 | E34: =IF(ABS(C34-D34)<=0.00017750696785096017,"✔ 一致","✘ 不一致（換成班級數據後本來就會不同）")
B35: 灰分 ANOVA F | C35: ='4_ANOVA'!F20 | D35: 14.242574 | E35: =IF(ABS(C35-D35)<=0.001424258425742591,"✔ 一致","✘ 不一致（換成班級數據後本來就會不同）")
B36: 灰分 ANOVA p 值 | C36: ='4_ANOVA'!G20 | D36: 0.00038996836 | E36: =IF(ABS(C36-D36)<=3.999683611692361e-08,"✔ 一致","✘ 不一致（換成班級數據後本來就會不同）")
B37: G4 蛋白質 z-score | C37: ='5_z分數'!D13 | D37: -3.825 | E37: =IF(ABS(C37-D37)<=0.00038250100000000004,"✔ 一致","✘ 不一致（換成班級數據後本來就會不同）")
B38: 蛋白質擴充不確定度 U (k=2, %) | C38: ='7_不確定度'!C18 | D38: 0.3758188 | E38: =IF(ABS(C38-D38)<=3.7582879867746255e-05,"✔ 一致","✘ 不一致（換成班級數據後本來就會不同）")
B39: 碳水化合物 U_碳水 (k=2, %) | C39: ='7_不確定度'!C31 | D39: 0.81660258 | E39: =IF(ABS(C39-D39)<=8.166125774141122e-05,"✔ 一致","✘ 不一致（換成班級數據後本來就會不同）")
B40: 「Colab 筆記本的值」是用內建模擬數據算出的答案；換成全班數據後，這一欄就不再適用。
B42: 相關連結
B43: 本週實驗投影片 | C43: https://tai-shengyeh.github.io/food-analysis-lab/labs/w08_proficiency/index.html
B44: Orange 流程檔 | C44: https://tai-shengyeh.github.io/food-analysis-lab/orange/OR08_proficiency_anova.ows
B45: 進階：Colab 筆記本（Python） | C45: https://colab.research.google.com/github/Tai-ShengYeh/food-analysis-lab/blob/main/notebooks/NB08_proficiency_qc.ipynb
...

Sheet 1_原始數據
A1: group | B1: student | C1: item | D1: rep | E1: value | F1: unit | G1: temp_C | H1: note | J1: 這張工作表怎麼用
A2: G1 | B2: G1 | C2: moisture | D2: 1 | E2: 2.75 | F2: % | J2: 本週欄位：group＝組別（G1–G5 是 5 組共同盲樣；QC＝管制圖的檢核樣品；TA＝助教的蛋白質重複性數據）。
A3: G1 | B3: G1 | C3: moisture | D3: 2 | E3: 2.78 | F3: % | J3: item＝項目：moisture 水分、ash 灰分、protein 蛋白質（每組單次測定）、fat 脂肪（W6 直接 Soxhlet 三重複）、fat_qc_check QC 檢核樣品（rep＝第幾次 run）、protein_repeatability 助教蛋白質三重複。
A4: G1 | B4: G1 | C4: moisture | D4: 3 | E4: 2.8 | F4: % | J4: value＝量測值（%）。temp_C 本週不用，留空。
A5: G1 | B5: G1 | C5: ash | D5: 1 | E5: 5.95 | F5: % | J5: 黃色欄位＝原始數據。換成全班數據時：從共用 Google Sheet 複製，貼到 A2（欄位順序必須一樣），舊資料多出來的列要整列刪除。
A6: G1 | B6: G1 | C6: ash | D6: 2 | E6: 6.02 | F6: % | J6: 綠色欄位＝公式，會自動算到第 1000 列，不要手動修改。
A7: G1 | B7: G1 | C7: ash | D7: 3 | E7: 5.98 | F7: %
A8: G1 | B8: G1 | C8: protein | D8: 1 | E8: 25.93 | F8: %
A9: G1 | B9: G1 | C9: fat | D9: 1 | E9: 21.13 | F9: % | H9: W6 直接 Soxhlet(未水解) 盲樣三重複
A10: G1 | B10: G1 | C10: fat | D10: 2 | E10: 20.78 | F10: % | H10: W6 直接 Soxhlet(未水解) 盲樣三重複
A11: G1 | B11: G1 | C11: fat | D11: 3 | E11: 20.55 | F11: % | H11: W6 直接 Soxhlet(未水解) 盲樣三重複
A12: G2 | B12: G2 | C12: moisture | D12: 1 | E12: 2.85 | F12: %
A13: G2 | B13: G2 | C13: moisture | D13: 2 | E13: 2.88 | F13: %
A14: G2 | B14: G2 | C14: moisture | D14: 3 | E14: 2.83 | F14: %
A15: G2 | B15: G2 | C15: ash | D15: 1 | E15: 6.1 | F15: %
A16: G2 | B16: G2 | C16: ash | D16: 2 | E16: 6.05 | F16: %
A17: G2 | B17: G2 | C17: ash | D17: 3 | E17: 6.08 | F17: %
A18: G2 | B18: G2 | C18: protein | D18: 1 | E18: 26.17 | F18: %
A19: G2 | B19: G2 | C19: fat | D19: 1 | E19: 21.84 | F19: % | H19: W6 直接 Soxhlet(未水解) 盲樣三重複
A20: G2 | B20: G2 | C20: fat | D20: 2 | E20: 22.06 | F20: % | H20: W6 直接 Soxhlet(未水解) 盲樣三重複
A21: G2 | B21: G2 | C21: fat | D21: 3 | E21: 21.89 | F21: % | H21: W6 直接 Soxhlet(未水解) 盲樣三重複
A22: G3 | B22: G3 | C22: moisture | D22: 1 | E22: 2.7 | F22: %
A23: G3 | B23: G3 | C23: moisture | D23: 2 | E23: 2.74 | F23: %
A24: G3 | B24: G3 | C24: moisture | D24: 3 | E24: 3.3 | F24: % | H24: 疑似離群值 (possible outlier)
A25: G3 | B25: G3 | C25: ash | D25: 1 | E25: 5.9 | F25: %
A26: G3 | B26: G3 | C26: ash | D26: 2 | E26: 5.95 | F26: %
A27: G3 | B27: G3 | C27: ash | D27: 3 | E27: 5.92 | F27: %
A28: G3 | B28: G3 | C28: protein | D28: 1 | E28: 26.03 | F28: %
A29: G3 | B29: G3 | C29: fat | D29: 1 | E29: 21.47 | F29: % | H29: W6 直接 Soxhlet(未水解) 盲樣三重複
A30: G3 | B30: G3 | C30: fat | D30: 2 | E30: 21.48 | F30: % | H30: W6 直接 Soxhlet(未水解) 盲樣三重複
A31: G3 | B31: G3 | C31: fat | D31: 3 | E31: 21.16 | F31: % | H31: W6 直接 Soxhlet(未水解) 盲樣三重複
A32: G4 | B32: G4 | C32: moisture | D32: 1 | E32: 2.9 | F32: %
A33: G4 | B33: G4 | C33: moisture | D33: 2 | E33: 2.92 | F33: %
A34: G4 | B34: G4 | C34: moisture | D34: 3 | E34: 2.89 | F34: %
A35: G4 | B35: G4 | C35: ash | D35: 1 | E35: 6.05 | F35: %
A36: G4 | B36: G4 | C36: ash | D36: 2 | E36: 6 | F36: %
A37: G4 | B37: G4 | C37: ash | D37: 3 | E37: 6.03 | F37: %
A38: G4 | B38: G4 | C38: protein | D38: 1 | E38: 24.47 | F38: % | H38: 系統性偏低 (systematic bias, ~1.5 個百分點)
A39: G4 | B39: G4 | C39: fat | D39: 1 | E39: 21.19 | F39: % | H39: W6 直接 Soxhlet(未水解) 盲樣三重複
A40: G4 | B40: G4 | C40: fat | D40: 2 | E40: 21.16 | F40: % | H40: W6 直接 Soxhlet(未水解) 盲樣三重複
...

Sheet 2_組成表
A1: 步驟 1 Proximate 組成表與差減法碳水化合物
A2: 把 5 組的水分、灰分、蛋白質、脂肪彙整成一張表。碳水化合物不是測出來的，而是用差減法：碳水化合物% = 100 − (水分% + 灰分% + 蛋白質% + 脂肪%)。
A4: 項目代號 → | B4: moisture | C4: ash | D4: protein | E4: fat | F4: carbohydrate
A5: 組別 | B5: 水分 (%) | C5: 灰分 (%) | D5: 蛋白質 (%) | E5: 脂肪 (%) | F5: 碳水化合物 (%) 差減法 | H5: 水分 n | I5: 灰分 n | J5: 蛋白質 n | K5: 脂肪 n | M5: A 欄的組別名稱（黃色）要和「1_原始數據」的 group 欄一模一樣。本檔固定 5 組；
A6: G1 | B6: =AVERAGEIFS('1_原始數據'!$E$2:$E$1000,'1_原始數據'!$A$2:$A$1000,$A6,'1_原始數據'!$C$2:$C$1000,B$4) | C6: =AVERAGEIFS('1_原始數據'!$E$2:$E$1000,'1_原始數據'!$A$2:$A$1000,$A6,'1_原始數據'!$C$2:$C$1000,C$4) | D6: =AVERAGEIFS('1_原始數據'!$E$2:$E$1000,'1_原始數據'!$A$2:$A$1000,$A6,'1_原始數據'!$C$2:$C$1000,D$4) | E6: =AVERAGEIFS('1_原始數據'!$E$2:$E$1000,'1_原始數據'!$A$2:$A$1000,$A6,'1_原始數據'!$C$2:$C$1000,E$4) | F6: =100-SUM(B6:E6) | H6: =COUNTIFS('1_原始數據'!$A$2:$A$1000,$A6,'1_原始數據'!$C$2:$C$1000,B$4) | I6: =COUNTIFS('1_原始數據'!$A$2:$A$1000,$A6,'1_原始數據'!$C$2:$C$1000,C$4) | J6: =COUNTIFS('1_原始數據'!$A$2:$A$1000,$A6,'1_原始數據'!$C$2:$C$1000,D$4) | K6: =COUNTIFS('1_原始數據'!$A$2:$A$1000,$A6,'1_原始數據'!$C$2:$C$1000,E$4) | M6: 組數不同時請用 Colab 筆記本。
A7: G2 | B7: =AVERAGEIFS('1_原始數據'!$E$2:$E$1000,'1_原始數據'!$A$2:$A$1000,$A7,'1_原始數據'!$C$2:$C$1000,B$4) | C7: =AVERAGEIFS('1_原始數據'!$E$2:$E$1000,'1_原始數據'!$A$2:$A$1000,$A7,'1_原始數據'!$C$2:$C$1000,C$4) | D7: =AVERAGEIFS('1_原始數據'!$E$2:$E$1000,'1_原始數據'!$A$2:$A$1000,$A7,'1_原始數據'!$C$2:$C$1000,D$4) | E7: =AVERAGEIFS('1_原始數據'!$E$2:$E$1000,'1_原始數據'!$A$2:$A$1000,$A7,'1_原始數據'!$C$2:$C$1000,E$4) | F7: =100-SUM(B7:E7) | H7: =COUNTIFS('1_原始數據'!$A$2:$A$1000,$A7,'1_原始數據'!$C$2:$C$1000,B$4) | I7: =COUNTIFS('1_原始數據'!$A$2:$A$1000,$A7,'1_原始數據'!$C$2:$C$1000,C$4) | J7: =COUNTIFS('1_原始數據'!$A$2:$A$1000,$A7,'1_原始數據'!$C$2:$C$1000,D$4) | K7: =COUNTIFS('1_原始數據'!$A$2:$A$1000,$A7,'1_原始數據'!$C$2:$C$1000,E$4)
A8: G3 | B8: =AVERAGEIFS('1_原始數據'!$E$2:$E$1000,'1_原始數據'!$A$2:$A$1000,$A8,'1_原始數據'!$C$2:$C$1000,B$4) | C8: =AVERAGEIFS('1_原始數據'!$E$2:$E$1000,'1_原始數據'!$A$2:$A$1000,$A8,'1_原始數據'!$C$2:$C$1000,C$4) | D8: =AVERAGEIFS('1_原始數據'!$E$2:$E$1000,'1_原始數據'!$A$2:$A$1000,$A8,'1_原始數據'!$C$2:$C$1000,D$4) | E8: =AVERAGEIFS('1_原始數據'!$E$2:$E$1000,'1_原始數據'!$A$2:$A$1000,$A8,'1_原始數據'!$C$2:$C$1000,E$4) | F8: =100-SUM(B8:E8) | H8: =COUNTIFS('1_原始數據'!$A$2:$A$1000,$A8,'1_原始數據'!$C$2:$C$1000,B$4) | I8: =COUNTIFS('1_原始數據'!$A$2:$A$1000,$A8,'1_原始數據'!$C$2:$C$1000,C$4) | J8: =COUNTIFS('1_原始數據'!$A$2:$A$1000,$A8,'1_原始數據'!$C$2:$C$1000,D$4) | K8: =COUNTIFS('1_原始數據'!$A$2:$A$1000,$A8,'1_原始數據'!$C$2:$C$1000,E$4) | M8: B–E 欄公式都一樣：AVERAGEIFS(數值, group 欄, 本列組別, item
A9: G4 | B9: =AVERAGEIFS('1_原始數據'!$E$2:$E$1000,'1_原始數據'!$A$2:$A$1000,$A9,'1_原始數據'!$C$2:$C$1000,B$4) | C9: =AVERAGEIFS('1_原始數據'!$E$2:$E$1000,'1_原始數據'!$A$2:$A$1000,$A9,'1_原始數據'!$C$2:$C$1000,C$4) | D9: =AVERAGEIFS('1_原始數據'!$E$2:$E$1000,'1_原始數據'!$A$2:$A$1000,$A9,'1_原始數據'!$C$2:$C$1000,D$4) | E9: =AVERAGEIFS('1_原始數據'!$E$2:$E$1000,'1_原始數據'!$A$2:$A$1000,$A9,'1_原始數據'!$C$2:$C$1000,E$4) | F9: =100-SUM(B9:E9) | H9: =COUNTIFS('1_原始數據'!$A$2:$A$1000,$A9,'1_原始數據'!$C$2:$C$1000,B$4) | I9: =COUNTIFS('1_原始數據'!$A$2:$A$1000,$A9,'1_原始數據'!$C$2:$C$1000,C$4) | J9: =COUNTIFS('1_原始數據'!$A$2:$A$1000,$A9,'1_原始數據'!$C$2:$C$1000,D$4) | K9: =COUNTIFS('1_原始數據'!$A$2:$A$1000,$A9,'1_原始數據'!$C$2:$C$1000,E$4) | M9: 欄, 第 4 列的項目代號)。蛋白質每組只有 1 次測定（n=1），所以「平均」就是那一個值
A10: G5 | B10: =AVERAGEIFS('1_原始數據'!$E$2:$E$1000,'1_原始數據'!$A$2:$A$1000,$A10,'1_原始數據'!$C$2:$C$1000,B$4) | C10: =AVERAGEIFS('1_原始數據'!$E$2:$E$1000,'1_原始數據'!$A$2:$A$1000,$A10,'1_原始數據'!$C$2:$C$1000,C$4) | D10: =AVERAGEIFS('1_原始數據'!$E$2:$E$1000,'1_原始數據'!$A$2:$A$1000,$A10,'1_原始數據'!$C$2:$C$1000,D$4) | E10: =AVERAGEIFS('1_原始數據'!$E$2:$E$1000,'1_原始數據'!$A$2:$A$1000,$A10,'1_原始數據'!$C$2:$C$1000,E$4) | F10: =100-SUM(B10:E10) | H10: =COUNTIFS('1_原始數據'!$A$2:$A$1000,$A10,'1_原始數據'!$C$2:$C$1000,B$4) | I10: =COUNTIFS('1_原始數據'!$A$2:$A$1000,$A10,'1_原始數據'!$C$2:$C$1000,C$4) | J10: =COUNTIFS('1_原始數據'!$A$2:$A$1000,$A10,'1_原始數據'!$C$2:$C$1000,D$4) | K10: =COUNTIFS('1_原始數據'!$A$2:$A$1000,$A10,'1_原始數據'!$C$2:$C$1000,E$4) | M10: 。
A11: 中位數 (median) | B11: =MEDIAN(B6:B10) | C11: =MEDIAN(C6:C10) | D11: =MEDIAN(D6:D10) | E11: =MEDIAN(E6:E10) | F11: =MEDIAN(F6:F10) | M11: H–K 欄是每一項的重複數 n，確認數據有沒有漏貼：水分/灰分/脂肪應為 3，
A12: 平均 (mean) | B12: =AVERAGE(B6:B10) | C12: =AVERAGE(C6:C10) | D12: =AVERAGE(D6:D10) | E12: =AVERAGE(E6:E10) | F12: =AVERAGE(F6:F10) | M12: 蛋白質為 1。
A13: 組間 SD | B13: =_xlfn.STDEV.S(B6:B10) | C13: =_xlfn.STDEV.S(C6:C10) | D13: =_xlfn.STDEV.S(D6:D10) | E13: =_xlfn.STDEV.S(E6:E10) | F13: =_xlfn.STDEV.S(F6:F10)
M14: 中位數（median）不容易被一個離群組拉走，第 3、5、9 張表會用它當「全班代表值／指定
M15: 值」。
A16: 公式說明
A17: AVERAGEIFS | B17: =AVERAGEIFS(平均的範圍, 條件範圍1, 條件1, 條件範圍2, 條件2) 只把同時符合「組別」與「項目」的數字拿來平均
A18: 碳水化合物 | B18: =100-SUM(B6:E6) 差減法沒有自己的實驗步驟，只是拿其他四項做減法
A19: MEDIAN | B19: =MEDIAN(B6:B10) 把 5 個數字排好取中間那一個
A20: STDEV.S | B20: =STDEV.S(B6:B10) 組間標準差（除以 n−1 的樣本 SD）
A21: 和 Colab 的差異 | B21: Colab 先把各項平均四捨五入到小數 4 位再相減，Excel 用完整數字，所以 G3 碳水化合物可能在小數第 4 位差 1。
A23: 差減法「繼承所有人的誤差」：任何一項偏低，碳水化合物就偏高。碳水化合物的不確定度要用平方和開根號合併，算法在「7_不確定度」7-2；和資料庫的比對在「9_資料庫比對」。

Sheet 3_Grubbs離群
B1: 步驟 2 Grubbs 離群值檢定（組內 n=3 vs 班級層級 n=5）
B2: G = 最大的 |x − 平均| ÷ SD。G 大於臨界值 G_crit 才判定為離群值。臨界值用 t 分布的公式直接算，不用查表。
B4: α（顯著水準，雙側） | C4: 0.05
B6: 2-1 臨界值 G_crit 與理論上界
B7: n（數據個數） | C7: t 值 | D7: G_crit | E7: 理論上界 (n−1)/√n | F7: 上界 − G_crit | H7: t 值 =T.INV(1−α/(2n), n−2)：T.INV 是 t 分布的「反函數」，
B8: 3 | C8: =_xlfn.T.INV(1-$C$4/(2*B8),B8-2) | D8: =(B8-1)/SQRT(B8)*SQRT(C8^2/(B8-2+C8^2)) | E8: =(B8-1)/SQRT(B8) | F8: =E8-D8 | H8: 給機率、給自由度，回傳 t 值。G_crit = (n−1)/√n × √(t² ÷ (n−
B9: 4 | C9: =_xlfn.T.INV(1-$C$4/(2*B9),B9-2) | D9: =(B9-1)/SQRT(B9)*SQRT(C9^2/(B9-2+C9^2)) | E9: =(B9-1)/SQRT(B9) | F9: =E9-D9 | H9: 2+t²))。
B10: 5 | C10: =_xlfn.T.INV(1-$C$4/(2*B10),B10-2) | D10: =(B10-1)/SQRT(B10)*SQRT(C10^2/(B10-2+C10^2)) | E10: =(B10-1)/SQRT(B10) | F10: =E10-D10
B11: 6 | C11: =_xlfn.T.INV(1-$C$4/(2*B11),B11-2) | D11: =(B11-1)/SQRT(B11)*SQRT(C11^2/(B11-2+C11^2)) | E11: =(B11-1)/SQRT(B11) | F11: =E11-D11 | H11: 看 n=3 這一列：G 最大也只能到 (n−1)/√n = 1.1547，而 G_crit
B12: 8 | C12: =_xlfn.T.INV(1-$C$4/(2*B12),B12-2) | D12: =(B12-1)/SQRT(B12)*SQRT(C12^2/(B12-2+C12^2)) | E12: =(B12-1)/SQRT(B12) | F12: =E12-D12 | H12: ≈ 1.1543，只差 0.0004。所以只有 3 個重複值時，Grubbs 實質上永遠判不
B13: 10 | C13: =_xlfn.T.INV(1-$C$4/(2*B13),B13-2) | D13: =(B13-1)/SQRT(B13)*SQRT(C13^2/(B13-2+C13^2)) | E13: =(B13-1)/SQRT(B13) | F13: =E13-D13 | H13: 出離群值。
B16: 2-2 組內層級（n=3）：某一組某一項的重複值
B17: 組別 | C17: G3 | H17: 黃色格子可改：換別組或別的項目（moisture / ash / fat）。
B18: 項目代號 | C18: moisture
B20: 重複 rep | C20: 數值 (%) | D20: |x − 平均|
B21: 1 | C21: =IF(COUNTIFS('1_原始數據'!$A$2:$A$1000,$C$17,'1_原始數據'!$C$2:$C$1000,$C$18,'1_原始數據'!$D$2:$D$1000,B21)=0,"",SUMIFS('1_原始數據'!$E$2:$E$1000,'1_原始數據'!$A$2:$A$1000,$C$17,'1_原始數據'!$C$2:$C$1000,$C$18,'1_原始數據'!$D$2:$D$1000,B21)) | D21: =IF(C21="","",ABS(C21-$C$29))
B22: 2 | C22: =IF(COUNTIFS('1_原始數據'!$A$2:$A$1000,$C$17,'1_原始數據'!$C$2:$C$1000,$C$18,'1_原始數據'!$D$2:$D$1000,B22)=0,"",SUMIFS('1_原始數據'!$E$2:$E$1000,'1_原始數據'!$A$2:$A$1000,$C$17,'1_原始數據'!$C$2:$C$1000,$C$18,'1_原始數據'!$D$2:$D$1000,B22)) | D22: =IF(C22="","",ABS(C22-$C$29))
B23: 3 | C23: =IF(COUNTIFS('1_原始數據'!$A$2:$A$1000,$C$17,'1_原始數據'!$C$2:$C$1000,$C$18,'1_原始數據'!$D$2:$D$1000,B23)=0,"",SUMIFS('1_原始數據'!$E$2:$E$1000,'1_原始數據'!$A$2:$A$1000,$C$17,'1_原始數據'!$C$2:$C$1000,$C$18,'1_原始數據'!$D$2:$D$1000,B23)) | D23: =IF(C23="","",ABS(C23-$C$29))
B24: 4 | C24: =IF(COUNTIFS('1_原始數據'!$A$2:$A$1000,$C$17,'1_原始數據'!$C$2:$C$1000,$C$18,'1_原始數據'!$D$2:$D$1000,B24)=0,"",SUMIFS('1_原始數據'!$E$2:$E$1000,'1_原始數據'!$A$2:$A$1000,$C$17,'1_原始數據'!$C$2:$C$1000,$C$18,'1_原始數據'!$D$2:$D$1000,B24)) | D24: =IF(C24="","",ABS(C24-$C$29))
B25: 5 | C25: =IF(COUNTIFS('1_原始數據'!$A$2:$A$1000,$C$17,'1_原始數據'!$C$2:$C$1000,$C$18,'1_原始數據'!$D$2:$D$1000,B25)=0,"",SUMIFS('1_原始數據'!$E$2:$E$1000,'1_原始數據'!$A$2:$A$1000,$C$17,'1_原始數據'!$C$2:$C$1000,$C$18,'1_原始數據'!$D$2:$D$1000,B25)) | D25: =IF(C25="","",ABS(C25-$C$29))
B26: 6 | C26: =IF(COUNTIFS('1_原始數據'!$A$2:$A$1000,$C$17,'1_原始數據'!$C$2:$C$1000,$C$18,'1_原始數據'!$D$2:$D$1000,B26)=0,"",SUMIFS('1_原始數據'!$E$2:$E$1000,'1_原始數據'!$A$2:$A$1000,$C$17,'1_原始數據'!$C$2:$C$1000,$C$18,'1_原始數據'!$D$2:$D$1000,B26)) | D26: =IF(C26="","",ABS(C26-$C$29))
B28: n | C28: =COUNT(C21:C26) | H28: 最大 |x − 平均| 用 MAX 找出離平均最遠的那一點。G = 最大偏離 ÷ SD。
B29: 平均 | C29: =AVERAGE(C21:C26)
B30: SD | C30: =_xlfn.STDEV.S(C21:C26)
B31: 最大 |x − 平均| | C31: =MAX(D21:D26)
B32: G | C32: =C31/C30 | H32: G3 水分：3.30% 用眼睛看很像離群值，但 G = 1.1526 < G_crit =
B33: G_crit（依 n 計算） | C33: =(C28-1)/SQRT(C28)*SQRT(_xlfn.T.INV(1-$C$4/(2*C28),C28-2)^2/(C28-2+_xlfn.T.INV(1-$C$4/(2*C28),C28-2)^2)) | H33: 1.1543，統計上判不出來——n=3 太少了。
B34: 理論上界 (n−1)/√n | C34: =(C28-1)/SQRT(C28)
B35: 判定 | C35: =IF(C32>C33,"G > G_crit：判定為離群值","G ≤ G_crit：統計上測不出來，不能判定為離群值")
B38: 2-3 班級層級（n=5）：5 組的結果互相比
B39: 項目代號 | C39: protein | H39: 數值直接取自「2_組成表」各組結果（蛋白質是單次測定值）。可改成其他項目。
B41: 組別 | C41: 數值 (%) | D41: |x − 平均| | E41: G
B42: ='2_組成表'!A6 | C42: =INDEX('2_組成表'!$B$6:$F$10,1,MATCH($C$39,'2_組成表'!$B$4:$F$4,0)) | D42: =ABS(C42-$C$49) | E42: =D42/$C$50
B43: ='2_組成表'!A7 | C43: =INDEX('2_組成表'!$B$6:$F$10,2,MATCH($C$39,'2_組成表'!$B$4:$F$4,0)) | D43: =ABS(C43-$C$49) | E43: =D43/$C$50
B44: ='2_組成表'!A8 | C44: =INDEX('2_組成表'!$B$6:$F$10,3,MATCH($C$39,'2_組成表'!$B$4:$F$4,0)) | D44: =ABS(C44-$C$49) | E44: =D44/$C$50
B45: ='2_組成表'!A9 | C45: =INDEX('2_組成表'!$B$6:$F$10,4,MATCH($C$39,'2_組成表'!$B$4:$F$4,0)) | D45: =ABS(C45-$C$49) | E45: =D45/$C$50
B46: ='2_組成表'!A10 | C46: =INDEX('2_組成表'!$B$6:$F$10,5,MATCH($C$39,'2_組成表'!$B$4:$F$4,0)) | D46: =ABS(C46-$C$49) | E46: =D46/$C$50
B48: n | C48: =COUNT(C42:C46)
B49: 平均 | C49: =AVERAGE(C42:C46)
B50: SD | C50: =_xlfn.STDEV.S(C42:C46)
...

Sheet 4_ANOVA
B1: 步驟 3 一元 ANOVA：組間差異與重複性 s_r／再現性 s_R（以灰分為例）
B2: 把總變異拆成「組內」（同一組重複測定的隨機誤差）與「組間」（各組平均的差異）。F = MS組間 ÷ MS組內；F 很大、p < 0.05 代表組間差異不能只用隨機誤差解釋。
B4: 項目代號 | C4: ash
B5: α | C5: 0.05
J6: 給「資料分析工具箱」用的排列（自動）
B7: 組別 | C7: n | D7: 平均 (%) | E7: SD (%) | F7: 組內平方和 (n−1)·SD² | G7: 組間平方和 n·(平均−總平均)² | J7: rep | K7: =B8 | L7: =B9 | M7: =B10 | N7: =B11 | O7: =B12
B8: ='2_組成表'!A6 | C8: =COUNTIFS('1_原始數據'!$A$2:$A$1000,B8,'1_原始數據'!$C$2:$C$1000,$C$4) | D8: =AVERAGEIFS('1_原始數據'!$E$2:$E$1000,'1_原始數據'!$A$2:$A$1000,B8,'1_原始數據'!$C$2:$C$1000,$C$4) | E8: {=_xlfn.STDEV.S(IF(('1_原始數據'!$A$2:$A$1000=B8)*('1_原始數據'!$C$2:$C$1000=$C$4),'1_原始數據'!$E$2:$E$1000))} | F8: =(C8-1)*E8^2 | G8: =C8*(D8-$D$14)^2 | J8: 1 | K8: =IF(COUNTIFS('1_原始數據'!$A$2:$A$1000,K$7,'1_原始數據'!$C$2:$C$1000,$C$4,'1_原始數據'!$D$2:$D$1000,$J8)=0,"",SUMIFS('1_原始數據'!$E$2:$E$1000,'1_原始數據'!$A$2:$A$1000,K$7,'1_原始數據'!$C$2:$C$1000,$C$4,'1_原始數據'!$D$2:$D$1000,$J8)) | L8: =IF(COUNTIFS('1_原始數據'!$A$2:$A$1000,L$7,'1_原始數據'!$C$2:$C$1000,$C$4,'1_原始數據'!$D$2:$D$1000,$J8)=0,"",SUMIFS('1_原始數據'!$E$2:$E$1000,'1_原始數據'!$A$2:$A$1000,L$7,'1_原始數據'!$C$2:$C$1000,$C$4,'1_原始數據'!$D$2:$D$1000,$J8)) | M8: =IF(COUNTIFS('1_原始數據'!$A$2:$A$1000,M$7,'1_原始數據'!$C$2:$C$1000,$C$4,'1_原始數據'!$D$2:$D$1000,$J8)=0,"",SUMIFS('1_原始數據'!$E$2:$E$1000,'1_原始數據'!$A$2:$A$1000,M$7,'1_原始數據'!$C$2:$C$1000,$C$4,'1_原始數據'!$D$2:$D$1000,$J8)) | N8: =IF(COUNTIFS('1_原始數據'!$A$2:$A$1000,N$7,'1_原始數據'!$C$2:$C$1000,$C$4,'1_原始數據'!$D$2:$D$1000,$J8)=0,"",SUMIFS('1_原始數據'!$E$2:$E$1000,'1_原始數據'!$A$2:$A$1000,N$7,'1_原始數據'!$C$2:$C$1000,$C$4,'1_原始數據'!$D$2:$D$1000,$J8)) | O8: =IF(COUNTIFS('1_原始數據'!$A$2:$A$1000,O$7,'1_原始數據'!$C$2:$C$1000,$C$4,'1_原始數據'!$D$2:$D$1000,$J8)=0,"",SUMIFS('1_原始數據'!$E$2:$E$1000,'1_原始數據'!$A$2:$A$1000,O$7,'1_原始數據'!$C$2:$C$1000,$C$4,'1_原始數據'!$D$2:$D$1000,$J8))
B9: ='2_組成表'!A7 | C9: =COUNTIFS('1_原始數據'!$A$2:$A$1000,B9,'1_原始數據'!$C$2:$C$1000,$C$4) | D9: =AVERAGEIFS('1_原始數據'!$E$2:$E$1000,'1_原始數據'!$A$2:$A$1000,B9,'1_原始數據'!$C$2:$C$1000,$C$4) | E9: {=_xlfn.STDEV.S(IF(('1_原始數據'!$A$2:$A$1000=B9)*('1_原始數據'!$C$2:$C$1000=$C$4),'1_原始數據'!$E$2:$E$1000))} | F9: =(C9-1)*E9^2 | G9: =C9*(D9-$D$14)^2 | J9: 2 | K9: =IF(COUNTIFS('1_原始數據'!$A$2:$A$1000,K$7,'1_原始數據'!$C$2:$C$1000,$C$4,'1_原始數據'!$D$2:$D$1000,$J9)=0,"",SUMIFS('1_原始數據'!$E$2:$E$1000,'1_原始數據'!$A$2:$A$1000,K$7,'1_原始數據'!$C$2:$C$1000,$C$4,'1_原始數據'!$D$2:$D$1000,$J9)) | L9: =IF(COUNTIFS('1_原始數據'!$A$2:$A$1000,L$7,'1_原始數據'!$C$2:$C$1000,$C$4,'1_原始數據'!$D$2:$D$1000,$J9)=0,"",SUMIFS('1_原始數據'!$E$2:$E$1000,'1_原始數據'!$A$2:$A$1000,L$7,'1_原始數據'!$C$2:$C$1000,$C$4,'1_原始數據'!$D$2:$D$1000,$J9)) | M9: =IF(COUNTIFS('1_原始數據'!$A$2:$A$1000,M$7,'1_原始數據'!$C$2:$C$1000,$C$4,'1_原始數據'!$D$2:$D$1000,$J9)=0,"",SUMIFS('1_原始數據'!$E$2:$E$1000,'1_原始數據'!$A$2:$A$1000,M$7,'1_原始數據'!$C$2:$C$1000,$C$4,'1_原始數據'!$D$2:$D$1000,$J9)) | N9: =IF(COUNTIFS('1_原始數據'!$A$2:$A$1000,N$7,'1_原始數據'!$C$2:$C$1000,$C$4,'1_原始數據'!$D$2:$D$1000,$J9)=0,"",SUMIFS('1_原始數據'!$E$2:$E$1000,'1_原始數據'!$A$2:$A$1000,N$7,'1_原始數據'!$C$2:$C$1000,$C$4,'1_原始數據'!$D$2:$D$1000,$J9)) | O9: =IF(COUNTIFS('1_原始數據'!$A$2:$A$1000,O$7,'1_原始數據'!$C$2:$C$1000,$C$4,'1_原始數據'!$D$2:$D$1000,$J9)=0,"",SUMIFS('1_原始數據'!$E$2:$E$1000,'1_原始數據'!$A$2:$A$1000,O$7,'1_原始數據'!$C$2:$C$1000,$C$4,'1_原始數據'!$D$2:$D$1000,$J9))
B10: ='2_組成表'!A8 | C10: =COUNTIFS('1_原始數據'!$A$2:$A$1000,B10,'1_原始數據'!$C$2:$C$1000,$C$4) | D10: =AVERAGEIFS('1_原始數據'!$E$2:$E$1000,'1_原始數據'!$A$2:$A$1000,B10,'1_原始數據'!$C$2:$C$1000,$C$4) | E10: {=_xlfn.STDEV.S(IF(('1_原始數據'!$A$2:$A$1000=B10)*('1_原始數據'!$C$2:$C$1000=$C$4),'1_原始數據'!$E$2:$E$1000))} | F10: =(C10-1)*E10^2 | G10: =C10*(D10-$D$14)^2 | J10: 3 | K10: =IF(COUNTIFS('1_原始數據'!$A$2:$A$1000,K$7,'1_原始數據'!$C$2:$C$1000,$C$4,'1_原始數據'!$D$2:$D$1000,$J10)=0,"",SUMIFS('1_原始數據'!$E$2:$E$1000,'1_原始數據'!$A$2:$A$1000,K$7,'1_原始數據'!$C$2:$C$1000,$C$4,'1_原始數據'!$D$2:$D$1000,$J10)) | L10: =IF(COUNTIFS('1_原始數據'!$A$2:$A$1000,L$7,'1_原始數據'!$C$2:$C$1000,$C$4,'1_原始數據'!$D$2:$D$1000,$J10)=0,"",SUMIFS('1_原始數據'!$E$2:$E$1000,'1_原始數據'!$A$2:$A$1000,L$7,'1_原始數據'!$C$2:$C$1000,$C$4,'1_原始數據'!$D$2:$D$1000,$J10)) | M10: =IF(COUNTIFS('1_原始數據'!$A$2:$A$1000,M$7,'1_原始數據'!$C$2:$C$1000,$C$4,'1_原始數據'!$D$2:$D$1000,$J10)=0,"",SUMIFS('1_原始數據'!$E$2:$E$1000,'1_原始數據'!$A$2:$A$1000,M$7,'1_原始數據'!$C$2:$C$1000,$C$4,'1_原始數據'!$D$2:$D$1000,$J10)) | N10: =IF(COUNTIFS('1_原始數據'!$A$2:$A$1000,N$7,'1_原始數據'!$C$2:$C$1000,$C$4,'1_原始數據'!$D$2:$D$1000,$J10)=0,"",SUMIFS('1_原始數據'!$E$2:$E$1000,'1_原始數據'!$A$2:$A$1000,N$7,'1_原始數據'!$C$2:$C$1000,$C$4,'1_原始數據'!$D$2:$D$1000,$J10)) | O10: =IF(COUNTIFS('1_原始數據'!$A$2:$A$1000,O$7,'1_原始數據'!$C$2:$C$1000,$C$4,'1_原始數據'!$D$2:$D$1000,$J10)=0,"",SUMIFS('1_原始數據'!$E$2:$E$1000,'1_原始數據'!$A$2:$A$1000,O$7,'1_原始數據'!$C$2:$C$1000,$C$4,'1_原始數據'!$D$2:$D$1000,$J10))
B11: ='2_組成表'!A9 | C11: =COUNTIFS('1_原始數據'!$A$2:$A$1000,B11,'1_原始數據'!$C$2:$C$1000,$C$4) | D11: =AVERAGEIFS('1_原始數據'!$E$2:$E$1000,'1_原始數據'!$A$2:$A$1000,B11,'1_原始數據'!$C$2:$C$1000,$C$4) | E11: {=_xlfn.STDEV.S(IF(('1_原始數據'!$A$2:$A$1000=B11)*('1_原始數據'!$C$2:$C$1000=$C$4),'1_原始數據'!$E$2:$E$1000))} | F11: =(C11-1)*E11^2 | G11: =C11*(D11-$D$14)^2
B12: ='2_組成表'!A10 | C12: =COUNTIFS('1_原始數據'!$A$2:$A$1000,B12,'1_原始數據'!$C$2:$C$1000,$C$4) | D12: =AVERAGEIFS('1_原始數據'!$E$2:$E$1000,'1_原始數據'!$A$2:$A$1000,B12,'1_原始數據'!$C$2:$C$1000,$C$4) | E12: {=_xlfn.STDEV.S(IF(('1_原始數據'!$A$2:$A$1000=B12)*('1_原始數據'!$C$2:$C$1000=$C$4),'1_原始數據'!$E$2:$E$1000))} | F12: =(C12-1)*E12^2 | G12: =C12*(D12-$D$14)^2 | J12: 對答案用：Excel「資料 → 資料分析 → 單因子變異數分析（Anova: Single Factor）」，輸入範圍選 K7:O10、分組方式選「逐欄」、勾「類別軸標記是在第一列上」、α = 0.05。工具箱算出的 F、P-值、F 臨界值應該和左邊 ANOVA 表相同。（工具箱結果是靜態數字，數據改了不會自動更新，所以本檔用公式。Mac 版要先到「工具 → Excel 增益集」勾選「分析工具箱」。）
B13: 合計 | C13: =SUM(C8:C12) | F13: =SUM(F8:F12) | G13: =SUM(G8:G12)
B14: 總平均 (grand mean) | D14: =SUMPRODUCT(C8:C12,D8:D12)/C13
B15: 組數 k | C15: =COUNTIF(C8:C12,">0")
B16: 每組重複數 n | C16: =C13/C15
B18: ANOVA 表
B19: 變異來源 | C19: SS 平方和 | D19: df 自由度 | E19: MS 均方 | F19: F | G19: p 值 | H19: F 臨界值
B20: 組間 (between) | C20: =G13 | D20: =C15-1 | E20: =C20/D20 | F20: =E20/E21 | G20: =_xlfn.F.DIST.RT(F20,D20,D21) | H20: =_xlfn.F.INV.RT($C$5,D20,D21)
B21: 組內 (within) | C21: =F13 | D21: =C13-C15 | E21: =C21/D21
B22: 總和 (total) | C22: =C20+C21 | D22: =C13-1
B23: 結論 | C23: =IF(G20<$C$5,"p < α：各組平均有顯著差異，組間有真實的系統性落差","p ≥ α：沒有足夠證據說各組平均不同")
B25: 重複性與再現性
B26: s_r 重複性 = √MSW | C26: =SQRT(E21)
B27: s_L 組間 = √max(0, (MSB−MSW)/n) | C27: =SQRT(MAX(0,(E20-E21)/C16))
B28: s_R 再現性 = √(s_r² + s_L²) | C28: =SQRT(C26^2+C27^2)
B30: 公式說明
B31: 組內平方和 | C31: =(n−1)*SD^2 就是每一組「每個值減本組平均」的平方加總；SSW = 各組相加
B32: 組間平方和 | C32: =n*(本組平均−總平均)^2 SSB = 各組相加
B33: MS | C33: = SS ÷ df 組間 df = k−1，組內 df = N−k
B34: F.DIST.RT | C34: =F.DIST.RT(F, df組間, df組內) F 分布的右尾機率，就是 p 值
B35: F.INV.RT | C35: =F.INV.RT(α, df組間, df組內) F 臨界值；F 大於它就等於 p < α
B36: SD 陣列公式 | C36: {=STDEV.S(IF(條件, 數值))} 只把符合條件的數字交給 STDEV.S；舊版 Excel 輸入時按 Ctrl+Shift+Enter
B37: s_r 只看「同一組重複做」的變異；s_R 還加上「換一組人做」的變異。灰分 s_L > s_r：組與組之間的差（秤重習慣、坩堝恆重判斷…）比組內重複的差更大，所以報告再現性要用 s_R。 | J37: 看圖：誤差線（±SD）是組內的重複性；點與點之間的上下落差是組間差異。落差明顯大於誤差線時，F 就會很大。

Sheet 5_z分數
B1: 步驟 4 z-score 與分級
B2: z = (本組結果 − 指定值) ÷ σ_pt。指定值用全班中位數（穩健、不易被離群組拉走）；σ_pt 是事先訂好的目標標準差（本課固定 0.40%），不是用班上算出來的 SD。
B4: 項目代號 | C4: protein | P4: 黃色可改：項目代號（練習題 7 改成 fat）、σ_pt。
B5: σ_pt（目標標準差, %） | C5: 0.4
B6: 指定值 x_assigned（中位數） | C6: =MEDIAN(C10:C14) | P6: MEDIAN 取 5 組結果的中位數。這個數字也是「7_不確定度」蛋白質預算的參考量。
H8: 圖用輔助數據（自動）
B9: 組別 | C9: 結果 (%) | D9: z | E9: |z| | F9: 分級 | H9: satisfactory | I9: questionable | J9: unsatisfactory | K9: +2 | L9: −2 | M9: +3 | N9: −3
B10: ='2_組成表'!A6 | C10: =INDEX('2_組成表'!$B$6:$F$10,1,MATCH($C$4,'2_組成表'!$B$4:$F$4,0)) | D10: =(C10-$C$6)/$C$5 | E10: =ABS(D10) | F10: =IF(E10<=2,"滿意 (satisfactory)",IF(E10<3,"問題 (questionable)","不滿意 (unsatisfactory)")) | H10: =IF(E10<=2,D10,0) | I10: =IF(AND(E10>2,E10<3),D10,0) | J10: =IF(E10>=3,D10,0) | K10: =2 | L10: =-2 | M10: =3 | N10: =-3 | P10: 分級用巢狀 IF：先問 |z| ≤ 2？是→滿意；不是再問 |z| < 3？是→問題；
B11: ='2_組成表'!A7 | C11: =INDEX('2_組成表'!$B$6:$F$10,2,MATCH($C$4,'2_組成表'!$B$4:$F$4,0)) | D11: =(C11-$C$6)/$C$5 | E11: =ABS(D11) | F11: =IF(E11<=2,"滿意 (satisfactory)",IF(E11<3,"問題 (questionable)","不滿意 (unsatisfactory)")) | H11: =IF(E11<=2,D11,0) | I11: =IF(AND(E11>2,E11<3),D11,0) | J11: =IF(E11>=3,D11,0) | K11: =2 | L11: =-2 | M11: =3 | N11: =-3 | P11: 都不是→不滿意。
B12: ='2_組成表'!A8 | C12: =INDEX('2_組成表'!$B$6:$F$10,3,MATCH($C$4,'2_組成表'!$B$4:$F$4,0)) | D12: =(C12-$C$6)/$C$5 | E12: =ABS(D12) | F12: =IF(E12<=2,"滿意 (satisfactory)",IF(E12<3,"問題 (questionable)","不滿意 (unsatisfactory)")) | H12: =IF(E12<=2,D12,0) | I12: =IF(AND(E12>2,E12<3),D12,0) | J12: =IF(E12>=3,D12,0) | K12: =2 | L12: =-2 | M12: =3 | N12: =-3
B13: ='2_組成表'!A9 | C13: =INDEX('2_組成表'!$B$6:$F$10,4,MATCH($C$4,'2_組成表'!$B$4:$F$4,0)) | D13: =(C13-$C$6)/$C$5 | E13: =ABS(D13) | F13: =IF(E13<=2,"滿意 (satisfactory)",IF(E13<3,"問題 (questionable)","不滿意 (unsatisfactory)")) | H13: =IF(E13<=2,D13,0) | I13: =IF(AND(E13>2,E13<3),D13,0) | J13: =IF(E13>=3,D13,0) | K13: =2 | L13: =-2 | M13: =3 | N13: =-3 | P13: G4 蛋白質 z = −3.825 → 不滿意；和「3_Grubbs離群」2-3 抓到的是同
B14: ='2_組成表'!A10 | C14: =INDEX('2_組成表'!$B$6:$F$10,5,MATCH($C$4,'2_組成表'!$B$4:$F$4,0)) | D14: =(C14-$C$6)/$C$5 | E14: =ABS(D14) | F14: =IF(E14<=2,"滿意 (satisfactory)",IF(E14<3,"問題 (questionable)","不滿意 (unsatisfactory)")) | H14: =IF(E14<=2,D14,0) | I14: =IF(AND(E14>2,E14<3),D14,0) | J14: =IF(E14>=3,D14,0) | K14: =2 | L14: =-2 | M14: =3 | N14: =-3 | P14: 一組，兩種方法互相印證。
B16: 分級規則
B17: |z| ≤ 2 | C17: 滿意 (satisfactory)
B18: 2 < |z| < 3 | C18: 問題 (questionable)：要查原因
B19: |z| ≥ 3 | C19: 不滿意 (unsatisfactory)：要找出原因並改正
B21: 各等級組數
B22: 滿意 | C22: =COUNTIF($F$10:$F$14,"滿意 (satisfactory)")
B23: 問題 | C23: =COUNTIF($F$10:$F$14,"問題 (questionable)")
B24: 不滿意 | C24: =COUNTIF($F$10:$F$14,"不滿意 (unsatisfactory)")

Sheet 6_管制圖
B1: 步驟 5 Shewhart 管制圖與 Westgard 規則（QC 檢核樣品）
B2: 管制界線用「既有基準」（歷史建立的平均與 s），不是用這 12 點自己算——否則違規點會把界線撐大，自己把自己吃掉。
B4: QC 項目代號 | D4: fat_qc_check
B5: 既有平均 | D5: 26
B6: 既有 s | D6: 0.3
N8: 圖用輔助數據（界線）
B9: run | C9: 數值 (%) | D9: z | E9: 1_3s | F9: 2_2s | G9: R_4s | H9: 4_1s 起點 | I9: 4_1s | J9: 10_x 起點 | K9: 10_x | L9: 任一違規 | N9: x | O9: y | Q9: z = (數值 − 既有平均) ÷ 既有 s，代表「離中心線幾個 s」。每條規則一欄，
B10: 1 | C10: =IF(COUNTIFS('1_原始數據'!$C$2:$C$1000,$D$4,'1_原始數據'!$D$2:$D$1000,B10)=0,"",SUMIFS('1_原始數據'!$E$2:$E$1000,'1_原始數據'!$C$2:$C$1000,$D$4,'1_原始數據'!$D$2:$D$1000,B10)) | D10: =(C10-$D$5)/$D$6 | E10: =IF(ABS(D10)>3,"✘","") | F10: =IF(OR(AND(ABS(D10)>2,ABS(D11)>2,(D10>0)=(D11>0))),"✘","") | G10: =IF(ABS(D10-D11)>4,"✘","") | H10: =IF(OR(COUNTIF(D10:D13,">1")=4,COUNTIF(D10:D13,"<-1")=4),"起點","") | I10: =IF(COUNTIF(H10:H10,"起點")>0,"✘","") | J10: =IF(OR(COUNTIF(D10:D19,">0")=10,COUNTIF(D10:D19,"<0")=10),"起點","") | K10: =IF(COUNTIF(J10:J10,"起點")>0,"✘","") | L10: =IF(COUNTIF(E10:K10,"✘")>0,"違規","") | N10: =MIN($B$10:$B$21) | O10: =$D$5+(0)*$D$6 | Q10: 違規打 ✘；4_1s 與 10_x 要看一段連續的點，所以先標出「起點」，再把這一段裡的每一
B11: 2 | C11: =IF(COUNTIFS('1_原始數據'!$C$2:$C$1000,$D$4,'1_原始數據'!$D$2:$D$1000,B11)=0,"",SUMIFS('1_原始數據'!$E$2:$E$1000,'1_原始數據'!$C$2:$C$1000,$D$4,'1_原始數據'!$D$2:$D$1000,B11)) | D11: =(C11-$D$5)/$D$6 | E11: =IF(ABS(D11)>3,"✘","") | F11: =IF(OR(AND(ABS(D10)>2,ABS(D11)>2,(D10>0)=(D11>0)),AND(ABS(D11)>2,ABS(D12)>2,(D11>0)=(D12>0))),"✘","") | G11: =IF(ABS(D11-D12)>4,"✘","") | H11: =IF(OR(COUNTIF(D11:D14,">1")=4,COUNTIF(D11:D14,"<-1")=4),"起點","") | I11: =IF(COUNTIF(H10:H11,"起點")>0,"✘","") | J11: =IF(OR(COUNTIF(D11:D20,">0")=10,COUNTIF(D11:D20,"<0")=10),"起點","") | K11: =IF(COUNTIF(J10:J11,"起點")>0,"✘","") | L11: =IF(COUNTIF(E11:K11,"✘")>0,"違規","") | N11: =MAX($B$10:$B$21) | O11: =$D$5+(0)*$D$6 | Q11: 點都標 ✘。
B12: 3 | C12: =IF(COUNTIFS('1_原始數據'!$C$2:$C$1000,$D$4,'1_原始數據'!$D$2:$D$1000,B12)=0,"",SUMIFS('1_原始數據'!$E$2:$E$1000,'1_原始數據'!$C$2:$C$1000,$D$4,'1_原始數據'!$D$2:$D$1000,B12)) | D12: =(C12-$D$5)/$D$6 | E12: =IF(ABS(D12)>3,"✘","") | F12: =IF(OR(AND(ABS(D11)>2,ABS(D12)>2,(D11>0)=(D12>0)),AND(ABS(D12)>2,ABS(D13)>2,(D12>0)=(D13>0))),"✘","") | G12: =IF(ABS(D12-D13)>4,"✘","") | H12: =IF(OR(COUNTIF(D12:D15,">1")=4,COUNTIF(D12:D15,"<-1")=4),"起點","") | I12: =IF(COUNTIF(H10:H12,"起點")>0,"✘","") | J12: =IF(OR(COUNTIF(D12:D21,">0")=10,COUNTIF(D12:D21,"<0")=10),"起點","") | K12: =IF(COUNTIF(J10:J12,"起點")>0,"✘","") | L12: =IF(COUNTIF(E12:K12,"✘")>0,"違規","") | N12: =MIN($B$10:$B$21) | O12: =$D$5+(2)*$D$6 | Q12: =IF(ABS(D10)>3,"✘","") 1_3s：|z| > 3 就違規
B13: 4 | C13: =IF(COUNTIFS('1_原始數據'!$C$2:$C$1000,$D$4,'1_原始數據'!$D$2:$D$1000,B13)=0,"",SUMIFS('1_原始數據'!$E$2:$E$1000,'1_原始數據'!$C$2:$C$1000,$D$4,'1_原始數據'!$D$2:$D$1000,B13)) | D13: =(C13-$D$5)/$D$6 | E13: =IF(ABS(D13)>3,"✘","") | F13: =IF(OR(AND(ABS(D12)>2,ABS(D13)>2,(D12>0)=(D13>0)),AND(ABS(D13)>2,ABS(D14)>2,(D13>0)=(D14>0))),"✘","") | G13: =IF(ABS(D13-D14)>4,"✘","") | H13: =IF(OR(COUNTIF(D13:D16,">1")=4,COUNTIF(D13:D16,"<-1")=4),"起點","") | I13: =IF(COUNTIF(H10:H13,"起點")>0,"✘","") | J13: ="" | K13: =IF(COUNTIF(J10:J12,"起點")>0,"✘","") | L13: =IF(COUNTIF(E13:K13,"✘")>0,"違規","") | N13: =MAX($B$10:$B$21) | O13: =$D$5+(2)*$D$6 | Q13: 2_2s：這一點和前一點（或後一點）都 |z| > 2，而且同號 (D>0)=(D>0)
B14: 5 | C14: =IF(COUNTIFS('1_原始數據'!$C$2:$C$1000,$D$4,'1_原始數據'!$D$2:$D$1000,B14)=0,"",SUMIFS('1_原始數據'!$E$2:$E$1000,'1_原始數據'!$C$2:$C$1000,$D$4,'1_原始數據'!$D$2:$D$1000,B14)) | D14: =(C14-$D$5)/$D$6 | E14: =IF(ABS(D14)>3,"✘","") | F14: =IF(OR(AND(ABS(D13)>2,ABS(D14)>2,(D13>0)=(D14>0)),AND(ABS(D14)>2,ABS(D15)>2,(D14>0)=(D15>0))),"✘","") | G14: =IF(ABS(D14-D15)>4,"✘","") | H14: =IF(OR(COUNTIF(D14:D17,">1")=4,COUNTIF(D14:D17,"<-1")=4),"起點","") | I14: =IF(COUNTIF(H11:H14,"起點")>0,"✘","") | J14: ="" | K14: =IF(COUNTIF(J10:J12,"起點")>0,"✘","") | L14: =IF(COUNTIF(E14:K14,"✘")>0,"違規","") | N14: =MIN($B$10:$B$21) | O14: =$D$5+(-2)*$D$6
B15: 6 | C15: =IF(COUNTIFS('1_原始數據'!$C$2:$C$1000,$D$4,'1_原始數據'!$D$2:$D$1000,B15)=0,"",SUMIFS('1_原始數據'!$E$2:$E$1000,'1_原始數據'!$C$2:$C$1000,$D$4,'1_原始數據'!$D$2:$D$1000,B15)) | D15: =(C15-$D$5)/$D$6 | E15: =IF(ABS(D15)>3,"✘","") | F15: =IF(OR(AND(ABS(D14)>2,ABS(D15)>2,(D14>0)=(D15>0)),AND(ABS(D15)>2,ABS(D16)>2,(D15>0)=(D16>0))),"✘","") | G15: =IF(ABS(D15-D16)>4,"✘","") | H15: =IF(OR(COUNTIF(D15:D18,">1")=4,COUNTIF(D15:D18,"<-1")=4),"起點","") | I15: =IF(COUNTIF(H12:H15,"起點")>0,"✘","") | J15: ="" | K15: =IF(COUNTIF(J10:J12,"起點")>0,"✘","") | L15: =IF(COUNTIF(E15:K15,"✘")>0,"違規","") | N15: =MAX($B$10:$B$21) | O15: =$D$5+(-2)*$D$6 | Q15: 4_1s 起點：=COUNTIF(D10:D13,">1")=4 四點都 > +1s（或都
B16: 7 | C16: =IF(COUNTIFS('1_原始數據'!$C$2:$C$1000,$D$4,'1_原始數據'!$D$2:$D$1000,B16)=0,"",SUMIFS('1_原始數據'!$E$2:$E$1000,'1_原始數據'!$C$2:$C$1000,$D$4,'1_原始數據'!$D$2:$D$1000,B16)) | D16: =(C16-$D$5)/$D$6 | E16: =IF(ABS(D16)>3,"✘","") | F16: =IF(OR(AND(ABS(D15)>2,ABS(D16)>2,(D15>0)=(D16>0)),AND(ABS(D16)>2,ABS(D17)>2,(D16>0)=(D17>0))),"✘","") | G16: =IF(ABS(D16-D17)>4,"✘","") | H16: =IF(OR(COUNTIF(D16:D19,">1")=4,COUNTIF(D16:D19,"<-1")=4),"起點","") | I16: =IF(COUNTIF(H13:H16,"起點")>0,"✘","") | J16: ="" | K16: =IF(COUNTIF(J10:J12,"起點")>0,"✘","") | L16: =IF(COUNTIF(E16:K16,"✘")>0,"違規","") | N16: =MIN($B$10:$B$21) | O16: =$D$5+(3)*$D$6 | Q16: < −1s）
B17: 8 | C17: =IF(COUNTIFS('1_原始數據'!$C$2:$C$1000,$D$4,'1_原始數據'!$D$2:$D$1000,B17)=0,"",SUMIFS('1_原始數據'!$E$2:$E$1000,'1_原始數據'!$C$2:$C$1000,$D$4,'1_原始數據'!$D$2:$D$1000,B17)) | D17: =(C17-$D$5)/$D$6 | E17: =IF(ABS(D17)>3,"✘","") | F17: =IF(OR(AND(ABS(D16)>2,ABS(D17)>2,(D16>0)=(D17>0)),AND(ABS(D17)>2,ABS(D18)>2,(D17>0)=(D18>0))),"✘","") | G17: =IF(ABS(D17-D18)>4,"✘","") | H17: =IF(OR(COUNTIF(D17:D20,">1")=4,COUNTIF(D17:D20,"<-1")=4),"起點","") | I17: =IF(COUNTIF(H14:H17,"起點")>0,"✘","") | J17: ="" | K17: =IF(COUNTIF(J10:J12,"起點")>0,"✘","") | L17: =IF(COUNTIF(E17:K17,"✘")>0,"違規","") | N17: =MAX($B$10:$B$21) | O17: =$D$5+(3)*$D$6
B18: 9 | C18: =IF(COUNTIFS('1_原始數據'!$C$2:$C$1000,$D$4,'1_原始數據'!$D$2:$D$1000,B18)=0,"",SUMIFS('1_原始數據'!$E$2:$E$1000,'1_原始數據'!$C$2:$C$1000,$D$4,'1_原始數據'!$D$2:$D$1000,B18)) | D18: =(C18-$D$5)/$D$6 | E18: =IF(ABS(D18)>3,"✘","") | F18: =IF(OR(AND(ABS(D17)>2,ABS(D18)>2,(D17>0)=(D18>0)),AND(ABS(D18)>2,ABS(D19)>2,(D18>0)=(D19>0))),"✘","") | G18: =IF(ABS(D18-D19)>4,"✘","") | H18: =IF(OR(COUNTIF(D18:D21,">1")=4,COUNTIF(D18:D21,"<-1")=4),"起點","") | I18: =IF(COUNTIF(H15:H18,"起點")>0,"✘","") | J18: ="" | K18: =IF(COUNTIF(J10:J12,"起點")>0,"✘","") | L18: =IF(COUNTIF(E18:K18,"✘")>0,"違規","") | N18: =MIN($B$10:$B$21) | O18: =$D$5+(-3)*$D$6
B19: 10 | C19: =IF(COUNTIFS('1_原始數據'!$C$2:$C$1000,$D$4,'1_原始數據'!$D$2:$D$1000,B19)=0,"",SUMIFS('1_原始數據'!$E$2:$E$1000,'1_原始數據'!$C$2:$C$1000,$D$4,'1_原始數據'!$D$2:$D$1000,B19)) | D19: =(C19-$D$5)/$D$6 | E19: =IF(ABS(D19)>3,"✘","") | F19: =IF(OR(AND(ABS(D18)>2,ABS(D19)>2,(D18>0)=(D19>0)),AND(ABS(D19)>2,ABS(D20)>2,(D19>0)=(D20>0))),"✘","") | G19: =IF(ABS(D19-D20)>4,"✘","") | H19: ="" | I19: =IF(COUNTIF(H16:H18,"起點")>0,"✘","") | J19: ="" | K19: =IF(COUNTIF(J10:J12,"起點")>0,"✘","") | L19: =IF(COUNTIF(E19:K19,"✘")>0,"違規","") | N19: =MAX($B$10:$B$21) | O19: =$D$5+(-3)*$D$6
B20: 11 | C20: =IF(COUNTIFS('1_原始數據'!$C$2:$C$1000,$D$4,'1_原始數據'!$D$2:$D$1000,B20)=0,"",SUMIFS('1_原始數據'!$E$2:$E$1000,'1_原始數據'!$C$2:$C$1000,$D$4,'1_原始數據'!$D$2:$D$1000,B20)) | D20: =(C20-$D$5)/$D$6 | E20: =IF(ABS(D20)>3,"✘","") | F20: =IF(OR(AND(ABS(D19)>2,ABS(D20)>2,(D19>0)=(D20>0)),AND(ABS(D20)>2,ABS(D21)>2,(D20>0)=(D21>0))),"✘","") | G20: =IF(ABS(D20-D21)>4,"✘","") | H20: ="" | I20: =IF(COUNTIF(H17:H18,"起點")>0,"✘","") | J20: ="" | K20: =IF(COUNTIF(J11:J12,"起點")>0,"✘","") | L20: =IF(COUNTIF(E20:K20,"✘")>0,"違規","")
B21: 12 | C21: =IF(COUNTIFS('1_原始數據'!$C$2:$C$1000,$D$4,'1_原始數據'!$D$2:$D$1000,B21)=0,"",SUMIFS('1_原始數據'!$E$2:$E$1000,'1_原始數據'!$C$2:$C$1000,$D$4,'1_原始數據'!$D$2:$D$1000,B21)) | D21: =(C21-$D$5)/$D$6 | E21: =IF(ABS(D21)>3,"✘","") | F21: =IF(OR(AND(ABS(D20)>2,ABS(D21)>2,(D20>0)=(D21>0))),"✘","") | G21: ="" | H21: ="" | I21: =IF(COUNTIF(H18:H18,"起點")>0,"✘","") | J21: ="" | K21: =IF(COUNTIF(J12:J12,"起點")>0,"✘","") | L21: =IF(COUNTIF(E21:K21,"✘")>0,"違規","")
Q22: 本批數據：run 8 觸發 1_3s（26.95%），run 10、11 觸發 2_2s；
Q23: R_4s、4_1s、10_x 沒有觸發——不同規則抓不同型態的異常，這批沒有緩慢飄移。
B24: 規則檢查結果
B25: 規則 | D25: 違規點數 | E25: 第一個違規 run | G25: 意思
B26: 1_3s | D26: =COUNTIF(E10:E21,"✘") | E26: =IF(D26=0,"沒有違規",INDEX($B$10:$B$21,MATCH("✘",E10:E21,0))) | G26: 任一點超出 ±3s：單次劇烈失控
B27: 2_2s | D27: =COUNTIF(F10:F21,"✘") | E27: =IF(D27=0,"沒有違規",INDEX($B$10:$B$21,MATCH("✘",F10:F21,0))) | G27: 連續兩點同側超出 ±2s：短期系統性偏移
B28: R_4s | D28: =COUNTIF(G10:G21,"✘") | E28: =IF(D28=0,"沒有違規",INDEX($B$10:$B$21,MATCH("✘",G10:G21,0))) | G28: 相鄰兩點差距超過 4s（標在前一點）：隨機誤差變大
B29: 4_1s | D29: =COUNTIF(I10:I21,"✘") | E29: =IF(D29=0,"沒有違規",INDEX($B$10:$B$21,MATCH("✘",I10:I21,0))) | G29: 連續四點同側超出 ±1s：緩慢飄移
B30: 10_x | D30: =COUNTIF(K10:K21,"✘") | E30: =IF(D30=0,"沒有違規",INDEX($B$10:$B$21,MATCH("✘",K10:K21,0))) | G30: 連續十點在中心線同一側：緩慢飄移
B31: 結論 | D31: =IF(COUNTIF(L10:L21,"違規")>0,"有違規（紅色列）：這些 run 失控，要先找原因，該批結果不能直接報告","全部在管制內")
B53: 看圖：黑線＝既有平均；橘色虛線＝±2s（警告線）；紅色點線＝±3s（管制線）。run 8 跑出紅線上方，run 10、11 連續兩點在下方橘線以外。

Sheet 7_不確定度
B1: 步驟 6 量測不確定度預算（蛋白質 Kjeldahl）與碳水化合物的不確定度
B2: 每個來源先換成「標準不確定度」（矩形分布＝半寬 ÷ √3；已經是標準差型式的直接用），再用平方和開根號合併成 u_c，最後乘上涵蓋因子 k=2 得到擴充不確定度 U（約 95% 信心水準）。
B4: 參考量：蛋白質指定值（5 組中位數, %） | C4: =MEDIAN('2_組成表'!D6:D10)
B5: 涵蓋因子 k | C5: 2
B6: 助教重複測定 s_r (%) | C6: {=_xlfn.STDEV.S(IF('1_原始數據'!$C$2:$C$1000="protein_repeatability",'1_原始數據'!$E$2:$E$1000))} | D6: n = | E6: =COUNTIF('1_原始數據'!$C$2:$C$1000,"protein_repeatability")
B8: 7-1 蛋白質不確定度預算
B9: 來源 | C9: 說明 | D9: 輸入值 | E9: 除數 | F9: 參考量 | G9: 相對標準不確定度 (%) | H9: 占 u_c² (%) | J9: 黃色格子可改（練習題 4：把滴定劑濃度 0.30 改成 0.10）。除數 √3 是矩形分布；
B10: 秤重 weighing | C10: 分析天平 ±0.0002 g，矩形分布；樣品 1.0000 g | D10: 0.0002 | E10: =SQRT(3) | F10: 1 | G10: =D10/E10/F10*100 | H10: =G10^2/SUMSQ($G$10:$G$14)*100 | J10: 已經是 SD 的來源除數填 1。
B11: 滴定劑濃度 titrant conc. | C11: HCl 標定後的相對標準不確定度 0.30%（已是標準差型式） | D11: 0.3 | E11: 1 | F11: （已是 %） | G11: =D11/E11 | H11: =G11^2/SUMSQ($G$10:$G$14)*100 | J11: 相對標準不確定度 = 輸入值 ÷ 除數 ÷ 參考量 × 100。
B12: 滴定體積 titration volume | C12: 滴定管刻度 ±0.05 mL，矩形分布；滴定約 25.0 mL | D12: 0.05 | E12: =SQRT(3) | F12: 25 | G12: =D12/E12/F12*100 | H12: =G12^2/SUMSQ($G$10:$G$14)*100
B13: 轉換因子 6.38 | C13: 牛乳蛋白質係數 6.38 ± 0.03，矩形分布 | D13: 0.03 | E13: =SQRT(3) | F13: 6.38 | G13: =D13/E13/F13*100 | H13: =G13^2/SUMSQ($G$10:$G$14)*100
B14: 重複性 repeatability | C14: 助教 3 重複的 s_r；每組報告單次值，所以不除以 √n | D14: =C6 | E14: 1 | F14: =C4 | G14: =D14/E14/F14*100 | H14: =G14^2/SUMSQ($G$10:$G$14)*100 | J14: 重複性這一項：每組蛋白質只消化 1 管（n=1），無法用組內重複估計 s_r，
J15: 改用助教同一份奶粉的 3 重複。
B16: 合併相對標準不確定度 u_c (%) | C16: =SQRT(SUMSQ(G10:G14)) | J16: =SQRT(SUMSQ(G10:G14)) SUMSQ 把每個數平方後加總；
B17: 合併絕對標準不確定度 u_c (%) | C17: =C4*C16/100 | J17: 再開根號就是「平方和開根號」(RSS)。
B18: 擴充不確定度 U = k·u_c (%) | C18: =C5*C17 | J18: u_c(絕對) = 指定值 × u_c(相對) ÷ 100
B19: 最大的分量 | C19: =INDEX(B10:B14,MATCH(MAX(G10:G14),G10:G14,0)) | J19: U = k × u_c；k = 2 約對應 95% 信心水準。
B20: 報告寫法 | C20: ="蛋白質 = "&FIXED(C4,2)&"% ± "&FIXED(C18,2)&"%（U, k="&C5&"）" | J20: FIXED(數字, 2) 把數字轉成小數 2 位的文字，用 & 串成一句話。
B23: 7-2 碳水化合物（差減法）的不確定度
B24: 成分 | C24: 來源 | D24: 標準不確定度 u (%) | E24: u²
B25: 水分 | C25: W2 方法精密度（示意值，給定） | D25: 0.05 | E25: =D25^2 | J25: 差減法沒有自己的實驗步驟，四項的不確定度都被帶進碳水化合物，所以它永遠是 proximate
B26: 灰分 | C26: W3 方法精密度（示意值，給定） | D26: 0.08 | E26: =D26^2 | J26: 分析中不確定度最大的一項。
B27: 蛋白質 | C27: 上面 7-1 的 u_c（絕對） | D27: =C17 | E27: =D27^2
B28: 脂肪 | C28: W6 Soxhlet 精密度（示意值，給定） | D28: 0.35 | E28: =D28^2
B30: u_碳水 = √(Σu²) (%) | C30: =SQRT(SUMSQ(D25:D28)) | J30: 不確定度不能直接相加：隨機誤差會部分抵銷，所以用平方和開根號。直接相加會高估。
B31: U_碳水 = k·u (%) | C31: =C5*C30
B32: 對照：直接相加（錯誤做法）(%) | C32: =SUM(D25:D28) | J32: 注意：U_碳水 只涵蓋隨機的不確定度（約 ±0.8%）。脂肪用直接 Soxhlet 造成的方
J33: 法偏差（約 −4.4 個百分點）會原封不動加到碳水化合物上，U 蓋不住它——
J34: 見「9_資料庫比對」。

Sheet 8_放行判定
B1: 步驟 7 放行判定：guard band（防護帶）規則
B2: 奶油測得 80.3% ± 0.4%（U, k=2），規格乳脂 ≥ 80%，可以放行嗎？點估計高於規格 ≠ 這批一定合格。要看「結果 ± U」整段和規格的關係。
B5: 案例 | C5: 結果 | D5: U (k=2) | E5: 規格 | F5: 規格類型 ≥ 下限／≤ 上限 | G5: 最壞情況 | H5: 最佳情況 | I5: 判定 | K5: 黃色都可以改。第 12、13 列留給你自己的案例（例如「7_不確定度」算出的蛋白質 ± U
B6: 奶油 乳脂 (butter fat, %) | C6: 80.3 | D6: 0.4 | E6: 80 | F6: ≥ | G6: =IF(C6="","",IF(F6="≥",C6-D6,C6+D6)) | H6: =IF(C6="","",IF(F6="≥",C6+D6,C6-D6)) | I6: =IF(C6="","",IF(F6="≥",IF(G6>=E6,"放行 (pass)",IF(H6<E6,"不放行 (fail)","無法判斷 (inconclusive)")),IF(G6<=E6,"放行 (pass)",IF(H6>E6,"不放行 (fail)","無法判斷 (inconclusive)")))) | K6: 對規格 ≥ 25%）。F 欄用下拉選單選 ≥ 或 ≤。
B7: 全脂奶粉 蛋白質 (milk powder protein, %) | C7: 26.5 | D7: 0.3 | E7: 25 | F7: ≥ | G7: =IF(C7="","",IF(F7="≥",C7-D7,C7+D7)) | H7: =IF(C7="","",IF(F7="≥",C7+D7,C7-D7)) | I7: =IF(C7="","",IF(F7="≥",IF(G7>=E7,"放行 (pass)",IF(H7<E7,"不放行 (fail)","無法判斷 (inconclusive)")),IF(G7<=E7,"放行 (pass)",IF(H7>E7,"不放行 (fail)","無法判斷 (inconclusive)")))) | K7: 判定公式是兩層 IF：先看規格類型，再依序問「最壞情況過關嗎？」「最佳情況也不過關嗎？」。
B8: 全脂奶粉 水分 (milk powder moisture, %) | C8: 3.6 | D8: 0.15 | E8: 3.5 | F8: ≤ | G8: =IF(C8="","",IF(F8="≥",C8-D8,C8+D8)) | H8: =IF(C8="","",IF(F8="≥",C8+D8,C8-D8)) | I8: =IF(C8="","",IF(F8="≥",IF(G8>=E8,"放行 (pass)",IF(H8<E8,"不放行 (fail)","無法判斷 (inconclusive)")),IF(G8<=E8,"放行 (pass)",IF(H8>E8,"不放行 (fail)","無法判斷 (inconclusive)"))))
B9: 罐頭湯 鈉 (canned soup sodium, mg/100g) | C9: 620 | D9: 15 | E9: 500 | F9: ≤ | G9: =IF(C9="","",IF(F9="≥",C9-D9,C9+D9)) | H9: =IF(C9="","",IF(F9="≥",C9+D9,C9-D9)) | I9: =IF(C9="","",IF(F9="≥",IF(G9>=E9,"放行 (pass)",IF(H9<E9,"不放行 (fail)","無法判斷 (inconclusive)")),IF(G9<=E9,"放行 (pass)",IF(H9>E9,"不放行 (fail)","無法判斷 (inconclusive)"))))
B10: 果汁 維生素C (juice vitamin C, mg/100mL) | C10: 33 | D10: 1 | E10: 30 | F10: ≥ | G10: =IF(C10="","",IF(F10="≥",C10-D10,C10+D10)) | H10: =IF(C10="","",IF(F10="≥",C10+D10,C10-D10)) | I10: =IF(C10="","",IF(F10="≥",IF(G10>=E10,"放行 (pass)",IF(H10<E10,"不放行 (fail)","無法判斷 (inconclusive)")),IF(G10<=E10,"放行 (pass)",IF(H10>E10,"不放行 (fail)","無法判斷 (inconclusive)"))))
B11: 巧克力 水分 (chocolate moisture, %) | C11: 2.3 | D11: 0.1 | E11: 2 | F11: ≤ | G11: =IF(C11="","",IF(F11="≥",C11-D11,C11+D11)) | H11: =IF(C11="","",IF(F11="≥",C11+D11,C11-D11)) | I11: =IF(C11="","",IF(F11="≥",IF(G11>=E11,"放行 (pass)",IF(H11<E11,"不放行 (fail)","無法判斷 (inconclusive)")),IF(G11<=E11,"放行 (pass)",IF(H11>E11,"不放行 (fail)","無法判斷 (inconclusive)"))))
B12: （自己的案例） | G12: =IF(C12="","",IF(F12="≥",C12-D12,C12+D12)) | H12: =IF(C12="","",IF(F12="≥",C12+D12,C12-D12)) | I12: =IF(C12="","",IF(F12="≥",IF(G12>=E12,"放行 (pass)",IF(H12<E12,"不放行 (fail)","無法判斷 (inconclusive)")),IF(G12<=E12,"放行 (pass)",IF(H12>E12,"不放行 (fail)","無法判斷 (inconclusive)"))))
B13: （自己的案例） | G13: =IF(C13="","",IF(F13="≥",C13-D13,C13+D13)) | H13: =IF(C13="","",IF(F13="≥",C13+D13,C13-D13)) | I13: =IF(C13="","",IF(F13="≥",IF(G13>=E13,"放行 (pass)",IF(H13<E13,"不放行 (fail)","無法判斷 (inconclusive)")),IF(G13<=E13,"放行 (pass)",IF(H13>E13,"不放行 (fail)","無法判斷 (inconclusive)"))))
B16: guard band 規則（本課採用）
B17: • 規格是「≥ 下限」：最壞情況＝結果 − U，最佳情況＝結果 + U。最壞情況 ≥ 規格 → 放行；最佳情況 < 規格 → 不放行；其餘 → 無法判斷。
B18: • 規格是「≤ 上限」：最壞情況＝結果 + U，最佳情況＝結果 − U。最壞情況 ≤ 規格 → 放行；最佳情況 > 規格 → 不放行；其餘 → 無法判斷。
B19: • 「無法判斷」＝規格落在「結果 ± U」區間內：需要複測（降低 U）或和客戶協商，不是直接放行。
B20: • 奶油：80.3 已高於 80，但最壞情況 80.3 − 0.4 = 79.9 < 80，所以是「無法判斷」，不是「放行」。

Sheet 9_資料庫比對
B1: 步驟 8 用資料庫檢查全班盲樣：全脂奶粉 vs USDA 與 TFND
B2: 前面的 Grubbs、ANOVA、z-score 都是「全班互相比」。這裡換成外部參考：USDA FoodData Central SR Legacy 170876（173454 的一般成分數值相同）與衛福部食藥署食品營養成分資料庫 L0200101「全脂奶粉」。單位都是 g/100 g（濕基）。
B4: 9-1 全班 proximate 結果 vs 資料庫合理範圍
B5: 營養素 | C5: 中文 | D5: 本班項目 | E5: USDA 170876 | F5: USDA 173454 | G5: TFND L0200101 | H5: TFND SD | I5: TFND n | J5: 相對容許差 | K5: 絕對下限 | L5: USDA 下限 | M5: USDA 上限 | N5: TFND 下限 | O5: TFND 上限 | P5: 合理範圍 下限 | Q5: 合理範圍 上限 | R5: 中心值 | S5: 全班中位數 | T5: 狀態 | U5: USDA 涵蓋？ | V5: TFND 涵蓋？ | W5: 全班 − 中心值 | Z5: E–K 欄（黃色）是資料庫數值與教學預設容許差，取自 data/reference_food
B6: water | C6: 水分 | D6: moisture | E6: 2.47 | F6: 2.47 | G6: 2.8 | H6: 0.1 | I6: 2 | J6: 0.1 | K6: 0.3 | L6: =MAX(0,E6-MAX($J6*E6,$K6)) | M6: =E6+MAX($J6*E6,$K6) | N6: =MAX(0,IF(AND(H6<>"",I6>=2),MIN(G6-MAX($J6*G6,$K6),G6-2*H6),G6-MAX($J6*G6,$K6))) | O6: =IF(AND(H6<>"",I6>=2),MAX(G6+MAX($J6*G6,$K6),G6+2*H6),G6+MAX($J6*G6,$K6)) | P6: =MIN(L6,N6) | Q6: =MAX(M6,O6) | R6: =AVERAGE(E6:G6) | S6: =INDEX('2_組成表'!$B$11:$F$11,MATCH(D6,'2_組成表'!$B$4:$F$4,0)) | T6: =IF(S6<P6,"偏低",IF(S6>Q6,"偏高","範圍內")) | U6: =IF(AND(S6>=L6,S6<=M6),"✓","✗") | V6: =IF(AND(S6>=N6,S6<=O6),"✓","✗") | W6: =S6-R6 | Z6: s.json，不要亂改。每一筆資料庫數值的區間 = 數值 ± max(相對容許差 × 數值,
B7: ash | C7: 灰分 | D7: ash | E7: 6.08 | F7: 6.08 | G7: 5.6 | H7: 0 | I7: 2 | J7: 0.15 | K7: 0.05 | L7: =MAX(0,E7-MAX($J7*E7,$K7)) | M7: =E7+MAX($J7*E7,$K7) | N7: =MAX(0,IF(AND(H7<>"",I7>=2),MIN(G7-MAX($J7*G7,$K7),G7-2*H7),G7-MAX($J7*G7,$K7))) | O7: =IF(AND(H7<>"",I7>=2),MAX(G7+MAX($J7*G7,$K7),G7+2*H7),G7+MAX($J7*G7,$K7)) | P7: =MIN(L7,N7) | Q7: =MAX(M7,O7) | R7: =AVERAGE(E7:G7) | S7: =INDEX('2_組成表'!$B$11:$F$11,MATCH(D7,'2_組成表'!$B$4:$F$4,0)) | T7: =IF(S7<P7,"偏低",IF(S7>Q7,"偏高","範圍內")) | U7: =IF(AND(S7>=L7,S7<=M7),"✓","✗") | V7: =IF(AND(S7>=N7,S7<=O7),"✓","✗") | W7: =S7-R7 | Z7: 絕對下限)；TFND 有 SD 且 n ≥ 2 時再和「平均 ± 2SD」取聯集。
B8: protein | C8: 蛋白質 | D8: protein | E8: 26.32 | F8: 26.32 | G8: 26.4 | H8: 0.3 | I8: 2 | J8: 0.1 | K8: 0.3 | L8: =MAX(0,E8-MAX($J8*E8,$K8)) | M8: =E8+MAX($J8*E8,$K8) | N8: =MAX(0,IF(AND(H8<>"",I8>=2),MIN(G8-MAX($J8*G8,$K8),G8-2*H8),G8-MAX($J8*G8,$K8))) | O8: =IF(AND(H8<>"",I8>=2),MAX(G8+MAX($J8*G8,$K8),G8+2*H8),G8+MAX($J8*G8,$K8)) | P8: =MIN(L8,N8) | Q8: =MAX(M8,O8) | R8: =AVERAGE(E8:G8) | S8: =INDEX('2_組成表'!$B$11:$F$11,MATCH(D8,'2_組成表'!$B$4:$F$4,0)) | T8: =IF(S8<P8,"偏低",IF(S8>Q8,"偏高","範圍內")) | U8: =IF(AND(S8>=L8,S8<=M8),"✓","✗") | V8: =IF(AND(S8>=N8,S8<=O8),"✓","✗") | W8: =S8-R8 | Z8: 合理範圍 = 各筆區間的聯集（最小的下限到最大的上限）。容許差是教學假設，不是資料庫數值。
B9: fat | C9: 脂肪 | D9: fat | E9: 26.71 | F9: 26.71 | G9: 28.2 | H9: 0.6 | I9: 2 | J9: 0.15 | K9: 0.3 | L9: =MAX(0,E9-MAX($J9*E9,$K9)) | M9: =E9+MAX($J9*E9,$K9) | N9: =MAX(0,IF(AND(H9<>"",I9>=2),MIN(G9-MAX($J9*G9,$K9),G9-2*H9),G9-MAX($J9*G9,$K9))) | O9: =IF(AND(H9<>"",I9>=2),MAX(G9+MAX($J9*G9,$K9),G9+2*H9),G9+MAX($J9*G9,$K9)) | P9: =MIN(L9,N9) | Q9: =MAX(M9,O9) | R9: =AVERAGE(E9:G9) | S9: =INDEX('2_組成表'!$B$11:$F$11,MATCH(D9,'2_組成表'!$B$4:$F$4,0)) | T9: =IF(S9<P9,"偏低",IF(S9>Q9,"偏高","範圍內")) | U9: =IF(AND(S9>=L9,S9<=M9),"✓","✗") | V9: =IF(AND(S9>=N9,S9<=O9),"✓","✗") | W9: =S9-R9 | Z9: 水分：全班 2.85% 在合理範圍內，但只被 TFND 那一筆涵蓋（USDA ✗）
B10: carbohydrate | C10: 碳水化合物 | D10: carbohydrate | E10: 38.42 | F10: 38.42 | G10: 37 | J10: 0.1 | K10: 1 | L10: =MAX(0,E10-MAX($J10*E10,$K10)) | M10: =E10+MAX($J10*E10,$K10) | N10: =MAX(0,IF(AND(H10<>"",I10>=2),MIN(G10-MAX($J10*G10,$K10),G10-2*H10),G10-MAX($J10*G10,$K10))) | O10: =IF(AND(H10<>"",I10>=2),MAX(G10+MAX($J10*G10,$K10),G10+2*H10),G10+MAX($J10*G10,$K10)) | P10: =MIN(L10,N10) | Q10: =MAX(M10,O10) | R10: =AVERAGE(E10:G10) | S10: =INDEX('2_組成表'!$B$11:$F$11,MATCH(D10,'2_組成表'!$B$4:$F$4,0)) | T10: =IF(S10<P10,"偏低",IF(S10>Q10,"偏高","範圍內")) | U10: =IF(AND(S10>=L10,S10<=M10),"✓","✗") | V10: =IF(AND(S10>=N10,S10<=O10),"✓","✗") | W10: =S10-R10 | Z10: ——看 U、V 欄，不要只看「範圍內」。
B11: sugars_total | C11: 總糖 | D11: carbohydrate | E11: 38.42 | F11: 38.42 | G11: 36.4 | J11: 0.15 | K11: 0.5 | L11: =MAX(0,E11-MAX($J11*E11,$K11)) | M11: =E11+MAX($J11*E11,$K11) | N11: =MAX(0,IF(AND(H11<>"",I11>=2),MIN(G11-MAX($J11*G11,$K11),G11-2*H11),G11-MAX($J11*G11,$K11))) | O11: =IF(AND(H11<>"",I11>=2),MAX(G11+MAX($J11*G11,$K11),G11+2*H11),G11+MAX($J11*G11,$K11)) | P11: =MIN(L11,N11) | Q11: =MAX(M11,O11) | R11: =AVERAGE(E11:G11) | S11: =INDEX('2_組成表'!$B$11:$F$11,MATCH(D11,'2_組成表'!$B$4:$F$4,0)) | T11: =IF(S11<P11,"偏低",IF(S11>Q11,"偏高","範圍內")) | U11: =IF(AND(S11>=L11,S11<=M11),"✓","✗") | V11: =IF(AND(S11>=N11,S11<=O11),"✓","✗") | W11: =S11-R11 | Z11: 脂肪偏低、碳水化合物偏高：看 W 欄「全班 − 中心值」，脂肪約 −6、碳水約 +6，
Z12: 其他三項都在 ±0.5 以內——碳水偏高幾乎完全是脂肪低估傳過來的（誤差傳遞）
B13: 蛋白質：USDA 全脂奶粉用換算係數 6.38（乳品係數），本課 W5 也用 6.38，可以直接比；TFND 開放資料沒有註明係數。 | Z13: 。
Z14: 最後一列故意拿「差減法碳水化合物」去比資料庫的「總糖」：兩者不是同一件事。USDA 的總糖
B15: 9-2 脂肪：全班「直接 Soxhlet」一起偏低 | Z15: 38.42 是由其他營養素推算（n = 0），TFND 則實際分析（36.4）
B16: Röse–Gottlieb 參考法脂肪 (%) | E16: 25.7 | Z16: 。比對前先確認資料庫欄位的定義。
B18: 組別 | D18: 脂肪 (%) 直接 Soxhlet | E18: 脂肪狀態 | F18: 碳水 (%) 差減法 | G18: 碳水狀態 | H18: 碳水 (%) 脂肪改用 RG | I18: 狀態
B19: ='2_組成表'!A6 | D19: ='2_組成表'!E6 | E19: =IF(D19<$P$9,"偏低",IF(D19>$Q$9,"偏高","範圍內")) | F19: ='2_組成表'!F6 | G19: =IF(F19<$P$10,"偏低",IF(F19>$Q$10,"偏高","範圍內")) | H19: =100-('2_組成表'!B6+'2_組成表'!C6+'2_組成表'!D6+$E$16) | I19: =IF(H19<$P$10,"偏低",IF(H19>$Q$10,"偏高","範圍內")) | K19: 5 組彼此非常接近（組間 SD 不到 0.5），卻一起落在資料庫範圍之下；Röse–Gott
B20: ='2_組成表'!A7 | D20: ='2_組成表'!E7 | E20: =IF(D20<$P$9,"偏低",IF(D20>$Q$9,"偏高","範圍內")) | F20: ='2_組成表'!F7 | G20: =IF(F20<$P$10,"偏低",IF(F20>$Q$10,"偏高","範圍內")) | H20: =100-('2_組成表'!B7+'2_組成表'!C7+'2_組成表'!D7+$E$16) | I20: =IF(H20<$P$10,"偏低",IF(H20>$Q$10,"偏高","範圍內")) | K20: lieb 參考法則在範圍內——這是方法本身的系統偏差（奶粉脂肪被蛋白質／乳糖包覆，
B21: ='2_組成表'!A8 | D21: ='2_組成表'!E8 | E21: =IF(D21<$P$9,"偏低",IF(D21>$Q$9,"偏高","範圍內")) | F21: ='2_組成表'!F8 | G21: =IF(F21<$P$10,"偏低",IF(F21>$Q$10,"偏高","範圍內")) | H21: =100-('2_組成表'!B8+'2_組成表'!C8+'2_組成表'!D8+$E$16) | I21: =IF(H21<$P$10,"偏低",IF(H21>$Q$10,"偏高","範圍內")) | K21: 未水解就萃取不完全），不是哪一組做錯。
B22: ='2_組成表'!A9 | D22: ='2_組成表'!E9 | E22: =IF(D22<$P$9,"偏低",IF(D22>$Q$9,"偏高","範圍內")) | F22: ='2_組成表'!F9 | G22: =IF(F22<$P$10,"偏低",IF(F22>$Q$10,"偏高","範圍內")) | H22: =100-('2_組成表'!B9+'2_組成表'!C9+'2_組成表'!D9+$E$16) | I22: =IF(H22<$P$10,"偏低",IF(H22>$Q$10,"偏高","範圍內"))
B23: ='2_組成表'!A10 | D23: ='2_組成表'!E10 | E23: =IF(D23<$P$9,"偏低",IF(D23>$Q$9,"偏高","範圍內")) | F23: ='2_組成表'!F10 | G23: =IF(F23<$P$10,"偏低",IF(F23>$Q$10,"偏高","範圍內")) | H23: =100-('2_組成表'!B10+'2_組成表'!C10+'2_組成表'!D10+$E$16) | I23: =IF(H23<$P$10,"偏低",IF(H23>$Q$10,"偏高","範圍內")) | K23: H 欄：把脂肪換成 Röse–Gottlieb 值（其他三項不變）重算差減法碳水，
B24: 全班平均 | D24: =AVERAGE(D19:D23) | K24: 5 組全部回到範圍內。看到差減法碳水偏高時，先回頭檢查其他四項。
B25: 組間 SD | D25: =_xlfn.STDEV.S(D19:D23)
B26: bias = 全班平均 − RG | D26: =D24-E16
B27: RG 參考值狀態 | D27: =IF(E16<$P$9,"偏低",IF(E16>$Q$9,"偏高","範圍內")) | K27: z-score 的指定值是全班中位數，全班一起偏掉時每組 z 都「滿意」（練習題 7）
K28: ；資料庫範圍很寬，單一組別的小錯（例如 G4 蛋白質）它又看不出來。兩種檢查互補。
B30: 9-3 判斷：「我這組有問題」還是「全班／方法有問題」？
B31: 線索 | D31: 我這組有問題 | I31: 全班／方法有問題
B32: 跟全班比（z、Grubbs） | D32: 只有我這組偏離 | I32: 各組彼此接近，z-score 都「滿意」
B33: 跟資料庫或參考方法比 | D33: 常常仍在資料庫範圍內（範圍很寬） | I33: 全班一起偏向同一側，甚至一起落在範圍外
B34: 下一步 | D34: 檢查本組計算、試劑濃度、操作，重做 | I34: 換方法或加前處理（例如水解），用參考物質／參考方法校正
B55: 看圖：藍色（脂肪用直接 Soxhlet）的碳水都高過紅色虛線上限；綠色（脂肪改用 Röse–Gottlieb）全部回到兩條紅線之間。（縱軸從 30 開始。）
B57: 資料來源：USDA FoodData Central SR Legacy (2018-04)，公共領域／CC0 1.0；衛生福利部食品藥物管理署「食品營養成分資料庫」，政府資料開放平臺 data.gov.tw 資料集 8543，依政府資料開放授權條款第1版釋出。
B59: 圖用輔助數據（自動）
B60: 組別 | C60: carb (Soxhlet fat) | D60: carb (RG fat) | E60: range low | F60: range high
B61: =B19 | C61: =F19 | D61: =H19 | E61: =$P$10 | F61: =$Q$10
B62: =B20 | C62: =F20 | D62: =H20 | E62: =$P$10 | F62: =$Q$10
B63: =B21 | C63: =F21 | D63: =H21 | E63: =$P$10 | F63: =$Q$10
B64: =B22 | C64: =F22 | D64: =H22 | E64: =$P$10 | F64: =$Q$10
B65: =B23 | C65: =F23 | D65: =H23 | E65: =$P$10 | F65: =$Q$10

Sheet 練習題
B1: 練習題（寫在黃色格子裡，交報告時一起附上）
B3: 問題 1：如果 G3 水分的第 3 重複值不是 3.30%，而是 3.60%，Grubbs 的 G 值變成多少？是否仍然「測不出來」（G < G_crit）？
B4: 提示：到「1_原始數據」把 E24（G3 moisture rep 3）改成 3.6，看「3_Grubbs離群」C32 與 C35。再想：G 的理論上界 C34 是多少？改完記得改回 3.3。
B7: 問題 2：班級層級 Grubbs（5 組蛋白質）中，除了被標記離群的那一組，G 值第二大的是哪一組？它的 z-score 屬於哪個等級？
B8: 提示：「3_Grubbs離群」E42:E46 是各組 G，可以用 =LARGE(E42:E46,2) 找第二大；再到「5_z分數」看同一組的分級。
B11: 問題 3：灰分 ANOVA 的 s_r（重複性）與 s_L（組間）哪一個大？這代表什麼？如果 s_L 降到幾乎 0，s_R 會接近什麼？
B12: 提示：「4_ANOVA」C26:C28。s_R = √(s_r² + s_L²)。
B15: 問題 4：蛋白質不確定度預算中哪一個分量貢獻最大？把滴定劑濃度的相對標準不確定度從 0.30% 降到 0.10%，u_c（相對）變成多少？影響大不大？
B16: 提示：「7_不確定度」H 欄是每一項占 u_c² 的比例；把 D11 改成 0.1，看 C16。改完記得改回 0.30。
B19: 問題 5：巧克力水分的規格從 ≤ 2% 放寬成 ≤ 2.5%，結果仍是 2.30% ± 0.10%，用 guard band 規則重新判定，結論會改變嗎？
B20: 提示：「8_放行判定」把 E11 改成 2.5。
B23: 問題 6：假設 G4 是把含氮量乘上一般係數 6.25 才得到 24.47%。換回 6.38 後蛋白質是多少？用同樣的指定值與 σ_pt，G4 的 z 與分級變成什麼？「用錯換算係數」能完全解釋 G4 偏低嗎？
... B28: 提示：「5_z分數」C4 改成 fat；再看「9_資料庫比對」9-1 脂肪列與 9-2。看完把 C4 改回 protein。
