Workbook

Sheet 0_說明
B1: 學習成效評量工具包（教師用）
B2: 食品分析實驗｜配合 assessment.html 使用。所有示範數據都是模擬的，正式使用前請清空黃色的學生資料區。
B4: 工作表 | C4: 用途
B5: 1_目標與證據 | C5: 先確認每個學習目標由哪些評量提供證據。
B6: 2_前後測題庫 | C6: 15 題概念題，W1 前測、W18 後測用同一份。可直接貼到 Google 表單（測驗模式）。
B7: 3_前測作答／4_後測作答 | C7: 貼上學生的 A/B/C/D 答案，自動改分。
B8: 5_學習成效 | C8: 個人與全班的標準化增益 g、配對 t 檢定、效果量。
B9: 6_試題分析 | C9: 每題的答對率與鑑別度，找出全班仍沒學會的觀念，依學習目標彙整。
B10: 7_自我效能問卷 | C10: W1、W9、W18 各填一次；看信心的變化，和前後測對照找迷思。
B11: 8_評分規準 | C11: 每週作業與實作考的四級規準，工具中立；附評分試算。
B12: 9_成績總表 | C12: 依權重算學期成績，含進階加分（Colab/Jupyter）。
B15: 建議時程
B16: W1 | C16: 前測（15 分鐘）＋自我效能問卷；說明評分規準
B17: 每週 | C17: 課後 3 分鐘出場券（1 題觀念題＋「今天最不懂的一點」）
B18: W4、W8 | C18: 數據作業回饋：依規準給分並附一句具體建議
B19: W9 | C19: 期中實作考（Excel 或 Colab 任選）＋自我效能問卷
B20: W17 | C20: 專題發表與同儕審查
B21: W18 | C21: 後測＋自我效能問卷；期末實作考（Orange 或 Colab 任選）
B22: 期末後 | C22: 看 5_學習成效 與 6_試題分析，寫下學期要調整的 3 件事
B25: 評量設計說明（網頁） | C25: https://tai-shengyeh.github.io/food-analysis-lab/assessment.html

Sheet 1_目標與證據
A1: 課程學習目標 × 評量證據對應表
A2: 每一個目標至少要有兩種不同的證據。✔＝這項評量主要用來看這個目標；○＝次要。黃色格子可以依你的課程修改。
A4: 代號 | B4: 學習目標 | C4: 具體表現 | D4: 前後測 | E4: 每週數據作業 | F4: 實驗報告 | G4: 期中實作 | H4: 期末實作 | I4: 專題成績單 | J4: 自我效能問卷
A5: CLO1 | B5: 正確操作一般成分分析並完成計算 | C5: 濕基/乾基、%N×係數、回收率、稀釋倍數 | D5: ✔ | E5: ✔ | F5: ✔ | G5: ✔ | J5: ○
A6: CLO2 | B6: 用統計判斷數據品質並下結論 | C6: SD/RSD/CI、檢定、檢量線、z-score、管制圖、不確定度 | D6: ✔ | E6: ✔ | F6: ✔ | G6: ✔ | I6: ○ | J6: ○
A7: CLO3 | B7: 建立與評估光譜化學計量模型 | C7: 前處理、PCA、PLS、RMSECV/RMSEP、適用範圍 | D7: ✔ | E7: ○ | H7: ✔ | I7: ✔ | J7: ○
A8: CLO4 | B8: 依問題選擇合適的分析工具 | C8: Excel / Orange / Colab，結果能互相核對 | E8: ✔ | G8: ✔ | H8: ✔ | I8: ○ | J8: ✔
A9: CLO5 | B9: 以書面與口頭清楚溝通數據 | C9: 報告、模型成績單、同儕審查 | F9: ✔ | I9: ✔
A11: CLO4 是本課程特別加的目標：學生不必每個工具都精通，但要知道什麼問題用什麼工具，並能用第二個工具核對答案（例如 Excel 算出的 RMSEP 與 Orange 一致）。

Sheet 2_前後測題庫
A1: 概念前後測題庫（15 題，同一份卷 W1 前測、W18 後測）
A2: 題目只考觀念，不考軟體操作，用 Excel、Orange 或 Colab 的學生都能作答。可以直接貼到 Google 表單（測驗模式）。正確答案在 I 欄，印給學生前請隱藏。
A4: 題號 | B4: 週次 | C4: 目標 | D4: 題目 | E4: A | F4: B | G4: C | H4: D | I4: 答案
A5: 1 | B5: W1 | C5: CLO2 | D5: 同一支吸管重複 10 次：SD 很小，但平均比標稱值低 0.03 mL（Class A 公差 ±0.02 mL）。這代表？ | E5: 精密但不準確 | F5: 準確且精密 | G5: 準確但不精密 | H5: 既不準確也不精密 | I5: A
A6: 2 | B6: W1 | C6: CLO2 | D6: 想讓平均值的 95% 信賴區間變窄，最直接的做法是？ | E6: 改用 STDEV.P 計算 | F6: 增加重複次數 | G6: 平均值多報幾位小數 | H6: 刪掉最大的那個值 | I6: B
A7: 3 | B7: W2 | C7: CLO1 | D7: 濕基水分 20%，換算成乾基水分是多少？ | E7: 25% | F7: 80% | G7: 20% | H7: 16.7% | I7: A
A8: 4 | B8: W2/W4 | C8: CLO2 | D8: 兩種方法測同一批樣品，要比較兩種方法時應該用？ | E8: 只看相關係數 r 是否接近 1 | F8: 只比較兩種方法的 SD | G8: 配對 t 檢定或 Bland–Altman 圖 | H8: 兩個獨立樣本的 t 檢定 | I8: C
A9: 5 | B9: W3 | C9: CLO2 | D9: 鈉的標準添加回收率只有 76%，最可能表示？ | E9: 儀器的精密度很好 | F9: 樣品本身含鈉很高 | G9: 有基質干擾或損失，結果可能偏低 | H9: 稀釋倍數被算成兩倍 | I9: C
A10: 6 | B10: W5 | C10: CLO1 | D10: 全脂奶粉若用 6.25（而非 6.38）把 %N 換算成蛋白質，結果會？ | E10: 無法判斷 | F10: 偏高 | G10: 不變 | H10: 偏低 | I10: D
A11: 7 | B11: W7 | C11: CLO2 | D11: 檢量線 R² = 0.999，代表什麼？ | E11: 一定是完美的直線關係 | F11: 殘差圖仍可能有彎曲，還要檢查殘差 | G11: LOD 一定很低 | H11: 樣品濃度一定準確 | I11: B
A12: 8 | B12: W7 | C12: CLO2 | D12: 樣品的吸光值高於最高濃度的標準品，正確做法是？ | E12: 延長檢量線外插計算 | F12: 直接報告為最高標準品的濃度 | G12: 用 R² 修正結果 | H12: 稀釋後重測，讓它落在檢量線範圍內 | I12: D
A13: 9 | B13: W8 | C13: CLO2 | D13: 能力試驗中，某組的 z-score = −3.8，應判定為？ | E13: 滿意 | F13: 可疑 | G13: 無法判定 | H13: 不滿意 | I13: D
A14: 10 | B14: W8 | C14: CLO2 | D14: 五組灰分結果的單因子 ANOVA 得 p = 0.0004，代表？ | E14: 組內重複性很差 | F14: 至少有一組的平均和其他組不同 | G14: 數據裡一定有離群值 | H14: 每一組都彼此不同 | I14: B
A15: 11 | B15: W8 | C15: CLO2 | D15: 規格為蛋白質 ≥ 25.0%，測得 25.2 ± 0.4%（擴充不確定度 U，k = 2），應判定？ | E15: 無法判斷：區間跨過規格限 | F15: 不放行 | G15: 放行 | H15: 再測一次取平均就可以放行 | I15: A
A16: 12 | B16: W11 | C16: CLO3 | D16: 光譜比對前先做正規化（例如向量正規化、SNV），主要目的是？ | E16: 把雜訊峰去掉 | F16: 消除強度差異（濃度、光程、散射），只比較形狀 | G16: 增加波數的資料點 | H16: 讓光譜變得更平滑 | I16: B
... A19: 15 | B19: W13/W16 | C19: CLO3 | D19: 報告模型表現時，最能代表「未來預測新樣品能力」的指標是？ | E19: 校正集的 RMSEC | F19: 獨立測試集的 RMSEP | G19: 校正集的 R² | H19: PLS 的 LV 數 | I19: B

Sheet 3_前測作答
A1: 前測作答（W1 第一堂課，不計分）
A2: 每位學生一列，填 A/B/C/D（大小寫皆可）。Google 表單可匯出成試算表，把答案欄貼到 C5 起。右邊綠色是對錯（1/0）與總分。示範資料是模擬的，正式使用前請整塊刪除 A5:Q64。
A4: 學號 | B4: 姓名 | C4: Q1 | D4: Q2 | E4: Q3 | F4: Q4 | G4: Q5 | H4: Q6 | I4: Q7 | J4: Q8 | K4: Q9 | L4: Q10 | M4: Q11 | N4: Q12 | O4: Q13 | P4: Q14 | Q4: Q15 | S4: 對1 | T4: 對2 | U4: 對3 | V4: 對4 | W4: 對5 | X4: 對6 | Y4: 對7 | Z4: 對8 | AA4: 對9 | AB4: 對10 | AC4: 對11 | AD4: 對12 | AE4: 對13 | AF4: 對14 | AG4: 對15 | AH4: 總分
A5: S01 | B5: 學生1 | C5: C | D5: B | E5: A | F5: D | G5: C | H5: A | I5: D | J5: D | K5: D | L5: B | M5: C | N5: C | O5: D | P5: C | Q5: C | S5: =IF($C5="","",IF(UPPER(TRIM(C5))=INDEX('2_前後測題庫'!$I$5:$I$19,1),1,0)) | T5: =IF($D5="","",IF(UPPER(TRIM(D5))=INDEX('2_前後測題庫'!$I$5:$I$19,2),1,0)) | U5: =IF($E5="","",IF(UPPER(TRIM(E5))=INDEX('2_前後測題庫'!$I$5:$I$19,3),1,0)) | V5: =IF($F5="","",IF(UPPER(TRIM(F5))=INDEX('2_前後測題庫'!$I$5:$I$19,4),1,0)) | W5: =IF($G5="","",IF(UPPER(TRIM(G5))=INDEX('2_前後測題庫'!$I$5:$I$19,5),1,0)) | X5: =IF($H5="","",IF(UPPER(TRIM(H5))=INDEX('2_前後測題庫'!$I$5:$I$19,6),1,0)) | Y5: =IF($I5="","",IF(UPPER(TRIM(I5))=INDEX('2_前後測題庫'!$I$5:$I$19,7),1,0)) | Z5: =IF($J5="","",IF(UPPER(TRIM(J5))=INDEX('2_前後測題庫'!$I$5:$I$19,8),1,0)) | AA5: =IF($K5="","",IF(UPPER(TRIM(K5))=INDEX('2_前後測題庫'!$I$5:$I$19,9),1,0)) | AB5: =IF($L5="","",IF(UPPER(TRIM(L5))=INDEX('2_前後測題庫'!$I$5:$I$19,10),1,0)) | AC5: =IF($M5="","",IF(UPPER(TRIM(M5))=INDEX('2_前後測題庫'!$I$5:$I$19,11),1,0)) | AD5: =IF($N5="","",IF(UPPER(TRIM(N5))=INDEX('2_前後測題庫'!$I$5:$I$19,12),1,0)) | AE5: =IF($O5="","",IF(UPPER(TRIM(O5))=INDEX('2_前後測題庫'!$I$5:$I$19,13),1,0)) | AF5: =IF($P5="","",IF(UPPER(TRIM(P5))=INDEX('2_前後測題庫'!$I$5:$I$19,14),1,0)) | AG5: =IF($Q5="","",IF(UPPER(TRIM(Q5))=INDEX('2_前後測題庫'!$I$5:$I$19,15),1,0)) | AH5: =IF($A5="","",SUM(S5:AG5))
A6: S02 | B6: 學生2 | C6: B | D6: B | E6: A | F6: D | G6: B | H6: B | I6: C | J6: D | K6: D | L6: B | M6: D | N6: A | O6: B | P6: B | Q6: A | S6: =IF($C6="","",IF(UPPER(TRIM(C6))=INDEX('2_前後測題庫'!$I$5:$I$19,1),1,0)) | T6: =IF($D6="","",IF(UPPER(TRIM(D6))=INDEX('2_前後測題庫'!$I$5:$I$19,2),1,0)) | U6: =IF($E6="","",IF(UPPER(TRIM(E6))=INDEX('2_前後測題庫'!$I$5:$I$19,3),1,0)) | V6: =IF($F6="","",IF(UPPER(TRIM(F6))=INDEX('2_前後測題庫'!$I$5:$I$19,4),1,0)) | W6: =IF($G6="","",IF(UPPER(TRIM(G6))=INDEX('2_前後測題庫'!$I$5:$I$19,5),1,0)) | X6: =IF($H6="","",IF(UPPER(TRIM(H6))=INDEX('2_前後測題庫'!$I$5:$I$19,6),1,0)) | Y6: =IF($I6="","",IF(UPPER(TRIM(I6))=INDEX('2_前後測題庫'!$I$5:$I$19,7),1,0)) | Z6: =IF($J6="","",IF(UPPER(TRIM(J6))=INDEX('2_前後測題庫'!$I$5:$I$19,8),1,0)) | AA6: =IF($K6="","",IF(UPPER(TRIM(K6))=INDEX('2_前後測題庫'!$I$5:$I$19,9),1,0)) | AB6: =IF($L6="","",IF(UPPER(TRIM(L6))=INDEX('2_前後測題庫'!$I$5:$I$19,10),1,0)) | AC6: =IF($M6="","",IF(UPPER(TRIM(M6))=INDEX('2_前後測題庫'!$I$5:$I$19,11),1,0)) | AD6: =IF($N6="","",IF(UPPER(TRIM(N6))=INDEX('2_前後測題庫'!$I$5:$I$19,12),1,0)) | AE6: =IF($O6="","",IF(UPPER(TRIM(O6))=INDEX('2_前後測題庫'!$I$5:$I$19,13),1,0)) | AF6: =IF($P6="","",IF(UPPER(TRIM(P6))=INDEX('2_前後測題庫'!$I$5:$I$19,14),1,0)) | AG6: =IF($Q6="","",IF(UPPER(TRIM(Q6))=INDEX('2_前後測題庫'!$I$5:$I$19,15),1,0)) | AH6: =IF($A6="","",SUM(S6:AG6))
A7: S03 | B7: 學生3 | C7: D | D7: D | E7: C | F7: A | G7: B | H7: D | I7: D | J7: D | K7: D | L7: B | M7: A | N7: C | O7: C | P7: B | Q7: C | S7: =IF($C7="","",IF(UPPER(TRIM(C7))=INDEX('2_前後測題庫'!$I$5:$I$19,1),1,0)) | T7: =IF($D7="","",IF(UPPER(TRIM(D7))=INDEX('2_前後測題庫'!$I$5:$I$19,2),1,0)) | U7: =IF($E7="","",IF(UPPER(TRIM(E7))=INDEX('2_前後測題庫'!$I$5:$I$19,3),1,0)) | V7: =IF($F7="","",IF(UPPER(TRIM(F7))=INDEX('2_前後測題庫'!$I$5:$I$19,4),1,0)) | W7: =IF($G7="","",IF(UPPER(TRIM(G7))=INDEX('2_前後測題庫'!$I$5:$I$19,5),1,0)) | X7: =IF($H7="","",IF(UPPER(TRIM(H7))=INDEX('2_前後測題庫'!$I$5:$I$19,6),1,0)) | Y7: =IF($I7="","",IF(UPPER(TRIM(I7))=INDEX('2_前後測題庫'!$I$5:$I$19,7),1,0)) | Z7: =IF($J7="","",IF(UPPER(TRIM(J7))=INDEX('2_前後測題庫'!$I$5:$I$19,8),1,0)) | AA7: =IF($K7="","",IF(UPPER(TRIM(K7))=INDEX('2_前後測題庫'!$I$5:$I$19,9),1,0)) | AB7: =IF($L7="","",IF(UPPER(TRIM(L7))=INDEX('2_前後測題庫'!$I$5:$I$19,10),1,0)) | AC7: =IF($M7="","",IF(UPPER(TRIM(M7))=INDEX('2_前後測題庫'!$I$5:$I$19,11),1,0)) | AD7: =IF($N7="","",IF(UPPER(TRIM(N7))=INDEX('2_前後測題庫'!$I$5:$I$19,12),1,0)) | AE7: =IF($O7="","",IF(UPPER(TRIM(O7))=INDEX('2_前後測題庫'!$I$5:$I$19,13),1,0)) | AF7: =IF($P7="","",IF(UPPER(TRIM(P7))=INDEX('2_前後測題庫'!$I$5:$I$19,14),1,0)) | AG7: =IF($Q7="","",IF(UPPER(TRIM(Q7))=INDEX('2_前後測題庫'!$I$5:$I$19,15),1,0)) | AH7: =IF($A7="","",SUM(S7:AG7))
A8: S04 | B8: 學生4 | C8: A | D8: C | E8: B | F8: C | G8: D | H8: A | I8: B | J8: A | K8: D | L8: C | M8: C | N8: D | O8: B | P8: D | Q8: A | S8: =IF($C8="","",IF(UPPER(TRIM(C8))=INDEX('2_前後測題庫'!$I$5:$I$19,1),1,0)) | T8: =IF($D8="","",IF(UPPER(TRIM(D8))=INDEX('2_前後測題庫'!$I$5:$I$19,2),1,0)) | U8: =IF($E8="","",IF(UPPER(TRIM(E8))=INDEX('2_前後測題庫'!$I$5:$I$19,3),1,0)) | V8: =IF($F8="","",IF(UPPER(TRIM(F8))=INDEX('2_前後測題庫'!$I$5:$I$19,4),1,0)) | W8: =IF($G8="","",IF(UPPER(TRIM(G8))=INDEX('2_前後測題庫'!$I$5:$I$19,5),1,0)) | X8: =IF($H8="","",IF(UPPER(TRIM(H8))=INDEX('2_前後測題庫'!$I$5:$I$19,6),1,0)) | Y8: =IF($I8="","",IF(UPPER(TRIM(I8))=INDEX('2_前後測題庫'!$I$5:$I$19,7),1,0)) | Z8: =IF($J8="","",IF(UPPER(TRIM(J8))=INDEX('2_前後測題庫'!$I$5:$I$19,8),1,0)) | AA8: =IF($K8="","",IF(UPPER(TRIM(K8))=INDEX('2_前後測題庫'!$I$5:$I$19,9),1,0)) | AB8: =IF($L8="","",IF(UPPER(TRIM(L8))=INDEX('2_前後測題庫'!$I$5:$I$19,10),1,0)) | AC8: =IF($M8="","",IF(UPPER(TRIM(M8))=INDEX('2_前後測題庫'!$I$5:$I$19,11),1,0)) | AD8: =IF($N8="","",IF(UPPER(TRIM(N8))=INDEX('2_前後測題庫'!$I$5:$I$19,12),1,0)) | AE8: =IF($O8="","",IF(UPPER(TRIM(O8))=INDEX('2_前後測題庫'!$I$5:$I$19,13),1,0)) | AF8: =IF($P8="","",IF(UPPER(TRIM(P8))=INDEX('2_前後測題庫'!$I$5:$I$19,14),1,0)) | AG8: =IF($Q8="","",IF(UPPER(TRIM(Q8))=INDEX('2_前後測題庫'!$I$5:$I$19,15),1,0)) | AH8: =IF($A8="","",SUM(S8:AG8))
A9: S05 | B9: 學生5 | C9: C | D9: C | E9: A | F9: C | G9: C | H9: D | I9: C | J9: D | K9: B | L9: A | M9: A | N9: B | O9: B | P9: D | Q9: A | S9: =IF($C9="","",IF(UPPER(TRIM(C9))=INDEX('2_前後測題庫'!$I$5:$I$19,1),1,0)) | T9: =IF($D9="","",IF(UPPER(TRIM(D9))=INDEX('2_前後測題庫'!$I$5:$I$19,2),1,0)) | U9: =IF($E9="","",IF(UPPER(TRIM(E9))=INDEX('2_前後測題庫'!$I$5:$I$19,3),1,0)) | V9: =IF($F9="","",IF(UPPER(TRIM(F9))=INDEX('2_前後測題庫'!$I$5:$I$19,4),1,0)) | W9: =IF($G9="","",IF(UPPER(TRIM(G9))=INDEX('2_前後測題庫'!$I$5:$I$19,5),1,0)) | X9: =IF($H9="","",IF(UPPER(TRIM(H9))=INDEX('2_前後測題庫'!$I$5:$I$19,6),1,0)) | Y9: =IF($I9="","",IF(UPPER(TRIM(I9))=INDEX('2_前後測題庫'!$I$5:$I$19,7),1,0)) | Z9: =IF($J9="","",IF(UPPER(TRIM(J9))=INDEX('2_前後測題庫'!$I$5:$I$19,8),1,0)) | AA9: =IF($K9="","",IF(UPPER(TRIM(K9))=INDEX('2_前後測題庫'!$I$5:$I$19,9),1,0)) | AB9: =IF($L9="","",IF(UPPER(TRIM(L9))=INDEX('2_前後測題庫'!$I$5:$I$19,10),1,0)) | AC9: =IF($M9="","",IF(UPPER(TRIM(M9))=INDEX('2_前後測題庫'!$I$5:$I$19,11),1,0)) | AD9: =IF($N9="","",IF(UPPER(TRIM(N9))=INDEX('2_前後測題庫'!$I$5:$I$19,12),1,0)) | AE9: =IF($O9="","",IF(UPPER(TRIM(O9))=INDEX('2_前後測題庫'!$I$5:$I$19,13),1,0)) | AF9: =IF($P9="","",IF(UPPER(TRIM(P9))=INDEX('2_前後測題庫'!$I$5:$I$19,14),1,0)) | AG9: =IF($Q9="","",IF(UPPER(TRIM(Q9))=INDEX('2_前後測題庫'!$I$5:$I$19,15),1,0)) | AH9: =IF($A9="","",SUM(S9:AG9))
A10: S06 | B10: 學生6 | C10: C | D10: D | E10: C | F10: D | G10: B | H10: C | I10: B | J10: C | K10: D | L10: D | M10: A | N10: D | O10: D | P10: A | Q10: D | S10: =IF($C10="","",IF(UPPER(TRIM(C10))=INDEX('2_前後測題庫'!$I$5:$I$19,1),1,0)) | T10: =IF($D10="","",IF(UPPER(TRIM(D10))=INDEX('2_前後測題庫'!$I$5:$I$19,2),1,0)) | U10: =IF($E10="","",IF(UPPER(TRIM(E10))=INDEX('2_前後測題庫'!$I$5:$I$19,3),1,0)) | V10: =IF($F10="","",IF(UPPER(TRIM(F10))=INDEX('2_前後測題庫'!$I$5:$I$19,4),1,0)) | W10: =IF($G10="","",IF(UPPER(TRIM(G10))=INDEX('2_前後測題庫'!$I$5:$I$19,5),1,0)) | X10: =IF($H10="","",IF(UPPER(TRIM(H10))=INDEX('2_前後測題庫'!$I$5:$I$19,6),1,0)) | Y10: =IF($I10="","",IF(UPPER(TRIM(I10))=INDEX('2_前後測題庫'!$I$5:$I$19,7),1,0)) | Z10: =IF($J10="","",IF(UPPER(TRIM(J10))=INDEX('2_前後測題庫'!$I$5:$I$19,8),1,0)) | AA10: =IF($K10="","",IF(UPPER(TRIM(K10))=INDEX('2_前後測題庫'!$I$5:$I$19,9),1,0)) | AB10: =IF($L10="","",IF(UPPER(TRIM(L10))=INDEX('2_前後測題庫'!$I$5:$I$19,10),1,0)) | AC10: =IF($M10="","",IF(UPPER(TRIM(M10))=INDEX('2_前後測題庫'!$I$5:$I$19,11),1,0)) | AD10: =IF($N10="","",IF(UPPER(TRIM(N10))=INDEX('2_前後測題庫'!$I$5:$I$19,12),1,0)) | AE10: =IF($O10="","",IF(UPPER(TRIM(O10))=INDEX('2_前後測題庫'!$I$5:$I$19,13),1,0)) | AF10: =IF($P10="","",IF(UPPER(TRIM(P10))=INDEX('2_前後測題庫'!$I$5:$I$19,14),1,0)) | AG10: =IF($Q10="","",IF(UPPER(TRIM(Q10))=INDEX('2_前後測題庫'!$I$5:$I$19,15),1,0)) | AH10: =IF($A10="","",SUM(S10:AG10))
A11: S07 | B11: 學生7 | C11: C | D11: D | E11: C | F11: A | G11: D | H11: A | I11: A | J11: A | K11: C | L11: D | M11: D | N11: D | O11: C | P11: C | Q11: B | S11: =IF($C11="","",IF(UPPER(TRIM(C11))=INDEX('2_前後測題庫'!$I$5:$I$19,1),1,0)) | T11: =IF($D11="","",IF(UPPER(TRIM(D11))=INDEX('2_前後測題庫'!$I$5:$I$19,2),1,0)) | U11: =IF($E11="","",IF(UPPER(TRIM(E11))=INDEX('2_前後測題庫'!$I$5:$I$19,3),1,0)) | V11: =IF($F11="","",IF(UPPER(TRIM(F11))=INDEX('2_前後測題庫'!$I$5:$I$19,4),1,0)) | W11: =IF($G11="","",IF(UPPER(TRIM(G11))=INDEX('2_前後測題庫'!$I$5:$I$19,5),1,0)) | X11: =IF($H11="","",IF(UPPER(TRIM(H11))=INDEX('2_前後測題庫'!$I$5:$I$19,6),1,0)) | Y11: =IF($I11="","",IF(UPPER(TRIM(I11))=INDEX('2_前後測題庫'!$I$5:$I$19,7),1,0)) | Z11: =IF($J11="","",IF(UPPER(TRIM(J11))=INDEX('2_前後測題庫'!$I$5:$I$19,8),1,0)) | AA11: =IF($K11="","",IF(UPPER(TRIM(K11))=INDEX('2_前後測題庫'!$I$5:$I$19,9),1,0)) | AB11: =IF($L11="","",IF(UPPER(TRIM(L11))=INDEX('2_前後測題庫'!$I$5:$I$19,10),1,0)) | AC11: =IF($M11="","",IF(UPPER(TRIM(M11))=INDEX('2_前後測題庫'!$I$5:$I$19,11),1,0)) | AD11: =IF($N11="","",IF(UPPER(TRIM(N11))=INDEX('2_前後測題庫'!$I$5:$I$19,12),1,0)) | AE11: =IF($O11="","",IF(UPPER(TRIM(O11))=INDEX('2_前後測題庫'!$I$5:$I$19,13),1,0)) | AF11: =IF($P11="","",IF(UPPER(TRIM(P11))=INDEX('2_前後測題庫'!$I$5:$I$19,14),1,0)) | AG11: =IF($Q11="","",IF(UPPER(TRIM(Q11))=INDEX('2_前後測題庫'!$I$5:$I$19,15),1,0)) | AH11: =IF($A11="","",SUM(S11:AG11))
A12: S08 | B12: 學生8 | C12: A | D12: D | E12: A | F12: D | G12: D | H12: D | I12: A | J12: D | K12: D | L12: B | M12: A | N12: A | O12: C | P12: A | Q12: B | S12: =IF($C12="","",IF(UPPER(TRIM(C12))=INDEX('2_前後測題庫'!$I$5:$I$19,1),1,0)) | T12: =IF($D12="","",IF(UPPER(TRIM(D12))=INDEX('2_前後測題庫'!$I$5:$I$19,2),1,0)) | U12: =IF($E12="","",IF(UPPER(TRIM(E12))=INDEX('2_前後測題庫'!$I$5:$I$19,3),1,0)) | V12: =IF($F12="","",IF(UPPER(TRIM(F12))=INDEX('2_前後測題庫'!$I$5:$I$19,4),1,0)) | W12: =IF($G12="","",IF(UPPER(TRIM(G12))=INDEX('2_前後測題庫'!$I$5:$I$19,5),1,0)) | X12: =IF($H12="","",IF(UPPER(TRIM(H12))=INDEX('2_前後測題庫'!$I$5:$I$19,6),1,0)) | Y12: =IF($I12="","",IF(UPPER(TRIM(I12))=INDEX('2_前後測題庫'!$I$5:$I$19,7),1,0)) | Z12: =IF($J12="","",IF(UPPER(TRIM(J12))=INDEX('2_前後測題庫'!$I$5:$I$19,8),1,0)) | AA12: =IF($K12="","",IF(UPPER(TRIM(K12))=INDEX('2_前後測題庫'!$I$5:$I$19,9),1,0)) | AB12: =IF($L12="","",IF(UPPER(TRIM(L12))=INDEX('2_前後測題庫'!$I$5:$I$19,10),1,0)) | AC12: =IF($M12="","",IF(UPPER(TRIM(M12))=INDEX('2_前後測題庫'!$I$5:$I$19,11),1,0)) | AD12: =IF($N12="","",IF(UPPER(TRIM(N12))=INDEX('2_前後測題庫'!$I$5:$I$19,12),1,0)) | AE12: =IF($O12="","",IF(UPPER(TRIM(O12))=INDEX('2_前後測題庫'!$I$5:$I$19,13),1,0)) | AF12: =IF($P12="","",IF(UPPER(TRIM(P12))=INDEX('2_前後測題庫'!$I$5:$I$19,14),1,0)) | AG12: =IF($Q12="","",IF(UPPER(TRIM(Q12))=INDEX('2_前後測題庫'!$I$5:$I$19,15),1,0)) | AH12: =IF($A12="","",SUM(S12:AG12))
A13: S09 | B13: 學生9 | C13: C | D13: A | E13: B | F13: B | G13: D | H13: A | I13: D | J13: C | K13: D | L13: D | M13: D | N13: D | O13: B | P13: D | Q13: B | S13: =IF($C13="","",IF(UPPER(TRIM(C13))=INDEX('2_前後測題庫'!$I$5:$I$19,1),1,0)) | T13: =IF($D13="","",IF(UPPER(TRIM(D13))=INDEX('2_前後測題庫'!$I$5:$I$19,2),1,0)) | U13: =IF($E13="","",IF(UPPER(TRIM(E13))=INDEX('2_前後測題庫'!$I$5:$I$19,3),1,0)) | V13: =IF($F13="","",IF(UPPER(TRIM(F13))=INDEX('2_前後測題庫'!$I$5:$I$19,4),1,0)) | W13: =IF($G13="","",IF(UPPER(TRIM(G13))=INDEX('2_前後測題庫'!$I$5:$I$19,5),1,0)) | X13: =IF($H13="","",IF(UPPER(TRIM(H13))=INDEX('2_前後測題庫'!$I$5:$I$19,6),1,0)) | Y13: =IF($I13="","",IF(UPPER(TRIM(I13))=INDEX('2_前後測題庫'!$I$5:$I$19,7),1,0)) | Z13: =IF($J13="","",IF(UPPER(TRIM(J13))=INDEX('2_前後測題庫'!$I$5:$I$19,8),1,0)) | AA13: =IF($K13="","",IF(UPPER(TRIM(K13))=INDEX('2_前後測題庫'!$I$5:$I$19,9),1,0)) | AB13: =IF($L13="","",IF(UPPER(TRIM(L13))=INDEX('2_前後測題庫'!$I$5:$I$19,10),1,0)) | AC13: =IF($M13="","",IF(UPPER(TRIM(M13))=INDEX('2_前後測題庫'!$I$5:$I$19,11),1,0)) | AD13: =IF($N13="","",IF(UPPER(TRIM(N13))=INDEX('2_前後測題庫'!$I$5:$I$19,12),1,0)) | AE13: =IF($O13="","",IF(UPPER(TRIM(O13))=INDEX('2_前後測題庫'!$I$5:$I$19,13),1,0)) | AF13: =IF($P13="","",IF(UPPER(TRIM(P13))=INDEX('2_前後測題庫'!$I$5:$I$19,14),1,0)) | AG13: =IF($Q13="","",IF(UPPER(TRIM(Q13))=INDEX('2_前後測題庫'!$I$5:$I$19,15),1,0)) | AH13: =IF($A13="","",SUM(S13:AG13))
A14: S10 | B14: 學生10 | C14: A | D14: B | E14: D | F14: C | G14: A | H14: A | I14: B | J14: D | K14: C | L14: C | M14: B | N14: B | O14: C | P14: D | Q14: C | S14: =IF($C14="","",IF(UPPER(TRIM(C14))=INDEX('2_前後測題庫'!$I$5:$I$19,1),1,0)) | T14: =IF($D14="","",IF(UPPER(TRIM(D14))=INDEX('2_前後測題庫'!$I$5:$I$19,2),1,0)) | U14: =IF($E14="","",IF(UPPER(TRIM(E14))=INDEX('2_前後測題庫'!$I$5:$I$19,3),1,0)) | V14: =IF($F14="","",IF(UPPER(TRIM(F14))=INDEX('2_前後測題庫'!$I$5:$I$19,4),1,0)) | W14: =IF($G14="","",IF(UPPER(TRIM(G14))=INDEX('2_前後測題庫'!$I$5:$I$19,5),1,0)) | X14: =IF($H14="","",IF(UPPER(TRIM(H14))=INDEX('2_前後測題庫'!$I$5:$I$19,6),1,0)) | Y14: =IF($I14="","",IF(UPPER(TRIM(I14))=INDEX('2_前後測題庫'!$I$5:$I$19,7),1,0)) | Z14: =IF($J14="","",IF(UPPER(TRIM(J14))=INDEX('2_前後測題庫'!$I$5:$I$19,8),1,0)) | AA14: =IF($K14="","",IF(UPPER(TRIM(K14))=INDEX('2_前後測題庫'!$I$5:$I$19,9),1,0)) | AB14: =IF($L14="","",IF(UPPER(TRIM(L14))=INDEX('2_前後測題庫'!$I$5:$I$19,10),1,0)) | AC14: =IF($M14="","",IF(UPPER(TRIM(M14))=INDEX('2_前後測題庫'!$I$5:$I$19,11),1,0)) | AD14: =IF($N14="","",IF(UPPER(TRIM(N14))=INDEX('2_前後測題庫'!$I$5:$I$19,12),1,0)) | AE14: =IF($O14="","",IF(UPPER(TRIM(O14))=INDEX('2_前後測題庫'!$I$5:$I$19,13),1,0)) | AF14: =IF($P14="","",IF(UPPER(TRIM(P14))=INDEX('2_前後測題庫'!$I$5:$I$19,14),1,0)) | AG14: =IF($Q14="","",IF(UPPER(TRIM(Q14))=INDEX('2_前後測題庫'!$I$5:$I$19,15),1,0)) | AH14: =IF($A14="","",SUM(S14:AG14))
A15: S11 | B15: 學生11 | C15: A | D15: B | E15: A | F15: C | G15: C | H15: C | I15: B | J15: B | K15: D | L15: D | M15: C | N15: B | O15: A | P15: C | Q15: A | S15: =IF($C15="","",IF(UPPER(TRIM(C15))=INDEX('2_前後測題庫'!$I$5:$I$19,1),1,0)) | T15: =IF($D15="","",IF(UPPER(TRIM(D15))=INDEX('2_前後測題庫'!$I$5:$I$19,2),1,0)) | U15: =IF($E15="","",IF(UPPER(TRIM(E15))=INDEX('2_前後測題庫'!$I$5:$I$19,3),1,0)) | V15: =IF($F15="","",IF(UPPER(TRIM(F15))=INDEX('2_前後測題庫'!$I$5:$I$19,4),1,0)) | W15: =IF($G15="","",IF(UPPER(TRIM(G15))=INDEX('2_前後測題庫'!$I$5:$I$19,5),1,0)) | X15: =IF($H15="","",IF(UPPER(TRIM(H15))=INDEX('2_前後測題庫'!$I$5:$I$19,6),1,0)) | Y15: =IF($I15="","",IF(UPPER(TRIM(I15))=INDEX('2_前後測題庫'!$I$5:$I$19,7),1,0)) | Z15: =IF($J15="","",IF(UPPER(TRIM(J15))=INDEX('2_前後測題庫'!$I$5:$I$19,8),1,0)) | AA15: =IF($K15="","",IF(UPPER(TRIM(K15))=INDEX('2_前後測題庫'!$I$5:$I$19,9),1,0)) | AB15: =IF($L15="","",IF(UPPER(TRIM(L15))=INDEX('2_前後測題庫'!$I$5:$I$19,10),1,0)) | AC15: =IF($M15="","",IF(UPPER(TRIM(M15))=INDEX('2_前後測題庫'!$I$5:$I$19,11),1,0)) | AD15: =IF($N15="","",IF(UPPER(TRIM(N15))=INDEX('2_前後測題庫'!$I$5:$I$19,12),1,0)) | AE15: =IF($O15="","",IF(UPPER(TRIM(O15))=INDEX('2_前後測題庫'!$I$5:$I$19,13),1,0)) | AF15: =IF($P15="","",IF(UPPER(TRIM(P15))=INDEX('2_前後測題庫'!$I$5:$I$19,14),1,0)) | AG15: =IF($Q15="","",IF(UPPER(TRIM(Q15))=INDEX('2_前後測題庫'!$I$5:$I$19,15),1,0)) | AH15: =IF($A15="","",SUM(S15:AG15))
A16: S12 | B16: 學生12 | C16: D | D16: B | E16: D | F16: B | G16: C | H16: D | I16: D | J16: D | K16: B | L16: B | M16: A | N16: D | O16: C | P16: A | Q16: B | S16: =IF($C16="","",IF(UPPER(TRIM(C16))=INDEX('2_前後測題庫'!$I$5:$I$19,1),1,0)) | T16: =IF($D16="","",IF(UPPER(TRIM(D16))=INDEX('2_前後測題庫'!$I$5:$I$19,2),1,0)) | U16: =IF($E16="","",IF(UPPER(TRIM(E16))=INDEX('2_前後測題庫'!$I$5:$I$19,3),1,0)) | V16: =IF($F16="","",IF(UPPER(TRIM(F16))=INDEX('2_前後測題庫'!$I$5:$I$19,4),1,0)) | W16: =IF($G16="","",IF(UPPER(TRIM(G16))=INDEX('2_前後測題庫'!$I$5:$I$19,5),1,0)) | X16: =IF($H16="","",IF(UPPER(TRIM(H16))=INDEX('2_前後測題庫'!$I$5:$I$19,6),1,0)) | Y16: =IF($I16="","",IF(UPPER(TRIM(I16))=INDEX('2_前後測題庫'!$I$5:$I$19,7),1,0)) | Z16: =IF($J16="","",IF(UPPER(TRIM(J16))=INDEX('2_前後測題庫'!$I$5:$I$19,8),1,0)) | AA16: =IF($K16="","",IF(UPPER(TRIM(K16))=INDEX('2_前後測題庫'!$I$5:$I$19,9),1,0)) | AB16: =IF($L16="","",IF(UPPER(TRIM(L16))=INDEX('2_前後測題庫'!$I$5:$I$19,10),1,0)) | AC16: =IF($M16="","",IF(UPPER(TRIM(M16))=INDEX('2_前後測題庫'!$I$5:$I$19,11),1,0)) | AD16: =IF($N16="","",IF(UPPER(TRIM(N16))=INDEX('2_前後測題庫'!$I$5:$I$19,12),1,0)) | AE16: =IF($O16="","",IF(UPPER(TRIM(O16))=INDEX('2_前後測題庫'!$I$5:$I$19,13),1,0)) | AF16: =IF($P16="","",IF(UPPER(TRIM(P16))=INDEX('2_前後測題庫'!$I$5:$I$19,14),1,0)) | AG16: =IF($Q16="","",IF(UPPER(TRIM(Q16))=INDEX('2_前後測題庫'!$I$5:$I$19,15),1,0)) | AH16: =IF($A16="","",SUM(S16:AG16))
... A19: S15 | B19: 學生15 | C19: D | D19: C | E19: A | F19: C | G19: D | H19: A | I19: D | J19: C | K19: C | L19: A | M19: A | N19: C | O19: A | P19: C | Q19: C | S19: =IF($C19="","",IF(UPPER(TRIM(C19))=INDEX('2_前後測題庫'!$I$5:$I$19,1),1,0)) | T19: =IF($D19="","",IF(UPPER(TRIM(D19))=INDEX('2_前後測題庫'!$I$5:$I$19,2),1,0)) | U19: =IF($E19="","",IF(UPPER(TRIM(E19))=INDEX('2_前後測題庫'!$I$5:$I$19,3),1,0)) | V19: =IF($F19="","",IF(UPPER(TRIM(F19))=INDEX('2_前後測題庫'!$I$5:$I$19,4),1,0)) | W19: =IF($G19="","",IF(UPPER(TRIM(G19))=INDEX('2_前後測題庫'!$I$5:$I$19,5),1,0)) | X19: =IF($H19="","",IF(UPPER(TRIM(H19))=INDEX('2_前後測題庫'!$I$5:$I$19,6),1,0)) | Y19: =IF($I19="","",IF(UPPER(TRIM(I19))=INDEX('2_前後測題庫'!$I$5:$I$19,7),1,0)) | Z19: =IF($J19="","",IF(UPPER(TRIM(J19))=INDEX('2_前後測題庫'!$I$5:$I$19,8),1,0)) | AA19: =IF($K19="","",IF(UPPER(TRIM(K19))=INDEX('2_前後測題庫'!$I$5:$I$19,9),1,0)) | AB19: =IF($L19="","",IF(UPPER(TRIM(L19))=INDEX('2_前後測題庫'!$I$5:$I$19,10),1,0)) | AC19: =IF($M19="","",IF(UPPER(TRIM(M19))=INDEX('2_前後測題庫'!$I$5:$I$19,11),1,0)) | AD19: =IF($N19="","",IF(UPPER(TRIM(N19))=INDEX('2_前後測題庫'!$I$5:$I$19,12),1,0)) | AE19: =IF($O19="","",IF(UPPER(TRIM(O19))=INDEX('2_前後測題庫'!$I$5:$I$19,13),1,0)) | AF19: =IF($P19="","",IF(UPPER(TRIM(P19))=INDEX('2_前後測題庫'!$I$5:$I$19,14),1,0)) | AG19: =IF($Q19="","",IF(UPPER(TRIM(Q19))=INDEX('2_前後測題庫'!$I$5:$I$19,15),1,0)) | AH19: =IF($A19="","",SUM(S19:AG19))
S20: =IF($C20="","",IF(UPPER(TRIM(C20))=INDEX('2_前後測題庫'!$I$5:$I$19,1),1,0)) | T20: =IF($D20="","",IF(UPPER(TRIM(D20))=INDEX('2_前後測題庫'!$I$5:$I$19,2),1,0)) | U20: =IF($E20="","",IF(UPPER(TRIM(E20))=INDEX('2_前後測題庫'!$I$5:$I$19,3),1,0)) | V20: =IF($F20="","",IF(UPPER(TRIM(F20))=INDEX('2_前後測題庫'!$I$5:$I$19,4),1,0)) | W20: =IF($G20="","",IF(UPPER(TRIM(G20))=INDEX('2_前後測題庫'!$I$5:$I$19,5),1,0)) | X20: =IF($H20="","",IF(UPPER(TRIM(H20))=INDEX('2_前後測題庫'!$I$5:$I$19,6),1,0)) | Y20: =IF($I20="","",IF(UPPER(TRIM(I20))=INDEX('2_前後測題庫'!$I$5:$I$19,7),1,0)) | Z20: =IF($J20="","",IF(UPPER(TRIM(J20))=INDEX('2_前後測題庫'!$I$5:$I$19,8),1,0)) | AA20: =IF($K20="","",IF(UPPER(TRIM(K20))=INDEX('2_前後測題庫'!$I$5:$I$19,9),1,0)) | AB20: =IF($L20="","",IF(UPPER(TRIM(L20))=INDEX('2_前後測題庫'!$I$5:$I$19,10),1,0)) | AC20: =IF($M20="","",IF(UPPER(TRIM(M20))=INDEX('2_前後測題庫'!$I$5:$I$19,11),1,0)) | AD20: =IF($N20="","",IF(UPPER(TRIM(N20))=INDEX('2_前後測題庫'!$I$5:$I$19,12),1,0)) | AE20: =IF($O20="","",IF(UPPER(TRIM(O20))=INDEX('2_前後測題庫'!$I$5:$I$19,13),1,0)) | AF20: =IF($P20="","",IF(UPPER(TRIM(P20))=INDEX('2_前後測題庫'!$I$5:$I$19,14),1,0)) | AG20: =IF($Q20="","",IF(UPPER(TRIM(Q20))=INDEX('2_前後測題庫'!$I$5:$I$19,15),1,0)) | AH20: =IF($A20="","",SUM(S20:AG20))
S21: =IF($C21="","",IF(UPPER(TRIM(C21))=INDEX('2_前後測題庫'!$I$5:$I$19,1),1,0)) | T21: =IF($D21="","",IF(UPPER(TRIM(D21))=INDEX('2_前後測題庫'!$I$5:$I$19,2),1,0)) | U21: =IF($E21="","",IF(UPPER(TRIM(E21))=INDEX('2_前後測題庫'!$I$5:$I$19,3),1,0)) | V21: =IF($F21="","",IF(UPPER(TRIM(F21))=INDEX('2_前後測題庫'!$I$5:$I$19,4),1,0)) | W21: =IF($G21="","",IF(UPPER(TRIM(G21))=INDEX('2_前後測題庫'!$I$5:$I$19,5),1,0)) | X21: =IF($H21="","",IF(UPPER(TRIM(H21))=INDEX('2_前後測題庫'!$I$5:$I$19,6),1,0)) | Y21: =IF($I21="","",IF(UPPER(TRIM(I21))=INDEX('2_前後測題庫'!$I$5:$I$19,7),1,0)) | Z21: =IF($J21="","",IF(UPPER(TRIM(J21))=INDEX('2_前後測題庫'!$I$5:$I$19,8),1,0)) | AA21: =IF($K21="","",IF(UPPER(TRIM(K21))=INDEX('2_前後測題庫'!$I$5:$I$19,9),1,0)) | AB21: =IF($L21="","",IF(UPPER(TRIM(L21))=INDEX('2_前後測題庫'!$I$5:$I$19,10),1,0)) | AC21: =IF($M21="","",IF(UPPER(TRIM(M21))=INDEX('2_前後測題庫'!$I$5:$I$19,11),1,0)) | AD21: =IF($N21="","",IF(UPPER(TRIM(N21))=INDEX('2_前後測題庫'!$I$5:$I$19,12),1,0)) | AE21: =IF($O21="","",IF(UPPER(TRIM(O21))=INDEX('2_前後測題庫'!$I$5:$I$19,13),1,0)) | AF21: =IF($P21="","",IF(UPPER(TRIM(P21))=INDEX('2_前後測題庫'!$I$5:$I$19,14),1,0)) | AG21: =IF($Q21="","",IF(UPPER(TRIM(Q21))=INDEX('2_前後測題庫'!$I$5:$I$19,15),1,0)) | AH21: =IF($A21="","",SUM(S21:AG21))
S22: =IF($C22="","",IF(UPPER(TRIM(C22))=INDEX('2_前後測題庫'!$I$5:$I$19,1),1,0)) | T22: =IF($D22="","",IF(UPPER(TRIM(D22))=INDEX('2_前後測題庫'!$I$5:$I$19,2),1,0)) | U22: =IF($E22="","",IF(UPPER(TRIM(E22))=INDEX('2_前後測題庫'!$I$5:$I$19,3),1,0)) | V22: =IF($F22="","",IF(UPPER(TRIM(F22))=INDEX('2_前後測題庫'!$I$5:$I$19,4),1,0)) | W22: =IF($G22="","",IF(UPPER(TRIM(G22))=INDEX('2_前後測題庫'!$I$5:$I$19,5),1,0)) | X22: =IF($H22="","",IF(UPPER(TRIM(H22))=INDEX('2_前後測題庫'!$I$5:$I$19,6),1,0)) | Y22: =IF($I22="","",IF(UPPER(TRIM(I22))=INDEX('2_前後測題庫'!$I$5:$I$19,7),1,0)) | Z22: =IF($J22="","",IF(UPPER(TRIM(J22))=INDEX('2_前後測題庫'!$I$5:$I$19,8),1,0)) | AA22: =IF($K22="","",IF(UPPER(TRIM(K22))=INDEX('2_前後測題庫'!$I$5:$I$19,9),1,0)) | AB22: =IF($L22="","",IF(UPPER(TRIM(L22))=INDEX('2_前後測題庫'!$I$5:$I$19,10),1,0)) | AC22: =IF($M22="","",IF(UPPER(TRIM(M22))=INDEX('2_前後測題庫'!$I$5:$I$19,11),1,0)) | AD22: =IF($N22="","",IF(UPPER(TRIM(N22))=INDEX('2_前後測題庫'!$I$5:$I$19,12),1,0)) | AE22: =IF($O22="","",IF(UPPER(TRIM(O22))=INDEX('2_前後測題庫'!$I$5:$I$19,13),1,0)) | AF22: =IF($P22="","",IF(UPPER(TRIM(P22))=INDEX('2_前後測題庫'!$I$5:$I$19,14),1,0)) | AG22: =IF($Q22="","",IF(UPPER(TRIM(Q22))=INDEX('2_前後測題庫'!$I$5:$I$19,15),1,0)) | AH22: =IF($A22="","",SUM(S22:AG22))
S23: =IF($C23="","",IF(UPPER(TRIM(C23))=INDEX('2_前後測題庫'!$I$5:$I$19,1),1,0)) | T23: =IF($D23="","",IF(UPPER(TRIM(D23))=INDEX('2_前後測題庫'!$I$5:$I$19,2),1,0)) | U23: =IF($E23="","",IF(UPPER(TRIM(E23))=INDEX('2_前後測題庫'!$I$5:$I$19,3),1,0)) | V23: =IF($F23="","",IF(UPPER(TRIM(F23))=INDEX('2_前後測題庫'!$I$5:$I$19,4),1,0)) | W23: =IF($G23="","",IF(UPPER(TRIM(G23))=INDEX('2_前後測題庫'!$I$5:$I$19,5),1,0)) | X23: =IF($H23="","",IF(UPPER(TRIM(H23))=INDEX('2_前後測題庫'!$I$5:$I$19,6),1,0)) | Y23: =IF($I23="","",IF(UPPER(TRIM(I23))=INDEX('2_前後測題庫'!$I$5:$I$19,7),1,0)) | Z23: =IF($J23="","",IF(UPPER(TRIM(J23))=INDEX('2_前後測題庫'!$I$5:$I$19,8),1,0)) | AA23: =IF($K23="","",IF(UPPER(TRIM(K23))=INDEX('2_前後測題庫'!$I$5:$I$19,9),1,0)) | AB23: =IF($L23="","",IF(UPPER(TRIM(L23))=INDEX('2_前後測題庫'!$I$5:$I$19,10),1,0)) | AC23: =IF($M23="","",IF(UPPER(TRIM(M23))=INDEX('2_前後測題庫'!$I$5:$I$19,11),1,0)) | AD23: =IF($N23="","",IF(UPPER(TRIM(N23))=INDEX('2_前後測題庫'!$I$5:$I$19,12),1,0)) | AE23: =IF($O23="","",IF(UPPER(TRIM(O23))=INDEX('2_前後測題庫'!$I$5:$I$19,13),1,0)) | AF23: =IF($P23="","",IF(UPPER(TRIM(P23))=INDEX('2_前後測題庫'!$I$5:$I$19,14),1,0)) | AG23: =IF($Q23="","",IF(UPPER(TRIM(Q23))=INDEX('2_前後測題庫'!$I$5:$I$19,15),1,0)) | AH23: =IF($A23="","",SUM(S23:AG23))
S24: =IF($C24="","",IF(UPPER(TRIM(C24))=INDEX('2_前後測題庫'!$I$5:$I$19,1),1,0)) | T24: =IF($D24="","",IF(UPPER(TRIM(D24))=INDEX('2_前後測題庫'!$I$5:$I$19,2),1,0)) | U24: =IF($E24="","",IF(UPPER(TRIM(E24))=INDEX('2_前後測題庫'!$I$5:$I$19,3),1,0)) | V24: =IF($F24="","",IF(UPPER(TRIM(F24))=INDEX('2_前後測題庫'!$I$5:$I$19,4),1,0)) | W24: =IF($G24="","",IF(UPPER(TRIM(G24))=INDEX('2_前後測題庫'!$I$5:$I$19,5),1,0)) | X24: =IF($H24="","",IF(UPPER(TRIM(H24))=INDEX('2_前後測題庫'!$I$5:$I$19,6),1,0)) | Y24: =IF($I24="","",IF(UPPER(TRIM(I24))=INDEX('2_前後測題庫'!$I$5:$I$19,7),1,0)) | Z24: =IF($J24="","",IF(UPPER(TRIM(J24))=INDEX('2_前後測題庫'!$I$5:$I$19,8),1,0)) | AA24: =IF($K24="","",IF(UPPER(TRIM(K24))=INDEX('2_前後測題庫'!$I$5:$I$19,9),1,0)) | AB24: =IF($L24="","",IF(UPPER(TRIM(L24))=INDEX('2_前後測題庫'!$I$5:$I$19,10),1,0)) | AC24: =IF($M24="","",IF(UPPER(TRIM(M24))=INDEX('2_前後測題庫'!$I$5:$I$19,11),1,0)) | AD24: =IF($N24="","",IF(UPPER(TRIM(N24))=INDEX('2_前後測題庫'!$I$5:$I$19,12),1,0)) | AE24: =IF($O24="","",IF(UPPER(TRIM(O24))=INDEX('2_前後測題庫'!$I$5:$I$19,13),1,0)) | AF24: =IF($P24="","",IF(UPPER(TRIM(P24))=INDEX('2_前後測題庫'!$I$5:$I$19,14),1,0)) | AG24: =IF($Q24="","",IF(UPPER(TRIM(Q24))=INDEX('2_前後測題庫'!$I$5:$I$19,15),1,0)) | AH24: =IF($A24="","",SUM(S24:AG24))
S25: =IF($C25="","",IF(UPPER(TRIM(C25))=INDEX('2_前後測題庫'!$I$5:$I$19,1),1,0)) | T25: =IF($D25="","",IF(UPPER(TRIM(D25))=INDEX('2_前後測題庫'!$I$5:$I$19,2),1,0)) | U25: =IF($E25="","",IF(UPPER(TRIM(E25))=INDEX('2_前後測題庫'!$I$5:$I$19,3),1,0)) | V25: =IF($F25="","",IF(UPPER(TRIM(F25))=INDEX('2_前後測題庫'!$I$5:$I$19,4),1,0)) | W25: =IF($G25="","",IF(UPPER(TRIM(G25))=INDEX('2_前後測題庫'!$I$5:$I$19,5),1,0)) | X25: =IF($H25="","",IF(UPPER(TRIM(H25))=INDEX('2_前後測題庫'!$I$5:$I$19,6),1,0)) | Y25: =IF($I25="","",IF(UPPER(TRIM(I25))=INDEX('2_前後測題庫'!$I$5:$I$19,7),1,0)) | Z25: =IF($J25="","",IF(UPPER(TRIM(J25))=INDEX('2_前後測題庫'!$I$5:$I$19,8),1,0)) | AA25: =IF($K25="","",IF(UPPER(TRIM(K25))=INDEX('2_前後測題庫'!$I$5:$I$19,9),1,0)) | AB25: =IF($L25="","",IF(UPPER(TRIM(L25))=INDEX('2_前後測題庫'!$I$5:$I$19,10),1,0)) | AC25: =IF($M25="","",IF(UPPER(TRIM(M25))=INDEX('2_前後測題庫'!$I$5:$I$19,11),1,0)) | AD25: =IF($N25="","",IF(UPPER(TRIM(N25))=INDEX('2_前後測題庫'!$I$5:$I$19,12),1,0)) | AE25: =IF($O25="","",IF(UPPER(TRIM(O25))=INDEX('2_前後測題庫'!$I$5:$I$19,13),1,0)) | AF25: =IF($P25="","",IF(UPPER(TRIM(P25))=INDEX('2_前後測題庫'!$I$5:$I$19,14),1,0)) | AG25: =IF($Q25="","",IF(UPPER(TRIM(Q25))=INDEX('2_前後測題庫'!$I$5:$I$19,15),1,0)) | AH25: =IF($A25="","",SUM(S25:AG25))
S26: =IF($C26="","",IF(UPPER(TRIM(C26))=INDEX('2_前後測題庫'!$I$5:$I$19,1),1,0)) | T26: =IF($D26="","",IF(UPPER(TRIM(D26))=INDEX('2_前後測題庫'!$I$5:$I$19,2),1,0)) | U26: =IF($E26="","",IF(UPPER(TRIM(E26))=INDEX('2_前後測題庫'!$I$5:$I$19,3),1,0)) | V26: =IF($F26="","",IF(UPPER(TRIM(F26))=INDEX('2_前後測題庫'!$I$5:$I$19,4),1,0)) | W26: =IF($G26="","",IF(UPPER(TRIM(G26))=INDEX('2_前後測題庫'!$I$5:$I$19,5),1,0)) | X26: =IF($H26="","",IF(UPPER(TRIM(H26))=INDEX('2_前後測題庫'!$I$5:$I$19,6),1,0)) | Y26: =IF($I26="","",IF(UPPER(TRIM(I26))=INDEX('2_前後測題庫'!$I$5:$I$19,7),1,0)) | Z26: =IF($J26="","",IF(UPPER(TRIM(J26))=INDEX('2_前後測題庫'!$I$5:$I$19,8),1,0)) | AA26: =IF($K26="","",IF(UPPER(TRIM(K26))=INDEX('2_前後測題庫'!$I$5:$I$19,9),1,0)) | AB26: =IF($L26="","",IF(UPPER(TRIM(L26))=INDEX('2_前後測題庫'!$I$5:$I$19,10),1,0)) | AC26: =IF($M26="","",IF(UPPER(TRIM(M26))=INDEX('2_前後測題庫'!$I$5:$I$19,11),1,0)) | AD26: =IF($N26="","",IF(UPPER(TRIM(N26))=INDEX('2_前後測題庫'!$I$5:$I$19,12),1,0)) | AE26: =IF($O26="","",IF(UPPER(TRIM(O26))=INDEX('2_前後測題庫'!$I$5:$I$19,13),1,0)) | AF26: =IF($P26="","",IF(UPPER(TRIM(P26))=INDEX('2_前後測題庫'!$I$5:$I$19,14),1,0)) | AG26: =IF($Q26="","",IF(UPPER(TRIM(Q26))=INDEX('2_前後測題庫'!$I$5:$I$19,15),1,0)) | AH26: =IF($A26="","",SUM(S26:AG26))
S27: =IF($C27="","",IF(UPPER(TRIM(C27))=INDEX('2_前後測題庫'!$I$5:$I$19,1),1,0)) | T27: =IF($D27="","",IF(UPPER(TRIM(D27))=INDEX('2_前後測題庫'!$I$5:$I$19,2),1,0)) | U27: =IF($E27="","",IF(UPPER(TRIM(E27))=INDEX('2_前後測題庫'!$I$5:$I$19,3),1,0)) | V27: =IF($F27="","",IF(UPPER(TRIM(F27))=INDEX('2_前後測題庫'!$I$5:$I$19,4),1,0)) | W27: =IF($G27="","",IF(UPPER(TRIM(G27))=INDEX('2_前後測題庫'!$I$5:$I$19,5),1,0)) | X27: =IF($H27="","",IF(UPPER(TRIM(H27))=INDEX('2_前後測題庫'!$I$5:$I$19,6),1,0)) | Y27: =IF($I27="","",IF(UPPER(TRIM(I27))=INDEX('2_前後測題庫'!$I$5:$I$19,7),1,0)) | Z27: =IF($J27="","",IF(UPPER(TRIM(J27))=INDEX('2_前後測題庫'!$I$5:$I$19,8),1,0)) | AA27: =IF($K27="","",IF(UPPER(TRIM(K27))=INDEX('2_前後測題庫'!$I$5:$I$19,9),1,0)) | AB27: =IF($L27="","",IF(UPPER(TRIM(L27))=INDEX('2_前後測題庫'!$I$5:$I$19,10),1,0)) | AC27: =IF($M27="","",IF(UPPER(TRIM(M27))=INDEX('2_前後測題庫'!$I$5:$I$19,11),1,0)) | AD27: =IF($N27="","",IF(UPPER(TRIM(N27))=INDEX('2_前後測題庫'!$I$5:$I$19,12),1,0)) | AE27: =IF($O27="","",IF(UPPER(TRIM(O27))=INDEX('2_前後測題庫'!$I$5:$I$19,13),1,0)) | AF27: =IF($P27="","",IF(UPPER(TRIM(P27))=INDEX('2_前後測題庫'!$I$5:$I$19,14),1,0)) | AG27: =IF($Q27="","",IF(UPPER(TRIM(Q27))=INDEX('2_前後測題庫'!$I$5:$I$19,15),1,0)) | AH27: =IF($A27="","",SUM(S27:AG27))
S28: =IF($C28="","",IF(UPPER(TRIM(C28))=INDEX('2_前後測題庫'!$I$5:$I$19,1),1,0)) | T28: =IF($D28="","",IF(UPPER(TRIM(D28))=INDEX('2_前後測題庫'!$I$5:$I$19,2),1,0)) | U28: =IF($E28="","",IF(UPPER(TRIM(E28))=INDEX('2_前後測題庫'!$I$5:$I$19,3),1,0)) | V28: =IF($F28="","",IF(UPPER(TRIM(F28))=INDEX('2_前後測題庫'!$I$5:$I$19,4),1,0)) | W28: =IF($G28="","",IF(UPPER(TRIM(G28))=INDEX('2_前後測題庫'!$I$5:$I$19,5),1,0)) | X28: =IF($H28="","",IF(UPPER(TRIM(H28))=INDEX('2_前後測題庫'!$I$5:$I$19,6),1,0)) | Y28: =IF($I28="","",IF(UPPER(TRIM(I28))=INDEX('2_前後測題庫'!$I$5:$I$19,7),1,0)) | Z28: =IF($J28="","",IF(UPPER(TRIM(J28))=INDEX('2_前後測題庫'!$I$5:$I$19,8),1,0)) | AA28: =IF($K28="","",IF(UPPER(TRIM(K28))=INDEX('2_前後測題庫'!$I$5:$I$19,9),1,0)) | AB28: =IF($L28="","",IF(UPPER(TRIM(L28))=INDEX('2_前後測題庫'!$I$5:$I$19,10),1,0)) | AC28: =IF($M28="","",IF(UPPER(TRIM(M28))=INDEX('2_前後測題庫'!$I$5:$I$19,11),1,0)) | AD28: =IF($N28="","",IF(UPPER(TRIM(N28))=INDEX('2_前後測題庫'!$I$5:$I$19,12),1,0)) | AE28: =IF($O28="","",IF(UPPER(TRIM(O28))=INDEX('2_前後測題庫'!$I$5:$I$19,13),1,0)) | AF28: =IF($P28="","",IF(UPPER(TRIM(P28))=INDEX('2_前後測題庫'!$I$5:$I$19,14),1,0)) | AG28: =IF($Q28="","",IF(UPPER(TRIM(Q28))=INDEX('2_前後測題庫'!$I$5:$I$19,15),1,0)) | AH28: =IF($A28="","",SUM(S28:AG28))
S29: =IF($C29="","",IF(UPPER(TRIM(C29))=INDEX('2_前後測題庫'!$I$5:$I$19,1),1,0)) | T29: =IF($D29="","",IF(UPPER(TRIM(D29))=INDEX('2_前後測題庫'!$I$5:$I$19,2),1,0)) | U29: =IF($E29="","",IF(UPPER(TRIM(E29))=INDEX('2_前後測題庫'!$I$5:$I$19,3),1,0)) | V29: =IF($F29="","",IF(UPPER(TRIM(F29))=INDEX('2_前後測題庫'!$I$5:$I$19,4),1,0)) | W29: =IF($G29="","",IF(UPPER(TRIM(G29))=INDEX('2_前後測題庫'!$I$5:$I$19,5),1,0)) | X29: =IF($H29="","",IF(UPPER(TRIM(H29))=INDEX('2_前後測題庫'!$I$5:$I$19,6),1,0)) | Y29: =IF($I29="","",IF(UPPER(TRIM(I29))=INDEX('2_前後測題庫'!$I$5:$I$19,7),1,0)) | Z29: =IF($J29="","",IF(UPPER(TRIM(J29))=INDEX('2_前後測題庫'!$I$5:$I$19,8),1,0)) | AA29: =IF($K29="","",IF(UPPER(TRIM(K29))=INDEX('2_前後測題庫'!$I$5:$I$19,9),1,0)) | AB29: =IF($L29="","",IF(UPPER(TRIM(L29))=INDEX('2_前後測題庫'!$I$5:$I$19,10),1,0)) | AC29: =IF($M29="","",IF(UPPER(TRIM(M29))=INDEX('2_前後測題庫'!$I$5:$I$19,11),1,0)) | AD29: =IF($N29="","",IF(UPPER(TRIM(N29))=INDEX('2_前後測題庫'!$I$5:$I$19,12),1,0)) | AE29: =IF($O29="","",IF(UPPER(TRIM(O29))=INDEX('2_前後測題庫'!$I$5:$I$19,13),1,0)) | AF29: =IF($P29="","",IF(UPPER(TRIM(P29))=INDEX('2_前後測題庫'!$I$5:$I$19,14),1,0)) | AG29: =IF($Q29="","",IF(UPPER(TRIM(Q29))=INDEX('2_前後測題庫'!$I$5:$I$19,15),1,0)) | AH29: =IF($A29="","",SUM(S29:AG29))
S30: =IF($C30="","",IF(UPPER(TRIM(C30))=INDEX('2_前後測題庫'!$I$5:$I$19,1),1,0)) | T30: =IF($D30="","",IF(UPPER(TRIM(D30))=INDEX('2_前後測題庫'!$I$5:$I$19,2),1,0)) | U30: =IF($E30="","",IF(UPPER(TRIM(E30))=INDEX('2_前後測題庫'!$I$5:$I$19,3),1,0)) | V30: =IF($F30="","",IF(UPPER(TRIM(F30))=INDEX('2_前後測題庫'!$I$5:$I$19,4),1,0)) | W30: =IF($G30="","",IF(UPPER(TRIM(G30))=INDEX('2_前後測題庫'!$I$5:$I$19,5),1,0)) | X30: =IF($H30="","",IF(UPPER(TRIM(H30))=INDEX('2_前後測題庫'!$I$5:$I$19,6),1,0)) | Y30: =IF($I30="","",IF(UPPER(TRIM(I30))=INDEX('2_前後測題庫'!$I$5:$I$19,7),1,0)) | Z30: =IF($J30="","",IF(UPPER(TRIM(J30))=INDEX('2_前後測題庫'!$I$5:$I$19,8),1,0)) | AA30: =IF($K30="","",IF(UPPER(TRIM(K30))=INDEX('2_前後測題庫'!$I$5:$I$19,9),1,0)) | AB30: =IF($L30="","",IF(UPPER(TRIM(L30))=INDEX('2_前後測題庫'!$I$5:$I$19,10),1,0)) | AC30: =IF($M30="","",IF(UPPER(TRIM(M30))=INDEX('2_前後測題庫'!$I$5:$I$19,11),1,0)) | AD30: =IF($N30="","",IF(UPPER(TRIM(N30))=INDEX('2_前後測題庫'!$I$5:$I$19,12),1,0)) | AE30: =IF($O30="","",IF(UPPER(TRIM(O30))=INDEX('2_前後測題庫'!$I$5:$I$19,13),1,0)) | AF30: =IF($P30="","",IF(UPPER(TRIM(P30))=INDEX('2_前後測題庫'!$I$5:$I$19,14),1,0)) | AG30: =IF($Q30="","",IF(UPPER(TRIM(Q30))=INDEX('2_前後測題庫'!$I$5:$I$19,15),1,0)) | AH30: =IF($A30="","",SUM(S30:AG30))
S31: =IF($C31="","",IF(UPPER(TRIM(C31))=INDEX('2_前後測題庫'!$I$5:$I$19,1),1,0)) | T31: =IF($D31="","",IF(UPPER(TRIM(D31))=INDEX('2_前後測題庫'!$I$5:$I$19,2),1,0)) | U31: =IF($E31="","",IF(UPPER(TRIM(E31))=INDEX('2_前後測題庫'!$I$5:$I$19,3),1,0)) | V31: =IF($F31="","",IF(UPPER(TRIM(F31))=INDEX('2_前後測題庫'!$I$5:$I$19,4),1,0)) | W31: =IF($G31="","",IF(UPPER(TRIM(G31))=INDEX('2_前後測題庫'!$I$5:$I$19,5),1,0)) | X31: =IF($H31="","",IF(UPPER(TRIM(H31))=INDEX('2_前後測題庫'!$I$5:$I$19,6),1,0)) | Y31: =IF($I31="","",IF(UPPER(TRIM(I31))=INDEX('2_前後測題庫'!$I$5:$I$19,7),1,0)) | Z31: =IF($J31="","",IF(UPPER(TRIM(J31))=INDEX('2_前後測題庫'!$I$5:$I$19,8),1,0)) | AA31: =IF($K31="","",IF(UPPER(TRIM(K31))=INDEX('2_前後測題庫'!$I$5:$I$19,9),1,0)) | AB31: =IF($L31="","",IF(UPPER(TRIM(L31))=INDEX('2_前後測題庫'!$I$5:$I$19,10),1,0)) | AC31: =IF($M31="","",IF(UPPER(TRIM(M31))=INDEX('2_前後測題庫'!$I$5:$I$19,11),1,0)) | AD31: =IF($N31="","",IF(UPPER(TRIM(N31))=INDEX('2_前後測題庫'!$I$5:$I$19,12),1,0)) | AE31: =IF($O31="","",IF(UPPER(TRIM(O31))=INDEX('2_前後測題庫'!$I$5:$I$19,13),1,0)) | AF31: =IF($P31="","",IF(UPPER(TRIM(P31))=INDEX('2_前後測題庫'!$I$5:$I$19,14),1,0)) | AG31: =IF($Q31="","",IF(UPPER(TRIM(Q31))=INDEX('2_前後測題庫'!$I$5:$I$19,15),1,0)) | AH31: =IF($A31="","",SUM(S31:AG31))
... S64: =IF($C64="","",IF(UPPER(TRIM(C64))=INDEX('2_前後測題庫'!$I$5:$I$19,1),1,0)) | T64: =IF($D64="","",IF(UPPER(TRIM(D64))=INDEX('2_前後測題庫'!$I$5:$I$19,2),1,0)) | U64: =IF($E64="","",IF(UPPER(TRIM(E64))=INDEX('2_前後測題庫'!$I$5:$I$19,3),1,0)) | V64: =IF($F64="","",IF(UPPER(TRIM(F64))=INDEX('2_前後測題庫'!$I$5:$I$19,4),1,0)) | W64: =IF($G64="","",IF(UPPER(TRIM(G64))=INDEX('2_前後測題庫'!$I$5:$I$19,5),1,0)) | X64: =IF($H64="","",IF(UPPER(TRIM(H64))=INDEX('2_前後測題庫'!$I$5:$I$19,6),1,0)) | Y64: =IF($I64="","",IF(UPPER(TRIM(I64))=INDEX('2_前後測題庫'!$I$5:$I$19,7),1,0)) | Z64: =IF($J64="","",IF(UPPER(TRIM(J64))=INDEX('2_前後測題庫'!$I$5:$I$19,8),1,0)) | AA64: =IF($K64="","",IF(UPPER(TRIM(K64))=INDEX('2_前後測題庫'!$I$5:$I$19,9),1,0)) | AB64: =IF($L64="","",IF(UPPER(TRIM(L64))=INDEX('2_前後測題庫'!$I$5:$I$19,10),1,0)) | AC64: =IF($M64="","",IF(UPPER(TRIM(M64))=INDEX('2_前後測題庫'!$I$5:$I$19,11),1,0)) | AD64: =IF($N64="","",IF(UPPER(TRIM(N64))=INDEX('2_前後測題庫'!$I$5:$I$19,12),1,0)) | AE64: =IF($O64="","",IF(UPPER(TRIM(O64))=INDEX('2_前後測題庫'!$I$5:$I$19,13),1,0)) | AF64: =IF($P64="","",IF(UPPER(TRIM(P64))=INDEX('2_前後測題庫'!$I$5:$I$19,14),1,0)) | AG64: =IF($Q64="","",IF(UPPER(TRIM(Q64))=INDEX('2_前後測題庫'!$I$5:$I$19,15),1,0)) | AH64: =IF($A64="","",SUM(S64:AG64))

Sheet 4_後測作答
A1: 後測作答（W18 期末考前，不計分或計參與分）
A2: 每位學生一列，填 A/B/C/D（大小寫皆可）。Google 表單可匯出成試算表，把答案欄貼到 C5 起。右邊綠色是對錯（1/0）與總分。示範資料是模擬的，正式使用前請整塊刪除 A5:Q64。
A4: 學號 | B4: 姓名 | C4: Q1 | D4: Q2 | E4: Q3 | F4: Q4 | G4: Q5 | H4: Q6 | I4: Q7 | J4: Q8 | K4: Q9 | L4: Q10 | M4: Q11 | N4: Q12 | O4: Q13 | P4: Q14 | Q4: Q15 | S4: 對1 | T4: 對2 | U4: 對3 | V4: 對4 | W4: 對5 | X4: 對6 | Y4: 對7 | Z4: 對8 | AA4: 對9 | AB4: 對10 | AC4: 對11 | AD4: 對12 | AE4: 對13 | AF4: 對14 | AG4: 對15 | AH4: 總分
A5: S01 | B5: 學生1 | C5: C | D5: B | E5: A | F5: C | G5: C | H5: D | I5: A | J5: D | K5: D | L5: D | M5: B | N5: B | O5: A | P5: A | Q5: B | S5: =IF($C5="","",IF(UPPER(TRIM(C5))=INDEX('2_前後測題庫'!$I$5:$I$19,1),1,0)) | T5: =IF($D5="","",IF(UPPER(TRIM(D5))=INDEX('2_前後測題庫'!$I$5:$I$19,2),1,0)) | U5: =IF($E5="","",IF(UPPER(TRIM(E5))=INDEX('2_前後測題庫'!$I$5:$I$19,3),1,0)) | V5: =IF($F5="","",IF(UPPER(TRIM(F5))=INDEX('2_前後測題庫'!$I$5:$I$19,4),1,0)) | W5: =IF($G5="","",IF(UPPER(TRIM(G5))=INDEX('2_前後測題庫'!$I$5:$I$19,5),1,0)) | X5: =IF($H5="","",IF(UPPER(TRIM(H5))=INDEX('2_前後測題庫'!$I$5:$I$19,6),1,0)) | Y5: =IF($I5="","",IF(UPPER(TRIM(I5))=INDEX('2_前後測題庫'!$I$5:$I$19,7),1,0)) | Z5: =IF($J5="","",IF(UPPER(TRIM(J5))=INDEX('2_前後測題庫'!$I$5:$I$19,8),1,0)) | AA5: =IF($K5="","",IF(UPPER(TRIM(K5))=INDEX('2_前後測題庫'!$I$5:$I$19,9),1,0)) | AB5: =IF($L5="","",IF(UPPER(TRIM(L5))=INDEX('2_前後測題庫'!$I$5:$I$19,10),1,0)) | AC5: =IF($M5="","",IF(UPPER(TRIM(M5))=INDEX('2_前後測題庫'!$I$5:$I$19,11),1,0)) | AD5: =IF($N5="","",IF(UPPER(TRIM(N5))=INDEX('2_前後測題庫'!$I$5:$I$19,12),1,0)) | AE5: =IF($O5="","",IF(UPPER(TRIM(O5))=INDEX('2_前後測題庫'!$I$5:$I$19,13),1,0)) | AF5: =IF($P5="","",IF(UPPER(TRIM(P5))=INDEX('2_前後測題庫'!$I$5:$I$19,14),1,0)) | AG5: =IF($Q5="","",IF(UPPER(TRIM(Q5))=INDEX('2_前後測題庫'!$I$5:$I$19,15),1,0)) | AH5: =IF($A5="","",SUM(S5:AG5))
A6: S02 | B6: 學生2 | C6: A | D6: B | E6: A | F6: C | G6: C | H6: D | I6: B | J6: D | K6: D | L6: B | M6: A | N6: B | O6: B | P6: D | Q6: B | S6: =IF($C6="","",IF(UPPER(TRIM(C6))=INDEX('2_前後測題庫'!$I$5:$I$19,1),1,0)) | T6: =IF($D6="","",IF(UPPER(TRIM(D6))=INDEX('2_前後測題庫'!$I$5:$I$19,2),1,0)) | U6: =IF($E6="","",IF(UPPER(TRIM(E6))=INDEX('2_前後測題庫'!$I$5:$I$19,3),1,0)) | V6: =IF($F6="","",IF(UPPER(TRIM(F6))=INDEX('2_前後測題庫'!$I$5:$I$19,4),1,0)) | W6: =IF($G6="","",IF(UPPER(TRIM(G6))=INDEX('2_前後測題庫'!$I$5:$I$19,5),1,0)) | X6: =IF($H6="","",IF(UPPER(TRIM(H6))=INDEX('2_前後測題庫'!$I$5:$I$19,6),1,0)) | Y6: =IF($I6="","",IF(UPPER(TRIM(I6))=INDEX('2_前後測題庫'!$I$5:$I$19,7),1,0)) | Z6: =IF($J6="","",IF(UPPER(TRIM(J6))=INDEX('2_前後測題庫'!$I$5:$I$19,8),1,0)) | AA6: =IF($K6="","",IF(UPPER(TRIM(K6))=INDEX('2_前後測題庫'!$I$5:$I$19,9),1,0)) | AB6: =IF($L6="","",IF(UPPER(TRIM(L6))=INDEX('2_前後測題庫'!$I$5:$I$19,10),1,0)) | AC6: =IF($M6="","",IF(UPPER(TRIM(M6))=INDEX('2_前後測題庫'!$I$5:$I$19,11),1,0)) | AD6: =IF($N6="","",IF(UPPER(TRIM(N6))=INDEX('2_前後測題庫'!$I$5:$I$19,12),1,0)) | AE6: =IF($O6="","",IF(UPPER(TRIM(O6))=INDEX('2_前後測題庫'!$I$5:$I$19,13),1,0)) | AF6: =IF($P6="","",IF(UPPER(TRIM(P6))=INDEX('2_前後測題庫'!$I$5:$I$19,14),1,0)) | AG6: =IF($Q6="","",IF(UPPER(TRIM(Q6))=INDEX('2_前後測題庫'!$I$5:$I$19,15),1,0)) | AH6: =IF($A6="","",SUM(S6:AG6))
A7: S03 | B7: 學生3 | C7: A | D7: A | E7: B | F7: C | G7: C | H7: D | I7: B | J7: D | K7: D | L7: B | M7: A | N7: D | O7: B | P7: D | Q7: D | S7: =IF($C7="","",IF(UPPER(TRIM(C7))=INDEX('2_前後測題庫'!$I$5:$I$19,1),1,0)) | T7: =IF($D7="","",IF(UPPER(TRIM(D7))=INDEX('2_前後測題庫'!$I$5:$I$19,2),1,0)) | U7: =IF($E7="","",IF(UPPER(TRIM(E7))=INDEX('2_前後測題庫'!$I$5:$I$19,3),1,0)) | V7: =IF($F7="","",IF(UPPER(TRIM(F7))=INDEX('2_前後測題庫'!$I$5:$I$19,4),1,0)) | W7: =IF($G7="","",IF(UPPER(TRIM(G7))=INDEX('2_前後測題庫'!$I$5:$I$19,5),1,0)) | X7: =IF($H7="","",IF(UPPER(TRIM(H7))=INDEX('2_前後測題庫'!$I$5:$I$19,6),1,0)) | Y7: =IF($I7="","",IF(UPPER(TRIM(I7))=INDEX('2_前後測題庫'!$I$5:$I$19,7),1,0)) | Z7: =IF($J7="","",IF(UPPER(TRIM(J7))=INDEX('2_前後測題庫'!$I$5:$I$19,8),1,0)) | AA7: =IF($K7="","",IF(UPPER(TRIM(K7))=INDEX('2_前後測題庫'!$I$5:$I$19,9),1,0)) | AB7: =IF($L7="","",IF(UPPER(TRIM(L7))=INDEX('2_前後測題庫'!$I$5:$I$19,10),1,0)) | AC7: =IF($M7="","",IF(UPPER(TRIM(M7))=INDEX('2_前後測題庫'!$I$5:$I$19,11),1,0)) | AD7: =IF($N7="","",IF(UPPER(TRIM(N7))=INDEX('2_前後測題庫'!$I$5:$I$19,12),1,0)) | AE7: =IF($O7="","",IF(UPPER(TRIM(O7))=INDEX('2_前後測題庫'!$I$5:$I$19,13),1,0)) | AF7: =IF($P7="","",IF(UPPER(TRIM(P7))=INDEX('2_前後測題庫'!$I$5:$I$19,14),1,0)) | AG7: =IF($Q7="","",IF(UPPER(TRIM(Q7))=INDEX('2_前後測題庫'!$I$5:$I$19,15),1,0)) | AH7: =IF($A7="","",SUM(S7:AG7))
A8: S04 | B8: 學生4 | C8: A | D8: B | E8: A | F8: C | G8: C | H8: D | I8: A | J8: D | K8: D | L8: B | M8: D | N8: B | O8: D | P8: D | Q8: B | S8: =IF($C8="","",IF(UPPER(TRIM(C8))=INDEX('2_前後測題庫'!$I$5:$I$19,1),1,0)) | T8: =IF($D8="","",IF(UPPER(TRIM(D8))=INDEX('2_前後測題庫'!$I$5:$I$19,2),1,0)) | U8: =IF($E8="","",IF(UPPER(TRIM(E8))=INDEX('2_前後測題庫'!$I$5:$I$19,3),1,0)) | V8: =IF($F8="","",IF(UPPER(TRIM(F8))=INDEX('2_前後測題庫'!$I$5:$I$19,4),1,0)) | W8: =IF($G8="","",IF(UPPER(TRIM(G8))=INDEX('2_前後測題庫'!$I$5:$I$19,5),1,0)) | X8: =IF($H8="","",IF(UPPER(TRIM(H8))=INDEX('2_前後測題庫'!$I$5:$I$19,6),1,0)) | Y8: =IF($I8="","",IF(UPPER(TRIM(I8))=INDEX('2_前後測題庫'!$I$5:$I$19,7),1,0)) | Z8: =IF($J8="","",IF(UPPER(TRIM(J8))=INDEX('2_前後測題庫'!$I$5:$I$19,8),1,0)) | AA8: =IF($K8="","",IF(UPPER(TRIM(K8))=INDEX('2_前後測題庫'!$I$5:$I$19,9),1,0)) | AB8: =IF($L8="","",IF(UPPER(TRIM(L8))=INDEX('2_前後測題庫'!$I$5:$I$19,10),1,0)) | AC8: =IF($M8="","",IF(UPPER(TRIM(M8))=INDEX('2_前後測題庫'!$I$5:$I$19,11),1,0)) | AD8: =IF($N8="","",IF(UPPER(TRIM(N8))=INDEX('2_前後測題庫'!$I$5:$I$19,12),1,0)) | AE8: =IF($O8="","",IF(UPPER(TRIM(O8))=INDEX('2_前後測題庫'!$I$5:$I$19,13),1,0)) | AF8: =IF($P8="","",IF(UPPER(TRIM(P8))=INDEX('2_前後測題庫'!$I$5:$I$19,14),1,0)) | AG8: =IF($Q8="","",IF(UPPER(TRIM(Q8))=INDEX('2_前後測題庫'!$I$5:$I$19,15),1,0)) | AH8: =IF($A8="","",SUM(S8:AG8))
A9: S05 | B9: 學生5 | C9: D | D9: B | E9: A | F9: C | G9: C | H9: D | I9: A | J9: C | K9: C | L9: A | M9: D | N9: C | O9: B | P9: A | Q9: B | S9: =IF($C9="","",IF(UPPER(TRIM(C9))=INDEX('2_前後測題庫'!$I$5:$I$19,1),1,0)) | T9: =IF($D9="","",IF(UPPER(TRIM(D9))=INDEX('2_前後測題庫'!$I$5:$I$19,2),1,0)) | U9: =IF($E9="","",IF(UPPER(TRIM(E9))=INDEX('2_前後測題庫'!$I$5:$I$19,3),1,0)) | V9: =IF($F9="","",IF(UPPER(TRIM(F9))=INDEX('2_前後測題庫'!$I$5:$I$19,4),1,0)) | W9: =IF($G9="","",IF(UPPER(TRIM(G9))=INDEX('2_前後測題庫'!$I$5:$I$19,5),1,0)) | X9: =IF($H9="","",IF(UPPER(TRIM(H9))=INDEX('2_前後測題庫'!$I$5:$I$19,6),1,0)) | Y9: =IF($I9="","",IF(UPPER(TRIM(I9))=INDEX('2_前後測題庫'!$I$5:$I$19,7),1,0)) | Z9: =IF($J9="","",IF(UPPER(TRIM(J9))=INDEX('2_前後測題庫'!$I$5:$I$19,8),1,0)) | AA9: =IF($K9="","",IF(UPPER(TRIM(K9))=INDEX('2_前後測題庫'!$I$5:$I$19,9),1,0)) | AB9: =IF($L9="","",IF(UPPER(TRIM(L9))=INDEX('2_前後測題庫'!$I$5:$I$19,10),1,0)) | AC9: =IF($M9="","",IF(UPPER(TRIM(M9))=INDEX('2_前後測題庫'!$I$5:$I$19,11),1,0)) | AD9: =IF($N9="","",IF(UPPER(TRIM(N9))=INDEX('2_前後測題庫'!$I$5:$I$19,12),1,0)) | AE9: =IF($O9="","",IF(UPPER(TRIM(O9))=INDEX('2_前後測題庫'!$I$5:$I$19,13),1,0)) | AF9: =IF($P9="","",IF(UPPER(TRIM(P9))=INDEX('2_前後測題庫'!$I$5:$I$19,14),1,0)) | AG9: =IF($Q9="","",IF(UPPER(TRIM(Q9))=INDEX('2_前後測題庫'!$I$5:$I$19,15),1,0)) | AH9: =IF($A9="","",SUM(S9:AG9))
A10: S06 | B10: 學生6 | C10: A | D10: B | E10: C | F10: C | G10: C | H10: A | I10: B | J10: A | K10: A | L10: B | M10: A | N10: A | O10: B | P10: B | Q10: D | S10: =IF($C10="","",IF(UPPER(TRIM(C10))=INDEX('2_前後測題庫'!$I$5:$I$19,1),1,0)) | T10: =IF($D10="","",IF(UPPER(TRIM(D10))=INDEX('2_前後測題庫'!$I$5:$I$19,2),1,0)) | U10: =IF($E10="","",IF(UPPER(TRIM(E10))=INDEX('2_前後測題庫'!$I$5:$I$19,3),1,0)) | V10: =IF($F10="","",IF(UPPER(TRIM(F10))=INDEX('2_前後測題庫'!$I$5:$I$19,4),1,0)) | W10: =IF($G10="","",IF(UPPER(TRIM(G10))=INDEX('2_前後測題庫'!$I$5:$I$19,5),1,0)) | X10: =IF($H10="","",IF(UPPER(TRIM(H10))=INDEX('2_前後測題庫'!$I$5:$I$19,6),1,0)) | Y10: =IF($I10="","",IF(UPPER(TRIM(I10))=INDEX('2_前後測題庫'!$I$5:$I$19,7),1,0)) | Z10: =IF($J10="","",IF(UPPER(TRIM(J10))=INDEX('2_前後測題庫'!$I$5:$I$19,8),1,0)) | AA10: =IF($K10="","",IF(UPPER(TRIM(K10))=INDEX('2_前後測題庫'!$I$5:$I$19,9),1,0)) | AB10: =IF($L10="","",IF(UPPER(TRIM(L10))=INDEX('2_前後測題庫'!$I$5:$I$19,10),1,0)) | AC10: =IF($M10="","",IF(UPPER(TRIM(M10))=INDEX('2_前後測題庫'!$I$5:$I$19,11),1,0)) | AD10: =IF($N10="","",IF(UPPER(TRIM(N10))=INDEX('2_前後測題庫'!$I$5:$I$19,12),1,0)) | AE10: =IF($O10="","",IF(UPPER(TRIM(O10))=INDEX('2_前後測題庫'!$I$5:$I$19,13),1,0)) | AF10: =IF($P10="","",IF(UPPER(TRIM(P10))=INDEX('2_前後測題庫'!$I$5:$I$19,14),1,0)) | AG10: =IF($Q10="","",IF(UPPER(TRIM(Q10))=INDEX('2_前後測題庫'!$I$5:$I$19,15),1,0)) | AH10: =IF($A10="","",SUM(S10:AG10))
A11: S07 | B11: 學生7 | C11: A | D11: B | E11: A | F11: C | G11: C | H11: D | I11: C | J11: D | K11: D | L11: B | M11: A | N11: B | O11: B | P11: D | Q11: B | S11: =IF($C11="","",IF(UPPER(TRIM(C11))=INDEX('2_前後測題庫'!$I$5:$I$19,1),1,0)) | T11: =IF($D11="","",IF(UPPER(TRIM(D11))=INDEX('2_前後測題庫'!$I$5:$I$19,2),1,0)) | U11: =IF($E11="","",IF(UPPER(TRIM(E11))=INDEX('2_前後測題庫'!$I$5:$I$19,3),1,0)) | V11: =IF($F11="","",IF(UPPER(TRIM(F11))=INDEX('2_前後測題庫'!$I$5:$I$19,4),1,0)) | W11: =IF($G11="","",IF(UPPER(TRIM(G11))=INDEX('2_前後測題庫'!$I$5:$I$19,5),1,0)) | X11: =IF($H11="","",IF(UPPER(TRIM(H11))=INDEX('2_前後測題庫'!$I$5:$I$19,6),1,0)) | Y11: =IF($I11="","",IF(UPPER(TRIM(I11))=INDEX('2_前後測題庫'!$I$5:$I$19,7),1,0)) | Z11: =IF($J11="","",IF(UPPER(TRIM(J11))=INDEX('2_前後測題庫'!$I$5:$I$19,8),1,0)) | AA11: =IF($K11="","",IF(UPPER(TRIM(K11))=INDEX('2_前後測題庫'!$I$5:$I$19,9),1,0)) | AB11: =IF($L11="","",IF(UPPER(TRIM(L11))=INDEX('2_前後測題庫'!$I$5:$I$19,10),1,0)) | AC11: =IF($M11="","",IF(UPPER(TRIM(M11))=INDEX('2_前後測題庫'!$I$5:$I$19,11),1,0)) | AD11: =IF($N11="","",IF(UPPER(TRIM(N11))=INDEX('2_前後測題庫'!$I$5:$I$19,12),1,0)) | AE11: =IF($O11="","",IF(UPPER(TRIM(O11))=INDEX('2_前後測題庫'!$I$5:$I$19,13),1,0)) | AF11: =IF($P11="","",IF(UPPER(TRIM(P11))=INDEX('2_前後測題庫'!$I$5:$I$19,14),1,0)) | AG11: =IF($Q11="","",IF(UPPER(TRIM(Q11))=INDEX('2_前後測題庫'!$I$5:$I$19,15),1,0)) | AH11: =IF($A11="","",SUM(S11:AG11))
A12: S08 | B12: 學生8 | C12: A | D12: B | E12: A | F12: C | G12: C | H12: D | I12: B | J12: D | K12: B | L12: B | M12: B | N12: A | O12: C | P12: D | Q12: A | S12: =IF($C12="","",IF(UPPER(TRIM(C12))=INDEX('2_前後測題庫'!$I$5:$I$19,1),1,0)) | T12: =IF($D12="","",IF(UPPER(TRIM(D12))=INDEX('2_前後測題庫'!$I$5:$I$19,2),1,0)) | U12: =IF($E12="","",IF(UPPER(TRIM(E12))=INDEX('2_前後測題庫'!$I$5:$I$19,3),1,0)) | V12: =IF($F12="","",IF(UPPER(TRIM(F12))=INDEX('2_前後測題庫'!$I$5:$I$19,4),1,0)) | W12: =IF($G12="","",IF(UPPER(TRIM(G12))=INDEX('2_前後測題庫'!$I$5:$I$19,5),1,0)) | X12: =IF($H12="","",IF(UPPER(TRIM(H12))=INDEX('2_前後測題庫'!$I$5:$I$19,6),1,0)) | Y12: =IF($I12="","",IF(UPPER(TRIM(I12))=INDEX('2_前後測題庫'!$I$5:$I$19,7),1,0)) | Z12: =IF($J12="","",IF(UPPER(TRIM(J12))=INDEX('2_前後測題庫'!$I$5:$I$19,8),1,0)) | AA12: =IF($K12="","",IF(UPPER(TRIM(K12))=INDEX('2_前後測題庫'!$I$5:$I$19,9),1,0)) | AB12: =IF($L12="","",IF(UPPER(TRIM(L12))=INDEX('2_前後測題庫'!$I$5:$I$19,10),1,0)) | AC12: =IF($M12="","",IF(UPPER(TRIM(M12))=INDEX('2_前後測題庫'!$I$5:$I$19,11),1,0)) | AD12: =IF($N12="","",IF(UPPER(TRIM(N12))=INDEX('2_前後測題庫'!$I$5:$I$19,12),1,0)) | AE12: =IF($O12="","",IF(UPPER(TRIM(O12))=INDEX('2_前後測題庫'!$I$5:$I$19,13),1,0)) | AF12: =IF($P12="","",IF(UPPER(TRIM(P12))=INDEX('2_前後測題庫'!$I$5:$I$19,14),1,0)) | AG12: =IF($Q12="","",IF(UPPER(TRIM(Q12))=INDEX('2_前後測題庫'!$I$5:$I$19,15),1,0)) | AH12: =IF($A12="","",SUM(S12:AG12))
A13: S09 | B13: 學生9 | C13: A | D13: B | E13: A | F13: C | G13: C | H13: D | I13: B | J13: D | K13: D | L13: B | M13: A | N13: B | O13: D | P13: D | Q13: B | S13: =IF($C13="","",IF(UPPER(TRIM(C13))=INDEX('2_前後測題庫'!$I$5:$I$19,1),1,0)) | T13: =IF($D13="","",IF(UPPER(TRIM(D13))=INDEX('2_前後測題庫'!$I$5:$I$19,2),1,0)) | U13: =IF($E13="","",IF(UPPER(TRIM(E13))=INDEX('2_前後測題庫'!$I$5:$I$19,3),1,0)) | V13: =IF($F13="","",IF(UPPER(TRIM(F13))=INDEX('2_前後測題庫'!$I$5:$I$19,4),1,0)) | W13: =IF($G13="","",IF(UPPER(TRIM(G13))=INDEX('2_前後測題庫'!$I$5:$I$19,5),1,0)) | X13: =IF($H13="","",IF(UPPER(TRIM(H13))=INDEX('2_前後測題庫'!$I$5:$I$19,6),1,0)) | Y13: =IF($I13="","",IF(UPPER(TRIM(I13))=INDEX('2_前後測題庫'!$I$5:$I$19,7),1,0)) | Z13: =IF($J13="","",IF(UPPER(TRIM(J13))=INDEX('2_前後測題庫'!$I$5:$I$19,8),1,0)) | AA13: =IF($K13="","",IF(UPPER(TRIM(K13))=INDEX('2_前後測題庫'!$I$5:$I$19,9),1,0)) | AB13: =IF($L13="","",IF(UPPER(TRIM(L13))=INDEX('2_前後測題庫'!$I$5:$I$19,10),1,0)) | AC13: =IF($M13="","",IF(UPPER(TRIM(M13))=INDEX('2_前後測題庫'!$I$5:$I$19,11),1,0)) | AD13: =IF($N13="","",IF(UPPER(TRIM(N13))=INDEX('2_前後測題庫'!$I$5:$I$19,12),1,0)) | AE13: =IF($O13="","",IF(UPPER(TRIM(O13))=INDEX('2_前後測題庫'!$I$5:$I$19,13),1,0)) | AF13: =IF($P13="","",IF(UPPER(TRIM(P13))=INDEX('2_前後測題庫'!$I$5:$I$19,14),1,0)) | AG13: =IF($Q13="","",IF(UPPER(TRIM(Q13))=INDEX('2_前後測題庫'!$I$5:$I$19,15),1,0)) | AH13: =IF($A13="","",SUM(S13:AG13))
A14: S10 | B14: 學生10 | C14: A | D14: B | E14: B | F14: B | G14: D | H14: C | I14: B | J14: D | K14: D | L14: B | M14: A | N14: C | O14: C | P14: D | Q14: D | S14: =IF($C14="","",IF(UPPER(TRIM(C14))=INDEX('2_前後測題庫'!$I$5:$I$19,1),1,0)) | T14: =IF($D14="","",IF(UPPER(TRIM(D14))=INDEX('2_前後測題庫'!$I$5:$I$19,2),1,0)) | U14: =IF($E14="","",IF(UPPER(TRIM(E14))=INDEX('2_前後測題庫'!$I$5:$I$19,3),1,0)) | V14: =IF($F14="","",IF(UPPER(TRIM(F14))=INDEX('2_前後測題庫'!$I$5:$I$19,4),1,0)) | W14: =IF($G14="","",IF(UPPER(TRIM(G14))=INDEX('2_前後測題庫'!$I$5:$I$19,5),1,0)) | X14: =IF($H14="","",IF(UPPER(TRIM(H14))=INDEX('2_前後測題庫'!$I$5:$I$19,6),1,0)) | Y14: =IF($I14="","",IF(UPPER(TRIM(I14))=INDEX('2_前後測題庫'!$I$5:$I$19,7),1,0)) | Z14: =IF($J14="","",IF(UPPER(TRIM(J14))=INDEX('2_前後測題庫'!$I$5:$I$19,8),1,0)) | AA14: =IF($K14="","",IF(UPPER(TRIM(K14))=INDEX('2_前後測題庫'!$I$5:$I$19,9),1,0)) | AB14: =IF($L14="","",IF(UPPER(TRIM(L14))=INDEX('2_前後測題庫'!$I$5:$I$19,10),1,0)) | AC14: =IF($M14="","",IF(UPPER(TRIM(M14))=INDEX('2_前後測題庫'!$I$5:$I$19,11),1,0)) | AD14: =IF($N14="","",IF(UPPER(TRIM(N14))=INDEX('2_前後測題庫'!$I$5:$I$19,12),1,0)) | AE14: =IF($O14="","",IF(UPPER(TRIM(O14))=INDEX('2_前後測題庫'!$I$5:$I$19,13),1,0)) | AF14: =IF($P14="","",IF(UPPER(TRIM(P14))=INDEX('2_前後測題庫'!$I$5:$I$19,14),1,0)) | AG14: =IF($Q14="","",IF(UPPER(TRIM(Q14))=INDEX('2_前後測題庫'!$I$5:$I$19,15),1,0)) | AH14: =IF($A14="","",SUM(S14:AG14))
A15: S11 | B15: 學生11 | C15: A | D15: B | E15: A | F15: C | G15: C | H15: D | I15: D | J15: D | K15: D | L15: B | M15: A | N15: B | O15: A | P15: B | Q15: B | S15: =IF($C15="","",IF(UPPER(TRIM(C15))=INDEX('2_前後測題庫'!$I$5:$I$19,1),1,0)) | T15: =IF($D15="","",IF(UPPER(TRIM(D15))=INDEX('2_前後測題庫'!$I$5:$I$19,2),1,0)) | U15: =IF($E15="","",IF(UPPER(TRIM(E15))=INDEX('2_前後測題庫'!$I$5:$I$19,3),1,0)) | V15: =IF($F15="","",IF(UPPER(TRIM(F15))=INDEX('2_前後測題庫'!$I$5:$I$19,4),1,0)) | W15: =IF($G15="","",IF(UPPER(TRIM(G15))=INDEX('2_前後測題庫'!$I$5:$I$19,5),1,0)) | X15: =IF($H15="","",IF(UPPER(TRIM(H15))=INDEX('2_前後測題庫'!$I$5:$I$19,6),1,0)) | Y15: =IF($I15="","",IF(UPPER(TRIM(I15))=INDEX('2_前後測題庫'!$I$5:$I$19,7),1,0)) | Z15: =IF($J15="","",IF(UPPER(TRIM(J15))=INDEX('2_前後測題庫'!$I$5:$I$19,8),1,0)) | AA15: =IF($K15="","",IF(UPPER(TRIM(K15))=INDEX('2_前後測題庫'!$I$5:$I$19,9),1,0)) | AB15: =IF($L15="","",IF(UPPER(TRIM(L15))=INDEX('2_前後測題庫'!$I$5:$I$19,10),1,0)) | AC15: =IF($M15="","",IF(UPPER(TRIM(M15))=INDEX('2_前後測題庫'!$I$5:$I$19,11),1,0)) | AD15: =IF($N15="","",IF(UPPER(TRIM(N15))=INDEX('2_前後測題庫'!$I$5:$I$19,12),1,0)) | AE15: =IF($O15="","",IF(UPPER(TRIM(O15))=INDEX('2_前後測題庫'!$I$5:$I$19,13),1,0)) | AF15: =IF($P15="","",IF(UPPER(TRIM(P15))=INDEX('2_前後測題庫'!$I$5:$I$19,14),1,0)) | AG15: =IF($Q15="","",IF(UPPER(TRIM(Q15))=INDEX('2_前後測題庫'!$I$5:$I$19,15),1,0)) | AH15: =IF($A15="","",SUM(S15:AG15))
A16: S12 | B16: 學生12 | C16: B | D16: B | E16: B | F16: B | G16: A | H16: B | I16: B | J16: B | K16: D | L16: C | M16: C | N16: B | O16: A | P16: B | Q16: B | S16: =IF($C16="","",IF(UPPER(TRIM(C16))=INDEX('2_前後測題庫'!$I$5:$I$19,1),1,0)) | T16: =IF($D16="","",IF(UPPER(TRIM(D16))=INDEX('2_前後測題庫'!$I$5:$I$19,2),1,0)) | U16: =IF($E16="","",IF(UPPER(TRIM(E16))=INDEX('2_前後測題庫'!$I$5:$I$19,3),1,0)) | V16: =IF($F16="","",IF(UPPER(TRIM(F16))=INDEX('2_前後測題庫'!$I$5:$I$19,4),1,0)) | W16: =IF($G16="","",IF(UPPER(TRIM(G16))=INDEX('2_前後測題庫'!$I$5:$I$19,5),1,0)) | X16: =IF($H16="","",IF(UPPER(TRIM(H16))=INDEX('2_前後測題庫'!$I$5:$I$19,6),1,0)) | Y16: =IF($I16="","",IF(UPPER(TRIM(I16))=INDEX('2_前後測題庫'!$I$5:$I$19,7),1,0)) | Z16: =IF($J16="","",IF(UPPER(TRIM(J16))=INDEX('2_前後測題庫'!$I$5:$I$19,8),1,0)) | AA16: =IF($K16="","",IF(UPPER(TRIM(K16))=INDEX('2_前後測題庫'!$I$5:$I$19,9),1,0)) | AB16: =IF($L16="","",IF(UPPER(TRIM(L16))=INDEX('2_前後測題庫'!$I$5:$I$19,10),1,0)) | AC16: =IF($M16="","",IF(UPPER(TRIM(M16))=INDEX('2_前後測題庫'!$I$5:$I$19,11),1,0)) | AD16: =IF($N16="","",IF(UPPER(TRIM(N16))=INDEX('2_前後測題庫'!$I$5:$I$19,12),1,0)) | AE16: =IF($O16="","",IF(UPPER(TRIM(O16))=INDEX('2_前後測題庫'!$I$5:$I$19,13),1,0)) | AF16: =IF($P16="","",IF(UPPER(TRIM(P16))=INDEX('2_前後測題庫'!$I$5:$I$19,14),1,0)) | AG16: =IF($Q16="","",IF(UPPER(TRIM(Q16))=INDEX('2_前後測題庫'!$I$5:$I$19,15),1,0)) | AH16: =IF($A16="","",SUM(S16:AG16))
... A19: S15 | B19: 學生15 | C19: A | D19: B | E19: A | F19: C | G19: A | H19: D | I19: B | J19: D | K19: D | L19: D | M19: B | N19: C | O19: B | P19: C | Q19: C | S19: =IF($C19="","",IF(UPPER(TRIM(C19))=INDEX('2_前後測題庫'!$I$5:$I$19,1),1,0)) | T19: =IF($D19="","",IF(UPPER(TRIM(D19))=INDEX('2_前後測題庫'!$I$5:$I$19,2),1,0)) | U19: =IF($E19="","",IF(UPPER(TRIM(E19))=INDEX('2_前後測題庫'!$I$5:$I$19,3),1,0)) | V19: =IF($F19="","",IF(UPPER(TRIM(F19))=INDEX('2_前後測題庫'!$I$5:$I$19,4),1,0)) | W19: =IF($G19="","",IF(UPPER(TRIM(G19))=INDEX('2_前後測題庫'!$I$5:$I$19,5),1,0)) | X19: =IF($H19="","",IF(UPPER(TRIM(H19))=INDEX('2_前後測題庫'!$I$5:$I$19,6),1,0)) | Y19: =IF($I19="","",IF(UPPER(TRIM(I19))=INDEX('2_前後測題庫'!$I$5:$I$19,7),1,0)) | Z19: =IF($J19="","",IF(UPPER(TRIM(J19))=INDEX('2_前後測題庫'!$I$5:$I$19,8),1,0)) | AA19: =IF($K19="","",IF(UPPER(TRIM(K19))=INDEX('2_前後測題庫'!$I$5:$I$19,9),1,0)) | AB19: =IF($L19="","",IF(UPPER(TRIM(L19))=INDEX('2_前後測題庫'!$I$5:$I$19,10),1,0)) | AC19: =IF($M19="","",IF(UPPER(TRIM(M19))=INDEX('2_前後測題庫'!$I$5:$I$19,11),1,0)) | AD19: =IF($N19="","",IF(UPPER(TRIM(N19))=INDEX('2_前後測題庫'!$I$5:$I$19,12),1,0)) | AE19: =IF($O19="","",IF(UPPER(TRIM(O19))=INDEX('2_前後測題庫'!$I$5:$I$19,13),1,0)) | AF19: =IF($P19="","",IF(UPPER(TRIM(P19))=INDEX('2_前後測題庫'!$I$5:$I$19,14),1,0)) | AG19: =IF($Q19="","",IF(UPPER(TRIM(Q19))=INDEX('2_前後測題庫'!$I$5:$I$19,15),1,0)) | AH19: =IF($A19="","",SUM(S19:AG19))
S20: =IF($C20="","",IF(UPPER(TRIM(C20))=INDEX('2_前後測題庫'!$I$5:$I$19,1),1,0)) | T20: =IF($D20="","",IF(UPPER(TRIM(D20))=INDEX('2_前後測題庫'!$I$5:$I$19,2),1,0)) | U20: =IF($E20="","",IF(UPPER(TRIM(E20))=INDEX('2_前後測題庫'!$I$5:$I$19,3),1,0)) | V20: =IF($F20="","",IF(UPPER(TRIM(F20))=INDEX('2_前後測題庫'!$I$5:$I$19,4),1,0)) | W20: =IF($G20="","",IF(UPPER(TRIM(G20))=INDEX('2_前後測題庫'!$I$5:$I$19,5),1,0)) | X20: =IF($H20="","",IF(UPPER(TRIM(H20))=INDEX('2_前後測題庫'!$I$5:$I$19,6),1,0)) | Y20: =IF($I20="","",IF(UPPER(TRIM(I20))=INDEX('2_前後測題庫'!$I$5:$I$19,7),1,0)) | Z20: =IF($J20="","",IF(UPPER(TRIM(J20))=INDEX('2_前後測題庫'!$I$5:$I$19,8),1,0)) | AA20: =IF($K20="","",IF(UPPER(TRIM(K20))=INDEX('2_前後測題庫'!$I$5:$I$19,9),1,0)) | AB20: =IF($L20="","",IF(UPPER(TRIM(L20))=INDEX('2_前後測題庫'!$I$5:$I$19,10),1,0)) | AC20: =IF($M20="","",IF(UPPER(TRIM(M20))=INDEX('2_前後測題庫'!$I$5:$I$19,11),1,0)) | AD20: =IF($N20="","",IF(UPPER(TRIM(N20))=INDEX('2_前後測題庫'!$I$5:$I$19,12),1,0)) | AE20: =IF($O20="","",IF(UPPER(TRIM(O20))=INDEX('2_前後測題庫'!$I$5:$I$19,13),1,0)) | AF20: =IF($P20="","",IF(UPPER(TRIM(P20))=INDEX('2_前後測題庫'!$I$5:$I$19,14),1,0)) | AG20: =IF($Q20="","",IF(UPPER(TRIM(Q20))=INDEX('2_前後測題庫'!$I$5:$I$19,15),1,0)) | AH20: =IF($A20="","",SUM(S20:AG20))
S21: =IF($C21="","",IF(UPPER(TRIM(C21))=INDEX('2_前後測題庫'!$I$5:$I$19,1),1,0)) | T21: =IF($D21="","",IF(UPPER(TRIM(D21))=INDEX('2_前後測題庫'!$I$5:$I$19,2),1,0)) | U21: =IF($E21="","",IF(UPPER(TRIM(E21))=INDEX('2_前後測題庫'!$I$5:$I$19,3),1,0)) | V21: =IF($F21="","",IF(UPPER(TRIM(F21))=INDEX('2_前後測題庫'!$I$5:$I$19,4),1,0)) | W21: =IF($G21="","",IF(UPPER(TRIM(G21))=INDEX('2_前後測題庫'!$I$5:$I$19,5),1,0)) | X21: =IF($H21="","",IF(UPPER(TRIM(H21))=INDEX('2_前後測題庫'!$I$5:$I$19,6),1,0)) | Y21: =IF($I21="","",IF(UPPER(TRIM(I21))=INDEX('2_前後測題庫'!$I$5:$I$19,7),1,0)) | Z21: =IF($J21="","",IF(UPPER(TRIM(J21))=INDEX('2_前後測題庫'!$I$5:$I$19,8),1,0)) | AA21: =IF($K21="","",IF(UPPER(TRIM(K21))=INDEX('2_前後測題庫'!$I$5:$I$19,9),1,0)) | AB21: =IF($L21="","",IF(UPPER(TRIM(L21))=INDEX('2_前後測題庫'!$I$5:$I$19,10),1,0)) | AC21: =IF($M21="","",IF(UPPER(TRIM(M21))=INDEX('2_前後測題庫'!$I$5:$I$19,11),1,0)) | AD21: =IF($N21="","",IF(UPPER(TRIM(N21))=INDEX('2_前後測題庫'!$I$5:$I$19,12),1,0)) | AE21: =IF($O21="","",IF(UPPER(TRIM(O21))=INDEX('2_前後測題庫'!$I$5:$I$19,13),1,0)) | AF21: =IF($P21="","",IF(UPPER(TRIM(P21))=INDEX('2_前後測題庫'!$I$5:$I$19,14),1,0)) | AG21: =IF($Q21="","",IF(UPPER(TRIM(Q21))=INDEX('2_前後測題庫'!$I$5:$I$19,15),1,0)) | AH21: =IF($A21="","",SUM(S21:AG21))
S22: =IF($C22="","",IF(UPPER(TRIM(C22))=INDEX('2_前後測題庫'!$I$5:$I$19,1),1,0)) | T22: =IF($D22="","",IF(UPPER(TRIM(D22))=INDEX('2_前後測題庫'!$I$5:$I$19,2),1,0)) | U22: =IF($E22="","",IF(UPPER(TRIM(E22))=INDEX('2_前後測題庫'!$I$5:$I$19,3),1,0)) | V22: =IF($F22="","",IF(UPPER(TRIM(F22))=INDEX('2_前後測題庫'!$I$5:$I$19,4),1,0)) | W22: =IF($G22="","",IF(UPPER(TRIM(G22))=INDEX('2_前後測題庫'!$I$5:$I$19,5),1,0)) | X22: =IF($H22="","",IF(UPPER(TRIM(H22))=INDEX('2_前後測題庫'!$I$5:$I$19,6),1,0)) | Y22: =IF($I22="","",IF(UPPER(TRIM(I22))=INDEX('2_前後測題庫'!$I$5:$I$19,7),1,0)) | Z22: =IF($J22="","",IF(UPPER(TRIM(J22))=INDEX('2_前後測題庫'!$I$5:$I$19,8),1,0)) | AA22: =IF($K22="","",IF(UPPER(TRIM(K22))=INDEX('2_前後測題庫'!$I$5:$I$19,9),1,0)) | AB22: =IF($L22="","",IF(UPPER(TRIM(L22))=INDEX('2_前後測題庫'!$I$5:$I$19,10),1,0)) | AC22: =IF($M22="","",IF(UPPER(TRIM(M22))=INDEX('2_前後測題庫'!$I$5:$I$19,11),1,0)) | AD22: =IF($N22="","",IF(UPPER(TRIM(N22))=INDEX('2_前後測題庫'!$I$5:$I$19,12),1,0)) | AE22: =IF($O22="","",IF(UPPER(TRIM(O22))=INDEX('2_前後測題庫'!$I$5:$I$19,13),1,0)) | AF22: =IF($P22="","",IF(UPPER(TRIM(P22))=INDEX('2_前後測題庫'!$I$5:$I$19,14),1,0)) | AG22: =IF($Q22="","",IF(UPPER(TRIM(Q22))=INDEX('2_前後測題庫'!$I$5:$I$19,15),1,0)) | AH22: =IF($A22="","",SUM(S22:AG22))
